Workbook

Sheet seed1
B2: 120秒平均 | F2: 全て受け入れ | J2: 既存 | N2: 提案（遅い車両が上に凸）
B3: 大型割合 | C3: 合流 | F3: cav0=cav_low | G3: cav1=cav_high | H3: all | J3: cav0=cav_low | K3: cav1=cav_high | L3: all | N3: cav0=cav_low | O3: cav1=cav_high | P3: all
B5: 10 | C5: 600 | D5: 600 | F5: 10.9344 | G5: 12.5432 | H5: 12.3441 | J5: 10.7245 | K5: 12.477 | L5: 12.2576 | N5: 10.9344 | O5: 12.4185 | P5: 12.2365 | Q5: 既存:distなし
C6: 600 | D6: 800 | F6: 11.0723 | G6: 12.9292 | H6: 12.7558 | J6: 10.9705 | K6: 10.9647 | L6: 10.9652 | N6: 11.0723 | O6: 11.1431 | P6: 11.1371
C7: 800 | D7: 800 | F7: 7.8475 | G7: 9.3516 | H7: 9.2278 | J7: 9.7244 | K7: 10.1039 | L7: 10.0752 | N7: 9.7244 | O7: 9.9892 | P7: 9.9692
C8: 1000 | D8: 800 | F8: 10.1713 | G8: 10.8641 | H8: 10.7985 | J8: 9.2489 | K8: 10.0596 | L8: 9.9805 | N8: 10.1713 | O8: 10.8641 | P8: 10.7985 | Q8: 既存:distなし
B10: 15 | C10: 600 | D10: 600
C11: 600 | D11: 800 | J11: 10.7117 | K11: 11.2696 | L11: 11.177 | N11: 10.7117 | O11: 11.2696 | P11: 11.177
C12: 800 | D12: 800
C13: 1000 | D13: 800 | J13: 7.0955 | K13: 7.6483 | L13: 7.5735 | N13: 8.218 | O13: 9.0306 | P13: 8.9164 | Q13: seed2
B15: 25 | C15: 600 | D15: 600 | F15: 10.8676 | G15: 12.5465 | H15: 12.0412 | J15: 10.8474 | K15: 11.8763 | L15: 11.578 | N15: 10.8676 | O15: 12.5465 | P15: 12.0412
C16: 600 | D16: 800 | F16: 10.5802 | G16: 11.5543 | H16: 11.2939 | J16: 10.3108 | K16: 11.2036 | L16: 10.9625 | N16: 10.342 | O16: 11.3152 | P16: 11.0535
C17: 800 | D17: 800 | F17: 10.392 | G17: 11.0593 | H17: 10.8768 | J17: 10.2982 | K17: 11.1783 | L17: 10.9343 | N17: 10.392 | O17: 11.0593 | P17: 10.8768 | Q17: 提案,受け入れ：distなし
C18: 1000 | D18: 800 | F18: 8.0067 | G18: 8.3524 | H18: 8.266 | J18: 7.6889 | K18: 8.2969 | L18: 8.1398 | N18: 7.6849 | O18: 8.2924 | P18: 8.1354
B20: 30
B25: 40 | C25: 600 | D25: 600 | F25: 10.7312 | G25: 11.2406 | H25: 11.042 | J25: 10.6636 | K25: 11.4032 | L25: 11.1109 | N25: 10.7312 | O25: 11.2406 | P25: 11.042
C26: 600 | D26: 800 | F26: 10.7497 | G26: 11.7686 | H26: 11.3607 | J26: 10.7497 | K26: 11.7686 | L26: 11.3607 | N26: 10.7497 | O26: 11.7686 | P26: 11.3607
C27: 800 | D27: 800 | F27: 7.5848 | G27: 8.254 | H27: 7.9722 | J27: 7.447 | K27: 8.5423 | L27: 8.0689 | N27: 9.5856 | O27: 10.0654 | P27: 9.8715
C28: 1000 | D28: 800 | F28: 9.0847 | G28: 9.2353 | H28: 9.1775 | J28: 8.4341 | K28: 8.872 | L28: 8.7014 | N28: 9.0847 | O28: 9.2353 | P28: 9.1775
C31: 試しに
B32: 40 | C32: 600 | D32: 600 | J32: 10.6563 | K32: 11.3404 | L32: 11.07 | N32: 9.7852 | O32: 10.4365 | P32: 10.1779
C33: 800 | D33: 800 | J33: 7.0166 | K33: 8.4463 | L33: 7.8133 | N33: 7.0166 | O33: 8.4463 | P33: 7.8133
C34: 800 | D34: 600 | J34: 10.5724 | K34: 11.3648 | L34: 11.0751 | N34: 10.5724 | O34: 11.3648 | P34: 11.0751
C35: 1000 | D35: 800 | J35: 8.4341 | K35: 8.872 | L35: 8.7014 | N35: 8.9766 | O35: 9.295 | P35: 9.1715

Sheet seed2
F2: 全て受け入れ | J2: 既存 | N2: 提案（遅い車両が上に凸）
B3: 大型割合 | C3: 合流 | F3: cav0=cav_low | G3: cav1=cav_high | H3: all | J3: cav0=cav_low | K3: cav1=cav_high | L3: all | N3: cav0=cav_low | O3: cav1=cav_high | P3: all
B5: 10 | C5: 600 | D5: 600 | F5: 10.5379 | G5: 12.5946 | H5: 12.3295 | J5: 10.2072 | K5: 12.2428 | L5: 11.9818 | N5: 10.2072 | O5: 12.2428 | P5: 11.9818
C6: 600 | D6: 800 | F6: 10.2365 | G6: 11.9253 | H6: 11.7476 | J6: 10.0841 | K6: 11.5589 | L6: 11.4034 | N6: 9.0551 | O6: 11.1674 | P6: 10.9347
C7: 800 | D7: 800 | F7: 10.9079 | G7: 11.0734 | H7: 11.0597 | J7: 10.3299 | K7: 10.6498 | L7: 10.6223 | N7: 10.835 | O7: 10.9609 | P7: 10.9504
C8: 1000 | D8: 800 | F8: 9.5611 | G8: 11.147 | H8: 10.9908 | J8: 8.5551 | K8: 10.7946 | L8: 10.5672 | N8: 8.4186 | O8: 10.6383 | P8: 10.4145
B10: 15 | C10: 600 | D10: 600
C11: 600 | D11: 800
C12: 800 | D12: 800
C13: 1000 | D13: 800
B15: 25 | C15: 600 | D15: 600 | F15: 10.6134 | G15: 12.3981 | H15: 11.9468 | J15: 10.1521 | K15: 12.0478 | L15: 11.5719 | N15: 10.1521 | O15: 12.0478 | P15: 11.5719
C16: 600 | D16: 800 | F16: 10.5319 | G16: 11.5166 | H16: 11.273 | J16: 10.3042 | K16: 11.328 | L16: 11.0737 | N16: 10.5319 | O16: 11.5069 | P16: 11.2658
C17: 800 | D17: 800 | F17: 10.339 | G17: 11.1489 | H17: 10.9517 | J17: 10.339 | K17: 11.1489 | L17: 10.9517 | N17: 10.339 | O17: 11.1489 | P17: 10.9517
C18: 1000 | D18: 800 | Q18: 受け入れ:seed7で代用,既存:seed9 distなし
B20: 30
B25: 40 | C25: 600 | D25: 600 | F25: 10.7538 | G25: 12.1658 | H25: 11.5955 | J25: 10.4072 | K25: 11.7945 | L25: 11.2385 | N25: 10.4072 | O25: 11.7945 | P25: 11.2385
C26: 600 | D26: 800 | F26: 10.6829 | G26: 10.7393 | H26: 10.716 | J26: 10.3249 | K26: 10.5406 | L26: 10.455 | N26: 10.3028 | O26: 10.277 | P26: 10.2877 | Q26: 既存:seed5で代用
C27: 800 | D27: 800 | F27: 9.7028 | G27: 10.3944 | H27: 10.118 | J27: 9.9575 | K27: 10.4967 | L27: 10.2832 | N27: 9.9575 | O27: 10.4967 | P27: 10.2832
C28: 1000 | D28: 800 | Q28: 受け入れ:seed7で代用
B30: 40 | C30: 1000 | D30: 800 | F30: 8.8243 | G30: 8.5873 | H30: 8.6791
B32: 25 | C32: 1000 | D32: 800 | F32: 8.7661 | G32: 9.5185 | H32: 9.3408 | J32: 9.0893 | K32: 8.5057 | L32: 8.6524

Sheet seed3
F2: 全て受け入れ | J2: 既存 | N2: 提案（遅い車両が上に凸）
B3: 大型割合 | C3: 合流 | F3: cav0=cav_low | G3: cav1=cav_high | H3: all | J3: cav0=cav_low | K3: cav1=cav_high | L3: all | N3: cav0=cav_low | O3: cav1=cav_high | P3: all
B5: 10 | C5: 600 | D5: 600 | F5: 11.0746 | G5: 12.4416 | H5: 12.2964 | J5: 11.0746 | K5: 12.4416 | L5: 12.2964 | N5: 11.0746 | O5: 12.5571 | P5: 12.4
C6: 600 | D6: 800 | F6: 9.4617 | G6: 11.6919 | H6: 11.503 | J6: 10.1543 | K6: 12.2136 | L6: 12.0392 | N6: 9.4617 | O6: 11.6919 | P6: 11.503
C7: 800 | D7: 800 | F7: 10.7061 | G7: 11.9556 | H7: 11.8383 | J7: 10.7061 | K7: 11.9556 | L7: 11.8383 | N7: 10.7061 | O7: 11.9556 | P7: 11.8383 | Q7: 提案:distなし
C8: 1000 | D8: 800 | F8: 7.9578 | G8: 10.0996 | H8: 9.9038 | J8: 9.361 | K8: 11.6662 | L8: 11.4502 | N8: 9.361 | O8: 11.6662 | P8: 11.4502
B10: 15 | C10: 600 | D10: 600
C11: 600 | D11: 800
C12: 800 | D12: 800
C13: 1000 | D13: 800
B15: 25 | C15: 600 | D15: 600 | F15: 10.9685 | G15: 11.9329 | H15: 11.6557 | J15: 10.9685 | K15: 11.9329 | L15: 11.6557 | N15: 10.9685 | O15: 11.9329 | P15: 11.6557
C16: 600 | D16: 800 | F16: 10.4492 | G16: 11.4032 | H16: 11.1687 | J16: 9.6413 | K16: 11.3975 | L16: 10.9555 | N16: 10.4179 | O16: 10.8359 | P16: 10.7364
C17: 800 | D17: 800 | F17: 10.7386 | G17: 11.4247 | H17: 11.2548 | J17: 10.7386 | K17: 11.4247 | L17: 11.2548 | N17: 10.7386 | O17: 11.4247 | P17: 11.2548
C18: 1000 | D18: 800 | F18: 9.5705 | G18: 9.9373 | H18: 9.844 | J18: 10.1024 | K18: 11.0831 | L18: 10.8507 | N18: 9.5267 | O18: 9.8245 | P18: 9.749 | Q18: 既存:distなし110s
B20: 30
B25: 40 | C25: 600 | D25: 600 | F25: 10.8624 | G25: 11.7972 | H25: 11.3836 | J25: 10.8048 | K25: 11.6678 | L25: 11.2871 | N25: 10.8048 | O25: 11.6678 | P25: 11.2871
C26: 600 | D26: 800 | F26: 10.3474 | G26: 11.5522 | H26: 11.0307 | J26: 10.524 | K26: 12.0077 | L26: 11.3619 | N26: 10.524 | O26: 12.0077 | P26: 11.3619
C27: 800 | D27: 800 | F27: 10.7622 | G27: 11.2558 | H27: 11.0468 | J27: 10.6346 | K27: 11.1137 | L27: 10.9097 | N27: 10.7651 | O27: 11.2331 | P27: 11.0351
C28: 1000 | D28: 800 | F28: 7.3779 | G28: 7.309 | H28: 7.3365 | J28: 8.319 | K28: 7.5948 | L28: 7.8765 | N28: 7.3779 | O28: 7.309 | P28: 7.3365 | Q28: 既存:seed9で代用→全てseed9で合わせる
F29: ?
F30: 9.0364 | G30: 9.7113 | H30: 9.4353 | N30: 9.0364 | O30: 9.7113 | P30: 9.4353 | Q30: seed3

Sheet seed4
F2: 全て受け入れ | J2: 既存 | N2: 提案（遅い車両が上に凸）
B3: 大型割合 | C3: 合流 | F3: cav0=cav_low | G3: cav1=cav_high | H3: all | J3: cav0=cav_low | K3: cav1=cav_high | L3: all | N3: cav0=cav_low | O3: cav1=cav_high | P3: all
B5: 10 | C5: 600 | D5: 600 | F5: 11.0679 | G5: 12.7851 | H5: 12.6195 | J5: 11.0679 | K5: 12.7851 | L5: 12.6195 | N5: 11.0679 | O5: 12.7851 | P5: 12.6195
C6: 600 | D6: 800 | F6: 9.24 | G6: 10.2793 | H6: 10.165 | J6: 7.3857 | K6: 8.7235 | L6: 8.5571 | N6: 9.2637 | O6: 10.7535 | P6: 10.5842
C7: 800 | D7: 800 | F7: 8.8494 | G7: 8.8331 | H7: 8.8346 | J7: 8.5376 | K7: 8.4449 | L7: 8.4536 | N7: 8.5376 | O7: 8.4475 | P7: 8.4559
C8: 1000 | D8: 800 | F8: 7.7171 | G8: 7.7579 | H8: 7.7552 | J8: 8.1988 | K8: 7.8228 | L8: 7.8466 | N8: 7.7171 | O8: 7.7579 | P8: 7.7552
B10: 15 | C10: 600 | D10: 600
C11: 600 | D11: 800
C12: 800 | D12: 800
C13: 1000 | D13: 800
B15: 25 | C15: 600 | D15: 600 | F15: 10.8274 | G15: 10.8244 | H15: 10.8252 | J15: 10.7357 | K15: 10.6077 | L15: 10.641 | N15: 10.7357 | O15: 10.6077 | P15: 10.641
C16: 600 | D16: 800 | F16: 9.5784 | G16: 9.7699 | H16: 9.7173 | J16: 10.0563 | K16: 10.3843 | L16: 10.2938 | N16: 9.6308 | O16: 9.8088 | P16: 9.7599
C17: 800 | D17: 800 | F17: 8.3989 | G17: 9.019 | H17: 8.8743 | J17: 8.2988 | K17: 8.9864 | L17: 8.8261 | N17: 8.2988 | O17: 8.9864 | P17: 8.8261
C18: 1000 | D18: 800 | F18: 7.645 | G18: 7.6323 | H18: 7.6351 | J18: 7.645 | K18: 7.6323 | L18: 7.6351 | N18: 7.645 | O18: 7.6323 | P18: 7.6351 | Q18: 既存:データなし
B20: 30
B25: 40 | C25: 600 | D25: 600 | F25: 10.1446 | G25: 10.0351 | H25: 10.0769 | J25: 10.2753 | K25: 10.9436 | L25: 10.6803 | N25: 10.5838 | O25: 11.473 | P25: 11.1212 | Q25: 既存:distなし
C26: 600 | D26: 800 | F26: 10.119 | G26: 10.731 | H26: 10.483 | J26: 10.0045 | K26: 10.2643 | L26: 10.16 | N26: 10.119 | O26: 10.731 | P26: 10.483
C27: 800 | D27: 800 | F27: 7.8246 | G27: 7.4552 | H27: 7.5958 | J27: 8.5158 | K27: 8.4468 | L27: 8.4737 | N27: 8.5158 | O27: 8.4468 | P27: 8.4737
C28: 1000 | D28: 800 | Q28: 受け入れ:

Sheet seed5
F2: 全て受け入れ | J2: 既存 | N2: 提案（遅い車両が上に凸）
B3: 大型割合 | C3: 合流 | F3: cav0=cav_low | G3: cav1=cav_high | H3: all | J3: cav0=cav_low | K3: cav1=cav_high | L3: all | N3: cav0=cav_low | O3: cav1=cav_high | P3: all
B5: 10 | C5: 600 | D5: 600
C6: 600 | D6: 800
C7: 800 | D7: 800
C8: 1000 | D8: 800
B10: 15 | C10: 600 | D10: 600
C11: 600 | D11: 800
C12: 800 | D12: 800
C13: 1000 | D13: 800
B15: 25 | C15: 600 | D15: 600
C16: 600 | D16: 800
C17: 800 | D17: 800
C18: 1000 | D18: 800
B20: 30
B25: 40 | C25: 600 | D25: 600
C26: 600 | D26: 800
C27: 800 | D27: 800
C28: 1000 | D28: 800

Sheet average
F2: 全て受け入れ | J2: 既存 | N2: 提案（遅い車両が上に凸）
B3: 大型割合 | C3: 合流 | F3: cav0=cav_low | G3: cav1=cav_high | H3: all | J3: cav0=cav_low | K3: cav1=cav_high | L3: all | N3: cav0=cav_low | O3: cav1=cav_high | P3: all
S4: 全て | T4: 既存 | U4: 提案
B5: 10 | C5: 600 | D5: 600 | F5: =AVERAGE(seed1!F5,seed2!F5,seed3!F5,seed4!F5,seed5!F5) -> 10.9037 | G5: =AVERAGE(seed1!G5,seed2!G5,seed3!G5,seed4!G5,seed5!G5) -> 12.591125 | H5: =AVERAGE(seed1!H5,seed2!H5,seed3!H5,seed4!H5,seed5!H5) -> 12.397375 | J5: =AVERAGE(seed1!J5,seed2!J5,seed3!J5,seed4!J5,seed5!J5) -> 10.76855 | K5: =AVERAGE(seed1!K5,seed2!K5,seed3!K5,seed4!K5,seed5!K5) -> 12.486625 | L5: =AVERAGE(seed1!L5,seed2!L5,seed3!L5,seed4!L5,seed5!L5) -> 12.288825 | N5: =AVERAGE(seed1!N5,seed2!N5,seed3!N5,seed4!N5,seed5!N5) -> 10.821025 | O5: =AVERAGE(seed1!O5,seed2!O5,seed3!O5,seed4!O5,seed5!O5) -> 12.500875 | P5: =AVERAGE(seed1!P5,seed2!P5,seed3!P5,seed4!P5,seed5!P5) -> 12.30945 | R5: 1 | S5: =H5*3.6 -> 44.63055 | T5: =L5*3.6 -> 44.23977 | U5: =P5*3.6 -> 44.31402
C6: 600 | D6: 800 | F6: =AVERAGE(seed1!F6,seed2!F6,seed3!F6,seed4!F6,seed5!F6) -> 10.002625 | G6: =AVERAGE(seed1!G6,seed2!G6,seed3!G6,seed4!G6,seed5!G6) -> 11.706425 | H6: =AVERAGE(seed1!H6,seed2!H6,seed3!H6,seed4!H6,seed5!H6) -> 11.54285 | J6: =AVERAGE(seed1!J6,seed2!J6,seed3!J6,seed4!J6,seed5!J6) -> 9.64865 | K6: =AVERAGE(seed1!K6,seed2!K6,seed3!K6,seed4!K6,seed5!K6) -> 10.865175 | L6: =AVERAGE(seed1!L6,seed2!L6,seed3!L6,seed4!L6,seed5!L6) -> 10.741225 | N6: =AVERAGE(seed1!N6,seed2!N6,seed3!N6,seed4!N6,seed5!N6) -> 9.7132 | O6: =AVERAGE(seed1!O6,seed2!O6,seed3!O6,seed4!O6,seed5!O6) -> 11.188975 | P6: =AVERAGE(seed1!P6,seed2!P6,seed3!P6,seed4!P6,seed5!P6) -> 11.03975 | R6: 2 | S6: =H6*3.6 -> 41.55426 | T6: =L6*3.6 -> 38.66841 | U6: =P6*3.6 -> 39.7431 | W6: =S6/T6 -> 1.0746307
C7: 800 | D7: 800 | F7: =AVERAGE(seed1!F7,seed2!F7,seed3!F7,seed4!F7,seed5!F7) -> 9.577725 | G7: =AVERAGE(seed1!G7,seed2!G7,seed3!G7,seed4!G7,seed5!G7) -> 10.303425 | H7: =AVERAGE(seed1!H7,seed2!H7,seed3!H7,seed4!H7,seed5!H7) -> 10.2401 | J7: =AVERAGE(seed1!J7,seed2!J7,seed3!J7,seed4!J7,seed5!J7) -> 9.8245 | K7: =AVERAGE(seed1!K7,seed2!K7,seed3!K7,seed4!K7,seed5!K7) -> 10.28855 | L7: =AVERAGE(seed1!L7,seed2!L7,seed3!L7,seed4!L7,seed5!L7) -> 10.24735 | N7: =AVERAGE(seed1!N7,seed2!N7,seed3!N7,seed4!N7,seed5!N7) -> 9.950775 | O7: =AVERAGE(seed1!O7,seed2!O7,seed3!O7,seed4!O7,seed5!O7) -> 10.3383 | P7: =AVERAGE(seed1!P7,seed2!P7,seed3!P7,seed4!P7,seed5!P7) -> 10.30345 | R7: 3 | S7: =H7*3.6 -> 36.86436 | T7: =L7*3.6 -> 36.89046 | U7: =P7*3.6 -> 37.09242
C8: 1000 | D8: 800 | F8: =AVERAGE(seed1!F8,seed2!F8,seed3!F8,seed4!F8,seed5!F8) -> 8.851825 | G8: =AVERAGE(seed1!G8,seed2!G8,seed3!G8,seed4!G8,seed5!G8) -> 9.96715 | H8: =AVERAGE(seed1!H8,seed2!H8,seed3!H8,seed4!H8,seed5!H8) -> 9.862075 | J8: =AVERAGE(seed1!J8,seed2!J8,seed3!J8,seed4!J8,seed5!J8) -> 8.84095 | K8: =AVERAGE(seed1!K8,seed2!K8,seed3!K8,seed4!K8,seed5!K8) -> 10.0858 | L8: =AVERAGE(seed1!L8,seed2!L8,seed3!L8,seed4!L8,seed5!L8) -> 9.961125 | N8: =AVERAGE(seed1!N8,seed2!N8,seed3!N8,seed4!N8,seed5!N8) -> 8.917 | O8: =AVERAGE(seed1!O8,seed2!O8,seed3!O8,seed4!O8,seed5!O8) -> 10.231625 | P8: =AVERAGE(seed1!P8,seed2!P8,seed3!P8,seed4!P8,seed5!P8) -> 10.1046 | R8: 4 | S8: =H8*3.6 -> 35.50347 | T8: =L8*3.6 -> 35.86005 | U8: =P8*3.6 -> 36.37656
B10: 15 | C10: 600 | D10: 600 | F10: =AVERAGE(seed1!F10,seed2!F10,seed3!F10,seed4!F10,seed5!F10) -> #DIV/0! | G10: =AVERAGE(seed1!G10,seed2!G10,seed3!G10,seed4!G10,seed5!G10) -> #DIV/0! | H10: =AVERAGE(seed1!H10,seed2!H10,seed3!H10,seed4!H10,seed5!H10) -> #DIV/0! | J10: =AVERAGE(seed1!J10,seed2!J10,seed3!J10,seed4!J10,seed5!J10) -> #DIV/0! | K10: =AVERAGE(seed1!K10,seed2!K10,seed3!K10,seed4!K10,seed5!K10) -> #DIV/0! | L10: =AVERAGE(seed1!L10,seed2!L10,seed3!L10,seed4!L10,seed5!L10) -> #DIV/0! | N10: =AVERAGE(seed1!N10,seed2!N10,seed3!N10,seed4!N10,seed5!N10) -> #DIV/0! | O10: =AVERAGE(seed1!O10,seed2!O10,seed3!O10,seed4!O10,seed5!O10) -> #DIV/0! | P10: =AVERAGE(seed1!P10,seed2!P10,seed3!P10,seed4!P10,seed5!P10) -> #DIV/0!
C11: 600 | D11: 800 | F11: =AVERAGE(seed1!F11,seed2!F11,seed3!F11,seed4!F11,seed5!F11) -> #DIV/0! | G11: =AVERAGE(seed1!G11,seed2!G11,seed3!G11,seed4!G11,seed5!G11) -> #DIV/0! | H11: =AVERAGE(seed1!H11,seed2!H11,seed3!H11,seed4!H11,seed5!H11) -> #DIV/0! | J11: =AVERAGE(seed1!J11,seed2!J11,seed3!J11,seed4!J11,seed5!J11) -> 10.7117 | K11: =AVERAGE(seed1!K11,seed2!K11,seed3!K11,seed4!K11,seed5!K11) -> 11.2696 | L11: =AVERAGE(seed1!L11,seed2!L11,seed3!L11,seed4!L11,seed5!L11) -> 11.177 | N11: =AVERAGE(seed1!N11,seed2!N11,seed3!N11,seed4!N11,seed5!N11) -> 10.7117 | O11: =AVERAGE(seed1!O11,seed2!O11,seed3!O11,seed4!O11,seed5!O11) -> 11.2696 | P11: =AVERAGE(seed1!P11,seed2!P11,seed3!P11,seed4!P11,seed5!P11) -> 11.177
C12: 800 | D12: 800 | F12: =AVERAGE(seed1!F12,seed2!F12,seed3!F12,seed4!F12,seed5!F12) -> #DIV/0! | G12: =AVERAGE(seed1!G12,seed2!G12,seed3!G12,seed4!G12,seed5!G12) -> #DIV/0! | H12: =AVERAGE(seed1!H12,seed2!H12,seed3!H12,seed4!H12,seed5!H12) -> #DIV/0! | J12: =AVERAGE(seed1!J12,seed2!J12,seed3!J12,seed4!J12,seed5!J12) -> #DIV/0! | K12: =AVERAGE(seed1!K12,seed2!K12,seed3!K12,seed4!K12,seed5!K12) -> #DIV/0! | L12: =AVERAGE(seed1!L12,seed2!L12,seed3!L12,seed4!L12,seed5!L12) -> #DIV/0! | N12: =AVERAGE(seed1!N12,seed2!N12,seed3!N12,seed4!N12,seed5!N12) -> #DIV/0! | O12: =AVERAGE(seed1!O12,seed2!O12,seed3!O12,seed4!O12,seed5!O12) -> #DIV/0! | P12: =AVERAGE(seed1!P12,seed2!P12,seed3!P12,seed4!P12,seed5!P12) -> #DIV/0!
C13: 1000 | D13: 800 | F13: =AVERAGE(seed1!F13,seed2!F13,seed3!F13,seed4!F13,seed5!F13) -> #DIV/0! | G13: =AVERAGE(seed1!G13,seed2!G13,seed3!G13,seed4!G13,seed5!G13) -> #DIV/0! | H13: =AVERAGE(seed1!H13,seed2!H13,seed3!H13,seed4!H13,seed5!H13) -> #DIV/0! | J13: =AVERAGE(seed1!J13,seed2!J13,seed3!J13,seed4!J13,seed5!J13) -> 7.0955 | K13: =AVERAGE(seed1!K13,seed2!K13,seed3!K13,seed4!K13,seed5!K13) -> 7.6483 | L13: =AVERAGE(seed1!L13,seed2!L13,seed3!L13,seed4!L13,seed5!L13) -> 7.5735 | N13: =AVERAGE(seed1!N13,seed2!N13,seed3!N13,seed4!N13,seed5!N13) -> 8.218 | O13: =AVERAGE(seed1!O13,seed2!O13,seed3!O13,seed4!O13,seed5!O13) -> 9.0306 | P13: =AVERAGE(seed1!P13,seed2!P13,seed3!P13,seed4!P13,seed5!P13) -> 8.9164
S14: 全て | T14: 既存 | U14: 提案
B15: 25 | C15: 600 | D15: 600 | F15: =AVERAGE(seed1!F15,seed2!F15,seed3!F15,seed4!F15,seed5!F15) -> 10.819225 | G15: =AVERAGE(seed1!G15,seed2!G15,seed3!G15,seed4!G15,seed5!G15) -> 11.925475 | H15: =AVERAGE(seed1!H15,seed2!H15,seed3!H15,seed4!H15,seed5!H15) -> 11.617225 | J15: =AVERAGE(seed1!J15,seed2!J15,seed3!J15,seed4!J15,seed5!J15) -> 10.675925 | K15: =AVERAGE(seed1!K15,seed2!K15,seed3!K15,seed4!K15,seed5!K15) -> 11.616175 | L15: =AVERAGE(seed1!L15,seed2!L15,seed3!L15,seed4!L15,seed5!L15) -> 11.36165 | N15: =AVERAGE(seed1!N15,seed2!N15,seed3!N15,seed4!N15,seed5!N15) -> 10.680975 | O15: =AVERAGE(seed1!O15,seed2!O15,seed3!O15,seed4!O15,seed5!O15) -> 11.783725 | P15: =AVERAGE(seed1!P15,seed2!P15,seed3!P15,seed4!P15,seed5!P15) -> 11.47745 | R15: 1 | S15: =H15*3.6 -> 41.82201 | T15: =L15*3.6 -> 40.90194 | U15: =P15*3.6 -> 41.31882
C16: 600 | D16: 800 | F16: =AVERAGE(seed1!F16,seed2!F16,seed3!F16,seed4!F16,seed5!F16) -> 10.284925 | G16: =AVERAGE(seed1!G16,seed2!G16,seed3!G16,seed4!G16,seed5!G16) -> 11.061 | H16: =AVERAGE(seed1!H16,seed2!H16,seed3!H16,seed4!H16,seed5!H16) -> 10.863225 | J16: =AVERAGE(seed1!J16,seed2!J16,seed3!J16,seed4!J16,seed5!J16) -> 10.07815 | K16: =AVERAGE(seed1!K16,seed2!K16,seed3!K16,seed4!K16,seed5!K16) -> 11.07835 | L16: =AVERAGE(seed1!L16,seed2!L16,seed3!L16,seed4!L16,seed5!L16) -> 10.821375 | N16: =AVERAGE(seed1!N16,seed2!N16,seed3!N16,seed4!N16,seed5!N16) -> 10.23065 | O16: =AVERAGE(seed1!O16,seed2!O16,seed3!O16,seed4!O16,seed5!O16) -> 10.8667 | P16: =AVERAGE(seed1!P16,seed2!P16,seed3!P16,seed4!P16,seed5!P16) -> 10.7039 | R16: 2 | S16: =H16*3.6 -> 39.10761 | T16: =L16*3.6 -> 38.95695 | U16: =P16*3.6 -> 38.53404
C17: 800 | D17: 800 | F17: =AVERAGE(seed1!F17,seed2!F17,seed3!F17,seed4!F17,seed5!F17) -> 9.967125 | G17: =AVERAGE(seed1!G17,seed2!G17,seed3!G17,seed4!G17,seed5!G17) -> 10.662975 | H17: =AVERAGE(seed1!H17,seed2!H17,seed3!H17,seed4!H17,seed5!H17) -> 10.4894 | J17: =AVERAGE(seed1!J17,seed2!J17,seed3!J17,seed4!J17,seed5!J17) -> 9.91865 | K17: =AVERAGE(seed1!K17,seed2!K17,seed3!K17,seed4!K17,seed5!K17) -> 10.684575 | L17: =AVERAGE(seed1!L17,seed2!L17,seed3!L17,seed4!L17,seed5!L17) -> 10.491725 | N17: =AVERAGE(seed1!N17,seed2!N17,seed3!N17,seed4!N17,seed5!N17) -> 9.9421 | O17: =AVERAGE(seed1!O17,seed2!O17,seed3!O17,seed4!O17,seed5!O17) -> 10.654825 | P17: =AVERAGE(seed1!P17,seed2!P17,seed3!P17,seed4!P17,seed5!P17) -> 10.47735 | R17: 3 | S17: =H17*3.6 -> 37.76184 | T17: =L17*3.6 -> 37.77021 | U17: =P17*3.6 -> 37.71846
C18: 1000 | D18: 800 | F18: =AVERAGE(seed1!F18,seed2!F18,seed3!F18,seed4!F18,seed5!F18) -> 8.4074 | G18: =AVERAGE(seed1!G18,seed2!G18,seed3!G18,seed4!G18,seed5!G18) -> 8.6406667 | H18: =AVERAGE(seed1!H18,seed2!H18,seed3!H18,seed4!H18,seed5!H18) -> 8.5817 | J18: =AVERAGE(seed1!J18,seed2!J18,seed3!J18,seed4!J18,seed5!J18) -> 8.4787667 | K18: =AVERAGE(seed1!K18,seed2!K18,seed3!K18,seed4!K18,seed5!K18) -> 9.0041 | L18: =AVERAGE(seed1!L18,seed2!L18,seed3!L18,seed4!L18,seed5!L18) -> 8.8752 | N18: =AVERAGE(seed1!N18,seed2!N18,seed3!N18,seed4!N18,seed5!N18) -> 8.2855333 | O18: =AVERAGE(seed1!O18,seed2!O18,seed3!O18,seed4!O18,seed5!O18) -> 8.5830667 | P18: =AVERAGE(seed1!P18,seed2!P18,seed3!P18,seed4!P18,seed5!P18) -> 8.5065 | R18: 4 | S18: =H18*3.6 -> 30.89412 | T18: =L18*3.6 -> 31.95072 | U18: =P18*3.6 -> 30.6234 | W18: =T18/U18 -> 1.0433433
R19: 1 | S19: 41.82201 | T19: 40.90194 | U19: 41.31882
B20: 30 | R20: 2 | S20: 39.10761 | T20: 38.95695 | U20: 38.53404
R21: 3 | S21: 37.76184 | T21: 37.77021 | U21: 37.71846
R22: 4 | S22: 31.57731 | T22: 31.7502 | U22: 30.6234
S24: 全て | T24: 既存 | U24: 提案
B25: 40 | C25: 600 | D25: 600 | F25: =AVERAGE(seed1!F25,seed2!F25,seed3!F25,seed4!F25,seed5!F25) -> 10.623 | G25: =AVERAGE(seed1!G25,seed2!G25,seed3!G25,seed4!G25,seed5!G25) -> 11.309675 | H25: =AVERAGE(seed1!H25,seed2!H25,seed3!H25,seed4!H25,seed5!H25) -> 11.0245 | J25: =AVERAGE(seed1!J25,seed2!J25,seed3!J25,seed4!J25,seed5!J25) -> 10.537725 | K25: =AVERAGE(seed1!K25,seed2!K25,seed3!K25,seed4!K25,seed5!K25) -> 11.452275 | L25: =AVERAGE(seed1!L25,seed2!L25,seed3!L25,seed4!L25,seed5!L25) -> 11.0792 | N25: =AVERAGE(seed1!N25,seed2!N25,seed3!N25,seed4!N25,seed5!N25) -> 10.63175 | O25: =AVERAGE(seed1!O25,seed2!O25,seed3!O25,seed4!O25,seed5!O25) -> 11.543975 | P25: =AVERAGE(seed1!P25,seed2!P25,seed3!P25,seed4!P25,seed5!P25) -> 11.1722 | R25: 1 | S25: =H25*3.6 -> 39.6882 | T25: =L25*3.6 -> 39.88512 | U25: =P25*3.6 -> 40.21992
C26: 600 | D26: 800 | F26: =AVERAGE(seed1!F26,seed2!F26,seed3!F26,seed4!F26,seed5!F26) -> 10.47475 | G26: =AVERAGE(seed1!G26,seed2!G26,seed3!G26,seed4!G26,seed5!G26) -> 11.197775 | H26: =AVERAGE(seed1!H26,seed2!H26,seed3!H26,seed4!H26,seed5!H26) -> 10.8976 | J26: =AVERAGE(seed1!J26,seed2!J26,seed3!J26,seed4!J26,seed5!J26) -> 10.400775 | K26: =AVERAGE(seed1!K26,seed2!K26,seed3!K26,seed4!K26,seed5!K26) -> 11.1453 | L26: =AVERAGE(seed1!L26,seed2!L26,seed3!L26,seed4!L26,seed5!L26) -> 10.8344 | N26: =AVERAGE(seed1!N26,seed2!N26,seed3!N26,seed4!N26,seed5!N26) -> 10.423875 | O26: =AVERAGE(seed1!O26,seed2!O26,seed3!O26,seed4!O26,seed5!O26) -> 11.196075 | P26: =AVERAGE(seed1!P26,seed2!P26,seed3!P26,seed4!P26,seed5!P26) -> 10.873325 | R26: 2 | S26: =H26*3.6 -> 39.23136 | T26: =L26*3.6 -> 39.00384 | U26: =P26*3.6 -> 39.14397
C27: 800 | D27: 800 | F27: =AVERAGE(seed1!F27,seed2!F27,seed3!F27,seed4!F27,seed5!F27) -> 8.9686 | G27: =AVERAGE(seed1!G27,seed2!G27,seed3!G27,seed4!G27,seed5!G27) -> 9.33985 | H27: =AVERAGE(seed1!H27,seed2!H27,seed3!H27,seed4!H27,seed5!H27) -> 9.1832 | J27: =AVERAGE(seed1!J27,seed2!J27,seed3!J27,seed4!J27,seed5!J27) -> 9.138725 | K27: =AVERAGE(seed1!K27,seed2!K27,seed3!K27,seed4!K27,seed5!K27) -> 9.649875 | L27: =AVERAGE(seed1!L27,seed2!L27,seed3!L27,seed4!L27,seed5!L27) -> 9.433875 | N27: =AVERAGE(seed1!N27,seed2!N27,seed3!N27,seed4!N27,seed5!N27) -> 9.706 | O27: =AVERAGE(seed1!O27,seed2!O27,seed3!O27,seed4!O27,seed5!O27) -> 10.0605 | P27: =AVERAGE(seed1!P27,seed2!P27,seed3!P27,seed4!P27,seed5!P27) -> 9.915875 | R27: 3 | S27: =H27*3.6 -> 33.05952 | T27: =L27*3.6 -> 33.96195 | U27: =P27*3.6 -> 35.69715 | W27: =U27/S27 -> 1.0797843
C28: 1000 | D28: 800 | F28: =AVERAGE(seed1!F28,seed2!F28,seed3!F28,seed4!F28,seed5!F28) -> 8.2313 | G28: =AVERAGE(seed1!G28,seed2!G28,seed3!G28,seed4!G28,seed5!G28) -> 8.27215 | H28: =AVERAGE(seed1!H28,seed2!H28,seed3!H28,seed4!H28,seed5!H28) -> 8.257 | J28: =AVERAGE(seed1!J28,seed2!J28,seed3!J28,seed4!J28,seed5!J28) -> 8.37655 | K28: =AVERAGE(seed1!K28,seed2!K28,seed3!K28,seed4!K28,seed5!K28) -> 8.2334 | L28: =AVERAGE(seed1!L28,seed2!L28,seed3!L28,seed4!L28,seed5!L28) -> 8.28895 | N28: =AVERAGE(seed1!N28,seed2!N28,seed3!N28,seed4!N28,seed5!N28) -> 8.2313 | O28: =AVERAGE(seed1!O28,seed2!O28,seed3!O28,seed4!O28,seed5!O28) -> 8.27215 | P28: =AVERAGE(seed1!P28,seed2!P28,seed3!P28,seed4!P28,seed5!P28) -> 8.257 | R28: 4 | S28: =H28*3.6 -> 29.7252 | T28: =L28*3.6 -> 29.84022 | U28: =P28*3.6 -> 29.7252

Sheet Sheet1
F2: 全て受け入れ | J2: 既存 | N2: 提案（遅い車両が上に凸）
B3: 大型割合 | C3: 合流 | F3: cav0=cav_low | G3: cav1=cav_high | H3: all | J3: cav0=cav_low | K3: cav1=cav_high | L3: all | N3: cav0=cav_low | O3: cav1=cav_high | P3: all
B5: 10
B10: 15
B15: 25
B20: 30
B25: 40

Sheet 後続係数のグラフ
C3: ケース1 | D3: ケース2 | E3: ケース3
B4: 0 | C4: =(200-B4)/200 -> 1 | D4: =(200-B4)^2/40000 -> 1 | E4: =(40000-B4^2)/40000 -> 1
B5: 10 | C5: =(200-B5)/200 -> 0.95 | D5: =(200-B5)^2/40000 -> 0.9025 | E5: =(40000-B5^2)/40000 -> 0.9975
B6: 20 | C6: =(200-B6)/200 -> 0.9 | D6: =(200-B6)^2/40000 -> 0.81 | E6: =(40000-B6^2)/40000 -> 0.99
B7: 30 | C7: =(200-B7)/200 -> 0.85 | D7: =(200-B7)^2/40000 -> 0.7225 | E7: =(40000-B7^2)/40000 -> 0.9775
B8: 40 | C8: =(200-B8)/200 -> 0.8 | D8: =(200-B8)^2/40000 -> 0.64 | E8: =(40000-B8^2)/40000 -> 0.96
B9: 50 | C9: =(200-B9)/200 -> 0.75 | D9: =(200-B9)^2/40000 -> 0.5625 | E9: =(40000-B9^2)/40000 -> 0.9375
B10: 60 | C10: =(200-B10)/200 -> 0.7 | D10: =(200-B10)^2/40000 -> 0.49 | E10: =(40000-B10^2)/40000 -> 0.91
B11: 70 | C11: =(200-B11)/200 -> 0.65 | D11: =(200-B11)^2/40000 -> 0.4225 | E11: =(40000-B11^2)/40000 -> 0.8775
B12: 80 | C12: =(200-B12)/200 -> 0.6 | D12: =(200-B12)^2/40000 -> 0.36 | E12: =(40000-B12^2)/40000 -> 0.84
B13: 90 | C13: =(200-B13)/200 -> 0.55 | D13: =(200-B13)^2/40000 -> 0.3025 | E13: =(40000-B13^2)/40000 -> 0.7975
B14: 100 | C14: =(200-B14)/200 -> 0.5 | D14: =(200-B14)^2/40000 -> 0.25 | E14: =(40000-B14^2)/40000 -> 0.75
B15: 110 | C15: =(200-B15)/200 -> 0.45 | D15: =(200-B15)^2/40000 -> 0.2025 | E15: =(40000-B15^2)/40000 -> 0.6975
... B24: 200 | C24: =(200-B24)/200 -> 0 | D24: =(200-B24)^2/40000 -> 0 | E24: =(40000-B24^2)/40000 -> 0

Sheet 加速度分布
B2: CAV_lowに限定
A4: 800/800/1/40 | C4: -1 | D4: -0.9 | E4: -0.8 | F4: -0.7 | G4: -0.6 | H4: -0.5 | I4: -0.4 | J4: -0.3 | K4: -0.2 | L4: -0.1 | M4: 0 | N4: 0.1 | O4: 0.2 | P4: 0.3 | Q4: 0.4 | R4: 0.5 | S4: 0.6 | T4: 0.7 | U4: 0.8 | V4: 0.9 | W4: 1
B5: 全て受け入れ | C5: =C10/$Y10 -> 0.023721177 | D5: =D10/$Y10 -> 0.022528492 | E5: =E10/$Y10 -> 0.031407368 | F5: =F10/$Y10 -> 0.037768354 | G5: =G10/$Y10 -> 0.039358601 | H5: =H10/$Y10 -> 0.042406573 | I5: =I10/$Y10 -> 0.047839915 | J5: =J10/$Y10 -> 0.0490326 | ... W5: =W10/$Y10 -> 0.018685396 | Y5: =SUM(C5:W5) -> 1
B6: 既存手法 | C6: =C11/$Y11 -> 0.025257128 | D6: =D11/$Y11 -> 0.017966411 | E6: =E11/$Y11 -> 0.028381721 | F6: =F11/$Y11 -> 0.027860956 | G6: =G11/$Y11 -> 0.033459185 | H6: =H11/$Y11 -> 0.036974352 | I6: =I11/$Y11 -> 0.043093347 | J6: =J11/$Y11 -> 0.046087749 | ... W6: =W11/$Y11 -> 0.021611769 | Y6: =SUM(C6:W6) -> 1
B7: 提案手法 | C7: =C12/$Y12 -> 0.010526316 | D7: =D12/$Y12 -> 0.018880535 | E7: =E12/$Y12 -> 0.024895572 | F7: =F12/$Y12 -> 0.025730994 | G7: =G12/$Y12 -> 0.031077694 | H7: =H12/$Y12 -> 0.030409357 | I7: =I12/$Y12 -> 0.032247285 | J7: =J12/$Y12 -> 0.038095238 | ... W7: =W12/$Y12 -> 0.010359231 | Y7: =SUM(C7:W7) -> 1
B9: 元の値 | C9: -1 | D9: -0.9 | E9: -0.8 | F9: -0.7 | G9: -0.6 | H9: -0.5 | I9: -0.4 | J9: -0.3 | K9: -0.2 | L9: -0.1 | M9: 0 | N9: 0.1 | O9: 0.2 | P9: 0.3 | Q9: 0.4 | R9: 0.5 | S9: 0.6 | T9: 0.7 | U9: 0.8 | V9: 0.9 | W9: 1
B10: 全て | C10: 179 | D10: 170 | E10: 237 | F10: 285 | G10: 297 | H10: 320 | I10: 361 | J10: 370 | K10: 373 | L10: 418 | M10: 2225 | N10: 443 | O10: 348 | P10: 225 | Q10: 195 | R10: 178 | S10: 147 | T10: 150 | U10: 270 | V10: 214 | W10: 141 | Y10: =SUM(C10:W10) -> 7546
B11: 既存 | C11: 194 | D11: 138 | E11: 218 | F11: 214 | G11: 257 | H11: 284 | I11: 331 | J11: 354 | K11: 350 | L11: 458 | M11: 2477 | N11: 534 | O11: 399 | P11: 272 | Q11: 202 | R11: 176 | S11: 142 | T11: 119 | U11: 195 | V11: 201 | W11: 166 | Y11: =SUM(C11:W11) -> 7681
B12: 提案 | C12: 63 | D12: 113 | E12: 149 | F12: 154 | G12: 186 | H12: 182 | I12: 193 | J12: 228 | K12: 195 | L12: 240 | M12: 3066 | N12: 205 | O12: 175 | P12: 124 | Q12: 100 | R12: 84 | S12: 92 | T12: 116 | U12: 123 | V12: 135 | W12: 62 | Y12: =SUM(C12:W12) -> 5985
B14: 値の総和 | AA14: 平均
B15: 全て | C15: =C9*C10 -> -179 | D15: =D9*D10 -> -153 | E15: =E9*E10 -> -189.6 | F15: =F9*F10 -> -199.5 | G15: =G9*G10 -> -178.2 | H15: =H9*H10 -> -160 | I15: =I9*I10 -> -144.4 | J15: =J9*J10 -> -111 | ... W15: =W9*W10 -> 141 | Y15: =SUM(C15:W15) -> -339.9 | Z15: 0 | AA15: =Y15/Y10 -> -0.045043732
B16: 既存 | C16: =C9*C11 -> -194 | D16: =D9*D11 -> -124.2 | E16: =E9*E11 -> -174.4 | F16: =F9*F11 -> -149.8 | G16: =G9*G11 -> -154.2 | H16: =H9*H11 -> -142 | I16: =I9*I11 -> -132.4 | J16: =J9*J11 -> -106.2 | ... W16: =W9*W11 -> 166 | Y16: =SUM(C16:W16) -> -238 | Z16: 0 | AA16: =Y16/Y11 -> -0.030985549
B17: 提案 | C17: =C9*C12 -> -63 | D17: =D9*D12 -> -101.7 | E17: =E9*E12 -> -119.2 | F17: =F9*F12 -> -107.8 | G17: =G9*G12 -> -111.6 | H17: =H9*H12 -> -91 | I17: =I9*I12 -> -77.2 | J17: =J9*J12 -> -68.4 | ... W17: =W9*W12 -> 62 | Y17: =SUM(C17:W17) -> -209.9 | Z17: 0 | AA17: =Y17/Y12 -> -0.035071011
B19: 偏差合計 | Z19: 分散 | AA19: 標準偏差
C20: =(C$9-$Z15)^2*C10 -> 179 | D20: =(D$9-$Z15)^2*D10 -> 137.7 | E20: =(E$9-$Z15)^2*E10 -> 151.68 | F20: =(F$9-$Z15)^2*F10 -> 139.65 | G20: =(G$9-$Z15)^2*G10 -> 106.92 | H20: =(H$9-$Z15)^2*H10 -> 80 | I20: =(I$9-$Z15)^2*I10 -> 57.76 | J20: =(J$9-$Z15)^2*J10 -> 33.3 | ... W20: =(W$9-$Z15)^2*W10 -> 141 | Z20: =SUM(C20:W20)/Y10 -> 0.21640207 | AA20: =SQRT(Z20) -> 0.46519036
C21: =(C$9-$Z16)^2*C11 -> 194 | D21: =(D$9-$Z16)^2*D11 -> 111.78 | E21: =(E$9-$Z16)^2*E11 -> 139.52 | F21: =(F$9-$Z16)^2*F11 -> 104.86 | G21: =(G$9-$Z16)^2*G11 -> 92.52 | H21: =(H$9-$Z16)^2*H11 -> 71 | I21: =(I$9-$Z16)^2*I11 -> 52.96 | J21: =(J$9-$Z16)^2*J11 -> 31.86 | ... W21: =(W$9-$Z16)^2*W11 -> 166 | Z21: =SUM(C21:W21)/Y11 -> 0.1955761 | AA21: =SQRT(Z21) -> 0.44223986
C22: =(C$9-$Z17)^2*C12 -> 63 | D22: =(D$9-$Z17)^2*D12 -> 91.53 | E22: =(E$9-$Z17)^2*E12 -> 95.36 | F22: =(F$9-$Z17)^2*F12 -> 75.46 | G22: =(G$9-$Z17)^2*G12 -> 66.96 | H22: =(H$9-$Z17)^2*H12 -> 45.5 | I22: =(I$9-$Z17)^2*I12 -> 30.88 | J22: =(J$9-$Z17)^2*J12 -> 20.52 | ... W22: =(W$9-$Z17)^2*W12 -> 62 | Z22: =SUM(C22:W22)/Y12 -> 0.14981621 | AA22: =SQRT(Z22) -> 0.38706099
A24: 600/800/3/25 | C24: -1 | D24: -0.9 | E24: -0.8 | F24: -0.7 | G24: -0.6 | H24: -0.5 | I24: -0.4 | J24: -0.3 | K24: -0.2 | L24: -0.1 | M24: 0 | N24: 0.1 | O24: 0.2 | P24: 0.3 | Q24: 0.4 | R24: 0.5 | S24: 0.6 | T24: 0.7 | U24: 0.8 | V24: 0.9 | W24: 1
B25: 全て受け入れ | C25: =C30/$Y30 -> 0.016295707 | D25: =D30/$Y30 -> 0.0087440382 | E25: =E30/$Y30 -> 0.013116057 | F25: =F30/$Y30 -> 0.011923688 | G25: =G30/$Y30 -> 0.018680445 | H25: =H30/$Y30 -> 0.016693164 | I25: =I30/$Y30 -> 0.028219396 | J25: =J30/$Y30 -> 0.024642289 | ... W25: =W30/$Y30 -> 0.0039745628 | Y25: =SUM(C25:W25) -> 1
B26: 既存手法 | C26: =C31/$Y31 -> 0.013328256 | D26: =D31/$Y31 -> 0.012566641 | E26: =E31/$Y31 -> 0.022848439 | F26: =F31/$Y31 -> 0.027037319 | G26: =G31/$Y31 -> 0.033891851 | H26: =H31/$Y31 -> 0.033130236 | I26: =I31/$Y31 -> 0.031607007 | J26: =J31/$Y31 -> 0.038461538 | ... W26: =W31/$Y31 -> 0.0022848439 | Y26: =SUM(C26:W26) -> 1
B27: 提案手法 | C27: =C32/$Y32 -> 0.013481364 | D27: =D32/$Y32 -> 0.015067407 | E27: =E32/$Y32 -> 0.020222046 | F27: =F32/$Y32 -> 0.015067407 | G27: =G32/$Y32 -> 0.020618557 | H27: =H32/$Y32 -> 0.017842982 | I27: =I32/$Y32 -> 0.014274385 | J27: =J32/$Y32 -> 0.014670896 | ... W27: =W32/$Y32 -> 0.0015860428 | Y27: =SUM(C27:W27) -> 1
B29: 元の値 | C29: -1 | D29: -0.9 | E29: -0.8 | F29: -0.7 | G29: -0.6 | H29: -0.5 | I29: -0.4 | J29: -0.3 | K29: -0.2 | L29: -0.1 | M29: 0 | N29: 0.1 | O29: 0.2 | P29: 0.3 | Q29: 0.4 | R29: 0.5 | S29: 0.6 | T29: 0.7 | U29: 0.8 | V29: 0.9 | W29: 1
B30: 全て | C30: 41 | D30: 22 | E30: 33 | F30: 30 | G30: 47 | H30: 42 | I30: 71 | J30: 62 | K30: 39 | L30: 39 | M30: 1971 | N30: 13 | O30: 22 | P30: 18 | Q30: 18 | R30: 8 | S30: 8 | T30: 5 | U30: 9 | V30: 8 | W30: 10 | Y30: =SUM(C30:W30) -> 2516
B31: 既存 | C31: 35 | D31: 33 | E31: 60 | F31: 71 | G31: 89 | H31: 87 | I31: 83 | J31: 101 | K31: 58 | L31: 69 | M31: 1765 | N31: 58 | O31: 30 | P31: 21 | Q31: 13 | R31: 6 | S31: 10 | T31: 9 | U31: 17 | V31: 5 | W31: 6 | Y31: =SUM(C31:W31) -> 2626
B32: 提案 | C32: 34 | D32: 38 | E32: 51 | F32: 38 | G32: 52 | H32: 45 | I32: 36 | J32: 37 | K32: 41 | L32: 36 | M32: 1984 | N32: 32 | O32: 16 | P32: 7 | Q32: 8 | R32: 14 | S32: 13 | T32: 11 | U32: 19 | V32: 6 | W32: 4 | Y32: =SUM(C32:W32) -> 2522
B34: 値の総和 | AA34: 平均
B35: 全て | C35: =C29*C30 -> -41 | D35: =D29*D30 -> -19.8 | E35: =E29*E30 -> -26.4 | F35: =F29*F30 -> -21 | G35: =G29*G30 -> -28.2 | H35: =H29*H30 -> -21 | I35: =I29*I30 -> -28.4 | J35: =J29*J30 -> -18.6 | ... W35: =W29*W30 -> 10 | Y35: =SUM(C35:W35) -> -161.1 | Z35: 0 | AA35: =Y35/Y30 -> -0.064030207
B36: 既存 | C36: =C29*C31 -> -35 | D36: =D29*D31 -> -29.7 | E36: =E29*E31 -> -48 | F36: =F29*F31 -> -49.7 | G36: =G29*G31 -> -53.4 | H36: =H29*H31 -> -43.5 | I36: =I29*I31 -> -33.2 | J36: =J29*J31 -> -30.3 | ... W36: =W29*W31 -> 6 | Y36: =SUM(C36:W36) -> -278.6 | Z36: 0 | AA36: =Y36/Y31 -> -0.10609292
B37: 提案 | C37: =C29*C32 -> -34 | D37: =D29*D32 -> -34.2 | E37: =E29*E32 -> -40.8 | F37: =F29*F32 -> -26.6 | G37: =G29*G32 -> -31.2 | H37: =H29*H32 -> -22.5 | I37: =I29*I32 -> -14.4 | J37: =J29*J32 -> -11.1 | ... W37: =W29*W32 -> 4 | Y37: =SUM(C37:W37) -> -167.8 | Z37: 0 | AA37: =Y37/Y32 -> -0.066534496
B39: 偏差合計 | Z39: 分散 | AA39: 標準偏差
C40: =(C$9-$Z35)^2*C30 -> 41 | D40: =(D$9-$Z35)^2*D30 -> 17.82 | E40: =(E$9-$Z35)^2*E30 -> 21.12 | F40: =(F$9-$Z35)^2*F30 -> 14.7 | G40: =(G$9-$Z35)^2*G30 -> 16.92 | H40: =(H$9-$Z35)^2*H30 -> 10.5 | I40: =(I$9-$Z35)^2*I30 -> 11.36 | J40: =(J$9-$Z35)^2*J30 -> 5.58 | ... W40: =(W$9-$Z35)^2*W30 -> 10 | Z40: =SUM(C40:W40)/Y30 -> 0.069964229 | AA40: =SQRT(Z40) -> 0.26450752
C41: =(C$9-$Z36)^2*C31 -> 35 | D41: =(D$9-$Z36)^2*D31 -> 26.73 | E41: =(E$9-$Z36)^2*E31 -> 38.4 | F41: =(F$9-$Z36)^2*F31 -> 34.79 | G41: =(G$9-$Z36)^2*G31 -> 32.04 | H41: =(H$9-$Z36)^2*H31 -> 21.75 | I41: =(I$9-$Z36)^2*I31 -> 13.28 | J41: =(J$9-$Z36)^2*J31 -> 9.09 | ... W41: =(W$9-$Z36)^2*W31 -> 6 | Z41: =SUM(C41:W41)/Y31 -> 0.095308454 | AA41: =SQRT(Z41) -> 0.30872067
C42: =(C$9-$Z37)^2*C32 -> 34 | D42: =(D$9-$Z37)^2*D32 -> 30.78 | E42: =(E$9-$Z37)^2*E32 -> 32.64 | F42: =(F$9-$Z37)^2*F32 -> 18.62 | G42: =(G$9-$Z37)^2*G32 -> 18.72 | H42: =(H$9-$Z37)^2*H32 -> 11.25 | I42: =(I$9-$Z37)^2*I32 -> 5.76 | J42: =(J$9-$Z37)^2*J32 -> 3.33 | ... W42: =(W$9-$Z37)^2*W32 -> 4 | Z42: =SUM(C42:W42)/Y32 -> 0.077145123 | AA42: =SQRT(Z42) -> 0.27775011
A45: 600/800/1~4合計/25 | C45: -1 | D45: -0.9 | E45: -0.8 | F45: -0.7 | G45: -0.6 | H45: -0.5 | I45: -0.4 | J45: -0.3 | K45: -0.2 | L45: -0.1 | M45: 0 | N45: 0.1 | O45: 0.2 | P45: 0.3 | Q45: 0.4 | R45: 0.5 | S45: 0.6 | T45: 0.7 | U45: 0.8 | V45: 0.9 | W45: 1
B46: 全て受け入れ | C46: =C51/$Y51 -> 0.012200183 | D46: =D51/$Y51 -> 0.010872272 | E46: =E51/$Y51 -> 0.01477301 | F46: =F51/$Y51 -> 0.014109055 | G46: =G51/$Y51 -> 0.01850776 | H46: =H51/$Y51 -> 0.019088721 | I46: =I51/$Y51 -> 0.024068387 | J46: =J51/$Y51 -> 0.02523031 | ... W46: =W51/$Y51 -> 0.0084654328 | Y46: =SUM(C46:W46) -> 1
B47: 既存手法 | C47: =C52/$Y52 -> 0.0091097308 | D47: =D52/$Y52 -> 0.012836439 | E47: =E52/$Y52 -> 0.018136646 | F47: =F52/$Y52 -> 0.021283644 | G47: =G52/$Y52 -> 0.025590062 | H47: =H52/$Y52 -> 0.023602484 | I47: =I52/$Y52 -> 0.025175983 | J47: =J52/$Y52 -> 0.027246377 | ... W47: =W52/$Y52 -> 0.0086956522 | Y47: =SUM(C47:W47) -> 1
B48: 提案手法 | C48: =C53/$Y53 -> 0.011232243 | D48: =D53/$Y53 -> 0.012636274 | E48: =E53/$Y53 -> 0.016187645 | F48: =F53/$Y53 -> 0.015444334 | G48: =G53/$Y53 -> 0.018582755 | H48: =H53/$Y53 -> 0.018500165 | I48: =I53/$Y53 -> 0.021638586 | J48: =J53/$Y53 -> 0.021968946 | ... W48: =W53/$Y53 -> 0.0091674926 | Y48: =SUM(C48:W48) -> 1
B50: 元の値 | C50: -1 | D50: -0.9 | E50: -0.8 | F50: -0.7 | G50: -0.6 | H50: -0.5 | I50: -0.4 | J50: -0.3 | K50: -0.2 | L50: -0.1 | M50: 0 | N50: 0.1 | O50: 0.2 | P50: 0.3 | Q50: 0.4 | R50: 0.5 | S50: 0.6 | T50: 0.7 | U50: 0.8 | V50: 0.9 | W50: 1
B51: 全て | C51: =C67+C70+C73+C76 -> 147 | D51: =D67+D70+D73+D76 -> 131 | E51: =E67+E70+E73+E76 -> 178 | F51: =F67+F70+F73+F76 -> 170 | G51: =G67+G70+G73+G76 -> 223 | H51: =H67+H70+H73+H76 -> 230 | I51: =I67+I70+I73+I76 -> 290 | J51: =J67+J70+J73+J76 -> 304 | ... W51: =W67+W70+W73+W76 -> 102 | Y51: =SUM(C51:W51) -> 12049
B52: 既存 | C52: =C68+C71+C74+C77 -> 110 | D52: =D68+D71+D74+D77 -> 155 | E52: =E68+E71+E74+E77 -> 219 | F52: =F68+F71+F74+F77 -> 257 | G52: =G68+G71+G74+G77 -> 309 | H52: =H68+H71+H74+H77 -> 285 | I52: =I68+I71+I74+I77 -> 304 | J52: =J68+J71+J74+J77 -> 329 | ... W52: =W68+W71+W74+W77 -> 105 | Y52: =SUM(C52:W52) -> 12075
...

Sheet 【参考】加速度分布_high
A4: 800/800/1/40 | C4: -2 | D4: -1.9 | E4: -1.8 | F4: -1.7 | G4: -1.6 | H4: -1.5 | I4: -1.4 | J4: -1.3 | K4: -1.2 | L4: -1.1 | M4: -1 | N4: -0.9 | O4: -0.8 | P4: -0.7 | Q4: -0.6 | R4: -0.5 | S4: -0.4 | T4: -0.3 | U4: -0.2 | V4: -0.1 | W4: 0 | X4: 0.1 | Y4: 0.2 | Z4: 0.3 | AA4: 0.4 | AB4: 0.5 | AC4: 0.6 | AD4: 0.7 | AE4: 0.8 | AF4: 0.9 | AG4: 1 | AH4: 1.1 | AI4: 1.2 | AJ4: 1.3 | AK4: 1.4 | AL4: 1.5
B5: 全て受け入れ | C5: =C10/$AN10 -> 0.00020108586 | D5: =D10/$AN10 -> 0.00090488639 | E5: =E10/$AN10 -> 0.00080434345 | F5: =F10/$AN10 -> 0.003016288 | G5: =G10/$AN10 -> 0.0053287754 | H5: =H10/$AN10 -> 0.0045244319 | I5: =I10/$AN10 -> 0.0055298613 | J5: =J10/$AN10 -> 0.0084456063 | ... AL5: =AL10/$AN10 -> 0.0068369194 | AN5: =SUM(C5:AL5) -> 1
B6: 既存手法 | C6: =C11/$AN11 -> 0.0002080516 | D6: =D11/$AN11 -> 0.0033288255 | E6: =E11/$AN11 -> 0.0021845418 | F6: =F11/$AN11 -> 0.0064495995 | G6: =G11/$AN11 -> 0.0062415479 | H6: =H11/$AN11 -> 0.0061375221 | I6: =I11/$AN11 -> 0.0076979091 | J6: =J11/$AN11 -> 0.011026735 | ... AL6: =AL11/$AN11 -> 0.0049932383 | AN6: =SUM(C6:AL6) -> 1
B7: 提案手法 | C7: =C12/$AN12 -> 0.00011804982 | D7: =D12/$AN12 -> 0.00011804982 | E7: =E12/$AN12 -> 0.0010624484 | F7: =F12/$AN12 -> 0.0037775941 | G7: =G12/$AN12 -> 0.0042497934 | H7: =H12/$AN12 -> 0.0060205407 | I7: =I12/$AN12 -> 0.0062566403 | J7: =J12/$AN12 -> 0.0093259355 | ... AL7: =AL12/$AN12 -> 0.0049580923 | AN7: =SUM(C7:AL7) -> 1
B9: 元の値 | C9: -2 | D9: -1.9 | E9: -1.8 | F9: -1.7 | G9: -1.6 | H9: -1.5 | I9: -1.4 | J9: -1.3 | K9: -1.2 | L9: -1.1 | M9: -1 | N9: -0.9 | O9: -0.8 | P9: -0.7 | Q9: -0.6 | R9: -0.5 | S9: -0.4 | T9: -0.3 | U9: -0.2 | V9: -0.1 | W9: 0 | X9: 0.1 | Y9: 0.2 | Z9: 0.3 | AA9: 0.4 | AB9: 0.5 | AC9: 0.6 | AD9: 0.7 | AE9: 0.8 | AF9: 0.9 | AG9: 1 | AH9: 1.1 | AI9: 1.2 | AJ9: 1.3 | AK9: 1.4 | AL9: 1.5
B10: 全て | C10: 2 | D10: 9 | E10: 8 | F10: 30 | G10: 53 | H10: 45 | I10: 55 | J10: 84 | K10: 145 | L10: 235 | M10: 243 | N10: 349 | O10: 353 | P10: 362 | Q10: 393 | R10: 425 | S10: 493 | T10: 499 | U10: 571 | V10: 616 | W10: 1639 | X10: 533 | Y10: 416 | Z10: 310 | AA10: 314 | AB10: 237 | AC10: 270 | AD10: 226 | AE10: 175 | AF10: 154 | AG10: 175 | AH10: 114 | AI10: 102 | AJ10: 105 | AK10: 138 | AL10: 68 | AN10: =SUM(C10:AL10) -> 9946
B11: 既存 | C11: 2 | D11: 32 | E11: 21 | F11: 62 | G11: 60 | H11: 59 | I11: 74 | J11: 106 | K11: 105 | L11: 192 | M11: 206 | N11: 290 | O11: 270 | P11: 282 | Q11: 354 | R11: 354 | S11: 482 | T11: 475 | U11: 544 | V11: 627 | W11: 2095 | X11: 499 | Y11: 376 | Z11: 290 | AA11: 276 | AB11: 234 | AC11: 191 | AD11: 176 | AE11: 138 | AF11: 120 | AG11: 131 | AH11: 89 | AI11: 125 | AJ11: 125 | AK11: 103 | AL11: 48 | AN11: =SUM(C11:AL11) -> 9613
B12: 提案 | C12: 1 | D12: 1 | E12: 9 | F12: 32 | G12: 36 | H12: 51 | I12: 53 | J12: 79 | K12: 80 | L12: 149 | M12: 167 | N12: 218 | O12: 256 | P12: 272 | Q12: 292 | R12: 298 | S12: 359 | T12: 406 | U12: 470 | V12: 569 | W12: 2090 | X12: 418 | Y12: 280 | Z12: 231 | AA12: 210 | AB12: 167 | AC12: 149 | AD12: 166 | AE12: 145 | AF12: 129 | AG12: 129 | AH12: 138 | AI12: 135 | AJ12: 138 | AK12: 106 | AL12: 42 | AN12: =SUM(C12:AL12) -> 8471
B14: 値の総和 | AP14: 平均
B15: 全て | C15: =C9*C10 -> -4 | D15: =D9*D10 -> -17.1 | E15: =E9*E10 -> -14.4 | F15: =F9*F10 -> -51 | G15: =G9*G10 -> -84.8 | H15: =H9*H10 -> -67.5 | I15: =I9*I10 -> -77 | J15: =J9*J10 -> -109.2 | ... AL15: =AL9*AL10 -> 102 | AN15: =SUM(C15:AL15) -> -994.5 | AO15: -0.099989946 | AP15: =AN15/AN10 -> -0.099989946
B16: 既存 | C16: =C9*C11 -> -4 | D16: =D9*D11 -> -60.8 | E16: =E9*E11 -> -37.8 | F16: =F9*F11 -> -105.4 | G16: =G9*G11 -> -96 | H16: =H9*H11 -> -88.5 | I16: =I9*I11 -> -103.6 | J16: =J9*J11 -> -137.8 | ... AL16: =AL9*AL11 -> 72 | AN16: =SUM(C16:AL16) -> -1094.4 | AO16: -0.11384583 | AP16: =AN16/AN11 -> -0.11384583
B17: 提案 | C17: =C9*C12 -> -2 | D17: =D9*D12 -> -1.9 | E17: =E9*E12 -> -16.2 | F17: =F9*F12 -> -54.4 | G17: =G9*G12 -> -57.6 | H17: =H9*H12 -> -76.5 | I17: =I9*I12 -> -74.2 | J17: =J9*J12 -> -102.7 | ... AL17: =AL9*AL12 -> 63 | AN17: =SUM(C17:AL17) -> -538.4 | AO17: -0.063558021 | AP17: =AN17/AN12 -> -0.063558021
B19: 偏差合計 | AO19: 分散 | AP19: 標準偏差
C20: =(C$9-$AO15)^2*C10 -> 7.2200764 | D20: =(D$9-$AO15)^2*D10 -> 29.160326 | E20: =(E$9-$AO15)^2*E10 -> 23.120273 | F20: =(F$9-$AO15)^2*F10 -> 76.800965 | G20: =(G$9-$AO15)^2*G10 -> 119.2516 | H20: =(H$9-$AO15)^2*H10 -> 88.201267 | I20: =(I$9-$AO15)^2*I10 -> 92.951438 | J20: =(J$9-$AO15)^2*J10 -> 120.96203 | ... AL20: =(AL$9-$AO15)^2*AL10 -> 174.07781 | AO20: =SUM(C20:AL20)/AN10 -> 0.40496783 | AP20: =SQRT(AO20) -> 0.63637082
C21: =(C$9-$AO16)^2*C11 -> 7.1151551 | D21: =(D$9-$AO16)^2*D11 -> 102.09109 | E21: =(E$9-$AO16)^2*E11 -> 59.705433 | F21: =(F$9-$AO16)^2*F11 -> 155.98487 | G21: =(G$9-$AO16)^2*G11 -> 132.51925 | H21: =(H$9-$AO16)^2*H11 -> 113.36398 | I21: =(I$9-$AO16)^2*I11 -> 122.41025 | J21: =(J$9-$AO16)^2*J11 -> 149.13794 | ... AL21: =(AL$9-$AO16)^2*AL11 -> 125.01592 | AO21: =SUM(C21:AL21)/AN11 -> 0.39374255 | AP21: =SQRT(AO21) -> 0.62748908
C22: =(C$9-$AO17)^2*C12 -> 3.7498075 | D22: =(D$9-$AO17)^2*D12 -> 3.3725191 | E22: =(E$9-$AO17)^2*E12 -> 27.137077 | F22: =(F$9-$AO17)^2*F12 -> 85.694155 | G22: =(G$9-$AO17)^2*G12 -> 84.983542 | H22: =(H$9-$AO17)^2*H12 -> 105.23164 | I22: =(I$9-$AO17)^2*I12 -> 94.66209 | J22: =(J$9-$AO17)^2*J12 -> 120.77431 | ... AL22: =(AL$9-$AO17)^2*AL12 -> 102.67797 | AO22: =SUM(C22:AL22)/AN12 -> 0.38286629 | AP22: =SQRT(AO22) -> 0.6187619
