Workbook

Sheet seed1_before
C2: 合流200m手前（後続全て） | H2: 合流200m手前（後続120） | K2: 分母v_max
B3: α | C3: vehicle0 | D3: vehicle1 | E3: all | G3: α | H3: vehicle0 | I3: vehicle1 | J3: all | K3: 10秒後
B4: 0 | C4: 14.7242 | D4: 13.2237 | E4: 13.9828 | G4: 0 | H4: 14.7243 | I4: 13.2237 | J4: 13.9829
B5: 0.1 | C5: 14.7242 | D5: 13.2237 | E5: 13.9828 | G5: 0.1 | H5: 14.7243 | I5: 13.2237 | J5: 13.9829
B6: 0.2 | C6: 14.7242 | D6: 13.2237 | E6: 13.9828 | G6: 0.2 | H6: 14.7243 | I6: 13.2237 | J6: 13.9829
B7: 0.3 | C7: 14.7233 | D7: 13.2269 | E7: 13.984 | G7: 0.3 | H7: 14.7234 | I7: 13.2269 | J7: 13.984
B8: 0.4 | C8: 14.7233 | D8: 13.2269 | E8: 13.984 | G8: 0.4 | H8: 14.7234 | I8: 13.2269 | J8: 13.984
B9: 0.5 | C9: 14.4061 | D9: 13.6768 | E9: 14.0458 | G9: 0.5 | H9: 14.2485 | I9: 14.1894 | J9: 14.2195
B10: 0.6 | C10: 14.235 | D10: 15.173 | E10: 14.6927 | G10: 0.6 | H10: 14.2351 | I10: 15.173 | J10: 14.6927
B11: 0.7 | C11: 13.3844 | D11: 16.2527 | E11: 14.7117 | G11: 0.7 | H11: 13.4495 | I11: 16.4233 | J11: 14.8287
B12: 0.8 | C12: 10.9337 | D12: 16.67 | E12: 13.4037 | G12: 0.8 | H12: 11.0084 | I12: 16.6486 | J12: 13.437
B13: 0.9 | C13: 10.9337 | D13: 16.67 | E13: 13.4037 | G13: 0.9 | H13: 10.9337 | I13: 16.67 | J13: 13.4038
B14: 1 | C14: 10.9337 | D14: 16.67 | E14: 13.4037 | G14: 1 | H14: 10.9337 | I14: 16.67 | J14: 13.4038
D16: excel8 | I16: excel9
C18: 合流200m手前（後続全て） | H18: 合流200m手前（後続120） | K18: 分母v_max
B19: α | C19: vehicle0 | D19: vehicle1 | E19: all | G19: α | H19: vehicle0 | I19: vehicle1 | J19: all | K19: 3秒後
B20: 0 | G20: 0
B21: 0.1 | G21: 0.1
B22: 0.2 | C22: 14.5156 | D22: 14.3571 | E22: 14.4377 | G22: 0.2
B23: 0.3 | C23: 14.1565 | D23: 14.0025 | E23: 14.0826 | G23: 0.3 | H23: 14.1565 | I23: 14.0025 | J23: 14.0826 | L23: 13.6562 | M23: 15.426 | N23: 14.4917
B24: 0.4 | G24: 0.4
B25: 0.5 | C25: 13.0609 | D25: 15.4907 | E25: 14.2101 | G25: 0.5 | H25: 12.2226 | I25: 16.5358 | J25: 14.1305
B26: 0.6 | G26: 0.6
B27: 0.7 | C27: 12.2736 | D27: 16.5827 | E27: 14.1808 | G27: 0.7 | H27: 11.0849 | I27: 16.3695 | J27: 13.3604
B28: 0.8 | G28: 0.8
B29: 0.9 | G29: 0.9
B30: 1 | G30: 1
D32: mac | I32: mac
C34: 合流200m手前（後続全て） | H34: 合流200m手前（後続120） | K34: 分母v_DT
B35: α | C35: vehicle0 | D35: vehicle1 | E35: all | G35: α | H35: vehicle0 | I35: vehicle1 | J35: all | K35: 10秒後
B36: 0 | G36: 0
B37: 0.1 | G37: 0.1
B38: 0.2 | G38: 0.2
B39: 0.3 | C39: 14.7243 | D39: 13.2237 | E39: 13.9829 | G39: 0.3 | H39: 14.7243 | I39: 13.2237 | J39: 13.9829
B40: 0.4 | G40: 0.4
B41: 0.5 | C41: 14.4686 | D41: 13.4893 | E41: 13.9847 | G41: 0.5 | H41: 14.362 | I41: 13.9385 | J41: 14.154
B42: 0.6 | G42: 0.6
B43: 0.7 | C43: 14.025 | D43: 13.973 | E43: 14.0001 | G43: 0.7 | H43: 13.693 | I43: 16.2576 | J43: 14.8835
B44: 0.8 | G44: 0.8
B45: 0.9 | G45: 0.9
...

Sheet seed1
C2: 合流200m手前（後続全て） | H2: 合流200m手前（後続110） | K2: 分母v_max
B3: α | C3: vehicle0 | D3: vehicle1 | E3: all | G3: α | H3: vehicle0 | I3: vehicle1 | J3: all | K3: 10秒後
B4: 0 | G4: 0
B5: 0.1 | G5: 0.1
B6: 0.2 | G6: 0.2
B7: 0.3 | G7: 0.3
B8: 0.4 | G8: 0.4
B9: 0.5 | C9: 14.4062 | D9: 13.6768 | E9: 14.0458 | G9: 0.5 | H9: 14.2668 | I9: 14.9791 | J9: 14.6145
B10: 0.6 | C10: 13.9006 | D10: 15.352 | E10: 14.6021 | G10: 0.6 | H10: 13.4536 | I10: 16.4109 | J10: 14.8252
B11: 0.7 | G11: 0.7 | H11: 13.1885 | I11: 16.5223 | J11: 14.7209
B12: 0.8 | G12: 0.8
B13: 0.9 | G13: 0.9
B14: 1 | G14: 1
G15: 0.55 | H15: 14.4758 | I15: 14.3266 | J15: 14.4039
D16: excel16
C18: 合流200m手前（後続全て） | H18: 合流200m手前（後続110） | K18: 分母v_max
B19: α | C19: vehicle0 | D19: vehicle1 | E19: all | G19: α | H19: vehicle0 | I19: vehicle1 | J19: all | K19: 3秒後
B20: 0 | G20: 0
B21: 0.1 | G21: 0.1
B22: 0.2 | G22: 0.2
B23: 0.3 | G23: 0.3
B24: 0.4 | G24: 0.4
B25: 0.5 | C25: 13.1967 | D25: 16.3267 | E25: 14.6056 | G25: 0.5 | H25: 11.9877 | I25: 16.1756 | J25: 13.8413 | M25: 12.0457 | N25: 16.1467 | O25: 13.8137
B26: 0.6 | C26: 13.1967 | D26: 16.3267 | E26: 14.6056 | G26: 0.6 | H26: 12.2736 | I26: 16.5827 | J26: 14.1808 | M26: 12.0457 | N26: 16.1467 | O26: 13.8137
B27: 0.7 | C27: 12.2736 | D27: 16.5827 | E27: 14.1808 | G27: 0.7 | M27: 10.7412 | N27: 16.5518 | O27: 13.1815
B28: 0.8 | G28: 0.8
B29: 0.9 | G29: 0.9
B30: 1 | G30: 1
C34: 合流200m手前（後続全て） | H34: 合流200m手前（後続110） | K34: 分母v_DT
B35: α | C35: vehicle0 | D35: vehicle1 | E35: all | G35: α | H35: vehicle0 | I35: vehicle1 | J35: all | K35: 10秒後
B36: 0 | G36: 0
B37: 0.1 | G37: 0.1
B38: 0.2 | G38: 0.2
B39: 0.3 | G39: 0.3
B40: 0.4 | C40: 14.7243 | D40: 13.2237 | E40: 13.9829 | G40: 0.4 | H40: 14.467 | I40: 13.4826 | J40: 13.9806 | M40: 13.8337 | N40: 11.6236 | O40: 12.7334
B41: 0.5 | C41: 14.4109 | D41: 13.6648 | E41: 14.0423 | G41: 0.5 | H41: 14.2423 | I41: 14.4183 | J41: 14.3282 | M41: 13.3519 | N41: 12.2917 | O41: 12.824
B42: 0.6 | C42: 14.0017 | D42: 15.1736 | E42: 14.5682 | G42: 0.6 | H42: 13.7125 | I42: 16.2533 | J42: 14.8923 | M42: 12.7498 | N42: 14.5499 | O42: 13.6165
B43: 0.7 | C43: 13.475 | D43: 14.5776 | E43: 14.0023 | G43: 0.7 | H43: 13.2056 | I43: 16.4924 | J43: 14.7164 | M43: 12.0018 | N43: 13.6392 | O43: 12.7775
B44: 0.8 | G44: 0.8
B45: 0.9 | G45: 0.9
...

Sheet seed2
C2: 合流200m手前（後続全て） | H2: 合流200m手前（後続110） | K2: 分母v_max
B3: α | C3: vehicle0 | D3: vehicle1 | E3: all | G3: α | H3: vehicle0 | I3: vehicle1 | J3: all | K3: 10秒後
B4: 0 | G4: 0
B5: 0.1 | G5: 0.1
B6: 0.2 | G6: 0.2
B7: 0.3 | G7: 0.3
B8: 0.4 | G8: 0.4
B9: 0.5 | C9: 14.2567 | D9: 16.3433 | E9: 15.2771 | G9: 0.5 | H9: 14.2596 | I9: 16.4322 | J9: 15.3223
B10: 0.6 | C10: 14.2567 | D10: 16.3433 | E10: 15.2771 | G10: 0.6 | H10: 14.2831 | I10: 16.3355 | J10: 15.287
B11: 0.7 | G11: 0.7 | H11: 13.2817 | I11: 16.5464 | J11: 14.8337
B12: 0.8 | G12: 0.8
B13: 0.9 | G13: 0.9
B14: 1 | G14: 1
G15: 0.55 | H15: 14.2567 | I15: 16.3505 | J15: 15.2808
D16: excel16
C18: 合流200m手前（後続全て） | H18: 合流200m手前（後続110） | K18: 分母v_max
B19: α | C19: vehicle0 | D19: vehicle1 | E19: all | G19: α | H19: vehicle0 | I19: vehicle1 | J19: all | K19: 3秒後
B20: 0 | G20: 0
B21: 0.1 | G21: 0.1
B22: 0.2 | G22: 0.2
B23: 0.3 | G23: 0.3
B24: 0.4 | G24: 0.4
B25: 0.5 | G25: 0.5
B26: 0.6 | G26: 0.6
B27: 0.7 | G27: 0.7
B28: 0.8 | G28: 0.8
B29: 0.9 | G29: 0.9
B30: 1 | G30: 1
C34: 合流200m手前（後続全て） | H34: 合流200m手前（後続110） | K34: 分母v_DT
B35: α | C35: vehicle0 | D35: vehicle1 | E35: all | G35: α | H35: vehicle0 | I35: vehicle1 | J35: all | K35: 10秒後
B36: 0 | G36: 0
B37: 0.1 | G37: 0.1
B38: 0.2 | G38: 0.2
B39: 0.3 | G39: 0.3
B40: 0.4 | G40: 0.4 | H40: 15.2775 | I40: 15.2418 | J40: 15.2592
B41: 0.5 | G41: 0.5 | H41: 14.134 | I41: 16.1218 | J41: 15.1068
B42: 0.6 | G42: 0.6 | H42: 14.3198 | I42: 16.392 | J42: 15.3332
B43: 0.7 | G43: 0.7 | H43: 13.4025 | I43: 16.5361 | J43: 14.8922
B44: 0.8 | G44: 0.8
B45: 0.9 | G45: 0.9
...

Sheet seed3
C2: 合流200m手前（後続全て） | H2: 合流200m手前（後続110） | K2: 分母v_max
B3: α | C3: vehicle0 | D3: vehicle1 | E3: all | G3: α | H3: vehicle0 | I3: vehicle1 | J3: all | K3: 10秒後
B4: 0 | G4: 0
B5: 0.1 | G5: 0.1
B6: 0.2 | G6: 0.2
B7: 0.3 | G7: 0.3
B8: 0.4 | G8: 0.4
B9: 0.5 | C9: 16.2158 | D9: 16.1456 | E9: 16.1791 | G9: 0.5 | H9: 14.8766 | I9: 16.5565 | J9: 15.7174
B10: 0.6 | C10: 16.2158 | D10: 16.1456 | E10: 16.1791 | G10: 0.6 | H10: 14.7384 | I10: 16.607 | J10: 15.6679
B11: 0.7 | G11: 0.7 | H11: 14.7384 | I11: 16.607 | J11: 15.6679
B12: 0.8 | G12: 0.8
B13: 0.9 | G13: 0.9
B14: 1 | G14: 1
G15: 0.55 | H15: 14.8766 | I15: 16.5565 | J15: 15.7174
D16: excel16
C18: 合流200m手前（後続全て） | H18: 合流200m手前（後続110） | K18: 分母v_max
B19: α | C19: vehicle0 | D19: vehicle1 | E19: all | G19: α | H19: vehicle0 | I19: vehicle1 | J19: all | K19: 3秒後
B20: 0 | G20: 0
B21: 0.1 | G21: 0.1
B22: 0.2 | G22: 0.2
B23: 0.3 | G23: 0.3
B24: 0.4 | G24: 0.4
B25: 0.5 | G25: 0.5
B26: 0.6 | G26: 0.6
B27: 0.7 | G27: 0.7
B28: 0.8 | G28: 0.8
B29: 0.9 | G29: 0.9
B30: 1 | G30: 1
C34: 合流200m手前（後続全て） | H34: 合流200m手前（後続110） | K34: 分母v_DT
B35: α | C35: vehicle0 | D35: vehicle1 | E35: all | G35: α | H35: vehicle0 | I35: vehicle1 | J35: all | K35: 10秒後
B36: 0 | G36: 0
B37: 0.1 | G37: 0.1
B38: 0.2 | G38: 0.2
B39: 0.3 | G39: 0.3
B40: 0.4 | G40: 0.4 | H40: 16.1834 | I40: 16.2225 | J40: 16.2038
B41: 0.5 | G41: 0.5 | H41: 16.0203 | I41: 16.2394 | J41: 16.1336
B42: 0.6 | G42: 0.6 | H42: 14.7397 | I42: 16.6068 | J42: 15.6685
B43: 0.7 | G43: 0.7 | H43: 14.7384 | I43: 16.607 | J43: 15.6679
B44: 0.8 | G44: 0.8
B45: 0.9 | G45: 0.9
...

Sheet seed4
C2: 合流200m手前（後続全て） | H2: 合流200m手前（後続110） | K2: 分母v_max
B3: α | C3: vehicle0 | D3: vehicle1 | E3: all | G3: α | H3: vehicle0 | I3: vehicle1 | J3: all | K3: 10秒後
B4: 0 | G4: 0
B5: 0.1 | G5: 0.1
B6: 0.2 | G6: 0.2
B7: 0.3 | G7: 0.3
B8: 0.4 | G8: 0.4
B9: 0.5 | C9: 14.9592 | D9: 15.6212 | E9: 15.2784 | G9: 0.5 | H9: 15.2088 | I9: 16.0801 | J9: 15.6217
B10: 0.6 | C10: 14.97 | D10: 15.7224 | E10: 15.3324 | G10: 0.6 | H10: 13.685 | I10: 16.2394 | J10: 14.8373
B11: 0.7 | G11: 0.7 | H11: 12.6599 | I11: 16.509 | J11: 14.3574
B12: 0.8 | G12: 0.8
B13: 0.9 | G13: 0.9
B14: 1 | G14: 1
G15: 0.55 | H15: 12.4252 | I15: 16.04 | J15: 14.0307
D16: excel16
C18: 合流200m手前（後続全て） | H18: 合流200m手前（後続110） | K18: 分母v_max
B19: α | C19: vehicle0 | D19: vehicle1 | E19: all | G19: α | H19: vehicle0 | I19: vehicle1 | J19: all | K19: 3秒後
B20: 0 | G20: 0
B21: 0.1 | G21: 0.1
B22: 0.2 | G22: 0.2
B23: 0.3 | G23: 0.3
B24: 0.4 | G24: 0.4
B25: 0.5 | G25: 0.5
B26: 0.6 | G26: 0.6
B27: 0.7 | G27: 0.7
B28: 0.8 | G28: 0.8
B29: 0.9 | G29: 0.9
B30: 1 | G30: 1
C34: 合流200m手前（後続全て） | H34: 合流200m手前（後続110） | K34: 分母v_DT
B35: α | C35: vehicle0 | D35: vehicle1 | E35: all | G35: α | H35: vehicle0 | I35: vehicle1 | J35: all | K35: 10秒後
B36: 0 | G36: 0
B37: 0.1 | G37: 0.1
B38: 0.2 | G38: 0.2
B39: 0.3 | G39: 0.3
B40: 0.4 | G40: 0.4 | H40: 14.8178 | I40: 15.0007 | J40: 14.906
B41: 0.5 | G41: 0.5 | H41: 15.2088 | I41: 16.0801 | J41: 15.6217
B42: 0.6 | G42: 0.6 | H42: 13.1983 | I42: 15.3318 | J42: 14.1921
B43: 0.7 | G43: 0.7 | H43: 12.6546 | I43: 16.3617 | J43: 14.301
B44: 0.8 | G44: 0.8
B45: 0.9 | G45: 0.9
...

Sheet seed4_before
C2: 合流200m手前（後続全て） | H2: 合流200m手前（後続120） | K2: 分母v_max
B3: α | C3: vehicle0 | D3: vehicle1 | E3: all | G3: α | H3: vehicle0 | I3: vehicle1 | J3: all | K3: 10秒後
B4: 0 | G4: 0 | M4: 15.3153 | N4: 15.6675 | O4: 15.4833 | Q4: 15.3154 | R4: 15.6674 | S4: 15.4833
B5: 0.1 | C5: 15.3154 | D5: 15.6674 | E5: 15.4833 | G5: 0.1 | H5: 15.3154 | I5: 15.6674 | J5: 15.4833 | M5: 15.3153 | N5: 15.6675 | O5: 15.4833 | Q5: 15.3154 | R5: 15.6674 | S5: 15.4833
B6: 0.2 | C6: 15.3154 | D6: 15.6674 | E6: 15.4833 | G6: 0.2 | H6: 15.3154 | I6: 15.6674 | J6: 15.4833 | M6: 15.3153 | N6: 15.6675 | O6: 15.4833 | Q6: 15.3154 | R6: 15.6674 | S6: 15.4833
B7: 0.3 | C7: 14.8178 | D7: 15.0007 | E7: 14.906 | G7: 0.3 | H7: 14.7949 | I7: 14.9854 | J7: 14.8867 | M7: 14.8079 | N7: 14.9924 | O7: 14.8969 | Q7: 14.7949 | R7: 14.9854 | S7: 14.8867
B8: 0.4 | C8: 14.9597 | D8: 15.4615 | E8: 15.2017 | G8: 0.4 | H8: 14.8178 | I8: 15.0007 | J8: 14.906 | M8: 14.8177 | N8: 15.0007 | O8: 14.906 | Q8: 14.8178 | R8: 15.0007 | S8: 14.906
B9: 0.5 | C9: 14.9592 | D9: 15.6212 | E9: 15.2784 | G9: 0.5 | M9: 14.8593 | N9: 15.6086 | O9: 15.2206 | Q9: 15.2088 | R9: 16.0801 | S9: 15.6217
B10: 0.6 | C10: 14.97 | D10: 15.7224 | E10: 15.3324 | G10: 0.6 | M10: 14.9699 | N10: 15.7224 | O10: 15.3323 | Q10: 15.2088 | R10: 16.0801 | S10: 15.6217
B11: 0.7 | C11: 13.6636 | D11: 16.3272 | E11: 14.8652 | G11: 0.7 | M11: 13.6635 | N11: 16.3272 | O11: 14.8651 | Q11: 12.6582 | R11: 16.3834 | S11: 14.3126
B12: 0.8 | C12: 12.4409 | D12: 16.67 | E12: 14.2773 | G12: 0.8 | M12: 12.4408 | N12: 16.67 | O12: 14.2773 | Q12: 12.4409 | R12: 16.67 | S12: 14.2773
B13: 0.9 | G13: 0.9 | M13: 12.4408 | N13: 16.67 | O13: 14.2773 | Q13: 12.4409 | R13: 16.67 | S13: 14.2773
B14: 1 | G14: 1 | M14: 12.4408 | N14: 16.67 | O14: 14.2773 | Q14: 12.4409 | R14: 16.67 | S14: 14.2773
E16: (excel8) | J16: (excel9)
C18: 合流200m手前（後続全て） | H18: 合流200m手前（後続120） | K18: 分母v_max
B19: α | C19: vehicle0 | D19: vehicle1 | E19: all | G19: α | H19: vehicle0 | I19: vehicle1 | J19: all | K19: 3秒後
B20: 0 | G20: 0
B21: 0.1 | G21: 0.1
B22: 0.2 | G22: 0.2
B23: 0.3 | G23: 0.3
B24: 0.4 | G24: 0.4
B25: 0.5 | G25: 0.5
B26: 0.6 | G26: 0.6
B27: 0.7 | G27: 0.7
B28: 0.8 | G28: 0.8
B29: 0.9 | G29: 0.9
B30: 1 | G30: 1
C34: 合流200m手前（後続全て） | H34: 合流200m手前（後続120） | K34: 分母v_DT
B35: α | C35: vehicle0 | D35: vehicle1 | E35: all | G35: α | H35: vehicle0 | I35: vehicle1 | J35: all | K35: 10秒後
B36: 0 | G36: 0
B37: 0.1 | G37: 0.1
B38: 0.2 | G38: 0.2
B39: 0.3 | G39: 0.3
B40: 0.4 | G40: 0.4
B41: 0.5 | G41: 0.5
B42: 0.6 | G42: 0.6
B43: 0.7 | G43: 0.7
B44: 0.8 | G44: 0.8
B45: 0.9 | G45: 0.9
B46: 1 | G46: 1
...

Sheet seed4_30s
C2: 合流200m手前（後続全て） | H2: 合流200m手前（後続120） | K2: 分母v_max
B3: α | C3: vehicle0 | D3: vehicle1 | E3: all | G3: α | H3: vehicle0 | I3: vehicle1 | J3: all | K3: 10秒後
B4: 0 | G4: 0
B5: 0.1 | C5: 14.7572 | D5: 15.0203 | E5: 14.8822 | G5: 0.1
B6: 0.2 | C6: 14.7572 | D6: 15.0203 | E6: 14.8822 | G6: 0.2
B7: 0.3 | C7: 13.8965 | D7: 13.8982 | E7: 13.8973 | G7: 0.3
B8: 0.4 | C8: 14.1399 | D8: 14.6834 | E8: 14.4028 | G8: 0.4
B9: 0.5 | C9: 14.9592 | D9: 15.6212 | E9: 15.2784 | G9: 0.5
B10: 0.6 | C10: 14.1574 | D10: 15.1257 | E10: 14.625 | G10: 0.6
B11: 0.7 | C11: 12.7154 | D11: 16.0713 | E11: 14.1677 | G11: 0.7
B12: 0.8 | C12: 10.8577 | D12: 16.67 | E12: 13.2136 | G12: 0.8
B13: 0.9 | G13: 0.9
B14: 1 | G14: 1
D16: hpc | E16: (excel8) | J16: (excel9)
C18: 合流200m手前（後続全て） | H18: 合流200m手前（後続120） | K18: 分母v_max
B19: α | C19: vehicle0 | D19: vehicle1 | E19: all | G19: α | H19: vehicle0 | I19: vehicle1 | J19: all | K19: 3秒後
B20: 0 | G20: 0
B21: 0.1 | G21: 0.1
B22: 0.2 | G22: 0.2
B23: 0.3 | G23: 0.3
B24: 0.4 | G24: 0.4
B25: 0.5 | G25: 0.5
B26: 0.6 | G26: 0.6
B27: 0.7 | G27: 0.7
B28: 0.8 | G28: 0.8
B29: 0.9 | G29: 0.9
B30: 1 | G30: 1
C34: 合流200m手前（後続全て） | H34: 合流200m手前（後続120） | K34: 分母v_DT
B35: α | C35: vehicle0 | D35: vehicle1 | E35: all | G35: α | H35: vehicle0 | I35: vehicle1 | J35: all | K35: 10秒後
B36: 0 | G36: 0
B37: 0.1 | G37: 0.1
B38: 0.2 | G38: 0.2
B39: 0.3 | G39: 0.3
B40: 0.4 | G40: 0.4
B41: 0.5 | G41: 0.5
B42: 0.6 | G42: 0.6
B43: 0.7 | G43: 0.7
B44: 0.8 | G44: 0.8
B45: 0.9 | G45: 0.9
B46: 1 | G46: 1
...

Sheet seed5
C2: 合流200m手前（後続全て） | H2: 合流200m手前（後続120） | K2: 分母v_max
B3: α | C3: vehicle0 | D3: vehicle1 | E3: all | G3: α | H3: vehicle0 | I3: vehicle1 | J3: all | K3: 10秒後
B4: 0 | G4: 0
B5: 0.1 | G5: 0.1
B6: 0.2 | G6: 0.2
B7: 0.3 | G7: 0.3
B8: 0.4 | G8: 0.4
B9: 0.5 | G9: 0.5 | H9: 14.9308 | I9: 15.9299 | J9: 15.3924
B10: 0.6 | G10: 0.6 | H10: 14.2959 | I10: 16.2563 | J10: 15.1854
B11: 0.7 | G11: 0.7 | H11: 14.5214 | I11: 16.0164 | J11: 15.1998
B12: 0.8 | G12: 0.8
B13: 0.9 | G13: 0.9
B14: 1 | G14: 1
G15: 0.55 | H15: 14.2959 | I15: 16.2563 | J15: 15.1854
D16: excel16
C18: 合流200m手前（後続全て） | H18: 合流200m手前（後続120） | K18: 分母v_max
B19: α | C19: vehicle0 | D19: vehicle1 | E19: all | G19: α | H19: vehicle0 | I19: vehicle1 | J19: all | K19: 3秒後
B20: 0 | G20: 0
B21: 0.1 | G21: 0.1
B22: 0.2 | G22: 0.2
B23: 0.3 | G23: 0.3
B24: 0.4 | G24: 0.4
B25: 0.5 | G25: 0.5
B26: 0.6 | G26: 0.6
B27: 0.7 | G27: 0.7
B28: 0.8 | G28: 0.8
B29: 0.9 | G29: 0.9
B30: 1 | G30: 1
C34: 合流200m手前（後続全て） | H34: 合流200m手前（後続120） | K34: 分母v_DT
B35: α | C35: vehicle0 | D35: vehicle1 | E35: all | G35: α | H35: vehicle0 | I35: vehicle1 | J35: all | K35: 10秒後
B36: 0 | G36: 0
B37: 0.1 | G37: 0.1
B38: 0.2 | G38: 0.2
B39: 0.3 | G39: 0.3
B40: 0.4 | G40: 0.4
B41: 0.5 | G41: 0.5 | H41: 14.9297 | I41: 15.8701 | J41: 15.3642
B42: 0.6 | G42: 0.6 | H42: 14.5634 | I42: 15.751 | J42: 15.1022
B43: 0.7 | G43: 0.7 | H43: 14.5214 | I43: 16.0164 | J43: 15.1998
B44: 0.8 | G44: 0.8
B45: 0.9 | G45: 0.9
...

Sheet average1-5
C2: 合流200m手前（後続全て） | H2: 合流200m手前（後続120） | K2: 分母v_max
B3: α | C3: vehicle0 | D3: vehicle1 | E3: all | G3: α | H3: vehicle0 | I3: vehicle1 | J3: all | K3: 10秒後
B4: 0 | G4: 0
B5: 0.1 | G5: 0.1
B6: 0.2 | G6: 0.2
B7: 0.3 | G7: 0.3
B8: 0.4 | G8: 0.4
B9: 0.5 | G9: 0.5 | H9: =ROUND(AVERAGE(seed1!H9,seed2!H9,seed3!H9,seed4!H9,seed5!H9),4) -> 14.7085 | I9: =ROUND(AVERAGE(seed1!I9,seed2!I9,seed3!I9,seed4!I9,seed5!I9),4) -> 15.9956 | J9: =ROUND(AVERAGE(seed1!J9,seed2!J9,seed3!J9,seed4!J9,seed5!J9),4) -> 15.3337
B10: 0.6 | G10: 0.6 | H10: =ROUND(AVERAGE(seed1!H10,seed2!H10,seed3!H10,seed4!H10,seed5!H10),4) -> 14.0912 | I10: =ROUND(AVERAGE(seed1!I10,seed2!I10,seed3!I10,seed4!I10,seed5!I10),4) -> 16.3698 | J10: =ROUND(AVERAGE(seed1!J10,seed2!J10,seed3!J10,seed4!J10,seed5!J10),4) -> 15.1606
B11: 0.7 | G11: 0.7 | H11: =ROUND(AVERAGE(seed1!H11,seed2!H11,seed3!H11,seed4!H11,seed5!H11),4) -> 13.678 | I11: =ROUND(AVERAGE(seed1!I11,seed2!I11,seed3!I11,seed4!I11,seed5!I11),4) -> 16.4402 | J11: =ROUND(AVERAGE(seed1!J11,seed2!J11,seed3!J11,seed4!J11,seed5!J11),4) -> 14.9559
B12: 0.8 | G12: 0.8
B13: 0.9 | G13: 0.9
B14: 1 | G14: 1
G15: 0.55 | H15: =ROUND(AVERAGE(seed1!H15,seed2!H15,seed3!H15,seed4!H15,seed5!H15),4) -> 14.066 | I15: =ROUND(AVERAGE(seed1!I15,seed2!I15,seed3!I15,seed4!I15,seed5!I15),4) -> 15.906 | J15: =ROUND(AVERAGE(seed1!J15,seed2!J15,seed3!J15,seed4!J15,seed5!J15),4) -> 14.9236
I16: excel9
C18: 合流200m手前（後続全て） | H18: 合流200m手前（後続120） | K18: 分母v_max
B19: α | C19: vehicle0 | D19: vehicle1 | E19: all | G19: α | H19: vehicle0 | I19: vehicle1 | J19: all | K19: 3秒後
B20: 0 | G20: 0
B21: 0.1 | G21: 0.1
B22: 0.2 | G22: 0.2
B23: 0.3 | G23: 0.3
B24: 0.4 | G24: 0.4
B25: 0.5 | G25: 0.5
B26: 0.6 | G26: 0.6
B27: 0.7 | G27: 0.7
B28: 0.8 | G28: 0.8
B29: 0.9 | G29: 0.9
B30: 1 | G30: 1
C34: 合流200m手前（後続全て） | H34: 合流200m手前（後続120） | K34: 分母v_DT
B35: α | C35: vehicle0 | D35: vehicle1 | E35: all | G35: α | H35: vehicle0 | I35: vehicle1 | J35: all | K35: 10秒後
B36: 0 | G36: 0
B37: 0.1 | G37: 0.1
B38: 0.2 | G38: 0.2
B39: 0.3 | G39: 0.3
B40: 0.4 | G40: 0.4 | H40: =ROUND(AVERAGE(seed1!H40,seed2!H40,seed3!H40,seed4!H40,seed5!H40),4) -> 15.1864 | I40: =ROUND(AVERAGE(seed1!I40,seed2!I40,seed3!I40,seed4!I40,seed5!I40),4) -> 14.9869 | J40: =ROUND(AVERAGE(seed1!J40,seed2!J40,seed3!J40,seed4!J40,seed5!J40),4) -> 15.0874
B41: 0.5 | G41: 0.5 | H41: =ROUND(AVERAGE(seed1!H41,seed2!H41,seed3!H41,seed4!H41,seed5!H41),4) -> 14.907 | I41: =ROUND(AVERAGE(seed1!I41,seed2!I41,seed3!I41,seed4!I41,seed5!I41),4) -> 15.7459 | J41: =ROUND(AVERAGE(seed1!J41,seed2!J41,seed3!J41,seed4!J41,seed5!J41),4) -> 15.3109
B42: 0.6 | G42: 0.6 | H42: =ROUND(AVERAGE(seed1!H42,seed2!H42,seed3!H42,seed4!H42,seed5!H42),4) -> 14.1067 | I42: =ROUND(AVERAGE(seed1!I42,seed2!I42,seed3!I42,seed4!I42,seed5!I42),4) -> 16.067 | J42: =ROUND(AVERAGE(seed1!J42,seed2!J42,seed3!J42,seed4!J42,seed5!J42),4) -> 15.0377
B43: 0.7 | G43: 0.7 | H43: =ROUND(AVERAGE(seed1!H43,seed2!H43,seed3!H43,seed4!H43,seed5!H43),4) -> 13.7045 | I43: =ROUND(AVERAGE(seed1!I43,seed2!I43,seed3!I43,seed4!I43,seed5!I43),4) -> 16.4027 | J43: =ROUND(AVERAGE(seed1!J43,seed2!J43,seed3!J43,seed4!J43,seed5!J43),4) -> 14.9555
B44: 0.8 | G44: 0.8
B45: 0.9 | G45: 0.9
...

Sheet seed7
C2: 合流200m手前（後続全て） | H2: 合流200m手前（後続120） | K2: 分母v_max
B3: α | C3: vehicle0 | D3: vehicle1 | E3: all | G3: α | H3: vehicle0 | I3: vehicle1 | J3: all | K3: 10秒後
B4: 0 | C4: 13.6087 | D4: 13.573 | E4: 13.5901 | G4: 0 | H4: 13.6087 | I4: 13.573 | J4: 13.5901
B5: 0.1 | C5: 13.6087 | D5: 13.573 | E5: 13.5901 | G5: 0.1 | H5: 13.6087 | I5: 13.573 | J5: 13.5901
B6: 0.2 | C6: 13.6087 | D6: 13.573 | E6: 13.5901 | G6: 0.2 | H6: 13.6087 | I6: 13.573 | J6: 13.5901
B7: 0.3 | C7: 13.6087 | D7: 13.573 | E7: 13.5901 | G7: 0.3 | H7: 13.3917 | I7: 11.1717 | J7: 12.1778
B8: 0.4 | C8: 12.8835 | D8: 14.7014 | E8: 13.7529 | G8: 0.4 | H8: 12.7658 | I8: 15.5733 | J8: 14.094
B9: 0.5 | C9: 12.7537 | D9: 15.5823 | E9: 14.0919 | G9: 0.5 | H9: 13.971 | I9: 15.2024 | J9: 14.5588
B10: 0.6 | C10: 12.7275 | D10: 15.6912 | E10: 14.129 | G10: 0.6 | H10: 10.9411 | I10: 14.1225 | J10: 12.4676
B11: 0.7 | C11: 10.322 | D11: 16.3707 | E11: 12.9557 | G11: 0.7 | H11: 10.9808 | I11: 15.8863 | J11: 13.1299
B12: 0.8 | C12: 10.1142 | D12: 16.4953 | E12: 12.8833 | G12: 0.8 | H12: 10.6015 | I12: 16.4754 | J12: 13.1749
B13: 0.9 | C13: 9.87834 | D13: 16.67 | E13: 12.8256 | G13: 0.9 | H13: 9.884 | I13: 16.6648 | J13: 12.8266
B14: 1 | C14: 9.87834 | D14: 16.67 | E14: 12.8256 | G14: 1 | H14: 9.8783 | I14: 16.67 | J14: 12.8256
D16: excel8 | I16: excel9
C18: 合流200m手前（後続全て） | H18: 合流200m手前（後続120） | K18: 分母v_max
B19: α | C19: vehicle0 | D19: vehicle1 | E19: all | G19: α | H19: vehicle0 | I19: vehicle1 | J19: all | K19: 3秒後
B20: 0 | G20: 0
B21: 0.1 | G21: 0.1
B22: 0.2 | G22: 0.2
B23: 0.3 | G23: 0.3
B24: 0.4 | G24: 0.4
B25: 0.5 | G25: 0.5
B26: 0.6 | G26: 0.6
B27: 0.7 | G27: 0.7
B28: 0.8 | G28: 0.8
B29: 0.9 | G29: 0.9
B30: 1 | G30: 1
C34: 合流200m手前（後続全て） | H34: 合流200m手前（後続120） | K34: 分母v_DT
B35: α | C35: vehicle0 | D35: vehicle1 | E35: all | G35: α | H35: vehicle0 | I35: vehicle1 | J35: all | K35: 10秒後
B36: 0 | G36: 0
B37: 0.1 | G37: 0.1
B38: 0.2 | G38: 0.2
B39: 0.3 | G39: 0.3
B40: 0.4 | G40: 0.4
B41: 0.5 | G41: 0.5
B42: 0.6 | G42: 0.6
B43: 0.7 | G43: 0.7
B44: 0.8 | G44: 0.8
B45: 0.9 | G45: 0.9
B46: 1 | G46: 1
...

Sheet seed8
C2: 合流200m手前（後続全て） | H2: 合流200m手前（後続120） | K2: 分母v_max
B3: α | C3: vehicle0 | D3: vehicle1 | E3: all | G3: α | H3: vehicle0 | I3: vehicle1 | J3: all | K3: 10秒後
B4: 0 | C4: 15.5361 | D4: 15.7677 | E4: 15.6527 | G4: 0 | H4: 15.5361 | I4: 15.7677 | J4: 15.6527
B5: 0.1 | C5: 15.5361 | D5: 15.7677 | E5: 15.6527 | G5: 0.1 | H5: 15.5361 | I5: 15.7677 | J5: 15.6527
B6: 0.2 | C6: 14.9596 | D6: 15.5626 | E6: 15.2611 | G6: 0.2 | H6: 14.08 | I6: 16.5503 | J6: 15.2653
B7: 0.3 | C7: 14.6901 | D7: 14.854 | E7: 14.7736 | G7: 0.3 | H7: 14.0982 | I7: 16.1841 | J7: 15.0999
B8: 0.4 | C8: 15.6472 | D8: 16.2887 | E8: 15.9661 | G8: 0.4 | H8: 15.6473 | I8: 16.2887 | J8: 15.9661
B9: 0.5 | C9: 15.6472 | D9: 16.2887 | E9: 15.9661 | G9: 0.5 | H9: 15.6473 | I9: 16.2887 | J9: 15.9661
B10: 0.6 | C10: 15.6472 | D10: 16.2887 | E10: 15.9661 | G10: 0.6 | H10: 15.5735 | I10: 16.3182 | J10: 15.9437
B11: 0.7 | C11: 12.9957 | D11: 16.67 | E11: 14.7034 | G11: 0.7 | H11: 15.2115 | I11: 16.5192 | J11: 15.8563
B12: 0.8 | C12: 12.9957 | D12: 16.67 | E12: 14.7034 | G12: 0.8 | H12: 12.9353 | I12: 16.669 | J12: 14.6662
B13: 0.9 | C13: 12.9533 | D13: 16.666 | E13: 14.6766 | G13: 0.9 | H13: 13.0008 | I13: 16.67 | J13: 14.7059
B14: 1 | C14: 13.0007 | D14: 16.67 | E14: 14.7058 | G14: 1 | H14: 13.0008 | I14: 16.67 | J14: 14.7059
D16: excel8 | I16: excel9
C18: 合流200m手前（後続全て） | H18: 合流200m手前（後続120） | K18: 分母v_max
B19: α | C19: vehicle0 | D19: vehicle1 | E19: all | G19: α | H19: vehicle0 | I19: vehicle1 | J19: all | K19: 3秒後
B20: 0 | G20: 0
B21: 0.1 | G21: 0.1
B22: 0.2 | G22: 0.2
B23: 0.3 | G23: 0.3
B24: 0.4 | G24: 0.4
B25: 0.5 | G25: 0.5
B26: 0.6 | G26: 0.6
B27: 0.7 | G27: 0.7
B28: 0.8 | G28: 0.8
B29: 0.9 | G29: 0.9
B30: 1 | G30: 1
C34: 合流200m手前（後続全て） | H34: 合流200m手前（後続120） | K34: 分母v_DT
B35: α | C35: vehicle0 | D35: vehicle1 | E35: all | G35: α | H35: vehicle0 | I35: vehicle1 | J35: all | K35: 10秒後
B36: 0 | G36: 0
B37: 0.1 | G37: 0.1
B38: 0.2 | G38: 0.2
B39: 0.3 | G39: 0.3
B40: 0.4 | G40: 0.4
B41: 0.5 | G41: 0.5
B42: 0.6 | G42: 0.6
B43: 0.7 | G43: 0.7
B44: 0.8 | G44: 0.8
B45: 0.9 | G45: 0.9
B46: 1 | G46: 1
...

Sheet seed9
C2: 合流200m手前（後続全て） | H2: 合流200m手前（後続120） | K2: 分母v_max
B3: α | C3: vehicle0 | D3: vehicle1 | E3: all | G3: α | H3: vehicle0 | I3: vehicle1 | J3: all | K3: 10秒後
B4: 0 | C4: 14.6021 | D4: 13.301 | E4: 13.9709 | G4: 0 | H4: 14.6022 | I4: 13.301 | J4: 13.9709
B5: 0.1 | C5: 14.6021 | D5: 13.301 | E5: 13.9709 | G5: 0.1 | H5: 14.5794 | I5: 13.3638 | J5: 13.9897
B6: 0.2 | C6: 14.51 | D6: 13.3539 | E6: 13.9498 | G6: 0.2 | H6: 14.5101 | I6: 13.3538 | J6: 13.9498
B7: 0.3 | C7: 15.2058 | D7: 14.8733 | E7: 15.0465 | G7: 0.3 | H7: 15.2059 | I7: 14.8733 | J7: 15.0466
B8: 0.4 | C8: 15.1825 | D8: 14.9359 | E8: 15.0643 | G8: 0.4 | H8: 14.2486 | I8: 13.0437 | J8: 13.6775
B9: 0.5 | C9: 14.3581 | D9: 14.9521 | E9: 14.6397 | G9: 0.5 | H9: 14.3503 | I9: 14.9536 | J9: 14.6363
B10: 0.6 | C10: 14.4578 | D10: 15.8551 | E10: 15.1049 | G10: 0.6 | H10: 14.4578 | I10: 15.8551 | J10: 15.1049
B11: 0.7 | C11: 13.2739 | D11: 16.2717 | E11: 14.5907 | G11: 0.7 | H11: 13.2265 | I11: 16.4446 | J11: 14.6436
B12: 0.8 | C12: 12.7865 | D12: 16.561 | E12: 14.4248 | G12: 0.8 | H12: 11.703 | I12: 16.6448 | J12: 13.7612
B13: 0.9 | C13: 12.0417 | D13: 16.67 | E13: 13.9693 | G13: 0.9 | H13: 12.0417 | I13: 16.67 | J13: 13.9693
B14: 1 | C14: 12.0417 | D14: 16.67 | E14: 13.9693 | G14: 1 | H14: 12.0417 | I14: 16.67 | J14: 13.9693
D16: excel8 | I16: excel9
C18: 合流200m手前（後続全て） | H18: 合流200m手前（後続120） | K18: 分母v_max
B19: α | C19: vehicle0 | D19: vehicle1 | E19: all | G19: α | H19: vehicle0 | I19: vehicle1 | J19: all | K19: 3秒後
B20: 0 | G20: 0
B21: 0.1 | G21: 0.1
B22: 0.2 | G22: 0.2
B23: 0.3 | G23: 0.3
B24: 0.4 | G24: 0.4
B25: 0.5 | G25: 0.5
B26: 0.6 | G26: 0.6
B27: 0.7 | G27: 0.7
B28: 0.8 | G28: 0.8
B29: 0.9 | G29: 0.9
B30: 1 | G30: 1
C34: 合流200m手前（後続全て） | H34: 合流200m手前（後続120） | K34: 分母v_DT
B35: α | C35: vehicle0 | D35: vehicle1 | E35: all | G35: α | H35: vehicle0 | I35: vehicle1 | J35: all | K35: 10秒後
B36: 0 | G36: 0
B37: 0.1 | G37: 0.1
B38: 0.2 | G38: 0.2
B39: 0.3 | G39: 0.3
B40: 0.4 | G40: 0.4
B41: 0.5 | G41: 0.5
B42: 0.6 | G42: 0.6
B43: 0.7 | G43: 0.7
B44: 0.8 | G44: 0.8
B45: 0.9 | G45: 0.9
B46: 1 | G46: 1
...

Sheet seed10
C2: 合流200m手前（後続全て） | H2: 合流200m手前（後続120） | K2: 分母v_max
B3: α | C3: vehicle0 | D3: vehicle1 | E3: all | G3: α | H3: vehicle0 | I3: vehicle1 | J3: all | K3: 10秒後
B4: 0 | C4: 11.9406 | D4: 11.9671 | E4: 11.9531 | G4: 0 | H4: 11.9406 | I4: 11.9671 | J4: 11.9531
B5: 0.1 | C5: 11.9406 | D5: 11.9671 | E5: 11.9531 | G5: 0.1 | H5: 11.9406 | I5: 11.9671 | J5: 11.9531
B6: 0.2 | C6: 11.9406 | D6: 11.9671 | E6: 11.9531 | G6: 0.2 | H6: 10.0883 | I6: 12.318 | J6: 11.0751
B7: 0.3 | C7: 11.9406 | D7: 11.9671 | E7: 11.9531 | G7: 0.3 | H7: 13.0838 | I7: 13.0825 | J7: 13.0832
B8: 0.4 | C8: 12.0659 | D8: 12.6706 | E8: 12.3475 | G8: 0.4 | H8: 13.2731 | I8: 13.4602 | J8: 13.3605
B9: 0.5 | C9: 12.9608 | D9: 14.2486 | E9: 13.5621 | G9: 0.5 | H9: 12.9609 | I9: 14.2486 | J9: 13.5621
B10: 0.6 | C10: 11.566 | D10: 13.5323 | E10: 12.466 | G10: 0.6 | H10: 12.9475 | I10: 14.2468 | J10: 13.5542
B11: 0.7 | C11: 12.3569 | D11: 16.3762 | E11: 14.0906 | G11: 0.7 | H11: 12.357 | I11: 16.3762 | J11: 14.0906
B12: 0.8 | C12: 10.1492 | D12: 16.6248 | E12: 12.7464 | G12: 0.8 | H12: 10.1493 | I12: 16.6248 | J12: 12.7464
B13: 0.9 | C13: 10.1371 | D13: 16.6695 | E13: 12.757 | G13: 0.9 | H13: 10.134 | I13: 16.67 | J13: 12.7557
B14: 1 | C14: 10.134 | D14: 16.67 | E14: 12.7557 | G14: 1 | H14: 10.134 | I14: 16.67 | J14: 12.7557
D16: excel8 | I16: excel9
C18: 合流200m手前（後続全て） | H18: 合流200m手前（後続120） | K18: 分母v_max
B19: α | C19: vehicle0 | D19: vehicle1 | E19: all | G19: α | H19: vehicle0 | I19: vehicle1 | J19: all | K19: 3秒後
B20: 0 | G20: 0
B21: 0.1 | G21: 0.1
B22: 0.2 | G22: 0.2
B23: 0.3 | G23: 0.3
B24: 0.4 | G24: 0.4
B25: 0.5 | G25: 0.5
B26: 0.6 | G26: 0.6
B27: 0.7 | G27: 0.7
B28: 0.8 | G28: 0.8
B29: 0.9 | G29: 0.9
B30: 1 | G30: 1
C34: 合流200m手前（後続全て） | H34: 合流200m手前（後続120） | K34: 分母v_DT
B35: α | C35: vehicle0 | D35: vehicle1 | E35: all | G35: α | H35: vehicle0 | I35: vehicle1 | J35: all | K35: 10秒後
B36: 0 | G36: 0
B37: 0.1 | G37: 0.1
B38: 0.2 | G38: 0.2
B39: 0.3 | G39: 0.3
B40: 0.4 | G40: 0.4
B41: 0.5 | G41: 0.5
B42: 0.6 | G42: 0.6
B43: 0.7 | G43: 0.7
B44: 0.8 | G44: 0.8
B45: 0.9 | G45: 0.9
B46: 1 | G46: 1
...

Sheet average1-10
C2: 合流200m手前（後続全て） | H2: 合流200m手前（後続120） | K2: 分母v_max
B3: α | C3: vehicle0 | D3: vehicle1 | E3: all | G3: α | H3: vehicle0 | I3: vehicle1 | J3: all | K3: 10秒後
B4: 0 | G4: 0
B5: 0.1 | G5: 0.1
B6: 0.2 | G6: 0.2
B7: 0.3 | G7: 0.3
B8: 0.4 | G8: 0.4
B9: 0.5 | G9: 0.5
B10: 0.6 | G10: 0.6
B11: 0.7 | G11: 0.7
B12: 0.8 | G12: 0.8
B13: 0.9 | G13: 0.9
B14: 1 | G14: 1
D16: excel8 | I16: excel9
C18: 合流200m手前（後続全て） | H18: 合流200m手前（後続120） | K18: 分母v_max
B19: α | C19: vehicle0 | D19: vehicle1 | E19: all | G19: α | H19: vehicle0 | I19: vehicle1 | J19: all | K19: 3秒後
B20: 0 | G20: 0
B21: 0.1 | G21: 0.1
B22: 0.2 | G22: 0.2
B23: 0.3 | G23: 0.3
B24: 0.4 | G24: 0.4
B25: 0.5 | G25: 0.5
B26: 0.6 | G26: 0.6
B27: 0.7 | G27: 0.7
B28: 0.8 | G28: 0.8
B29: 0.9 | G29: 0.9
B30: 1 | G30: 1
C34: 合流200m手前（後続全て） | H34: 合流200m手前（後続120） | K34: 分母v_DT
B35: α | C35: vehicle0 | D35: vehicle1 | E35: all | G35: α | H35: vehicle0 | I35: vehicle1 | J35: all | K35: 10秒後
B36: 0 | G36: 0
B37: 0.1 | G37: 0.1
B38: 0.2 | G38: 0.2
B39: 0.3 | G39: 0.3
B40: 0.4 | G40: 0.4
B41: 0.5 | G41: 0.5
B42: 0.6 | G42: 0.6
B43: 0.7 | G43: 0.7
B44: 0.8 | G44: 0.8
B45: 0.9 | G45: 0.9
B46: 1 | G46: 1
...

Sheet seed11
C2: 合流200m手前（後続全て） | H2: 合流200m手前（後続120） | K2: 分母v_max
B3: α | C3: vehicle0 | D3: vehicle1 | E3: all | G3: α | H3: vehicle0 | I3: vehicle1 | J3: all | K3: 10秒後
B4: 0 | C4: 14.9702 | D4: 14.926 | E4: 14.9482 | G4: 0 | H4: 14.9702 | I4: 14.926 | J4: 14.9482
B5: 0.1 | C5: 14.9702 | D5: 14.926 | E5: 14.9482 | G5: 0.1 | H5: 14.9702 | I5: 14.926 | J5: 14.9482
B6: 0.2 | C6: 14.9702 | D6: 14.926 | E6: 14.9482 | G6: 0.2 | H6: 14.9666 | I6: 14.9824 | J6: 14.9745
B7: 0.3 | C7: 14.9531 | D7: 15.0205 | E7: 14.9868 | G7: 0.3 | H7: 14.9531 | I7: 15.0205 | J7: 14.9868
B8: 0.4 | C8: 14.9531 | D8: 15.0205 | E8: 14.9868 | G8: 0.4 | H8: 14.9336 | I8: 15.0333 | J8: 14.9834
B9: 0.5 | C9: 14.7881 | D9: 15.7739 | E9: 15.2802 | G9: 0.5 | H9: 14.7881 | I9: 15.7739 | J9: 15.2802
B10: 0.6 | C10: 15.0424 | D10: 15.8653 | E10: 15.4534 | G10: 0.6 | H10: 15.1361 | I10: 15.7582 | J10: 15.4468
B11: 0.7 | C11: 14.6558 | D11: 16.3675 | E11: 15.5077 | G11: 0.7 | H11: 11.3261 | I11: 16.5774 | J11: 13.7191
B12: 0.8 | C12: 11.3913 | D12: 16.5926 | E12: 13.7615 | G12: 0.8 | H12: 11.3913 | I12: 16.5926 | J12: 13.7615
B13: 0.9 | C13: 11.2703 | D13: 16.67 | E13: 13.7309 | G13: 0.9 | H13: 11.2703 | I13: 16.67 | J13: 13.7309
B14: 1 | C14: 11.2703 | D14: 16.67 | E14: 13.7309 | G14: 1 | H14: 11.2703 | I14: 16.67 | J14: 13.7309
D16: excel8 | I16: excel9
C18: 合流200m手前（後続全て） | H18: 合流200m手前（後続120） | K18: 分母v_max
B19: α | C19: vehicle0 | D19: vehicle1 | E19: all | G19: α | H19: vehicle0 | I19: vehicle1 | J19: all | K19: 3秒後
B20: 0 | G20: 0
B21: 0.1 | G21: 0.1
B22: 0.2 | G22: 0.2
B23: 0.3 | G23: 0.3
B24: 0.4 | G24: 0.4
B25: 0.5 | G25: 0.5
B26: 0.6 | G26: 0.6
B27: 0.7 | G27: 0.7
B28: 0.8 | G28: 0.8
B29: 0.9 | G29: 0.9
B30: 1 | G30: 1
C34: 合流200m手前（後続全て） | H34: 合流200m手前（後続120） | K34: 分母v_DT
B35: α | C35: vehicle0 | D35: vehicle1 | E35: all | G35: α | H35: vehicle0 | I35: vehicle1 | J35: all | K35: 10秒後
B36: 0 | G36: 0
B37: 0.1 | G37: 0.1
B38: 0.2 | G38: 0.2
B39: 0.3 | G39: 0.3
B40: 0.4 | G40: 0.4
B41: 0.5 | G41: 0.5
B42: 0.6 | G42: 0.6
B43: 0.7 | G43: 0.7
B44: 0.8 | G44: 0.8
B45: 0.9 | G45: 0.9
B46: 1 | G46: 1
...

Sheet seed12
C2: 合流200m手前（後続全て） | H2: 合流200m手前（後続120） | K2: 分母v_max
B3: α | C3: vehicle0 | D3: vehicle1 | E3: all | G3: α | H3: vehicle0 | I3: vehicle1 | J3: all | K3: 10秒後
B4: 0 | C4: 12.9883 | D4: 12.8925 | E4: 12.9457 | G4: 0 | H4: 12.9883 | I4: 12.8924 | J4: 12.9457
B5: 0.1 | C5: 12.9883 | D5: 12.8925 | E5: 12.9457 | G5: 0.1 | H5: 12.9883 | I5: 12.8924 | J5: 12.9457
B6: 0.2 | C6: 12.9883 | D6: 12.8925 | E6: 12.9457 | G6: 0.2 | H6: 12.9965 | I6: 13.0063 | J6: 13.0009
B7: 0.3 | C7: 12.9823 | D7: 13.5993 | E7: 13.2599 | G7: 0.3 | H7: 13.4722 | I7: 13.4647 | J7: 13.4689
B8: 0.4 | C8: 12.6654 | D8: 14.7949 | E8: 13.6086 | G8: 0.4 | H8: 11.9146 | I8: 14.2103 | J8: 12.9217
B9: 0.5 | C9: 13.0663 | D9: 13.6723 | E9: 13.349 | G9: 0.5 | H9: 13.3701 | I9: 15.7243 | J9: 14.3962
B10: 0.6 | C10: 12.6621 | D10: 15.4548 | E10: 13.8765 | G10: 0.6 | H10: 12.8824 | I10: 15.4109 | J10: 13.9894
B11: 0.7 | C11: 11.9332 | D11: 15.7264 | E11: 13.5469 | G11: 0.7 | H11: 13.0472 | I11: 15.9915 | J11: 14.3203
B12: 0.8 | C12: 12.0619 | D12: 16.67 | E12: 13.9616 | G12: 0.8 | H12: 11.6837 | I12: 15.8081 | J12: 13.4383
B13: 0.9 | C13: 12.0619 | D13: 16.67 | E13: 13.9616 | G13: 0.9 | H13: 12.0619 | I13: 16.67 | J13: 13.9616
B14: 1 | C14: 12.0619 | D14: 16.67 | E14: 13.9616 | G14: 1 | H14: 12.0619 | I14: 16.67 | J14: 13.9616
D16: excel8 | I16: excel9
C18: 合流200m手前（後続全て） | H18: 合流200m手前（後続120） | K18: 分母v_max
B19: α | C19: vehicle0 | D19: vehicle1 | E19: all | G19: α | H19: vehicle0 | I19: vehicle1 | J19: all | K19: 3秒後
B20: 0 | G20: 0
B21: 0.1 | G21: 0.1
B22: 0.2 | G22: 0.2
B23: 0.3 | G23: 0.3
B24: 0.4 | G24: 0.4
B25: 0.5 | G25: 0.5
B26: 0.6 | G26: 0.6
B27: 0.7 | G27: 0.7
B28: 0.8 | G28: 0.8
B29: 0.9 | G29: 0.9
B30: 1 | G30: 1
C34: 合流200m手前（後続全て） | H34: 合流200m手前（後続120） | K34: 分母v_DT
B35: α | C35: vehicle0 | D35: vehicle1 | E35: all | G35: α | H35: vehicle0 | I35: vehicle1 | J35: all | K35: 10秒後
B36: 0 | G36: 0
B37: 0.1 | G37: 0.1
B38: 0.2 | G38: 0.2
B39: 0.3 | G39: 0.3
B40: 0.4 | G40: 0.4
B41: 0.5 | G41: 0.5
B42: 0.6 | G42: 0.6
B43: 0.7 | G43: 0.7
B44: 0.8 | G44: 0.8
B45: 0.9 | G45: 0.9
B46: 1 | G46: 1
...

Sheet seed13
C2: 合流200m手前（後続全て） | H2: 合流200m手前（後続120） | K2: 分母v_max
B3: α | C3: vehicle0 | D3: vehicle1 | E3: all | G3: α | H3: vehicle0 | I3: vehicle1 | J3: all | K3: 10秒後
B4: 0 | C4: 12.142 | D4: 12.4002 | E4: 12.2698 | G4: 0 | H4: 12.142 | I4: 12.4002 | J4: 12.2698
B5: 0.1 | C5: 12.142 | D5: 12.4002 | E5: 12.2698 | G5: 0.1 | H5: 12.142 | I5: 12.4002 | J5: 12.2698
B6: 0.2 | C6: 12.142 | D6: 12.4002 | E6: 12.2698 | G6: 0.2 | H6: 12.1406 | I6: 12.4055 | J6: 12.2717
B7: 0.3 | C7: 12.4434 | D7: 12.5875 | E7: 12.5147 | G7: 0.3 | H7: 12.1406 | I7: 12.4055 | J7: 12.2717
B8: 0.4 | C8: 12.4427 | D8: 12.5784 | E8: 12.5099 | G8: 0.4 | H8: 12.0684 | I8: 12.3956 | J8: 12.2297
B9: 0.5 | C9: 12.311 | D9: 13.3291 | E9: 12.8036 | G9: 0.5 | H9: 12.2864 | I9: 13.5039 | J9: 12.8666
B10: 0.6 | C10: 11.1708 | D10: 14.6151 | E10: 12.7054 | G10: 0.6 | H10: 11.0842 | I10: 15.4895 | J10: 12.9652
B11: 0.7 | C11: 12.0865 | D11: 15.9581 | E11: 13.748 | G11: 0.7 | H11: 10.851 | I11: 15.9836 | J11: 13.0139
B12: 0.8 | C12: 9.8757 | D12: 16.2927 | E12: 12.4271 | G12: 0.8 | H12: 9.9883 | I12: 16.3382 | J12: 12.513
B13: 0.9 | C13: 9.6273 | D13: 16.67 | E13: 12.3922 | G13: 0.9 | H13: 9.6273 | I13: 16.67 | J13: 12.3922
B14: 1 | C14: 9.6273 | D14: 16.67 | E14: 12.3922 | G14: 1 | H14: 9.6273 | I14: 16.67 | J14: 12.3922
D16: excel8 | I16: excel9
C18: 合流200m手前（後続全て） | H18: 合流200m手前（後続120） | K18: 分母v_max
B19: α | C19: vehicle0 | D19: vehicle1 | E19: all | G19: α | H19: vehicle0 | I19: vehicle1 | J19: all | K19: 3秒後
B20: 0 | G20: 0
B21: 0.1 | G21: 0.1
B22: 0.2 | G22: 0.2
B23: 0.3 | G23: 0.3
B24: 0.4 | G24: 0.4
B25: 0.5 | G25: 0.5
B26: 0.6 | G26: 0.6
B27: 0.7 | G27: 0.7
B28: 0.8 | G28: 0.8
B29: 0.9 | G29: 0.9
B30: 1 | G30: 1
C34: 合流200m手前（後続全て） | H34: 合流200m手前（後続120） | K34: 分母v_DT
B35: α | C35: vehicle0 | D35: vehicle1 | E35: all | G35: α | H35: vehicle0 | I35: vehicle1 | J35: all | K35: 10秒後
B36: 0 | G36: 0
B37: 0.1 | G37: 0.1
B38: 0.2 | G38: 0.2
B39: 0.3 | G39: 0.3
B40: 0.4 | G40: 0.4
B41: 0.5 | G41: 0.5
B42: 0.6 | G42: 0.6
B43: 0.7 | G43: 0.7
B44: 0.8 | G44: 0.8
B45: 0.9 | G45: 0.9
B46: 1 | G46: 1
...

Sheet seed14
C2: 合流200m手前（後続全て） | H2: 合流200m手前（後続120） | K2: 分母v_max
B3: α | C3: vehicle0 | D3: vehicle1 | E3: all | G3: α | H3: vehicle0 | I3: vehicle1 | J3: all | K3: 10秒後
B4: 0 | C4: 11.8174 | D4: 11.9574 | E4: 11.8868 | G4: 0 | H4: 11.8174 | I4: 11.9574 | J4: 11.8868
B5: 0.1 | C5: 11.8174 | D5: 11.9574 | E5: 11.8868 | G5: 0.1 | H5: 11.8174 | I5: 11.9574 | J5: 11.8868
B6: 0.2 | C6: 11.8174 | D6: 11.9574 | E6: 11.8868 | G6: 0.2 | H6: 11.8445 | I6: 12.0619 | J6: 11.9521
B7: 0.3 | C7: 11.8056 | D7: 12.2026 | E7: 12.0022 | G7: 0.3 | H7: 11.8428 | I7: 12.064 | J7: 11.9523
B8: 0.4 | C8: 11.5762 | D8: 12.1156 | E8: 11.8418 | G8: 0.4 | H8: 11.5248 | I8: 12.5174 | J8: 12.0163
B9: 0.5 | C9: 11.3517 | D9: 13.9652 | E9: 12.6082 | G9: 0.5 | H9: 11.0028 | I9: 15.6013 | J9: 13.0494
B10: 0.6 | C10: 11.3461 | D10: 13.9743 | E10: 12.6097 | G10: 0.6 | H10: 11.6116 | I10: 14.863 | J10: 13.1471
B11: 0.7 | C11: 11.9963 | D11: 16.0396 | E11: 13.8218 | G11: 0.7 | H11: 11.0149 | I11: 15.9019 | J11: 13.1858
B12: 0.8 | C12: 10.5352 | D12: 16.5975 | E12: 13.1686 | G12: 0.8 | H12: 10.5352 | I12: 16.5975 | J12: 13.1686
B13: 0.9 | C13: 10.2834 | D13: 16.67 | E13: 13.0124 | G13: 0.9 | H13: 10.2834 | I13: 16.67 | J13: 13.0124
B14: 1 | C14: 10.2834 | D14: 16.67 | E14: 13.0124 | G14: 1 | H14: 10.2834 | I14: 16.67 | J14: 13.0124
D16: excel8 | I16: excel9
C18: 合流200m手前（後続全て） | H18: 合流200m手前（後続120） | K18: 分母v_max
B19: α | C19: vehicle0 | D19: vehicle1 | E19: all | G19: α | H19: vehicle0 | I19: vehicle1 | J19: all | K19: 3秒後
B20: 0 | G20: 0
B21: 0.1 | G21: 0.1
B22: 0.2 | G22: 0.2
B23: 0.3 | G23: 0.3
B24: 0.4 | G24: 0.4
B25: 0.5 | G25: 0.5
B26: 0.6 | G26: 0.6
B27: 0.7 | G27: 0.7
B28: 0.8 | G28: 0.8
B29: 0.9 | G29: 0.9
B30: 1 | G30: 1
C34: 合流200m手前（後続全て） | H34: 合流200m手前（後続120） | K34: 分母v_DT
B35: α | C35: vehicle0 | D35: vehicle1 | E35: all | G35: α | H35: vehicle0 | I35: vehicle1 | J35: all | K35: 10秒後
B36: 0 | G36: 0
B37: 0.1 | G37: 0.1
B38: 0.2 | G38: 0.2
B39: 0.3 | G39: 0.3
B40: 0.4 | G40: 0.4
B41: 0.5 | G41: 0.5
B42: 0.6 | G42: 0.6
B43: 0.7 | G43: 0.7
B44: 0.8 | G44: 0.8
B45: 0.9 | G45: 0.9
B46: 1 | G46: 1
...

Sheet seed15
C2: 合流200m手前（後続全て） | H2: 合流200m手前（後続120） | K2: 分母v_max
B3: α | C3: vehicle0 | D3: vehicle1 | E3: all | G3: α | H3: vehicle0 | I3: vehicle1 | J3: all | K3: 10秒後
B4: 0 | C4: 11.0315 | D4: 13.6134 | E4: 12.287 | G4: 0 | H4: 11.0315 | I4: 13.6134 | J4: 12.287
B5: 0.1 | C5: 11.0315 | D5: 13.6134 | E5: 12.287 | G5: 0.1 | H5: 11.0315 | I5: 13.6134 | J5: 12.287
B6: 0.2 | C6: 11.0315 | D6: 13.6134 | E6: 12.287 | G6: 0.2 | H6: 11.0315 | I6: 13.6134 | J6: 12.287
B7: 0.3 | C7: 11.0315 | D7: 13.6134 | E7: 12.287 | G7: 0.3 | H7: 11.0315 | I7: 13.6134 | J7: 12.287
B8: 0.4 | C8: 11.0315 | D8: 13.6782 | E8: 12.317 | G8: 0.4 | H8: 11.3247 | I8: 14.374 | J8: 12.7691
B9: 0.5 | C9: 11.5214 | D9: 14.8616 | E9: 13.0875 | G9: 0.5 | H9: 11.2187 | I9: 15.1541 | J9: 13.0506
B10: 0.6 | C10: 11.2509 | D10: 14.8677 | E10: 12.9427 | G10: 0.6 | H10: 11.3018 | I10: 15.2821 | J10: 13.1546
B11: 0.7 | C11: 12.0284 | D11: 16.4263 | E11: 14.0622 | G11: 0.7 | H11: 12.1642 | I11: 16.1718 | J11: 14.0175
B12: 0.8 | C12: 11.1375 | D12: 16.6697 | E12: 13.6085 | G12: 0.8 | H12: 11.1374 | I12: 16.6697 | J12: 13.6085
B13: 0.9 | C13: 10.4423 | D13: 16.67 | E13: 13.2197 | G13: 0.9 | H13: 10.4423 | I13: 16.67 | J13: 13.2197
B14: 1 | C14: 10.4423 | D14: 16.67 | E14: 13.2197 | G14: 1 | H14: 10.4423 | I14: 16.67 | J14: 13.2197
D16: excel8 | I16: excel9
C18: 合流200m手前（後続全て） | H18: 合流200m手前（後続120） | K18: 分母v_max
B19: α | C19: vehicle0 | D19: vehicle1 | E19: all | G19: α | H19: vehicle0 | I19: vehicle1 | J19: all | K19: 3秒後
B20: 0 | G20: 0
B21: 0.1 | G21: 0.1
B22: 0.2 | G22: 0.2
B23: 0.3 | G23: 0.3
B24: 0.4 | G24: 0.4
B25: 0.5 | G25: 0.5
B26: 0.6 | G26: 0.6
B27: 0.7 | G27: 0.7
B28: 0.8 | G28: 0.8
B29: 0.9 | G29: 0.9
B30: 1 | G30: 1
C34: 合流200m手前（後続全て） | H34: 合流200m手前（後続120） | K34: 分母v_DT
B35: α | C35: vehicle0 | D35: vehicle1 | E35: all | G35: α | H35: vehicle0 | I35: vehicle1 | J35: all | K35: 10秒後
B36: 0 | G36: 0
B37: 0.1 | G37: 0.1
B38: 0.2 | G38: 0.2
B39: 0.3 | G39: 0.3
B40: 0.4 | G40: 0.4
B41: 0.5 | G41: 0.5
B42: 0.6 | G42: 0.6
B43: 0.7 | G43: 0.7
B44: 0.8 | G44: 0.8
B45: 0.9 | G45: 0.9
B46: 1 | G46: 1
...

Sheet average
C2: 合流200m手前（後続全て） | H2: 合流200m手前（後続120） | K2: 分母v_max
B3: α | C3: vehicle0 | D3: vehicle1 | E3: all | G3: α | H3: vehicle0 | I3: vehicle1 | J3: all | K3: 10秒後
B4: 0 | G4: 0
B5: 0.1 | G5: 0.1
B6: 0.2 | G6: 0.2
B7: 0.3 | G7: 0.3
B8: 0.4 | G8: 0.4
B9: 0.5 | G9: 0.5
B10: 0.6 | G10: 0.6
B11: 0.7 | G11: 0.7
B12: 0.8 | G12: 0.8
B13: 0.9 | G13: 0.9
B14: 1 | G14: 1
D16: excel8 | I16: excel9
C18: 合流200m手前（後続全て） | H18: 合流200m手前（後続120） | K18: 分母v_max
B19: α | C19: vehicle0 | D19: vehicle1 | E19: all | G19: α | H19: vehicle0 | I19: vehicle1 | J19: all | K19: 3秒後
B20: 0 | G20: 0
B21: 0.1 | G21: 0.1
B22: 0.2 | G22: 0.2
B23: 0.3 | G23: 0.3
B24: 0.4 | G24: 0.4
B25: 0.5 | G25: 0.5
B26: 0.6 | G26: 0.6
B27: 0.7 | G27: 0.7
B28: 0.8 | G28: 0.8
B29: 0.9 | G29: 0.9
B30: 1 | G30: 1
C34: 合流200m手前（後続全て） | H34: 合流200m手前（後続120） | K34: 分母v_DT
B35: α | C35: vehicle0 | D35: vehicle1 | E35: all | G35: α | H35: vehicle0 | I35: vehicle1 | J35: all | K35: 10秒後
B36: 0 | G36: 0
B37: 0.1 | G37: 0.1
B38: 0.2 | G38: 0.2
B39: 0.3 | G39: 0.3
B40: 0.4 | G40: 0.4
B41: 0.5 | G41: 0.5
B42: 0.6 | G42: 0.6
B43: 0.7 | G43: 0.7
B44: 0.8 | G44: 0.8
B45: 0.9 | G45: 0.9
B46: 1 | G46: 1
...
