Workbook

Sheet seed1
C2: 合流200m手前（元の関数） | F2: merge3 | I2: 合流200m手前（新しい関数） | L2: merge3
B3: α | C3: vehicle0 | D3: vehicle1 | E3: all | H3: α | I3: vehicle0 | J3: vehicle1 | K3: all
B4: 0 | H4: 0
B5: 0.1 | H5: 0.1
B6: 0.2 | H6: 0.2
B7: 0.3 | C7: 12.8628 | D7: 15.5196 | E7: 14.174 | H7: 0.3 | I7: 12.712 | J7: 14.012 | K7: 13.3699
B8: 0.4 | C8: 10.9029 | D8: 16.4189 | E8: 13.3687 | H8: 0.4 | I8: 12.6855 | J8: 14.1945 | K8: 13.45
B9: 0.5 | C9: 10.4246 | D9: 16.5828 | E9: 13.1308 | H9: 0.5 | I9: 12.6152 | J9: 15.2452 | K9: 13.8969
B10: 0.6 | C10: 10.4246 | D10: 16.5828 | E10: 13.1308 | H10: 0.6 | I10: 11.5732 | J10: 16.1176 | K10: 13.7052
B11: 0.7 | C11: 10.0229 | D11: 16.5983 | E11: 12.8969 | H11: 0.7 | I11: 11.02 | J11: 16.318 | K11: 13.3932
B12: 0.8 | H12: 0.8
B13: 0.9 | H13: 0.9
B14: 1 | H14: 1
D16: mac | J16: mac
C18: α=0.3 | I18: α=0.5
B19: 0~90 | C19: 11.244 | D19: 16.078 | E19: 13.3294 | H19: 0~90 | I19: 11.7203 | J19: 15.4466 | K19: 13.3751
B20: 30~90 | C20: 10.2918 | D20: 16.1532 | E20: 12.8112 | H20: 30~90 | I20: 10.872 | J20: 15.3564 | K20: 12.8713

Sheet seed2
C2: 合流200m手前（元の関数） | F2: merge3 | I2: 合流200m手前（新しい関数） | L2: merge3
B3: α | C3: vehicle0 | D3: vehicle1 | E3: all | H3: α | I3: vehicle0 | J3: vehicle1 | K3: all
B4: 0 | H4: 0
B5: 0.1 | H5: 0.1
B6: 0.2 | H6: 0.2
B7: 0.3 | C7: 13.1314 | D7: 15.5616 | E7: 14.3769 | H7: 0.3 | I7: 14.0493 | J7: 14.0289 | K7: 14.0383
B8: 0.4 | C8: 11.0483 | D8: 16.3177 | E8: 13.4849 | H8: 0.4 | I8: 13.4291 | J8: 14.7138 | K8: 14.0976
B9: 0.5 | C9: 11.1624 | D9: 16.4118 | E9: 13.5585 | H9: 0.5 | I9: 13.3086 | J9: 14.8201 | K9: 14.0891
B10: 0.6 | C10: 11.6284 | D10: 16.4858 | E10: 13.9016 | H10: 0.6 | I10: 11.9766 | J10: 15.8998 | K10: 13.8034
B11: 0.7 | C11: 11.6284 | D11: 16.4858 | E11: 13.9016 | H11: 0.7 | I11: 11.8762 | J11: 16.4239 | K11: 14.0047
B12: 0.8 | H12: 0.8
B13: 0.9 | H13: 0.9
B14: 1 | H14: 1
D16: mac | J16: mac
C18: α=0.3 | I18: α=0.5
B19: 0~90 | C19: 12.3521 | D19: 15.6178 | E19: 13.8523 | H19: 0~90 | I19: 11.9439 | J19: 14.2769 | K19: 13.0545
B20: 30~90 | C20: 11.3484 | D20: 15.4433 | E20: 13.2787 | H20: 30~90 | I20: 10.8095 | J20: 13.8574 | K20: 12.308

Sheet seed4
C2: 合流200m手前（元の関数） | F2: merge3 | I2: 合流200m手前（新しい関数） | L2: merge3
B3: α | C3: vehicle0 | D3: vehicle1 | E3: all | H3: α | I3: vehicle0 | J3: vehicle1 | K3: all
B4: 0 | H4: 0
B5: 0.1 | H5: 0.1
B6: 0.2 | H6: 0.2
B7: 0.3 | C7: 10.4027 | D7: 16.1746 | E7: 12.7132 | H7: 0.3 | I7: 9.8928 | J7: 11.5233 | K7: 10.6407
B8: 0.4 | C8: 10.6484 | D8: 16.3654 | E8: 12.929 | H8: 0.4 | I8: 9.2655 | J8: 12.4374 | K8: 10.6308
B9: 0.5 | C9: 9.2843 | D9: 16.4958 | E9: 11.9957 | H9: 0.5 | I9: 10.6772 | J9: 14.1834 | K9: 12.1798
B10: 0.6 | C10: 8.4819 | D10: 16.5273 | E10: 11.4651 | H10: 0.6 | I10: 10.9467 | J10: 16.0122 | K10: 13.0291
B11: 0.7 | C11: 9.0154 | D11: 16.67 | E11: 11.8551 | H11: 0.7 | I11: 9.5172 | J11: 16.1909 | K11: 12.0958
B12: 0.8 | H12: 0.8
B13: 0.9 | H13: 0.9
B14: 1 | H14: 1
D16: mac | J16: mac
I19: 合流100m手前（新しい関数） | L19: merge3
H20: α | I20: vehicle0 | J20: vehicle1 | K20: all
H21: 0
H22: 0.1
H23: 0.2
H24: 0.3 | I24: 7.0361 | J24: 11.6262 | K24: 9.0182
H25: 0.4 | I25: 7.0361 | J25: 11.6262 | K25: 9.0182
H26: 0.5 | I26: 7.0361 | J26: 11.6262 | K26: 9.0182
H27: 0.6 | I27: 9.2926 | J27: 14.2717 | K27: 11.3685
H28: 0.7 | I28: 8.4111 | J28: 15.8758 | K28: 11.2917
H29: 0.8
H30: 0.9
H31: 1
J33: mac
I35: 合流50m手前（新しい関数） | L35: merge3
H36: α | I36: vehicle0 | J36: vehicle1 | K36: all
H37: 0
H38: 0.1
H39: 0.2
H40: 0.3 | I40: 8.2673 | J40: 12.0085 | K40: 9.8162
H41: 0.4 | I41: 5.3473 | J41: 9.9276 | K41: 7.2264
H42: 0.5 | I42: 6.2907 | J42: 12.6302 | K42: 8.6513
H43: 0.6 | I43: 6.0531 | J43: 13.6267 | K43: 8.6785
H44: 0.7 | I44: 5.6997 | J44: 14.6531 | K44: 8.6278
H45: 0.8
H46: 0.9
...

Sheet seed5
C2: 合流200m手前（元の関数） | F2: merge3 | I2: 合流200m手前（新しい関数） | L2: merge3
B3: α | C3: vehicle0 | D3: vehicle1 | E3: all | H3: α | I3: vehicle0 | J3: vehicle1 | K3: all
B4: 0 | H4: 0
B5: 0.1 | H5: 0.1
B6: 0.2 | H6: 0.2
B7: 0.3 | H7: 0.3
B8: 0.4 | H8: 0.4
B9: 0.5 | H9: 0.5
B10: 0.6 | H10: 0.6
B11: 0.7 | H11: 0.7
B12: 0.8 | H12: 0.8
B13: 0.9 | H13: 0.9
B14: 1 | H14: 1
D16: mac | J16: mac

Sheet average
C2: 合流200m手前（元の関数） | F2: merge3 | I2: 合流200m手前（新しい関数） | L2: merge3
B3: α | C3: vehicle0 | D3: vehicle1 | E3: all | H3: α | I3: vehicle0 | J3: vehicle1 | K3: all
B4: 0 | H4: 0
B5: 0.1 | H5: 0.1
B6: 0.2 | H6: 0.2
B7: 0.3 | C7: =ROUND(AVERAGE(seed1!C7,seed2!C7,seed4!C7),4) -> 12.1323 | D7: =ROUND(AVERAGE(seed1!D7,seed2!D7,seed4!D7),4) -> 15.7519 | E7: =ROUND(AVERAGE(seed1!E7,seed2!E7,seed4!E7),4) -> 13.7547 | H7: 0.3 | I7: =ROUND(AVERAGE(seed1!I7,seed2!I7,seed4!I7),4) -> 12.218 | J7: =ROUND(AVERAGE(seed1!J7,seed2!J7,seed4!J7),4) -> 13.1881 | K7: =ROUND(AVERAGE(seed1!K7,seed2!K7,seed4!K7),4) -> 12.683
B8: 0.4 | C8: =ROUND(AVERAGE(seed1!C8,seed2!C8,seed4!C8),4) -> 10.8665 | D8: =ROUND(AVERAGE(seed1!D8,seed2!D8,seed4!D8),4) -> 16.3673 | E8: =ROUND(AVERAGE(seed1!E8,seed2!E8,seed4!E8),4) -> 13.2609 | H8: 0.4 | I8: =ROUND(AVERAGE(seed1!I8,seed2!I8,seed4!I8),4) -> 11.7934 | J8: =ROUND(AVERAGE(seed1!J8,seed2!J8,seed4!J8),4) -> 13.7819 | K8: =ROUND(AVERAGE(seed1!K8,seed2!K8,seed4!K8),4) -> 12.7261
B9: 0.5 | C9: =ROUND(AVERAGE(seed1!C9,seed2!C9,seed4!C9),4) -> 10.2904 | D9: =ROUND(AVERAGE(seed1!D9,seed2!D9,seed4!D9),4) -> 16.4968 | E9: =ROUND(AVERAGE(seed1!E9,seed2!E9,seed4!E9),4) -> 12.895 | H9: 0.5 | I9: =ROUND(AVERAGE(seed1!I9,seed2!I9,seed4!I9),4) -> 12.2003 | J9: =ROUND(AVERAGE(seed1!J9,seed2!J9,seed4!J9),4) -> 14.7496 | K9: =ROUND(AVERAGE(seed1!K9,seed2!K9,seed4!K9),4) -> 13.3886
B10: 0.6 | C10: =ROUND(AVERAGE(seed1!C10,seed2!C10,seed4!C10),4) -> 10.1783 | D10: =ROUND(AVERAGE(seed1!D10,seed2!D10,seed4!D10),4) -> 16.532 | E10: =ROUND(AVERAGE(seed1!E10,seed2!E10,seed4!E10),4) -> 12.8325 | H10: 0.6 | I10: =ROUND(AVERAGE(seed1!I10,seed2!I10,seed4!I10),4) -> 11.4988 | J10: =ROUND(AVERAGE(seed1!J10,seed2!J10,seed4!J10),4) -> 16.0099 | K10: =ROUND(AVERAGE(seed1!K10,seed2!K10,seed4!K10),4) -> 13.5126
B11: 0.7 | C11: =ROUND(AVERAGE(seed1!C11,seed2!C11,seed4!C11),4) -> 10.2222 | D11: =ROUND(AVERAGE(seed1!D11,seed2!D11,seed4!D11),4) -> 16.5847 | E11: =ROUND(AVERAGE(seed1!E11,seed2!E11,seed4!E11),4) -> 12.8845 | H11: 0.7 | I11: =ROUND(AVERAGE(seed1!I11,seed2!I11,seed4!I11),4) -> 10.8045 | J11: =ROUND(AVERAGE(seed1!J11,seed2!J11,seed4!J11),4) -> 16.3109 | K11: =ROUND(AVERAGE(seed1!K11,seed2!K11,seed4!K11),4) -> 13.1646
B12: 0.8 | H12: 0.8
B13: 0.9 | H13: 0.9
B14: 1 | H14: 1
D16: mac | J16: mac
