Workbook

Sheet seed1
C2: 合流100m手前（元の関数） | H2: 合流200m手前（元の関数）
B3: α | C3: vehicle0 | D3: vehicle1 | E3: all | G3: α | H3: vehicle0 | I3: vehicle1 | J3: all
B4: 0 | C4: 11.5436 | D4: 14.1593 | E4: 12.737 | G4: 0 | H4: 14.7243 | I4: 13.2238 | J4: 13.9829 | P4: 30秒以降
B5: 0.1 | C5: 11.5361 | D5: 14.0358 | E5: 12.6975 | G5: 0.1 | H5: 14.7234 | I5: 13.2269 | J5: 13.984
B6: 0.2 | C6: 11.3715 | D6: 15.7503 | E6: 13.3082 | G6: 0.2 | H6: 13.5341 | I6: 15.176 | J6: 14.3136 | L6: 14.1589 | M6: 15.0305 | N6: 14.585
B7: 0.3 | C7: 10.0484 | D7: 16.5315 | E7: 12.8259 | G7: 0.3 | H7: 13.5779 | I7: 15.8294 | J7: 14.6198 | L7: 13.853 | M7: 16.366 | N7: 15.019 | P7: 12.5762 | Q7: 16.3849 | R7: 14.2963
B8: 0.4 | C8: 10.0484 | D8: 16.5315 | E8: 12.8259 | G8: 0.4 | H8: 12.4376 | I8: 16.4761 | J8: 14.2572
B9: 0.5 | C9: 10.0484 | D9: 16.5315 | E9: 12.8259 | G9: 0.5 | H9: 11.1079 | I9: 16.5815 | J9: 13.4648
B10: 0.6 | C10: 8.8982 | D10: 16.5777 | E10: 12.0359 | G10: 0.6 | H10: 11.0855 | I10: 16.6193 | J10: 13.4683
B11: 0.7 | C11: 8.8982 | D11: 16.5777 | E11: 12.0359 | G11: 0.7 | H11: 10.9337 | I11: 16.67 | J11: 13.4038
B12: 0.8 | C12: 8.8982 | D12: 16.5777 | E12: 12.0359 | G12: 0.8 | H12: 10.9337 | I12: 16.67 | J12: 13.4038
B13: 0.9 | C13: 8.8982 | D13: 16.5777 | E13: 12.0359 | G13: 0.9 | H13: 10.9337 | I13: 16.67 | J13: 13.4038
B14: 1 | C14: 8.8982 | D14: 16.5777 | E14: 12.0359 | G14: 1 | H14: 10.9337 | I14: 16.67 | J14: 13.4038
D16: excel6 | I16: excel6
C18: 合流100m手前（新しい関数） | H18: 合流200m手前（新しい関数）
B19: α | C19: vehicle0 | D19: vehicle1 | E19: all | G19: α | H19: vehicle0 | I19: vehicle1 | J19: all
B20: 0 | C20: 11.5436 | D20: 14.1593 | E20: 12.737 | G20: 0 | H20: 14.7242 | I20: 13.2237 | J20: 13.9828
B21: 0.1 | C21: 11.5436 | D21: 14.1593 | E21: 12.737 | G21: 0.1 | H21: 14.7242 | I21: 13.2237 | J21: 13.9828
B22: 0.2 | C22: 11.5436 | D22: 14.1593 | E22: 12.737 | G22: 0.2 | H22: 14.7242 | I22: 13.2237 | J22: 13.9828
B23: 0.3 | C23: 12.1535 | D23: 13.0561 | E23: 12.5774 | G23: 0.3 | H23: 14.7233 | I23: 13.2269 | J23: 13.984
B24: 0.4 | C24: 11.9633 | D24: 13.2994 | E24: 12.5908 | G24: 0.4 | H24: 14.7233 | I24: 13.2269 | J24: 13.984
B25: 0.5 | C25: 11.5361 | D25: 14.0358 | E25: 12.6975 | G25: 0.5 | H25: 14.4061 | I25: 13.6768 | J25: 14.0458
B26: 0.6 | C26: 10.7817 | D26: 15.9795 | E26: 13.0711 | G26: 0.6 | H26: 14.235 | I26: 15.173 | J26: 14.6927
B27: 0.7 | C27: 10.0484 | D27: 16.5315 | E27: 12.8259 | G27: 0.7 | H27: 13.3844 | I27: 16.2527 | J27: 14.7117
B28: 0.8 | C28: 9.2418 | D28: 16.4097 | E28: 12.1705 | G28: 0.8 | H28: 10.9337 | I28: 16.67 | J28: 13.4037
B29: 0.9 | C29: 8.8982 | D29: 16.5777 | E29: 12.0359 | G29: 0.9 | H29: 10.9337 | I29: 16.67 | J29: 13.4037
B30: 1 | C30: 8.8982 | D30: 16.5777 | E30: 12.0359 | G30: 1 | H30: 10.9337 | I30: 16.67 | J30: 13.4037
D32: excel5 | I32: excel4
H34: 合流200m手前（新しい関数） | K34: merge3
G35: α | H35: vehicle0 | I35: vehicle1 | J35: all
G36: 0 | H36: 14.7243 | I36: 13.2237 | J36: 13.9829
G37: 0.1 | H37: 14.7243 | I37: 13.2237 | J37: 13.9829
G38: 0.2 | H38: 14.7243 | I38: 13.2237 | J38: 13.9829
G39: 0.3 | H39: 14.7234 | I39: 13.2269 | J39: 13.984 | P39: 13.8323 | Q39: 11.6284 | R39: 12.7351
G40: 0.4 | H40: 14.7234 | I40: 13.2269 | J40: 13.984
G41: 0.5 | H41: 14.4062 | I41: 13.6768 | J41: 14.0458
G42: 0.6 | H42: 13.9006 | I42: 15.352 | J42: 14.6021 | P42: 12.5954 | Q42: 14.8243 | R42: 13.6686
G43: 0.7 | H43: 13.1904 | I43: 16.2237 | J43: 14.594
G44: 0.8 | H44: 10.9337 | I44: 16.67 | J44: 13.4038
G45: 0.9 | H45: 10.9337 | I45: 16.67 | J45: 13.4038
...

Sheet seed2
C2: 合流100m手前（元の関数） | H2: 合流200m手前（元の関数）
B3: α | C3: vehicle0 | D3: vehicle1 | E3: all | G3: α | H3: vehicle0 | I3: vehicle1 | J3: all
B4: 0 | C4: 14.5399 | D4: 11.905 | E4: 13.1371 | G4: 0 | H4: 15.4712 | I4: 14.8276 | J4: 15.1421
B5: 0.1 | C5: 14.5399 | D5: 11.905 | E5: 13.1371 | G5: 0.1 | H5: 15.3667 | I5: 15.0019 | J5: 15.1802
B6: 0.2 | C6: 13.9224 | D6: 13.5157 | E6: 13.7095 | G6: 0.2 | H6: 15.2775 | I6: 15.2418 | J6: 15.2592
B7: 0.3 | C7: 11.0572 | D7: 16.6199 | E7: 13.5822 | G7: 0.3 | H7: 14.2808 | I7: 16.3754 | J7: 15.3053
B8: 0.4 | C8: 11.0572 | D8: 16.6199 | E8: 13.5822 | G8: 0.4 | H8: 13.3664 | I8: 16.4565 | J8: 14.8537
B9: 0.5 | C9: 11.0572 | D9: 16.6199 | E9: 13.5822 | G9: 0.5 | H9: 13.2566 | I9: 16.67 | J9: 14.8792
B10: 0.6 | C10: 11.0572 | D10: 16.6199 | E10: 13.5822 | G10: 0.6 | H10: 13.2566 | I10: 16.67 | J10: 14.8792
B11: 0.7 | C11: 8.764 | D11: 16.67 | E11: 12.0534 | G11: 0.7 | H11: 13.2566 | I11: 16.67 | J11: 14.8792
B12: 0.8 | C12: 8.764 | D12: 16.67 | E12: 12.0534 | G12: 0.8 | H12: 13.2566 | I12: 16.67 | J12: 14.8792
B13: 0.9 | C13: 8.764 | D13: 16.67 | E13: 12.0534 | G13: 0.9 | H13: 13.2566 | I13: 16.67 | J13: 14.8792
B14: 1 | C14: 8.764 | D14: 16.67 | E14: 12.0534 | G14: 1 | H14: 13.2566 | I14: 16.67 | J14: 14.8792
D16: excel6 | I16: excel6
C18: 合流100m手前（新しい関数） | H18: 合流200m手前（新しい関数）
B19: α | C19: vehicle0 | D19: vehicle1 | E19: all | G19: α | H19: vehicle0 | I19: vehicle1 | J19: all
B20: 0 | C20: 14.5399 | D20: 11.905 | E20: 13.1371 | G20: 0 | H20: 15.4711 | I20: 14.8276 | J20: 15.142
B21: 0.1 | C21: 14.5399 | D21: 11.905 | E21: 13.1371 | G21: 0.1 | H21: 15.4711 | I21: 14.8276 | J21: 15.142
B22: 0.2 | C22: 14.5399 | D22: 11.905 | E22: 13.1371 | G22: 0.2 | H22: 15.3745 | I22: 14.9393 | J22: 15.1519
B23: 0.3 | C23: 13.9553 | D23: 13.0045 | E23: 13.4575 | G23: 0.3 | H23: 15.3003 | I23: 15.1827 | J23: 15.2401
B24: 0.4 | C24: 13.9363 | D24: 13.246 | E24: 13.5749 | G24: 0.4 | H24: 15.2775 | I24: 15.2417 | J24: 15.2592
B25: 0.5 | C25: 11.7954 | D25: 15.796 | E25: 13.631 | G25: 0.5 | H25: 15.2775 | I25: 15.2417 | J25: 15.2592
B26: 0.6 | C26: 11.6631 | D26: 16.2013 | E26: 13.7296 | G26: 0.6 | H26: 14.2566 | I26: 16.3433 | J26: 15.2771
B27: 0.7 | C27: 11.4938 | D27: 16.2963 | E27: 13.6807 | G27: 0.7 | H27: 13.3663 | I27: 16.4565 | J27: 14.8537
B28: 0.8 | C28: 11.3636 | D28: 16.5456 | E28: 13.7158 | G28: 0.8 | H28: 13.2565 | I28: 16.67 | J28: 14.8792
B29: 0.9 | C29: 11.0572 | D29: 16.6199 | E29: 13.5822 | G29: 0.9 | H29: 13.2565 | I29: 16.67 | J29: 14.8792
B30: 1 | C30: 8.76395 | D30: 16.67 | E30: 12.0534 | G30: 1 | H30: 13.2565 | I30: 16.67 | J30: 14.8792
D32: excel5 | I32: excel4
H34: 合流200m手前（新しい関数） | K34: merge3
G35: α | H35: vehicle0 | I35: vehicle1 | J35: all
G36: 0 | H36: 15.4712 | I36: 14.8276 | J36: 15.1421 | M36: 15.4712 | N36: 14.8276 | O36: 15.1421
G37: 0.1 | H37: 15.4712 | I37: 14.8276 | J37: 15.1421 | M37: 15.4712 | N37: 14.8276 | O37: 15.1421
G38: 0.2 | H38: 15.3746 | I38: 14.9393 | J38: 15.1519 | M38: 15.3746 | N38: 14.9393 | O38: 15.152
G39: 0.3 | H39: 15.3003 | I39: 15.1827 | J39: 15.2402 | M39: 15.3003 | N39: 15.1827 | O39: 15.2402
G40: 0.4 | H40: 15.2775 | I40: 15.2418 | J40: 15.2592 | M40: 15.2775 | N40: 15.2418 | O40: 15.2592
G41: 0.5 | H41: 14.2557 | I41: 16.343 | J41: 15.2765 | M41: 14.2838 | N41: 16.3791 | O41: 15.3087
G42: 0.6 | H42: 14.326 | I42: 16.4092 | J42: 15.345 | M42: 14.2474 | N42: 16.3505 | O42: 15.276
G43: 0.7 | H43: 13.2566 | I43: 16.67 | J43: 14.8792 | M43: 13.2566 | N43: 16.67 | O43: 14.8792
G44: 0.8 | H44: 13.2566 | I44: 16.67 | J44: 14.8792 | M44: 13.2566 | N44: 16.67 | O44: 14.8792
G45: 0.9 | H45: 13.2566 | I45: 16.67 | J45: 14.8792 | M45: 13.2566 | N45: 16.67 | O45: 14.8792
...

Sheet seed3
C2: 合流100m手前（元の関数） | H2: 合流200m手前（元の関数）
B3: α | C3: vehicle0 | D3: vehicle1 | E3: all | G3: α | H3: vehicle0 | I3: vehicle1 | J3: all
B4: 0 | C4: 14.5818 | D4: 15.4292 | E4: 15.0124 | G4: 0 | H4: 16.2158 | I4: 16.1456 | J4: 16.1791
B5: 0.1 | C5: 14.5818 | D5: 15.4292 | E5: 15.0124 | G5: 0.1 | H5: 16.2158 | I5: 16.1456 | J5: 16.1791
B6: 0.2 | C6: 14.5775 | D6: 15.4383 | E6: 15.0149 | G6: 0.2 | H6: 16.2158 | I6: 16.1456 | J6: 16.1791
B7: 0.3 | C7: 14.5774 | D7: 15.4382 | E7: 15.0153 | G7: 0.3 | H7: 16.2158 | I7: 16.1456 | J7: 16.1791
B8: 0.4 | C8: 14.3765 | D8: 15.8698 | E8: 15.1353 | G8: 0.4 | H8: 16.1834 | I8: 16.2225 | J8: 16.2038
B9: 0.5 | C9: 9.8138 | D9: 16.6475 | E9: 12.8902 | G9: 0.5 | H9: 13.0121 | I9: 16.67 | J9: 14.7402
B10: 0.6 | C10: 9.8138 | D10: 16.6475 | E10: 12.8902 | G10: 0.6 | H10: 13.0121 | I10: 16.67 | J10: 14.7402
B11: 0.7 | C11: 9.8138 | D11: 16.6475 | E11: 12.8902 | G11: 0.7 | H11: 13.0121 | I11: 16.67 | J11: 14.7402
B12: 0.8 | C12: 9.8138 | D12: 16.6475 | E12: 12.8902 | G12: 0.8 | H12: 13.0121 | I12: 16.67 | J12: 14.7402
B13: 0.9 | C13: 9.8138 | D13: 16.6475 | E13: 12.8902 | G13: 0.9 | H13: 13.0121 | I13: 16.67 | J13: 14.7402
B14: 1 | C14: 9.8138 | D14: 16.6475 | E14: 12.8902 | G14: 1 | H14: 13.0121 | I14: 16.67 | J14: 14.7402
D16: excel6 | I16: excel6
C18: 合流100m手前（新しい関数） | H18: 合流200m手前（新しい関数）
B19: α | C19: vehicle0 | D19: vehicle1 | E19: all | G19: α | H19: vehicle0 | I19: vehicle1 | J19: all
B20: 0 | C20: 14.5818 | D20: 15.4292 | E20: 15.0124 | G20: 0 | H20: 16.2157 | I20: 16.1456 | J20: 16.1791
B21: 0.1 | C21: 14.5818 | D21: 15.4292 | E21: 15.0124 | G21: 0.1 | H21: 16.2157 | I21: 16.1456 | J21: 16.1791
B22: 0.2 | C22: 14.5818 | D22: 15.4292 | E22: 15.0124 | G22: 0.2 | H22: 16.2157 | I22: 16.1456 | J22: 16.1791
B23: 0.3 | C23: 14.5818 | D23: 15.4292 | E23: 15.0124 | G23: 0.3 | H23: 16.2157 | I23: 16.1456 | J23: 16.1791
B24: 0.4 | C24: 14.5818 | D24: 15.4292 | E24: 15.0124 | G24: 0.4 | H24: 16.2157 | I24: 16.1456 | J24: 16.1791
B25: 0.5 | C25: 14.5818 | D25: 15.4292 | E25: 15.0124 | G25: 0.5 | H25: 16.2157 | I25: 16.1456 | J25: 16.1791
B26: 0.6 | C26: 14.5775 | D26: 15.4383 | E26: 15.0149 | G26: 0.6 | H26: 16.2157 | I26: 16.1456 | J26: 16.1791
B27: 0.7 | C27: 14.5357 | D27: 15.5485 | E27: 15.0503 | G27: 0.7 | H27: 16.0202 | I27: 16.2394 | J27: 16.1336
B28: 0.8 | C28: 10.2907 | D28: 16.4628 | E28: 13.0693 | G28: 0.8 | H28: 14.7384 | I28: 16.607 | J28: 15.6679
B29: 0.9 | C29: 9.8138 | D29: 16.6475 | E29: 12.8902 | G29: 0.9 | H29: 13.0121 | I29: 16.67 | J29: 14.7402
B30: 1 | C30: 9.8138 | D30: 16.6475 | E30: 12.8902 | G30: 1 | H30: 13.0121 | I30: 16.67 | J30: 14.7402
D32: excel5 | I32: excel4
H34: 合流200m手前（新しい関数） | K34: merge3
G35: α | H35: vehicle0 | I35: vehicle1 | J35: all
G36: 0 | H36: 16.2158 | I36: 16.1456 | J36: 16.1791
G37: 0.1 | H37: 16.2158 | I37: 16.1456 | J37: 16.1791
G38: 0.2 | H38: 16.2158 | I38: 16.1456 | J38: 16.1791
G39: 0.3 | H39: 16.2158 | I39: 16.1456 | J39: 16.1791
G40: 0.4 | H40: 16.2158 | I40: 16.1456 | J40: 16.1791
G41: 0.5 | H41: 16.2158 | I41: 16.1456 | J41: 16.1791
G42: 0.6 | H42: 16.2158 | I42: 16.1456 | J42: 16.1791
G43: 0.7 | H43: 16.0203 | I43: 16.2394 | J43: 16.1336
G44: 0.8 | H44: 13.0121 | I44: 16.67 | J44: 14.7402
G45: 0.9 | H45: 13.0121 | I45: 16.67 | J45: 14.7402
...

Sheet seed4
C2: 合流100m手前（元の関数） | H2: 合流200m手前（元の関数）
B3: α | C3: vehicle0 | D3: vehicle1 | E3: all | G3: α | H3: vehicle0 | I3: vehicle1 | J3: all
B4: 0 | C4: 12.2518 | D4: 14.6237 | E4: 13.3329 | G4: 0 | H4: 15.3154 | I4: 15.6674 | J4: 15.4833
B5: 0.1 | C5: 12.2518 | D5: 14.6237 | E5: 13.3329 | G5: 0.1 | H5: 15.3154 | I5: 15.6674 | J5: 15.4833
B6: 0.2 | C6: 11.7124 | D6: 16.2167 | E6: 13.7071 | G6: 0.2 | H6: 15.3154 | I6: 15.6674 | J6: 15.4833
B7: 0.3 | C7: 12.1723 | D7: 16.0087 | E7: 13.8875 | G7: 0.3 | H7: 14.5184 | I7: 15.6345 | J7: 15.0415
B8: 0.4 | C8: 11.611 | D8: 16.1364 | E8: 13.6065 | G8: 0.4 | H8: 14.3003 | I8: 16.4156 | J8: 15.2714
B9: 0.5 | C9: 9.9876 | D9: 16.6263 | E9: 12.7574 | G9: 0.5 | H9: 12.7439 | I9: 16.5109 | J9: 14.3886
B10: 0.6 | C10: 9.9876 | D10: 16.6263 | E10: 12.7574 | G10: 0.6 | H10: 12.4409 | I10: 16.67 | J10: 14.2773
B11: 0.7 | C11: 9.9876 | D11: 16.6263 | E11: 12.7574 | G11: 0.7 | H11: 12.4409 | I11: 16.67 | J11: 14.2773
B12: 0.8 | C12: 9.9876 | D12: 16.6263 | E12: 12.7574 | G12: 0.8 | H12: 12.4409 | I12: 16.67 | J12: 14.2773
B13: 0.9 | C13: 9.9876 | D13: 16.6263 | E13: 12.7574 | G13: 0.9 | H13: 12.4409 | I13: 16.67 | J13: 14.2773
B14: 1 | C14: 9.9876 | D14: 16.6263 | E14: 12.7574 | G14: 1 | H14: 12.4409 | I14: 16.67 | J14: 14.2773
D16: excel6 | I16: excel6
C18: 合流100m手前（新しい関数） | H18: 合流200m手前（新しい関数）
B19: α | C19: vehicle0 | D19: vehicle1 | E19: all | G19: α | H19: vehicle0 | I19: vehicle1 | J19: all
B20: 0 | C20: 12.2518 | D20: 14.6237 | E20: 13.3329 | G20: 0 | H20: 15.3153 | I20: 15.6675 | J20: 15.4833
B21: 0.1 | C21: 12.2518 | D21: 14.6237 | E21: 13.3329 | G21: 0.1 | H21: 15.3153 | I21: 15.6675 | J21: 15.4833
B22: 0.2 | C22: 12.2518 | D22: 14.6237 | E22: 13.3329 | G22: 0.2 | H22: 15.3153 | I22: 15.6675 | J22: 15.4833
B23: 0.3 | C23: 12.2518 | D23: 14.6237 | E23: 13.3329 | G23: 0.3 | H23: 14.8079 | I23: 14.9924 | J23: 14.8969
B24: 0.4 | C24: 12.2518 | D24: 14.6237 | E24: 13.3329 | G24: 0.4 | H24: 14.8177 | I24: 15.0007 | J24: 14.906
B25: 0.5 | C25: 12.1464 | D25: 14.8033 | E25: 13.3574 | G25: 0.5 | H25: 14.8593 | I25: 15.6086 | J25: 15.2206
B26: 0.6 | C26: 12.2957 | D26: 15.8215 | E26: 13.8711 | G26: 0.6 | H26: 14.9699 | I26: 15.7224 | J26: 15.3323
B27: 0.7 | C27: 11.7124 | D27: 16.2167 | E27: 13.7071 | G27: 0.7 | H27: 13.6635 | I27: 16.3272 | J27: 14.8651
B28: 0.8 | C28: 12.071 | D28: 16.0798 | E28: 13.8604 | G28: 0.8 | H28: 12.4408 | I28: 16.67 | J28: 14.2773
B29: 0.9 | C29: 9.9876 | D29: 16.6263 | E29: 12.7574 | G29: 0.9 | H29: 12.4408 | I29: 16.67 | J29: 14.2773
B30: 1 | C30: 9.9876 | D30: 16.6263 | E30: 12.7574 | G30: 1 | H30: 12.4408 | I30: 16.67 | J30: 14.2773
D32: excel5 | I32: excel4
H34: 合流200m手前（新しい関数） | K34: merge3
G35: α | H35: vehicle0 | I35: vehicle1 | J35: all
G36: 0 | H36: 15.3154 | I36: 15.6674 | J36: 15.4833
G37: 0.1 | H37: 15.3154 | I37: 15.6674 | J37: 15.4833
G38: 0.2 | H38: 15.3154 | I38: 15.6674 | J38: 15.4833
G39: 0.3 | H39: 14.8178 | I39: 15.0007 | J39: 14.906
G40: 0.4 | H40: 14.9597 | I40: 15.4615 | J40: 15.2017
G41: 0.5 | H41: 14.9592 | I41: 15.6212 | J41: 15.2784
G42: 0.6 | H42: 14.97 | I42: 15.7224 | J42: 15.3324
G43: 0.7 | H43: 13.6636 | I43: 16.3272 | J43: 14.8652
G44: 0.8 | H44: 12.4409 | I44: 16.67 | J44: 14.2773
G45: 0.9 | H45: 12.4409 | I45: 16.67 | J45: 14.2773
...

Sheet seed5
C2: 合流100m手前（元の関数） | H2: 合流200m手前（元の関数）
B3: α | C3: vehicle0 | D3: vehicle1 | E3: all | G3: α | H3: vehicle0 | I3: vehicle1 | J3: all
B4: 0 | C4: 12.2336 | D4: 13.8007 | E4: 12.937 | G4: 0 | H4: 15.8562 | I4: 10.3655 | J4: 13.1837
B5: 0.1 | C5: 11.9194 | D5: 15.0592 | E5: 13.3266 | G5: 0.1 | H5: 15.1144 | I5: 13.8182 | J5: 14.508
B6: 0.2 | C6: 11.2707 | D6: 15.1903 | E6: 12.9927 | G6: 0.2 | H6: 15.4971 | I6: 15.646 | J6: 15.5659
B7: 0.3 | C7: 10.4669 | D7: 15.9326 | E7: 12.789 | G7: 0.3 | H7: 14.9306 | I7: 15.9321 | J7: 15.3933
B8: 0.4 | C8: 11.1881 | D8: 16.3227 | E8: 13.374 | G8: 0.4 | H8: 14.3645 | I8: 16.4109 | J8: 15.293
B9: 0.5 | C9: 7.7135 | D9: 16.67 | E9: 11.1017 | G9: 0.5 | H9: 12.8498 | I9: 16.67 | J9: 14.5104
B10: 0.6 | C10: 7.7135 | D10: 16.67 | E10: 11.1017 | G10: 0.6 | H10: 11.7876 | I10: 16.67 | J10: 13.8556
B11: 0.7 | C11: 7.7135 | D11: 16.67 | E11: 11.1017 | G11: 0.7 | H11: 11.7876 | I11: 16.67 | J11: 13.8556
B12: 0.8 | C12: 7.7135 | D12: 16.67 | E12: 11.1017 | G12: 0.8 | H12: 11.7876 | I12: 16.67 | J12: 13.8556
B13: 0.9 | C13: 7.7135 | D13: 16.67 | E13: 11.1017 | G13: 0.9 | H13: 11.7876 | I13: 16.67 | J13: 13.8556
B14: 1 | C14: 7.7135 | D14: 16.67 | E14: 11.1017 | G14: 1 | H14: 11.7876 | I14: 16.67 | J14: 13.8556
D16: excel6 | I16: excel6
C18: 合流100m手前（新しい関数） | H18: 合流200m手前（新しい関数）
B19: α | C19: vehicle0 | D19: vehicle1 | E19: all | G19: α | H19: vehicle0 | I19: vehicle1 | J19: all
B20: 0 | C20: 12.2336 | D20: 13.8007 | E20: 12.937 | G20: 0 | H20: 15.8561 | I20: 10.3655 | J20: 13.1836
B21: 0.1 | C21: 12.2336 | D21: 13.8007 | E21: 12.937 | G21: 0.1 | H21: 15.8561 | I21: 10.3655 | J21: 13.1836
B22: 0.2 | C22: 12.2336 | D22: 13.8007 | E22: 12.937 | G22: 0.2 | H22: 15.3171 | I22: 12.4634 | J22: 13.9629
B23: 0.3 | C23: 12.2336 | D23: 13.8007 | E23: 12.937 | G23: 0.3 | H23: 15.2091 | I23: 13.568 | J23: 14.4412
B24: 0.4 | C24: 12.144 | D24: 13.6719 | E24: 12.8298 | G24: 0.4 | H24: 14.3834 | I24: 14.6792 | J24: 14.5192
B25: 0.5 | C25: 11.987 | D25: 14.9016 | E25: 13.2933 | G25: 0.5 | H25: 15.3392 | I25: 14.9591 | J25: 15.1636
B26: 0.6 | C26: 11.2926 | D26: 15.1549 | E26: 12.9894 | G26: 0.6 | H26: 14.9305 | I26: 15.9321 | J26: 15.3933
B27: 0.7 | C27: 11.2353 | D27: 16.2392 | E27: 13.3656 | G27: 0.7 | H27: 14.8426 | I27: 16.2127 | J27: 15.4756
B28: 0.8 | C28: 7.7227 | D28: 16.6699 | E28: 11.1074 | G28: 0.8 | H28: 14.1606 | I28: 16.4973 | J28: 15.2209
B29: 0.9 | C29: 7.7135 | D29: 16.67 | E29: 11.1017 | G29: 0.9 | H29: 11.7876 | I29: 16.67 | J29: 13.8556
B30: 1 | C30: 7.7135 | D30: 16.67 | E30: 11.1017 | G30: 1 | H30: 11.7876 | I30: 16.67 | J30: 13.8556
D32: excel5 | I32: excel4
H34: 合流200m手前（新しい関数） | K34: merge3
G35: α | H35: vehicle0 | I35: vehicle1 | J35: all
G36: 0 | H36: 15.8562 | I36: 10.3655 | J36: 13.1837
G37: 0.1 | H37: 15.8562 | I37: 10.3655 | J37: 13.1837
G38: 0.2 | H38: 15.3172 | I38: 12.4635 | J38: 13.963
G39: 0.3 | H39: 15.2091 | I39: 13.5681 | J39: 14.4413
G40: 0.4 | H40: 15.1643 | I40: 12.9628 | J40: 14.1201
G41: 0.5 | H41: 15.3392 | I41: 14.9591 | J41: 15.1636
G42: 0.6 | H42: 14.9306 | I42: 15.9321 | J42: 15.3933
G43: 0.7 | H43: 14.8426 | I43: 16.2127 | J43: 15.4756
G44: 0.8 | H44: 13.0294 | I44: 16.5516 | J44: 14.5605
G45: 0.9 | H45: 11.7876 | I45: 16.67 | J45: 13.8556
...

Sheet average1-5
C2: 合流100m手前（元の関数） | H2: 合流200m手前（元の関数）
B3: α | C3: vehicle0 | D3: vehicle1 | E3: all | G3: α | H3: vehicle0 | I3: vehicle1 | J3: all
B4: 0 | C4: =ROUND(AVERAGE(seed1!C4,seed2!C4,seed3!C4,seed4!C4,seed5!C4),4) -> 13.0301 | D4: =ROUND(AVERAGE(seed1!D4,seed2!D4,seed3!D4,seed4!D4,seed5!D4),4) -> 13.9836 | E4: =ROUND(AVERAGE(seed1!E4,seed2!E4,seed3!E4,seed4!E4,seed5!E4),4) -> 13.4313 | G4: 0 | H4: =ROUND(AVERAGE(seed1!H4,seed2!H4,seed3!H4,seed4!H4,seed5!H4),4) -> 15.5166 | I4: =ROUND(AVERAGE(seed1!I4,seed2!I4,seed3!I4,seed4!I4,seed5!I4),4) -> 14.046 | J4: =ROUND(AVERAGE(seed1!J4,seed2!J4,seed3!J4,seed4!J4,seed5!J4),4) -> 14.7942
B5: 0.1 | C5: =ROUND(AVERAGE(seed1!C5,seed2!C5,seed3!C5,seed4!C5,seed5!C5),4) -> 12.9658 | D5: =ROUND(AVERAGE(seed1!D5,seed2!D5,seed3!D5,seed4!D5,seed5!D5),4) -> 14.2106 | E5: =ROUND(AVERAGE(seed1!E5,seed2!E5,seed3!E5,seed4!E5,seed5!E5),4) -> 13.5013 | G5: 0.1 | H5: =ROUND(AVERAGE(seed1!H5,seed2!H5,seed3!H5,seed4!H5,seed5!H5),4) -> 15.3471 | I5: =ROUND(AVERAGE(seed1!I5,seed2!I5,seed3!I5,seed4!I5,seed5!I5),4) -> 14.772 | J5: =ROUND(AVERAGE(seed1!J5,seed2!J5,seed3!J5,seed4!J5,seed5!J5),4) -> 15.0669
B6: 0.2 | C6: =ROUND(AVERAGE(seed1!C6,seed2!C6,seed3!C6,seed4!C6,seed5!C6),4) -> 12.5709 | D6: =ROUND(AVERAGE(seed1!D6,seed2!D6,seed3!D6,seed4!D6,seed5!D6),4) -> 15.2223 | E6: =ROUND(AVERAGE(seed1!E6,seed2!E6,seed3!E6,seed4!E6,seed5!E6),4) -> 13.7465 | G6: 0.2 | H6: =ROUND(AVERAGE(seed1!H6,seed2!H6,seed3!H6,seed4!H6,seed5!H6),4) -> 15.168 | I6: =ROUND(AVERAGE(seed1!I6,seed2!I6,seed3!I6,seed4!I6,seed5!I6),4) -> 15.5754 | J6: =ROUND(AVERAGE(seed1!J6,seed2!J6,seed3!J6,seed4!J6,seed5!J6),4) -> 15.3602
B7: 0.3 | C7: =ROUND(AVERAGE(seed1!C7,seed2!C7,seed3!C7,seed4!C7,seed5!C7),4) -> 11.6644 | D7: =ROUND(AVERAGE(seed1!D7,seed2!D7,seed3!D7,seed4!D7,seed5!D7),4) -> 16.1062 | E7: =ROUND(AVERAGE(seed1!E7,seed2!E7,seed3!E7,seed4!E7,seed5!E7),4) -> 13.62 | G7: 0.3 | H7: =ROUND(AVERAGE(seed1!H7,seed2!H7,seed3!H7,seed4!H7,seed5!H7),4) -> 14.7047 | I7: =ROUND(AVERAGE(seed1!I7,seed2!I7,seed3!I7,seed4!I7,seed5!I7),4) -> 15.9834 | J7: =ROUND(AVERAGE(seed1!J7,seed2!J7,seed3!J7,seed4!J7,seed5!J7),4) -> 15.3078
B8: 0.4 | C8: =ROUND(AVERAGE(seed1!C8,seed2!C8,seed3!C8,seed4!C8,seed5!C8),4) -> 11.6562 | D8: =ROUND(AVERAGE(seed1!D8,seed2!D8,seed3!D8,seed4!D8,seed5!D8),4) -> 16.2961 | E8: =ROUND(AVERAGE(seed1!E8,seed2!E8,seed3!E8,seed4!E8,seed5!E8),4) -> 13.7048 | G8: 0.4 | H8: =ROUND(AVERAGE(seed1!H8,seed2!H8,seed3!H8,seed4!H8,seed5!H8),4) -> 14.1304 | I8: =ROUND(AVERAGE(seed1!I8,seed2!I8,seed3!I8,seed4!I8,seed5!I8),4) -> 16.3963 | J8: =ROUND(AVERAGE(seed1!J8,seed2!J8,seed3!J8,seed4!J8,seed5!J8),4) -> 15.1758
B9: 0.5 | C9: =ROUND(AVERAGE(seed1!C9,seed2!C9,seed3!C9,seed4!C9,seed5!C9),4) -> 9.7241 | D9: =ROUND(AVERAGE(seed1!D9,seed2!D9,seed3!D9,seed4!D9,seed5!D9),4) -> 16.619 | E9: =ROUND(AVERAGE(seed1!E9,seed2!E9,seed3!E9,seed4!E9,seed5!E9),4) -> 12.6315 | G9: 0.5 | H9: =ROUND(AVERAGE(seed1!H9,seed2!H9,seed3!H9,seed4!H9,seed5!H9),4) -> 12.5941 | I9: =ROUND(AVERAGE(seed1!I9,seed2!I9,seed3!I9,seed4!I9,seed5!I9),4) -> 16.6205 | J9: =ROUND(AVERAGE(seed1!J9,seed2!J9,seed3!J9,seed4!J9,seed5!J9),4) -> 14.3966
B10: 0.6 | C10: =ROUND(AVERAGE(seed1!C10,seed2!C10,seed3!C10,seed4!C10,seed5!C10),4) -> 9.4941 | D10: =ROUND(AVERAGE(seed1!D10,seed2!D10,seed3!D10,seed4!D10,seed5!D10),4) -> 16.6283 | E10: =ROUND(AVERAGE(seed1!E10,seed2!E10,seed3!E10,seed4!E10,seed5!E10),4) -> 12.4735 | G10: 0.6 | H10: =ROUND(AVERAGE(seed1!H10,seed2!H10,seed3!H10,seed4!H10,seed5!H10),4) -> 12.3165 | I10: =ROUND(AVERAGE(seed1!I10,seed2!I10,seed3!I10,seed4!I10,seed5!I10),4) -> 16.6599 | J10: =ROUND(AVERAGE(seed1!J10,seed2!J10,seed3!J10,seed4!J10,seed5!J10),4) -> 14.2441
B11: 0.7 | C11: =ROUND(AVERAGE(seed1!C11,seed2!C11,seed3!C11,seed4!C11,seed5!C11),4) -> 9.0354 | D11: =ROUND(AVERAGE(seed1!D11,seed2!D11,seed3!D11,seed4!D11,seed5!D11),4) -> 16.6383 | E11: =ROUND(AVERAGE(seed1!E11,seed2!E11,seed3!E11,seed4!E11,seed5!E11),4) -> 12.1677 | G11: 0.7 | H11: =ROUND(AVERAGE(seed1!H11,seed2!H11,seed3!H11,seed4!H11,seed5!H11),4) -> 12.2862 | I11: =ROUND(AVERAGE(seed1!I11,seed2!I11,seed3!I11,seed4!I11,seed5!I11),4) -> 16.67 | J11: =ROUND(AVERAGE(seed1!J11,seed2!J11,seed3!J11,seed4!J11,seed5!J11),4) -> 14.2312
B12: 0.8 | C12: =ROUND(AVERAGE(seed1!C12,seed2!C12,seed3!C12,seed4!C12,seed5!C12),4) -> 9.0354 | D12: =ROUND(AVERAGE(seed1!D12,seed2!D12,seed3!D12,seed4!D12,seed5!D12),4) -> 16.6383 | E12: =ROUND(AVERAGE(seed1!E12,seed2!E12,seed3!E12,seed4!E12,seed5!E12),4) -> 12.1677 | G12: 0.8 | H12: =ROUND(AVERAGE(seed1!H12,seed2!H12,seed3!H12,seed4!H12,seed5!H12),4) -> 12.2862 | I12: =ROUND(AVERAGE(seed1!I12,seed2!I12,seed3!I12,seed4!I12,seed5!I12),4) -> 16.67 | J12: =ROUND(AVERAGE(seed1!J12,seed2!J12,seed3!J12,seed4!J12,seed5!J12),4) -> 14.2312
B13: 0.9 | C13: =ROUND(AVERAGE(seed1!C13,seed2!C13,seed3!C13,seed4!C13,seed5!C13),4) -> 9.0354 | D13: =ROUND(AVERAGE(seed1!D13,seed2!D13,seed3!D13,seed4!D13,seed5!D13),4) -> 16.6383 | E13: =ROUND(AVERAGE(seed1!E13,seed2!E13,seed3!E13,seed4!E13,seed5!E13),4) -> 12.1677 | G13: 0.9 | H13: =ROUND(AVERAGE(seed1!H13,seed2!H13,seed3!H13,seed4!H13,seed5!H13),4) -> 12.2862 | I13: =ROUND(AVERAGE(seed1!I13,seed2!I13,seed3!I13,seed4!I13,seed5!I13),4) -> 16.67 | J13: =ROUND(AVERAGE(seed1!J13,seed2!J13,seed3!J13,seed4!J13,seed5!J13),4) -> 14.2312
B14: 1 | C14: =ROUND(AVERAGE(seed1!C14,seed2!C14,seed3!C14,seed4!C14,seed5!C14),4) -> 9.0354 | D14: =ROUND(AVERAGE(seed1!D14,seed2!D14,seed3!D14,seed4!D14,seed5!D14),4) -> 16.6383 | E14: =ROUND(AVERAGE(seed1!E14,seed2!E14,seed3!E14,seed4!E14,seed5!E14),4) -> 12.1677 | G14: 1 | H14: =ROUND(AVERAGE(seed1!H14,seed2!H14,seed3!H14,seed4!H14,seed5!H14),4) -> 12.2862 | I14: =ROUND(AVERAGE(seed1!I14,seed2!I14,seed3!I14,seed4!I14,seed5!I14),4) -> 16.67 | J14: =ROUND(AVERAGE(seed1!J14,seed2!J14,seed3!J14,seed4!J14,seed5!J14),4) -> 14.2312
C18: 合流100m手前（新しい関数） | H18: 合流200m手前（新しい関数）
B19: α | C19: vehicle0 | D19: vehicle1 | E19: all | G19: α | H19: vehicle0 | I19: vehicle1 | J19: all
B20: 0 | C20: =ROUND(AVERAGE(seed1!C20,seed2!C20,seed3!C20,seed4!C20,seed5!C20),4) -> 13.0301 | D20: =ROUND(AVERAGE(seed1!D20,seed2!D20,seed3!D20,seed4!D20,seed5!D20),4) -> 13.9836 | E20: =ROUND(AVERAGE(seed1!E20,seed2!E20,seed3!E20,seed4!E20,seed5!E20),4) -> 13.4313 | G20: 0 | H20: =ROUND(AVERAGE(seed1!H20,seed2!H20,seed3!H20,seed4!H20,seed5!H20),4) -> 15.5165 | I20: =ROUND(AVERAGE(seed1!I20,seed2!I20,seed3!I20,seed4!I20,seed5!I20),4) -> 14.046 | J20: =ROUND(AVERAGE(seed1!J20,seed2!J20,seed3!J20,seed4!J20,seed5!J20),4) -> 14.7942
B21: 0.1 | C21: =ROUND(AVERAGE(seed1!C21,seed2!C21,seed3!C21,seed4!C21,seed5!C21),4) -> 13.0301 | D21: =ROUND(AVERAGE(seed1!D21,seed2!D21,seed3!D21,seed4!D21,seed5!D21),4) -> 13.9836 | E21: =ROUND(AVERAGE(seed1!E21,seed2!E21,seed3!E21,seed4!E21,seed5!E21),4) -> 13.4313 | G21: 0.1 | H21: =ROUND(AVERAGE(seed1!H21,seed2!H21,seed3!H21,seed4!H21,seed5!H21),4) -> 15.5165 | I21: =ROUND(AVERAGE(seed1!I21,seed2!I21,seed3!I21,seed4!I21,seed5!I21),4) -> 14.046 | J21: =ROUND(AVERAGE(seed1!J21,seed2!J21,seed3!J21,seed4!J21,seed5!J21),4) -> 14.7942
B22: 0.2 | C22: =ROUND(AVERAGE(seed1!C22,seed2!C22,seed3!C22,seed4!C22,seed5!C22),4) -> 13.0301 | D22: =ROUND(AVERAGE(seed1!D22,seed2!D22,seed3!D22,seed4!D22,seed5!D22),4) -> 13.9836 | E22: =ROUND(AVERAGE(seed1!E22,seed2!E22,seed3!E22,seed4!E22,seed5!E22),4) -> 13.4313 | G22: 0.2 | H22: =ROUND(AVERAGE(seed1!H22,seed2!H22,seed3!H22,seed4!H22,seed5!H22),4) -> 15.3894 | I22: =ROUND(AVERAGE(seed1!I22,seed2!I22,seed3!I22,seed4!I22,seed5!I22),4) -> 14.4879 | J22: =ROUND(AVERAGE(seed1!J22,seed2!J22,seed3!J22,seed4!J22,seed5!J22),4) -> 14.952
B23: 0.3 | C23: =ROUND(AVERAGE(seed1!C23,seed2!C23,seed3!C23,seed4!C23,seed5!C23),4) -> 13.0352 | D23: =ROUND(AVERAGE(seed1!D23,seed2!D23,seed3!D23,seed4!D23,seed5!D23),4) -> 13.9828 | E23: =ROUND(AVERAGE(seed1!E23,seed2!E23,seed3!E23,seed4!E23,seed5!E23),4) -> 13.4634 | G23: 0.3 | H23: =ROUND(AVERAGE(seed1!H23,seed2!H23,seed3!H23,seed4!H23,seed5!H23),4) -> 15.2513 | I23: =ROUND(AVERAGE(seed1!I23,seed2!I23,seed3!I23,seed4!I23,seed5!I23),4) -> 14.6231 | J23: =ROUND(AVERAGE(seed1!J23,seed2!J23,seed3!J23,seed4!J23,seed5!J23),4) -> 14.9483
B24: 0.4 | C24: =ROUND(AVERAGE(seed1!C24,seed2!C24,seed3!C24,seed4!C24,seed5!C24),4) -> 12.9754 | D24: =ROUND(AVERAGE(seed1!D24,seed2!D24,seed3!D24,seed4!D24,seed5!D24),4) -> 14.054 | E24: =ROUND(AVERAGE(seed1!E24,seed2!E24,seed3!E24,seed4!E24,seed5!E24),4) -> 13.4682 | G24: 0.4 | H24: =ROUND(AVERAGE(seed1!H24,seed2!H24,seed3!H24,seed4!H24,seed5!H24),4) -> 15.0835 | I24: =ROUND(AVERAGE(seed1!I24,seed2!I24,seed3!I24,seed4!I24,seed5!I24),4) -> 14.8588 | J24: =ROUND(AVERAGE(seed1!J24,seed2!J24,seed3!J24,seed4!J24,seed5!J24),4) -> 14.9695
B25: 0.5 | C25: =ROUND(AVERAGE(seed1!C25,seed2!C25,seed3!C25,seed4!C25,seed5!C25),4) -> 12.4093 | D25: =ROUND(AVERAGE(seed1!D25,seed2!D25,seed3!D25,seed4!D25,seed5!D25),4) -> 14.9932 | E25: =ROUND(AVERAGE(seed1!E25,seed2!E25,seed3!E25,seed4!E25,seed5!E25),4) -> 13.5983 | G25: 0.5 | H25: =ROUND(AVERAGE(seed1!H25,seed2!H25,seed3!H25,seed4!H25,seed5!H25),4) -> 15.2196 | I25: =ROUND(AVERAGE(seed1!I25,seed2!I25,seed3!I25,seed4!I25,seed5!I25),4) -> 15.1264 | J25: =ROUND(AVERAGE(seed1!J25,seed2!J25,seed3!J25,seed4!J25,seed5!J25),4) -> 15.1737
B26: 0.6 | C26: =ROUND(AVERAGE(seed1!C26,seed2!C26,seed3!C26,seed4!C26,seed5!C26),4) -> 12.1221 | D26: =ROUND(AVERAGE(seed1!D26,seed2!D26,seed3!D26,seed4!D26,seed5!D26),4) -> 15.7191 | E26: =ROUND(AVERAGE(seed1!E26,seed2!E26,seed3!E26,seed4!E26,seed5!E26),4) -> 13.7352 | G26: 0.6 | H26: =ROUND(AVERAGE(seed1!H26,seed2!H26,seed3!H26,seed4!H26,seed5!H26),4) -> 14.9215 | I26: =ROUND(AVERAGE(seed1!I26,seed2!I26,seed3!I26,seed4!I26,seed5!I26),4) -> 15.8633 | J26: =ROUND(AVERAGE(seed1!J26,seed2!J26,seed3!J26,seed4!J26,seed5!J26),4) -> 15.3749
B27: 0.7 | C27: =ROUND(AVERAGE(seed1!C27,seed2!C27,seed3!C27,seed4!C27,seed5!C27),4) -> 11.8051 | D27: =ROUND(AVERAGE(seed1!D27,seed2!D27,seed3!D27,seed4!D27,seed5!D27),4) -> 16.1664 | E27: =ROUND(AVERAGE(seed1!E27,seed2!E27,seed3!E27,seed4!E27,seed5!E27),4) -> 13.7259 | G27: 0.7 | H27: =ROUND(AVERAGE(seed1!H27,seed2!H27,seed3!H27,seed4!H27,seed5!H27),4) -> 14.2554 | I27: =ROUND(AVERAGE(seed1!I27,seed2!I27,seed3!I27,seed4!I27,seed5!I27),4) -> 16.2977 | J27: =ROUND(AVERAGE(seed1!J27,seed2!J27,seed3!J27,seed4!J27,seed5!J27),4) -> 15.2079
B28: 0.8 | C28: =ROUND(AVERAGE(seed1!C28,seed2!C28,seed3!C28,seed4!C28,seed5!C28),4) -> 10.138 | D28: =ROUND(AVERAGE(seed1!D28,seed2!D28,seed3!D28,seed4!D28,seed5!D28),4) -> 16.4336 | E28: =ROUND(AVERAGE(seed1!E28,seed2!E28,seed3!E28,seed4!E28,seed5!E28),4) -> 12.7847 | G28: 0.8 | H28: =ROUND(AVERAGE(seed1!H28,seed2!H28,seed3!H28,seed4!H28,seed5!H28),4) -> 13.106 | I28: =ROUND(AVERAGE(seed1!I28,seed2!I28,seed3!I28,seed4!I28,seed5!I28),4) -> 16.6229 | J28: =ROUND(AVERAGE(seed1!J28,seed2!J28,seed3!J28,seed4!J28,seed5!J28),4) -> 14.6898
B29: 0.9 | C29: =ROUND(AVERAGE(seed1!C29,seed2!C29,seed3!C29,seed4!C29,seed5!C29),4) -> 9.4941 | D29: =ROUND(AVERAGE(seed1!D29,seed2!D29,seed3!D29,seed4!D29,seed5!D29),4) -> 16.6283 | E29: =ROUND(AVERAGE(seed1!E29,seed2!E29,seed3!E29,seed4!E29,seed5!E29),4) -> 12.4735 | G29: 0.9 | H29: =ROUND(AVERAGE(seed1!H29,seed2!H29,seed3!H29,seed4!H29,seed5!H29),4) -> 12.2861 | I29: =ROUND(AVERAGE(seed1!I29,seed2!I29,seed3!I29,seed4!I29,seed5!I29),4) -> 16.67 | J29: =ROUND(AVERAGE(seed1!J29,seed2!J29,seed3!J29,seed4!J29,seed5!J29),4) -> 14.2312
B30: 1 | C30: =ROUND(AVERAGE(seed1!C30,seed2!C30,seed3!C30,seed4!C30,seed5!C30),4) -> 9.0354 | D30: =ROUND(AVERAGE(seed1!D30,seed2!D30,seed3!D30,seed4!D30,seed5!D30),4) -> 16.6383 | E30: =ROUND(AVERAGE(seed1!E30,seed2!E30,seed3!E30,seed4!E30,seed5!E30),4) -> 12.1677 | G30: 1 | H30: =ROUND(AVERAGE(seed1!H30,seed2!H30,seed3!H30,seed4!H30,seed5!H30),4) -> 12.2861 | I30: =ROUND(AVERAGE(seed1!I30,seed2!I30,seed3!I30,seed4!I30,seed5!I30),4) -> 16.67 | J30: =ROUND(AVERAGE(seed1!J30,seed2!J30,seed3!J30,seed4!J30,seed5!J30),4) -> 14.2312
H34: 合流200m手前（新しい関数） | K34: merge3
G35: α | H35: vehicle0 | I35: vehicle1 | J35: all
G36: 0 | H36: =ROUND(AVERAGE(seed1!H36,seed2!H36,seed3!H36,seed4!H36,seed5!H36),4) -> 15.5166 | I36: =ROUND(AVERAGE(seed1!I36,seed2!I36,seed3!I36,seed4!I36,seed5!I36),4) -> 14.046 | J36: =ROUND(AVERAGE(seed1!J36,seed2!J36,seed3!J36,seed4!J36,seed5!J36),4) -> 14.7942
G37: 0.1 | H37: =ROUND(AVERAGE(seed1!H37,seed2!H37,seed3!H37,seed4!H37,seed5!H37),4) -> 15.5166 | I37: =ROUND(AVERAGE(seed1!I37,seed2!I37,seed3!I37,seed4!I37,seed5!I37),4) -> 14.046 | J37: =ROUND(AVERAGE(seed1!J37,seed2!J37,seed3!J37,seed4!J37,seed5!J37),4) -> 14.7942
G38: 0.2 | H38: =ROUND(AVERAGE(seed1!H38,seed2!H38,seed3!H38,seed4!H38,seed5!H38),4) -> 15.3895 | I38: =ROUND(AVERAGE(seed1!I38,seed2!I38,seed3!I38,seed4!I38,seed5!I38),4) -> 14.4879 | J38: =ROUND(AVERAGE(seed1!J38,seed2!J38,seed3!J38,seed4!J38,seed5!J38),4) -> 14.952
G39: 0.3 | H39: =ROUND(AVERAGE(seed1!H39,seed2!H39,seed3!H39,seed4!H39,seed5!H39),4) -> 15.2533 | I39: =ROUND(AVERAGE(seed1!I39,seed2!I39,seed3!I39,seed4!I39,seed5!I39),4) -> 14.6248 | J39: =ROUND(AVERAGE(seed1!J39,seed2!J39,seed3!J39,seed4!J39,seed5!J39),4) -> 14.9501
G40: 0.4 | H40: =ROUND(AVERAGE(seed1!H40,seed2!H40,seed3!H40,seed4!H40,seed5!H40),4) -> 15.2681 | I40: =ROUND(AVERAGE(seed1!I40,seed2!I40,seed3!I40,seed4!I40,seed5!I40),4) -> 14.6077 | J40: =ROUND(AVERAGE(seed1!J40,seed2!J40,seed3!J40,seed4!J40,seed5!J40),4) -> 14.9488
G41: 0.5 | H41: =ROUND(AVERAGE(seed1!H41,seed2!H41,seed3!H41,seed4!H41,seed5!H41),4) -> 15.0352 | I41: =ROUND(AVERAGE(seed1!I41,seed2!I41,seed3!I41,seed4!I41,seed5!I41),4) -> 15.3491 | J41: =ROUND(AVERAGE(seed1!J41,seed2!J41,seed3!J41,seed4!J41,seed5!J41),4) -> 15.1887
G42: 0.6 | H42: =ROUND(AVERAGE(seed1!H42,seed2!H42,seed3!H42,seed4!H42,seed5!H42),4) -> 14.8686 | I42: =ROUND(AVERAGE(seed1!I42,seed2!I42,seed3!I42,seed4!I42,seed5!I42),4) -> 15.9123 | J42: =ROUND(AVERAGE(seed1!J42,seed2!J42,seed3!J42,seed4!J42,seed5!J42),4) -> 15.3704
G43: 0.7 | H43: =ROUND(AVERAGE(seed1!H43,seed2!H43,seed3!H43,seed4!H43,seed5!H43),4) -> 14.1947 | I43: =ROUND(AVERAGE(seed1!I43,seed2!I43,seed3!I43,seed4!I43,seed5!I43),4) -> 16.3346 | J43: =ROUND(AVERAGE(seed1!J43,seed2!J43,seed3!J43,seed4!J43,seed5!J43),4) -> 15.1895
G44: 0.8 | H44: =ROUND(AVERAGE(seed1!H44,seed2!H44,seed3!H44,seed4!H44,seed5!H44),4) -> 12.5345 | I44: =ROUND(AVERAGE(seed1!I44,seed2!I44,seed3!I44,seed4!I44,seed5!I44),4) -> 16.6463 | J44: =ROUND(AVERAGE(seed1!J44,seed2!J44,seed3!J44,seed4!J44,seed5!J44),4) -> 14.3722
G45: 0.9 | H45: =ROUND(AVERAGE(seed1!H45,seed2!H45,seed3!H45,seed4!H45,seed5!H45),4) -> 12.2862 | I45: =ROUND(AVERAGE(seed1!I45,seed2!I45,seed3!I45,seed4!I45,seed5!I45),4) -> 16.67 | J45: =ROUND(AVERAGE(seed1!J45,seed2!J45,seed3!J45,seed4!J45,seed5!J45),4) -> 14.2312
G46: 1 | H46: =ROUND(AVERAGE(seed1!H46,seed2!H46,seed3!H46,seed4!H46,seed5!H46),4) -> 12.4108 | I46: =ROUND(AVERAGE(seed1!I46,seed2!I46,seed3!I46,seed4!I46,seed5!I46),4) -> 16.67 | J46: =ROUND(AVERAGE(seed1!J46,seed2!J46,seed3!J46,seed4!J46,seed5!J46),4) -> 14.3251

Sheet seed6
C2: 合流100m手前（元の関数） | H2: 合流200m手前（元の関数）
B3: α | C3: vehicle0 | D3: vehicle1 | E3: all | G3: α | H3: vehicle0 | I3: vehicle1 | J3: all
B4: 0 | C4: 12.0746 | D4: 12.8567 | E4: 12.4363 | G4: 0 | H4: 11.5948 | I4: 11.8484 | J4: 11.7096
B5: 0.1 | C5: 11.983 | D5: 13.0432 | E5: 12.4734 | G5: 0.1 | H5: 11.4417 | I5: 13.4132 | J5: 12.3215
B6: 0.2 | C6: 9.8214 | D6: 15.0769 | E6: 12.0663 | G6: 0.2 | H6: 11.651 | I6: 14.7829 | J6: 12.9796
B7: 0.3 | C7: 10.4717 | D7: 15.375 | E7: 12.5742 | G7: 0.3 | H7: 11.7488 | I7: 15.924 | J7: 13.5135
B8: 0.4 | C8: 10.9898 | D8: 16.4374 | E8: 13.2434 | G8: 0.4 | H8: 10.9223 | I8: 16.4209 | J8: 13.1415
B9: 0.5 | C9: 7.9197 | D9: 16.6649 | E9: 11.2295 | G9: 0.5 | H9: 10.8471 | I9: 16.5953 | J9: 13.1426
B10: 0.6 | C10: 7.9197 | D10: 16.6649 | E10: 11.2295 | G10: 0.6 | H10: 10.8243 | I10: 16.5818 | J10: 13.1236
B11: 0.7 | C11: 7.9197 | D11: 16.6649 | E11: 11.2295 | G11: 0.7 | H11: 10.8243 | I11: 16.5818 | J11: 13.1236
B12: 0.8 | C12: 7.9197 | D12: 16.6649 | E12: 11.2295 | G12: 0.8 | H12: 10.6152 | I12: 16.67 | J12: 13.0332
B13: 0.9 | C13: 7.9197 | D13: 16.6649 | E13: 11.2295 | G13: 0.9 | H13: 10.6152 | I13: 16.67 | J13: 13.0332
B14: 1 | C14: 7.9197 | D14: 16.6649 | E14: 11.2295 | G14: 1 | H14: 10.6152 | I14: 16.67 | J14: 13.0332
D16: excel6 | I16: excel6
C18: 合流100m手前（新しい関数） | H18: 合流200m手前（新しい関数）
B19: α | C19: vehicle0 | D19: vehicle1 | E19: all | G19: α | H19: vehicle0 | I19: vehicle1 | J19: all
B20: 0 | C20: 12.0746 | D20: 12.8567 | E20: 12.4363 | G20: 0 | H20: 11.5948 | I20: 11.8484 | J20: 11.7096 | L20: 11.5948 | M20: 11.8486 | N20: 11.7097
B21: 0.1 | C21: 12.0746 | D21: 12.8567 | E21: 12.4363 | G21: 0.1 | H21: 11.5948 | I21: 11.8484 | J21: 11.7096 | L21: 11.5948 | M21: 11.8486 | N21: 11.7097
B22: 0.2 | C22: 12.0746 | D22: 12.8567 | E22: 12.4363 | G22: 0.2 | H22: 11.5948 | I22: 11.8484 | J22: 11.7096 | L22: 11.5948 | M22: 11.8486 | N22: 11.7097
B23: 0.3 | C23: 12.0746 | D23: 12.8567 | E23: 12.4363 | G23: 0.3 | L23: 10.99 | M23: 10.9109 | N23: 10.9537 | P23: 0.3~0.5は譲る対象の判定に問題があるように感じる
B24: 0.4 | C24: 11.6 | D24: 13.1512 | E24: 12.3156 | G24: 0.4 | L24: 8.72211 | M24: 11.2911 | N24: 9.86842 | P24: 結果として無駄な減速、低速での一定走行になってしまう
B25: 0.5 | C25: 10.6928 | D25: 14.5934 | E25: 12.3514 | G25: 0.5 | L25: 11.3283 | M25: 12.2069 | N25: 11.7048
B26: 0.6 | C26: 11.1424 | D26: 14.841 | E26: 12.7266 | G26: 0.6 | H26: 11.675 | I26: 14.6087 | J26: 12.943 | L26: 11.6749 | M26: 14.6087 | N26: 12.9429
B27: 0.7 | C27: 9.833 | D27: 15.0678 | E27: 12.0691 | G27: 0.7 | H27: 13.1232 | I27: 16.1985 | J27: 14.4522 | L27: 13.1231 | M27: 16.1985 | N27: 14.4522
B28: 0.8 | C28: 8.5851 | D28: 16.3587 | E28: 11.6083 | G28: 0.8 | H28: 10.8029 | I28: 16.3202 | J28: 13.0303 | L28: 10.8029 | M28: 16.3202 | N28: 13.0303
B29: 0.9 | C29: 7.9197 | D29: 16.6649 | E29: 11.2295 | G29: 0.9 | H29: 10.6152 | I29: 16.67 | J29: 13.0332 | L29: 10.6152 | M29: 16.67 | N29: 13.0332
B30: 1 | C30: 7.9197 | D30: 16.6649 | E30: 11.2295 | G30: 1 | H30: 10.6152 | I30: 16.67 | J30: 13.0332 | L30: 10.6152 | M30: 16.67 | N30: 13.0332
D32: hpc | I32: mac | M32: excel4

Sheet seed7
C2: 合流100m手前（元の関数） | H2: 合流200m手前（元の関数）
B3: α | C3: vehicle0 | D3: vehicle1 | E3: all | G3: α | H3: vehicle0 | I3: vehicle1 | J3: all
B4: 0 | C4: 12.9194 | D4: 11.3866 | E4: 12.1189 | G4: 0 | H4: 13.6087 | I4: 13.573 | J4: 13.5901
B5: 0.1 | C5: 12.1211 | D5: 12.3275 | E5: 12.2282 | G5: 0.1 | H5: 13.4705 | I5: 13.1496 | J5: 13.3053
B6: 0.2 | C6: 10.8372 | D6: 14.6644 | E6: 12.7202 | G6: 0.2 | H6: 13.1367 | I6: 15.8948 | J6: 14.4383
B7: 0.3 | C7: 9.3767 | D7: 15.9131 | E7: 12.2894 | G7: 0.3 | H7: 12.4991 | I7: 16.0649 | J7: 14.1683
B8: 0.4 | C8: 7.7124 | D8: 16.6401 | E8: 11.3916 | G8: 0.4 | H8: 10.717 | I8: 16.3494 | J8: 13.2069
B9: 0.5 | C9: 7.7124 | D9: 16.6401 | E9: 11.3916 | G9: 0.5 | H9: 10.6632 | I9: 16.5312 | J9: 13.2573
B10: 0.6 | C10: 7.7124 | D10: 16.6401 | E10: 11.3916 | G10: 0.6 | H10: 10.1142 | I10: 16.4953 | J10: 12.8833
B11: 0.7 | C11: 7.7124 | D11: 16.6401 | E11: 11.3916 | G11: 0.7 | H11: 9.8783 | I11: 16.67 | J11: 12.8256
B12: 0.8 | C12: 7.7124 | D12: 16.6401 | E12: 11.3916 | G12: 0.8 | H12: 9.8783 | I12: 16.67 | J12: 12.8256
B13: 0.9 | C13: 7.7124 | D13: 16.6401 | E13: 11.3916 | G13: 0.9 | H13: 9.8783 | I13: 16.67 | J13: 12.8256
B14: 1 | C14: 7.7124 | D14: 16.6401 | E14: 11.3916 | G14: 1 | H14: 9.8783 | I14: 16.67 | J14: 12.8256
D16: excel6 | I16: excel6
C18: 合流100m手前（新しい関数） | H18: 合流200m手前（新しい関数）
B19: α | C19: vehicle0 | D19: vehicle1 | E19: all | G19: α | H19: vehicle0 | I19: vehicle1 | J19: all
B20: 0 | C20: 12.9194 | D20: 11.3866 | E20: 12.1189 | G20: 0 | H20: 13.6087 | I20: 13.573 | J20: 13.5901
B21: 0.1 | C21: 12.9194 | D21: 11.3866 | E21: 12.1189 | G21: 0.1 | H21: 13.6087 | I21: 13.573 | J21: 13.5901
B22: 0.2 | C22: 12.9194 | D22: 11.3866 | E22: 12.1189 | G22: 0.2 | H22: 13.6087 | I22: 13.573 | J22: 13.5901
B23: 0.3 | C23: 12.9194 | D23: 11.3866 | E23: 12.1189 | G23: 0.3 | H23: 13.6087 | I23: 13.573 | J23: 13.5901
B24: 0.4 | C24: 12.5998 | D24: 11.5677 | E24: 12.0638 | G24: 0.4 | H24: 12.8835 | I24: 14.7014 | J24: 13.7529
B25: 0.5 | C25: 11.8324 | D25: 13.4163 | E25: 12.6193 | G25: 0.5 | H25: 12.7537 | I25: 15.5823 | J25: 14.0919
B26: 0.6 | C26: 11.1161 | D26: 14.8119 | E26: 12.8112 | G26: 0.6 | H26: 12.7275 | I26: 15.6912 | J26: 14.129
B27: 0.7 | C27: 8.1984 | D27: 16.2519 | E27: 11.5935 | G27: 0.7 | H27: 10.322 | I27: 16.3707 | J27: 12.9557
B28: 0.8 | C28: 7.7124 | D28: 16.6401 | E28: 11.3916 | G28: 0.8 | H28: 10.1142 | I28: 16.4953 | J28: 12.8833
B29: 0.9 | C29: 7.7124 | D29: 16.6401 | E29: 11.3916 | G29: 0.9 | H29: 9.87834 | I29: 16.67 | J29: 12.8256
B30: 1 | C30: 7.7124 | D30: 16.6401 | E30: 11.3916 | G30: 1 | H30: 9.87834 | I30: 16.67 | J30: 12.8256
D32: mac | I32: excel4
H34: 合流200m手前（新しい関数） | K34: merge3
G35: α | H35: vehicle0 | I35: vehicle1 | J35: all
G36: 0
G37: 0.1 | H37: 13.6087 | I37: 13.573 | J37: 13.5901
G38: 0.2 | H38: 13.6087 | I38: 13.573 | J38: 13.5901
G39: 0.3 | H39: 13.6087 | I39: 13.573 | J39: 13.5901
G40: 0.4 | H40: 12.8836 | I40: 14.7014 | J40: 13.7529
G41: 0.5
G42: 0.6
G43: 0.7
G44: 0.8
G45: 0.9
...

Sheet seed8
C2: 合流100m手前（元の関数） | H2: 合流200m手前（元の関数）
B3: α | C3: vehicle0 | D3: vehicle1 | E3: all | G3: α | H3: vehicle0 | I3: vehicle1 | J3: all
B4: 0 | C4: 13.406 | D4: 13.807 | E4: 13.6102 | G4: 0 | H4: 15.5361 | I4: 15.7677 | J4: 15.6527
B5: 0.1 | C5: 13.3988 | D5: 13.8146 | E5: 13.6106 | G5: 0.1 | H5: 14.9161 | I5: 15.7293 | J5: 15.3227
B6: 0.2 | C6: 12.1944 | D6: 15.6127 | E6: 13.8386 | G6: 0.2 | H6: 14.0189 | I6: 16.4194 | J6: 15.1703
B7: 0.3 | C7: 11.2198 | D7: 16.1871 | E7: 13.51 | G7: 0.3 | H7: 15.6473 | I7: 16.2887 | J7: 15.9661
B8: 0.4 | C8: 11.0955 | D8: 16.5334 | E8: 13.5504 | G8: 0.4 | H8: 12.885 | I8: 16.666 | J8: 14.6365
B9: 0.5 | C9: 11.0328 | D9: 16.5324 | E9: 13.5124 | G9: 0.5 | H9: 12.4654 | I9: 16.6679 | J9: 14.4095
B10: 0.6 | C10: 9.0913 | D10: 16.67 | E10: 12.3091 | G10: 0.6 | H10: 12.9533 | I10: 16.666 | J10: 14.6766
B11: 0.7 | C11: 9.0913 | D11: 16.67 | E11: 12.3091 | G11: 0.7 | H11: 12.9984 | I11: 16.6659 | J11: 14.703
B12: 0.8 | C12: 9.0913 | D12: 16.67 | E12: 12.3091 | G12: 0.8 | H12: 13.0008 | I12: 16.67 | J12: 14.7059
B13: 0.9 | C13: 9.0913 | D13: 16.67 | E13: 12.3091 | G13: 0.9 | H13: 13.0008 | I13: 16.67 | J13: 14.7059
B14: 1 | C14: 9.0913 | D14: 16.67 | E14: 12.3091 | G14: 1 | H14: 13.0008 | I14: 16.67 | J14: 14.7059
D16: excel6 | I16: excel6
C18: 合流100m手前（新しい関数） | H18: 合流200m手前（新しい関数）
B19: α | C19: vehicle0 | D19: vehicle1 | E19: all | G19: α | H19: vehicle0 | I19: vehicle1 | J19: all
B20: 0 | C20: 13.406 | D20: 13.807 | E20: 13.6102 | G20: 0 | H20: 15.5361 | I20: 15.7677 | J20: 15.6527
B21: 0.1 | C21: 13.406 | D21: 13.807 | E21: 13.6102 | G21: 0.1 | H21: 15.5361 | I21: 15.7677 | J21: 15.6527
B22: 0.2 | C22: 13.406 | D22: 13.807 | E22: 13.6102 | G22: 0.2 | H22: 14.9596 | I22: 15.5626 | J22: 15.2611
B23: 0.3 | C23: 13.406 | D23: 13.807 | E23: 13.6102 | G23: 0.3 | H23: 14.6901 | I23: 14.854 | J23: 14.7736
B24: 0.4 | C24: 13.5629 | D24: 14.9225 | E24: 14.2454 | G24: 0.4 | H24: 15.6472 | I24: 16.2887 | J24: 15.9661
B25: 0.5 | C25: 12.7514 | D25: 15.4151 | E25: 14.0338 | G25: 0.5 | H25: 15.6472 | I25: 16.2887 | J25: 15.9661
B26: 0.6 | C26: 11.8058 | D26: 15.9295 | E26: 13.7274 | G26: 0.6 | H26: 15.6472 | I26: 16.2887 | J26: 15.9661
B27: 0.7 | C27: 11.0955 | D27: 16.5334 | E27: 13.5504 | G27: 0.7 | H27: 12.9957 | I27: 16.67 | J27: 14.7034
B28: 0.8 | C28: 11.0955 | D28: 16.5334 | E28: 13.5504 | G28: 0.8 | H28: 12.9957 | I28: 16.67 | J28: 14.7034
B29: 0.9 | C29: 9.0913 | D29: 16.67 | E29: 12.3091 | G29: 0.9 | H29: 12.9533 | I29: 16.666 | J29: 14.6766
B30: 1 | C30: 9.0913 | D30: 16.67 | E30: 12.3091 | G30: 1 | H30: 13.0007 | I30: 16.67 | J30: 14.7058
D32: mac | I32: excel4
H34: 合流200m手前（新しい関数） | K34: merge3
G35: α | H35: vehicle0 | I35: vehicle1 | J35: all
G36: 0
G37: 0.1
G38: 0.2
G39: 0.3
G40: 0.4
G41: 0.5
G42: 0.6
G43: 0.7
G44: 0.8
G45: 0.9
...

Sheet seed9
C2: 合流100m手前（元の関数） | H2: 合流200m手前（元の関数）
B3: α | C3: vehicle0 | D3: vehicle1 | E3: all | G3: α | H3: vehicle0 | I3: vehicle1 | J3: all
B4: 0 | C4: 12.631 | D4: 14.4865 | E4: 13.4736 | G4: 0 | H4: 14.6022 | I4: 13.301 | J4: 13.9709
B5: 0.1 | C5: 12.631 | D5: 14.4865 | E5: 13.4736 | G5: 0.1 | H5: 14.5436 | I5: 13.4347 | J5: 14.0056
B6: 0.2 | C6: 11.9938 | D6: 15.0418 | E6: 13.3779 | G6: 0.2 | H6: 13.9937 | I6: 14.8865 | J6: 14.4148
B7: 0.3 | C7: 12.229 | D7: 14.0696 | E7: 13.0404 | G7: 0.3 | H7: 15.1658 | I7: 15.1629 | J7: 15.1644
B8: 0.4 | C8: 11.7595 | D8: 16.4102 | E8: 13.7266 | G8: 0.4 | H8: 13.4078 | I8: 16.1232 | J8: 14.6229
B9: 0.5 | C9: 9.286 | D9: 16.5885 | E9: 12.1634 | G9: 0.5 | H9: 12.105 | I9: 16.5973 | J9: 13.9866
B10: 0.6 | C10: 7.2513 | D10: 16.4197 | E10: 10.5974 | G10: 0.6 | H10: 12.0417 | I10: 16.67 | J10: 13.9693
B11: 0.7 | C11: 7.2513 | D11: 16.4197 | E11: 10.5974 | G11: 0.7 | H11: 12.0417 | I11: 16.67 | J11: 13.9693
B12: 0.8 | C12: 7.2513 | D12: 16.4197 | E12: 10.5974 | G12: 0.8 | H12: 12.0417 | I12: 16.67 | J12: 13.9693
B13: 0.9 | C13: 7.2513 | D13: 16.4197 | E13: 10.5974 | G13: 0.9 | H13: 12.0417 | I13: 16.67 | J13: 13.9693
B14: 1 | C14: 7.2513 | D14: 16.4197 | E14: 10.5974 | G14: 1 | H14: 12.0417 | I14: 16.67 | J14: 13.9693
D16: excel6 | I16: excel6
C18: 合流100m手前（新しい関数） | H18: 合流200m手前（新しい関数）
B19: α | C19: vehicle0 | D19: vehicle1 | E19: all | G19: α | H19: vehicle0 | I19: vehicle1 | J19: all
B20: 0 | C20: 12.631 | D20: 14.4865 | E20: 13.4736 | G20: 0 | H20: 14.6021 | I20: 13.301 | J20: 13.9709
B21: 0.1 | C21: 12.631 | D21: 14.4865 | E21: 13.4736 | G21: 0.1 | H21: 14.6021 | I21: 13.301 | J21: 13.9709
B22: 0.2 | C22: 12.631 | D22: 14.4865 | E22: 13.4736 | G22: 0.2 | H22: 14.51 | I22: 13.3539 | J22: 13.9498
B23: 0.3 | C23: 12.631 | D23: 14.4865 | E23: 13.4736 | G23: 0.3 | H23: 15.2058 | I23: 14.8733 | J23: 15.0465
B24: 0.4 | C24: 12.631 | D24: 14.4865 | E24: 13.4736 | G24: 0.4 | H24: 15.1825 | I24: 14.9359 | J24: 15.0643
B25: 0.5 | C25: 12.631 | D25: 14.4865 | E25: 13.4736 | G25: 0.5 | H25: 14.3581 | I25: 14.9521 | J25: 14.6397
B26: 0.6 | C26: 12.5146 | D26: 15.2796 | E26: 13.7531 | G26: 0.6 | H26: 14.4578 | I26: 15.8551 | J26: 15.1049
B27: 0.7 | C27: 11.7463 | D27: 15.7825 | E27: 13.5027 | G27: 0.7 | H27: 13.2739 | I27: 16.2717 | J27: 14.5907
B28: 0.8 | C28: 11.7595 | D28: 16.4102 | E28: 13.7266 | G28: 0.8 | H28: 12.7865 | I28: 16.561 | J28: 14.4248
B29: 0.9 | C29: 7.2513 | D29: 16.4197 | E29: 10.5974 | G29: 0.9 | H29: 12.0417 | I29: 16.67 | J29: 13.9693
B30: 1 | C30: 7.2513 | D30: 16.4197 | E30: 10.5974 | G30: 1 | H30: 12.0417 | I30: 16.67 | J30: 13.9693
D32: mac | I32: excel4
H34: 合流200m手前（新しい関数） | K34: merge3
G35: α | H35: vehicle0 | I35: vehicle1 | J35: all
G36: 0
G37: 0.1
G38: 0.2
G39: 0.3
G40: 0.4
G41: 0.5
G42: 0.6
G43: 0.7
G44: 0.8
G45: 0.9
...

Sheet seed10
C2: 合流100m手前（元の関数） | H2: 合流200m手前（元の関数）
B3: α | C3: vehicle0 | D3: vehicle1 | E3: all | G3: α | H3: vehicle0 | I3: vehicle1 | J3: all
B4: 0 | C4: 12.4469 | D4: 10.165 | E4: 11.3171 | G4: 0 | H4: 11.9406 | I4: 11.9671 | J4: 11.9531
B5: 0.1 | C5: 12.0421 | D5: 10.6447 | E5: 11.3502 | G5: 0.1 | H5: 13.3506 | I5: 13.3183 | J5: 13.3355
B6: 0.2 | C6: 9.0967 | D6: 16.2325 | E6: 11.9756 | G6: 0.2 | H6: 12.27 | I6: 16.1973 | J6: 13.9688
B7: 0.3 | C7: 9.0967 | D7: 16.2325 | E7: 11.9756 | G7: 0.3 | H7: 12.3586 | I7: 16.3881 | J7: 14.0962
B8: 0.4 | C8: 7.391 | D8: 16.67 | E8: 10.881 | G8: 0.4 | H8: 11.3519 | I8: 16.288 | J8: 13.4119
B9: 0.5 | C9: 7.391 | D9: 16.67 | E9: 10.881 | G9: 0.5 | H9: 10.3764 | I9: 16.4746 | J9: 12.8209
B10: 0.6 | C10: 7.391 | D10: 16.67 | E10: 10.881 | G10: 0.6 | H10: 10.1479 | I10: 16.6279 | J10: 12.7455
B11: 0.7 | C11: 7.391 | D11: 16.67 | E11: 10.881 | G11: 0.7 | H11: 10.1493 | I11: 16.6248 | J11: 12.7464
B12: 0.8 | C12: 7.391 | D12: 16.67 | E12: 10.881 | G12: 0.8 | H12: 10.134 | I12: 16.67 | J12: 12.7557
B13: 0.9 | C13: 7.391 | D13: 16.67 | E13: 10.881 | G13: 0.9 | H13: 10.134 | I13: 16.67 | J13: 12.7557
B14: 1 | C14: 7.391 | D14: 16.67 | E14: 10.881 | G14: 1 | H14: 10.134 | I14: 16.67 | J14: 12.7557
D16: excel6 | I16: excel6
C18: 合流100m手前（新しい関数） | H18: 合流200m手前（新しい関数）
B19: α | C19: vehicle0 | D19: vehicle1 | E19: all | G19: α | H19: vehicle0 | I19: vehicle1 | J19: all
B20: 0 | C20: 12.4469 | D20: 10.165 | E20: 11.3171 | G20: 0 | H20: 11.9406 | I20: 11.9671 | J20: 11.9531
B21: 0.1 | C21: 12.4469 | D21: 10.165 | E21: 11.3171 | G21: 0.1 | H21: 11.9406 | I21: 11.9671 | J21: 11.9531
B22: 0.2 | C22: 12.4469 | D22: 10.165 | E22: 11.3171 | G22: 0.2 | H22: 11.9406 | I22: 11.9671 | J22: 11.9531
B23: 0.3 | C23: 12.4469 | D23: 10.165 | E23: 11.3171 | G23: 0.3 | H23: 11.9406 | I23: 11.9671 | J23: 11.9531
B24: 0.4 | C24: 12.0642 | D24: 11.1582 | E24: 11.6159 | G24: 0.4 | H24: 12.0659 | I24: 12.6706 | J24: 12.3475
B25: 0.5 | C25: 11.0705 | D25: 12.4636 | E25: 11.747 | G25: 0.5 | H25: 12.9608 | I25: 14.2486 | J25: 13.5621
B26: 0.6 | C26: 9.9263 | D26: 15.0384 | E26: 12.0537 | G26: 0.6 | H26: 11.566 | I26: 13.5323 | J26: 12.466
B27: 0.7 | C27: 9.5278 | D27: 15.511 | E27: 11.9868 | G27: 0.7 | H27: 12.3569 | I27: 16.3762 | J27: 14.0906
B28: 0.8 | C28: 8.9174 | D28: 15.6244 | E28: 11.6568 | G28: 0.8 | H28: 10.1492 | I28: 16.6248 | J28: 12.7464
B29: 0.9 | C29: 7.391 | D29: 16.67 | E29: 10.881 | G29: 0.9 | H29: 10.1371 | I29: 16.6695 | J29: 12.757
B30: 1 | C30: 7.391 | D30: 16.67 | E30: 10.881 | G30: 1 | H30: 10.134 | I30: 16.67 | J30: 12.7557
D32: mac | I32: excel4
H34: 合流200m手前（新しい関数） | K34: merge3
G35: α | H35: vehicle0 | I35: vehicle1 | J35: all
G36: 0
G37: 0.1
G38: 0.2
G39: 0.3
G40: 0.4
G41: 0.5
G42: 0.6
G43: 0.7
G44: 0.8
G45: 0.9
...

Sheet average
C2: 合流100m手前（元の関数） | H2: 合流200m手前（元の関数） | O2: 合流200m手前
B3: α | C3: vehicle0 | D3: vehicle1 | E3: all | G3: α | H3: vehicle0 | I3: vehicle1 | J3: all | N3: α | O3: 後続考慮あり | P3: 後続考慮なし
B4: 0 | C4: =ROUND(AVERAGE(seed1!C4,seed2!C4,seed3!C4,seed4!C4,seed5!C4,seed7!C4,seed8!C4,seed9!C4,seed10!C4),4) -> 12.9504 | D4: =ROUND(AVERAGE(seed1!D4,seed2!D4,seed3!D4,seed4!D4,seed5!D4,seed7!D4,seed8!D4,seed9!D4,seed10!D4),4) -> 13.307 | E4: =ROUND(AVERAGE(seed1!E4,seed2!E4,seed3!E4,seed4!E4,seed5!E4,seed7!E4,seed8!E4,seed9!E4,seed10!E4),4) -> 13.0751 | G4: 0 | H4: =ROUND(AVERAGE(seed1!H4,seed2!H4,seed3!H4,seed4!H4,seed5!H4,seed7!H4,seed8!H4,seed9!H4,seed10!H4),4) -> 14.8078 | I4: =ROUND(AVERAGE(seed1!I4,seed2!I4,seed3!I4,seed4!I4,seed5!I4,seed7!I4,seed8!I4,seed9!I4,seed10!I4),4) -> 13.871 | J4: =ROUND(AVERAGE(seed1!J4,seed2!J4,seed3!J4,seed4!J4,seed5!J4,seed7!J4,seed8!J4,seed9!J4,seed10!J4),4) -> 14.3487 | N4: 0 | O4: =J20 -> 14.3486 | P4: =J4 -> 14.3487
B5: 0.1 | C5: =ROUND(AVERAGE(seed1!C5,seed2!C5,seed3!C5,seed4!C5,seed5!C5,seed7!C5,seed8!C5,seed9!C5,seed10!C5),4) -> 12.7802 | D5: =ROUND(AVERAGE(seed1!D5,seed2!D5,seed3!D5,seed4!D5,seed5!D5,seed7!D5,seed8!D5,seed9!D5,seed10!D5),4) -> 13.5918 | E5: =ROUND(AVERAGE(seed1!E5,seed2!E5,seed3!E5,seed4!E5,seed5!E5,seed7!E5,seed8!E5,seed9!E5,seed10!E5),4) -> 13.1299 | G5: 0.1 | H5: =ROUND(AVERAGE(seed1!H5,seed2!H5,seed3!H5,seed4!H5,seed5!H5,seed7!H5,seed8!H5,seed9!H5,seed10!H5),4) -> 14.7796 | I5: =ROUND(AVERAGE(seed1!I5,seed2!I5,seed3!I5,seed4!I5,seed5!I5,seed7!I5,seed8!I5,seed9!I5,seed10!I5),4) -> 14.388 | J5: =ROUND(AVERAGE(seed1!J5,seed2!J5,seed3!J5,seed4!J5,seed5!J5,seed7!J5,seed8!J5,seed9!J5,seed10!J5),4) -> 14.5893 | N5: 0.1 | O5: =J21 -> 14.3486 | P5: =J5 -> 14.5893
B6: 0.2 | C6: =ROUND(AVERAGE(seed1!C6,seed2!C6,seed3!C6,seed4!C6,seed5!C6,seed7!C6,seed8!C6,seed9!C6,seed10!C6),4) -> 11.8863 | D6: =ROUND(AVERAGE(seed1!D6,seed2!D6,seed3!D6,seed4!D6,seed5!D6,seed7!D6,seed8!D6,seed9!D6,seed10!D6),4) -> 15.2959 | E6: =ROUND(AVERAGE(seed1!E6,seed2!E6,seed3!E6,seed4!E6,seed5!E6,seed7!E6,seed8!E6,seed9!E6,seed10!E6),4) -> 13.405 | G6: 0.2 | H6: =ROUND(AVERAGE(seed1!H6,seed2!H6,seed3!H6,seed4!H6,seed5!H6,seed7!H6,seed8!H6,seed9!H6,seed10!H6),4) -> 14.3621 | I6: =ROUND(AVERAGE(seed1!I6,seed2!I6,seed3!I6,seed4!I6,seed5!I6,seed7!I6,seed8!I6,seed9!I6,seed10!I6),4) -> 15.6972 | J6: =ROUND(AVERAGE(seed1!J6,seed2!J6,seed3!J6,seed4!J6,seed5!J6,seed7!J6,seed8!J6,seed9!J6,seed10!J6),4) -> 14.977 | N6: 0.2 | O6: =J22 -> 14.3905 | P6: =J6 -> 14.977
B7: 0.3 | C7: =ROUND(AVERAGE(seed1!C7,seed2!C7,seed3!C7,seed4!C7,seed5!C7,seed7!C7,seed8!C7,seed9!C7,seed10!C7),4) -> 11.1383 | D7: =ROUND(AVERAGE(seed1!D7,seed2!D7,seed3!D7,seed4!D7,seed5!D7,seed7!D7,seed8!D7,seed9!D7,seed10!D7),4) -> 15.8815 | E7: =ROUND(AVERAGE(seed1!E7,seed2!E7,seed3!E7,seed4!E7,seed5!E7,seed7!E7,seed8!E7,seed9!E7,seed10!E7),4) -> 13.2128 | G7: 0.3 | H7: =ROUND(AVERAGE(seed1!H7,seed2!H7,seed3!H7,seed4!H7,seed5!H7,seed7!H7,seed8!H7,seed9!H7,seed10!H7),4) -> 14.3549 | I7: =ROUND(AVERAGE(seed1!I7,seed2!I7,seed3!I7,seed4!I7,seed5!I7,seed7!I7,seed8!I7,seed9!I7,seed10!I7),4) -> 15.9802 | J7: =ROUND(AVERAGE(seed1!J7,seed2!J7,seed3!J7,seed4!J7,seed5!J7,seed7!J7,seed8!J7,seed9!J7,seed10!J7),4) -> 15.1038 | N7: 0.3 | O7: =J23 -> 14.4561 | P7: =J7 -> 15.1038
B8: 0.4 | C8: =ROUND(AVERAGE(seed1!C8,seed2!C8,seed3!C8,seed4!C8,seed5!C8,seed7!C8,seed8!C8,seed9!C8,seed10!C8),4) -> 10.6933 | D8: =ROUND(AVERAGE(seed1!D8,seed2!D8,seed3!D8,seed4!D8,seed5!D8,seed7!D8,seed8!D8,seed9!D8,seed10!D8),4) -> 16.4149 | E8: =ROUND(AVERAGE(seed1!E8,seed2!E8,seed3!E8,seed4!E8,seed5!E8,seed7!E8,seed8!E8,seed9!E8,seed10!E8),4) -> 13.1193 | G8: 0.4 | H8: =ROUND(AVERAGE(seed1!H8,seed2!H8,seed3!H8,seed4!H8,seed5!H8,seed7!H8,seed8!H8,seed9!H8,seed10!H8),4) -> 13.2238 | I8: =ROUND(AVERAGE(seed1!I8,seed2!I8,seed3!I8,seed4!I8,seed5!I8,seed7!I8,seed8!I8,seed9!I8,seed10!I8),4) -> 16.3787 | J8: =ROUND(AVERAGE(seed1!J8,seed2!J8,seed3!J8,seed4!J8,seed5!J8,seed7!J8,seed8!J8,seed9!J8,seed10!J8),4) -> 14.6397 | N8: 0.4 | O8: =J24 -> 14.6643 | P8: =J8 -> 14.6397
B9: 0.5 | C9: =ROUND(AVERAGE(seed1!C9,seed2!C9,seed3!C9,seed4!C9,seed5!C9,seed7!C9,seed8!C9,seed9!C9,seed10!C9),4) -> 9.3381 | D9: =ROUND(AVERAGE(seed1!D9,seed2!D9,seed3!D9,seed4!D9,seed5!D9,seed7!D9,seed8!D9,seed9!D9,seed10!D9),4) -> 16.614 | E9: =ROUND(AVERAGE(seed1!E9,seed2!E9,seed3!E9,seed4!E9,seed5!E9,seed7!E9,seed8!E9,seed9!E9,seed10!E9),4) -> 12.3451 | G9: 0.5 | H9: =ROUND(AVERAGE(seed1!H9,seed2!H9,seed3!H9,seed4!H9,seed5!H9,seed7!H9,seed8!H9,seed9!H9,seed10!H9),4) -> 12.0645 | I9: =ROUND(AVERAGE(seed1!I9,seed2!I9,seed3!I9,seed4!I9,seed5!I9,seed7!I9,seed8!I9,seed9!I9,seed10!I9),4) -> 16.597 | J9: =ROUND(AVERAGE(seed1!J9,seed2!J9,seed3!J9,seed4!J9,seed5!J9,seed7!J9,seed8!J9,seed9!J9,seed10!J9),4) -> 14.0508 | N9: 0.5 | O9: =J25 -> 14.9031 | P9: =J9 -> 14.0508
B10: 0.6 | C10: =ROUND(AVERAGE(seed1!C10,seed2!C10,seed3!C10,seed4!C10,seed5!C10,seed7!C10,seed8!C10,seed9!C10,seed10!C10),4) -> 8.7685 | D10: =ROUND(AVERAGE(seed1!D10,seed2!D10,seed3!D10,seed4!D10,seed5!D10,seed7!D10,seed8!D10,seed9!D10,seed10!D10),4) -> 16.6157 | E10: =ROUND(AVERAGE(seed1!E10,seed2!E10,seed3!E10,seed4!E10,seed5!E10,seed7!E10,seed8!E10,seed9!E10,seed10!E10),4) -> 11.9496 | G10: 0.6 | H10: =ROUND(AVERAGE(seed1!H10,seed2!H10,seed3!H10,seed4!H10,seed5!H10,seed7!H10,seed8!H10,seed9!H10,seed10!H10),4) -> 11.8711 | I10: =ROUND(AVERAGE(seed1!I10,seed2!I10,seed3!I10,seed4!I10,seed5!I10,seed7!I10,seed8!I10,seed9!I10,seed10!I10),4) -> 16.6398 | J10: =ROUND(AVERAGE(seed1!J10,seed2!J10,seed3!J10,seed4!J10,seed5!J10,seed7!J10,seed8!J10,seed9!J10,seed10!J10),4) -> 13.9439 | N10: 0.6 | O10: =J26 -> 14.9489 | P10: =J10 -> 13.9439
B11: 0.7 | C11: =ROUND(AVERAGE(seed1!C11,seed2!C11,seed3!C11,seed4!C11,seed5!C11,seed7!C11,seed8!C11,seed9!C11,seed10!C11),4) -> 8.5137 | D11: =ROUND(AVERAGE(seed1!D11,seed2!D11,seed3!D11,seed4!D11,seed5!D11,seed7!D11,seed8!D11,seed9!D11,seed10!D11),4) -> 16.6213 | E11: =ROUND(AVERAGE(seed1!E11,seed2!E11,seed3!E11,seed4!E11,seed5!E11,seed7!E11,seed8!E11,seed9!E11,seed10!E11),4) -> 11.7797 | G11: 0.7 | H11: =ROUND(AVERAGE(seed1!H11,seed2!H11,seed3!H11,seed4!H11,seed5!H11,seed7!H11,seed8!H11,seed9!H11,seed10!H11),4) -> 11.8332 | I11: =ROUND(AVERAGE(seed1!I11,seed2!I11,seed3!I11,seed4!I11,seed5!I11,seed7!I11,seed8!I11,seed9!I11,seed10!I11),4) -> 16.6645 | J11: =ROUND(AVERAGE(seed1!J11,seed2!J11,seed3!J11,seed4!J11,seed5!J11,seed7!J11,seed8!J11,seed9!J11,seed10!J11),4) -> 13.9334 | N11: 0.7 | O11: =J27 -> 14.7089 | P11: =J11 -> 13.9334
B12: 0.8 | C12: =ROUND(AVERAGE(seed1!C12,seed2!C12,seed3!C12,seed4!C12,seed5!C12,seed7!C12,seed8!C12,seed9!C12,seed10!C12),4) -> 8.5137 | D12: =ROUND(AVERAGE(seed1!D12,seed2!D12,seed3!D12,seed4!D12,seed5!D12,seed7!D12,seed8!D12,seed9!D12,seed10!D12),4) -> 16.6213 | E12: =ROUND(AVERAGE(seed1!E12,seed2!E12,seed3!E12,seed4!E12,seed5!E12,seed7!E12,seed8!E12,seed9!E12,seed10!E12),4) -> 11.7797 | G12: 0.8 | H12: =ROUND(AVERAGE(seed1!H12,seed2!H12,seed3!H12,seed4!H12,seed5!H12,seed7!H12,seed8!H12,seed9!H12,seed10!H12),4) -> 11.8317 | I12: =ROUND(AVERAGE(seed1!I12,seed2!I12,seed3!I12,seed4!I12,seed5!I12,seed7!I12,seed8!I12,seed9!I12,seed10!I12),4) -> 16.67 | J12: =ROUND(AVERAGE(seed1!J12,seed2!J12,seed3!J12,seed4!J12,seed5!J12,seed7!J12,seed8!J12,seed9!J12,seed10!J12),4) -> 13.9347 | N12: 0.8 | O12: =J28 -> 14.2452 | P12: =J12 -> 13.9347
B13: 0.9 | C13: =ROUND(AVERAGE(seed1!C13,seed2!C13,seed3!C13,seed4!C13,seed5!C13,seed7!C13,seed8!C13,seed9!C13,seed10!C13),4) -> 8.5137 | D13: =ROUND(AVERAGE(seed1!D13,seed2!D13,seed3!D13,seed4!D13,seed5!D13,seed7!D13,seed8!D13,seed9!D13,seed10!D13),4) -> 16.6213 | E13: =ROUND(AVERAGE(seed1!E13,seed2!E13,seed3!E13,seed4!E13,seed5!E13,seed7!E13,seed8!E13,seed9!E13,seed10!E13),4) -> 11.7797 | G13: 0.9 | H13: =ROUND(AVERAGE(seed1!H13,seed2!H13,seed3!H13,seed4!H13,seed5!H13,seed7!H13,seed8!H13,seed9!H13,seed10!H13),4) -> 11.8317 | I13: =ROUND(AVERAGE(seed1!I13,seed2!I13,seed3!I13,seed4!I13,seed5!I13,seed7!I13,seed8!I13,seed9!I13,seed10!I13),4) -> 16.67 | J13: =ROUND(AVERAGE(seed1!J13,seed2!J13,seed3!J13,seed4!J13,seed5!J13,seed7!J13,seed8!J13,seed9!J13,seed10!J13),4) -> 13.9347 | N13: 0.9 | O13: =J29 -> 13.9316 | P13: =J13 -> 13.9347
B14: 1 | C14: =ROUND(AVERAGE(seed1!C14,seed2!C14,seed3!C14,seed4!C14,seed5!C14,seed7!C14,seed8!C14,seed9!C14,seed10!C14),4) -> 8.5137 | D14: =ROUND(AVERAGE(seed1!D14,seed2!D14,seed3!D14,seed4!D14,seed5!D14,seed7!D14,seed8!D14,seed9!D14,seed10!D14),4) -> 16.6213 | E14: =ROUND(AVERAGE(seed1!E14,seed2!E14,seed3!E14,seed4!E14,seed5!E14,seed7!E14,seed8!E14,seed9!E14,seed10!E14),4) -> 11.7797 | G14: 1 | H14: =ROUND(AVERAGE(seed1!H14,seed2!H14,seed3!H14,seed4!H14,seed5!H14,seed7!H14,seed8!H14,seed9!H14,seed10!H14),4) -> 11.8317 | I14: =ROUND(AVERAGE(seed1!I14,seed2!I14,seed3!I14,seed4!I14,seed5!I14,seed7!I14,seed8!I14,seed9!I14,seed10!I14),4) -> 16.67 | J14: =ROUND(AVERAGE(seed1!J14,seed2!J14,seed3!J14,seed4!J14,seed5!J14,seed7!J14,seed8!J14,seed9!J14,seed10!J14),4) -> 13.9347 | N14: 1 | O14: =J30 -> 13.9347 | P14: =J14 -> 13.9347
C18: 合流100m手前（新しい関数） | H18: 合流200m手前（新しい関数） | O18: 後続考慮
B19: α | C19: vehicle0 | D19: vehicle1 | E19: all | G19: α | H19: vehicle0 | I19: vehicle1 | J19: all | N19: α | O19: 100m手前 | P19: 200m手前
B20: 0 | C20: =ROUND(AVERAGE(seed1!C20,seed2!C20,seed3!C20,seed4!C20,seed5!C20,seed7!C20,seed8!C20,seed9!C20,seed10!C20),4) -> 12.9504 | D20: =ROUND(AVERAGE(seed1!D20,seed2!D20,seed3!D20,seed4!D20,seed5!D20,seed7!D20,seed8!D20,seed9!D20,seed10!D20),4) -> 13.307 | E20: =ROUND(AVERAGE(seed1!E20,seed2!E20,seed3!E20,seed4!E20,seed5!E20,seed7!E20,seed8!E20,seed9!E20,seed10!E20),4) -> 13.0751 | G20: 0 | H20: =ROUND(AVERAGE(seed1!H20,seed2!H20,seed3!H20,seed4!H20,seed5!H20,seed7!H20,seed8!H20,seed9!H20,seed10!H20),4) -> 14.8078 | I20: =ROUND(AVERAGE(seed1!I20,seed2!I20,seed3!I20,seed4!I20,seed5!I20,seed7!I20,seed8!I20,seed9!I20,seed10!I20),4) -> 13.871 | J20: =ROUND(AVERAGE(seed1!J20,seed2!J20,seed3!J20,seed4!J20,seed5!J20,seed7!J20,seed8!J20,seed9!J20,seed10!J20),4) -> 14.3486 | N20: 0 | O20: =E20 -> 13.0751 | P20: =J20 -> 14.3486
B21: 0.1 | C21: =ROUND(AVERAGE(seed1!C21,seed2!C21,seed3!C21,seed4!C21,seed5!C21,seed7!C21,seed8!C21,seed9!C21,seed10!C21),4) -> 12.9504 | D21: =ROUND(AVERAGE(seed1!D21,seed2!D21,seed3!D21,seed4!D21,seed5!D21,seed7!D21,seed8!D21,seed9!D21,seed10!D21),4) -> 13.307 | E21: =ROUND(AVERAGE(seed1!E21,seed2!E21,seed3!E21,seed4!E21,seed5!E21,seed7!E21,seed8!E21,seed9!E21,seed10!E21),4) -> 13.0751 | G21: 0.1 | H21: =ROUND(AVERAGE(seed1!H21,seed2!H21,seed3!H21,seed4!H21,seed5!H21,seed7!H21,seed8!H21,seed9!H21,seed10!H21),4) -> 14.8078 | I21: =ROUND(AVERAGE(seed1!I21,seed2!I21,seed3!I21,seed4!I21,seed5!I21,seed7!I21,seed8!I21,seed9!I21,seed10!I21),4) -> 13.871 | J21: =ROUND(AVERAGE(seed1!J21,seed2!J21,seed3!J21,seed4!J21,seed5!J21,seed7!J21,seed8!J21,seed9!J21,seed10!J21),4) -> 14.3486 | N21: 0.1 | O21: =E21 -> 13.0751 | P21: =J21 -> 14.3486
B22: 0.2 | C22: =ROUND(AVERAGE(seed1!C22,seed2!C22,seed3!C22,seed4!C22,seed5!C22,seed7!C22,seed8!C22,seed9!C22,seed10!C22),4) -> 12.9504 | D22: =ROUND(AVERAGE(seed1!D22,seed2!D22,seed3!D22,seed4!D22,seed5!D22,seed7!D22,seed8!D22,seed9!D22,seed10!D22),4) -> 13.307 | E22: =ROUND(AVERAGE(seed1!E22,seed2!E22,seed3!E22,seed4!E22,seed5!E22,seed7!E22,seed8!E22,seed9!E22,seed10!E22),4) -> 13.0751 | G22: 0.2 | H22: =ROUND(AVERAGE(seed1!H22,seed2!H22,seed3!H22,seed4!H22,seed5!H22,seed7!H22,seed8!H22,seed9!H22,seed10!H22),4) -> 14.6629 | I22: =ROUND(AVERAGE(seed1!I22,seed2!I22,seed3!I22,seed4!I22,seed5!I22,seed7!I22,seed8!I22,seed9!I22,seed10!I22),4) -> 14.0996 | J22: =ROUND(AVERAGE(seed1!J22,seed2!J22,seed3!J22,seed4!J22,seed5!J22,seed7!J22,seed8!J22,seed9!J22,seed10!J22),4) -> 14.3905 | N22: 0.2 | O22: =E22 -> 13.0751 | P22: =J22 -> 14.3905
B23: 0.3 | C23: =ROUND(AVERAGE(seed1!C23,seed2!C23,seed3!C23,seed4!C23,seed5!C23,seed7!C23,seed8!C23,seed9!C23,seed10!C23),4) -> 12.9533 | D23: =ROUND(AVERAGE(seed1!D23,seed2!D23,seed3!D23,seed4!D23,seed5!D23,seed7!D23,seed8!D23,seed9!D23,seed10!D23),4) -> 13.3066 | E23: =ROUND(AVERAGE(seed1!E23,seed2!E23,seed3!E23,seed4!E23,seed5!E23,seed7!E23,seed8!E23,seed9!E23,seed10!E23),4) -> 13.093 | G23: 0.3 | H23: =ROUND(AVERAGE(seed1!H23,seed2!H23,seed3!H23,seed4!H23,seed5!H23,seed7!H23,seed8!H23,seed9!H23,seed10!H23),4) -> 14.6335 | I23: =ROUND(AVERAGE(seed1!I23,seed2!I23,seed3!I23,seed4!I23,seed5!I23,seed7!I23,seed8!I23,seed9!I23,seed10!I23),4) -> 14.2648 | J23: =ROUND(AVERAGE(seed1!J23,seed2!J23,seed3!J23,seed4!J23,seed5!J23,seed7!J23,seed8!J23,seed9!J23,seed10!J23),4) -> 14.4561 | N23: 0.3 | O23: =E23 -> 13.093 | P23: =J23 -> 14.4561
