Workbook

Sheet 範囲100_seed1
C2: 合流200m手前（後続100） | E2: 1000/1000 | H2: 合流200m手前（後続100） | J2: 750/750
B3: α | C3: vehicle0 | D3: vehicle1 | E3: all | G3: α | H3: vehicle0 | I3: vehicle1 | J3: all
B4: 0 | C4: 14.7243 | D4: 13.2237 | E4: 13.9829 | G4: 0
B5: 0.1 | C5: 14.7243 | D5: 13.2237 | E5: 13.9829 | G5: 0.1
B6: 0.2 | C6: 14.7243 | D6: 13.2237 | E6: 13.9829 | G6: 0.2
B7: 0.3 | C7: 14.7234 | D7: 13.2269 | E7: 13.984 | G7: 0.3
B8: 0.4 | C8: 14.7234 | D8: 13.2269 | E8: 13.984 | G8: 0.4
B9: 0.5 | C9: 14.4103 | D9: 13.6697 | E9: 14.0444 | G9: 0.5
B10: 0.6 | C10: 12.2583 | D10: 13.8111 | E10: 12.9761 | G10: 0.6
B11: 0.7 | C11: 12.3103 | D11: 16.0743 | E11: 13.9748 | G11: 0.7
B12: 0.8 | C12: 11.0227 | D12: 16.648 | E12: 13.4449 | G12: 0.8
B13: 0.9 | C13: 10.9337 | D13: 16.67 | E13: 13.4038 | G13: 0.9
B14: 1 | C14: 10.9337 | D14: 16.67 | E14: 13.4038 | G14: 1
D16: mac
C18: 合流200m手前（後続100） | E18: 1250/750 | H18: 合流200m手前（後続100） | J18: 750/1250
B19: α | C19: vehicle0 | D19: vehicle1 | E19: all | G19: α | H19: vehicle0 | I19: vehicle1 | J19: all
B20: 0 | C20: 11.6867 | D20: 12.6771 | E20: 12.0491 | G20: 0
B21: 0.1 | C21: 11.6867 | D21: 12.6771 | E21: 12.0491 | G21: 0.1
B22: 0.2 | C22: 12.742 | D22: 12.4678 | E22: 12.64 | G22: 0.2
B23: 0.3 | C23: 12.6613 | D23: 11.8896 | E23: 12.3752 | G23: 0.3
B24: 0.4 | C24: 12.5256 | D24: 13.4596 | E24: 12.8666 | G24: 0.4
B25: 0.5 | C25: 12.8198 | D25: 12.7034 | E25: 12.7772 | G25: 0.5
B26: 0.6 | C26: 12.4483 | D26: 14.1194 | E26: 13.051 | G26: 0.6
B27: 0.7 | C27: 11.8935 | D27: 15.7755 | E27: 13.2037 | G27: 0.7
B28: 0.8 | C28: 11.6481 | D28: 16.4962 | E28: 13.2839 | G28: 0.8
B29: 0.9 | C29: 11.5212 | D29: 16.67 | E29: 13.2373 | G29: 0.9
B30: 1 | C30: 11.5212 | D30: 16.67 | E30: 13.2373 | G30: 1
D32: mac

Sheet 範囲150_seed1
C2: 合流200m手前（後続150） | E2: 1000/1000
B3: α | C3: vehicle0 | D3: vehicle1 | E3: all
B4: 0 | C4: 14.7243 | D4: 13.2237 | E4: 13.9829
B5: 0.1 | C5: 14.7243 | D5: 13.2237 | E5: 13.9829
B6: 0.2 | C6: 14.7243 | D6: 13.2237 | E6: 13.9829
B7: 0.3 | C7: 14.7234 | D7: 13.2269 | E7: 13.984
B8: 0.4 | C8: 14.7234 | D8: 13.2269 | E8: 13.984
B9: 0.5 | C9: 14.3002 | D9: 13.9987 | E9: 14.1521
B10: 0.6 | C10: 14.2351 | D10: 15.173 | E10: 14.6927
B11: 0.7 | C11: 13.4083 | D11: 16.2329 | E11: 14.7154
B12: 0.8 | C12: 10.9337 | D12: 16.67 | E12: 13.4038
B13: 0.9 | C13: 10.9337 | D13: 16.67 | E13: 13.4038
B14: 1 | C14: 10.9337 | D14: 16.67 | E14: 13.4038
D16: mac
C18: 合流200m手前（後続150） | E18: 1250/750
B19: α | C19: vehicle0 | D19: vehicle1 | E19: all
B20: 0 | C20: 11.6867 | D20: 12.6771 | E20: 12.0491
B21: 0.1 | C21: 11.6867 | D21: 12.6771 | E21: 12.0491
B22: 0.2 | C22: 14.2498 | D22: 11.4428 | E22: 13.1637
B23: 0.3 | C23: 12.2293 | D23: 12.17 | E23: 12.2073
B24: 0.4 | C24: 12.5256 | D24: 13.4596 | E24: 12.8666
B25: 0.5 | C25: 12.218 | D25: 13.3914 | E25: 12.6407
B26: 0.6 | C26: 12.4239 | D26: 14.4708 | E26: 13.1622
B27: 0.7 | C27: 12.7292 | D27: 13.9778 | E27: 13.1802
B28: 0.8 | C28: 11.6481 | D28: 16.4962 | E28: 13.2839
B29: 0.9 | C29: 11.5212 | D29: 16.67 | E29: 13.2373
B30: 1 | C30: 11.5212 | D30: 16.67 | E30: 13.2373
D32: mac

Sheet 範囲200_seed1
C2: 合流200m手前（後続200） | E2: 1000/1000 | H2: 合流200m手前（後続200） | J2: 750/750 | O2: 1250/750 | U2: 1000/1000
B3: α | C3: vehicle0 | D3: vehicle1 | E3: all | G3: α | H3: vehicle0 | I3: vehicle1 | J3: all | N3: α | O3: 範囲内全て | P3: 後方200m | Q3: 後方100m | R3: 後方150m | T3: α | U3: 範囲内全て | V3: 後方200m | W3: 後方100m
B4: 0 | C4: 14.7243 | D4: 13.2237 | E4: 13.9829 | G4: 0 | N4: 0 | O4: 12.0491 | P4: =E20 -> 12.0491 | Q4: =範囲100_seed1!E20 -> 12.0491 | R4: =範囲150_seed1!E20 -> 12.0491 | T4: 0 | U4: 13.9828 | V4: =E4 -> 13.9829 | W4: =範囲100_seed1!E4 -> 13.9829
B5: 0.1 | C5: 14.7243 | D5: 13.2237 | E5: 13.9829 | G5: 0.1 | N5: 0.1 | O5: 12.0491 | P5: =E21 -> 12.0491 | Q5: =範囲100_seed1!E21 -> 12.0491 | R5: =範囲150_seed1!E21 -> 12.0491 | T5: 0.1 | U5: 13.9828 | V5: =E5 -> 13.9829 | W5: =範囲100_seed1!E5 -> 13.9829
B6: 0.2 | C6: 14.7243 | D6: 13.2237 | E6: 13.9829 | G6: 0.2 | N6: 0.2 | O6: 12.0491 | P6: =E22 -> 12.0491 | Q6: =範囲100_seed1!E22 -> 12.64 | R6: =範囲150_seed1!E22 -> 13.1637 | T6: 0.2 | U6: 13.9828 | V6: =E6 -> 13.9829 | W6: =範囲100_seed1!E6 -> 13.9829
B7: 0.3 | C7: 14.7234 | D7: 13.2269 | E7: 13.984 | G7: 0.3 | N7: 0.3 | O7: 12.0491 | P7: =E23 -> 12.0491 | Q7: =範囲100_seed1!E23 -> 12.3752 | R7: =範囲150_seed1!E23 -> 12.2073 | T7: 0.3 | U7: 13.984 | V7: =E7 -> 13.984 | W7: =範囲100_seed1!E7 -> 13.984
B8: 0.4 | C8: 14.7234 | D8: 13.2269 | E8: 13.984 | G8: 0.4 | N8: 0.4 | O8: 12.0491 | P8: =E24 -> 12.8948 | Q8: =範囲100_seed1!E24 -> 12.8666 | R8: =範囲150_seed1!E24 -> 12.8666 | T8: 0.4 | U8: 13.984 | V8: =E8 -> 13.984 | W8: =範囲100_seed1!E8 -> 13.984
B9: 0.5 | C9: 14.4062 | D9: 13.6768 | E9: 14.0458 | G9: 0.5 | N9: 0.5 | O9: 13.3705 | P9: =E25 -> 12.6545 | Q9: =範囲100_seed1!E25 -> 12.7772 | R9: =範囲150_seed1!E25 -> 12.6407 | T9: 0.5 | U9: 14.0458 | V9: =E9 -> 14.0458 | W9: =範囲100_seed1!E9 -> 14.0444
B10: 0.6 | C10: 14.2351 | D10: 15.173 | E10: 14.6927 | G10: 0.6 | N10: 0.6 | O10: 13.1826 | P10: =E26 -> 13.1826 | Q10: =範囲100_seed1!E26 -> 13.051 | R10: =範囲150_seed1!E26 -> 13.1622 | T10: 0.6 | U10: 14.6927 | V10: =E10 -> 14.6927 | W10: =範囲100_seed1!E10 -> 12.9761
B11: 0.7 | C11: 13.3844 | D11: 16.2527 | E11: 14.7117 | G11: 0.7 | N11: 0.7 | O11: 12.5399 | P11: =E27 -> 12.5399 | Q11: =範囲100_seed1!E27 -> 13.2037 | R11: =範囲150_seed1!E27 -> 13.1802 | T11: 0.7 | U11: 14.7117 | V11: =E11 -> 14.7117 | W11: =範囲100_seed1!E11 -> 13.9748
B12: 0.8 | C12: 10.9337 | D12: 16.67 | E12: 13.4038 | G12: 0.8 | N12: 0.8 | O12: 13.2839 | P12: =E28 -> 13.2839 | Q12: =範囲100_seed1!E28 -> 13.2839 | R12: =範囲150_seed1!E28 -> 13.2839 | T12: 0.8 | U12: 13.4037 | V12: =E12 -> 13.4038 | W12: =範囲100_seed1!E12 -> 13.4449
B13: 0.9 | C13: 10.9337 | D13: 16.67 | E13: 13.4038 | G13: 0.9 | N13: 0.9 | O13: 13.2372 | P13: =E29 -> 13.2373 | Q13: =範囲100_seed1!E29 -> 13.2373 | R13: =範囲150_seed1!E29 -> 13.2373 | T13: 0.9 | U13: 13.4037 | V13: =E13 -> 13.4038 | W13: =範囲100_seed1!E13 -> 13.4038
B14: 1 | C14: 10.9337 | D14: 16.67 | E14: 13.4038 | G14: 1 | N14: 1 | O14: 13.2372 | P14: =E30 -> 13.2373 | Q14: =範囲100_seed1!E30 -> 13.2373 | R14: =範囲150_seed1!E30 -> 13.2373 | T14: 1 | U14: 13.4037 | V14: =E14 -> 13.4038 | W14: =範囲100_seed1!E14 -> 13.4038
D16: mac
C18: 合流200m手前（後続200） | E18: 1250/750 | H18: 合流200m手前（後続200） | J18: 750/1250
B19: α | C19: vehicle0 | D19: vehicle1 | E19: all | G19: α | H19: vehicle0 | I19: vehicle1 | J19: all
B20: 0 | C20: 11.6867 | D20: 12.6771 | E20: 12.0491 | G20: 0
B21: 0.1 | C21: 11.6867 | D21: 12.6771 | E21: 12.0491 | G21: 0.1
B22: 0.2 | C22: 11.6867 | D22: 12.6771 | E22: 12.0491 | G22: 0.2
B23: 0.3 | C23: 11.6867 | D23: 12.6771 | E23: 12.0491 | G23: 0.3
B24: 0.4 | C24: 12.1564 | D24: 14.2231 | E24: 12.8948 | G24: 0.4
B25: 0.5 | C25: 11.8526 | D25: 14.108 | E25: 12.6545 | G25: 0.5
B26: 0.6 | C26: 12.4242 | D26: 14.5269 | E26: 13.1826 | G26: 0.6
B27: 0.7 | C27: 11.4368 | D27: 14.5005 | E27: 12.5399 | G27: 0.7
B28: 0.8 | C28: 11.6481 | D28: 16.4962 | E28: 13.2839 | G28: 0.8
B29: 0.9 | C29: 11.5212 | D29: 16.67 | E29: 13.2373 | G29: 0.9
B30: 1 | C30: 11.5212 | D30: 16.67 | E30: 13.2373 | G30: 1
D32: mac

Sheet seed1
C2: 合流200m手前（後続120） | E2: 1000/1000 | H2: 合流200m手前（後続120） | J2: 750/750
B3: α | C3: vehicle0 | D3: vehicle1 | E3: all | G3: α | H3: vehicle0 | I3: vehicle1 | J3: all
B4: 0 | C4: 14.7243 | D4: 13.2237 | E4: 13.9829 | G4: 0
B5: 0.1 | C5: 14.7243 | D5: 13.2237 | E5: 13.9829 | G5: 0.1
B6: 0.2 | C6: 14.7243 | D6: 13.2237 | E6: 13.9829 | G6: 0.2
B7: 0.3 | C7: 14.7234 | D7: 13.2269 | E7: 13.984 | G7: 0.3
B8: 0.4 | C8: 14.7234 | D8: 13.2269 | E8: 13.984 | G8: 0.4
B9: 0.5 | C9: 14.2485 | D9: 14.1894 | E9: 14.2195 | G9: 0.5
B10: 0.6 | C10: 14.2351 | D10: 15.173 | E10: 14.6927 | G10: 0.6
B11: 0.7 | C11: 13.4495 | D11: 16.4233 | E11: 14.8287 | G11: 0.7
B12: 0.8 | C12: 11.0084 | D12: 16.6486 | E12: 13.437 | G12: 0.8
B13: 0.9 | C13: 10.9337 | D13: 16.67 | E13: 13.4038 | G13: 0.9
B14: 1 | C14: 10.9337 | D14: 16.67 | E14: 13.4038 | G14: 1
D16: mac | J16: (12/15)
C18: 合流200m手前（後続120） | E18: 1250/750 | H18: 合流200m手前（後続120） | J18: 750/1250
B19: α | C19: vehicle0 | D19: vehicle1 | E19: all | G19: α | H19: vehicle0 | I19: vehicle1 | J19: all
B20: 0 | C20: 11.6867 | D20: 12.6771 | E20: 12.0491 | G20: 0 | H20: 14.8982 | I20: 13.2539 | J20: 13.8633
B21: 0.1 | C21: 11.6867 | D21: 12.6771 | E21: 12.0491 | G21: 0.1 | H21: 14.8982 | I21: 13.2539 | J21: 13.8633
B22: 0.2 | C22: 12.742 | D22: 12.4678 | E22: 12.64 | G22: 0.2 | H22: 14.8889 | I22: 13.3629 | J22: 13.9285 | L22: veh17低速走行
B23: 0.3 | C23: 10.824 | D23: 12.8335 | E23: 11.5395 | G23: 0.3 | H23: 12.573 | I23: 13.326 | J23: 13.0346
B24: 0.4 | C24: 12.5256 | D24: 13.4596 | E24: 12.8666 | G24: 0.4 | H24: 12.0186 | I24: 16.0735 | J24: 14.3831
B25: 0.5 | C25: 11.9334 | D25: 14.4274 | E25: 12.8326 | G25: 0.5 | H25: 11.81 | I25: 16.3388 | J25: 14.4509
B26: 0.6 | C26: 12.4239 | D26: 14.4708 | E26: 13.1622 | G26: 0.6 | H26: 11.7502 | I26: 16.4182 | J26: 14.4722
B27: 0.7 | C27: 10.824 | D27: 12.8335 | E27: 11.5395 | G27: 0.7 | H27: 11.731 | I27: 16.4459 | J27: 14.4804
B28: 0.8 | C28: 11.6471 | D28: 16.5082 | E28: 13.2869 | G28: 0.8 | H28: 9.7993 | I28: 16.67 | J28: 13.6484
B29: 0.9 | C29: 11.5212 | D29: 16.67 | E29: 13.2373 | G29: 0.9 | H29: 9.7993 | I29: 16.67 | J29: 13.6484
B30: 1 | C30: 11.5212 | D30: 16.67 | E30: 13.2373 | G30: 1 | H30: 9.7993 | I30: 16.67 | J30: 13.6484
D32: hpc | I32: hpc

Sheet seed2
C2: 合流200m手前（後続120） | E2: 1000/1000 | H2: 合流200m手前（後続120） | J2: 750/750
B3: α | C3: vehicle0 | D3: vehicle1 | E3: all | G3: α | H3: vehicle0 | I3: vehicle1 | J3: all
B4: 0 | C4: 15.4712 | D4: 14.8276 | E4: 15.1421 | G4: 0
B5: 0.1 | C5: 15.4712 | D5: 14.8276 | E5: 15.1421 | G5: 0.1
B6: 0.2 | C6: 15.3667 | D6: 15.0019 | E6: 15.1802 | G6: 0.2
B7: 0.3 | C7: 15.3003 | D7: 15.1827 | E7: 15.2402 | G7: 0.3
B8: 0.4 | C8: 15.2775 | D8: 15.2418 | E8: 15.2592 | G8: 0.4
B9: 0.5 | C9: 15.2824 | D9: 15.5678 | E9: 15.4284 | G9: 0.5
B10: 0.6 | C10: 14.2831 | D10: 16.3355 | E10: 15.287 | G10: 0.6
B11: 0.7 | C11: 13.385 | D11: 16.342 | E11: 14.8083 | G11: 0.7
B12: 0.8 | C12: 13.2566 | D12: 16.67 | E12: 14.8792 | G12: 0.8
B13: 0.9 | C13: 13.2566 | D13: 16.67 | E13: 14.8792 | G13: 0.9
B14: 1 | C14: 13.2566 | D14: 16.67 | E14: 14.8792 | G14: 1
D16: mac | J16: (12/15)
C18: 合流200m手前（後続120） | E18: 1250/750 | H18: 合流200m手前（後続120） | J18: 750/1250
B19: α | C19: vehicle0 | D19: vehicle1 | E19: all | G19: α | H19: vehicle0 | I19: vehicle1 | J19: all
B20: 0 | C20: 14.7948 | D20: 14.3115 | E20: 14.6176 | G20: 0 | H20: 13.7583 | I20: 13.5191 | J20: 13.6058
B21: 0.1 | C21: 14.7948 | D21: 14.3115 | E21: 14.6176 | G21: 0.1 | H21: 13.7843 | I21: 13.4989 | J21: 13.6023
B22: 0.2 | C22: 14.7811 | D22: 14.357 | E22: 14.6255 | G22: 0.2 | H22: 13.6283 | I22: 14.9799 | J22: 14.4755
B23: 0.3 | C23: 14.7811 | D23: 14.357 | E23: 14.6255 | G23: 0.3 | H23: 13.7333 | I23: 15.9588 | J23: 15.1116
B24: 0.4 | C24: 14.8957 | D24: 14.3264 | E24: 14.6869 | G24: 0.4 | H24: 13.7602 | I24: 16.4056 | J24: 15.3957
B25: 0.5 | C25: 14.8342 | D25: 15.2293 | E25: 14.9791 | G25: 0.5 | H25: 13.8023 | I25: 16.465 | J25: 15.4485
B26: 0.6 | C26: 14.2548 | D26: 13.8086 | E26: 14.0942 | G26: 0.6 | H26: 12.6514 | I26: 16.4193 | J26: 14.9342
B27: 0.7 | C27: 13.5374 | D27: 14.8633 | E27: 13.9989 | G27: 0.7 | H27: 12.6062 | I27: 16.0834 | J27: 14.7324
B28: 0.8 | C28: 13.1839 | D28: 16.6638 | E28: 14.3516 | G28: 0.8 | H28: 11.9487 | I28: 16.67 | J28: 14.8081
B29: 0.9 | C29: 13.1952 | D29: 16.669 | E29: 14.3608 | G29: 0.9 | H29: 11.9487 | I29: 16.67 | J29: 14.8081
B30: 1 | C30: 13.1865 | D30: 16.67 | E30: 14.3552 | G30: 1 | H30: 11.9487 | I30: 16.67 | J30: 14.8081
D32: mac | I32: mac

Sheet seed3
C2: 合流200m手前（後続120） | E2: 1000/1000 | H2: 合流200m手前（後続120） | J2: 750/750
B3: α | C3: vehicle0 | D3: vehicle1 | E3: all | G3: α | H3: vehicle0 | I3: vehicle1 | J3: all
B4: 0 | C4: 16.2158 | D4: 16.1456 | E4: 16.1791 | G4: 0 | H4: 16.2629 | I4: 16.5431 | J4: 16.3919
B5: 0.1 | C5: 16.2158 | D5: 16.1456 | E5: 16.1791 | G5: 0.1 | H5: 16.2629 | I5: 16.5431 | J5: 16.3919
B6: 0.2 | C6: 16.2158 | D6: 16.1456 | E6: 16.1791 | G6: 0.2 | H6: 16.2629 | I6: 16.5431 | J6: 16.3919
B7: 0.3 | C7: 16.2158 | D7: 16.1456 | E7: 16.1791 | G7: 0.3 | H7: 16.2629 | I7: 16.5431 | J7: 16.3919
B8: 0.4 | C8: 16.1834 | D8: 16.2225 | E8: 16.2038 | G8: 0.4 | H8: 16.2629 | I8: 16.5431 | J8: 16.3919
B9: 0.5 | C9: 14.8766 | D9: 16.5565 | E9: 15.7174 | G9: 0.5 | H9: 16.2629 | I9: 16.5431 | J9: 16.3919
B10: 0.6 | C10: 14.8766 | D10: 16.5565 | E10: 15.7174 | G10: 0.6 | H10: 16.2629 | I10: 16.5431 | J10: 16.3919
B11: 0.7 | C11: 14.7384 | D11: 16.607 | E11: 15.6679 | G11: 0.7 | H11: 16.2629 | I11: 16.5431 | J11: 16.3919
B12: 0.8 | C12: 14.7384 | D12: 16.607 | E12: 15.6679 | G12: 0.8 | H12: 16.2629 | I12: 16.5431 | J12: 16.3919
B13: 0.9 | C13: 13.0121 | D13: 16.67 | E13: 14.7402 | G13: 0.9 | H13: 16.0807 | I13: 16.67 | J13: 16.3493
B14: 1 | C14: 13.0121 | D14: 16.67 | E14: 14.7402 | G14: 1 | H14: 16.0807 | I14: 16.67 | J14: 16.3493
D16: hpc | I16: mac
C18: 合流200m手前（後続120） | E18: 1250/750 | H18: 合流200m手前（後続120） | J18: 750/1250
B19: α | C19: vehicle0 | D19: vehicle1 | E19: all | G19: α | H19: vehicle0 | I19: vehicle1 | J19: all
B20: 0 | C20: 15.5153 | D20: 15.8792 | E20: 15.6657 | G20: 0 | H20: 16.2629 | I20: 16.6058 | J20: 16.4803
B21: 0.1 | C21: 15.5153 | D21: 15.8792 | E21: 15.6657 | G21: 0.1 | H21: 16.2629 | I21: 16.6058 | J21: 16.4803
B22: 0.2 | C22: 15.5153 | D22: 15.8792 | E22: 15.6657 | G22: 0.2 | H22: 16.2629 | I22: 16.6058 | J22: 16.4803
B23: 0.3 | C23: 15.5153 | D23: 15.8792 | E23: 15.6657 | G23: 0.3 | H23: 16.2629 | I23: 16.6058 | J23: 16.4803
B24: 0.4 | C24: 15.5153 | D24: 15.8792 | E24: 15.6657 | G24: 0.4 | H24: 16.2629 | I24: 16.6058 | J24: 16.4803
B25: 0.5 | C25: 15.5191 | D25: 15.9222 | E25: 15.6857 | G25: 0.5 | H25: 16.2629 | I25: 16.6058 | J25: 16.4803
B26: 0.6 | C26: 14.4475 | D26: 16.2493 | E26: 15.1646 | G26: 0.6 | H26: 16.2629 | I26: 16.6058 | J26: 16.4803
B27: 0.7 | C27: 14.6894 | D27: 16.4491 | E27: 15.3953 | G27: 0.7 | H27: 16.2629 | I27: 16.6058 | J27: 16.4803
B28: 0.8 | C28: 13.4223 | D28: 16.39 | E28: 14.5674 | G28: 0.8 | H28: 13.5551 | I28: 16.67 | J28: 15.4202
B29: 0.9 | C29: 13.1843 | D29: 16.6403 | E29: 14.511 | G29: 0.9 | H29: 13.5551 | I29: 16.67 | J29: 15.4202
B30: 1 | C30: 11.9282 | D30: 16.67 | E30: 13.6683 | G30: 1 | H30: 13.5551 | I30: 16.67 | J30: 15.4202
D32: hpc | I32: hpc

Sheet seed4
C2: 合流200m手前（後続120） | E2: 1000/1000 | H2: 合流200m手前（後続120） | J2: 750/750
B3: α | C3: vehicle0 | D3: vehicle1 | E3: all | G3: α | H3: vehicle0 | I3: vehicle1 | J3: all
B4: 0 | C4: 15.3154 | D4: 15.6674 | E4: 15.4833 | G4: 0 | H4: 15.9991 | I4: 16.6638 | J4: 16.3263
B5: 0.1 | C5: 15.3154 | D5: 15.6674 | E5: 15.4833 | G5: 0.1 | H5: 15.9991 | I5: 16.6638 | J5: 16.3263
B6: 0.2 | C6: 15.3154 | D6: 15.6674 | E6: 15.4833 | G6: 0.2 | H6: 15.9991 | I6: 16.6638 | J6: 16.3263
B7: 0.3 | C7: 14.7949 | D7: 14.9854 | E7: 14.8867 | G7: 0.3 | H7: 15.9866 | I7: 16.669 | J7: 16.3225
B8: 0.4 | C8: 14.8178 | D8: 15.0007 | E8: 14.906 | G8: 0.4 | H8: 15.9866 | I8: 16.669 | J8: 16.3225
B9: 0.5 | C9: 15.2088 | D9: 16.0801 | E9: 15.6217 | G9: 0.5 | H9: 15.9866 | I9: 16.669 | J9: 16.3225
B10: 0.6 | C10: 15.2088 | D10: 16.0801 | E10: 15.6217 | G10: 0.6 | H10: 15.9866 | I10: 16.669 | J10: 16.3225
B11: 0.7 | C11: 12.6582 | D11: 16.3834 | E11: 14.3126 | G11: 0.7 | H11: 15.9866 | I11: 16.669 | J11: 16.3225
B12: 0.8 | C12: 12.4409 | D12: 16.67 | E12: 14.2773 | G12: 0.8 | H12: 15.8851 | I12: 16.6683 | J12: 16.269
B13: 0.9 | C13: 12.4409 | D13: 16.67 | E13: 14.2773 | G13: 0.9 | H13: 15.8908 | I13: 16.67 | J13: 16.2728
B14: 1 | C14: 12.4409 | D14: 16.67 | E14: 14.2773 | G14: 1 | H14: 15.8908 | I14: 16.67 | J14: 16.2728
D16: mac | I16: mac
C18: 合流200m手前（後続120） | E18: 1250/750 | H18: 合流200m手前（後続120） | J18: 750/1250
B19: α | C19: vehicle0 | D19: vehicle1 | E19: all | G19: α | H19: vehicle0 | I19: vehicle1 | J19: all
B20: 0 | C20: 13.7564 | D20: 13.0596 | E20: 13.5018 | G20: 0 | H20: 15.0533 | I20: 15.3276 | J20: 15.2181
B21: 0.1 | C21: 13.7564 | D21: 13.0596 | E21: 13.5018 | G21: 0.1 | H21: 15.0533 | I21: 15.3276 | J21: 15.2181
B22: 0.2 | C22: 13.7564 | D22: 13.0596 | E22: 13.5018 | G22: 0.2 | H22: 15.1458 | I22: 15.3998 | J22: 15.2984
B23: 0.3 | C23: 13.7564 | D23: 13.0596 | E23: 13.5018 | G23: 0.3 | H23: 15.0651 | I23: 16.0423 | J23: 15.6522
B24: 0.4 | C24: 13.7637 | D24: 13.8277 | E24: 13.7871 | G24: 0.4 | H24: 13.9222 | I24: 16.0758 | J24: 15.2018
B25: 0.5 | C25: 13.791 | D25: 13.9682 | E25: 13.8557 | G25: 0.5 | H25: 13.9222 | I25: 16.0758 | J25: 15.2018
B26: 0.6 | C26: 14.3079 | D26: 15.5226 | E26: 14.7286 | G26: 0.6 | H26: 13.748 | I26: 16.3857 | J26: 15.3153
B27: 0.7 | C27: 13.1174 | D27: 16.6696 | E27: 14.2418 | G27: 0.7 | H27: 14.0997 | I27: 16.4565 | J27: 15.5
B28: 0.8 | C28: 12.8377 | D28: 16.5066 | E28: 14.007 | G28: 0.8 | H28: 11.08 | I28: 16.6513 | J28: 14.1964
B29: 0.9 | C29: 12.8371 | D29: 16.5066 | E29: 14.0066 | G29: 0.9 | H29: 11.08 | I29: 16.6513 | J29: 14.1964
B30: 1 | C30: 13.112 | D30: 16.67 | E30: 14.2382 | G30: 1 | H30: 11.08 | I30: 16.6513 | J30: 14.1964
D32: hpc | I32: hpc

Sheet seed5
C2: 合流200m手前（後続120） | E2: 1000/1000 | H2: 合流200m手前（後続120） | J2: 750/750
B3: α | C3: vehicle0 | D3: vehicle1 | E3: all | G3: α | H3: vehicle0 | I3: vehicle1 | J3: all
B4: 0 | C4: 15.8562 | D4: 10.3655 | E4: 13.1837 | G4: 0 | H4: 16.0554 | I4: 16.1999 | J4: 16.1286
B5: 0.1 | C5: 15.8487 | D5: 10.6054 | E5: 13.2958 | G5: 0.1 | H5: 16.0554 | I5: 16.1999 | J5: 16.1286
B6: 0.2 | C6: 15.3172 | D6: 12.4635 | E6: 13.963 | G6: 0.2 | H6: 16.0554 | I6: 16.1999 | J6: 16.1286
B7: 0.3 | C7: 15.3041 | D7: 11.979 | E7: 13.7157 | G7: 0.3 | H7: 16.0554 | I7: 16.1999 | J7: 16.1286
B8: 0.4 | C8: 14.6094 | D8: 14.8855 | E8: 14.7365 | G8: 0.4 | H8: 16.0554 | I8: 16.1999 | J8: 16.1286
B9: 0.5 | C9: 14.9306 | D9: 15.9321 | E9: 15.3933 | G9: 0.5 | H9: 16.0554 | I9: 16.1999 | J9: 16.1286
B10: 0.6 | C10: 14.9306 | D10: 15.9321 | E10: 15.3933 | G10: 0.6 | H10: 15.9284 | I10: 16.3313 | J10: 16.1324
B11: 0.7 | C11: 14.8044 | D11: 16.2123 | E11: 15.4549 | G11: 0.7 | H11: 15.4673 | I11: 16.5586 | J11: 16.0159
B12: 0.8 | C12: 12.8498 | D12: 16.67 | E12: 14.5104 | G12: 0.8 | H12: 12.1423 | I12: 16.6699 | J12: 14.2107
B13: 0.9 | C13: 12.8498 | D13: 16.67 | E13: 14.5104 | G13: 0.9 | H13: 12.1295 | I13: 16.67 | J13: 14.2105
B14: 1 | C14: 11.7876 | D14: 16.67 | E14: 13.8556 | G14: 1 | H14: 12.1295 | I14: 16.67 | J14: 14.2105
D16: mac | I16: mac
C18: 合流200m手前（後続120） | E18: 1250/750 | H18: 合流200m手前（後続120） | J18: 750/1250
B19: α | C19: vehicle0 | D19: vehicle1 | E19: all | G19: α | H19: vehicle0 | I19: vehicle1 | J19: all
B20: 0 | C20: 15.8263 | D20: 13.8079 | E20: 15.1261 | G20: 0 | H20: 15.6479 | I20: 15.0956 | J20: 15.3076
B21: 0.1 | C21: 15.8263 | D21: 13.8079 | E21: 15.1261 | G21: 0.1 | H21: 15.6479 | I21: 15.0956 | J21: 15.3076
B22: 0.2 | C22: 15.7447 | D22: 14.7412 | E22: 15.3966 | G22: 0.2 | H22: 15.6255 | I22: 15.4742 | J22: 15.5323
B23: 0.3 | C23: 15.7447 | D23: 14.7412 | E23: 15.3966 | G23: 0.3 | H23: 15.6257 | I23: 15.6302 | J23: 15.6285
B24: 0.4 | C24: 15.823 | D24: 15.7511 | E24: 15.7981 | G24: 0.4 | H24: 15.6252 | I24: 15.631 | J24: 15.6288
B25: 0.5 | C25: 15.8611 | D25: 15.9842 | E25: 15.9038 | G25: 0.5 | H25: 15.6252 | I25: 15.631 | J25: 15.6288
B26: 0.6 | C26: 15.7633 | D26: 16.3921 | E26: 15.9815 | G26: 0.6 | H26: 15.1789 | I26: 16.3359 | J26: 15.8917
B27: 0.7 | C27: 15.7633 | D27: 16.3921 | E27: 15.9815 | G27: 0.7 | H27: 15.1789 | I27: 16.3359 | J27: 15.8917
B28: 0.8 | C28: 15.7112 | D28: 16.5815 | E28: 16.0131 | G28: 0.8 | H28: 11.2076 | I28: 16.67 | J28: 14.3238
B29: 0.9 | C29: 14.1382 | D29: 16.6424 | E29: 14.9818 | G29: 0.9 | H29: 11.2076 | I29: 16.67 | J29: 14.3238
B30: 1 | C30: 14.138 | D30: 16.67 | E30: 14.991 | G30: 1 | H30: 11.2076 | I30: 16.67 | J30: 14.3238
D32: hpc | I32: hpc

Sheet average1-5
C2: 合流200m手前（後続120） | E2: 1000/1000 | H2: 合流200m手前（後続120） | J2: 750/750
B3: α | C3: vehicle0 | D3: vehicle1 | E3: all | G3: α | H3: vehicle0 | I3: vehicle1 | J3: all
B4: 0 | C4: =ROUND(AVERAGE(seed1!C4,seed2!C4,seed3!C4,seed4!C4,seed5!C4),4) -> 15.5166 | D4: =ROUND(AVERAGE(seed1!D4,seed2!D4,seed3!D4,seed4!D4,seed5!D4),4) -> 14.046 | E4: =ROUND(AVERAGE(seed1!E4,seed2!E4,seed3!E4,seed4!E4,seed5!E4),4) -> 14.7942 | G4: 0 | H4: =ROUND(AVERAGE(seed1!H4,seed2!H4,seed3!H4,seed4!H4,seed5!H4),4) -> 16.1058 | I4: =ROUND(AVERAGE(seed1!I4,seed2!I4,seed3!I4,seed4!I4,seed5!I4),4) -> 16.4689 | J4: =ROUND(AVERAGE(seed1!J4,seed2!J4,seed3!J4,seed4!J4,seed5!J4),4) -> 16.2823
B5: 0.1 | C5: =ROUND(AVERAGE(seed1!C5,seed2!C5,seed3!C5,seed4!C5,seed5!C5),4) -> 15.5151 | D5: =ROUND(AVERAGE(seed1!D5,seed2!D5,seed3!D5,seed4!D5,seed5!D5),4) -> 14.0939 | E5: =ROUND(AVERAGE(seed1!E5,seed2!E5,seed3!E5,seed4!E5,seed5!E5),4) -> 14.8166 | G5: 0.1 | H5: =ROUND(AVERAGE(seed1!H5,seed2!H5,seed3!H5,seed4!H5,seed5!H5),4) -> 16.1058 | I5: =ROUND(AVERAGE(seed1!I5,seed2!I5,seed3!I5,seed4!I5,seed5!I5),4) -> 16.4689 | J5: =ROUND(AVERAGE(seed1!J5,seed2!J5,seed3!J5,seed4!J5,seed5!J5),4) -> 16.2823
B6: 0.2 | C6: =ROUND(AVERAGE(seed1!C6,seed2!C6,seed3!C6,seed4!C6,seed5!C6),4) -> 15.3879 | D6: =ROUND(AVERAGE(seed1!D6,seed2!D6,seed3!D6,seed4!D6,seed5!D6),4) -> 14.5004 | E6: =ROUND(AVERAGE(seed1!E6,seed2!E6,seed3!E6,seed4!E6,seed5!E6),4) -> 14.9577 | G6: 0.2 | H6: =ROUND(AVERAGE(seed1!H6,seed2!H6,seed3!H6,seed4!H6,seed5!H6),4) -> 16.1058 | I6: =ROUND(AVERAGE(seed1!I6,seed2!I6,seed3!I6,seed4!I6,seed5!I6),4) -> 16.4689 | J6: =ROUND(AVERAGE(seed1!J6,seed2!J6,seed3!J6,seed4!J6,seed5!J6),4) -> 16.2823
B7: 0.3 | C7: =ROUND(AVERAGE(seed1!C7,seed2!C7,seed3!C7,seed4!C7,seed5!C7),4) -> 15.2677 | D7: =ROUND(AVERAGE(seed1!D7,seed2!D7,seed3!D7,seed4!D7,seed5!D7),4) -> 14.3039 | E7: =ROUND(AVERAGE(seed1!E7,seed2!E7,seed3!E7,seed4!E7,seed5!E7),4) -> 14.8011 | G7: 0.3 | H7: =ROUND(AVERAGE(seed1!H7,seed2!H7,seed3!H7,seed4!H7,seed5!H7),4) -> 16.1016 | I7: =ROUND(AVERAGE(seed1!I7,seed2!I7,seed3!I7,seed4!I7,seed5!I7),4) -> 16.4707 | J7: =ROUND(AVERAGE(seed1!J7,seed2!J7,seed3!J7,seed4!J7,seed5!J7),4) -> 16.281
B8: 0.4 | C8: =ROUND(AVERAGE(seed1!C8,seed2!C8,seed3!C8,seed4!C8,seed5!C8),4) -> 15.1223 | D8: =ROUND(AVERAGE(seed1!D8,seed2!D8,seed3!D8,seed4!D8,seed5!D8),4) -> 14.9155 | E8: =ROUND(AVERAGE(seed1!E8,seed2!E8,seed3!E8,seed4!E8,seed5!E8),4) -> 15.0179 | G8: 0.4 | H8: =ROUND(AVERAGE(seed1!H8,seed2!H8,seed3!H8,seed4!H8,seed5!H8),4) -> 16.1016 | I8: =ROUND(AVERAGE(seed1!I8,seed2!I8,seed3!I8,seed4!I8,seed5!I8),4) -> 16.4707 | J8: =ROUND(AVERAGE(seed1!J8,seed2!J8,seed3!J8,seed4!J8,seed5!J8),4) -> 16.281
B9: 0.5 | C9: =ROUND(AVERAGE(seed1!C9,seed2!C9,seed3!C9,seed4!C9,seed5!C9),4) -> 14.9094 | D9: =ROUND(AVERAGE(seed1!D9,seed2!D9,seed3!D9,seed4!D9,seed5!D9),4) -> 15.6652 | E9: =ROUND(AVERAGE(seed1!E9,seed2!E9,seed3!E9,seed4!E9,seed5!E9),4) -> 15.2761 | G9: 0.5 | H9: =ROUND(AVERAGE(seed1!H9,seed2!H9,seed3!H9,seed4!H9,seed5!H9),4) -> 16.1016 | I9: =ROUND(AVERAGE(seed1!I9,seed2!I9,seed3!I9,seed4!I9,seed5!I9),4) -> 16.4707 | J9: =ROUND(AVERAGE(seed1!J9,seed2!J9,seed3!J9,seed4!J9,seed5!J9),4) -> 16.281
B10: 0.6 | C10: =ROUND(AVERAGE(seed1!C10,seed2!C10,seed3!C10,seed4!C10,seed5!C10),4) -> 14.7068 | D10: =ROUND(AVERAGE(seed1!D10,seed2!D10,seed3!D10,seed4!D10,seed5!D10),4) -> 16.0154 | E10: =ROUND(AVERAGE(seed1!E10,seed2!E10,seed3!E10,seed4!E10,seed5!E10),4) -> 15.3424 | G10: 0.6 | H10: =ROUND(AVERAGE(seed1!H10,seed2!H10,seed3!H10,seed4!H10,seed5!H10),4) -> 16.0593 | I10: =ROUND(AVERAGE(seed1!I10,seed2!I10,seed3!I10,seed4!I10,seed5!I10),4) -> 16.5145 | J10: =ROUND(AVERAGE(seed1!J10,seed2!J10,seed3!J10,seed4!J10,seed5!J10),4) -> 16.2823
B11: 0.7 | C11: =ROUND(AVERAGE(seed1!C11,seed2!C11,seed3!C11,seed4!C11,seed5!C11),4) -> 13.8071 | D11: =ROUND(AVERAGE(seed1!D11,seed2!D11,seed3!D11,seed4!D11,seed5!D11),4) -> 16.3936 | E11: =ROUND(AVERAGE(seed1!E11,seed2!E11,seed3!E11,seed4!E11,seed5!E11),4) -> 15.0145 | G11: 0.7 | H11: =ROUND(AVERAGE(seed1!H11,seed2!H11,seed3!H11,seed4!H11,seed5!H11),4) -> 15.9056 | I11: =ROUND(AVERAGE(seed1!I11,seed2!I11,seed3!I11,seed4!I11,seed5!I11),4) -> 16.5902 | J11: =ROUND(AVERAGE(seed1!J11,seed2!J11,seed3!J11,seed4!J11,seed5!J11),4) -> 16.2434
B12: 0.8 | C12: =ROUND(AVERAGE(seed1!C12,seed2!C12,seed3!C12,seed4!C12,seed5!C12),4) -> 12.8588 | D12: =ROUND(AVERAGE(seed1!D12,seed2!D12,seed3!D12,seed4!D12,seed5!D12),4) -> 16.6531 | E12: =ROUND(AVERAGE(seed1!E12,seed2!E12,seed3!E12,seed4!E12,seed5!E12),4) -> 14.5544 | G12: 0.8 | H12: =ROUND(AVERAGE(seed1!H12,seed2!H12,seed3!H12,seed4!H12,seed5!H12),4) -> 14.7634 | I12: =ROUND(AVERAGE(seed1!I12,seed2!I12,seed3!I12,seed4!I12,seed5!I12),4) -> 16.6271 | J12: =ROUND(AVERAGE(seed1!J12,seed2!J12,seed3!J12,seed4!J12,seed5!J12),4) -> 15.6239
B13: 0.9 | C13: =ROUND(AVERAGE(seed1!C13,seed2!C13,seed3!C13,seed4!C13,seed5!C13),4) -> 12.4986 | D13: =ROUND(AVERAGE(seed1!D13,seed2!D13,seed3!D13,seed4!D13,seed5!D13),4) -> 16.67 | E13: =ROUND(AVERAGE(seed1!E13,seed2!E13,seed3!E13,seed4!E13,seed5!E13),4) -> 14.3622 | G13: 0.9 | H13: =ROUND(AVERAGE(seed1!H13,seed2!H13,seed3!H13,seed4!H13,seed5!H13),4) -> 14.7003 | I13: =ROUND(AVERAGE(seed1!I13,seed2!I13,seed3!I13,seed4!I13,seed5!I13),4) -> 16.67 | J13: =ROUND(AVERAGE(seed1!J13,seed2!J13,seed3!J13,seed4!J13,seed5!J13),4) -> 15.6109
B14: 1 | C14: =ROUND(AVERAGE(seed1!C14,seed2!C14,seed3!C14,seed4!C14,seed5!C14),4) -> 12.2862 | D14: =ROUND(AVERAGE(seed1!D14,seed2!D14,seed3!D14,seed4!D14,seed5!D14),4) -> 16.67 | E14: =ROUND(AVERAGE(seed1!E14,seed2!E14,seed3!E14,seed4!E14,seed5!E14),4) -> 14.2312 | G14: 1 | H14: =ROUND(AVERAGE(seed1!H14,seed2!H14,seed3!H14,seed4!H14,seed5!H14),4) -> 14.7003 | I14: =ROUND(AVERAGE(seed1!I14,seed2!I14,seed3!I14,seed4!I14,seed5!I14),4) -> 16.67 | J14: =ROUND(AVERAGE(seed1!J14,seed2!J14,seed3!J14,seed4!J14,seed5!J14),4) -> 15.6109
C18: 合流200m手前（後続120） | E18: 1250/750 | H18: 合流200m手前（後続120） | J18: 750/1250
B19: α | C19: vehicle0 | D19: vehicle1 | E19: all | G19: α | H19: vehicle0 | I19: vehicle1 | J19: all
B20: 0 | C20: =ROUND(AVERAGE(seed1!C20,seed2!C20,seed3!C20,seed4!C20,seed5!C20),4) -> 14.3159 | D20: =ROUND(AVERAGE(seed1!D20,seed2!D20,seed3!D20,seed4!D20,seed5!D20),4) -> 13.9471 | E20: =ROUND(AVERAGE(seed1!E20,seed2!E20,seed3!E20,seed4!E20,seed5!E20),4) -> 14.1921 | G20: 0 | H20: =ROUND(AVERAGE(seed1!H21,seed2!H20,seed3!H20,seed4!H20,seed5!H20),4) -> 15.1241 | I20: =ROUND(AVERAGE(seed1!I21,seed2!I20,seed3!I20,seed4!I20,seed5!I20),4) -> 14.7604 | J20: =ROUND(AVERAGE(seed1!J21,seed2!J20,seed3!J20,seed4!J20,seed5!J20),4) -> 14.895
B21: 0.1 | C21: =ROUND(AVERAGE(seed1!C21,seed2!C21,seed3!C21,seed4!C21,seed5!C21),4) -> 14.3159 | D21: =ROUND(AVERAGE(seed1!D21,seed2!D21,seed3!D21,seed4!D21,seed5!D21),4) -> 13.9471 | E21: =ROUND(AVERAGE(seed1!E21,seed2!E21,seed3!E21,seed4!E21,seed5!E21),4) -> 14.1921 | G21: 0.1 | H21: =ROUND(AVERAGE(seed1!H21,seed2!H21,seed3!H21,seed4!H21,seed5!H21),4) -> 15.1293 | I21: =ROUND(AVERAGE(seed1!I21,seed2!I21,seed3!I21,seed4!I21,seed5!I21),4) -> 14.7564 | J21: =ROUND(AVERAGE(seed1!J21,seed2!J21,seed3!J21,seed4!J21,seed5!J21),4) -> 14.8943
B22: 0.2 | C22: =ROUND(AVERAGE(seed1!C22,seed2!C22,seed3!C22,seed4!C22,seed5!C22),4) -> 14.5079 | D22: =ROUND(AVERAGE(seed1!D22,seed2!D22,seed3!D22,seed4!D22,seed5!D22),4) -> 14.101 | E22: =ROUND(AVERAGE(seed1!E22,seed2!E22,seed3!E22,seed4!E22,seed5!E22),4) -> 14.3659 | G22: 0.2 | H22: =ROUND(AVERAGE(seed1!H22,seed2!H22,seed3!H22,seed4!H22,seed5!H22),4) -> 15.1103 | I22: =ROUND(AVERAGE(seed1!I22,seed2!I22,seed3!I22,seed4!I22,seed5!I22),4) -> 15.1645 | J22: =ROUND(AVERAGE(seed1!J22,seed2!J22,seed3!J22,seed4!J22,seed5!J22),4) -> 15.143
B23: 0.3 | C23: =ROUND(AVERAGE(seed1!C23,seed2!C23,seed3!C23,seed4!C23,seed5!C23),4) -> 14.1243 | D23: =ROUND(AVERAGE(seed1!D23,seed2!D23,seed3!D23,seed4!D23,seed5!D23),4) -> 14.1741 | E23: =ROUND(AVERAGE(seed1!E23,seed2!E23,seed3!E23,seed4!E23,seed5!E23),4) -> 14.1458 | G23: 0.3 | H23: =ROUND(AVERAGE(seed1!H23,seed2!H23,seed3!H23,seed4!H23,seed5!H23),4) -> 14.652 | I23: =ROUND(AVERAGE(seed1!I23,seed2!I23,seed3!I23,seed4!I23,seed5!I23),4) -> 15.5126 | J23: =ROUND(AVERAGE(seed1!J23,seed2!J23,seed3!J23,seed4!J23,seed5!J23),4) -> 15.1814
B24: 0.4 | C24: =ROUND(AVERAGE(seed1!C24,seed2!C24,seed3!C24,seed4!C24,seed5!C24),4) -> 14.5047 | D24: =ROUND(AVERAGE(seed1!D24,seed2!D24,seed3!D24,seed4!D24,seed5!D24),4) -> 14.6488 | E24: =ROUND(AVERAGE(seed1!E24,seed2!E24,seed3!E24,seed4!E24,seed5!E24),4) -> 14.5609 | G24: 0.4 | H24: =ROUND(AVERAGE(seed1!H24,seed2!H24,seed3!H24,seed4!H24,seed5!H24),4) -> 14.3178 | I24: =ROUND(AVERAGE(seed1!I24,seed2!I24,seed3!I24,seed4!I24,seed5!I24),4) -> 16.1583 | J24: =ROUND(AVERAGE(seed1!J24,seed2!J24,seed3!J24,seed4!J24,seed5!J24),4) -> 15.4179
B25: 0.5 | C25: =ROUND(AVERAGE(seed1!C25,seed2!C25,seed3!C25,seed4!C25,seed5!C25),4) -> 14.3878 | D25: =ROUND(AVERAGE(seed1!D25,seed2!D25,seed3!D25,seed4!D25,seed5!D25),4) -> 15.1063 | E25: =ROUND(AVERAGE(seed1!E25,seed2!E25,seed3!E25,seed4!E25,seed5!E25),4) -> 14.6514 | G25: 0.5 | H25: =ROUND(AVERAGE(seed1!H25,seed2!H25,seed3!H25,seed4!H25,seed5!H25),4) -> 14.2845 | I25: =ROUND(AVERAGE(seed1!I25,seed2!I25,seed3!I25,seed4!I25,seed5!I25),4) -> 16.2233 | J25: =ROUND(AVERAGE(seed1!J25,seed2!J25,seed3!J25,seed4!J25,seed5!J25),4) -> 15.4421
B26: 0.6 | C26: =ROUND(AVERAGE(seed1!C26,seed2!C26,seed3!C26,seed4!C26,seed5!C26),4) -> 14.2395 | D26: =ROUND(AVERAGE(seed1!D26,seed2!D26,seed3!D26,seed4!D26,seed5!D26),4) -> 15.2887 | E26: =ROUND(AVERAGE(seed1!E26,seed2!E26,seed3!E26,seed4!E26,seed5!E26),4) -> 14.6262 | G26: 0.6 | H26: =ROUND(AVERAGE(seed1!H26,seed2!H26,seed3!H26,seed4!H26,seed5!H26),4) -> 13.9183 | I26: =ROUND(AVERAGE(seed1!I26,seed2!I26,seed3!I26,seed4!I26,seed5!I26),4) -> 16.433 | J26: =ROUND(AVERAGE(seed1!J26,seed2!J26,seed3!J26,seed4!J26,seed5!J26),4) -> 15.4187
B27: 0.7 | C27: =ROUND(AVERAGE(seed1!C27,seed2!C27,seed3!C27,seed4!C27,seed5!C27),4) -> 13.5863 | D27: =ROUND(AVERAGE(seed1!D27,seed2!D27,seed3!D27,seed4!D27,seed5!D27),4) -> 15.4415 | E27: =ROUND(AVERAGE(seed1!E27,seed2!E27,seed3!E27,seed4!E27,seed5!E27),4) -> 14.2314 | G27: 0.7 | H27: =ROUND(AVERAGE(seed1!H27,seed2!H27,seed3!H27,seed4!H27,seed5!H27),4) -> 13.9757 | I27: =ROUND(AVERAGE(seed1!I27,seed2!I27,seed3!I27,seed4!I27,seed5!I27),4) -> 16.3855 | J27: =ROUND(AVERAGE(seed1!J27,seed2!J27,seed3!J27,seed4!J27,seed5!J27),4) -> 15.417
B28: 0.8 | C28: =ROUND(AVERAGE(seed1!C28,seed2!C28,seed3!C28,seed4!C28,seed5!C28),4) -> 13.3604 | D28: =ROUND(AVERAGE(seed1!D28,seed2!D28,seed3!D28,seed4!D28,seed5!D28),4) -> 16.53 | E28: =ROUND(AVERAGE(seed1!E28,seed2!E28,seed3!E28,seed4!E28,seed5!E28),4) -> 14.4452 | G28: 0.8 | H28: =ROUND(AVERAGE(seed1!H28,seed2!H28,seed3!H28,seed4!H28,seed5!H28),4) -> 11.5181 | I28: =ROUND(AVERAGE(seed1!I28,seed2!I28,seed3!I28,seed4!I28,seed5!I28),4) -> 16.6663 | J28: =ROUND(AVERAGE(seed1!J28,seed2!J28,seed3!J28,seed4!J28,seed5!J28),4) -> 14.4794
B29: 0.9 | C29: =ROUND(AVERAGE(seed1!C29,seed2!C29,seed3!C29,seed4!C29,seed5!C29),4) -> 12.9752 | D29: =ROUND(AVERAGE(seed1!D29,seed2!D29,seed3!D29,seed4!D29,seed5!D29),4) -> 16.6257 | E29: =ROUND(AVERAGE(seed1!E29,seed2!E29,seed3!E29,seed4!E29,seed5!E29),4) -> 14.2195 | G29: 0.9 | H29: =ROUND(AVERAGE(seed1!H29,seed2!H29,seed3!H29,seed4!H29,seed5!H29),4) -> 11.5181 | I29: =ROUND(AVERAGE(seed1!I29,seed2!I29,seed3!I29,seed4!I29,seed5!I29),4) -> 16.6663 | J29: =ROUND(AVERAGE(seed1!J29,seed2!J29,seed3!J29,seed4!J29,seed5!J29),4) -> 14.4794
B30: 1 | C30: =ROUND(AVERAGE(seed1!C30,seed2!C30,seed3!C30,seed4!C30,seed5!C30),4) -> 12.7772 | D30: =ROUND(AVERAGE(seed1!D30,seed2!D30,seed3!D30,seed4!D30,seed5!D30),4) -> 16.67 | E30: =ROUND(AVERAGE(seed1!E30,seed2!E30,seed3!E30,seed4!E30,seed5!E30),4) -> 14.098 | G30: 1 | H30: =ROUND(AVERAGE(seed1!H30,seed2!H30,seed3!H30,seed4!H30,seed5!H30),4) -> 11.5181 | I30: =ROUND(AVERAGE(seed1!I30,seed2!I30,seed3!I30,seed4!I30,seed5!I30),4) -> 16.6663 | J30: =ROUND(AVERAGE(seed1!J30,seed2!J30,seed3!J30,seed4!J30,seed5!J30),4) -> 14.4794

Sheet seed7
C2: 合流200m手前（後続120） | E2: 1000/1000 | H2: 合流200m手前（後続120） | J2: 750/750
B3: α | C3: vehicle0 | D3: vehicle1 | E3: all | G3: α | H3: vehicle0 | I3: vehicle1 | J3: all
B4: 0 | C4: 13.6087 | D4: 13.573 | E4: 13.5901 | G4: 0
B5: 0.1 | C5: 13.6087 | D5: 13.573 | E5: 13.5901 | G5: 0.1
B6: 0.2 | C6: 13.6087 | D6: 13.573 | E6: 13.5901 | G6: 0.2
B7: 0.3 | C7: 13.3917 | D7: 11.1717 | E7: 12.1778 | G7: 0.3
B8: 0.4 | C8: 12.7658 | D8: 15.5733 | E8: 14.094 | G8: 0.4
B9: 0.5 | C9: 13.971 | D9: 15.2024 | E9: 14.5588 | G9: 0.5
B10: 0.6 | C10: 10.9411 | D10: 14.1225 | E10: 12.4676 | G10: 0.6
B11: 0.7 | C11: 10.9808 | D11: 15.8863 | E11: 13.1299 | G11: 0.7
B12: 0.8 | C12: 10.6015 | D12: 16.4754 | E12: 13.1749 | G12: 0.8
B13: 0.9 | C13: 9.884 | D13: 16.6648 | E13: 12.8266 | G13: 0.9
B14: 1 | C14: 9.8783 | D14: 16.67 | E14: 12.8256 | G14: 1
D16: mac
C18: 合流200m手前（後続120） | E18: 1250/750 | H18: 合流200m手前（後続120） | J18: 750/1250
B19: α | C19: vehicle0 | D19: vehicle1 | E19: all | G19: α | H19: vehicle0 | I19: vehicle1 | J19: all
B20: 0 | C20: 12.5854 | D20: 12.7652 | E20: 12.6541 | G20: 0 | H20: 12.8015 | I20: 11.7582 | J20: 12.1744 | L20: veh15低速
B21: 0.1 | C21: 12.5854 | D21: 12.7652 | E21: 12.6541 | G21: 0.1 | H21: 12.8853 | I21: 11.8358 | J21: 12.2526 | L21: veh15低速
B22: 0.2 | C22: 12.0974 | D22: 11.7444 | E22: 11.963 | F22: veh9低速 | G22: 0.2 | H22: 12.8853 | I22: 11.8358 | J22: 12.2526 | L22: veh15低速
B23: 0.3 | C23: 12.0974 | D23: 11.7444 | E23: 11.963 | F23: veh9低速 | G23: 0.3 | H23: 12.2101 | I23: 13.9193 | J23: 13.2323
B24: 0.4 | C24: 11.7582 | D24: 12.4158 | E24: 12.0086 | F24: veh9低速 | G24: 0.4 | H24: 12.8503 | I24: 12.8648 | J24: 12.8592
B25: 0.5 | C25: 11.4959 | D25: 15.3592 | E25: 12.8338 | G25: 0.5 | H25: 12.4286 | I25: 14.1361 | J25: 13.4437
B26: 0.6 | C26: 13.5118 | D26: 16.6378 | E26: 14.6076 | G26: 0.6 | H26: 12.006 | I26: 15.7481 | J26: 14.1316
B27: 0.7 | C27: 13.1686 | D27: 16.434 | E27: 14.302 | G27: 0.7 | H27: 11.8765 | I27: 16 | J27: 14.2205
B28: 0.8 | C28: 13.1711 | D28: 16.4342 | E28: 14.3037 | G28: 0.8 | H28: 9.4037 | I28: 16.6669 | J28: 13.2368
B29: 0.9 | C29: 13.4956 | D29: 16.6697 | E29: 14.6081 | G29: 0.9 | H29: 9.4191 | I29: 16.67 | J29: 13.2463
B30: 1 | C30: 13.4961 | D30: 16.67 | E30: 14.6087 | G30: 1 | H30: 9.4191 | I30: 16.67 | J30: 13.2463
D32: mac | I32: hpc

Sheet seed8
C2: 合流200m手前（後続120） | E2: 1000/1000 | H2: 合流200m手前（後続120） | J2: 750/750
B3: α | C3: vehicle0 | D3: vehicle1 | E3: all | G3: α | H3: vehicle0 | I3: vehicle1 | J3: all
B4: 0 | C4: 15.5361 | D4: 15.7677 | E4: 15.6527 | G4: 0
B5: 0.1 | C5: 15.5361 | D5: 15.7677 | E5: 15.6527 | G5: 0.1
B6: 0.2 | C6: 14.08 | D6: 16.5503 | E6: 15.2653 | G6: 0.2
B7: 0.3 | C7: 14.0982 | D7: 16.1841 | E7: 15.0999 | G7: 0.3
B8: 0.4 | C8: 15.6473 | D8: 16.2887 | E8: 15.9661 | G8: 0.4
B9: 0.5 | C9: 15.6473 | D9: 16.2887 | E9: 15.9661 | G9: 0.5
B10: 0.6 | C10: 15.5735 | D10: 16.3182 | E10: 15.9437 | G10: 0.6
B11: 0.7 | C11: 15.2115 | D11: 16.5192 | E11: 15.8563 | G11: 0.7
B12: 0.8 | C12: 12.9353 | D12: 16.669 | E12: 14.6662 | G12: 0.8
B13: 0.9 | C13: 13.0008 | D13: 16.67 | E13: 14.7059 | G13: 0.9
B14: 1 | C14: 13.0008 | D14: 16.67 | E14: 14.7059 | G14: 1
D16: mac
C18: 合流200m手前（後続120） | E18: 1250/750 | H18: 合流200m手前（後続120） | J18: 750/1250
B19: α | C19: vehicle0 | D19: vehicle1 | E19: all | G19: α | H19: vehicle0 | I19: vehicle1 | J19: all
B20: 0 | C20: 14.6294 | D20: 15.9228 | E20: 15.116 | G20: 0 | H20: 15.3193 | I20: 14.8627 | J20: 15.0254
B21: 0.1 | C21: 14.6294 | D21: 15.9228 | E21: 15.116 | G21: 0.1 | H21: 15.3193 | I21: 14.8627 | J21: 15.0254
B22: 0.2 | C22: 14.8394 | D22: 16.655 | E22: 15.5028 | G22: 0.2 | H22: 15.3193 | I22: 14.8627 | J22: 15.0254
B23: 0.3 | C23: 14.7953 | D23: 16.6659 | E23: 15.4784 | G23: 0.3 | H23: 13.3809 | I23: 14.8899 | J23: 14.3187
B24: 0.4 | C24: 14.7953 | D24: 16.6659 | E24: 15.4784 | G24: 0.4 | H24: 14.3668 | I24: 14.9431 | J24: 14.7319
B25: 0.5 | C25: 14.7953 | D25: 16.6659 | E25: 15.4784 | G25: 0.5 | H25: 12.836 | I25: 15.8515 | J25: 14.694
B26: 0.6 | C26: 14.7953 | D26: 16.6659 | E26: 15.4784 | G26: 0.6 | H26: 12.932 | I26: 15.9559 | J26: 14.7952
B27: 0.7 | C27: 14.8167 | D27: 16.6609 | E27: 15.4914 | G27: 0.7 | H27: 13.3202 | I27: 16.526 | J27: 15.2762
B28: 0.8 | C28: 14.8167 | D28: 16.6609 | E28: 15.4914 | G28: 0.8 | H28: 13.1103 | I28: 16.6053 | J28: 15.2166
B29: 0.9 | C29: 14.7809 | D29: 16.6675 | E29: 15.4696 | G29: 0.9 | H29: 13.0358 | I29: 16.67 | J29: 15.226
B30: 1 | C30: 14.7514 | D30: 16.67 | E30: 15.4513 | G30: 1 | H30: 13.0358 | I30: 16.67 | J30: 15.226
D32: mac | I32: hpc

Sheet seed9
C2: 合流200m手前（後続120） | E2: 1000/1000 | H2: 合流200m手前（後続120） | J2: 750/750
B3: α | C3: vehicle0 | D3: vehicle1 | E3: all | G3: α | H3: vehicle0 | I3: vehicle1 | J3: all
B4: 0 | C4: 14.6022 | D4: 13.301 | E4: 13.9709 | G4: 0
B5: 0.1 | C5: 14.5794 | D5: 13.3638 | E5: 13.9897 | G5: 0.1
B6: 0.2 | C6: 14.5101 | D6: 13.3538 | E6: 13.9498 | G6: 0.2
B7: 0.3 | C7: 15.2059 | D7: 14.8733 | E7: 15.0466 | G7: 0.3
B8: 0.4 | C8: 14.2486 | D8: 13.0437 | E8: 13.6775 | G8: 0.4
B9: 0.5 | C9: 14.3503 | D9: 14.9536 | E9: 14.6363 | G9: 0.5
B10: 0.6 | C10: 14.4578 | D10: 15.8551 | E10: 15.1049 | G10: 0.6
B11: 0.7 | C11: 13.2265 | D11: 16.4446 | E11: 14.6436 | G11: 0.7
B12: 0.8 | C12: 11.703 | D12: 16.6448 | E12: 13.7612 | G12: 0.8
B13: 0.9 | C13: 12.0417 | D13: 16.67 | E13: 13.9693 | G13: 0.9
B14: 1 | C14: 12.0417 | D14: 16.67 | E14: 13.9693 | G14: 1
D16: mac
C18: 合流200m手前（後続120） | E18: 1250/750 | H18: 合流200m手前（後続120） | J18: 750/1250
B19: α | C19: vehicle0 | D19: vehicle1 | E19: all | G19: α | H19: vehicle0 | I19: vehicle1 | J19: all
B20: 0 | C20: 12.9383 | D20: 14.712 | E20: 13.5952 | G20: 0 | H20: 15.6593 | I20: 13.7388 | J20: 14.4466
B21: 0.1 | C21: 12.9383 | D21: 14.712 | E21: 13.5952 | G21: 0.1 | H21: 15.6527 | I21: 13.7656 | J21: 14.4611
B22: 0.2 | C22: 12.9383 | D22: 14.712 | E22: 13.5952 | G22: 0.2 | H22: 14.0274 | I22: 15.1915 | J22: 14.7257
B23: 0.3 | C23: 12.9383 | D23: 14.712 | E23: 13.5952 | G23: 0.3 | H23: 14.551 | I23: 13.6014 | J23: 13.956
B24: 0.4 | C24: 12.9803 | D24: 15.446 | E24: 13.8934 | G24: 0.4 | H24: 14.846 | I24: 16.0382 | J24: 15.5569
B25: 0.5 | C25: 13.8609 | D25: 15.9965 | E25: 14.6488 | G25: 0.5 | H25: 13.9088 | I25: 15.9104 | J25: 15.0898
B26: 0.6 | C26: 13.8688 | D26: 16.0766 | E26: 14.6823 | G26: 0.6 | H26: 13.867 | I26: 16.1865 | J26: 15.2356
B27: 0.7 | C27: 13.7545 | D27: 15.5264 | E27: 14.4187 | G27: 0.7 | H27: 10.1055 | I27: 15.5299 | J27: 13.0477
B28: 0.8 | C28: 11.8265 | D28: 16.482 | E28: 13.4336 | G28: 0.8 | H28: 9.7418 | I28: 16.6143 | J28: 13.2927
B29: 0.9 | C29: 11.7696 | D29: 16.5543 | E29: 13.4117 | G29: 0.9 | H29: 9.7418 | I29: 16.6143 | J29: 13.2927
B30: 1 | C30: 11.7696 | D30: 16.5543 | E30: 13.4117 | G30: 1 | H30: 9.7418 | I30: 16.6143 | J30: 13.2927
D32: hpc | I32: hpc

Sheet seed10
C2: 合流200m手前（後続120） | E2: 1000/1000 | H2: 合流200m手前（後続120） | J2: 750/750
B3: α | C3: vehicle0 | D3: vehicle1 | E3: all | G3: α | H3: vehicle0 | I3: vehicle1 | J3: all
B4: 0 | C4: 11.9406 | D4: 11.9671 | E4: 11.9531 | G4: 0
B5: 0.1 | C5: 11.9406 | D5: 11.9671 | E5: 11.9531 | G5: 0.1
B6: 0.2 | C6: 10.0883 | D6: 12.318 | E6: 11.0751 | G6: 0.2 | M6: 0.2の時、vehicle12が本線上で停止
B7: 0.3 | C7: 13.0838 | D7: 13.0825 | E7: 13.0832 | G7: 0.3
B8: 0.4 | C8: 13.2731 | D8: 13.4602 | E8: 13.3605 | G8: 0.4
B9: 0.5 | C9: 12.9609 | D9: 14.2486 | E9: 13.5621 | G9: 0.5
B10: 0.6 | C10: 12.9475 | D10: 14.2468 | E10: 13.5542 | G10: 0.6
B11: 0.7 | C11: 12.357 | D11: 16.3762 | E11: 14.0906 | G11: 0.7
B12: 0.8 | C12: 10.1493 | D12: 16.6248 | E12: 12.7464 | G12: 0.8
B13: 0.9 | C13: 10.134 | D13: 16.67 | E13: 12.7557 | G13: 0.9
B14: 1 | C14: 10.134 | D14: 16.67 | E14: 12.7557 | G14: 1
D16: mac
C18: 合流200m手前（後続120） | E18: 1250/750 | H18: 合流200m手前（後続120） | J18: 750/1250
B19: α | C19: vehicle0 | D19: vehicle1 | E19: all | G19: α | H19: vehicle0 | I19: vehicle1 | J19: all
B20: 0 | C20: 11.6523 | D20: 9.9703 | E20: 11.0684 | G20: 0 | H20: 10.5588 | I20: 11.6986 | J20: 11.2036
B21: 0.1 | C21: 11.6523 | D21: 9.9703 | E21: 11.0684 | G21: 0.1 | H21: 10.5588 | I21: 11.6986 | J21: 11.2036
B22: 0.2 | C22: 11.2529 | D22: 13.2963 | E22: 11.9185 | G22: 0.2 | H22: 10.5588 | I22: 11.6986 | J22: 11.2036
B23: 0.3 | C23: 11.9632 | D23: 13.0371 | E23: 12.313 | G23: 0.3 | H23: 10.5574 | I23: 11.7044 | J23: 11.2063
B24: 0.4 | C24: 11.993 | D24: 13.2929 | E24: 12.4164 | G24: 0.4 | H24: 10.5368 | I24: 11.9051 | J24: 11.3067
B25: 0.5 | C25: 12.4221 | D25: 12.9076 | E25: 12.5901 | G25: 0.5 | H25: 9.8356 | I25: 13.6792 | J25: 11.8936
B26: 0.6 | C26: 12.2663 | D26: 12.7505 | E26: 12.4338 | G26: 0.6 | H26: 9.0694 | I26: 15.1921 | J26: 12.2656
B27: 0.7 | C27: 11.9542 | D27: 14.0992 | E27: 12.6705 | G27: 0.7 | H27: 9.5992 | I27: 15.5432 | J27: 12.7993
B28: 0.8 | C28: 11.9901 | D28: 15.7057 | E28: 13.1545 | G28: 0.8 | H28: 9.1212 | I28: 16.6697 | J28: 12.9567
B29: 0.9 | C29: 12.2766 | D29: 16.67 | E29: 13.6072 | G29: 0.9 | H29: 9.1101 | I29: 16.67 | J29: 12.9479
B30: 1 | C30: 12.2766 | D30: 16.67 | E30: 13.6072 | G30: 1 | H30: 9.1101 | I30: 16.67 | J30: 12.9479
D32: hpc | I32: hpc

Sheet average1-10
C2: 合流200m手前（後続120） | E2: 1000/1000 | H2: 合流200m手前（後続120） | J2: 750/750
B3: α | C3: vehicle0 | D3: vehicle1 | E3: all | G3: α | H3: vehicle0 | I3: vehicle1 | J3: all | L3: α | M3: 120m後方考慮 | N3: 200m後方考慮
B4: 0 | C4: =ROUND(AVERAGE(seed1!C4,seed2!C4,seed3!C4,seed4!C4,seed5!C4,seed7!C4,seed8!C4,seed9!C4,seed10!C4),4) -> 14.8078 | D4: =ROUND(AVERAGE(seed1!D4,seed2!D4,seed3!D4,seed4!D4,seed5!D4,seed7!D4,seed8!D4,seed9!D4,seed10!D4),4) -> 13.871 | E4: =ROUND(AVERAGE(seed1!E4,seed2!E4,seed3!E4,seed4!E4,seed5!E4,seed7!E4,seed8!E4,seed9!E4,seed10!E4),4) -> 14.3487 | G4: 0 | L4: 0 | M4: 14.3487 | N4: 14.3486
B5: 0.1 | C5: =ROUND(AVERAGE(seed1!C5,seed2!C5,seed3!C5,seed4!C5,seed5!C5,seed7!C5,seed8!C5,seed9!C5,seed10!C5),4) -> 14.8045 | D5: =ROUND(AVERAGE(seed1!D5,seed2!D5,seed3!D5,seed4!D5,seed5!D5,seed7!D5,seed8!D5,seed9!D5,seed10!D5),4) -> 13.9046 | E5: =ROUND(AVERAGE(seed1!E5,seed2!E5,seed3!E5,seed4!E5,seed5!E5,seed7!E5,seed8!E5,seed9!E5,seed10!E5),4) -> 14.3632 | G5: 0.1 | L5: 0.1 | M5: 14.3632 | N5: 14.3486
B6: 0.2 | C6: =ROUND(AVERAGE(seed1!C6,seed2!C6,seed3!C6,seed4!C6,seed5!C6,seed7!C6,seed8!C6,seed9!C6,seed10!C6),4) -> 14.3585 | D6: =ROUND(AVERAGE(seed1!D6,seed2!D6,seed3!D6,seed4!D6,seed5!D6,seed7!D6,seed8!D6,seed9!D6,seed10!D6),4) -> 14.2552 | E6: =ROUND(AVERAGE(seed1!E6,seed2!E6,seed3!E6,seed4!E6,seed5!E6,seed7!E6,seed8!E6,seed9!E6,seed10!E6),4) -> 14.2965 | G6: 0.2 | L6: 0.2 | M6: 14.2965 | N6: 14.3905
B7: 0.3 | C7: =ROUND(AVERAGE(seed1!C7,seed2!C7,seed3!C7,seed4!C7,seed5!C7,seed7!C7,seed8!C7,seed9!C7,seed10!C7),4) -> 14.6798 | D7: =ROUND(AVERAGE(seed1!D7,seed2!D7,seed3!D7,seed4!D7,seed5!D7,seed7!D7,seed8!D7,seed9!D7,seed10!D7),4) -> 14.0924 | E7: =ROUND(AVERAGE(seed1!E7,seed2!E7,seed3!E7,seed4!E7,seed5!E7,seed7!E7,seed8!E7,seed9!E7,seed10!E7),4) -> 14.3792 | G7: 0.3 | L7: 0.3 | M7: 14.3792 | N7: 14.4561
B8: 0.4 | C8: =ROUND(AVERAGE(seed1!C8,seed2!C8,seed3!C8,seed4!C8,seed5!C8,seed7!C8,seed8!C8,seed9!C8,seed10!C8),4) -> 14.6163 | D8: =ROUND(AVERAGE(seed1!D8,seed2!D8,seed3!D8,seed4!D8,seed5!D8,seed7!D8,seed8!D8,seed9!D8,seed10!D8),4) -> 14.7715 | E8: =ROUND(AVERAGE(seed1!E8,seed2!E8,seed3!E8,seed4!E8,seed5!E8,seed7!E8,seed8!E8,seed9!E8,seed10!E8),4) -> 14.6875 | G8: 0.4 | L8: 0.4 | M8: 14.6875 | N8: 14.6643
B9: 0.5 | C9: =ROUND(AVERAGE(seed1!C9,seed2!C9,seed3!C9,seed4!C9,seed5!C9,seed7!C9,seed8!C9,seed9!C9,seed10!C9),4) -> 14.6085 | D9: =ROUND(AVERAGE(seed1!D9,seed2!D9,seed3!D9,seed4!D9,seed5!D9,seed7!D9,seed8!D9,seed9!D9,seed10!D9),4) -> 15.4466 | E9: =ROUND(AVERAGE(seed1!E9,seed2!E9,seed3!E9,seed4!E9,seed5!E9,seed7!E9,seed8!E9,seed9!E9,seed10!E9),4) -> 15.0115 | G9: 0.5 | L9: 0.5 | M9: 15.0115 | N9: 14.9031
B10: 0.6 | C10: =ROUND(AVERAGE(seed1!C10,seed2!C10,seed3!C10,seed4!C10,seed5!C10,seed7!C10,seed8!C10,seed9!C10,seed10!C10),4) -> 14.1616 | D10: =ROUND(AVERAGE(seed1!D10,seed2!D10,seed3!D10,seed4!D10,seed5!D10,seed7!D10,seed8!D10,seed9!D10,seed10!D10),4) -> 15.6244 | E10: =ROUND(AVERAGE(seed1!E10,seed2!E10,seed3!E10,seed4!E10,seed5!E10,seed7!E10,seed8!E10,seed9!E10,seed10!E10),4) -> 14.8647 | G10: 0.6 | L10: 0.6 | M10: 14.8647 | N10: 14.9489
B11: 0.7 | C11: =ROUND(AVERAGE(seed1!C11,seed2!C11,seed3!C11,seed4!C11,seed5!C11,seed7!C11,seed8!C11,seed9!C11,seed10!C11),4) -> 13.4235 | D11: =ROUND(AVERAGE(seed1!D11,seed2!D11,seed3!D11,seed4!D11,seed5!D11,seed7!D11,seed8!D11,seed9!D11,seed10!D11),4) -> 16.3549 | E11: =ROUND(AVERAGE(seed1!E11,seed2!E11,seed3!E11,seed4!E11,seed5!E11,seed7!E11,seed8!E11,seed9!E11,seed10!E11),4) -> 14.7548 | G11: 0.7 | L11: 0.7 | M11: 14.7548 | N11: 14.7089
B12: 0.8 | C12: =ROUND(AVERAGE(seed1!C12,seed2!C12,seed3!C12,seed4!C12,seed5!C12,seed7!C12,seed8!C12,seed9!C12,seed10!C12),4) -> 12.187 | D12: =ROUND(AVERAGE(seed1!D12,seed2!D12,seed3!D12,seed4!D12,seed5!D12,seed7!D12,seed8!D12,seed9!D12,seed10!D12),4) -> 16.6311 | E12: =ROUND(AVERAGE(seed1!E12,seed2!E12,seed3!E12,seed4!E12,seed5!E12,seed7!E12,seed8!E12,seed9!E12,seed10!E12),4) -> 14.1245 | G12: 0.8 | L12: 0.8 | M12: 14.1245 | N12: 14.2452
B13: 0.9 | C13: =ROUND(AVERAGE(seed1!C13,seed2!C13,seed3!C13,seed4!C13,seed5!C13,seed7!C13,seed8!C13,seed9!C13,seed10!C13),4) -> 11.9504 | D13: =ROUND(AVERAGE(seed1!D13,seed2!D13,seed3!D13,seed4!D13,seed5!D13,seed7!D13,seed8!D13,seed9!D13,seed10!D13),4) -> 16.6694 | E13: =ROUND(AVERAGE(seed1!E13,seed2!E13,seed3!E13,seed4!E13,seed5!E13,seed7!E13,seed8!E13,seed9!E13,seed10!E13),4) -> 14.0076 | G13: 0.9 | L13: 0.9 | M13: 14.0076 | N13: 13.9316
B14: 1 | C14: =ROUND(AVERAGE(seed1!C14,seed2!C14,seed3!C14,seed4!C14,seed5!C14,seed7!C14,seed8!C14,seed9!C14,seed10!C14),4) -> 11.8317 | D14: =ROUND(AVERAGE(seed1!D14,seed2!D14,seed3!D14,seed4!D14,seed5!D14,seed7!D14,seed8!D14,seed9!D14,seed10!D14),4) -> 16.67 | E14: =ROUND(AVERAGE(seed1!E14,seed2!E14,seed3!E14,seed4!E14,seed5!E14,seed7!E14,seed8!E14,seed9!E14,seed10!E14),4) -> 13.9347 | G14: 1 | L14: 1 | M14: 13.9347 | N14: 13.9347
C18: 合流200m手前（後続120） | E18: 1250/750 | H18: 合流200m手前（後続120） | J18: 750/1250
B19: α | C19: vehicle0 | D19: vehicle1 | E19: all | G19: α | H19: vehicle0 | I19: vehicle1 | J19: all
B20: 0 | C20: =ROUND(AVERAGE(seed1!C20,seed2!C20,seed3!C20,seed4!C20,seed5!C20,seed7!C20,seed8!C20,seed9!C20,seed10!C20),4) -> 13.7094 | D20: =ROUND(AVERAGE(seed1!D20,seed2!D20,seed3!D20,seed4!D20,seed5!D20,seed7!D20,seed8!D20,seed9!D20,seed10!D20),4) -> 13.6784 | E20: =ROUND(AVERAGE(seed1!E20,seed2!E20,seed3!E20,seed4!E20,seed5!E20,seed7!E20,seed8!E20,seed9!E20,seed10!E20),4) -> 13.7104 | G20: 0 | H20: =ROUND(AVERAGE(seed1!H20,seed2!H20,seed3!H20,seed4!H20,seed5!H20,seed7!H20,seed8!H20,seed9!H20,seed10!H20),4) -> 14.4399 | I20: =ROUND(AVERAGE(seed1!I20,seed2!I20,seed3!I20,seed4!I20,seed5!I20,seed7!I20,seed8!I20,seed9!I20,seed10!I20),4) -> 13.9845 | J20: =ROUND(AVERAGE(seed1!J20,seed2!J20,seed3!J20,seed4!J20,seed5!J20,seed7!J20,seed8!J20,seed9!J20,seed10!J20),4) -> 14.1472
B21: 0.1 | C21: =ROUND(AVERAGE(seed1!C21,seed2!C21,seed3!C21,seed4!C21,seed5!C21,seed7!C21,seed8!C21,seed9!C21,seed10!C21),4) -> 13.7094 | D21: =ROUND(AVERAGE(seed1!D21,seed2!D21,seed3!D21,seed4!D21,seed5!D21,seed7!D21,seed8!D21,seed9!D21,seed10!D21),4) -> 13.6784 | E21: =ROUND(AVERAGE(seed1!E21,seed2!E21,seed3!E21,seed4!E21,seed5!E21,seed7!E21,seed8!E21,seed9!E21,seed10!E21),4) -> 13.7104 | G21: 0.1 | H21: =ROUND(AVERAGE(seed1!H21,seed2!H21,seed3!H21,seed4!H21,seed5!H21,seed7!H21,seed8!H21,seed9!H21,seed10!H21),4) -> 14.4514 | I21: =ROUND(AVERAGE(seed1!I21,seed2!I21,seed3!I21,seed4!I21,seed5!I21,seed7!I21,seed8!I21,seed9!I21,seed10!I21),4) -> 13.9938 | J21: =ROUND(AVERAGE(seed1!J21,seed2!J21,seed3!J21,seed4!J21,seed5!J21,seed7!J21,seed8!J21,seed9!J21,seed10!J21),4) -> 14.1571
B22: 0.2 | C22: =ROUND(AVERAGE(seed1!C22,seed2!C22,seed3!C22,seed4!C22,seed5!C22,seed7!C22,seed8!C22,seed9!C22,seed10!C22),4) -> 13.7408 | D22: =ROUND(AVERAGE(seed1!D22,seed2!D22,seed3!D22,seed4!D22,seed5!D22,seed7!D22,seed8!D22,seed9!D22,seed10!D22),4) -> 14.1014 | E22: =ROUND(AVERAGE(seed1!E22,seed2!E22,seed3!E22,seed4!E22,seed5!E22,seed7!E22,seed8!E22,seed9!E22,seed10!E22),4) -> 13.8677 | G22: 0.2 | H22: =ROUND(AVERAGE(seed1!H22,seed2!H22,seed3!H22,seed4!H22,seed5!H22,seed7!H22,seed8!H22,seed9!H22,seed10!H22),4) -> 14.2602 | I22: =ROUND(AVERAGE(seed1!I22,seed2!I22,seed3!I22,seed4!I22,seed5!I22,seed7!I22,seed8!I22,seed9!I22,seed10!I22),4) -> 14.379 | J22: =ROUND(AVERAGE(seed1!J22,seed2!J22,seed3!J22,seed4!J22,seed5!J22,seed7!J22,seed8!J22,seed9!J22,seed10!J22),4) -> 14.3247
B23: 0.3 | C23: =ROUND(AVERAGE(seed1!C23,seed2!C23,seed3!C23,seed4!C23,seed5!C23,seed7!C23,seed8!C23,seed9!C23,seed10!C23),4) -> 13.6017 | D23: =ROUND(AVERAGE(seed1!D23,seed2!D23,seed3!D23,seed4!D23,seed5!D23,seed7!D23,seed8!D23,seed9!D23,seed10!D23),4) -> 14.1144 | E23: =ROUND(AVERAGE(seed1!E23,seed2!E23,seed3!E23,seed4!E23,seed5!E23,seed7!E23,seed8!E23,seed9!E23,seed10!E23),4) -> 13.7865 | G23: 0.3 | H23: =ROUND(AVERAGE(seed1!H23,seed2!H23,seed3!H23,seed4!H23,seed5!H23,seed7!H23,seed8!H23,seed9!H23,seed10!H23),4) -> 13.7733 | I23: =ROUND(AVERAGE(seed1!I23,seed2!I23,seed3!I23,seed4!I23,seed5!I23,seed7!I23,seed8!I23,seed9!I23,seed10!I23),4) -> 14.6309 | J23: =ROUND(AVERAGE(seed1!J23,seed2!J23,seed3!J23,seed4!J23,seed5!J23,seed7!J23,seed8!J23,seed9!J23,seed10!J23),4) -> 14.2912
B24: 0.4 | C24: =ROUND(AVERAGE(seed1!C24,seed2!C24,seed3!C24,seed4!C24,seed5!C24,seed7!C24,seed8!C24,seed9!C24,seed10!C24),4) -> 13.7833 | D24: =ROUND(AVERAGE(seed1!D24,seed2!D24,seed3!D24,seed4!D24,seed5!D24,seed7!D24,seed8!D24,seed9!D24,seed10!D24),4) -> 14.5627 | E24: =ROUND(AVERAGE(seed1!E24,seed2!E24,seed3!E24,seed4!E24,seed5!E24,seed7!E24,seed8!E24,seed9!E24,seed10!E24),4) -> 14.0668 | G24: 0.4 | H24: =ROUND(AVERAGE(seed1!H24,seed2!H24,seed3!H24,seed4!H24,seed5!H24,seed7!H24,seed8!H24,seed9!H24,seed10!H24),4) -> 13.7988 | I24: =ROUND(AVERAGE(seed1!I24,seed2!I24,seed3!I24,seed4!I24,seed5!I24,seed7!I24,seed8!I24,seed9!I24,seed10!I24),4) -> 15.1714 | J24: =ROUND(AVERAGE(seed1!J24,seed2!J24,seed3!J24,seed4!J24,seed5!J24,seed7!J24,seed8!J24,seed9!J24,seed10!J24),4) -> 14.616
B25: 0.5 | C25: =ROUND(AVERAGE(seed1!C25,seed2!C25,seed3!C25,seed4!C25,seed5!C25,seed7!C25,seed8!C25,seed9!C25,seed10!C25),4) -> 13.8348 | D25: =ROUND(AVERAGE(seed1!D25,seed2!D25,seed3!D25,seed4!D25,seed5!D25,seed7!D25,seed8!D25,seed9!D25,seed10!D25),4) -> 15.1623 | E25: =ROUND(AVERAGE(seed1!E25,seed2!E25,seed3!E25,seed4!E25,seed5!E25,seed7!E25,seed8!E25,seed9!E25,seed10!E25),4) -> 14.312 | G25: 0.5 | H25: =ROUND(AVERAGE(seed1!H25,seed2!H25,seed3!H25,seed4!H25,seed5!H25,seed7!H25,seed8!H25,seed9!H25,seed10!H25),4) -> 13.3813 | I25: =ROUND(AVERAGE(seed1!I25,seed2!I25,seed3!I25,seed4!I25,seed5!I25,seed7!I25,seed8!I25,seed9!I25,seed10!I25),4) -> 15.6326 | J25: =ROUND(AVERAGE(seed1!J25,seed2!J25,seed3!J25,seed4!J25,seed5!J25,seed7!J25,seed8!J25,seed9!J25,seed10!J25),4) -> 14.7035
B26: 0.6 | C26: =ROUND(AVERAGE(seed1!C26,seed2!C26,seed3!C26,seed4!C26,seed5!C26,seed7!C26,seed8!C26,seed9!C26,seed10!C26),4) -> 13.96 | D26: =ROUND(AVERAGE(seed1!D26,seed2!D26,seed3!D26,seed4!D26,seed5!D26,seed7!D26,seed8!D26,seed9!D26,seed10!D26),4) -> 15.3971 | E26: =ROUND(AVERAGE(seed1!E26,seed2!E26,seed3!E26,seed4!E26,seed5!E26,seed7!E26,seed8!E26,seed9!E26,seed10!E26),4) -> 14.4815 | G26: 0.6 | H26: =ROUND(AVERAGE(seed1!H26,seed2!H26,seed3!H26,seed4!H26,seed5!H26,seed7!H26,seed8!H26,seed9!H26,seed10!H26),4) -> 13.0518 | I26: =ROUND(AVERAGE(seed1!I26,seed2!I26,seed3!I26,seed4!I26,seed5!I26,seed7!I26,seed8!I26,seed9!I26,seed10!I26),4) -> 16.1386 | J26: =ROUND(AVERAGE(seed1!J26,seed2!J26,seed3!J26,seed4!J26,seed5!J26,seed7!J26,seed8!J26,seed9!J26,seed10!J26),4) -> 14.8357
B27: 0.7 | C27: =ROUND(AVERAGE(seed1!C27,seed2!C27,seed3!C27,seed4!C27,seed5!C27,seed7!C27,seed8!C27,seed9!C27,seed10!C27),4) -> 13.5139 | D27: =ROUND(AVERAGE(seed1!D27,seed2!D27,seed3!D27,seed4!D27,seed5!D27,seed7!D27,seed8!D27,seed9!D27,seed10!D27),4) -> 15.5476 | E27: =ROUND(AVERAGE(seed1!E27,seed2!E27,seed3!E27,seed4!E27,seed5!E27,seed7!E27,seed8!E27,seed9!E27,seed10!E27),4) -> 14.2266 | G27: 0.7 | H27: =ROUND(AVERAGE(seed1!H27,seed2!H27,seed3!H27,seed4!H27,seed5!H27,seed7!H27,seed8!H27,seed9!H27,seed10!H27),4) -> 12.7533 | I27: =ROUND(AVERAGE(seed1!I27,seed2!I27,seed3!I27,seed4!I27,seed5!I27,seed7!I27,seed8!I27,seed9!I27,seed10!I27),4) -> 16.1696 | J27: =ROUND(AVERAGE(seed1!J27,seed2!J27,seed3!J27,seed4!J27,seed5!J27,seed7!J27,seed8!J27,seed9!J27,seed10!J27),4) -> 14.7143
B28: 0.8 | C28: =ROUND(AVERAGE(seed1!C28,seed2!C28,seed3!C28,seed4!C28,seed5!C28,seed7!C28,seed8!C28,seed9!C28,seed10!C28),4) -> 13.1785 | D28: =ROUND(AVERAGE(seed1!D28,seed2!D28,seed3!D28,seed4!D28,seed5!D28,seed7!D28,seed8!D28,seed9!D28,seed10!D28),4) -> 16.437 | E28: =ROUND(AVERAGE(seed1!E28,seed2!E28,seed3!E28,seed4!E28,seed5!E28,seed7!E28,seed8!E28,seed9!E28,seed10!E28),4) -> 14.2899 | G28: 0.8 | H28: =ROUND(AVERAGE(seed1!H28,seed2!H28,seed3!H28,seed4!H28,seed5!H28,seed7!H28,seed8!H28,seed9!H28,seed10!H28),4) -> 10.9964 | I28: =ROUND(AVERAGE(seed1!I28,seed2!I28,seed3!I28,seed4!I28,seed5!I28,seed7!I28,seed8!I28,seed9!I28,seed10!I28),4) -> 16.6542 | J28: =ROUND(AVERAGE(seed1!J28,seed2!J28,seed3!J28,seed4!J28,seed5!J28,seed7!J28,seed8!J28,seed9!J28,seed10!J28),4) -> 14.1222
B29: 0.9 | C29: =ROUND(AVERAGE(seed1!C29,seed2!C29,seed3!C29,seed4!C29,seed5!C29,seed7!C29,seed8!C29,seed9!C29,seed10!C29),4) -> 13.0221 | D29: =ROUND(AVERAGE(seed1!D29,seed2!D29,seed3!D29,seed4!D29,seed5!D29,seed7!D29,seed8!D29,seed9!D29,seed10!D29),4) -> 16.6322 | E29: =ROUND(AVERAGE(seed1!E29,seed2!E29,seed3!E29,seed4!E29,seed5!E29,seed7!E29,seed8!E29,seed9!E29,seed10!E29),4) -> 14.2438 | G29: 0.9 | H29: =ROUND(AVERAGE(seed1!H29,seed2!H29,seed3!H29,seed4!H29,seed5!H29,seed7!H29,seed8!H29,seed9!H29,seed10!H29),4) -> 10.9886 | I29: =ROUND(AVERAGE(seed1!I29,seed2!I29,seed3!I29,seed4!I29,seed5!I29,seed7!I29,seed8!I29,seed9!I29,seed10!I29),4) -> 16.6617 | J29: =ROUND(AVERAGE(seed1!J29,seed2!J29,seed3!J29,seed4!J29,seed5!J29,seed7!J29,seed8!J29,seed9!J29,seed10!J29),4) -> 14.1233
B30: 1 | C30: =ROUND(AVERAGE(seed1!C30,seed2!C30,seed3!C30,seed4!C30,seed5!C30,seed7!C30,seed8!C30,seed9!C30,seed10!C30),4) -> 12.9088 | D30: =ROUND(AVERAGE(seed1!D30,seed2!D30,seed3!D30,seed4!D30,seed5!D30,seed7!D30,seed8!D30,seed9!D30,seed10!D30),4) -> 16.6571 | E30: =ROUND(AVERAGE(seed1!E30,seed2!E30,seed3!E30,seed4!E30,seed5!E30,seed7!E30,seed8!E30,seed9!E30,seed10!E30),4) -> 14.1743 | G30: 1 | H30: =ROUND(AVERAGE(seed1!H30,seed2!H30,seed3!H30,seed4!H30,seed5!H30,seed7!H30,seed8!H30,seed9!H30,seed10!H30),4) -> 10.9886 | I30: =ROUND(AVERAGE(seed1!I30,seed2!I30,seed3!I30,seed4!I30,seed5!I30,seed7!I30,seed8!I30,seed9!I30,seed10!I30),4) -> 16.6617 | J30: =ROUND(AVERAGE(seed1!J30,seed2!J30,seed3!J30,seed4!J30,seed5!J30,seed7!J30,seed8!J30,seed9!J30,seed10!J30),4) -> 14.1233

Sheet seed11
C2: 合流200m手前（後続120） | E2: 1000/1000
B3: α | C3: vehicle0 | D3: vehicle1 | E3: all
B4: 0 | C4: 14.9702 | D4: 14.926 | E4: 14.9482
B5: 0.1 | C5: 14.9702 | D5: 14.926 | E5: 14.9482
B6: 0.2 | C6: 14.9666 | D6: 14.9824 | E6: 14.9745
B7: 0.3 | C7: 14.9531 | D7: 15.0205 | E7: 14.9868
B8: 0.4 | C8: 14.9336 | D8: 15.0333 | E8: 14.9834
B9: 0.5 | C9: 14.7881 | D9: 15.7739 | E9: 15.2802
B10: 0.6 | C10: 15.1361 | D10: 15.7582 | E10: 15.4468
B11: 0.7 | C11: 11.3261 | D11: 16.5774 | E11: 13.7191
B12: 0.8 | C12: 11.3913 | D12: 16.5926 | E12: 13.7615
B13: 0.9 | C13: 11.2703 | D13: 16.67 | E13: 13.7309
B14: 1 | C14: 11.2703 | D14: 16.67 | E14: 13.7309
D16: mac

Sheet seed12
C2: 合流200m手前（後続120） | E2: 1000/1000
B3: α | C3: vehicle0 | D3: vehicle1 | E3: all
B4: 0 | C4: 12.9883 | D4: 12.8924 | E4: 12.9457
B5: 0.1 | C5: 12.9883 | D5: 12.8924 | E5: 12.9457
B6: 0.2 | C6: 12.9965 | D6: 13.0063 | E6: 13.0009 | G6: veh18が低速走行
B7: 0.3 | C7: 13.4722 | D7: 13.4647 | E7: 13.4689
B8: 0.4 | C8: 11.9146 | D8: 14.2103 | E8: 12.9217
B9: 0.5 | C9: 13.3701 | D9: 15.7243 | E9: 14.3962
B10: 0.6 | C10: 12.8824 | D10: 15.4109 | E10: 13.9894
B11: 0.7 | C11: 13.0472 | D11: 15.9915 | E11: 14.3203
B12: 0.8 | C12: 11.6837 | D12: 15.8081 | E12: 13.4383
B13: 0.9 | C13: 12.0619 | D13: 16.67 | E13: 13.9616
B14: 1 | C14: 12.0619 | D14: 16.67 | E14: 13.9616
D16: mac

Sheet seed13
C2: 合流200m手前（後続120） | E2: 1000/1000
B3: α | C3: vehicle0 | D3: vehicle1 | E3: all
B4: 0 | C4: 12.142 | D4: 12.4002 | E4: 12.2698
B5: 0.1 | C5: 12.142 | D5: 12.4002 | E5: 12.2698
B6: 0.2 | C6: 12.1406 | D6: 12.4055 | E6: 12.2717
B7: 0.3 | C7: 12.1406 | D7: 12.4055 | E7: 12.2717
B8: 0.4 | C8: 12.0684 | D8: 12.3956 | E8: 12.2297
B9: 0.5 | C9: 12.2864 | D9: 13.5039 | E9: 12.8666
B10: 0.6 | C10: 11.0842 | D10: 15.4895 | E10: 12.9652
B11: 0.7 | C11: 10.851 | D11: 15.9836 | E11: 13.0139
B12: 0.8 | C12: 9.9883 | D12: 16.3382 | E12: 12.513
B13: 0.9 | C13: 9.6273 | D13: 16.67 | E13: 12.3922
B14: 1 | C14: 9.6273 | D14: 16.67 | E14: 12.3922
D16: mac

Sheet seed14
C2: 合流200m手前（後続120） | E2: 1000/1000
B3: α | C3: vehicle0 | D3: vehicle1 | E3: all
B4: 0 | C4: 11.8174 | D4: 11.9574 | E4: 11.8868
B5: 0.1 | C5: 11.8174 | D5: 11.9574 | E5: 11.8868
B6: 0.2 | C6: 11.8445 | D6: 12.0619 | E6: 11.9521
B7: 0.3 | C7: 11.8428 | D7: 12.064 | E7: 11.9523
B8: 0.4 | C8: 11.5248 | D8: 12.5174 | E8: 12.0163
B9: 0.5 | C9: 11.0028 | D9: 15.6013 | E9: 13.0494
B10: 0.6 | C10: 11.6116 | D10: 14.863 | E10: 13.1471
B11: 0.7 | C11: 11.0149 | D11: 15.9019 | E11: 13.1858
B12: 0.8 | C12: 10.5352 | D12: 16.5975 | E12: 13.1686
B13: 0.9 | C13: 10.2834 | D13: 16.67 | E13: 13.0124
B14: 1 | C14: 10.2834 | D14: 16.67 | E14: 13.0124
D16: mac

Sheet seed15
C2: 合流200m手前（後続120） | E2: 1000/1000
B3: α | C3: vehicle0 | D3: vehicle1 | E3: all
B4: 0 | C4: 11.0315 | D4: 13.6134 | E4: 12.287
B5: 0.1 | C5: 11.0315 | D5: 13.6134 | E5: 12.287
B6: 0.2 | C6: 11.0315 | D6: 13.6134 | E6: 12.287
B7: 0.3 | C7: 11.0315 | D7: 13.6134 | E7: 12.287
B8: 0.4 | C8: 11.3247 | D8: 14.374 | E8: 12.7691
B9: 0.5 | C9: 11.2187 | D9: 15.1541 | E9: 13.0506
B10: 0.6 | C10: 11.3018 | D10: 15.2821 | E10: 13.1546
B11: 0.7 | C11: 12.1642 | D11: 16.1718 | E11: 14.0175
B12: 0.8 | C12: 11.1374 | D12: 16.6697 | E12: 13.6085
B13: 0.9 | C13: 10.4423 | D13: 16.67 | E13: 13.2197
B14: 1 | C14: 10.4423 | D14: 16.67 | E14: 13.2197
D16: mac

Sheet average1-15
C2: 合流200m手前（後続120） | E2: 1000/1000 | M2: 結果が良いseedの数
B3: α | C3: vehicle0 | D3: vehicle1 | E3: all | H3: α | I3: 後方120m考慮 | J3: 後方全て考慮 | L3: α | M3: 120m | N3: 後方全て | P3: 1 | Q3: 2 | R3: 3 | S3: 4 | T3: 5 | U3: 7 | V3: 8 | W3: 9 | X3: 10 | Y3: 11 | Z3: 12 | AA3: 13 | AB3: 14 | AC3: 15
B4: 0 | C4: =ROUND(AVERAGE(seed1!C4,seed2!C4,seed3!C4,seed4!C4,seed5!C4,seed7!C4,seed8!C4,seed9!C4,seed10!C4,seed11!C4,seed12!C4,seed13!C4,seed14!C4,seed15!C4),4) -> 14.0157 | D4: =ROUND(AVERAGE(seed1!D4,seed2!D4,seed3!D4,seed4!D4,seed5!D4,seed7!D4,seed8!D4,seed9!D4,seed10!D4,seed11!D4,seed12!D4,seed13!D4,seed14!D4,seed15!D4),4) -> 13.6163 | E4: =ROUND(AVERAGE(seed1!E4,seed2!E4,seed3!E4,seed4!E4,seed5!E4,seed7!E4,seed8!E4,seed9!E4,seed10!E4,seed11!E4,seed12!E4,seed13!E4,seed14!E4,seed15!E4),4) -> 13.8197 | H4: 0 | I4: 13.8197 | J4: 13.8197 | L4: 0 | M4: =COUNTIF(P4:AC4,"120") -> 0 | N4: =COUNTIF(P4:AC4,"200") -> 0
B5: 0.1 | C5: =ROUND(AVERAGE(seed1!C5,seed2!C5,seed3!C5,seed4!C5,seed5!C5,seed7!C5,seed8!C5,seed9!C5,seed10!C5,seed11!C5,seed12!C5,seed13!C5,seed14!C5,seed15!C5),4) -> 14.0135 | D5: =ROUND(AVERAGE(seed1!D5,seed2!D5,seed3!D5,seed4!D5,seed5!D5,seed7!D5,seed8!D5,seed9!D5,seed10!D5,seed11!D5,seed12!D5,seed13!D5,seed14!D5,seed15!D5),4) -> 13.6379 | E5: =ROUND(AVERAGE(seed1!E5,seed2!E5,seed3!E5,seed4!E5,seed5!E5,seed7!E5,seed8!E5,seed9!E5,seed10!E5,seed11!E5,seed12!E5,seed13!E5,seed14!E5,seed15!E5),4) -> 13.829 | H5: 0.1 | I5: 13.829 | J5: 13.8197 | L5: 0.1 | M5: =COUNTIF(P5:AC5,"120") -> 1 | N5: =COUNTIF(P5:AC5,"200") -> 0 | W5: 120
