Workbook

Sheet seed1
B2: 400/400/400 | K2: 600/600/600
C3: 1 | D3: 2 | E3: 3 | F3: 4 | G3: 5 | H3: 6 | I3: 7 | L3: 1 | M3: 2 | N3: 3 | O3: 4 | P3: 5 | Q3: 6 | R3: 7
C4: 全て受け入れ | D4: 道交法 | E4: 0.2 | F4: 0.4 | G4: 既存 | H4: 提案 | I4: 性能込み | L4: 全て受け入れ | M4: 道交法 | N4: 0.2 | O4: 0.4 | P4: 既存 | Q4: 提案 | R4: 性能込み
B5: （Bus） | C5: 4.9484 | D5: 5.1427 | E5: 5.2819 | F5: 5.4665 | G5: 4.8778 | H5: 5.1702 | I5: 5.3072 | K5: （Bus）
B6: （Car） | C6: 4.7052 | D6: 4.2178 | E6: 5.2813 | F6: 4.9021 | G6: 4.5188 | H6: 4.4672 | I6: 4.8639 | K6: （Car）
B7: 右折 | C7: 4.7486 | D7: 4.3639 | E7: 5.2814 | F7: 4.9976 | G7: 4.5815 | H7: 4.5832 | I7: 4.94 | K7: 右折
B8: （Bus） | C8: 5.1509 | D8: 3.7245 | E8: 4.8526 | F8: 4.6014 | G8: 4.221 | H8: 5.0416 | I8: 4.9312 | K8: （Bus）
B9: （Car） | C9: 5.22 | D9: 3.8813 | E9: 4.6203 | F9: 4.4973 | G9: 4.5429 | H9: 4.5315 | I9: 4.8721 | K9: （Car）
B10: 左折 | C10: 5.2013 | D10: 3.8377 | E10: 4.6803 | F10: 4.5246 | G10: 4.4523 | H10: 4.6574 | I10: 4.8877 | K10: 左折
B11: （Bus） | C11: 3.6968 | D11: 6.6452 | E11: 7.8324 | F11: 7.8591 | G11: 6.0411 | H11: 4.8068 | I11: 5.9136 | K11: （Bus）
B12: （Car） | C12: 5.0956 | D12: 7.6655 | E12: 7.5729 | F12: 7.1576 | G12: 5.5036 | H12: 6.3589 | I12: 6.932 | K12: （Car）
B13: 直進 | C13: 4.9305 | D13: 7.5631 | E13: 7.5951 | F13: 7.2144 | G13: 5.5472 | H13: 6.1823 | I13: 6.8279 | K13: 直進
B14: （Bus） | C14: 6.4516 | D14: 6.1404 | E14: 7.0247 | F14: 6.8235 | G14: 6.3755 | H14: 6.6181 | I14: 6.7718 | K14: （Bus）
B15: （Car） | C15: 6.9533 | D15: 6.9551 | E15: 7.6829 | F15: 7.4414 | G15: 6.8444 | H15: 7.0817 | I15: 7.466 | K15: （Car）
B16: 合計 | C16: 6.8583 | D16: 6.7932 | E16: 7.5568 | F16: 7.3233 | G16: 6.7557 | H16: 6.9946 | I16: 7.3317 | K16: 合計
A18: RB+BL | B18: 通過台数_L | C18: =32+31 -> 63 | D18: =32+29 -> 61 | E18: =32+31 -> 63 | F18: =32+31 -> 63 | G18: =32+31 -> 63 | H18: =32+31 -> 63 | I18: =32+31 -> 63 | J18: RB+BL | K18: 通過台数_L
A19: LB+BR | B19: 通過台数_R | C19: =25+33 -> 58 | D19: =25+33 -> 58 | E19: =25+33 -> 58 | F19: =25+33 -> 58 | G19: =25+33 -> 58 | H19: =25+33 -> 58 | I19: =25+33 -> 58 | J19: LB+BR | K19: 通過台数_R
A20: LR+RL | B20: 通過台数_B | C20: =37+31 -> 68 | D20: =37+31 -> 68 | E20: =37+31 -> 68 | F20: =37+31 -> 68 | G20: =37+31 -> 68 | H20: =37+31 -> 68 | I20: =37+31 -> 68 | J20: LR+RL | K20: 通過台数_B
B23: 500/500/500
C24: 1 | D24: 2 | E24: 3 | F24: 4 | G24: 5 | H24: 6 | I24: 7
C25: 全て受け入れ | D25: 道交法 | E25: 0.2 | F25: 0.4 | G25: 既存 | H25: 提案 | I25: 性能込み
B26: （Bus） | C26: 2.0236 | D26: 2.6786 | E26: 2.9066 | F26: 4.5069 | G26: 3.796 | H26: 3.6128 | I26: 1.5096
B27: （Car） | C27: 1.803 | D27: 3.2921 | E27: 3.1436 | F27: 4.1875 | G27: 3.6199 | H27: 4.0721 | I27: 1.7963
B28: 右折 | C28: 1.84 | D28: 3.1624 | E28: 3.0981 | F28: 4.241 | G28: 3.6501 | H28: 3.9814 | I28: 1.7476
B29: （Bus） | C29: 3.3522 | D29: 2.2684 | E29: 2.8877 | F29: 3.5842 | G29: 3.7003 | H29: 3.8558 | I29: 2.3118
B30: （Car） | C30: 3.3507 | D30: 2.0328 | E30: 2.9145 | F30: 3.7572 | G30: 3.6878 | H30: 3.7234 | I30: 2.6376
B31: 左折 | C31: 3.3511 | D31: 2.0942 | E31: 2.9069 | F31: 3.7073 | G31: 3.6913 | H31: 3.7599 | I31: 2.5353
B32: （Bus） | C32: 1.5744 | D32: 2.5892 | E32: 4.3672 | F32: 4.0151 | G32: 3.7561 | H32: 3.7845 | I32: 1.582
B33: （Car） | C33: 1.7369 | D33: 3.1287 | E33: 4.9445 | F33: 4.7395 | G33: 3.849 | H33: 4.6987 | I33: 3.1757
B34: 直進 | C34: 1.7126 | D34: 3.0286 | E34: 4.843 | F34: 4.6084 | G34: 3.8339 | H34: 4.5252 | I34: 2.8107
B35: （Bus） | C35: 3.6618 | D35: 3.9267 | E35: 4.7778 | F35: 5.6822 | G35: 5.4423 | H35: 5.4659 | I35: 3.0131
B36: （Car） | C36: 3.4574 | D36: 4.4086 | E36: 5.3616 | F36: 6.1695 | G36: 5.5571 | H36: 6.0156 | I36: 3.8312
B37: 合計 | C37: 3.4961 | D37: 4.3007 | E37: 5.2302 | F37: 6.0626 | G37: 5.5332 | H37: 5.8938 | I37: 3.6498
A39: RB+BL | B39: 通過台数_L | C39: =40+33 -> 73 | D39: =34+33 -> 67 | E39: =40+34 -> 74 | F39: =40+36 -> 76 | G39: =38+36 -> 74 | H39: =39+36 -> 75 | I39: =40+23 -> 63
A40: LB+BR | B40: 通過台数_R | C40: =25+42 -> 67 | D40: =38+42 -> 80 | E40: =38+42 -> 80 | F40: =38+45 -> 83 | G40: =37+45 -> 82 | H40: =37+45 -> 82 | I40: =22+30 -> 52
A41: LR+RL | B41: 通過台数_B | C41: =29+39 -> 68 | D41: =41+36 -> 77 | E41: =41+39 -> 80 | F41: =41+39 -> 80 | G41: =41+38 -> 79 | H41: =41+39 -> 80 | I41: =28+39 -> 67

Sheet seed2
B2: 400/400/400 | K2: 600/600/600
C3: 1 | D3: 2 | E3: 3 | F3: 4 | G3: 5 | H3: 6 | I3: 7 | L3: 1 | M3: 2 | N3: 3 | O3: 4 | P3: 5 | Q3: 6 | R3: 7
C4: 全て受け入れ | D4: 道交法 | E4: 0.2 | F4: 0.4 | G4: 既存 | H4: 提案 | I4: 性能込み | L4: 全て受け入れ | M4: 道交法 | N4: 0.2 | O4: 0.4 | P4: 既存 | Q4: 提案 | R4: 性能込み
B5: （Bus） | C5: 4.1693 | D5: 4.7627 | E5: 5.685 | F5: 5.4921 | G5: 4.7292 | H5: 5.5591 | I5: 5.6223 | K5: （Bus）
B6: （Car） | C6: 5.1283 | D6: 4.076 | E6: 5.3875 | F6: 5.7593 | G6: 4.6633 | H6: 5.5475 | I6: 5.3244 | K6: （Car）
B7: 右折 | C7: 4.894 | D7: 4.2016 | E7: 5.4458 | F7: 5.7019 | G7: 4.6768 | H7: 5.5499 | I7: 5.3832 | K7: 右折
B8: （Bus） | C8: 5.2783 | D8: 4.0999 | E8: 4.9374 | F8: 4.7342 | G8: 4.5034 | H8: 4.8531 | I8: 5.034 | K8: （Bus）
B9: （Car） | C9: 5.1929 | D9: 3.729 | E9: 4.5683 | F9: 4.6043 | G9: 4.1545 | H9: 5.0412 | I9: 4.8834 | K9: （Car）
B10: 左折 | C10: 5.2123 | D10: 3.8081 | E10: 4.6484 | F10: 4.6336 | G10: 4.2298 | H10: 4.9966 | I10: 4.9172 | K10: 左折
B11: （Bus） | C11: 3.3848 | D11: 8.5002 | E11: 8.2046 | F11: 7.9787 | G11: 4.6214 | H11: 5.9597 | I11: 7.3296 | K11: （Bus）
B12: （Car） | C12: 5.318 | D12: 7.658 | E12: 7.969 | F12: 7.6266 | G12: 5.5701 | H12: 7.7588 | I12: 7.6141 | K12: （Car）
B13: 直進 | C13: 4.767 | D13: 7.814 | E13: 8.0152 | F13: 7.6949 | G13: 5.3487 | H13: 7.3136 | I13: 7.5549 | K13: 直進
B14: （Bus） | C14: 5.8773 | D14: 6.8857 | E14: 7.4988 | F14: 7.3445 | G14: 6.2136 | H14: 6.9987 | I14: 7.4168 | K14: （Bus）
B15: （Car） | C15: 7.108 | D15: 6.6945 | E15: 7.6853 | F15: 7.7865 | G15: 6.6709 | H15: 7.8871 | I15: 7.7058 | K15: （Car）
B16: 合計 | C16: 6.8034 | D16: 6.7344 | E16: 7.6448 | F16: 7.688 | G16: 6.5669 | H16: 7.6794 | I16: 7.6424 | K16: 合計
A18: RB+BL | B18: 通過台数_L | C18: =30+24 -> 54 | D18: =30+24 -> 54 | E18: =30+24 -> 54 | F18: =30+24 -> 54 | G18: =29+24 -> 53 | H18: =30+24 -> 54 | I18: =30+24 -> 54 | J18: RB+BL | K18: 通過台数_L
A19: LB+BR | B19: 通過台数_R | C19: =28+35 -> 63 | D19: =28+37 -> 65 | E19: =28+37 -> 65 | F19: =28+36 -> 64 | G19: =26+35 -> 61 | H19: =28+36 -> 64 | I19: =27+36 -> 63 | J19: LB+BR | K19: 通過台数_R
A20: LR+RL | B20: 通過台数_B | C20: =35+33 -> 68 | D20: =35+33 -> 68 | E20: =35+33 -> 68 | F20: =35+33 -> 68 | G20: =35+33 -> 68 | H20: =35+33 -> 68 | I20: =35+33 -> 68 | J20: LR+RL | K20: 通過台数_B
B23: 500/500/500
C24: 1 | D24: 2 | E24: 3 | F24: 4 | G24: 5 | H24: 6 | I24: 7
C25: 全て受け入れ | D25: 道交法 | E25: 0.2 | F25: 0.4 | G25: 既存 | H25: 提案 | I25: 性能込み
B26: （Bus） | C26: 1.2928 | D26: 3.9262 | E26: 4.8087 | F26: 3.8032 | G26: 4.3133 | H26: 3.0283 | I26: 3.9649
B27: （Car） | C27: 1.7148 | D27: 3.4012 | E27: 4.2286 | F27: 4.0292 | G27: 3.8388 | H27: 1.4215 | I27: 4.4572
B28: 右折 | C28: 1.5992 | D28: 3.4952 | E28: 4.3324 | F28: 3.982 | G28: 3.924 | H28: 1.6422 | I28: 4.3493
B29: （Bus） | C29: 2.4394 | D29: 2.576 | E29: 2.9198 | F29: 3.4315 | G29: 3.1748 | H29: 1.3515 | I29: 4.1488
B30: （Car） | C30: 2.7252 | D30: 2.6219 | E30: 2.8615 | F30: 3.7597 | G30: 3.3044 | H30: 1.8627 | I30: 4.2731
B31: 左折 | C31: 2.6299 | D31: 2.6074 | E31: 2.8794 | F31: 3.6509 | G31: 3.2632 | H31: 1.6911 | I31: 4.2339
B32: （Bus） | C32: 1.9148 | D32: 4.308 | E32: 4.3659 | F32: 5.1579 | G32: 3.7593 | H32: 1.6982 | I32: 4.707
B33: （Car） | C33: 1.7057 | D33: 4.3413 | E33: 4.4831 | F33: 5.0177 | G33: 3.9785 | H33: 1.8403 | I33: 4.6019
B34: 直進 | C34: 1.7542 | D34: 4.3323 | E34: 4.4508 | F34: 5.0548 | G34: 3.9169 | H34: 1.8011 | I34: 4.6297
B35: （Bus） | C35: 3.0529 | D35: 4.9169 | E35: 5.3522 | F35: 5.6558 | G35: 5.2076 | H35: 2.8317 | I35: 5.9468
B36: （Car） | C36: 3.2809 | D36: 5.0873 | E36: 5.5153 | F36: 6.0505 | G36: 5.5238 | H36: 2.8116 | I36: 6.3725
B37: 合計 | C37: 3.2166 | D37: 5.0416 | E37: 5.4716 | F37: 5.9416 | G37: 5.4382 | H37: 2.8168 | I37: 6.2557
A39: RB+BL | B39: 通過台数_L | C39: =45+33 -> 78 | D39: =44+34 -> 78 | E39: =45+35 -> 80 | F39: =44+36 -> 80 | G39: =44+38 -> 82 | H39: =43+19 -> 62 | I39: =45+36 -> 81
A40: LB+BR | B40: 通過台数_R | C40: =27+34 -> 61 | D40: =36+34 -> 70 | E40: =37+36 -> 73 | F40: =37+36 -> 73 | G40: =36+36 -> 72 | H40: =21+24 -> 45 | I40: =36+36 -> 72
A41: LR+RL | B41: 通過台数_B | C41: =30+34 -> 64 | D41: =42+34 -> 76 | E41: =42+34 -> 76 | F41: =42+34 -> 76 | G41: =42+34 -> 76 | H41: =25+34 -> 59 | I41: =41+34 -> 75

Sheet seed3
B2: 400/400/400 | K2: 600/600/600
C3: 1 | D3: 2 | E3: 3 | F3: 4 | G3: 5 | H3: 6 | I3: 7 | L3: 1 | M3: 2 | N3: 3 | O3: 4 | P3: 5 | Q3: 6 | R3: 7
C4: 全て受け入れ | D4: 道交法 | E4: 0.2 | F4: 0.4 | G4: 既存 | H4: 提案 | I4: 性能込み | L4: 全て受け入れ | M4: 道交法 | N4: 0.2 | O4: 0.4 | P4: 既存 | Q4: 提案 | R4: 性能込み
B5: （Bus） | C5: 4.9918 | D5: 3.6146 | E5: 4.9588 | F5: 5.3693 | G5: 5.4777 | H5: 5.222 | I5: 5.3651 | K5: （Bus）
B6: （Car） | C6: 4.4143 | D6: 3.4863 | E6: 4.9325 | F6: 4.7822 | G6: 5.1429 | H6: 5.647 | I6: 5.6947 | K6: （Car）
B7: 右折 | C7: 4.5964 | D7: 3.5291 | E7: 4.9415 | F7: 4.968 | G7: 5.2533 | H7: 5.4939 | I7: 5.5774 | K7: 右折
B8: （Bus） | C8: 4.9065 | D8: 3.089 | E8: 4.5989 | F8: 4.7528 | G8: 4.7717 | H8: 5.0815 | I8: 5.0709 | K8: （Bus）
B9: （Car） | C9: 5.0109 | D9: 3.1261 | E9: 4.6745 | F9: 4.6156 | G9: 5.1899 | H9: 4.8277 | I9: 4.8917 | K9: （Car）
B10: 左折 | C10: 4.9857 | D10: 3.1172 | E10: 4.6565 | F10: 4.6472 | G10: 5.084 | H10: 4.8854 | I10: 4.9328 | K10: 左折
B11: （Bus） | C11: 4.2836 | D11: 7.6623 | E11: 8.0121 | F11: 6.2181 | G11: 5.3496 | H11: 6.9737 | I11: 6.9331 | K11: （Bus）
B12: （Car） | C12: 4.5424 | D12: 7.0995 | E12: 7.3608 | F12: 6.8198 | G12: 6.1061 | H12: 6.4874 | I12: 6.4513 | K12: （Car）
B13: 直進 | C13: 4.4455 | D13: 7.2926 | E13: 7.5833 | F13: 6.5898 | G13: 5.8085 | H13: 6.6551 | I13: 6.617 | K13: 直進
B14: （Bus） | C14: 6.3089 | D14: 6.1647 | E14: 7.4385 | F14: 7.1416 | G14: 6.8885 | H14: 7.4011 | I14: 7.4395 | K14: （Bus）
B15: （Car） | C15: 6.5829 | D15: 5.9737 | E15: 7.4531 | F15: 7.2682 | G15: 7.3953 | H15: 7.4845 | I15: 7.5336 | K15: （Car）
B16: 合計 | C16: 6.4944 | D16: 6.0322 | E16: 7.4485 | F16: 7.2281 | G16: 7.2282 | H16: 7.4582 | I16: 7.5039 | K16: 合計
A18: RB+BL | B18: 通過台数_L | C18: =26+34 -> 60 | D18: =27+33 -> 60 | E18: =27+33 -> 60 | F18: =27+34 -> 61 | G18: =26+33 -> 59 | H18: =27+33 -> 60 | I18: =27+34 -> 61 | J18: RB+BL | K18: 通過台数_L
A19: LB+BR | B19: 通過台数_R | C19: =27+29 -> 56 | D19: =27+29 -> 56 | E19: =27+29 -> 56 | F19: =27+29 -> 56 | G19: =27+29 -> 56 | H19: =27+29 -> 56 | I19: =27+29 -> 56 | J19: LB+BR | K19: 通過台数_R
A20: LR+RL | B20: 通過台数_B | C20: =35+37 -> 72 | D20: =35+38 -> 73 | E20: =36+37 -> 73 | F20: =35+37 -> 72 | G20: =36+37 -> 73 | H20: =35+37 -> 72 | I20: =35+38 -> 73 | J20: LR+RL | K20: 通過台数_B
B23: 500/500/500
C24: 1 | D24: 2 | E24: 3 | F24: 4 | G24: 5 | H24: 6 | I24: 7
C25: 全て受け入れ | D25: 道交法 | E25: 0.2 | F25: 0.4 | G25: 既存 | H25: 提案 | I25: 性能込み
B26: （Bus） | C26: 2.9497 | D26: 2.3772 | E26: 2.7177 | F26: 4.2638 | G26: 3.8919 | H26: 4.8212 | I26: 4.839
B27: （Car） | C27: 2.7595 | D27: 2.5937 | E27: 2.9536 | F27: 4.307 | G27: 3.9775 | H27: 4.5736 | I27: 4.6589
B28: 右折 | C28: 2.8072 | D28: 2.5349 | E28: 2.8886 | F28: 4.2956 | G28: 2.9545 | H28: 4.6363 | I28: 4.7054
B29: （Bus） | C29: 4.8621 | D29: 3.4183 | E29: 4.1161 | F29: 4.46 | G29: 4.0382 | H29: 4.7541 | I29: 4.7544
B30: （Car） | C30: 4.0102 | D30: 2.3874 | E30: 2.5982 | F30: 3.7145 | G30: 3.7967 | H30: 4.3712 | I30: 4.6633
B31: 左折 | C31: 4.1807 | D31: 2.5752 | E31: 2.8423 | F31: 3.8624 | G31: 3.8505 | H31: 4.4529 | I31: 4.6839
B32: （Bus） | C32: 3.0542 | D32: 6.0946 | E32: 5.5982 | F32: 4.7896 | G32: 4.7738 | H32: 5.1102 | I32: 5.5173
B33: （Car） | C33: 2.8739 | D33: 6.2881 | E33: 5.708 | F33: 5.9511 | G33: 4.7114 | H33: 5.4257 | I33: 5.4798
B34: 直進 | C34: 2.9285 | D34: 6.2269 | E34: 5.6735 | F34: 5.538 | G34: 4.7306 | H34: 5.3238 | I34: 5.4915
B35: （Bus） | C35: 4.9239 | D35: 5.1657 | E35: 5.5028 | F35: 6.2127 | G35: 5.8234 | H35: 6.5901 | I35: 6.7053
B36: （Car） | C36: 4.7438 | D36: 4.8418 | E36: 5.0892 | F36: 6.4266 | G36: 5.9436 | H36: 6.6315 | I36: 6.7344
B37: 合計 | C37: 4.7915 | D37: 4.9244 | E37: 5.1933 | F37: 6.3675 | G37: 5.9107 | H37: 6.6203 | I37: 6.7265
A39: RB+BL | B39: 通過台数_L | C39: =37+31 -> 68 | D39: =38+27 -> 65 | E39: =35+30 -> 65 | F39: =34+31 -> 65 | G39: =37+31 -> 68 | H39: =37+33 -> 70 | I39: =37+33 -> 70
A40: LB+BR | B40: 通過台数_R | C40: =35+39 -> 74 | D40: =40+37 -> 77 | E40: =40+39 -> 79 | F40: =40+43 -> 83 | G40: =39+43 -> 82 | H40: =40+45 -> 85 | I40: =38+46 -> 84
A41: LR+RL | B41: 通過台数_B | C41: =33+44 -> 77 | D41: =39+44 -> 83 | E41: =37+43 -> 80 | F41: =40+43 -> 83 | G41: =36+43 -> 79 | H41: =38+44 -> 82 | I41: =36+44 -> 80

Sheet seed4
B2: 400/400/400 | K2: 600/600/600
C3: 1 | D3: 2 | E3: 3 | F3: 4 | G3: 5 | H3: 6 | I3: 7 | L3: 1 | M3: 2 | N3: 3 | O3: 4 | P3: 5 | Q3: 6 | R3: 7
C4: 全て受け入れ | D4: 道交法 | E4: 0.2 | F4: 0.4 | G4: 既存 | H4: 提案 | I4: 性能込み | L4: 全て受け入れ | M4: 道交法 | N4: 0.2 | O4: 0.4 | P4: 既存 | Q4: 提案 | R4: 性能込み
B5: （Bus） | C5: 4.6403 | D5: 4.3687 | E5: 4.9604 | F5: 4.8314 | G5: 4.6393 | H5: 5.7699 | I5: 5.3882 | K5: （Bus）
B6: （Car） | C6: 4.1962 | D6: 4.7663 | E6: 5.5189 | F6: 5.5257 | G6: 4.7274 | H6: 5.6841 | I6: 5.4522 | K6: （Car）
B7: 右折 | C7: 4.3358 | D7: 4.6253 | E7: 5.3164 | F7: 5.2708 | G7: 4.6973 | H7: 5.7127 | I7: 5.4304 | K7: 右折
B8: （Bus） | C8: 5.1216 | D8: 3.5836 | E8: 4.5341 | F8: 4.5785 | G8: 3.9039 | H8: 5.3991 | I8: 5.4877 | K8: （Bus）
B9: （Car） | C9: 4.9271 | D9: 3.6797 | E9: 4.4467 | F9: 4.5629 | G9: 4.4077 | H9: 5.0871 | I9: 5.0837 | K9: （Car）
B10: 左折 | C10: 4.9747 | D10: 3.6554 | E10: 4.4684 | F10: 4.5668 | G10: 4.2676 | H10: 5.1626 | I10: 5.1801 | K10: 左折
B11: （Bus） | C11: 5.7018 | D11: 5.8502 | E11: 7.0992 | F11: 6.8351 | G11: 6.1038 | H11: 7.2204 | I11: 7.0401 | K11: （Bus）
B12: （Car） | C12: 3.422 | D12: 7.3771 | E12: 7.3144 | F12: 7.1259 | G12: 5.3896 | H12: 6.3723 | I12: 6.8867 | K12: （Car）
B13: 直進 | C13: 3.8629 | D13: 6.8709 | E13: 7.2522 | F13: 7.041 | G13: 5.5745 | H13: 6.5916 | I13: 6.9295 | K13: 直進
B14: （Bus） | C14: 6.7683 | D14: 6.2166 | E14: 6.9876 | F14: 6.8823 | G14: 6.3281 | H14: 7.6015 | I14: 7.4208 | K14: （Bus）
B15: （Car） | C15: 5.9815 | D15: 6.8545 | E15: 7.4716 | F15: 7.5809 | G15: 6.679 | H15: 7.5488 | I15: 7.6268 | K15: （Car）
B16: 合計 | C16: 6.1912 | D16: 6.6593 | E16: 7.3258 | F16: 7.368 | G16: 6.5742 | H16: 7.5638 | I16: 7.5667 | K16: 合計
A18: RB+BL | B18: 通過台数_L | C18: =30+33 -> 63 | D18: =31+29 -> 60 | E18: =31+32 -> 63 | F18: =31+31 -> 62 | G18: =31+32 -> 63 | H18: =31+32 -> 63 | I18: =31+32 -> 63 | K18: 通過台数_L
A19: LB+BR | B19: 通過台数_R | C19: =26+30 -> 56 | D19: =26+29 -> 55 | E19: =26+30 -> 56 | F19: =26+29 -> 55 | G19: =26+30 -> 56 | H19: =26+30 -> 56 | I19: =26+30 -> 56 | K19: 通過台数_R
A20: LR+RL | B20: 通過台数_B | C20: =38+29 -> 67 | D20: =38+33 -> 71 | E20: =38+33 -> 71 | F20: =38+33 -> 71 | G20: =38+33 -> 71 | H20: =38+33 -> 71 | I20: =38+33 -> 71 | K20: 通過台数_B
B23: 500/500/500
C24: 1 | D24: 2 | E24: 3 | F24: 4 | G24: 5 | H24: 6 | I24: 7
C25: 全て受け入れ | D25: 道交法 | E25: 0.2 | F25: 0.4 | G25: 既存 | H25: 提案 | I25: 性能込み
B26: （Bus）
B27: （Car）
B28: 右折
B29: （Bus）
B30: （Car）
B31: 左折
B32: （Bus）
B33: （Car）
B34: 直進
B35: （Bus）
B36: （Car）
B37: 合計
... B41: 通過台数_B

Sheet seed5
B2: 400/400/400 | K2: 600/600/600
C3: 1 | D3: 2 | E3: 3 | F3: 4 | G3: 5 | H3: 6 | I3: 7 | L3: 1 | M3: 2 | N3: 3 | O3: 4 | P3: 5 | Q3: 6 | R3: 7
C4: 全て受け入れ | D4: 道交法 | E4: 0.2 | F4: 0.4 | G4: 既存 | H4: 提案 | I4: 性能込み | L4: 全て受け入れ | M4: 道交法 | N4: 0.2 | O4: 0.4 | P4: 既存 | Q4: 提案 | R4: 性能込み
B5: （Bus） | C5: 4.7337 | D5: 4.7123 | E5: 4.8815 | F5: 5.0642 | G5: 5.4565 | H5: 5.4496 | I5: 5.3191 | K5: （Bus）
B6: （Car） | C6: 4.5695 | D6: 4.4887 | E6: 4.3994 | F6: 4.8392 | G6: 4.768 | H6: 4.7568 | I6: 4.72 | K6: （Car）
B7: 右折 | C7: 4.5986 | D7: 4.5277 | E7: 4.4797 | F7: 4.8786 | G7: 4.8795 | H7: 4.8689 | I7: 4.8188 | K7: 右折
B8: （Bus） | C8: 4.979 | D8: 4.4536 | E8: 4.3339 | F8: 4.9049 | G8: 5.1632 | H8: 5.111 | I8: 5.1928 | K8: （Bus）
B9: （Car） | C9: 5.1233 | D9: 4.5253 | E9: 4.4441 | F9: 4.6229 | G9: 4.725 | H9: 4.8132 | I9: 4.6707 | K9: （Car）
B10: 左折 | C10: 5.0926 | D10: 4.5103 | E10: 4.4211 | F10: 4.6783 | G10: 4.8098 | H10: 4.872 | I10: 4.77 | K10: 左折
B11: （Bus） | C11: 4.4584 | D11: 6.846 | E11: 7.2227 | F11: 6.5715 | G11: 5.0888 | H11: 5.8503 | I11: 5.4611 | K11: （Bus）
B12: （Car） | C12: 5.0408 | D12: 7.7001 | E12: 7.6577 | F12: 7.128 | G12: 5.896 | H12: 5.9713 | I12: 5.96 | K12: （Car）
B13: 直進 | C13: 4.9471 | D13: 7.5568 | E13: 7.5883 | F13: 7.0388 | G13: 5.7597 | H13: 5.9528 | I13: 5.8791 | K13: 直進
B14: （Bus） | C14: 6.0305 | D14: 6.6495 | E14: 6.6508 | F14: 6.8624 | G14: 6.7142 | H14: 6.8348 | I14: 6.7679 | K14: （Bus）
B15: （Car） | C15: 6.8402 | D15: 7.2554 | E15: 7.1795 | F15: 7.3734 | G15: 7.0566 | H15: 7.153 | I15: 7.0928 | K15: （Car）
B16: 合計 | C16: 6.69 | D16: 7.1417 | E16: 7.0812 | F16: 7.2803 | G16: 6.9958 | H16: 7.0962 | I16: 7.035 | K16: 合計
A18: RB+BL | B18: 通過台数_L | C18: =31+33 -> 64 | D18: =31+31 -> 62 | E18: =30+32 -> 62 | F18: =30+32 -> 62 | G18: =31+33 -> 64 | H18: =31+32 -> 63 | I18: =31+33 -> 64 | K18: 通過台数_L
A19: LB+BR | B19: 通過台数_R | C19: =28+30 -> 58 | D19: =29+29 -> 58 | E19: =29+30 -> 59 | F19: =29+30 -> 59 | G19: =29+30 -> 59 | H19: =29+30 -> 59 | I19: =29+30 -> 59 | K19: 通過台数_R
A20: LR+RL | B20: 通過台数_B | C20: =31+32 -> 63 | D20: =34+31 -> 65 | E20: =34+31 -> 65 | F20: =33+31 -> 64 | G20: =33+32 -> 65 | H20: =34+32 -> 66 | I20: =33+31 -> 64 | K20: 通過台数_B
B23: 500/500/500
C24: 1 | D24: 2 | E24: 3 | F24: 4 | G24: 5 | H24: 6 | I24: 7
C25: 全て受け入れ | D25: 道交法 | E25: 0.2 | F25: 0.4 | G25: 既存 | H25: 提案 | I25: 性能込み
B26: （Bus） | C26: 2.5 | D26: 3.1402 | E26: 4.8553 | F26: 4.5771 | G26: 3.6088 | H26: 4.3838 | I26: 5.1865
B27: （Car） | C27: 2.4123 | D27: 2.9947 | E27: 4.4969 | F27: 3.8674 | G27: 3.3875 | H27: 4.2974 | I27: 4.7445
B28: 右折 | C28: 2.4392 | D28: 3.04 | E28: 4.6025 | F28: 4.0652 | G28: 3.4533 | H28: 4.3239 | I28: 4.8732
B29: （Bus） | C29: 4.5526 | D29: 2.4834 | E29: 3.1403 | F29: 3.9364 | G29: 3.4853 | H29: 4.3861 | I29: 4.6298
B30: （Car） | C30: 3.971 | D30: 2.3495 | E30: 2.9743 | F30: 3.2764 | G30: 3.2923 | H30: 4.4421 | I30: 4.6477
B31: 左折 | C31: 4.1783 | D31: 2.3999 | E31: 3.0365 | F31: 3.5044 | G31: 3.3642 | H31: 4.4203 | I31: 4.6408
B32: （Bus） | C32: 3.0977 | D32: 4.3403 | E32: 3.3789 | F32: 4.7062 | G32: 3.5841 | H32: 4.8659 | I32: 5.1009
B33: （Car） | C33: 2.4339 | D33: 4.0424 | E33: 3.7928 | F33: 4.0539 | G33: 3.7469 | H33: 4.9062 | I33: 5.2194
B34: 直進 | C34: 2.5124 | D34: 4.0815 | E34: 3.7337 | F34: 4.1338 | G34: 3.7231 | H34: 4.9006 | I34: 5.2026
B35: （Bus） | C35: 4.7892 | D35: 4.5084 | E35: 5.3469 | F35: 5.9884 | G35: 5.1718 | H35: 6.109 | I35: 6.5718
B36: （Car） | C36: 4.3858 | D36: 4.8123 | E36: 5.6039 | F36: 5.622 | G36: 5.2298 | H36: 6.486 | I36: 6.8327
B37: 合計 | C37: 4.495 | D37: 4.7211 | E37: 5.5309 | F37: 5.7222 | G37: 5.2132 | H37: 6.3748 | I37: 6.7571
A39: RB+BL | B39: 通過台数_L | C39: =39+35 -> 74 | D39: =39+28 -> 67 | E39: =37+32 -> 69 | F39: =39+31 -> 70 | G39: =39+32 -> 71 | H39: =39+34 -> 73 | I39: =39+33 -> 72
A40: LB+BR | B40: 通過台数_R | C40: =39+45 -> 84 | D40: =48+37 -> 85 | E40: =48+45 -> 93 | F40: =48+40 -> 88 | G40: =47+44 -> 91 | H40: =48+45 -> 93 | I40: =48+45 -> 93
A41: LR+RL | B41: 通過台数_B | C41: =24+41 -> 65 | D41: =32+41 -> 73 | E41: =33+35 -> 68 | F41: =32+41 -> 73 | G41: =28+41 -> 69 | H41: =31+41 -> 72 | I41: =31+41 -> 72

Sheet seed6
B2: 400/400/400 | K2: 600/600/600
C3: 1 | D3: 2 | E3: 3 | F3: 4 | G3: 5 | H3: 6 | I3: 7 | L3: 1 | M3: 2 | N3: 3 | O3: 4 | P3: 5 | Q3: 6 | R3: 7
C4: 全て受け入れ | D4: 道交法 | E4: 0.2 | F4: 0.4 | G4: 既存 | H4: 提案 | I4: 性能込み | L4: 全て受け入れ | M4: 道交法 | N4: 0.2 | O4: 0.4 | P4: 既存 | Q4: 提案 | R4: 性能込み
B5: （Bus） | K5: （Bus）
B6: （Car） | K6: （Car）
B7: 右折 | K7: 右折
B8: （Bus） | K8: （Bus）
B9: （Car） | K9: （Car）
B10: 左折 | K10: 左折
B11: （Bus） | K11: （Bus）
B12: （Car） | K12: （Car）
B13: 直進 | K13: 直進
B14: （Bus） | K14: （Bus）
B15: （Car） | K15: （Car）
B16: 合計 | K16: 合計
A18: RB+BL | B18: 通過台数_L | K18: 通過台数_L
A19: LB+BR | B19: 通過台数_R | K19: 通過台数_R
A20: LR+RL | B20: 通過台数_B | K20: 通過台数_B
B23: 500/500/500
C24: 1 | D24: 2 | E24: 3 | F24: 4 | G24: 5 | H24: 6 | I24: 7
C25: 全て受け入れ | D25: 道交法 | E25: 0.2 | F25: 0.4 | G25: 既存 | H25: 提案 | I25: 性能込み
B26: （Bus） | C26: 2.3383 | D26: 4.1496 | E26: 4.7719 | F26: 3.9832 | G26: 3.4271 | H26: 3.6939 | I26: 3.8628
B27: （Car） | C27: 3.0743 | D27: 3.1376 | E27: 4.7209 | F27: 3.6165 | G27: 3.6385 | H27: 3.7302 | I27: 4.2358
B28: 右折 | C28: 2.8681 | D28: 3.3215 | E28: 4.7328 | F28: 3.6942 | G28: 3.587 | H28: 3.7215 | I28: 4.1426
B29: （Bus） | C29: 4.0053 | D29: 2.522 | E29: 3.3432 | F29: 3.5804 | G29: 3.4065 | H29: 3.7984 | I29: 4.303
B30: （Car） | C30: 3.578 | D30: 2.344 | E30: 3.4944 | F30: 3.3163 | G30: 3.7043 | H30: 3.6697 | I30: 3.76
B31: 左折 | C31: 3.683 | D31: 2.3907 | E31: 3.4527 | F31: 3.3845 | G31: 3.6206 | H31: 3.7026 | I31: 3.8903
B32: （Bus） | C32: 2.2445 | D32: 4.2173 | E32: 4.4397 | F32: 4.7129 | G32: 4.0034 | H32: 4.0864 | I32: 4.793
B33: （Car） | C33: 2.4393 | D33: 4.7048 | E33: 5.5941 | F33: 5.3749 | G33: 3.864 | H33: 4.1773 | I33: 4.6315
B34: 直進 | C34: 2.3843 | D34: 4.5682 | E34: 5.2433 | F34: 5.1858 | G34: 3.8993 | H34: 4.1533 | I34: 4.6722
B35: （Bus） | C35: 4.2087 | D35: 4.9685 | E35: 5.7448 | F35: 5.7359 | G35: 5.1641 | H35: 5.458 | I35: 5.9744
B36: （Car） | C36: 4.6353 | D36: 4.8509 | E36: 6.3363 | F36: 5.8057 | G36: 5.4758 | H36: 5.6149 | I36: 6.0125
B37: 合計 | C37: 4.5187 | D37: 4.8802 | E37: 6.1746 | F37: 5.7877 | G37: 5.3936 | H37: 5.5743 | I37: 6.0029
A39: RB+BL | B39: 通過台数_L | C39: =42+33 -> 75 | D39: =40+30 -> 70 | E39: =42+34 -> 76 | F39: =41+31 -> 72 | G39: =42+34 -> 76 | H39: =41+36 -> 77 | I39: =42+34 -> 76
A40: LB+BR | B40: 通過台数_R | C40: =34+38 -> 72 | D40: =42+34 -> 76 | E40: =41+38 -> 79 | F40: =41+35 -> 76 | G40: =39+39 -> 78 | H40: =40+40 -> 80 | I40: =39+39 -> 78
A41: LR+RL | B41: 通過台数_B | C41: =29+38 -> 67 | D41: =38+33 -> 71 | E41: =38+38 -> 76 | F41: =38+36 -> 74 | G41: =34+37 -> 71 | H41: =37+36 -> 73 | I41: =36+36 -> 72

Sheet 平均
B2: 400/400/400 | K2: 600/600/600
C3: 1 | D3: 2 | E3: 3 | F3: 4 | G3: 5 | H3: 6 | I3: 7 | L3: 1 | M3: 2 | N3: 3 | O3: 4 | P3: 5 | Q3: 6 | R3: 7
C4: 全て受け入れ | D4: 道交法 | E4: 0.2 | F4: 0.4 | G4: 既存 | H4: 提案 | I4: 性能込み | L4: 全て受け入れ | M4: 道交法 | N4: 0.2 | O4: 0.4 | P4: 既存 | Q4: 提案 | R4: 性能込み
B5: （Bus） | C5: =ROUND(AVERAGE(seed1!C5,seed2!C5,seed3!C5,seed4!C5,seed5!C5),4) -> 4.6967 | D5: =ROUND(AVERAGE(seed1!D5,seed2!D5,seed3!D5,seed4!D5,seed5!D5),4) -> 4.5202 | E5: =ROUND(AVERAGE(seed1!E5,seed2!E5,seed3!E5,seed4!E5,seed5!E5),4) -> 5.1535 | F5: =ROUND(AVERAGE(seed1!F5,seed2!F5,seed3!F5,seed4!F5,seed5!F5),4) -> 5.2447 | G5: =ROUND(AVERAGE(seed1!G5,seed2!G5,seed3!G5,seed4!G5,seed5!G5),4) -> 5.0361 | H5: =ROUND(AVERAGE(seed1!H5,seed2!H5,seed3!H5,seed4!H5,seed5!H5),4) -> 5.4342 | I5: =ROUND(AVERAGE(seed1!I5,seed2!I5,seed3!I5,seed4!I5,seed5!I5),4) -> 5.4004 | K5: （Bus） | L5: =ROUND(AVERAGE(seed1!L5,seed2!L5,seed3!L5,seed4!L5,seed5!L5),4) -> #DIV/0! | M5: =ROUND(AVERAGE(seed1!M5,seed2!M5,seed3!M5,seed4!M5,seed5!M5),4) -> #DIV/0! | N5: =ROUND(AVERAGE(seed1!N5,seed2!N5,seed3!N5,seed4!N5,seed5!N5),4) -> #DIV/0! | O5: =ROUND(AVERAGE(seed1!O5,seed2!O5,seed3!O5,seed4!O5,seed5!O5),4) -> #DIV/0! | P5: =ROUND(AVERAGE(seed1!P5,seed2!P5,seed3!P5,seed4!P5,seed5!P5),4) -> #DIV/0! | Q5: =ROUND(AVERAGE(seed1!Q5,seed2!Q5,seed3!Q5,seed4!Q5,seed5!Q5),4) -> #DIV/0! | R5: =ROUND(AVERAGE(seed1!R5,seed2!R5,seed3!R5,seed4!R5,seed5!R5),4) -> #DIV/0!
B6: （Car） | C6: =ROUND(AVERAGE(seed1!C6,seed2!C6,seed3!C6,seed4!C6,seed5!C6),4) -> 4.6027 | D6: =ROUND(AVERAGE(seed1!D6,seed2!D6,seed3!D6,seed4!D6,seed5!D6),4) -> 4.207 | E6: =ROUND(AVERAGE(seed1!E6,seed2!E6,seed3!E6,seed4!E6,seed5!E6),4) -> 5.1039 | F6: =ROUND(AVERAGE(seed1!F6,seed2!F6,seed3!F6,seed4!F6,seed5!F6),4) -> 5.1617 | G6: =ROUND(AVERAGE(seed1!G6,seed2!G6,seed3!G6,seed4!G6,seed5!G6),4) -> 4.7641 | H6: =ROUND(AVERAGE(seed1!H6,seed2!H6,seed3!H6,seed4!H6,seed5!H6),4) -> 5.2205 | I6: =ROUND(AVERAGE(seed1!I6,seed2!I6,seed3!I6,seed4!I6,seed5!I6),4) -> 5.211 | K6: （Car） | L6: =ROUND(AVERAGE(seed1!L6,seed2!L6,seed3!L6,seed4!L6,seed5!L6),4) -> #DIV/0! | M6: =ROUND(AVERAGE(seed1!M6,seed2!M6,seed3!M6,seed4!M6,seed5!M6),4) -> #DIV/0! | N6: =ROUND(AVERAGE(seed1!N6,seed2!N6,seed3!N6,seed4!N6,seed5!N6),4) -> #DIV/0! | O6: =ROUND(AVERAGE(seed1!O6,seed2!O6,seed3!O6,seed4!O6,seed5!O6),4) -> #DIV/0! | P6: =ROUND(AVERAGE(seed1!P6,seed2!P6,seed3!P6,seed4!P6,seed5!P6),4) -> #DIV/0! | Q6: =ROUND(AVERAGE(seed1!Q6,seed2!Q6,seed3!Q6,seed4!Q6,seed5!Q6),4) -> #DIV/0! | R6: =ROUND(AVERAGE(seed1!R6,seed2!R6,seed3!R6,seed4!R6,seed5!R6),4) -> #DIV/0!
B7: 右折 | C7: =ROUND(AVERAGE(seed1!C7,seed2!C7,seed3!C7,seed4!C7,seed5!C7),4) -> 4.6347 | D7: =ROUND(AVERAGE(seed1!D7,seed2!D7,seed3!D7,seed4!D7,seed5!D7),4) -> 4.2495 | E7: =ROUND(AVERAGE(seed1!E7,seed2!E7,seed3!E7,seed4!E7,seed5!E7),4) -> 5.093 | F7: =ROUND(AVERAGE(seed1!F7,seed2!F7,seed3!F7,seed4!F7,seed5!F7),4) -> 5.1634 | G7: =ROUND(AVERAGE(seed1!G7,seed2!G7,seed3!G7,seed4!G7,seed5!G7),4) -> 4.8177 | H7: =ROUND(AVERAGE(seed1!H7,seed2!H7,seed3!H7,seed4!H7,seed5!H7),4) -> 5.2417 | I7: =ROUND(AVERAGE(seed1!I7,seed2!I7,seed3!I7,seed4!I7,seed5!I7),4) -> 5.23 | K7: 右折 | L7: =ROUND(AVERAGE(seed1!L7,seed2!L7,seed3!L7,seed4!L7,seed5!L7),4) -> #DIV/0! | M7: =ROUND(AVERAGE(seed1!M7,seed2!M7,seed3!M7,seed4!M7,seed5!M7),4) -> #DIV/0! | N7: =ROUND(AVERAGE(seed1!N7,seed2!N7,seed3!N7,seed4!N7,seed5!N7),4) -> #DIV/0! | O7: =ROUND(AVERAGE(seed1!O7,seed2!O7,seed3!O7,seed4!O7,seed5!O7),4) -> #DIV/0! | P7: =ROUND(AVERAGE(seed1!P7,seed2!P7,seed3!P7,seed4!P7,seed5!P7),4) -> #DIV/0! | Q7: =ROUND(AVERAGE(seed1!Q7,seed2!Q7,seed3!Q7,seed4!Q7,seed5!Q7),4) -> #DIV/0! | R7: =ROUND(AVERAGE(seed1!R7,seed2!R7,seed3!R7,seed4!R7,seed5!R7),4) -> #DIV/0!
B8: （Bus） | C8: =ROUND(AVERAGE(seed1!C8,seed2!C8,seed3!C8,seed4!C8,seed5!C8),4) -> 5.0873 | D8: =ROUND(AVERAGE(seed1!D8,seed2!D8,seed3!D8,seed4!D8,seed5!D8),4) -> 3.7901 | E8: =ROUND(AVERAGE(seed1!E8,seed2!E8,seed3!E8,seed4!E8,seed5!E8),4) -> 4.6514 | F8: =ROUND(AVERAGE(seed1!F8,seed2!F8,seed3!F8,seed4!F8,seed5!F8),4) -> 4.7144 | G8: =ROUND(AVERAGE(seed1!G8,seed2!G8,seed3!G8,seed4!G8,seed5!G8),4) -> 4.5126 | H8: =ROUND(AVERAGE(seed1!H8,seed2!H8,seed3!H8,seed4!H8,seed5!H8),4) -> 5.0973 | I8: =ROUND(AVERAGE(seed1!I8,seed2!I8,seed3!I8,seed4!I8,seed5!I8),4) -> 5.1433 | K8: （Bus） | L8: =ROUND(AVERAGE(seed1!L8,seed2!L8,seed3!L8,seed4!L8,seed5!L8),4) -> #DIV/0! | M8: =ROUND(AVERAGE(seed1!M8,seed2!M8,seed3!M8,seed4!M8,seed5!M8),4) -> #DIV/0! | N8: =ROUND(AVERAGE(seed1!N8,seed2!N8,seed3!N8,seed4!N8,seed5!N8),4) -> #DIV/0! | O8: =ROUND(AVERAGE(seed1!O8,seed2!O8,seed3!O8,seed4!O8,seed5!O8),4) -> #DIV/0! | P8: =ROUND(AVERAGE(seed1!P8,seed2!P8,seed3!P8,seed4!P8,seed5!P8),4) -> #DIV/0! | Q8: =ROUND(AVERAGE(seed1!Q8,seed2!Q8,seed3!Q8,seed4!Q8,seed5!Q8),4) -> #DIV/0! | R8: =ROUND(AVERAGE(seed1!R8,seed2!R8,seed3!R8,seed4!R8,seed5!R8),4) -> #DIV/0!
B9: （Car） | C9: =ROUND(AVERAGE(seed1!C9,seed2!C9,seed3!C9,seed4!C9,seed5!C9),4) -> 5.0948 | D9: =ROUND(AVERAGE(seed1!D9,seed2!D9,seed3!D9,seed4!D9,seed5!D9),4) -> 3.7883 | E9: =ROUND(AVERAGE(seed1!E9,seed2!E9,seed3!E9,seed4!E9,seed5!E9),4) -> 4.5508 | F9: =ROUND(AVERAGE(seed1!F9,seed2!F9,seed3!F9,seed4!F9,seed5!F9),4) -> 4.5806 | G9: =ROUND(AVERAGE(seed1!G9,seed2!G9,seed3!G9,seed4!G9,seed5!G9),4) -> 4.604 | H9: =ROUND(AVERAGE(seed1!H9,seed2!H9,seed3!H9,seed4!H9,seed5!H9),4) -> 4.8601 | I9: =ROUND(AVERAGE(seed1!I9,seed2!I9,seed3!I9,seed4!I9,seed5!I9),4) -> 4.8803 | K9: （Car） | L9: =ROUND(AVERAGE(seed1!L9,seed2!L9,seed3!L9,seed4!L9,seed5!L9),4) -> #DIV/0! | M9: =ROUND(AVERAGE(seed1!M9,seed2!M9,seed3!M9,seed4!M9,seed5!M9),4) -> #DIV/0! | N9: =ROUND(AVERAGE(seed1!N9,seed2!N9,seed3!N9,seed4!N9,seed5!N9),4) -> #DIV/0! | O9: =ROUND(AVERAGE(seed1!O9,seed2!O9,seed3!O9,seed4!O9,seed5!O9),4) -> #DIV/0! | P9: =ROUND(AVERAGE(seed1!P9,seed2!P9,seed3!P9,seed4!P9,seed5!P9),4) -> #DIV/0! | Q9: =ROUND(AVERAGE(seed1!Q9,seed2!Q9,seed3!Q9,seed4!Q9,seed5!Q9),4) -> #DIV/0! | R9: =ROUND(AVERAGE(seed1!R9,seed2!R9,seed3!R9,seed4!R9,seed5!R9),4) -> #DIV/0!
B10: 左折 | C10: =ROUND(AVERAGE(seed1!C10,seed2!C10,seed3!C10,seed4!C10,seed5!C10),4) -> 5.0933 | D10: =ROUND(AVERAGE(seed1!D10,seed2!D10,seed3!D10,seed4!D10,seed5!D10),4) -> 3.7857 | E10: =ROUND(AVERAGE(seed1!E10,seed2!E10,seed3!E10,seed4!E10,seed5!E10),4) -> 4.5749 | F10: =ROUND(AVERAGE(seed1!F10,seed2!F10,seed3!F10,seed4!F10,seed5!F10),4) -> 4.6101 | G10: =ROUND(AVERAGE(seed1!G10,seed2!G10,seed3!G10,seed4!G10,seed5!G10),4) -> 4.5687 | H10: =ROUND(AVERAGE(seed1!H10,seed2!H10,seed3!H10,seed4!H10,seed5!H10),4) -> 4.9148 | I10: =ROUND(AVERAGE(seed1!I10,seed2!I10,seed3!I10,seed4!I10,seed5!I10),4) -> 4.9376 | K10: 左折 | L10: =ROUND(AVERAGE(seed1!L10,seed2!L10,seed3!L10,seed4!L10,seed5!L10),4) -> #DIV/0! | M10: =ROUND(AVERAGE(seed1!M10,seed2!M10,seed3!M10,seed4!M10,seed5!M10),4) -> #DIV/0! | N10: =ROUND(AVERAGE(seed1!N10,seed2!N10,seed3!N10,seed4!N10,seed5!N10),4) -> #DIV/0! | O10: =ROUND(AVERAGE(seed1!O10,seed2!O10,seed3!O10,seed4!O10,seed5!O10),4) -> #DIV/0! | P10: =ROUND(AVERAGE(seed1!P10,seed2!P10,seed3!P10,seed4!P10,seed5!P10),4) -> #DIV/0! | Q10: =ROUND(AVERAGE(seed1!Q10,seed2!Q10,seed3!Q10,seed4!Q10,seed5!Q10),4) -> #DIV/0! | R10: =ROUND(AVERAGE(seed1!R10,seed2!R10,seed3!R10,seed4!R10,seed5!R10),4) -> #DIV/0!
B11: （Bus） | C11: =ROUND(AVERAGE(seed1!C11,seed2!C11,seed3!C11,seed4!C11,seed5!C11),4) -> 4.3051 | D11: =ROUND(AVERAGE(seed1!D11,seed2!D11,seed3!D11,seed4!D11,seed5!D11),4) -> 7.1008 | E11: =ROUND(AVERAGE(seed1!E11,seed2!E11,seed3!E11,seed4!E11,seed5!E11),4) -> 7.6742 | F11: =ROUND(AVERAGE(seed1!F11,seed2!F11,seed3!F11,seed4!F11,seed5!F11),4) -> 7.0925 | G11: =ROUND(AVERAGE(seed1!G11,seed2!G11,seed3!G11,seed4!G11,seed5!G11),4) -> 5.4409 | H11: =ROUND(AVERAGE(seed1!H11,seed2!H11,seed3!H11,seed4!H11,seed5!H11),4) -> 6.1622 | I11: =ROUND(AVERAGE(seed1!I11,seed2!I11,seed3!I11,seed4!I11,seed5!I11),4) -> 6.5355 | K11: （Bus） | L11: =ROUND(AVERAGE(seed1!L11,seed2!L11,seed3!L11,seed4!L11,seed5!L11),4) -> #DIV/0! | M11: =ROUND(AVERAGE(seed1!M11,seed2!M11,seed3!M11,seed4!M11,seed5!M11),4) -> #DIV/0! | N11: =ROUND(AVERAGE(seed1!N11,seed2!N11,seed3!N11,seed4!N11,seed5!N11),4) -> #DIV/0! | O11: =ROUND(AVERAGE(seed1!O11,seed2!O11,seed3!O11,seed4!O11,seed5!O11),4) -> #DIV/0! | P11: =ROUND(AVERAGE(seed1!P11,seed2!P11,seed3!P11,seed4!P11,seed5!P11),4) -> #DIV/0! | Q11: =ROUND(AVERAGE(seed1!Q11,seed2!Q11,seed3!Q11,seed4!Q11,seed5!Q11),4) -> #DIV/0! | R11: =ROUND(AVERAGE(seed1!R11,seed2!R11,seed3!R11,seed4!R11,seed5!R11),4) -> #DIV/0!
B12: （Car） | C12: =ROUND(AVERAGE(seed1!C12,seed2!C12,seed3!C12,seed4!C12,seed5!C12),4) -> 4.6838 | D12: =ROUND(AVERAGE(seed1!D12,seed2!D12,seed3!D12,seed4!D12,seed5!D12),4) -> 7.5 | E12: =ROUND(AVERAGE(seed1!E12,seed2!E12,seed3!E12,seed4!E12,seed5!E12),4) -> 7.575 | F12: =ROUND(AVERAGE(seed1!F12,seed2!F12,seed3!F12,seed4!F12,seed5!F12),4) -> 7.1716 | G12: =ROUND(AVERAGE(seed1!G12,seed2!G12,seed3!G12,seed4!G12,seed5!G12),4) -> 5.6931 | H12: =ROUND(AVERAGE(seed1!H12,seed2!H12,seed3!H12,seed4!H12,seed5!H12),4) -> 6.5897 | I12: =ROUND(AVERAGE(seed1!I12,seed2!I12,seed3!I12,seed4!I12,seed5!I12),4) -> 6.7688 | K12: （Car） | L12: =ROUND(AVERAGE(seed1!L12,seed2!L12,seed3!L12,seed4!L12,seed5!L12),4) -> #DIV/0! | M12: =ROUND(AVERAGE(seed1!M12,seed2!M12,seed3!M12,seed4!M12,seed5!M12),4) -> #DIV/0! | N12: =ROUND(AVERAGE(seed1!N12,seed2!N12,seed3!N12,seed4!N12,seed5!N12),4) -> #DIV/0! | O12: =ROUND(AVERAGE(seed1!O12,seed2!O12,seed3!O12,seed4!O12,seed5!O12),4) -> #DIV/0! | P12: =ROUND(AVERAGE(seed1!P12,seed2!P12,seed3!P12,seed4!P12,seed5!P12),4) -> #DIV/0! | Q12: =ROUND(AVERAGE(seed1!Q12,seed2!Q12,seed3!Q12,seed4!Q12,seed5!Q12),4) -> #DIV/0! | R12: =ROUND(AVERAGE(seed1!R12,seed2!R12,seed3!R12,seed4!R12,seed5!R12),4) -> #DIV/0!
B13: 直進 | C13: =ROUND(AVERAGE(seed1!C13,seed2!C13,seed3!C13,seed4!C13,seed5!C13),4) -> 4.5906 | D13: =ROUND(AVERAGE(seed1!D13,seed2!D13,seed3!D13,seed4!D13,seed5!D13),4) -> 7.4195 | E13: =ROUND(AVERAGE(seed1!E13,seed2!E13,seed3!E13,seed4!E13,seed5!E13),4) -> 7.6068 | F13: =ROUND(AVERAGE(seed1!F13,seed2!F13,seed3!F13,seed4!F13,seed5!F13),4) -> 7.1158 | G13: =ROUND(AVERAGE(seed1!G13,seed2!G13,seed3!G13,seed4!G13,seed5!G13),4) -> 5.6077 | H13: =ROUND(AVERAGE(seed1!H13,seed2!H13,seed3!H13,seed4!H13,seed5!H13),4) -> 6.5391 | I13: =ROUND(AVERAGE(seed1!I13,seed2!I13,seed3!I13,seed4!I13,seed5!I13),4) -> 6.7617 | K13: 直進 | L13: =ROUND(AVERAGE(seed1!L13,seed2!L13,seed3!L13,seed4!L13,seed5!L13),4) -> #DIV/0! | M13: =ROUND(AVERAGE(seed1!M13,seed2!M13,seed3!M13,seed4!M13,seed5!M13),4) -> #DIV/0! | N13: =ROUND(AVERAGE(seed1!N13,seed2!N13,seed3!N13,seed4!N13,seed5!N13),4) -> #DIV/0! | O13: =ROUND(AVERAGE(seed1!O13,seed2!O13,seed3!O13,seed4!O13,seed5!O13),4) -> #DIV/0! | P13: =ROUND(AVERAGE(seed1!P13,seed2!P13,seed3!P13,seed4!P13,seed5!P13),4) -> #DIV/0! | Q13: =ROUND(AVERAGE(seed1!Q13,seed2!Q13,seed3!Q13,seed4!Q13,seed5!Q13),4) -> #DIV/0! | R13: =ROUND(AVERAGE(seed1!R13,seed2!R13,seed3!R13,seed4!R13,seed5!R13),4) -> #DIV/0!
B14: （Bus） | C14: =ROUND(AVERAGE(seed1!C14,seed2!C14,seed3!C14,seed4!C14,seed5!C14),4) -> 6.2873 | D14: =ROUND(AVERAGE(seed1!D14,seed2!D14,seed3!D14,seed4!D14,seed5!D14),4) -> 6.4114 | E14: =ROUND(AVERAGE(seed1!E14,seed2!E14,seed3!E14,seed4!E14,seed5!E14),4) -> 7.1201 | F14: =ROUND(AVERAGE(seed1!F14,seed2!F14,seed3!F14,seed4!F14,seed5!F14),4) -> 7.0109 | G14: =ROUND(AVERAGE(seed1!G14,seed2!G14,seed3!G14,seed4!G14,seed5!G14),4) -> 6.504 | H14: =ROUND(AVERAGE(seed1!H14,seed2!H14,seed3!H14,seed4!H14,seed5!H14),4) -> 7.0908 | I14: =ROUND(AVERAGE(seed1!I14,seed2!I14,seed3!I14,seed4!I14,seed5!I14),4) -> 7.1634 | K14: （Bus） | L14: =ROUND(AVERAGE(seed1!L14,seed2!L14,seed3!L14,seed4!L14,seed5!L14),4) -> #DIV/0! | M14: =ROUND(AVERAGE(seed1!M14,seed2!M14,seed3!M14,seed4!M14,seed5!M14),4) -> #DIV/0! | N14: =ROUND(AVERAGE(seed1!N14,seed2!N14,seed3!N14,seed4!N14,seed5!N14),4) -> #DIV/0! | O14: =ROUND(AVERAGE(seed1!O14,seed2!O14,seed3!O14,seed4!O14,seed5!O14),4) -> #DIV/0! | P14: =ROUND(AVERAGE(seed1!P14,seed2!P14,seed3!P14,seed4!P14,seed5!P14),4) -> #DIV/0! | Q14: =ROUND(AVERAGE(seed1!Q14,seed2!Q14,seed3!Q14,seed4!Q14,seed5!Q14),4) -> #DIV/0! | R14: =ROUND(AVERAGE(seed1!R14,seed2!R14,seed3!R14,seed4!R14,seed5!R14),4) -> #DIV/0!
B15: （Car） | C15: =ROUND(AVERAGE(seed1!C15,seed2!C15,seed3!C15,seed4!C15,seed5!C15),4) -> 6.6932 | D15: =ROUND(AVERAGE(seed1!D15,seed2!D15,seed3!D15,seed4!D15,seed5!D15),4) -> 6.7466 | E15: =ROUND(AVERAGE(seed1!E15,seed2!E15,seed3!E15,seed4!E15,seed5!E15),4) -> 7.4945 | F15: =ROUND(AVERAGE(seed1!F15,seed2!F15,seed3!F15,seed4!F15,seed5!F15),4) -> 7.4901 | G15: =ROUND(AVERAGE(seed1!G15,seed2!G15,seed3!G15,seed4!G15,seed5!G15),4) -> 6.9292 | H15: =ROUND(AVERAGE(seed1!H15,seed2!H15,seed3!H15,seed4!H15,seed5!H15),4) -> 7.431 | I15: =ROUND(AVERAGE(seed1!I15,seed2!I15,seed3!I15,seed4!I15,seed5!I15),4) -> 7.485 | K15: （Car） | L15: =ROUND(AVERAGE(seed1!L15,seed2!L15,seed3!L15,seed4!L15,seed5!L15),4) -> #DIV/0! | M15: =ROUND(AVERAGE(seed1!M15,seed2!M15,seed3!M15,seed4!M15,seed5!M15),4) -> #DIV/0! | N15: =ROUND(AVERAGE(seed1!N15,seed2!N15,seed3!N15,seed4!N15,seed5!N15),4) -> #DIV/0! | O15: =ROUND(AVERAGE(seed1!O15,seed2!O15,seed3!O15,seed4!O15,seed5!O15),4) -> #DIV/0! | P15: =ROUND(AVERAGE(seed1!P15,seed2!P15,seed3!P15,seed4!P15,seed5!P15),4) -> #DIV/0! | Q15: =ROUND(AVERAGE(seed1!Q15,seed2!Q15,seed3!Q15,seed4!Q15,seed5!Q15),4) -> #DIV/0! | R15: =ROUND(AVERAGE(seed1!R15,seed2!R15,seed3!R15,seed4!R15,seed5!R15),4) -> #DIV/0!
B16: 合計 | C16: =ROUND(AVERAGE(seed1!C16,seed2!C16,seed3!C16,seed4!C16,seed5!C16),4) -> 6.6075 | D16: =ROUND(AVERAGE(seed1!D16,seed2!D16,seed3!D16,seed4!D16,seed5!D16),4) -> 6.6722 | E16: =ROUND(AVERAGE(seed1!E16,seed2!E16,seed3!E16,seed4!E16,seed5!E16),4) -> 7.4114 | F16: =ROUND(AVERAGE(seed1!F16,seed2!F16,seed3!F16,seed4!F16,seed5!F16),4) -> 7.3775 | G16: =ROUND(AVERAGE(seed1!G16,seed2!G16,seed3!G16,seed4!G16,seed5!G16),4) -> 6.8242 | H16: =ROUND(AVERAGE(seed1!H16,seed2!H16,seed3!H16,seed4!H16,seed5!H16),4) -> 7.3584 | I16: =ROUND(AVERAGE(seed1!I16,seed2!I16,seed3!I16,seed4!I16,seed5!I16),4) -> 7.4159 | K16: 合計 | L16: =ROUND(AVERAGE(seed1!L16,seed2!L16,seed3!L16,seed4!L16,seed5!L16),4) -> #DIV/0! | M16: =ROUND(AVERAGE(seed1!M16,seed2!M16,seed3!M16,seed4!M16,seed5!M16),4) -> #DIV/0! | N16: =ROUND(AVERAGE(seed1!N16,seed2!N16,seed3!N16,seed4!N16,seed5!N16),4) -> #DIV/0! | O16: =ROUND(AVERAGE(seed1!O16,seed2!O16,seed3!O16,seed4!O16,seed5!O16),4) -> #DIV/0! | P16: =ROUND(AVERAGE(seed1!P16,seed2!P16,seed3!P16,seed4!P16,seed5!P16),4) -> #DIV/0! | Q16: =ROUND(AVERAGE(seed1!Q16,seed2!Q16,seed3!Q16,seed4!Q16,seed5!Q16),4) -> #DIV/0! | R16: =ROUND(AVERAGE(seed1!R16,seed2!R16,seed3!R16,seed4!R16,seed5!R16),4) -> #DIV/0!
B17: 交差点前_平均 | C17: =ROUND(AVERAGE(C7,C10,C13),4) -> 4.7729 | D17: =ROUND(AVERAGE(D7,D10,D13),4) -> 5.1516 | E17: =ROUND(AVERAGE(E7,E10,E13),4) -> 5.7582 | F17: =ROUND(AVERAGE(F7,F10,F13),4) -> 5.6298 | G17: =ROUND(AVERAGE(G7,G10,G13),4) -> 4.998 | H17: =ROUND(AVERAGE(H7,H10,H13),4) -> 5.5652 | I17: =ROUND(AVERAGE(I7,I10,I13),4) -> 5.6431 | K17: 交差点前_平均 | L17: =ROUND(AVERAGE(L7,L10,L13),4) -> #DIV/0! | M17: =ROUND(AVERAGE(M7,M10,M13),4) -> #DIV/0! | N17: =ROUND(AVERAGE(N7,N10,N13),4) -> #DIV/0! | O17: =ROUND(AVERAGE(O7,O10,O13),4) -> #DIV/0! | P17: =ROUND(AVERAGE(P7,P10,P13),4) -> #DIV/0! | Q17: =ROUND(AVERAGE(Q7,Q10,Q13),4) -> #DIV/0! | R17: =ROUND(AVERAGE(R7,R10,R13),4) -> #DIV/0!
B18: 通過台数_L | C18: =ROUND(AVERAGE(seed1!C18,seed2!C18,seed3!C18,seed4!C18,seed5!C18),1) -> 60.8 | D18: =ROUND(AVERAGE(seed1!D18,seed2!D18,seed3!D18,seed4!D18,seed5!D18),1) -> 59.4 | E18: =ROUND(AVERAGE(seed1!E18,seed2!E18,seed3!E18,seed4!E18,seed5!E18),1) -> 60.4 | F18: =ROUND(AVERAGE(seed1!F18,seed2!F18,seed3!F18,seed4!F18,seed5!F18),1) -> 60.4 | G18: =ROUND(AVERAGE(seed1!G18,seed2!G18,seed3!G18,seed4!G18,seed5!G18),1) -> 60.4 | H18: =ROUND(AVERAGE(seed1!H18,seed2!H18,seed3!H18,seed4!H18,seed5!H18),1) -> 60.6 | I18: =ROUND(AVERAGE(seed1!I18,seed2!I18,seed3!I18,seed4!I18,seed5!I18),1) -> 61 | K18: 通過台数_L | L18: =ROUND(AVERAGE(seed1!L18,seed2!L18,seed3!L18,seed4!L18,seed5!L18),1) -> #DIV/0! | M18: =ROUND(AVERAGE(seed1!M18,seed2!M18,seed3!M18,seed4!M18,seed5!M18),1) -> #DIV/0! | N18: =ROUND(AVERAGE(seed1!N18,seed2!N18,seed3!N18,seed4!N18,seed5!N18),1) -> #DIV/0! | O18: =ROUND(AVERAGE(seed1!O18,seed2!O18,seed3!O18,seed4!O18,seed5!O18),1) -> #DIV/0! | P18: =ROUND(AVERAGE(seed1!P18,seed2!P18,seed3!P18,seed4!P18,seed5!P18),1) -> #DIV/0! | Q18: =ROUND(AVERAGE(seed1!Q18,seed2!Q18,seed3!Q18,seed4!Q18,seed5!Q18),1) -> #DIV/0! | R18: =ROUND(AVERAGE(seed1!R18,seed2!R18,seed3!R18,seed4!R18,seed5!R18),1) -> #DIV/0!
B19: 通過台数_R | C19: =ROUND(AVERAGE(seed1!C19,seed2!C19,seed3!C19,seed4!C19,seed5!C19),1) -> 58.2 | D19: =ROUND(AVERAGE(seed1!D19,seed2!D19,seed3!D19,seed4!D19,seed5!D19),1) -> 58.4 | E19: =ROUND(AVERAGE(seed1!E19,seed2!E19,seed3!E19,seed4!E19,seed5!E19),1) -> 58.8 | F19: =ROUND(AVERAGE(seed1!F19,seed2!F19,seed3!F19,seed4!F19,seed5!F19),1) -> 58.4 | G19: =ROUND(AVERAGE(seed1!G19,seed2!G19,seed3!G19,seed4!G19,seed5!G19),1) -> 58 | H19: =ROUND(AVERAGE(seed1!H19,seed2!H19,seed3!H19,seed4!H19,seed5!H19),1) -> 58.6 | I19: =ROUND(AVERAGE(seed1!I19,seed2!I19,seed3!I19,seed4!I19,seed5!I19),1) -> 58.4 | K19: 通過台数_R | L19: =ROUND(AVERAGE(seed1!L19,seed2!L19,seed3!L19,seed4!L19,seed5!L19),1) -> #DIV/0! | M19: =ROUND(AVERAGE(seed1!M19,seed2!M19,seed3!M19,seed4!M19,seed5!M19),1) -> #DIV/0! | N19: =ROUND(AVERAGE(seed1!N19,seed2!N19,seed3!N19,seed4!N19,seed5!N19),1) -> #DIV/0! | O19: =ROUND(AVERAGE(seed1!O19,seed2!O19,seed3!O19,seed4!O19,seed5!O19),1) -> #DIV/0! | P19: =ROUND(AVERAGE(seed1!P19,seed2!P19,seed3!P19,seed4!P19,seed5!P19),1) -> #DIV/0! | Q19: =ROUND(AVERAGE(seed1!Q19,seed2!Q19,seed3!Q19,seed4!Q19,seed5!Q19),1) -> #DIV/0! | R19: =ROUND(AVERAGE(seed1!R19,seed2!R19,seed3!R19,seed4!R19,seed5!R19),1) -> #DIV/0!
B20: 通過台数_B | C20: =ROUND(AVERAGE(seed1!C20,seed2!C20,seed3!C20,seed4!C20,seed5!C20),1) -> 67.6 | D20: =ROUND(AVERAGE(seed1!D20,seed2!D20,seed3!D20,seed4!D20,seed5!D20),1) -> 69 | E20: =ROUND(AVERAGE(seed1!E20,seed2!E20,seed3!E20,seed4!E20,seed5!E20),1) -> 69 | F20: =ROUND(AVERAGE(seed1!F20,seed2!F20,seed3!F20,seed4!F20,seed5!F20),1) -> 68.6 | G20: =ROUND(AVERAGE(seed1!G20,seed2!G20,seed3!G20,seed4!G20,seed5!G20),1) -> 69 | H20: =ROUND(AVERAGE(seed1!H20,seed2!H20,seed3!H20,seed4!H20,seed5!H20),1) -> 69 | I20: =ROUND(AVERAGE(seed1!I20,seed2!I20,seed3!I20,seed4!I20,seed5!I20),1) -> 68.8 | K20: 通過台数_B | L20: =ROUND(AVERAGE(seed1!L20,seed2!L20,seed3!L20,seed4!L20,seed5!L20),1) -> #DIV/0! | M20: =ROUND(AVERAGE(seed1!M20,seed2!M20,seed3!M20,seed4!M20,seed5!M20),1) -> #DIV/0! | N20: =ROUND(AVERAGE(seed1!N20,seed2!N20,seed3!N20,seed4!N20,seed5!N20),1) -> #DIV/0! | O20: =ROUND(AVERAGE(seed1!O20,seed2!O20,seed3!O20,seed4!O20,seed5!O20),1) -> #DIV/0! | P20: =ROUND(AVERAGE(seed1!P20,seed2!P20,seed3!P20,seed4!P20,seed5!P20),1) -> #DIV/0! | Q20: =ROUND(AVERAGE(seed1!Q20,seed2!Q20,seed3!Q20,seed4!Q20,seed5!Q20),1) -> #DIV/0! | R20: =ROUND(AVERAGE(seed1!R20,seed2!R20,seed3!R20,seed4!R20,seed5!R20),1) -> #DIV/0!
B21: 通過台数_合計 | C21: =SUM(C18:C20) -> 186.6 | D21: =SUM(D18:D20) -> 186.8 | E21: =SUM(E18:E20) -> 188.2 | F21: =SUM(F18:F20) -> 187.4 | G21: =SUM(G18:G20) -> 187.4 | H21: =SUM(H18:H20) -> 188.2 | I21: =SUM(I18:I20) -> 188.2 | K21: 通過台数_合計 | L21: =SUM(L18:L20) -> #DIV/0! | M21: =SUM(M18:M20) -> #DIV/0! | N21: =SUM(N18:N20) -> #DIV/0! | O21: =SUM(O18:O20) -> #DIV/0! | P21: =SUM(P18:P20) -> #DIV/0! | Q21: =SUM(Q18:Q20) -> #DIV/0! | R21: =SUM(R18:R20) -> #DIV/0! | U21: =(I16-H16)*2/(H16+I16) -> 0.0077837867
B23: 500/500/500
C24: 1 | D24: 2 | E24: 3 | F24: 4 | G24: 5 | H24: 6 | I24: 7
C25: 全て受け入れ | D25: 道交法 | E25: 0.2 | F25: 0.4 | G25: 既存 | H25: 提案 | I25: 性能込み
B26: （Bus） | C26: =ROUND(AVERAGE(seed1!C26,seed2!C26,seed3!C26,seed4!C26,seed5!C26),4) -> 2.1915 | D26: =ROUND(AVERAGE(seed1!D26,seed2!D26,seed3!D26,seed4!D26,seed5!D26),4) -> 3.0306 | E26: =ROUND(AVERAGE(seed1!E26,seed2!E26,seed3!E26,seed4!E26,seed5!E26),4) -> 3.8221 | F26: =ROUND(AVERAGE(seed1!F26,seed2!F26,seed3!F26,seed4!F26,seed5!F26),4) -> 4.2878 | G26: =ROUND(AVERAGE(seed1!G26,seed2!G26,seed3!G26,seed4!G26,seed5!G26),4) -> 3.9025 | H26: =ROUND(AVERAGE(seed1!H26,seed2!H26,seed3!H26,seed4!H26,seed5!H26),4) -> 3.9615 | I26: =ROUND(AVERAGE(seed1!I26,seed2!I26,seed3!I26,seed4!I26,seed5!I26),4) -> 3.875
B27: （Car） | C27: =ROUND(AVERAGE(seed1!C27,seed2!C27,seed3!C27,seed4!C27,seed5!C27),4) -> 2.1724 | D27: =ROUND(AVERAGE(seed1!D27,seed2!D27,seed3!D27,seed4!D27,seed5!D27),4) -> 3.0704 | E27: =ROUND(AVERAGE(seed1!E27,seed2!E27,seed3!E27,seed4!E27,seed5!E27),4) -> 3.7057 | F27: =ROUND(AVERAGE(seed1!F27,seed2!F27,seed3!F27,seed4!F27,seed5!F27),4) -> 4.0978 | G27: =ROUND(AVERAGE(seed1!G27,seed2!G27,seed3!G27,seed4!G27,seed5!G27),4) -> 3.7059 | H27: =ROUND(AVERAGE(seed1!H27,seed2!H27,seed3!H27,seed4!H27,seed5!H27),4) -> 3.5912 | I27: =ROUND(AVERAGE(seed1!I27,seed2!I27,seed3!I27,seed4!I27,seed5!I27),4) -> 3.9142
B28: 右折 | C28: =ROUND(AVERAGE(seed1!C28,seed2!C28,seed3!C28,seed4!C28,seed5!C28),4) -> 2.1714 | D28: =ROUND(AVERAGE(seed1!D28,seed2!D28,seed3!D28,seed4!D28,seed5!D28),4) -> 3.0581 | E28: =ROUND(AVERAGE(seed1!E28,seed2!E28,seed3!E28,seed4!E28,seed5!E28),4) -> 3.7304 | F28: =ROUND(AVERAGE(seed1!F28,seed2!F28,seed3!F28,seed4!F28,seed5!F28),4) -> 4.146 | G28: =ROUND(AVERAGE(seed1!G28,seed2!G28,seed3!G28,seed4!G28,seed5!G28),4) -> 3.4955 | H28: =ROUND(AVERAGE(seed1!H28,seed2!H28,seed3!H28,seed4!H28,seed5!H28),4) -> 3.646 | I28: =ROUND(AVERAGE(seed1!I28,seed2!I28,seed3!I28,seed4!I28,seed5!I28),4) -> 3.9189
B29: （Bus） | C29: =ROUND(AVERAGE(seed1!C29,seed2!C29,seed3!C29,seed4!C29,seed5!C29),4) -> 3.8016 | D29: =ROUND(AVERAGE(seed1!D29,seed2!D29,seed3!D29,seed4!D29,seed5!D29),4) -> 2.6865 | E29: =ROUND(AVERAGE(seed1!E29,seed2!E29,seed3!E29,seed4!E29,seed5!E29),4) -> 3.266 | F29: =ROUND(AVERAGE(seed1!F29,seed2!F29,seed3!F29,seed4!F29,seed5!F29),4) -> 3.853 | G29: =ROUND(AVERAGE(seed1!G29,seed2!G29,seed3!G29,seed4!G29,seed5!G29),4) -> 3.5997 | H29: =ROUND(AVERAGE(seed1!H29,seed2!H29,seed3!H29,seed4!H29,seed5!H29),4) -> 3.5869 | I29: =ROUND(AVERAGE(seed1!I29,seed2!I29,seed3!I29,seed4!I29,seed5!I29),4) -> 3.9612
B30: （Car） | C30: =ROUND(AVERAGE(seed1!C30,seed2!C30,seed3!C30,seed4!C30,seed5!C30),4) -> 3.5143 | D30: =ROUND(AVERAGE(seed1!D30,seed2!D30,seed3!D30,seed4!D30,seed5!D30),4) -> 2.3479 | E30: =ROUND(AVERAGE(seed1!E30,seed2!E30,seed3!E30,seed4!E30,seed5!E30),4) -> 2.8371 | F30: =ROUND(AVERAGE(seed1!F30,seed2!F30,seed3!F30,seed4!F30,seed5!F30),4) -> 3.627 | G30: =ROUND(AVERAGE(seed1!G30,seed2!G30,seed3!G30,seed4!G30,seed5!G30),4) -> 3.5203 | H30: =ROUND(AVERAGE(seed1!H30,seed2!H30,seed3!H30,seed4!H30,seed5!H30),4) -> 3.5999 | I30: =ROUND(AVERAGE(seed1!I30,seed2!I30,seed3!I30,seed4!I30,seed5!I30),4) -> 4.0554 | L30: 600s seed1-5
B31: 左折 | C31: =ROUND(AVERAGE(seed1!C31,seed2!C31,seed3!C31,seed4!C31,seed5!C31),4) -> 3.585 | D31: =ROUND(AVERAGE(seed1!D31,seed2!D31,seed3!D31,seed4!D31,seed5!D31),4) -> 2.4192 | E31: =ROUND(AVERAGE(seed1!E31,seed2!E31,seed3!E31,seed4!E31,seed5!E31),4) -> 2.9163 | F31: =ROUND(AVERAGE(seed1!F31,seed2!F31,seed3!F31,seed4!F31,seed5!F31),4) -> 3.6813 | G31: =ROUND(AVERAGE(seed1!G31,seed2!G31,seed3!G31,seed4!G31,seed5!G31),4) -> 3.5423 | H31: =ROUND(AVERAGE(seed1!H31,seed2!H31,seed3!H31,seed4!H31,seed5!H31),4) -> 3.5811 | I31: =ROUND(AVERAGE(seed1!I31,seed2!I31,seed3!I31,seed4!I31,seed5!I31),4) -> 4.0235 | M31: 400 | N31: 500
B32: （Bus） | C32: =ROUND(AVERAGE(seed1!C32,seed2!C32,seed3!C32,seed4!C32,seed5!C32),4) -> 2.4103 | D32: =ROUND(AVERAGE(seed1!D32,seed2!D32,seed3!D32,seed4!D32,seed5!D32),4) -> 4.333 | E32: =ROUND(AVERAGE(seed1!E32,seed2!E32,seed3!E32,seed4!E32,seed5!E32),4) -> 4.4276 | F32: =ROUND(AVERAGE(seed1!F32,seed2!F32,seed3!F32,seed4!F32,seed5!F32),4) -> 4.6672 | G32: =ROUND(AVERAGE(seed1!G32,seed2!G32,seed3!G32,seed4!G32,seed5!G32),4) -> 3.9683 | H32: =ROUND(AVERAGE(seed1!H32,seed2!H32,seed3!H32,seed4!H32,seed5!H32),4) -> 3.8647 | I32: =ROUND(AVERAGE(seed1!I32,seed2!I32,seed3!I32,seed4!I32,seed5!I32),4) -> 4.2268 | L32: ALW | M32: 6.6075 | N32: 4.6017
B33: （Car） | C33: =ROUND(AVERAGE(seed1!C33,seed2!C33,seed3!C33,seed4!C33,seed5!C33),4) -> 2.1876 | D33: =ROUND(AVERAGE(seed1!D33,seed2!D33,seed3!D33,seed4!D33,seed5!D33),4) -> 4.4501 | E33: =ROUND(AVERAGE(seed1!E33,seed2!E33,seed3!E33,seed4!E33,seed5!E33),4) -> 4.7321 | F33: =ROUND(AVERAGE(seed1!F33,seed2!F33,seed3!F33,seed4!F33,seed5!F33),4) -> 4.9406 | G33: =ROUND(AVERAGE(seed1!G33,seed2!G33,seed3!G33,seed4!G33,seed5!G33),4) -> 4.0715 | H33: =ROUND(AVERAGE(seed1!H33,seed2!H33,seed3!H33,seed4!H33,seed5!H33),4) -> 4.2177 | I33: =ROUND(AVERAGE(seed1!I33,seed2!I33,seed3!I33,seed4!I33,seed5!I33),4) -> 4.6192 | L33: ACT | M33: 6.6722 | N33: 4.8419
B34: 直進 | C34: =ROUND(AVERAGE(seed1!C34,seed2!C34,seed3!C34,seed4!C34,seed5!C34),4) -> 2.2269 | D34: =ROUND(AVERAGE(seed1!D34,seed2!D34,seed3!D34,seed4!D34,seed5!D34),4) -> 4.4173 | E34: =ROUND(AVERAGE(seed1!E34,seed2!E34,seed3!E34,seed4!E34,seed5!E34),4) -> 4.6753 | F34: =ROUND(AVERAGE(seed1!F34,seed2!F34,seed3!F34,seed4!F34,seed5!F34),4) -> 4.8338 | G34: =ROUND(AVERAGE(seed1!G34,seed2!G34,seed3!G34,seed4!G34,seed5!G34),4) -> 4.0511 | H34: =ROUND(AVERAGE(seed1!H34,seed2!H34,seed3!H34,seed4!H34,seed5!H34),4) -> 4.1377 | I34: =ROUND(AVERAGE(seed1!I34,seed2!I34,seed3!I34,seed4!I34,seed5!I34),4) -> 4.5336 | L34: SPD | M34: 7.3775 | N34: 5.9591
B35: （Bus） | C35: =ROUND(AVERAGE(seed1!C35,seed2!C35,seed3!C35,seed4!C35,seed5!C35),4) -> 4.107 | D35: =ROUND(AVERAGE(seed1!D35,seed2!D35,seed3!D35,seed4!D35,seed5!D35),4) -> 4.6294 | E35: =ROUND(AVERAGE(seed1!E35,seed2!E35,seed3!E35,seed4!E35,seed5!E35),4) -> 5.2449 | F35: =ROUND(AVERAGE(seed1!F35,seed2!F35,seed3!F35,seed4!F35,seed5!F35),4) -> 5.8848 | G35: =ROUND(AVERAGE(seed1!G35,seed2!G35,seed3!G35,seed4!G35,seed5!G35),4) -> 5.4113 | H35: =ROUND(AVERAGE(seed1!H35,seed2!H35,seed3!H35,seed4!H35,seed5!H35),4) -> 5.2492 | I35: =ROUND(AVERAGE(seed1!I35,seed2!I35,seed3!I35,seed4!I35,seed5!I35),4) -> 5.5593 | L35: UTF | M35: 6.8242 | N35: 5.5058
B36: （Car） | C36: =ROUND(AVERAGE(seed1!C36,seed2!C36,seed3!C36,seed4!C36,seed5!C36),4) -> 3.967 | D36: =ROUND(AVERAGE(seed1!D36,seed2!D36,seed3!D36,seed4!D36,seed5!D36),4) -> 4.7875 | E36: =ROUND(AVERAGE(seed1!E36,seed2!E36,seed3!E36,seed4!E36,seed5!E36),4) -> 5.3925 | F36: =ROUND(AVERAGE(seed1!F36,seed2!F36,seed3!F36,seed4!F36,seed5!F36),4) -> 6.0672 | G36: =ROUND(AVERAGE(seed1!G36,seed2!G36,seed3!G36,seed4!G36,seed5!G36),4) -> 5.5636 | H36: =ROUND(AVERAGE(seed1!H36,seed2!H36,seed3!H36,seed4!H36,seed5!H36),4) -> 5.4862 | I36: =ROUND(AVERAGE(seed1!I36,seed2!I36,seed3!I36,seed4!I36,seed5!I36),4) -> 5.9427 | L36: TIV_te | M36: 7.3584 | N36: 6.1898
B37: 合計 | C37: =ROUND(AVERAGE(seed1!C37,seed2!C37,seed3!C37,seed4!C37,seed5!C37),4) -> 3.9998 | D37: =ROUND(AVERAGE(seed1!D37,seed2!D37,seed3!D37,seed4!D37,seed5!D37),4) -> 4.747 | E37: =ROUND(AVERAGE(seed1!E37,seed2!E37,seed3!E37,seed4!E37,seed5!E37),4) -> 5.3565 | F37: =ROUND(AVERAGE(seed1!F37,seed2!F37,seed3!F37,seed4!F37,seed5!F37),4) -> 6.0235 | G37: =ROUND(AVERAGE(seed1!G37,seed2!G37,seed3!G37,seed4!G37,seed5!G37),4) -> 5.5238 | H37: =ROUND(AVERAGE(seed1!H37,seed2!H37,seed3!H37,seed4!H37,seed5!H37),4) -> 5.4264 | I37: =ROUND(AVERAGE(seed1!I37,seed2!I37,seed3!I37,seed4!I37,seed5!I37),4) -> 5.8473 | L37: TIV_tep | M37: 7.4159 | N37: 6.4955
B38: 交差点前_平均 | C38: =ROUND(AVERAGE(C28,C31,C34),4) -> 2.6611 | D38: =ROUND(AVERAGE(D28,D31,D34),4) -> 3.2982 | E38: =ROUND(AVERAGE(E28,E31,E34),4) -> 3.774 | F38: =ROUND(AVERAGE(F28,F31,F34),4) -> 4.2204 | G38: =ROUND(AVERAGE(G28,G31,G34),4) -> 3.6963 | H38: =ROUND(AVERAGE(H28,H31,H34),4) -> 3.7883 | I38: =ROUND(AVERAGE(I28,I31,I34),4) -> 4.1587
B39: 通過台数_L | C39: =ROUND(AVERAGE(seed1!C39,seed2!C39,seed3!C39,seed4!C39,seed5!C39),1) -> 73.3 | D39: =ROUND(AVERAGE(seed1!D39,seed2!D39,seed3!D39,seed4!D39,seed5!D39),1) -> 69.3 | E39: =ROUND(AVERAGE(seed1!E39,seed2!E39,seed3!E39,seed4!E39,seed5!E39),1) -> 72 | F39: =ROUND(AVERAGE(seed1!F39,seed2!F39,seed3!F39,seed4!F39,seed5!F39),1) -> 72.8 | G39: =ROUND(AVERAGE(seed1!G39,seed2!G39,seed3!G39,seed4!G39,seed5!G39),1) -> 73.8 | H39: =ROUND(AVERAGE(seed1!H39,seed2!H39,seed3!H39,seed4!H39,seed5!H39),1) -> 70 | I39: =ROUND(AVERAGE(seed1!I39,seed2!I39,seed3!I39,seed4!I39,seed5!I39),1) -> 71.5
B40: 通過台数_R | C40: =ROUND(AVERAGE(seed1!C40,seed2!C40,seed3!C40,seed4!C40,seed5!C40),1) -> 71.5 | D40: =ROUND(AVERAGE(seed1!D40,seed2!D40,seed3!D40,seed4!D40,seed5!D40),1) -> 78 | E40: =ROUND(AVERAGE(seed1!E40,seed2!E40,seed3!E40,seed4!E40,seed5!E40),1) -> 81.3 | F40: =ROUND(AVERAGE(seed1!F40,seed2!F40,seed3!F40,seed4!F40,seed5!F40),1) -> 81.8 | G40: =ROUND(AVERAGE(seed1!G40,seed2!G40,seed3!G40,seed4!G40,seed5!G40),1) -> 81.8 | H40: =ROUND(AVERAGE(seed1!H40,seed2!H40,seed3!H40,seed4!H40,seed5!H40),1) -> 76.3 | I40: =ROUND(AVERAGE(seed1!I40,seed2!I40,seed3!I40,seed4!I40,seed5!I40),1) -> 75.3 | O40: 7.4114
B41: 通過台数_B | C41: =ROUND(AVERAGE(seed1!C41,seed2!C41,seed3!C41,seed4!C41,seed5!C41),1) -> 68.5 | D41: =ROUND(AVERAGE(seed1!D41,seed2!D41,seed3!D41,seed4!D41,seed5!D41),1) -> 77.3 | E41: =ROUND(AVERAGE(seed1!E41,seed2!E41,seed3!E41,seed4!E41,seed5!E41),1) -> 76 | F41: =ROUND(AVERAGE(seed1!F41,seed2!F41,seed3!F41,seed4!F41,seed5!F41),1) -> 78 | G41: =ROUND(AVERAGE(seed1!G41,seed2!G41,seed3!G41,seed4!G41,seed5!G41),1) -> 75.8 | H41: =ROUND(AVERAGE(seed1!H41,seed2!H41,seed3!H41,seed4!H41,seed5!H41),1) -> 73.3 | I41: =ROUND(AVERAGE(seed1!I41,seed2!I41,seed3!I41,seed4!I41,seed5!I41),1) -> 73.5 | O41: 5.6329
B42: 通過台数_合計 | C42: =SUM(C39:C41) -> 213.3 | D42: =SUM(D39:D41) -> 224.6 | E42: =SUM(E39:E41) -> 229.3 | F42: =SUM(F39:F41) -> 232.6 | G42: =SUM(G39:G41) -> 231.4 | H42: =SUM(H39:H41) -> 219.6 | I42: =SUM(I39:I41) -> 220.3
...
