Workbook

Sheet seed1
B2: 300/300/300/300 | K2: 600/600/600
C3: 1 | D3: 2 | E3: 3 | F3: 4 | G3: 5 | H3: 6 | I3: 7 | L3: 1 | M3: 2 | N3: 3 | O3: 4 | P3: 5 | Q3: 6 | R3: 7
C4: 全て受け入れ | D4: 道交法 | E4: 0.2 | F4: 0.4 | G4: 既存 | H4: 提案 | I4: 性能込み | L4: 全て受け入れ | M4: 道交法 | N4: 0.2 | O4: 0.4 | P4: 既存 | Q4: 提案 | R4: 性能込み
B5: （Bus） | C5: 4.0328 | D5: 5.3294 | E5: 4.316 | F5: 3.7446 | G5: 4.1349 | H5: 5.5178 | I5: 5.4452 | K5: （Bus）
B6: （Car） | C6: 4.5335 | D6: 4.9116 | E6: 4.782 | F6: 3.922 | G6: 4.3352 | H6: 5.4725 | I6: 5.7144 | K6: （Car）
B7: 右折 | C7: 4.3744 | D7: 5.0274 | E7: 4.6352 | F7: 3.8682 | G7: 4.2744 | H7: 5.4857 | I7: 5.6325 | K7: 右折
B8: （Bus） | C8: 3.2307 | D8: 4.1827 | E8: 3.9698 | F8: 2.8913 | G8: 3.1094 | H8: 4.7605 | I8: 4.6241 | K8: （Bus）
B9: （Car） | C9: 4.0187 | D9: 4.383 | E9: 4.3506 | F9: 3.3765 | G9: 3.9221 | H9: 4.4958 | I9: 4.9859 | K9: （Car）
B10: 直進 | C10: 3.7696 | D10: 4.3262 | E10: 4.2396 | F10: 3.2285 | G10: 3.6607 | H10: 4.5651 | I10: 4.8813 | K10: 直進
B11: （Bus） | C11: 2.908 | D11: 8.0046 | E11: 4.9305 | F11: 1.7257 | G11: 3.2871 | H11: 4.3033 | I11: 6.6717 | K11: （Bus）
B12: （Car） | C12: 3.0631 | D12: 7.3739 | E12: 3.8344 | F12: 2.298 | G12: 3.7128 | H12: 5.5886 | I12: 6.6147 | K12: （Car）
B13: 左折 | C13: 3.0354 | D13: 7.4749 | E13: 3.9868 | F13: 2.174 | G13: 3.6317 | H13: 5.3146 | I13: 6.6245 | K13: 左折
B14: （Bus） | C14: 5.1421 | D14: 6.5252 | E14: 5.8902 | F14: 4.6026 | G14: 5.1872 | H14: 6.5899 | I14: 6.7217 | K14: （Bus）
B15: （Car） | C15: 5.8474 | D15: 6.9353 | E15: 6.4036 | F15: 5.1376 | G15: 5.9531 | H15: 7.0352 | I15: 7.4522 | K15: （Car）
B16: 合計 | C16: 5.6432 | D16: 6.8224 | E16: 6.2603 | F16: 4.9845 | G16: 5.7298 | H16: 6.912 | I16: 7.2457 | K16: 合計
A18: RB+BL | B18: 通過台数_L | J18: RB+BL | K18: 通過台数_L
A19: LB+BR | B19: 通過台数_R | J19: LB+BR | K19: 通過台数_R
A20: LR+RL | B20: 通過台数_B | J20: LR+RL | K20: 通過台数_B
B23: 500/500/500
C24: 1 | D24: 2 | E24: 3 | F24: 4 | G24: 5 | H24: 6 | I24: 7 | L24: pass_LT | M24: pass_LR | N24: pass_LB | O24: pass_TR | P24: pass_TB | Q24: pass_TL | R24: pass_RB | S24: pass_RL | T24: pass_RT | U24: pass_BL | V24: pass_BT | W24: pass_BR
C25: 全て受け入れ | D25: 道交法 | E25: 0.2 | F25: 0.4 | G25: 既存 | H25: 提案 | I25: 性能込み | L25: 4 | M25: 2 | N25: 6 | O25: 7 | P25: 0 | Q25: 8 | R25: 2 | S25: 3 | T25: 6 | U25: 8 | V25: 0 | W25: 5
B26: （Bus） | L26: 8 | M26: 15 | N26: 11 | O26: 18 | P26: 0 | Q26: 16 | R26: 15 | S26: 12 | T26: 11 | U26: 13 | V26: 0 | W26: 22
B27: （Car） | L27: pass_LT | M27: pass_LR | N27: pass_LB | O27: pass_TR | P27: pass_TB | Q27: pass_TL | R27: pass_RB | S27: pass_RL | T27: pass_RT | U27: pass_BL | V27: pass_BT | W27: pass_BR
B28: 右折 | L28: 4 | M28: 2 | N28: 6 | O28: 7 | P28: 0 | Q28: 8 | R28: 2 | S28: 3 | T28: 6 | U28: 8 | V28: 0 | W28: 5
B29: （Bus） | L29: 8 | M29: 15 | N29: 11 | O29: 18 | P29: 0 | Q29: 16 | R29: 15 | S29: 12 | T29: 11 | U29: 13 | V29: 0 | W29: 22
B30: （Car） | L30: pass_LT | M30: pass_LR | N30: pass_LB | O30: pass_TR | P30: pass_TB | Q30: pass_TL | R30: pass_RB | S30: pass_RL | T30: pass_RT | U30: pass_BL | V30: pass_BT | W30: pass_BR
B31: 左折 | L31: 4 | M31: 2 | N31: 6 | O31: 7 | P31: 0 | Q31: 8 | R31: 2 | S31: 3 | T31: 6 | U31: 8 | V31: 0 | W31: 5
B32: （Bus） | L32: 8 | M32: 15 | N32: 11 | O32: 18 | P32: 0 | Q32: 16 | R32: 15 | S32: 12 | T32: 11 | U32: 13 | V32: 0 | W32: 22
B33: （Car） | L33: pass_LT | M33: pass_LR | N33: pass_LB | O33: pass_TR | P33: pass_TB | Q33: pass_TL | R33: pass_RB | S33: pass_RL | T33: pass_RT | U33: pass_BL | V33: pass_BT | W33: pass_BR
B34: 直進 | L34: 4 | M34: 2 | N34: 6 | O34: 7 | P34: 0 | Q34: 8 | R34: 2 | S34: 3 | T34: 6 | U34: 8 | V34: 0 | W34: 5
B35: （Bus） | L35: 8 | M35: 15 | N35: 11 | O35: 18 | P35: 0 | Q35: 16 | R35: 15 | S35: 12 | T35: 11 | U35: 13 | V35: 0 | W35: 22
B36: （Car） | L36: pass_LT | M36: pass_LR | N36: pass_LB | O36: pass_TR | P36: pass_TB | Q36: pass_TL | R36: pass_RB | S36: pass_RL | T36: pass_RT | U36: pass_BL | V36: pass_BT | W36: pass_BR
B37: 合計 | L37: 4 | M37: 2 | N37: 6 | O37: 7 | P37: 0 | Q37: 8 | R37: 2 | S37: 3 | T37: 6 | U37: 8 | V37: 0 | W37: 5
L38: 8 | M38: 15 | N38: 11 | O38: 18 | P38: 0 | Q38: 16 | R38: 15 | S38: 12 | T38: 11 | U38: 13 | V38: 0 | W38: 22
A39: RB+BL | B39: 通過台数_L | L39: pass_LT | M39: pass_LR | N39: pass_LB | O39: pass_TR | P39: pass_TB | Q39: pass_TL | R39: pass_RB | S39: pass_RL | T39: pass_RT | U39: pass_BL | V39: pass_BT | W39: pass_BR
A40: LB+BR | B40: 通過台数_R | L40: 4 | M40: 2 | N40: 6 | O40: 7 | P40: 0 | Q40: 8 | R40: 2 | S40: 3 | T40: 6 | U40: 8 | V40: 0 | W40: 5
A41: LR+RL | B41: 通過台数_B | L41: 8 | M41: 15 | N41: 11 | O41: 18 | P41: 0 | Q41: 16 | R41: 15 | S41: 12 | T41: 11 | U41: 13 | V41: 0 | W41: 22
L42: pass_LT | M42: pass_LR | N42: pass_LB | O42: pass_TR | P42: pass_TB | Q42: pass_TL | R42: pass_RB | S42: pass_RL | T42: pass_RT | U42: pass_BL | V42: pass_BT | W42: pass_BR
L43: 4 | M43: 2 | N43: 6 | O43: 7 | P43: 0 | Q43: 8 | R43: 2 | S43: 3 | T43: 6 | U43: 8 | V43: 0 | W43: 5
L44: 8 | M44: 15 | N44: 11 | O44: 18 | P44: 0 | Q44: 16 | R44: 15 | S44: 12 | T44: 11 | U44: 13 | V44: 0 | W44: 22

Sheet seed2
B2: 300/300/300/300 | K2: 600/600/600
C3: 1 | D3: 2 | E3: 3 | F3: 4 | G3: 5 | H3: 6 | I3: 7 | L3: 1 | M3: 2 | N3: 3 | O3: 4 | P3: 5 | Q3: 6 | R3: 7
C4: 全て受け入れ | D4: 道交法 | E4: 0.2 | F4: 0.4 | G4: 既存 | H4: 提案 | I4: 性能込み | L4: 全て受け入れ | M4: 道交法 | N4: 0.2 | O4: 0.4 | P4: 既存 | Q4: 提案 | R4: 性能込み
B5: （Bus） | C5: 4.572 | D5: 4.2427 | E5: 5.3828 | F5: 5.2541 | G5: 4.8951 | H5: 5.1444 | I5: 5.5859 | K5: （Bus）
B6: （Car） | C6: 5.1022 | D6: 5.1278 | E6: 5.5414 | F6: 5.3917 | G6: 5.165 | H6: 5.5772 | I6: 5.7494 | K6: （Car）
B7: 右折 | C7: 4.9844 | D7: 4.9182 | E7: 5.5085 | F7: 5.3632 | G7: 5.1074 | H7: 5.4833 | I7: 5.7153 | K7: 右折
B8: （Bus） | C8: 2.8319 | D8: 3.326 | E8: 3.2902 | F8: 3.2225 | G8: 3.6078 | H8: 4.0536 | I8: 4.1437 | K8: （Bus）
B9: （Car） | C9: 4.0101 | D9: 3.8356 | E9: 4.0434 | F9: 3.947 | G9: 3.8897 | H9: 4.2658 | I9: 4.635 | K9: （Car）
B10: 直進 | C10: 3.5289 | D10: 3.6531 | E10: 3.7618 | F10: 3.6773 | G10: 3.7921 | H10: 4.1938 | I10: 4.4619 | K10: 直進
B11: （Bus） | C11: 1.8085 | D11: 2.4869 | E11: 2.3402 | F11: 2.1975 | G11: 2.4239 | H11: 3.5207 | I11: 4.6935 | K11: （Bus）
B12: （Car） | C12: 2.2902 | D12: 3.5769 | E12: 3.0429 | F12: 2.8922 | G12: 3.3206 | H12: 5.0483 | I12: 5.5745 | K12: （Car）
B13: 左折 | C13: 2.1762 | D13: 3.2961 | E13: 2.8734 | F13: 2.723 | G13: 3.0945 | H13: 4.6534 | I13: 5.3772 | K13: 左折
B14: （Bus） | C14: 4.5647 | D14: 5.0379 | E14: 5.2143 | F14: 5.1351 | G14: 5.3119 | H14: 5.8777 | I14: 6.2219 | K14: （Bus）
B15: （Car） | C15: 5.8278 | D15: 6.2285 | E15: 6.2963 | F15: 6.1427 | G15: 6.1476 | H15: 6.862 | I15: 7.1394 | K15: （Car）
B16: 合計 | C16: 5.4518 | D16: 5.8829 | E16: 5.9874 | F16: 5.8561 | G16: 5.9149 | H16: 6.5891 | I16: 6.8859 | K16: 合計
A18: RB+BL | B18: 通過台数_L | J18: RB+BL | K18: 通過台数_L
A19: LB+BR | B19: 通過台数_R | J19: LB+BR | K19: 通過台数_R
A20: LR+RL | B20: 通過台数_B | J20: LR+RL | K20: 通過台数_B
B23: 500/500/500
C24: 1 | D24: 2 | E24: 3 | F24: 4 | G24: 5 | H24: 6 | I24: 7 | L24: pass_LT | M24: pass_LR | N24: pass_LB | O24: pass_TR | P24: pass_TB | Q24: pass_TL | R24: pass_RB | S24: pass_RL | T24: pass_RT | U24: pass_BL | V24: pass_BT | W24: pass_BR
C25: 全て受け入れ | D25: 道交法 | E25: 0.2 | F25: 0.4 | G25: 既存 | H25: 提案 | I25: 性能込み | L25: 5 | M25: 3 | N25: 5 | O25: 10 | P25: 0 | Q25: 6 | R25: 4 | S25: 3 | T25: 1 | U25: 5 | V25: 0 | W25: 5
B26: （Bus） | L26: 11 | M26: 13 | N26: 9 | O26: 15 | P26: 0 | Q26: 18 | R26: 9 | S26: 10 | T26: 20 | U26: 17 | V26: 0 | W26: 20
B27: （Car） | L27: pass_LT | M27: pass_LR | N27: pass_LB | O27: pass_TR | P27: pass_TB | Q27: pass_TL | R27: pass_RB | S27: pass_RL | T27: pass_RT | U27: pass_BL | V27: pass_BT | W27: pass_BR
B28: 右折 | L28: 5 | M28: 3 | N28: 5 | O28: 10 | P28: 0 | Q28: 6 | R28: 3 | S28: 3 | T28: 1 | U28: 5 | V28: 0 | W28: 5
B29: （Bus） | L29: 11 | M29: 14 | N29: 9 | O29: 15 | P29: 0 | Q29: 18 | R29: 8 | S29: 10 | T29: 20 | U29: 16 | V29: 0 | W29: 19
B30: （Car） | L30: pass_LT | M30: pass_LR | N30: pass_LB | O30: pass_TR | P30: pass_TB | Q30: pass_TL | R30: pass_RB | S30: pass_RL | T30: pass_RT | U30: pass_BL | V30: pass_BT | W30: pass_BR
B31: 左折 | L31: 5 | M31: 3 | N31: 4 | O31: 10 | P31: 0 | Q31: 6 | R31: 4 | S31: 3 | T31: 1 | U31: 5 | V31: 0 | W31: 5
B32: （Bus） | L32: 11 | M32: 13 | N32: 9 | O32: 15 | P32: 0 | Q32: 18 | R32: 9 | S32: 10 | T32: 20 | U32: 17 | V32: 0 | W32: 20
B33: （Car） | L33: pass_LT | M33: pass_LR | N33: pass_LB | O33: pass_TR | P33: pass_TB | Q33: pass_TL | R33: pass_RB | S33: pass_RL | T33: pass_RT | U33: pass_BL | V33: pass_BT | W33: pass_BR
B34: 直進 | L34: 5 | M34: 3 | N34: 5 | O34: 10 | P34: 0 | Q34: 6 | R34: 4 | S34: 3 | T34: 1 | U34: 5 | V34: 0 | W34: 5
B35: （Bus） | L35: 11 | M35: 13 | N35: 9 | O35: 15 | P35: 0 | Q35: 18 | R35: 9 | S35: 10 | T35: 20 | U35: 17 | V35: 0 | W35: 20
B36: （Car） | L36: pass_LT | M36: pass_LR | N36: pass_LB | O36: pass_TR | P36: pass_TB | Q36: pass_TL | R36: pass_RB | S36: pass_RL | T36: pass_RT | U36: pass_BL | V36: pass_BT | W36: pass_BR
B37: 合計 | L37: 5 | M37: 3 | N37: 5 | O37: 10 | P37: 0 | Q37: 6 | R37: 4 | S37: 3 | T37: 1 | U37: 5 | V37: 0 | W37: 5
L38: 11 | M38: 13 | N38: 9 | O38: 15 | P38: 0 | Q38: 18 | R38: 9 | S38: 10 | T38: 20 | U38: 17 | V38: 0 | W38: 20
A39: RB+BL | B39: 通過台数_L | L39: pass_LT | M39: pass_LR | N39: pass_LB | O39: pass_TR | P39: pass_TB | Q39: pass_TL | R39: pass_RB | S39: pass_RL | T39: pass_RT | U39: pass_BL | V39: pass_BT | W39: pass_BR
A40: LB+BR | B40: 通過台数_R | L40: 5 | M40: 3 | N40: 4 | O40: 10 | P40: 0 | Q40: 6 | R40: 4 | S40: 3 | T40: 1 | U40: 5 | V40: 0 | W40: 5
A41: LR+RL | B41: 通過台数_B | L41: 11 | M41: 13 | N41: 9 | O41: 15 | P41: 0 | Q41: 18 | R41: 9 | S41: 10 | T41: 20 | U41: 17 | V41: 0 | W41: 20
L42: pass_LT | M42: pass_LR | N42: pass_LB | O42: pass_TR | P42: pass_TB | Q42: pass_TL | R42: pass_RB | S42: pass_RL | T42: pass_RT | U42: pass_BL | V42: pass_BT | W42: pass_BR
L43: 5 | M43: 3 | N43: 5 | O43: 10 | P43: 0 | Q43: 6 | R43: 4 | S43: 3 | T43: 1 | U43: 5 | V43: 0 | W43: 5
L44: 11 | M44: 14 | N44: 9 | O44: 14 | P44: 0 | Q44: 18 | R44: 9 | S44: 10 | T44: 20 | U44: 17 | V44: 0 | W44: 20

Sheet seed3
B2: 300/300/300/300 | K2: 600/600/600
C3: 1 | D3: 2 | E3: 3 | F3: 4 | G3: 5 | H3: 6 | I3: 7 | L3: 1 | M3: 2 | N3: 3 | O3: 4 | P3: 5 | Q3: 6 | R3: 7
C4: 全て受け入れ | D4: 道交法 | E4: 0.2 | F4: 0.4 | G4: 既存 | H4: 提案 | I4: 性能込み | L4: 全て受け入れ | M4: 道交法 | N4: 0.2 | O4: 0.4 | P4: 既存 | Q4: 提案 | R4: 性能込み
B5: （Bus） | C5: 3.3486 | D5: 2.6267 | E5: 2.8809 | F5: 2.5261 | G5: 4.0847 | H5: 3.9646 | I5: 3.6301 | K5: （Bus）
B6: （Car） | C6: 3.8514 | D6: 3.2631 | E6: 3.4859 | F6: 3.7068 | G6: 4.1742 | H6: 4.5873 | I6: 4.4682 | K6: （Car）
B7: 右折 | C7: 3.6686 | D7: 3.0225 | E7: 3.2582 | F7: 3.2119 | G7: 4.1438 | H7: 4.358 | I7: 4.148 | K7: 右折
B8: （Bus） | C8: 2.5775 | D8: 2.2137 | E8: 2.4181 | F8: 2.3154 | G8: 3.2134 | H8: 3.1977 | I8: 2.8291 | K8: （Bus）
B9: （Car） | C9: 3.3333 | D9: 2.8902 | E9: 3.2577 | F9: 2.8403 | G9: 3.8284 | H9: 3.672 | I9: 3.4791 | K9: （Car）
B10: 直進 | C10: 3.1363 | D10: 2.7154 | E10: 3.0337 | F10: 2.7111 | G10: 3.6776 | H10: 3.5591 | I10: 3.3158 | K10: 直進
B11: （Bus） | C11: 2.5701 | D11: 3.2693 | E11: 2.1318 | F11: 3.3756 | G11: 3.2775 | H11: 3.663 | I11: 3.7674 | K11: （Bus）
B12: （Car） | C12: 2.7427 | D12: 3.1222 | E12: 2.6045 | F12: 2.2444 | G12: 3.7299 | H12: 3.7834 | I12: 3.8492 | K12: （Car）
B13: 左折 | C13: 2.6829 | D13: 3.1696 | E13: 2.4259 | F13: 2.5272 | G13: 3.5671 | H13: 3.7427 | I13: 3.8217 | K13: 左折
B14: （Bus） | C14: 4.2894 | D14: 3.9838 | E14: 3.9472 | F14: 3.9567 | G14: 5.151 | H14: 5.174 | I14: 4.9242 | K14: （Bus）
B15: （Car） | C15: 5.1237 | D15: 4.7511 | E15: 4.9689 | F15: 4.6318 | G15: 5.7349 | H15: 5.8538 | I15: 5.6822 | K15: （Car）
B16: 合計 | C16: 4.8627 | D16: 4.5127 | E16: 4.6365 | F16: 4.426 | G16: 5.5589 | H16: 5.6488 | I16: 5.4466 | K16: 合計
A18: RB+BL | B18: 通過台数_L | J18: RB+BL | K18: 通過台数_L
A19: LB+BR | B19: 通過台数_R | J19: LB+BR | K19: 通過台数_R
A20: LR+RL | B20: 通過台数_B | J20: LR+RL | K20: 通過台数_B
B23: 500/500/500
C24: 1 | D24: 2 | E24: 3 | F24: 4 | G24: 5 | H24: 6 | I24: 7 | L24: pass_LT | M24: pass_LR | N24: pass_LB | O24: pass_TR | P24: pass_TB | Q24: pass_TL | R24: pass_RB | S24: pass_RL | T24: pass_RT | U24: pass_BL | V24: pass_BT | W24: pass_BR
C25: 全て受け入れ | D25: 道交法 | E25: 0.2 | F25: 0.4 | G25: 既存 | H25: 提案 | I25: 性能込み | L25: 6 | M25: 4 | N25: 7 | O25: 7 | P25: 0 | Q25: 5 | R25: 2 | S25: 8 | T25: 3 | U25: 3 | V25: 0 | W25: 6
B26: （Bus） | L26: 14 | M26: 9 | N26: 5 | O26: 22 | P26: 0 | Q26: 13 | R26: 8 | S26: 14 | T26: 12 | U26: 21 | V26: 0 | W26: 16
B27: （Car） | L27: pass_LT | M27: pass_LR | N27: pass_LB | O27: pass_TR | P27: pass_TB | Q27: pass_TL | R27: pass_RB | S27: pass_RL | T27: pass_RT | U27: pass_BL | V27: pass_BT | W27: pass_BR
B28: 右折 | L28: 5 | M28: 4 | N28: 7 | O28: 7 | P28: 0 | Q28: 4 | R28: 2 | S28: 8 | T28: 3 | U28: 3 | V28: 0 | W28: 7
B29: （Bus） | L29: 14 | M29: 9 | N29: 5 | O29: 22 | P29: 0 | Q29: 13 | R29: 8 | S29: 14 | T29: 12 | U29: 21 | V29: 0 | W29: 16
B30: （Car） | L30: pass_LT | M30: pass_LR | N30: pass_LB | O30: pass_TR | P30: pass_TB | Q30: pass_TL | R30: pass_RB | S30: pass_RL | T30: pass_RT | U30: pass_BL | V30: pass_BT | W30: pass_BR
B31: 左折 | L31: 5 | M31: 4 | N31: 7 | O31: 7 | P31: 0 | Q31: 6 | R31: 2 | S31: 8 | T31: 3 | U31: 3 | V31: 0 | W31: 7
B32: （Bus） | L32: 14 | M32: 9 | N32: 5 | O32: 22 | P32: 0 | Q32: 13 | R32: 8 | S32: 14 | T32: 12 | U32: 22 | V32: 0 | W32: 16
B33: （Car） | L33: pass_LT | M33: pass_LR | N33: pass_LB | O33: pass_TR | P33: pass_TB | Q33: pass_TL | R33: pass_RB | S33: pass_RL | T33: pass_RT | U33: pass_BL | V33: pass_BT | W33: pass_BR
B34: 直進 | L34: 4 | M34: 4 | N34: 7 | O34: 7 | P34: 0 | Q34: 6 | R34: 2 | S34: 8 | T34: 3 | U34: 3 | V34: 0 | W34: 7
B35: （Bus） | L35: 12 | M35: 9 | N35: 5 | O35: 22 | P35: 0 | Q35: 13 | R35: 8 | S35: 14 | T35: 12 | U35: 22 | V35: 0 | W35: 17
B36: （Car） | L36: pass_LT | M36: pass_LR | N36: pass_LB | O36: pass_TR | P36: pass_TB | Q36: pass_TL | R36: pass_RB | S36: pass_RL | T36: pass_RT | U36: pass_BL | V36: pass_BT | W36: pass_BR
B37: 合計 | L37: 6 | M37: 4 | N37: 8 | O37: 7 | P37: 0 | Q37: 7 | R37: 2 | S37: 8 | T37: 3 | U37: 3 | V37: 0 | W37: 7
L38: 14 | M38: 10 | N38: 5 | O38: 22 | P38: 0 | Q38: 14 | R38: 8 | S38: 14 | T38: 12 | U38: 21 | V38: 0 | W38: 16
A39: RB+BL | B39: 通過台数_L | L39: pass_LT | M39: pass_LR | N39: pass_LB | O39: pass_TR | P39: pass_TB | Q39: pass_TL | R39: pass_RB | S39: pass_RL | T39: pass_RT | U39: pass_BL | V39: pass_BT | W39: pass_BR
A40: LB+BR | B40: 通過台数_R | L40: 6 | M40: 4 | N40: 8 | O40: 7 | P40: 0 | Q40: 6 | R40: 2 | S40: 8 | T40: 3 | U40: 3 | V40: 0 | W40: 7
A41: LR+RL | B41: 通過台数_B | L41: 14 | M41: 10 | N41: 5 | O41: 22 | P41: 0 | Q41: 13 | R41: 8 | S41: 14 | T41: 12 | U41: 22 | V41: 0 | W41: 16
L42: pass_LT | M42: pass_LR | N42: pass_LB | O42: pass_TR | P42: pass_TB | Q42: pass_TL | R42: pass_RB | S42: pass_RL | T42: pass_RT | U42: pass_BL | V42: pass_BT | W42: pass_BR
L43: 6 | M43: 4 | N43: 8 | O43: 7 | P43: 0 | Q43: 7 | R43: 2 | S43: 8 | T43: 3 | U43: 3 | V43: 0 | W43: 6
L44: 14 | M44: 10 | N44: 5 | O44: 22 | P44: 0 | Q44: 14 | R44: 8 | S44: 14 | T44: 12 | U44: 20 | V44: 0 | W44: 15

Sheet seed4
B2: 300/300/300/300 | K2: 600/600/600
C3: 1 | D3: 2 | E3: 3 | F3: 4 | G3: 5 | H3: 6 | I3: 7 | L3: 1 | M3: 2 | N3: 3 | O3: 4 | P3: 5 | Q3: 6 | R3: 7
C4: 全て受け入れ | D4: 道交法 | E4: 0.2 | F4: 0.4 | G4: 既存 | H4: 提案 | I4: 性能込み | L4: 全て受け入れ | M4: 道交法 | N4: 0.2 | O4: 0.4 | P4: 既存 | Q4: 提案 | R4: 性能込み
B5: （Bus） | C5: 3.6434 | D5: 4.4281 | E5: 4.4996 | F5: 4.1829 | G5: 4.776 | H5: 4.5036 | I5: 4.4488 | K5: （Bus）
B6: （Car） | C6: 4.0415 | D6: 4.4822 | E6: 4.5353 | F6: 4.7022 | G6: 4.8364 | H6: 4.6678 | I6: 4.725 | K6: （Car）
B7: 右折 | C7: 3.9378 | D7: 4.4691 | E7: 4.5267 | F7: 4.5682 | G7: 4.8219 | H7: 4.6276 | I7: 4.6566 | K7: 右折
B8: （Bus） | C8: 2.9256 | D8: 3.2328 | E8: 3.3918 | F8: 3.9302 | G8: 4.3238 | H8: 3.2497 | I8: 4.0019 | K8: （Bus）
B9: （Car） | C9: 3.2209 | D9: 3.5878 | E9: 3.8306 | F9: 3.5014 | G9: 4.2237 | H9: 3.6277 | I9: 3.7459 | K9: （Car）
B10: 直進 | C10: 3.1357 | D10: 3.4845 | E10: 3.7008 | F10: 3.6087 | G10: 4.2506 | H10: 3.5161 | I10: 3.8125 | K10: 直進
B11: （Bus） | C11: 3.4468 | D11: 3.8685 | E11: 3.8148 | F11: 3.9475 | G11: 4.7543 | H11: 3.8013 | I11: 4.7662 | K11: （Bus）
B12: （Car） | C12: 4.7471 | D12: 7.5448 | E12: 7.3097 | F12: 5.4477 | G12: 4.7652 | H12: 5.5054 | I12: 4.5028 | K12: （Car）
B13: 左折 | C13: 4.2409 | D13: 5.784 | E13: 5.6497 | F13: 4.8553 | G13: 4.7617 | H13: 4.8124 | I13: 4.5842 | K13: 左折
B14: （Bus） | C14: 4.855 | D14: 5.3611 | E14: 5.5203 | F14: 5.7261 | G14: 6.2146 | H14: 5.4361 | I14: 5.9731 | K14: （Bus）
B15: （Car） | C15: 5.5248 | D15: 6.1653 | E15: 6.3132 | F15: 6.0846 | G15: 6.4089 | H15: 6.1794 | I15: 6.1119 | K15: （Car）
B16: 合計 | C16: 5.3325 | D16: 5.9316 | E16: 6.084 | F16: 5.9848 | G16: 6.3557 | H16: 5.9652 | I16: 6.0744 | K16: 合計
A18: RB+BL | B18: 通過台数_L | K18: 通過台数_L
A19: LB+BR | B19: 通過台数_R | K19: 通過台数_R
A20: LR+RL | B20: 通過台数_B | K20: 通過台数_B
B23: 500/500/500
C24: 1 | D24: 2 | E24: 3 | F24: 4 | G24: 5 | H24: 6 | I24: 7 | L24: pass_LT | M24: pass_LR | N24: pass_LB | O24: pass_TR | P24: pass_TB | Q24: pass_TL | R24: pass_RB | S24: pass_RL | T24: pass_RT | U24: pass_BL | V24: pass_BT | W24: pass_BR
C25: 全て受け入れ | D25: 道交法 | E25: 0.2 | F25: 0.4 | G25: 既存 | H25: 提案 | I25: 性能込み | L25: 3 | M25: 5 | N25: 4 | O25: 4 | P25: 0 | Q25: 8 | R25: 6 | S25: 3 | T25: 4 | U25: 5 | V25: 0 | W25: 6
B26: （Bus） | L26: 15 | M26: 6 | N26: 9 | O26: 12 | P26: 0 | Q26: 24 | R26: 8 | S26: 13 | T26: 13 | U26: 18 | V26: 0 | W26: 20
B27: （Car） | L27: pass_LT | M27: pass_LR | N27: pass_LB | O27: pass_TR | P27: pass_TB | Q27: pass_TL | R27: pass_RB | S27: pass_RL | T27: pass_RT | U27: pass_BL | V27: pass_BT | W27: pass_BR
B28: 右折 | L28: 4 | M28: 5 | N28: 4 | O28: 4 | P28: 0 | Q28: 8 | R28: 6 | S28: 3 | T28: 4 | U28: 5 | V28: 0 | W28: 6
B29: （Bus） | L29: 15 | M29: 6 | N29: 10 | O29: 12 | P29: 0 | Q29: 23 | R29: 8 | S29: 13 | T29: 13 | U29: 18 | V29: 0 | W29: 20
B30: （Car） | L30: pass_LT | M30: pass_LR | N30: pass_LB | O30: pass_TR | P30: pass_TB | Q30: pass_TL | R30: pass_RB | S30: pass_RL | T30: pass_RT | U30: pass_BL | V30: pass_BT | W30: pass_BR
B31: 左折 | L31: 4 | M31: 5 | N31: 4 | O31: 4 | P31: 0 | Q31: 8 | R31: 6 | S31: 3 | T31: 4 | U31: 5 | V31: 0 | W31: 6
B32: （Bus） | L32: 15 | M32: 6 | N32: 10 | O32: 13 | P32: 0 | Q32: 24 | R32: 8 | S32: 13 | T32: 13 | U32: 18 | V32: 0 | W32: 20
B33: （Car） | L33: pass_LT | M33: pass_LR | N33: pass_LB | O33: pass_TR | P33: pass_TB | Q33: pass_TL | R33: pass_RB | S33: pass_RL | T33: pass_RT | U33: pass_BL | V33: pass_BT | W33: pass_BR
B34: 直進 | L34: 5 | M34: 6 | N34: 4 | O34: 4 | P34: 0 | Q34: 8 | R34: 6 | S34: 3 | T34: 4 | U34: 5 | V34: 0 | W34: 6
B35: （Bus） | L35: 15 | M35: 6 | N35: 13 | O35: 13 | P35: 0 | Q35: 24 | R35: 8 | S35: 13 | T35: 13 | U35: 17 | V35: 0 | W35: 20
B36: （Car） | L36: pass_LT | M36: pass_LR | N36: pass_LB | O36: pass_TR | P36: pass_TB | Q36: pass_TL | R36: pass_RB | S36: pass_RL | T36: pass_RT | U36: pass_BL | V36: pass_BT | W36: pass_BR
B37: 合計 | L37: 5 | M37: 6 | N37: 4 | O37: 4 | P37: 0 | Q37: 8 | R37: 6 | S37: 3 | T37: 4 | U37: 5 | V37: 0 | W37: 6
L38: 15 | M38: 6 | N38: 10 | O38: 12 | P38: 0 | Q38: 24 | R38: 8 | S38: 13 | T38: 13 | U38: 17 | V38: 0 | W38: 20
B39: 通過台数_L | L39: pass_LT | M39: pass_LR | N39: pass_LB | O39: pass_TR | P39: pass_TB | Q39: pass_TL | R39: pass_RB | S39: pass_RL | T39: pass_RT | U39: pass_BL | V39: pass_BT | W39: pass_BR
B40: 通過台数_R | L40: 4 | M40: 6 | N40: 4 | O40: 4 | P40: 0 | Q40: 8 | R40: 6 | S40: 3 | T40: 4 | U40: 5 | V40: 0 | W40: 6
B41: 通過台数_B | L41: 15 | M41: 6 | N41: 10 | O41: 12 | P41: 0 | Q41: 24 | R41: 8 | S41: 13 | T41: 13 | U41: 17 | V41: 0 | W41: 20
L42: pass_LT | M42: pass_LR | N42: pass_LB | O42: pass_TR | P42: pass_TB | Q42: pass_TL | R42: pass_RB | S42: pass_RL | T42: pass_RT | U42: pass_BL | V42: pass_BT | W42: pass_BR
L43: 5 | M43: 6 | N43: 4 | O43: 4 | P43: 0 | Q43: 8 | R43: 6 | S43: 3 | T43: 4 | U43: 5 | V43: 0 | W43: 6
L44: 15 | M44: 6 | N44: 13 | O44: 12 | P44: 0 | Q44: 24 | R44: 8 | S44: 13 | T44: 12 | U44: 17 | V44: 0 | W44: 20

Sheet seed5
B2: 300/300/300/300 | K2: 600/600/600
C3: 1 | D3: 2 | E3: 3 | F3: 4 | G3: 5 | H3: 6 | I3: 7 | L3: 1 | M3: 2 | N3: 3 | O3: 4 | P3: 5 | Q3: 6 | R3: 7
C4: 全て受け入れ | D4: 道交法 | E4: 0.2 | F4: 0.4 | G4: 既存 | H4: 提案 | I4: 性能込み | L4: 全て受け入れ | M4: 道交法 | N4: 0.2 | O4: 0.4 | P4: 既存 | Q4: 提案 | R4: 性能込み
B5: （Bus） | C5: 3.2902 | D5: 2.6595 | E5: 2.6054 | F5: 4.4833 | G5: 3.6778 | H5: 4.6758 | I5: 4.7178 | K5: （Bus）
B6: （Car） | C6: 4.0269 | D6: 3.9165 | E6: 3.7144 | F6: 4.8153 | G6: 4.4324 | H6: 4.9424 | I6: 5.4119 | K6: （Car）
B7: 右折 | C7: 3.8574 | D7: 3.5809 | E7: 3.4343 | F7: 4.7463 | G7: 4.2608 | H7: 4.8871 | I7: 5.2575 | K7: 右折
B8: （Bus） | C8: 3.8746 | D8: 3.7368 | E8: 4.0189 | F8: 4.333 | G8: 3.9056 | H8: 4.5355 | I8: 4.6848 | K8: （Bus）
B9: （Car） | C9: 3.4487 | D9: 3.0795 | E9: 2.8287 | F9: 3.7554 | G9: 3.6406 | H9: 4.0946 | I9: 4.2612 | K9: （Car）
B10: 直進 | C10: 3.553 | D10: 3.2307 | E10: 3.0715 | F10: 3.8941 | G10: 3.7081 | H10: 4.2038 | I10: 4.3668 | K10: 直進
B11: （Bus） | C11: 3.8699 | D11: 5.4923 | E11: 6.6633 | F11: 5.7065 | G11: 4.0086 | H11: 5.0269 | I11: 5.83 | K11: （Bus）
B12: （Car） | C12: 2.7929 | D12: 2.5476 | E12: 2.3206 | F12: 4.337 | G12: 4.1867 | H12: 4.2132 | I12: 4.6623 | K12: （Car）
B13: 左折 | C13: 2.9247 | D13: 2.7868 | E13: 2.5748 | F13: 4.5111 | G13: 4.1577 | H13: 4.3253 | I13: 4.8231 | K13: 左折
B14: （Bus） | C14: 5.1509 | D14: 4.8359 | E14: 4.9806 | F14: 5.9999 | G14: 5.3599 | H14: 6.155 | I14: 6.2943 | K14: （Bus）
B15: （Car） | C15: 5.2512 | D15: 5.0142 | E15: 4.7498 | F15: 6.0829 | G15: 5.8724 | H15: 6.3162 | I15: 6.6377 | K15: （Car）
B16: 合計 | C16: 5.2283 | D16: 4.9733 | E16: 4.7987 | F16: 6.0641 | G16: 5.7515 | H16: 6.2794 | I16: 6.5574 | K16: 合計
A18: RB+BL | B18: 通過台数_L | K18: 通過台数_L
A19: LB+BR | B19: 通過台数_R | K19: 通過台数_R
A20: LR+RL | B20: 通過台数_B | K20: 通過台数_B
B23: 500/500/500
C24: 1 | D24: 2 | E24: 3 | F24: 4 | G24: 5 | H24: 6 | I24: 7 | L24: pass_LT | M24: pass_LR | N24: pass_LB | O24: pass_TR | P24: pass_TB | Q24: pass_TL | R24: pass_RB | S24: pass_RL | T24: pass_RT | U24: pass_BL | V24: pass_BT | W24: pass_BR
C25: 全て受け入れ | D25: 道交法 | E25: 0.2 | F25: 0.4 | G25: 既存 | H25: 提案 | I25: 性能込み | L25: 1 | M25: 1 | N25: 6 | O25: 6 | P25: 0 | Q25: 1 | R25: 10 | S25: 2 | T25: 1 | U25: 7 | V25: 0 | W25: 5
B26: （Bus） | L26: 16 | M26: 7 | N26: 8 | O26: 20 | P26: 0 | Q26: 20 | R26: 14 | S26: 9 | T26: 13 | U26: 18 | V26: 0 | W26: 16
B27: （Car） | L27: pass_LT | M27: pass_LR | N27: pass_LB | O27: pass_TR | P27: pass_TB | Q27: pass_TL | R27: pass_RB | S27: pass_RL | T27: pass_RT | U27: pass_BL | V27: pass_BT | W27: pass_BR
B28: 右折 | L28: 1 | M28: 1 | N28: 6 | O28: 5 | P28: 0 | Q28: 1 | R28: 10 | S28: 2 | T28: 1 | U28: 7 | V28: 0 | W28: 6
B29: （Bus） | L29: 15 | M29: 7 | N29: 8 | O29: 19 | P29: 0 | Q29: 19 | R29: 14 | S29: 9 | T29: 13 | U29: 19 | V29: 0 | W29: 17
B30: （Car） | L30: pass_LT | M30: pass_LR | N30: pass_LB | O30: pass_TR | P30: pass_TB | Q30: pass_TL | R30: pass_RB | S30: pass_RL | T30: pass_RT | U30: pass_BL | V30: pass_BT | W30: pass_BR
B31: 左折 | L31: 0 | M31: 1 | N31: 5 | O31: 5 | P31: 0 | Q31: 1 | R31: 10 | S31: 2 | T31: 1 | U31: 7 | V31: 0 | W31: 6
B32: （Bus） | L32: 13 | M32: 7 | N32: 7 | O32: 19 | P32: 0 | Q32: 19 | R32: 14 | S32: 9 | T32: 13 | U32: 19 | V32: 0 | W32: 17
B33: （Car） | L33: pass_LT | M33: pass_LR | N33: pass_LB | O33: pass_TR | P33: pass_TB | Q33: pass_TL | R33: pass_RB | S33: pass_RL | T33: pass_RT | U33: pass_BL | V33: pass_BT | W33: pass_BR
B34: 直進 | L34: 1 | M34: 1 | N34: 6 | O34: 6 | P34: 0 | Q34: 1 | R34: 10 | S34: 2 | T34: 1 | U34: 7 | V34: 0 | W34: 5
B35: （Bus） | L35: 16 | M35: 7 | N35: 9 | O35: 20 | P35: 0 | Q35: 20 | R35: 14 | S35: 9 | T35: 13 | U35: 19 | V35: 0 | W35: 17
B36: （Car） | L36: pass_LT | M36: pass_LR | N36: pass_LB | O36: pass_TR | P36: pass_TB | Q36: pass_TL | R36: pass_RB | S36: pass_RL | T36: pass_RT | U36: pass_BL | V36: pass_BT | W36: pass_BR
B37: 合計 | L37: 1 | M37: 1 | N37: 5 | O37: 6 | P37: 0 | Q37: 1 | R37: 10 | S37: 2 | T37: 1 | U37: 7 | V37: 0 | W37: 5
L38: 14 | M38: 7 | N38: 8 | O38: 20 | P38: 0 | Q38: 20 | R38: 14 | S38: 9 | T38: 13 | U38: 19 | V38: 0 | W38: 17
A39: RB+BL | B39: 通過台数_L | L39: pass_LT | M39: pass_LR | N39: pass_LB | O39: pass_TR | P39: pass_TB | Q39: pass_TL | R39: pass_RB | S39: pass_RL | T39: pass_RT | U39: pass_BL | V39: pass_BT | W39: pass_BR
A40: LB+BR | B40: 通過台数_R | L40: 1 | M40: 1 | N40: 6 | O40: 6 | P40: 0 | Q40: 1 | R40: 10 | S40: 2 | T40: 1 | U40: 7 | V40: 0 | W40: 6
A41: LR+RL | B41: 通過台数_B | L41: 16 | M41: 7 | N41: 8 | O41: 19 | P41: 0 | Q41: 20 | R41: 14 | S41: 9 | T41: 13 | U41: 19 | V41: 0 | W41: 17
L42: pass_LT | M42: pass_LR | N42: pass_LB | O42: pass_TR | P42: pass_TB | Q42: pass_TL | R42: pass_RB | S42: pass_RL | T42: pass_RT | U42: pass_BL | V42: pass_BT | W42: pass_BR
L43: 2 | M43: 1 | N43: 6 | O43: 6 | P43: 0 | Q43: 1 | R43: 10 | S43: 2 | T43: 1 | U43: 7 | V43: 0 | W43: 6
L44: 17 | M44: 8 | N44: 9 | O44: 20 | P44: 0 | Q44: 20 | R44: 14 | S44: 9 | T44: 13 | U44: 19 | V44: 0 | W44: 17

Sheet 平均
B2: 300/300/300/300 | K2: 600/600/600
C3: 1 | D3: 2 | E3: 3 | F3: 4 | G3: 5 | H3: 6 | I3: 7 | L3: 1 | M3: 2 | N3: 3 | O3: 4 | P3: 5 | Q3: 6 | R3: 7
C4: 全て受け入れ | D4: 道交法 | E4: 0.2 | F4: 0.4 | G4: 既存 | H4: 提案 | I4: 性能込み | L4: 全て受け入れ | M4: 道交法 | N4: 0.2 | O4: 0.4 | P4: 既存 | Q4: 提案 | R4: 性能込み
B5: （Bus） | C5: =ROUND(AVERAGE(seed1!C5,seed2!C5,seed3!C5,seed4!C5,seed5!C5),4) -> 3.7774 | D5: =ROUND(AVERAGE(seed1!D5,seed2!D5,seed3!D5,seed4!D5,seed5!D5),4) -> 3.8573 | E5: =ROUND(AVERAGE(seed1!E5,seed2!E5,seed3!E5,seed4!E5,seed5!E5),4) -> 3.9369 | F5: =ROUND(AVERAGE(seed1!F5,seed2!F5,seed3!F5,seed4!F5,seed5!F5),4) -> 4.0382 | G5: =ROUND(AVERAGE(seed1!G5,seed2!G5,seed3!G5,seed4!G5,seed5!G5),4) -> 4.3137 | H5: =ROUND(AVERAGE(seed1!H5,seed2!H5,seed3!H5,seed4!H5,seed5!H5),4) -> 4.7612 | I5: =ROUND(AVERAGE(seed1!I5,seed2!I5,seed3!I5,seed4!I5,seed5!I5),4) -> 4.7656 | K5: （Bus） | L5: =ROUND(AVERAGE(seed1!L5,seed2!L5,seed3!L5,seed4!L5,seed5!L5),4) -> #DIV/0! | M5: =ROUND(AVERAGE(seed1!M5,seed2!M5,seed3!M5,seed4!M5,seed5!M5),4) -> #DIV/0! | N5: =ROUND(AVERAGE(seed1!N5,seed2!N5,seed3!N5,seed4!N5,seed5!N5),4) -> #DIV/0! | O5: =ROUND(AVERAGE(seed1!O5,seed2!O5,seed3!O5,seed4!O5,seed5!O5),4) -> #DIV/0! | P5: =ROUND(AVERAGE(seed1!P5,seed2!P5,seed3!P5,seed4!P5,seed5!P5),4) -> #DIV/0! | Q5: =ROUND(AVERAGE(seed1!Q5,seed2!Q5,seed3!Q5,seed4!Q5,seed5!Q5),4) -> #DIV/0! | R5: =ROUND(AVERAGE(seed1!R5,seed2!R5,seed3!R5,seed4!R5,seed5!R5),4) -> #DIV/0!
B6: （Car） | C6: =ROUND(AVERAGE(seed1!C6,seed2!C6,seed3!C6,seed4!C6,seed5!C6),4) -> 4.3111 | D6: =ROUND(AVERAGE(seed1!D6,seed2!D6,seed3!D6,seed4!D6,seed5!D6),4) -> 4.3402 | E6: =ROUND(AVERAGE(seed1!E6,seed2!E6,seed3!E6,seed4!E6,seed5!E6),4) -> 4.4118 | F6: =ROUND(AVERAGE(seed1!F6,seed2!F6,seed3!F6,seed4!F6,seed5!F6),4) -> 4.5076 | G6: =ROUND(AVERAGE(seed1!G6,seed2!G6,seed3!G6,seed4!G6,seed5!G6),4) -> 4.5886 | H6: =ROUND(AVERAGE(seed1!H6,seed2!H6,seed3!H6,seed4!H6,seed5!H6),4) -> 5.0494 | I6: =ROUND(AVERAGE(seed1!I6,seed2!I6,seed3!I6,seed4!I6,seed5!I6),4) -> 5.2138 | K6: （Car） | L6: =ROUND(AVERAGE(seed1!L6,seed2!L6,seed3!L6,seed4!L6,seed5!L6),4) -> #DIV/0! | M6: =ROUND(AVERAGE(seed1!M6,seed2!M6,seed3!M6,seed4!M6,seed5!M6),4) -> #DIV/0! | N6: =ROUND(AVERAGE(seed1!N6,seed2!N6,seed3!N6,seed4!N6,seed5!N6),4) -> #DIV/0! | O6: =ROUND(AVERAGE(seed1!O6,seed2!O6,seed3!O6,seed4!O6,seed5!O6),4) -> #DIV/0! | P6: =ROUND(AVERAGE(seed1!P6,seed2!P6,seed3!P6,seed4!P6,seed5!P6),4) -> #DIV/0! | Q6: =ROUND(AVERAGE(seed1!Q6,seed2!Q6,seed3!Q6,seed4!Q6,seed5!Q6),4) -> #DIV/0! | R6: =ROUND(AVERAGE(seed1!R6,seed2!R6,seed3!R6,seed4!R6,seed5!R6),4) -> #DIV/0!
B7: 右折 | C7: =ROUND(AVERAGE(seed1!C7,seed2!C7,seed3!C7,seed4!C7,seed5!C7),4) -> 4.1645 | D7: =ROUND(AVERAGE(seed1!D7,seed2!D7,seed3!D7,seed4!D7,seed5!D7),4) -> 4.2036 | E7: =ROUND(AVERAGE(seed1!E7,seed2!E7,seed3!E7,seed4!E7,seed5!E7),4) -> 4.2726 | F7: =ROUND(AVERAGE(seed1!F7,seed2!F7,seed3!F7,seed4!F7,seed5!F7),4) -> 4.3516 | G7: =ROUND(AVERAGE(seed1!G7,seed2!G7,seed3!G7,seed4!G7,seed5!G7),4) -> 4.5217 | H7: =ROUND(AVERAGE(seed1!H7,seed2!H7,seed3!H7,seed4!H7,seed5!H7),4) -> 4.9683 | I7: =ROUND(AVERAGE(seed1!I7,seed2!I7,seed3!I7,seed4!I7,seed5!I7),4) -> 5.082 | K7: 右折 | L7: =ROUND(AVERAGE(seed1!L7,seed2!L7,seed3!L7,seed4!L7,seed5!L7),4) -> #DIV/0! | M7: =ROUND(AVERAGE(seed1!M7,seed2!M7,seed3!M7,seed4!M7,seed5!M7),4) -> #DIV/0! | N7: =ROUND(AVERAGE(seed1!N7,seed2!N7,seed3!N7,seed4!N7,seed5!N7),4) -> #DIV/0! | O7: =ROUND(AVERAGE(seed1!O7,seed2!O7,seed3!O7,seed4!O7,seed5!O7),4) -> #DIV/0! | P7: =ROUND(AVERAGE(seed1!P7,seed2!P7,seed3!P7,seed4!P7,seed5!P7),4) -> #DIV/0! | Q7: =ROUND(AVERAGE(seed1!Q7,seed2!Q7,seed3!Q7,seed4!Q7,seed5!Q7),4) -> #DIV/0! | R7: =ROUND(AVERAGE(seed1!R7,seed2!R7,seed3!R7,seed4!R7,seed5!R7),4) -> #DIV/0!
B8: （Bus） | C8: =ROUND(AVERAGE(seed1!C8,seed2!C8,seed3!C8,seed4!C8,seed5!C8),4) -> 3.0881 | D8: =ROUND(AVERAGE(seed1!D8,seed2!D8,seed3!D8,seed4!D8,seed5!D8),4) -> 3.3384 | E8: =ROUND(AVERAGE(seed1!E8,seed2!E8,seed3!E8,seed4!E8,seed5!E8),4) -> 3.4178 | F8: =ROUND(AVERAGE(seed1!F8,seed2!F8,seed3!F8,seed4!F8,seed5!F8),4) -> 3.3385 | G8: =ROUND(AVERAGE(seed1!G8,seed2!G8,seed3!G8,seed4!G8,seed5!G8),4) -> 3.632 | H8: =ROUND(AVERAGE(seed1!H8,seed2!H8,seed3!H8,seed4!H8,seed5!H8),4) -> 3.9594 | I8: =ROUND(AVERAGE(seed1!I8,seed2!I8,seed3!I8,seed4!I8,seed5!I8),4) -> 4.0567 | K8: （Bus） | L8: =ROUND(AVERAGE(seed1!L8,seed2!L8,seed3!L8,seed4!L8,seed5!L8),4) -> #DIV/0! | M8: =ROUND(AVERAGE(seed1!M8,seed2!M8,seed3!M8,seed4!M8,seed5!M8),4) -> #DIV/0! | N8: =ROUND(AVERAGE(seed1!N8,seed2!N8,seed3!N8,seed4!N8,seed5!N8),4) -> #DIV/0! | O8: =ROUND(AVERAGE(seed1!O8,seed2!O8,seed3!O8,seed4!O8,seed5!O8),4) -> #DIV/0! | P8: =ROUND(AVERAGE(seed1!P8,seed2!P8,seed3!P8,seed4!P8,seed5!P8),4) -> #DIV/0! | Q8: =ROUND(AVERAGE(seed1!Q8,seed2!Q8,seed3!Q8,seed4!Q8,seed5!Q8),4) -> #DIV/0! | R8: =ROUND(AVERAGE(seed1!R8,seed2!R8,seed3!R8,seed4!R8,seed5!R8),4) -> #DIV/0!
B9: （Car） | C9: =ROUND(AVERAGE(seed1!C9,seed2!C9,seed3!C9,seed4!C9,seed5!C9),4) -> 3.6063 | D9: =ROUND(AVERAGE(seed1!D9,seed2!D9,seed3!D9,seed4!D9,seed5!D9),4) -> 3.5552 | E9: =ROUND(AVERAGE(seed1!E9,seed2!E9,seed3!E9,seed4!E9,seed5!E9),4) -> 3.6622 | F9: =ROUND(AVERAGE(seed1!F9,seed2!F9,seed3!F9,seed4!F9,seed5!F9),4) -> 3.4841 | G9: =ROUND(AVERAGE(seed1!G9,seed2!G9,seed3!G9,seed4!G9,seed5!G9),4) -> 3.9009 | H9: =ROUND(AVERAGE(seed1!H9,seed2!H9,seed3!H9,seed4!H9,seed5!H9),4) -> 4.0312 | I9: =ROUND(AVERAGE(seed1!I9,seed2!I9,seed3!I9,seed4!I9,seed5!I9),4) -> 4.2214 | K9: （Car） | L9: =ROUND(AVERAGE(seed1!L9,seed2!L9,seed3!L9,seed4!L9,seed5!L9),4) -> #DIV/0! | M9: =ROUND(AVERAGE(seed1!M9,seed2!M9,seed3!M9,seed4!M9,seed5!M9),4) -> #DIV/0! | N9: =ROUND(AVERAGE(seed1!N9,seed2!N9,seed3!N9,seed4!N9,seed5!N9),4) -> #DIV/0! | O9: =ROUND(AVERAGE(seed1!O9,seed2!O9,seed3!O9,seed4!O9,seed5!O9),4) -> #DIV/0! | P9: =ROUND(AVERAGE(seed1!P9,seed2!P9,seed3!P9,seed4!P9,seed5!P9),4) -> #DIV/0! | Q9: =ROUND(AVERAGE(seed1!Q9,seed2!Q9,seed3!Q9,seed4!Q9,seed5!Q9),4) -> #DIV/0! | R9: =ROUND(AVERAGE(seed1!R9,seed2!R9,seed3!R9,seed4!R9,seed5!R9),4) -> #DIV/0!
B10: 直進 | C10: =ROUND(AVERAGE(seed1!C10,seed2!C10,seed3!C10,seed4!C10,seed5!C10),4) -> 3.4247 | D10: =ROUND(AVERAGE(seed1!D10,seed2!D10,seed3!D10,seed4!D10,seed5!D10),4) -> 3.482 | E10: =ROUND(AVERAGE(seed1!E10,seed2!E10,seed3!E10,seed4!E10,seed5!E10),4) -> 3.5615 | F10: =ROUND(AVERAGE(seed1!F10,seed2!F10,seed3!F10,seed4!F10,seed5!F10),4) -> 3.4239 | G10: =ROUND(AVERAGE(seed1!G10,seed2!G10,seed3!G10,seed4!G10,seed5!G10),4) -> 3.8178 | H10: =ROUND(AVERAGE(seed1!H10,seed2!H10,seed3!H10,seed4!H10,seed5!H10),4) -> 4.0076 | I10: =ROUND(AVERAGE(seed1!I10,seed2!I10,seed3!I10,seed4!I10,seed5!I10),4) -> 4.1677 | K10: 直進 | L10: =ROUND(AVERAGE(seed1!L10,seed2!L10,seed3!L10,seed4!L10,seed5!L10),4) -> #DIV/0! | M10: =ROUND(AVERAGE(seed1!M10,seed2!M10,seed3!M10,seed4!M10,seed5!M10),4) -> #DIV/0! | N10: =ROUND(AVERAGE(seed1!N10,seed2!N10,seed3!N10,seed4!N10,seed5!N10),4) -> #DIV/0! | O10: =ROUND(AVERAGE(seed1!O10,seed2!O10,seed3!O10,seed4!O10,seed5!O10),4) -> #DIV/0! | P10: =ROUND(AVERAGE(seed1!P10,seed2!P10,seed3!P10,seed4!P10,seed5!P10),4) -> #DIV/0! | Q10: =ROUND(AVERAGE(seed1!Q10,seed2!Q10,seed3!Q10,seed4!Q10,seed5!Q10),4) -> #DIV/0! | R10: =ROUND(AVERAGE(seed1!R10,seed2!R10,seed3!R10,seed4!R10,seed5!R10),4) -> #DIV/0!
B11: （Bus） | C11: =ROUND(AVERAGE(seed1!C11,seed2!C11,seed3!C11,seed4!C11,seed5!C11),4) -> 2.9207 | D11: =ROUND(AVERAGE(seed1!D11,seed2!D11,seed3!D11,seed4!D11,seed5!D11),4) -> 4.6243 | E11: =ROUND(AVERAGE(seed1!E11,seed2!E11,seed3!E11,seed4!E11,seed5!E11),4) -> 3.9761 | F11: =ROUND(AVERAGE(seed1!F11,seed2!F11,seed3!F11,seed4!F11,seed5!F11),4) -> 3.3906 | G11: =ROUND(AVERAGE(seed1!G11,seed2!G11,seed3!G11,seed4!G11,seed5!G11),4) -> 3.5503 | H11: =ROUND(AVERAGE(seed1!H11,seed2!H11,seed3!H11,seed4!H11,seed5!H11),4) -> 4.063 | I11: =ROUND(AVERAGE(seed1!I11,seed2!I11,seed3!I11,seed4!I11,seed5!I11),4) -> 5.1458 | K11: （Bus） | L11: =ROUND(AVERAGE(seed1!L11,seed2!L11,seed3!L11,seed4!L11,seed5!L11),4) -> #DIV/0! | M11: =ROUND(AVERAGE(seed1!M11,seed2!M11,seed3!M11,seed4!M11,seed5!M11),4) -> #DIV/0! | N11: =ROUND(AVERAGE(seed1!N11,seed2!N11,seed3!N11,seed4!N11,seed5!N11),4) -> #DIV/0! | O11: =ROUND(AVERAGE(seed1!O11,seed2!O11,seed3!O11,seed4!O11,seed5!O11),4) -> #DIV/0! | P11: =ROUND(AVERAGE(seed1!P11,seed2!P11,seed3!P11,seed4!P11,seed5!P11),4) -> #DIV/0! | Q11: =ROUND(AVERAGE(seed1!Q11,seed2!Q11,seed3!Q11,seed4!Q11,seed5!Q11),4) -> #DIV/0! | R11: =ROUND(AVERAGE(seed1!R11,seed2!R11,seed3!R11,seed4!R11,seed5!R11),4) -> #DIV/0!
B12: （Car） | C12: =ROUND(AVERAGE(seed1!C12,seed2!C12,seed3!C12,seed4!C12,seed5!C12),4) -> 3.1272 | D12: =ROUND(AVERAGE(seed1!D12,seed2!D12,seed3!D12,seed4!D12,seed5!D12),4) -> 4.8331 | E12: =ROUND(AVERAGE(seed1!E12,seed2!E12,seed3!E12,seed4!E12,seed5!E12),4) -> 3.8224 | F12: =ROUND(AVERAGE(seed1!F12,seed2!F12,seed3!F12,seed4!F12,seed5!F12),4) -> 3.4439 | G12: =ROUND(AVERAGE(seed1!G12,seed2!G12,seed3!G12,seed4!G12,seed5!G12),4) -> 3.943 | H12: =ROUND(AVERAGE(seed1!H12,seed2!H12,seed3!H12,seed4!H12,seed5!H12),4) -> 4.8278 | I12: =ROUND(AVERAGE(seed1!I12,seed2!I12,seed3!I12,seed4!I12,seed5!I12),4) -> 5.0407 | K12: （Car） | L12: =ROUND(AVERAGE(seed1!L12,seed2!L12,seed3!L12,seed4!L12,seed5!L12),4) -> #DIV/0! | M12: =ROUND(AVERAGE(seed1!M12,seed2!M12,seed3!M12,seed4!M12,seed5!M12),4) -> #DIV/0! | N12: =ROUND(AVERAGE(seed1!N12,seed2!N12,seed3!N12,seed4!N12,seed5!N12),4) -> #DIV/0! | O12: =ROUND(AVERAGE(seed1!O12,seed2!O12,seed3!O12,seed4!O12,seed5!O12),4) -> #DIV/0! | P12: =ROUND(AVERAGE(seed1!P12,seed2!P12,seed3!P12,seed4!P12,seed5!P12),4) -> #DIV/0! | Q12: =ROUND(AVERAGE(seed1!Q12,seed2!Q12,seed3!Q12,seed4!Q12,seed5!Q12),4) -> #DIV/0! | R12: =ROUND(AVERAGE(seed1!R12,seed2!R12,seed3!R12,seed4!R12,seed5!R12),4) -> #DIV/0!
B13: 左折 | C13: =ROUND(AVERAGE(seed1!C13,seed2!C13,seed3!C13,seed4!C13,seed5!C13),4) -> 3.012 | D13: =ROUND(AVERAGE(seed1!D13,seed2!D13,seed3!D13,seed4!D13,seed5!D13),4) -> 4.5023 | E13: =ROUND(AVERAGE(seed1!E13,seed2!E13,seed3!E13,seed4!E13,seed5!E13),4) -> 3.5021 | F13: =ROUND(AVERAGE(seed1!F13,seed2!F13,seed3!F13,seed4!F13,seed5!F13),4) -> 3.3581 | G13: =ROUND(AVERAGE(seed1!G13,seed2!G13,seed3!G13,seed4!G13,seed5!G13),4) -> 3.8425 | H13: =ROUND(AVERAGE(seed1!H13,seed2!H13,seed3!H13,seed4!H13,seed5!H13),4) -> 4.5697 | I13: =ROUND(AVERAGE(seed1!I13,seed2!I13,seed3!I13,seed4!I13,seed5!I13),4) -> 5.0461 | K13: 左折 | L13: =ROUND(AVERAGE(seed1!L13,seed2!L13,seed3!L13,seed4!L13,seed5!L13),4) -> #DIV/0! | M13: =ROUND(AVERAGE(seed1!M13,seed2!M13,seed3!M13,seed4!M13,seed5!M13),4) -> #DIV/0! | N13: =ROUND(AVERAGE(seed1!N13,seed2!N13,seed3!N13,seed4!N13,seed5!N13),4) -> #DIV/0! | O13: =ROUND(AVERAGE(seed1!O13,seed2!O13,seed3!O13,seed4!O13,seed5!O13),4) -> #DIV/0! | P13: =ROUND(AVERAGE(seed1!P13,seed2!P13,seed3!P13,seed4!P13,seed5!P13),4) -> #DIV/0! | Q13: =ROUND(AVERAGE(seed1!Q13,seed2!Q13,seed3!Q13,seed4!Q13,seed5!Q13),4) -> #DIV/0! | R13: =ROUND(AVERAGE(seed1!R13,seed2!R13,seed3!R13,seed4!R13,seed5!R13),4) -> #DIV/0!
B14: （Bus） | C14: =ROUND(AVERAGE(seed1!C14,seed2!C14,seed3!C14,seed4!C14,seed5!C14),4) -> 4.8004 | D14: =ROUND(AVERAGE(seed1!D14,seed2!D14,seed3!D14,seed4!D14,seed5!D14),4) -> 5.1488 | E14: =ROUND(AVERAGE(seed1!E14,seed2!E14,seed3!E14,seed4!E14,seed5!E14),4) -> 5.1105 | F14: =ROUND(AVERAGE(seed1!F14,seed2!F14,seed3!F14,seed4!F14,seed5!F14),4) -> 5.0841 | G14: =ROUND(AVERAGE(seed1!G14,seed2!G14,seed3!G14,seed4!G14,seed5!G14),4) -> 5.4449 | H14: =ROUND(AVERAGE(seed1!H14,seed2!H14,seed3!H14,seed4!H14,seed5!H14),4) -> 5.8465 | I14: =ROUND(AVERAGE(seed1!I14,seed2!I14,seed3!I14,seed4!I14,seed5!I14),4) -> 6.027 | K14: （Bus） | L14: =ROUND(AVERAGE(seed1!L14,seed2!L14,seed3!L14,seed4!L14,seed5!L14),4) -> #DIV/0! | M14: =ROUND(AVERAGE(seed1!M14,seed2!M14,seed3!M14,seed4!M14,seed5!M14),4) -> #DIV/0! | N14: =ROUND(AVERAGE(seed1!N14,seed2!N14,seed3!N14,seed4!N14,seed5!N14),4) -> #DIV/0! | O14: =ROUND(AVERAGE(seed1!O14,seed2!O14,seed3!O14,seed4!O14,seed5!O14),4) -> #DIV/0! | P14: =ROUND(AVERAGE(seed1!P14,seed2!P14,seed3!P14,seed4!P14,seed5!P14),4) -> #DIV/0! | Q14: =ROUND(AVERAGE(seed1!Q14,seed2!Q14,seed3!Q14,seed4!Q14,seed5!Q14),4) -> #DIV/0! | R14: =ROUND(AVERAGE(seed1!R14,seed2!R14,seed3!R14,seed4!R14,seed5!R14),4) -> #DIV/0!
B15: （Car） | C15: =ROUND(AVERAGE(seed1!C15,seed2!C15,seed3!C15,seed4!C15,seed5!C15),4) -> 5.515 | D15: =ROUND(AVERAGE(seed1!D15,seed2!D15,seed3!D15,seed4!D15,seed5!D15),4) -> 5.8189 | E15: =ROUND(AVERAGE(seed1!E15,seed2!E15,seed3!E15,seed4!E15,seed5!E15),4) -> 5.7464 | F15: =ROUND(AVERAGE(seed1!F15,seed2!F15,seed3!F15,seed4!F15,seed5!F15),4) -> 5.6159 | G15: =ROUND(AVERAGE(seed1!G15,seed2!G15,seed3!G15,seed4!G15,seed5!G15),4) -> 6.0234 | H15: =ROUND(AVERAGE(seed1!H15,seed2!H15,seed3!H15,seed4!H15,seed5!H15),4) -> 6.4493 | I15: =ROUND(AVERAGE(seed1!I15,seed2!I15,seed3!I15,seed4!I15,seed5!I15),4) -> 6.6047 | K15: （Car） | L15: =ROUND(AVERAGE(seed1!L15,seed2!L15,seed3!L15,seed4!L15,seed5!L15),4) -> #DIV/0! | M15: =ROUND(AVERAGE(seed1!M15,seed2!M15,seed3!M15,seed4!M15,seed5!M15),4) -> #DIV/0! | N15: =ROUND(AVERAGE(seed1!N15,seed2!N15,seed3!N15,seed4!N15,seed5!N15),4) -> #DIV/0! | O15: =ROUND(AVERAGE(seed1!O15,seed2!O15,seed3!O15,seed4!O15,seed5!O15),4) -> #DIV/0! | P15: =ROUND(AVERAGE(seed1!P15,seed2!P15,seed3!P15,seed4!P15,seed5!P15),4) -> #DIV/0! | Q15: =ROUND(AVERAGE(seed1!Q15,seed2!Q15,seed3!Q15,seed4!Q15,seed5!Q15),4) -> #DIV/0! | R15: =ROUND(AVERAGE(seed1!R15,seed2!R15,seed3!R15,seed4!R15,seed5!R15),4) -> #DIV/0! | T15: =(I16-G16)*2/(G16+I16) -> 0.094244242
B16: 合計 | C16: =ROUND(AVERAGE(seed1!C16,seed2!C16,seed3!C16,seed4!C16,seed5!C16),4) -> 5.3037 | D16: =ROUND(AVERAGE(seed1!D16,seed2!D16,seed3!D16,seed4!D16,seed5!D16),4) -> 5.6246 | E16: =ROUND(AVERAGE(seed1!E16,seed2!E16,seed3!E16,seed4!E16,seed5!E16),4) -> 5.5534 | F16: =ROUND(AVERAGE(seed1!F16,seed2!F16,seed3!F16,seed4!F16,seed5!F16),4) -> 5.4631 | G16: =ROUND(AVERAGE(seed1!G16,seed2!G16,seed3!G16,seed4!G16,seed5!G16),4) -> 5.8622 | H16: =ROUND(AVERAGE(seed1!H16,seed2!H16,seed3!H16,seed4!H16,seed5!H16),4) -> 6.2789 | I16: =ROUND(AVERAGE(seed1!I16,seed2!I16,seed3!I16,seed4!I16,seed5!I16),4) -> 6.442 | K16: 合計 | L16: =ROUND(AVERAGE(seed1!L16,seed2!L16,seed3!L16,seed4!L16,seed5!L16),4) -> #DIV/0! | M16: =ROUND(AVERAGE(seed1!M16,seed2!M16,seed3!M16,seed4!M16,seed5!M16),4) -> #DIV/0! | N16: =ROUND(AVERAGE(seed1!N16,seed2!N16,seed3!N16,seed4!N16,seed5!N16),4) -> #DIV/0! | O16: =ROUND(AVERAGE(seed1!O16,seed2!O16,seed3!O16,seed4!O16,seed5!O16),4) -> #DIV/0! | P16: =ROUND(AVERAGE(seed1!P16,seed2!P16,seed3!P16,seed4!P16,seed5!P16),4) -> #DIV/0! | Q16: =ROUND(AVERAGE(seed1!Q16,seed2!Q16,seed3!Q16,seed4!Q16,seed5!Q16),4) -> #DIV/0! | R16: =ROUND(AVERAGE(seed1!R16,seed2!R16,seed3!R16,seed4!R16,seed5!R16),4) -> #DIV/0! | T16: =(H16-G16)*2/(G16+H16) -> 0.068642874
B17: 交差点前_平均 | C17: =ROUND(AVERAGE(C7,C10,C13),4) -> 3.5337 | D17: =ROUND(AVERAGE(D7,D10,D13),4) -> 4.0626 | E17: =ROUND(AVERAGE(E7,E10,E13),4) -> 3.7787 | F17: =ROUND(AVERAGE(F7,F10,F13),4) -> 3.7112 | G17: =ROUND(AVERAGE(G7,G10,G13),4) -> 4.0607 | H17: =ROUND(AVERAGE(H7,H10,H13),4) -> 4.5152 | I17: =ROUND(AVERAGE(I7,I10,I13),4) -> 4.7653 | K17: 交差点前_平均 | L17: =ROUND(AVERAGE(L7,L10,L13),4) -> #DIV/0! | M17: =ROUND(AVERAGE(M7,M10,M13),4) -> #DIV/0! | N17: =ROUND(AVERAGE(N7,N10,N13),4) -> #DIV/0! | O17: =ROUND(AVERAGE(O7,O10,O13),4) -> #DIV/0! | P17: =ROUND(AVERAGE(P7,P10,P13),4) -> #DIV/0! | Q17: =ROUND(AVERAGE(Q7,Q10,Q13),4) -> #DIV/0! | R17: =ROUND(AVERAGE(R7,R10,R13),4) -> #DIV/0!
B18: 通過台数_L | C18: =ROUND(AVERAGE(seed1!C18,seed2!C18,seed3!C18,seed4!C18,seed5!C18),1) -> #DIV/0! | D18: =ROUND(AVERAGE(seed1!D18,seed2!D18,seed3!D18,seed4!D18,seed5!D18),1) -> #DIV/0! | E18: =ROUND(AVERAGE(seed1!E18,seed2!E18,seed3!E18,seed4!E18,seed5!E18),1) -> #DIV/0! | F18: =ROUND(AVERAGE(seed1!F18,seed2!F18,seed3!F18,seed4!F18,seed5!F18),1) -> #DIV/0! | G18: =ROUND(AVERAGE(seed1!G18,seed2!G18,seed3!G18,seed4!G18,seed5!G18),1) -> #DIV/0! | H18: =ROUND(AVERAGE(seed1!H18,seed2!H18,seed3!H18,seed4!H18,seed5!H18),1) -> #DIV/0! | I18: =ROUND(AVERAGE(seed1!I18,seed2!I18,seed3!I18,seed4!I18,seed5!I18),1) -> #DIV/0! | K18: 通過台数_L | L18: =ROUND(AVERAGE(seed1!L18,seed2!L18,seed3!L18,seed4!L18,seed5!L18),1) -> #DIV/0! | M18: =ROUND(AVERAGE(seed1!M18,seed2!M18,seed3!M18,seed4!M18,seed5!M18),1) -> #DIV/0! | N18: =ROUND(AVERAGE(seed1!N18,seed2!N18,seed3!N18,seed4!N18,seed5!N18),1) -> #DIV/0! | O18: =ROUND(AVERAGE(seed1!O18,seed2!O18,seed3!O18,seed4!O18,seed5!O18),1) -> #DIV/0! | P18: =ROUND(AVERAGE(seed1!P18,seed2!P18,seed3!P18,seed4!P18,seed5!P18),1) -> #DIV/0! | Q18: =ROUND(AVERAGE(seed1!Q18,seed2!Q18,seed3!Q18,seed4!Q18,seed5!Q18),1) -> #DIV/0! | R18: =ROUND(AVERAGE(seed1!R18,seed2!R18,seed3!R18,seed4!R18,seed5!R18),1) -> #DIV/0!
B19: 通過台数_R | C19: =ROUND(AVERAGE(seed1!C19,seed2!C19,seed3!C19,seed4!C19,seed5!C19),1) -> #DIV/0! | D19: =ROUND(AVERAGE(seed1!D19,seed2!D19,seed3!D19,seed4!D19,seed5!D19),1) -> #DIV/0! | E19: =ROUND(AVERAGE(seed1!E19,seed2!E19,seed3!E19,seed4!E19,seed5!E19),1) -> #DIV/0! | F19: =ROUND(AVERAGE(seed1!F19,seed2!F19,seed3!F19,seed4!F19,seed5!F19),1) -> #DIV/0! | G19: =ROUND(AVERAGE(seed1!G19,seed2!G19,seed3!G19,seed4!G19,seed5!G19),1) -> #DIV/0! | H19: =ROUND(AVERAGE(seed1!H19,seed2!H19,seed3!H19,seed4!H19,seed5!H19),1) -> #DIV/0! | I19: =ROUND(AVERAGE(seed1!I19,seed2!I19,seed3!I19,seed4!I19,seed5!I19),1) -> #DIV/0! | K19: 通過台数_R | L19: =ROUND(AVERAGE(seed1!L19,seed2!L19,seed3!L19,seed4!L19,seed5!L19),1) -> #DIV/0! | M19: =ROUND(AVERAGE(seed1!M19,seed2!M19,seed3!M19,seed4!M19,seed5!M19),1) -> #DIV/0! | N19: =ROUND(AVERAGE(seed1!N19,seed2!N19,seed3!N19,seed4!N19,seed5!N19),1) -> #DIV/0! | O19: =ROUND(AVERAGE(seed1!O19,seed2!O19,seed3!O19,seed4!O19,seed5!O19),1) -> #DIV/0! | P19: =ROUND(AVERAGE(seed1!P19,seed2!P19,seed3!P19,seed4!P19,seed5!P19),1) -> #DIV/0! | Q19: =ROUND(AVERAGE(seed1!Q19,seed2!Q19,seed3!Q19,seed4!Q19,seed5!Q19),1) -> #DIV/0! | R19: =ROUND(AVERAGE(seed1!R19,seed2!R19,seed3!R19,seed4!R19,seed5!R19),1) -> #DIV/0!
B20: 通過台数_B | C20: =ROUND(AVERAGE(seed1!C20,seed2!C20,seed3!C20,seed4!C20,seed5!C20),1) -> #DIV/0! | D20: =ROUND(AVERAGE(seed1!D20,seed2!D20,seed3!D20,seed4!D20,seed5!D20),1) -> #DIV/0! | E20: =ROUND(AVERAGE(seed1!E20,seed2!E20,seed3!E20,seed4!E20,seed5!E20),1) -> #DIV/0! | F20: =ROUND(AVERAGE(seed1!F20,seed2!F20,seed3!F20,seed4!F20,seed5!F20),1) -> #DIV/0! | G20: =ROUND(AVERAGE(seed1!G20,seed2!G20,seed3!G20,seed4!G20,seed5!G20),1) -> #DIV/0! | H20: =ROUND(AVERAGE(seed1!H20,seed2!H20,seed3!H20,seed4!H20,seed5!H20),1) -> #DIV/0! | I20: =ROUND(AVERAGE(seed1!I20,seed2!I20,seed3!I20,seed4!I20,seed5!I20),1) -> #DIV/0! | K20: 通過台数_B | L20: =ROUND(AVERAGE(seed1!L20,seed2!L20,seed3!L20,seed4!L20,seed5!L20),1) -> #DIV/0! | M20: =ROUND(AVERAGE(seed1!M20,seed2!M20,seed3!M20,seed4!M20,seed5!M20),1) -> #DIV/0! | N20: =ROUND(AVERAGE(seed1!N20,seed2!N20,seed3!N20,seed4!N20,seed5!N20),1) -> #DIV/0! | O20: =ROUND(AVERAGE(seed1!O20,seed2!O20,seed3!O20,seed4!O20,seed5!O20),1) -> #DIV/0! | P20: =ROUND(AVERAGE(seed1!P20,seed2!P20,seed3!P20,seed4!P20,seed5!P20),1) -> #DIV/0! | Q20: =ROUND(AVERAGE(seed1!Q20,seed2!Q20,seed3!Q20,seed4!Q20,seed5!Q20),1) -> #DIV/0! | R20: =ROUND(AVERAGE(seed1!R20,seed2!R20,seed3!R20,seed4!R20,seed5!R20),1) -> #DIV/0!
B21: 通過台数_合計 | C21: =SUM(C18:C20) -> #DIV/0! | D21: =SUM(D18:D20) -> #DIV/0! | E21: =SUM(E18:E20) -> #DIV/0! | F21: =SUM(F18:F20) -> #DIV/0! | G21: =SUM(G18:G20) -> #DIV/0! | H21: =SUM(H18:H20) -> #DIV/0! | I21: =SUM(I18:I20) -> #DIV/0! | K21: 通過台数_合計 | L21: =SUM(L18:L20) -> #DIV/0! | M21: =SUM(M18:M20) -> #DIV/0! | N21: =SUM(N18:N20) -> #DIV/0! | O21: =SUM(O18:O20) -> #DIV/0! | P21: =SUM(P18:P20) -> #DIV/0! | Q21: =SUM(Q18:Q20) -> #DIV/0! | R21: =SUM(R18:R20) -> #DIV/0!
B23: 500/500/500
C24: 1 | D24: 2 | E24: 3 | F24: 4 | G24: 5 | H24: 6 | I24: 7 | L24: pass_LT | M24: pass_LR | N24: pass_LB | O24: pass_TR | P24: pass_TB | Q24: pass_TL | R24: pass_RB | S24: pass_RL | T24: pass_RT | U24: pass_BL | V24: pass_BT | W24: pass_BR | Y24: 左折 | Z24: 右折 | AA24: 直進
C25: 全て受け入れ | D25: 道交法 | E25: 0.2 | F25: 0.4 | G25: 既存 | H25: 提案 | I25: 性能込み | L25: =ROUND(AVERAGE(seed1!L25,seed2!L25,seed3!L25,seed4!L25,seed5!L25),1) -> 3.8 | M25: =ROUND(AVERAGE(seed1!M25,seed2!M25,seed3!M25,seed4!M25,seed5!M25),1) -> 3 | N25: =ROUND(AVERAGE(seed1!N25,seed2!N25,seed3!N25,seed4!N25,seed5!N25),1) -> 5.6 | O25: =ROUND(AVERAGE(seed1!O25,seed2!O25,seed3!O25,seed4!O25,seed5!O25),1) -> 6.8 | P25: =ROUND(AVERAGE(seed1!P25,seed2!P25,seed3!P25,seed4!P25,seed5!P25),1) -> 0 | Q25: =ROUND(AVERAGE(seed1!Q25,seed2!Q25,seed3!Q25,seed4!Q25,seed5!Q25),1) -> 5.6 | R25: =ROUND(AVERAGE(seed1!R25,seed2!R25,seed3!R25,seed4!R25,seed5!R25),1) -> 4.8 | S25: =ROUND(AVERAGE(seed1!S25,seed2!S25,seed3!S25,seed4!S25,seed5!S25),1) -> 3.8 | ... W25: =ROUND(AVERAGE(seed1!W25,seed2!W25,seed3!W25,seed4!W25,seed5!W25),1) -> 5.4 | Y25: =L25+O25+R25+U25 -> 21 | Z25: =N25+W25+T25+Q25 -> 19.6 | AA25: =M25+S25 -> 6.8
B26: （Bus） | C26: =ROUND(AVERAGE(seed1!C26,seed2!C26,seed3!C26,seed4!C26,seed5!C26),4) -> #DIV/0! | D26: =ROUND(AVERAGE(seed1!D26,seed2!D26,seed3!D26,seed4!D26,seed5!D26),4) -> #DIV/0! | E26: =ROUND(AVERAGE(seed1!E26,seed2!E26,seed3!E26,seed4!E26,seed5!E26),4) -> #DIV/0! | F26: =ROUND(AVERAGE(seed1!F26,seed2!F26,seed3!F26,seed4!F26,seed5!F26),4) -> #DIV/0! | G26: =ROUND(AVERAGE(seed1!G26,seed2!G26,seed3!G26,seed4!G26,seed5!G26),4) -> #DIV/0! | H26: =ROUND(AVERAGE(seed1!H26,seed2!H26,seed3!H26,seed4!H26,seed5!H26),4) -> #DIV/0! | I26: =ROUND(AVERAGE(seed1!I26,seed2!I26,seed3!I26,seed4!I26,seed5!I26),4) -> #DIV/0! | L26: =ROUND(AVERAGE(seed1!L26,seed2!L26,seed3!L26,seed4!L26,seed5!L26),1) -> 12.8 | M26: =ROUND(AVERAGE(seed1!M26,seed2!M26,seed3!M26,seed4!M26,seed5!M26),1) -> 10 | N26: =ROUND(AVERAGE(seed1!N26,seed2!N26,seed3!N26,seed4!N26,seed5!N26),1) -> 8.4 | O26: =ROUND(AVERAGE(seed1!O26,seed2!O26,seed3!O26,seed4!O26,seed5!O26),1) -> 17.4 | P26: =ROUND(AVERAGE(seed1!P26,seed2!P26,seed3!P26,seed4!P26,seed5!P26),1) -> 0 | Q26: =ROUND(AVERAGE(seed1!Q26,seed2!Q26,seed3!Q26,seed4!Q26,seed5!Q26),1) -> 18.2 | R26: =ROUND(AVERAGE(seed1!R26,seed2!R26,seed3!R26,seed4!R26,seed5!R26),1) -> 10.8 | S26: =ROUND(AVERAGE(seed1!S26,seed2!S26,seed3!S26,seed4!S26,seed5!S26),1) -> 11.6 | ... W26: =ROUND(AVERAGE(seed1!W26,seed2!W26,seed3!W26,seed4!W26,seed5!W26),1) -> 18.8 | Y26: =L26+O26+R26+U26 -> 58.4 | Z26: =N26+W26+T26+Q26 -> 59.2 | AA26: =M26+S26 -> 21.6
B27: （Car） | C27: =ROUND(AVERAGE(seed1!C27,seed2!C27,seed3!C27,seed4!C27,seed5!C27),4) -> #DIV/0! | D27: =ROUND(AVERAGE(seed1!D27,seed2!D27,seed3!D27,seed4!D27,seed5!D27),4) -> #DIV/0! | E27: =ROUND(AVERAGE(seed1!E27,seed2!E27,seed3!E27,seed4!E27,seed5!E27),4) -> #DIV/0! | F27: =ROUND(AVERAGE(seed1!F27,seed2!F27,seed3!F27,seed4!F27,seed5!F27),4) -> #DIV/0! | G27: =ROUND(AVERAGE(seed1!G27,seed2!G27,seed3!G27,seed4!G27,seed5!G27),4) -> #DIV/0! | H27: =ROUND(AVERAGE(seed1!H27,seed2!H27,seed3!H27,seed4!H27,seed5!H27),4) -> #DIV/0! | I27: =ROUND(AVERAGE(seed1!I27,seed2!I27,seed3!I27,seed4!I27,seed5!I27),4) -> #DIV/0! | Y27: =Y25+Y26 -> 79.4 | Z27: =Z25+Z26 -> 78.8 | AA27: =AA25+AA26 -> 28.4 | AB27: =SUM(Y27:AA27) -> 186.6
B28: 右折 | C28: =ROUND(AVERAGE(seed1!C28,seed2!C28,seed3!C28,seed4!C28,seed5!C28),4) -> #DIV/0! | D28: =ROUND(AVERAGE(seed1!D28,seed2!D28,seed3!D28,seed4!D28,seed5!D28),4) -> #DIV/0! | E28: =ROUND(AVERAGE(seed1!E28,seed2!E28,seed3!E28,seed4!E28,seed5!E28),4) -> #DIV/0! | F28: =ROUND(AVERAGE(seed1!F28,seed2!F28,seed3!F28,seed4!F28,seed5!F28),4) -> #DIV/0! | G28: =ROUND(AVERAGE(seed1!G28,seed2!G28,seed3!G28,seed4!G28,seed5!G28),4) -> #DIV/0! | H28: =ROUND(AVERAGE(seed1!H28,seed2!H28,seed3!H28,seed4!H28,seed5!H28),4) -> #DIV/0! | I28: =ROUND(AVERAGE(seed1!I28,seed2!I28,seed3!I28,seed4!I28,seed5!I28),4) -> #DIV/0! | L28: =ROUND(AVERAGE(seed1!L28,seed2!L28,seed3!L28,seed4!L28,seed5!L28),1) -> 3.8 | M28: =ROUND(AVERAGE(seed1!M28,seed2!M28,seed3!M28,seed4!M28,seed5!M28),1) -> 3 | N28: =ROUND(AVERAGE(seed1!N28,seed2!N28,seed3!N28,seed4!N28,seed5!N28),1) -> 5.6 | O28: =ROUND(AVERAGE(seed1!O28,seed2!O28,seed3!O28,seed4!O28,seed5!O28),1) -> 6.6 | P28: =ROUND(AVERAGE(seed1!P28,seed2!P28,seed3!P28,seed4!P28,seed5!P28),1) -> 0 | Q28: =ROUND(AVERAGE(seed1!Q28,seed2!Q28,seed3!Q28,seed4!Q28,seed5!Q28),1) -> 5.4 | R28: =ROUND(AVERAGE(seed1!R28,seed2!R28,seed3!R28,seed4!R28,seed5!R28),1) -> 4.6 | S28: =ROUND(AVERAGE(seed1!S28,seed2!S28,seed3!S28,seed4!S28,seed5!S28),1) -> 3.8 | ... W28: =ROUND(AVERAGE(seed1!W28,seed2!W28,seed3!W28,seed4!W28,seed5!W28),1) -> 5.8 | Y28: =L28+O28+R28+U28 -> 20.6 | Z28: =N28+W28+T28+Q28 -> 19.8 | AA28: =M28+S28 -> 6.8
B29: （Bus） | C29: =ROUND(AVERAGE(seed1!C29,seed2!C29,seed3!C29,seed4!C29,seed5!C29),4) -> #DIV/0! | D29: =ROUND(AVERAGE(seed1!D29,seed2!D29,seed3!D29,seed4!D29,seed5!D29),4) -> #DIV/0! | E29: =ROUND(AVERAGE(seed1!E29,seed2!E29,seed3!E29,seed4!E29,seed5!E29),4) -> #DIV/0! | F29: =ROUND(AVERAGE(seed1!F29,seed2!F29,seed3!F29,seed4!F29,seed5!F29),4) -> #DIV/0! | G29: =ROUND(AVERAGE(seed1!G29,seed2!G29,seed3!G29,seed4!G29,seed5!G29),4) -> #DIV/0! | H29: =ROUND(AVERAGE(seed1!H29,seed2!H29,seed3!H29,seed4!H29,seed5!H29),4) -> #DIV/0! | I29: =ROUND(AVERAGE(seed1!I29,seed2!I29,seed3!I29,seed4!I29,seed5!I29),4) -> #DIV/0! | L29: =ROUND(AVERAGE(seed1!L29,seed2!L29,seed3!L29,seed4!L29,seed5!L29),1) -> 12.6 | M29: =ROUND(AVERAGE(seed1!M29,seed2!M29,seed3!M29,seed4!M29,seed5!M29),1) -> 10.2 | N29: =ROUND(AVERAGE(seed1!N29,seed2!N29,seed3!N29,seed4!N29,seed5!N29),1) -> 8.6 | O29: =ROUND(AVERAGE(seed1!O29,seed2!O29,seed3!O29,seed4!O29,seed5!O29),1) -> 17.2 | P29: =ROUND(AVERAGE(seed1!P29,seed2!P29,seed3!P29,seed4!P29,seed5!P29),1) -> 0 | Q29: =ROUND(AVERAGE(seed1!Q29,seed2!Q29,seed3!Q29,seed4!Q29,seed5!Q29),1) -> 17.8 | R29: =ROUND(AVERAGE(seed1!R29,seed2!R29,seed3!R29,seed4!R29,seed5!R29),1) -> 10.6 | S29: =ROUND(AVERAGE(seed1!S29,seed2!S29,seed3!S29,seed4!S29,seed5!S29),1) -> 11.6 | ... W29: =ROUND(AVERAGE(seed1!W29,seed2!W29,seed3!W29,seed4!W29,seed5!W29),1) -> 18.8 | Y29: =L29+O29+R29+U29 -> 57.8 | Z29: =N29+W29+T29+Q29 -> 59 | AA29: =M29+S29 -> 21.8
B30: （Car） | C30: =ROUND(AVERAGE(seed1!C30,seed2!C30,seed3!C30,seed4!C30,seed5!C30),4) -> #DIV/0! | D30: =ROUND(AVERAGE(seed1!D30,seed2!D30,seed3!D30,seed4!D30,seed5!D30),4) -> #DIV/0! | E30: =ROUND(AVERAGE(seed1!E30,seed2!E30,seed3!E30,seed4!E30,seed5!E30),4) -> #DIV/0! | F30: =ROUND(AVERAGE(seed1!F30,seed2!F30,seed3!F30,seed4!F30,seed5!F30),4) -> #DIV/0! | G30: =ROUND(AVERAGE(seed1!G30,seed2!G30,seed3!G30,seed4!G30,seed5!G30),4) -> #DIV/0! | H30: =ROUND(AVERAGE(seed1!H30,seed2!H30,seed3!H30,seed4!H30,seed5!H30),4) -> #DIV/0! | I30: =ROUND(AVERAGE(seed1!I30,seed2!I30,seed3!I30,seed4!I30,seed5!I30),4) -> #DIV/0! | Y30: =Y28+Y29 -> 78.4 | Z30: =Z28+Z29 -> 78.8 | AA30: =AA28+AA29 -> 28.6 | AB30: =SUM(Y30:AA30) -> 185.8
B31: 左折 | C31: =ROUND(AVERAGE(seed1!C31,seed2!C31,seed3!C31,seed4!C31,seed5!C31),4) -> #DIV/0! | D31: =ROUND(AVERAGE(seed1!D31,seed2!D31,seed3!D31,seed4!D31,seed5!D31),4) -> #DIV/0! | E31: =ROUND(AVERAGE(seed1!E31,seed2!E31,seed3!E31,seed4!E31,seed5!E31),4) -> #DIV/0! | F31: =ROUND(AVERAGE(seed1!F31,seed2!F31,seed3!F31,seed4!F31,seed5!F31),4) -> #DIV/0! | G31: =ROUND(AVERAGE(seed1!G31,seed2!G31,seed3!G31,seed4!G31,seed5!G31),4) -> #DIV/0! | H31: =ROUND(AVERAGE(seed1!H31,seed2!H31,seed3!H31,seed4!H31,seed5!H31),4) -> #DIV/0! | I31: =ROUND(AVERAGE(seed1!I31,seed2!I31,seed3!I31,seed4!I31,seed5!I31),4) -> #DIV/0! | L31: =ROUND(AVERAGE(seed1!L31,seed2!L31,seed3!L31,seed4!L31,seed5!L31),1) -> 3.6 | M31: =ROUND(AVERAGE(seed1!M31,seed2!M31,seed3!M31,seed4!M31,seed5!M31),1) -> 3 | N31: =ROUND(AVERAGE(seed1!N31,seed2!N31,seed3!N31,seed4!N31,seed5!N31),1) -> 5.2 | O31: =ROUND(AVERAGE(seed1!O31,seed2!O31,seed3!O31,seed4!O31,seed5!O31),1) -> 6.6 | P31: =ROUND(AVERAGE(seed1!P31,seed2!P31,seed3!P31,seed4!P31,seed5!P31),1) -> 0 | Q31: =ROUND(AVERAGE(seed1!Q31,seed2!Q31,seed3!Q31,seed4!Q31,seed5!Q31),1) -> 5.8 | R31: =ROUND(AVERAGE(seed1!R31,seed2!R31,seed3!R31,seed4!R31,seed5!R31),1) -> 4.8 | S31: =ROUND(AVERAGE(seed1!S31,seed2!S31,seed3!S31,seed4!S31,seed5!S31),1) -> 3.8 | ... W31: =ROUND(AVERAGE(seed1!W31,seed2!W31,seed3!W31,seed4!W31,seed5!W31),1) -> 5.8 | Y31: =L31+O31+R31+U31 -> 20.6 | Z31: =N31+W31+T31+Q31 -> 19.8 | AA31: =M31+S31 -> 6.8
B32: （Bus） | C32: =ROUND(AVERAGE(seed1!C32,seed2!C32,seed3!C32,seed4!C32,seed5!C32),4) -> #DIV/0! | D32: =ROUND(AVERAGE(seed1!D32,seed2!D32,seed3!D32,seed4!D32,seed5!D32),4) -> #DIV/0! | E32: =ROUND(AVERAGE(seed1!E32,seed2!E32,seed3!E32,seed4!E32,seed5!E32),4) -> #DIV/0! | F32: =ROUND(AVERAGE(seed1!F32,seed2!F32,seed3!F32,seed4!F32,seed5!F32),4) -> #DIV/0! | G32: =ROUND(AVERAGE(seed1!G32,seed2!G32,seed3!G32,seed4!G32,seed5!G32),4) -> #DIV/0! | H32: =ROUND(AVERAGE(seed1!H32,seed2!H32,seed3!H32,seed4!H32,seed5!H32),4) -> #DIV/0! | I32: =ROUND(AVERAGE(seed1!I32,seed2!I32,seed3!I32,seed4!I32,seed5!I32),4) -> #DIV/0! | L32: =ROUND(AVERAGE(seed1!L32,seed2!L32,seed3!L32,seed4!L32,seed5!L32),1) -> 12.2 | M32: =ROUND(AVERAGE(seed1!M32,seed2!M32,seed3!M32,seed4!M32,seed5!M32),1) -> 10 | N32: =ROUND(AVERAGE(seed1!N32,seed2!N32,seed3!N32,seed4!N32,seed5!N32),1) -> 8.4 | O32: =ROUND(AVERAGE(seed1!O32,seed2!O32,seed3!O32,seed4!O32,seed5!O32),1) -> 17.4 | P32: =ROUND(AVERAGE(seed1!P32,seed2!P32,seed3!P32,seed4!P32,seed5!P32),1) -> 0 | Q32: =ROUND(AVERAGE(seed1!Q32,seed2!Q32,seed3!Q32,seed4!Q32,seed5!Q32),1) -> 18 | R32: =ROUND(AVERAGE(seed1!R32,seed2!R32,seed3!R32,seed4!R32,seed5!R32),1) -> 10.8 | S32: =ROUND(AVERAGE(seed1!S32,seed2!S32,seed3!S32,seed4!S32,seed5!S32),1) -> 11.6 | ... W32: =ROUND(AVERAGE(seed1!W32,seed2!W32,seed3!W32,seed4!W32,seed5!W32),1) -> 19 | Y32: =L32+O32+R32+U32 -> 58.2 | Z32: =N32+W32+T32+Q32 -> 59.2 | AA32: =M32+S32 -> 21.6
B33: （Car） | C33: =ROUND(AVERAGE(seed1!C33,seed2!C33,seed3!C33,seed4!C33,seed5!C33),4) -> #DIV/0! | D33: =ROUND(AVERAGE(seed1!D33,seed2!D33,seed3!D33,seed4!D33,seed5!D33),4) -> #DIV/0! | E33: =ROUND(AVERAGE(seed1!E33,seed2!E33,seed3!E33,seed4!E33,seed5!E33),4) -> #DIV/0! | F33: =ROUND(AVERAGE(seed1!F33,seed2!F33,seed3!F33,seed4!F33,seed5!F33),4) -> #DIV/0! | G33: =ROUND(AVERAGE(seed1!G33,seed2!G33,seed3!G33,seed4!G33,seed5!G33),4) -> #DIV/0! | H33: =ROUND(AVERAGE(seed1!H33,seed2!H33,seed3!H33,seed4!H33,seed5!H33),4) -> #DIV/0! | I33: =ROUND(AVERAGE(seed1!I33,seed2!I33,seed3!I33,seed4!I33,seed5!I33),4) -> #DIV/0! | Y33: =Y31+Y32 -> 78.8 | Z33: =Z31+Z32 -> 79 | AA33: =AA31+AA32 -> 28.4 | AB33: =SUM(Y33:AA33) -> 186.2 | AE33: =Y27 -> 79.4 | AF33: =Z27 -> 78.8 | AG33: =AA27 -> 28.4 | AH33: =AB27 -> 186.6
B34: 直進 | C34: =ROUND(AVERAGE(seed1!C34,seed2!C34,seed3!C34,seed4!C34,seed5!C34),4) -> #DIV/0! | D34: =ROUND(AVERAGE(seed1!D34,seed2!D34,seed3!D34,seed4!D34,seed5!D34),4) -> #DIV/0! | E34: =ROUND(AVERAGE(seed1!E34,seed2!E34,seed3!E34,seed4!E34,seed5!E34),4) -> #DIV/0! | F34: =ROUND(AVERAGE(seed1!F34,seed2!F34,seed3!F34,seed4!F34,seed5!F34),4) -> #DIV/0! | G34: =ROUND(AVERAGE(seed1!G34,seed2!G34,seed3!G34,seed4!G34,seed5!G34),4) -> #DIV/0! | H34: =ROUND(AVERAGE(seed1!H34,seed2!H34,seed3!H34,seed4!H34,seed5!H34),4) -> #DIV/0! | I34: =ROUND(AVERAGE(seed1!I34,seed2!I34,seed3!I34,seed4!I34,seed5!I34),4) -> #DIV/0! | L34: =ROUND(AVERAGE(seed1!L34,seed2!L34,seed3!L34,seed4!L34,seed5!L34),1) -> 3.8 | M34: =ROUND(AVERAGE(seed1!M34,seed2!M34,seed3!M34,seed4!M34,seed5!M34),1) -> 3.2 | N34: =ROUND(AVERAGE(seed1!N34,seed2!N34,seed3!N34,seed4!N34,seed5!N34),1) -> 5.6 | O34: =ROUND(AVERAGE(seed1!O34,seed2!O34,seed3!O34,seed4!O34,seed5!O34),1) -> 6.8 | P34: =ROUND(AVERAGE(seed1!P34,seed2!P34,seed3!P34,seed4!P34,seed5!P34),1) -> 0 | Q34: =ROUND(AVERAGE(seed1!Q34,seed2!Q34,seed3!Q34,seed4!Q34,seed5!Q34),1) -> 5.8 | R34: =ROUND(AVERAGE(seed1!R34,seed2!R34,seed3!R34,seed4!R34,seed5!R34),1) -> 4.8 | S34: =ROUND(AVERAGE(seed1!S34,seed2!S34,seed3!S34,seed4!S34,seed5!S34),1) -> 3.8 | ... W34: =ROUND(AVERAGE(seed1!W34,seed2!W34,seed3!W34,seed4!W34,seed5!W34),1) -> 5.6 | Y34: =L34+O34+R34+U34 -> 21 | Z34: =N34+W34+T34+Q34 -> 20 | AA34: =M34+S34 -> 7 | AE34: =Y30 -> 78.4 | AF34: =Z30 -> 78.8 | AG34: =AA30 -> 28.6 | AH34: =AB30 -> 185.8
B35: （Bus） | C35: =ROUND(AVERAGE(seed1!C35,seed2!C35,seed3!C35,seed4!C35,seed5!C35),4) -> #DIV/0! | D35: =ROUND(AVERAGE(seed1!D35,seed2!D35,seed3!D35,seed4!D35,seed5!D35),4) -> #DIV/0! | E35: =ROUND(AVERAGE(seed1!E35,seed2!E35,seed3!E35,seed4!E35,seed5!E35),4) -> #DIV/0! | F35: =ROUND(AVERAGE(seed1!F35,seed2!F35,seed3!F35,seed4!F35,seed5!F35),4) -> #DIV/0! | G35: =ROUND(AVERAGE(seed1!G35,seed2!G35,seed3!G35,seed4!G35,seed5!G35),4) -> #DIV/0! | H35: =ROUND(AVERAGE(seed1!H35,seed2!H35,seed3!H35,seed4!H35,seed5!H35),4) -> #DIV/0! | I35: =ROUND(AVERAGE(seed1!I35,seed2!I35,seed3!I35,seed4!I35,seed5!I35),4) -> #DIV/0! | L35: =ROUND(AVERAGE(seed1!L35,seed2!L35,seed3!L35,seed4!L35,seed5!L35),1) -> 12.4 | M35: =ROUND(AVERAGE(seed1!M35,seed2!M35,seed3!M35,seed4!M35,seed5!M35),1) -> 10 | N35: =ROUND(AVERAGE(seed1!N35,seed2!N35,seed3!N35,seed4!N35,seed5!N35),1) -> 9.4 | O35: =ROUND(AVERAGE(seed1!O35,seed2!O35,seed3!O35,seed4!O35,seed5!O35),1) -> 17.6 | P35: =ROUND(AVERAGE(seed1!P35,seed2!P35,seed3!P35,seed4!P35,seed5!P35),1) -> 0 | Q35: =ROUND(AVERAGE(seed1!Q35,seed2!Q35,seed3!Q35,seed4!Q35,seed5!Q35),1) -> 18.2 | R35: =ROUND(AVERAGE(seed1!R35,seed2!R35,seed3!R35,seed4!R35,seed5!R35),1) -> 10.8 | S35: =ROUND(AVERAGE(seed1!S35,seed2!S35,seed3!S35,seed4!S35,seed5!S35),1) -> 11.6 | ... W35: =ROUND(AVERAGE(seed1!W35,seed2!W35,seed3!W35,seed4!W35,seed5!W35),1) -> 19.2 | Y35: =L35+O35+R35+U35 -> 58.4 | Z35: =N35+W35+T35+Q35 -> 60.6 | AA35: =M35+S35 -> 21.6 | AE35: =Y33 -> 78.8 | AF35: =Z33 -> 79 | AG35: =AA33 -> 28.4 | AH35: =AB33 -> 186.2
B36: （Car） | C36: =ROUND(AVERAGE(seed1!C36,seed2!C36,seed3!C36,seed4!C36,seed5!C36),4) -> #DIV/0! | D36: =ROUND(AVERAGE(seed1!D36,seed2!D36,seed3!D36,seed4!D36,seed5!D36),4) -> #DIV/0! | E36: =ROUND(AVERAGE(seed1!E36,seed2!E36,seed3!E36,seed4!E36,seed5!E36),4) -> #DIV/0! | F36: =ROUND(AVERAGE(seed1!F36,seed2!F36,seed3!F36,seed4!F36,seed5!F36),4) -> #DIV/0! | G36: =ROUND(AVERAGE(seed1!G36,seed2!G36,seed3!G36,seed4!G36,seed5!G36),4) -> #DIV/0! | H36: =ROUND(AVERAGE(seed1!H36,seed2!H36,seed3!H36,seed4!H36,seed5!H36),4) -> #DIV/0! | I36: =ROUND(AVERAGE(seed1!I36,seed2!I36,seed3!I36,seed4!I36,seed5!I36),4) -> #DIV/0! | Y36: =Y34+Y35 -> 79.4 | Z36: =Z34+Z35 -> 80.6 | AA36: =AA34+AA35 -> 28.6 | AB36: =SUM(Y36:AA36) -> 188.6 | AE36: =Y36 -> 79.4 | AF36: =Z36 -> 80.6 | AG36: =AA36 -> 28.6 | AH36: =AB36 -> 188.6
