Workbook

Sheet seed1
B2: 400/400/400 | D2: 600s | K2: 660/180/660
C3: 1 | D3: 2 | E3: 3 | F3: 4 | G3: 5 | H3: 6 | L3: 1 | M3: 2 | N3: 3 | O3: 4 | P3: 5 | Q3: 6
C4: 全て受け入れ | D4: 道交法 | E4: 0.2 | F4: 0.4 | G4: 既存 | H4: 提案 | L4: 全て受け入れ | M4: 道交法 | N4: 0.2 | O4: 0.4 | P4: 既存 | Q4: 提案
B5: 右折 | C5: 4.3895 | D5: 5.1429 | E5: 5.6032 | F5: 2.1878 | G5: 5.4477 | H5: 5.3746 | K5: 右折 | L5: 6.225 | M5: 1.0004 | N5: 3.073 | O5: 3.994 | P5: 5.2447 | Q5: 5.6079
B6: 左折 | C6: 5.3699 | D6: 4.0337 | E6: 5.295 | F6: 1.2397 | G6: 5.0735 | H6: 5.6918 | K6: 左折 | L6: 6.2335 | M6: 0.7619 | N6: 2.4792 | O6: 2.6245 | P6: 4.0476 | Q6: 4.5921
B7: 直進 | C7: 4.9843 | D7: 7.077 | E7: 8.7808 | F7: 2.3682 | G7: 6.698 | H7: 7.1478 | K7: 直進 | L7: 10.8756 | M7: 12.9331 | N7: 12.9331 | O7: 12.4828 | P7: 10.965 | Q7: 12.5352
B8: 合計 | C8: 6.8388 | D8: 7.0347 | E8: 8.034 | F8: 2.8441 | G8: 7.5546 | H8: 7.8175 | K8: 合計 | L8: 11.47 | M8: 7.4697 | N8: 10.7047 | O8: 10.955 | P8: 10.9434 | Q8: 11.9036
K9: 右左折_通過 | L9: 29 | M9: 20 | N9: 29 | O9: 29 | P9: 29 | Q9: 29 | S9: 30
K10: 直進_通過 | L10: 216 | M10: 216 | N10: 216 | O10: 216 | P10: 216 | Q10: 216 | S10: 220
B13: 500/500/500 | K13: 630/240/630
C14: 1 | D14: 2 | E14: 3 | F14: 4 | G14: 5 | H14: 6 | L14: 1 | M14: 2 | N14: 3 | O14: 4 | P14: 5 | Q14: 6
C15: 全て受け入れ | D15: 道交法 | E15: 0.2 | F15: 0.4 | G15: 既存 | H15: 提案 | L15: 全て受け入れ | M15: 道交法 | N15: 0.2 | O15: 0.4 | P15: 既存 | Q15: 提案
B16: 右折 | C16: 3.1914 | D16: 3.9972 | E16: 4.5129 | F16: 4.3387 | G16: 4.2419 | H16: 5.4265 | K16: 右折 | L16: 4.6508 | M16: 0.7399 | N16: 1.7704 | O16: 3.2246 | P16: 4.9286 | Q16: 5.1404
B17: 左折 | C17: 3.076 | D17: 3.1427 | E17: 3.623 | F17: 3.4386 | G17: 3.5452 | H17: 4.7965 | K17: 左折 | L17: 3.6898 | M17: 0.7839 | N17: 1.7297 | O17: 3.3348 | P17: 5.2648 | Q17: 5.0215
B18: 直進 | C18: 2.7187 | D18: 6.2309 | E18: 6.0601 | F18: 5.4749 | G18: 4.6829 | H18: 6.0878 | K18: 直進 | L18: 9.6266 | M18: 13.2225 | N18: 12.9124 | O18: 12.4284 | P18: 10.5619 | Q18: 11.6086
B19: 合計 | C19: 4.6947 | D19: 6.1117 | E19: 6.557 | F19: 6.255 | G19: 6.0405 | H19: 7.344 | K19: 合計 | L19: 9.7683 | M19: 6.6344 | N19: 8.6167 | O19: 10.3956 | P19: 10.4822 | Q19: 11.0924
K20: 右左折_通過 | L20: 38 | M20: 22 | N20: 36 | O20: 38 | P20: 38 | Q20: 38 | S20: 40
K21: 直進_通過 | L21: 206 | M21: 206 | N21: 206 | O21: 206 | P21: 205 | Q21: 206 | S21: 210
B24: 600/600/600 | K24: 600/300/600
C25: 1 | D25: 2 | E25: 3 | F25: 4 | G25: 5 | H25: 6 | L25: 1 | M25: 2 | N25: 3 | O25: 4 | P25: 5 | Q25: 6
C26: 全て受け入れ | D26: 道交法 | E26: 0.2 | F26: 0.4 | G26: 既存 | H26: 提案 | L26: 全て受け入れ | M26: 道交法 | N26: 0.2 | O26: 0.4 | P26: 既存 | Q26: 提案
B27: 右折 | C27: 1.41 | D27: 2.3187 | E27: 2.2122 | F27: 2.3926 | G27: 1.8962 | H27: 2.3256 | K27: 右折 | L27: 4.9968 | M27: 1.1987 | N27: 1.4055 | O27: 2.8469 | P27: 4.5729 | Q27: 4.8564
B28: 左折 | C28: 2.1756 | D28: 1.4361 | E28: 1.6855 | F28: 1.9341 | G28: 1.6223 | H28: 2.0368 | K28: 左折 | L28: 3.9759 | M28: 1.0353 | N28: 1.4495 | O28: 2.8384 | P28: 4.331 | Q28: 4.7994
B29: 直進 | C29: 1.9152 | D29: 3.0369 | E29: 2.3278 | F29: 2.7865 | G29: 1.9539 | H29: 2.4307 | K29: 直進 | L29: 6.092 | M29: 13.2194 | N29: 12.8886 | O29: 12.4539 | P29: 9.4337 | Q29: 11.0744
B30: 合計 | C30: 3.0594 | D30: 3.5099 | E30: 3.4192 | F30: 3.8233 | G30: 3.0662 | H30: 3.6935 | K30: 合計 | L30: 7.7511 | M30: 6.729 | N30: 7.3422 | O30: 9.4359 | P30: 9.4938 | Q30: 10.3938
K31: 右左折_通過 | L31: 48 | M31: 35 | N31: 41 | O31: 46 | P31: 48 | Q31: 48 | S31: 50
K32: 直進_通過 | L32: 197 | M32: 197 | N32: 197 | O32: 197 | P32: 197 | Q32: 197 | S32: 200
O33: 186
K35: 570/360/570
L36: 1 | M36: 2 | N36: 3 | O36: 4 | P36: 5 | Q36: 6
L37: 全て受け入れ | M37: 道交法 | N37: 0.2 | O37: 0.4 | P37: 既存 | Q37: 提案
K38: 右折 | L38: 1.2436 | M38: 1.0459 | N38: 1.1357 | O38: 2.5895 | P38: 3.1122 | Q38: 4.0252
K39: 左折 | L39: 1.3765 | M39: 0.8453 | N39: 1.1456 | O39: 2.2773 | P39: 2.8176 | Q39: 3.7469
K40: 直進 | L40: 3.466 | M40: 13.2256 | N40: 12.8851 | O40: 12.161 | P40: 8.2959 | Q40: 9.2414
K41: 合計 | L41: 4.0457 | M41: 6.2485 | N41: 6.4038 | O41: 8.3996 | P41: 7.8234 | Q41: 8.839
K42: 右左折_通過 | L42: 35 | M42: 31 | N42: 40 | O42: 52 | P42: 56 | Q42: 58 | S42: 60
K43: 直進_通過 | L43: 149 | M43: 187 | N43: 187 | O43: 187 | P43: 185 | Q43: 185 | S43: 190
K46: 540/420/540
L47: 1 | M47: 2 | N47: 3 | O47: 4 | P47: 5 | Q47: 6
L48: 全て受け入れ | M48: 道交法 | N48: 0.2 | O48: 0.4 | P48: 既存 | Q48: 提案
...

Sheet seed2
B2: 400/400/400 | D2: 600s | K2: 660/180/660
C3: 1 | D3: 2 | E3: 3 | F3: 4 | G3: 5 | H3: 6 | L3: 1 | M3: 2 | N3: 3 | O3: 4 | P3: 5 | Q3: 6
C4: 全て受け入れ | D4: 道交法 | E4: 0.2 | F4: 0.4 | G4: 既存 | H4: 提案 | L4: 全て受け入れ | M4: 道交法 | N4: 0.2 | O4: 0.4 | P4: 既存 | Q4: 提案
B5: 右折 | C5: 5.1672 | D5: 5.483 | E5: 5.2782 | F5: 5.8676 | G5: 5.5337 | H5: 5.4373 | K5: 右折 | L5: 6.3016 | M5: 1.9016 | N5: 2.8201 | O5: 4.6317 | P5: 5.4758 | Q5: 5.1386
B6: 左折 | C6: 5.4472 | D6: 4.051 | E6: 4.0079 | F6: 4.5836 | G6: 4.7436 | H6: 4.7645 | K6: 左折 | L6: 4.9594 | M6: 1.7542 | N6: 2.3873 | O6: 3.3023 | P6: 4.5064 | Q6: 4.2548
B7: 直進 | C7: 5.7333 | D7: 8.3648 | E7: 7.4432 | F7: 7.5846 | G7: 6.1341 | H7: 6.8521 | K7: 直進 | L7: 10.8311 | M7: 13.2024 | N7: 12.9552 | O7: 12.4983 | P7: 11.2169 | Q7: 12.3299
B8: 合計 | C8: 7.3025 | D8: 7.4172 | E8: 7.2089 | F8: 7.6755 | G8: 7.2445 | H8: 7.3865 | K8: 合計 | L8: 11.2841 | M8: 9.8318 | N8: 10.7622 | O8: 11.4962 | P8: 11.2767 | Q8: 11.7199
K9: 右左折_通過 | L9: 25 | M9: 23 | N9: 24 | O9: 25 | P9: 26 | Q9: 25
K10: 直進_通過 | L10: 212 | M10: 213 | N10: 213 | O10: 213 | P10: 211 | Q10: 213
B13: 500/500/500 | K13: 630/240/630
C14: 1 | D14: 2 | E14: 3 | F14: 4 | G14: 5 | H14: 6 | L14: 1 | M14: 2 | N14: 3 | O14: 4 | P14: 5 | Q14: 6
C15: 全て受け入れ | D15: 道交法 | E15: 0.2 | F15: 0.4 | G15: 既存 | H15: 提案 | L15: 全て受け入れ | M15: 道交法 | N15: 0.2 | O15: 0.4 | P15: 既存 | Q15: 提案
B16: 右折 | C16: 2.15 | D16: 3.5498 | E16: 4.7549 | F16: 4.2062 | G16: 3.5384 | H16: 2.0454 | K16: 右折 | L16: 5.7437 | M16: 1.4021 | N16: 2.9762 | O16: 3.9776 | P16: 5.0116 | Q16: 5.5224
B17: 左折 | C17: 2.9991 | D17: 2.2616 | E17: 3.1095 | F17: 4.1628 | G17: 3.4 | H17: 3.0692 | K17: 左折 | L17: 3.4404 | M17: 1.3922 | N17: 2.4977 | O17: 3.5793 | P17: 4.2933 | Q17: 4.8528
B18: 直進 | C18: 2.1983 | D18: 3.9305 | E18: 4.4369 | F18: 5.4317 | G18: 4.1895 | H18: 2.4647 | K18: 直進 | L18: 9.8153 | M18: 13.1399 | N18: 12.9337 | O18: 12.6709 | P18: 10.6534 | Q18: 11.9004
B19: 合計 | K19: 合計 | L19: 10.1612 | M19: 8.3341 | N19: 10.2942 | O19: 11.0617 | P19: 10.569 | Q19: 11.3433
K20: 右左折_通過 | L20: 31 | M20: 26 | N20: 30 | O20: 31 | P20: 32 | Q20: 35
C21: 3.8542 | D21: 4.8538 | E21: 5.933 | F21: 6.4424 | G21: 5.489 | H21: 3.9437 | K21: 直進_通過 | L21: 202 | M21: 205 | N21: 205 | O21: 205 | P21: 201 | Q21: 205
B24: 600/600/600 | K24: 600/300/600
C25: 1 | D25: 2 | E25: 3 | F25: 4 | G25: 5 | H25: 6 | L25: 1 | M25: 2 | N25: 3 | O25: 4 | P25: 5 | Q25: 6
C26: 全て受け入れ | D26: 道交法 | E26: 0.2 | F26: 0.4 | G26: 既存 | H26: 提案 | L26: 全て受け入れ | M26: 道交法 | N26: 0.2 | O26: 0.4 | P26: 既存 | Q26: 提案
B27: 右折 | C27: 0.6475 | D27: 2.4073 | E27: 2.5901 | F27: 2.5403 | G27: 1.9982 | H27: 1.7799 | K27: 右折 | L27: 6.3501 | M27: 1.5673 | N27: 1.9979 | O27: 3.2488 | P27: 4.4018 | Q27: 5.2026
B28: 左折 | C28: 1.5898 | D28: 1.4498 | E28: 1.7123 | F28: 2.1821 | G28: 1.8933 | H28: 2.1454 | K28: 左折 | L28: 6.0064 | M28: 1.1965 | N28: 1.5065 | O28: 2.4071 | P28: 3.8095 | Q28: 4.3259
B29: 直進 | C29: 2.0332 | D29: 3.074 | E29: 2.9481 | F29: 3.6566 | G29: 2.1839 | H29: 2.3957 | K29: 直進 | L29: 10.0803 | M29: 13.2021 | N29: 13.0839 | O29: 12.2975 | P29: 9.5641 | Q29: 11.1637
B30: 合計 | C30: 2.0654 | D30: 3.6443 | E30: 3.8483 | F30: 4.3448 | G30: 3.3861 | H30: 3.4764 | K30: 合計 | L30: 10.6338 | M30: 8.064 | N30: 8.5757 | O30: 9.5343 | P30: 9.3214 | Q30: 10.5093
K31: 右左折_通過 | L31: 45 | M31: 28 | N31: 33 | O31: 40 | P31: 46 | Q31: 47
K32: 直進_通過 | L32: 192 | M32: 196 | N32: 196 | O32: 196 | P32: 190 | Q32: 191
K35: 570/360/570
L36: 1 | M36: 2 | N36: 3 | O36: 4 | P36: 5 | Q36: 6
L37: 全て受け入れ | M37: 道交法 | N37: 0.2 | O37: 0.4 | P37: 既存 | Q37: 提案
K38: 右折 | L38: 4.2779 | M38: 0.9736 | N38: 1.6159 | O38: 1.8244 | P38: 3.7864 | Q38: 4.2205
K39: 左折 | L39: 3.8898 | M39: 0.5739 | N39: 1.6566 | O39: 1.582 | P39: 3.7796 | Q39: 4.476
K40: 直進 | L40: 7.9984 | M40: 13.2308 | N40: 12.7678 | O40: 12.5124 | P40: 8.0525 | Q40: 9.7164
K41: 合計 | L41: 8.4349 | M41: 6.096 | N41: 7.6376 | O41: 7.5674 | P41: 8.3317 | Q41: 9.4152
K42: 右左折_通過 | L42: 55 | M42: 24 | N42: 41 | O42: 44 | P42: 53 | Q42: 55
K43: 直進_通過 | L43: 182 | M43: 187 | N43: 187 | O43: 187 | P43: 185 | Q43: 184
K46: 540/420/540
L47: 1 | M47: 2 | N47: 3 | O47: 4 | P47: 5 | Q47: 6
L48: 全て受け入れ | M48: 道交法 | N48: 0.2 | O48: 0.4 | P48: 既存 | Q48: 提案
K49: 右折 | L49: 3.7654 | M49: 0.6516 | N49: 1.2372 | O49: 1.2674 | P49: 3.7869 | Q49: 4.378
...

Sheet seed3
B2: 400/400/400 | D2: 600s | K2: 660/180/660
C3: 1 | D3: 2 | E3: 3 | F3: 4 | G3: 5 | H3: 6 | L3: 1 | M3: 2 | N3: 3 | O3: 4 | P3: 5 | Q3: 6
C4: 全て受け入れ | D4: 道交法 | E4: 0.2 | F4: 0.4 | G4: 既存 | H4: 提案 | L4: 全て受け入れ | M4: 道交法 | N4: 0.2 | O4: 0.4 | P4: 既存 | Q4: 提案
B5: 右折 | C5: 5.4857 | D5: 4.877 | E5: 5.8796 | F5: 5.5515 | G5: 5.9428 | H5: 6.3234 | K5: 右折 | L5: 5.9341 | M5: 1.0238 | N5: 1.3036 | O5: 4.1785 | P5: 5.6029 | Q5: 5.2057
B6: 左折 | C6: 5.736 | D6: 3.9786 | E6: 5.539 | F6: 4.9974 | G6: 5.2655 | H6: 5.5819 | K6: 左折 | L6: 4.9365 | M6: 0.9443 | N6: 1.2635 | O6: 3.2714 | P6: 4.3047 | Q6: 3.7923
B7: 直進 | C7: 5.2931 | D7: 8.1712 | E7: 8.7794 | F7: 8.5285 | G7: 6.6948 | H7: 7.5268 | K7: 直進 | L7: 10.8272 | M7: 13.2231 | N7: 13.1203 | O7: 12.7657 | P7: 10.8442 | Q7: 11.8791
B8: 合計 | C8: 7.4364 | D8: 7.1966 | E8: 8.3457 | F8: 7.9822 | G8: 7.8624 | H8: 8.2625 | K8: 合計 | L8: 11.168 | M8: 8.3487 | N8: 8.8502 | O8: 11.3464 | P8: 11.0672 | Q8: 11.2939
K9: 右左折_通過 | L9: 29 | M9: 17 | N9: 20 | O9: 29 | P9: 29 | Q9: 29
K10: 直進_通過 | L10: 213 | M10: 214 | N10: 214 | O10: 213 | P10: 213 | Q10: 213
B13: 500/500/500 | K13: 630/240/630
C14: 1 | D14: 2 | E14: 3 | F14: 4 | G14: 5 | H14: 6 | L14: 1 | M14: 2 | N14: 3 | O14: 4 | P14: 5 | Q14: 6
C15: 全て受け入れ | D15: 道交法 | E15: 0.2 | F15: 0.4 | G15: 既存 | H15: 提案 | L15: 全て受け入れ | M15: 道交法 | N15: 0.2 | O15: 0.4 | P15: 既存 | Q15: 提案
B16: 右折 | C16: 1.7241 | D16: 3.4709 | E16: 4.2391 | F16: 4.7011 | G16: 3.2373 | H16: 5.033 | K16: 右折 | L16: 5.4217 | M16: 1.0207 | N16: 1.5415 | O16: 1.9427 | P16: 3.8654 | Q16: 4.6238
B17: 左折 | C17: 4.4759 | D17: 2.7746 | E17: 3.6557 | F17: 3.9441 | G17: 3.2681 | H17: 4.8642 | K17: 左折 | L17: 5.6743 | M17: 1.1263 | N17: 1.8013 | O17: 1.8872 | P17: 4.3762 | Q17: 4.7447
B18: 直進 | C18: 1.5362 | D18: 4.4145 | E18: 6.6367 | F18: 5.3412 | G18: 4.1513 | H18: 5.89 | K18: 直進 | L18: 9.2347 | M18: 13.1691 | N18: 12.8857 | O18: 12.7054 | P18: 9.6053 | Q18: 11.8639
B19: 合計 | C19: 3.4073 | D19: 5.2772 | E19: 6.5246 | F19: 6.5698 | G19: 5.2705 | H19: 7.2092 | K19: 合計 | L19: 10.1487 | M19: 7.7843 | N19: 8.6397 | O19: 9.9031 | P19: 9.6087 | Q19: 11.0736
K20: 右左折_通過 | L20: 38 | M20: 22 | N20: 30 | O20: 30 | P20: 37 | Q20: 36
K21: 直進_通過 | L21: 105 | M21: 206 | N21: 206 | O21: 206 | P21: 202 | Q21: 206
B24: 600/600/600 | K24: 600/300/600
C25: 1 | D25: 2 | E25: 3 | F25: 4 | G25: 5 | H25: 6 | L25: 1 | M25: 2 | N25: 3 | O25: 4 | P25: 5 | Q25: 6
C26: 全て受け入れ | D26: 道交法 | E26: 0.2 | F26: 0.4 | G26: 既存 | H26: 提案 | L26: 全て受け入れ | M26: 道交法 | N26: 0.2 | O26: 0.4 | P26: 既存 | Q26: 提案
B27: 右折 | C27: 1.5311 | D27: 2.1942 | E27: 2.4805 | F27: 2.1735 | G27: 2.1224 | H27: 2.1522 | K27: 右折 | L27: 5.6119 | M27: 0.9712 | N27: 1.1998 | O27: 2.342 | P27: 2.2106 | Q27: 3.5282
B28: 左折 | C28: 2.0328 | D28: 1.3596 | E28: 2.1723 | F28: 1.9701 | G28: 2.2237 | H28: 2.8228 | K28: 左折 | L28: 5.1574 | M28: 0.9154 | N28: 1.0588 | O28: 2.1841 | P28: 2.0584 | Q28: 3.1177
B29: 直進 | C29: 1.7465 | D29: 2.6576 | E29: 3.0084 | F29: 2.6238 | G29: 2.2288 | H29: 2.4883 | K29: 直進 | L29: 8.1744 | M29: 13.2258 | N29: 12.9308 | O29: 12.4994 | P29: 8.4859 | Q29: 9.4958
B30: 合計 | C30: 2.9508 | D30: 3.3352 | E30: 4.1093 | F30: 3.7415 | G30: 3.6067 | H30: 4.0001 | K30: 合計 | L30: 9.3138 | M30: 7.1727 | N30: 7.4082 | O30: 8.8065 | P30: 7.3322 | Q30: 8.8734
K31: 右左折_通過 | L31: 46 | M31: 23 | N31: 27 | O31: 43 | P31: 43 | Q31: 44
K32: 直進_通過 | L32: 195 | M32: 196 | N32: 196 | O32: 195 | P32: 194 | Q32: 195
K35: 570/360/570
L36: 1 | M36: 2 | N36: 3 | O36: 4 | P36: 5 | Q36: 6
L37: 全て受け入れ | M37: 道交法 | N37: 0.2 | O37: 0.4 | P37: 既存 | Q37: 提案
K38: 右折 | L38: 4.7611 | M38: 0.9483 | N38: 1.2916 | O38: 1.9124 | P38: 3.42 | Q38: 5.3806
K39: 左折 | L39: 4.4103 | M39: 0.821 | N39: 1.1155 | O39: 1.6849 | P39: 3.2359 | Q39: 4.9159
K40: 直進 | L40: 7.3502 | M40: 13.2294 | N40: 12.9008 | O40: 12.3131 | P40: 8.1924 | Q40: 10.6313
K41: 合計 | L41: 8.435 | M41: 6.5218 | N41: 6.8819 | O41: 7.6837 | P41: 8.0459 | Q41: 10.2834
K42: 右左折_通過 | L42: 58 | M42: 26 | N42: 35 | O42: 44 | P42: 54 | Q42: 55
K43: 直進_通過 | L43: 183 | M43: 186 | N43: 186 | O43: 186 | P43: 179 | Q43: 186
K46: 540/420/540
L47: 1 | M47: 2 | N47: 3 | O47: 4 | P47: 5 | Q47: 6
L48: 全て受け入れ | M48: 道交法 | N48: 0.2 | O48: 0.4 | P48: 既存 | Q48: 提案
K49: 右折 | L49: 2.4294 | M49: 0.7899 | N49: 1.2796 | O49: 1.6845 | P49: 3.6449 | Q49: 4.6817
...

Sheet seed4
B2: 400/400/400 | D2: 600s | K2: 660/180/660
C3: 1 | D3: 2 | E3: 3 | F3: 4 | G3: 5 | H3: 6 | L3: 1 | M3: 2 | N3: 3 | O3: 4 | P3: 5 | Q3: 6
C4: 全て受け入れ | D4: 道交法 | E4: 0.2 | F4: 0.4 | G4: 既存 | H4: 提案 | L4: 全て受け入れ | M4: 道交法 | N4: 0.2 | O4: 0.4 | P4: 既存 | Q4: 提案
B5: 右折 | K5: 右折 | L5: 6.6178 | M5: 1.3552 | N5: 1.6898 | O5: 3.2151 | P5: 6.5346 | Q5: 5.6257
B6: 左折 | K6: 左折 | L6: 5.3155 | M6: 1.5917 | N6: 1.8566 | O6: 2.8517 | P6: 4.9743 | Q6: 4.3471
B7: 直進 | K7: 直進 | L7: 10.4706 | M7: 13.2305 | N7: 12.7758 | O7: 12.4665 | P7: 11.3661 | Q7: 12.3116
B8: 合計 | K8: 合計 | L8: 11.0355 | M8: 9.3157 | N8: 9.5345 | O8: 10.863 | P8: 11.4337 | Q8: 11.7693
K9: 右左折_通過 | L9: 28 | M9: 20 | N9: 25 | O9: 27 | P9: 28 | Q9: 27
K10: 直進_通過 | L10: 212 | M10: 214 | N10: 213 | O10: 214 | P10: 213 | Q10: 214
B13: 500/500/500 | K13: 630/240/630
C14: 1 | D14: 2 | E14: 3 | F14: 4 | G14: 5 | H14: 6 | L14: 1 | M14: 2 | N14: 3 | O14: 4 | P14: 5 | Q14: 6
C15: 全て受け入れ | D15: 道交法 | E15: 0.2 | F15: 0.4 | G15: 既存 | H15: 提案 | L15: 全て受け入れ | M15: 道交法 | N15: 0.2 | O15: 0.4 | P15: 既存 | Q15: 提案
B16: 右折 | K16: 右折 | L16: 4.2964 | M16: 2.0739 | N16: 2.1346 | O16: 3.4859 | P16: 5.6376 | Q16: 5.6216
B17: 左折 | K17: 左折 | L17: 4.4411 | M17: 2.1384 | N17: 2.1753 | O17: 3.3746 | P17: 5.2309 | Q17: 4.2496
B18: 直進 | K18: 直進 | L18: 9.0195 | M18: 13.2155 | N18: 12.9184 | O18: 12.0415 | P18: 10.7699 | Q18: 12.1056
B19: 合計 | K19: 合計 | L19: 9.4825 | M19: 9.3411 | N19: 9.2873 | O19: 10.4602 | P19: 10.814 | Q19: 11.3586
K20: 右左折_通過 | L20: 38 | M20: 35 | N20: 36 | O20: 37 | P20: 38 | Q20: 37
K21: 直進_通過 | L21: 200 | M21: 203 | N21: 203 | O21: 203 | P21: 201 | Q21: 203
B24: 600/600/600 | K24: 600/300/600
C25: 1 | D25: 2 | E25: 3 | F25: 4 | G25: 5 | H25: 6 | L25: 1 | M25: 2 | N25: 3 | O25: 4 | P25: 5 | Q25: 6
C26: 全て受け入れ | D26: 道交法 | E26: 0.2 | F26: 0.4 | G26: 既存 | H26: 提案 | L26: 全て受け入れ | M26: 道交法 | N26: 0.2 | O26: 0.4 | P26: 既存 | Q26: 提案
B27: 右折 | K27: 右折 | L27: 5.7818 | M27: 1.6014 | N27: 3.2457 | O27: 3.9712 | P27: 6.117 | Q27: 5.7979
B28: 左折 | K28: 左折 | L28: 3.4326 | M28: 0.991 | N28: 1.9719 | O28: 3.4002 | P28: 3.4878 | Q28: 4.7644
B29: 直進 | K29: 直進 | L29: 9.3616 | M29: 13.1973 | N29: 12.8245 | O29: 12.2094 | P29: 9.3264 | Q29: 11.6011
B30: 合計 | K30: 合計 | L30: 9.5062 | M30: 7.3928 | N30: 9.2348 | O30: 10.1761 | P30: 9.5797 | Q30: 10.9473
K31: 右左折_通過 | L31: 45 | M31: 33 | N31: 41 | O31: 44 | P31: 45 | Q31: 46
K32: 直進_通過 | L32: 190 | M32: 193 | N32: 193 | O32: 193 | P32: 190 | Q32: 193
K35: 570/360/570
L36: 1 | M36: 2 | N36: 3 | O36: 4 | P36: 5 | Q36: 6
L37: 全て受け入れ | M37: 道交法 | N37: 0.2 | O37: 0.4 | P37: 既存 | Q37: 提案
K38: 右折 | L38: 5.4205 | M38: 0.9663 | N38: 1.1948 | O38: 3.5427 | P38: 4.3667 | Q38: 4.6044
K39: 左折 | L39: 4.8652 | M39: 0.9828 | N39: 1.3233 | O39: 2.7292 | P39: 3.4703 | Q39: 3.2943
K40: 直進 | L40: 7.7209 | M40: 13.2288 | N40: 12.7157 | O40: 11.9771 | P40: 8.8502 | Q40: 10.4132
K41: 合計 | L41: 8.8497 | M41: 6.2231 | N41: 6.4757 | O41: 9.1528 | P41: 8.6409 | Q41: 9.2825
K42: 右左折_通過 | L42: 57 | M42: 33 | N42: 44 | O42: 57 | P42: 55 | Q42: 57
K43: 直進_通過 | L43: 180 | M43: 185 | N43: 184 | O43: 184 | P43: 185 | Q43: 184
K46: 540/420/540
L47: 1 | M47: 2 | N47: 3 | O47: 4 | P47: 5 | Q47: 6
L48: 全て受け入れ | M48: 道交法 | N48: 0.2 | O48: 0.4 | P48: 既存 | Q48: 提案
K49: 右折 | L49: 5.9753 | M49: 1.083 | N49: 1.1623 | O49: 2.6225 | P49: 3.229 | Q49: 4.6473
...

Sheet seed5
B2: 400/400/400 | D2: 600s | K2: 660/180/660
C3: 1 | D3: 2 | E3: 3 | F3: 4 | G3: 5 | H3: 6 | L3: 1 | M3: 2 | N3: 3 | O3: 4 | P3: 5 | Q3: 6
C4: 全て受け入れ | D4: 道交法 | E4: 0.2 | F4: 0.4 | G4: 既存 | H4: 提案 | L4: 全て受け入れ | M4: 道交法 | N4: 0.2 | O4: 0.4 | P4: 既存 | Q4: 提案
B5: 右折 | K5: 右折 | L5: 6.5976 | M5: 0.9519 | N5: 2.0391 | O5: 4.8123 | P5: 5.0511 | Q5: 5.4617
B6: 左折 | K6: 左折 | L6: 5.3719 | M6: 1.0569 | N6: 1.6881 | O6: 3.7327 | P6: 5.4001 | Q6: 4.5566
B7: 直進 | K7: 直進 | L7: 10.0713 | M7: 13.2277 | N7: 13.0719 | O7: 12.9246 | P7: 10.9294 | Q7: 12.6198
B8: 合計 | K8: 合計 | L8: 10.8715 | M8: 8.4487 | N8: 9.7733 | O8: 11.6977 | P8: 11.0493 | Q8: 11.8936
K9: 右左折_通過 | L9: 29 | M9: 16 | N9: 25 | O9: 29 | P9: 29 | Q9: 29
K10: 直進_通過 | L10: 217 | M10: 217 | N10: 217 | O10: 216 | P10: 217 | Q10: 216
B13: 500/500/500 | K13: 630/240/630
C14: 1 | D14: 2 | E14: 3 | F14: 4 | G14: 5 | H14: 6 | L14: 1 | M14: 2 | N14: 3 | O14: 4 | P14: 5 | Q14: 6
C15: 全て受け入れ | D15: 道交法 | E15: 0.2 | F15: 0.4 | G15: 既存 | H15: 提案 | L15: 全て受け入れ | M15: 道交法 | N15: 0.2 | O15: 0.4 | P15: 既存 | Q15: 提案
B16: 右折 | K16: 右折 | L16: 3.0357 | M16: 0.6376 | N16: 1.2409 | O16: 2.3099 | P16: 4.0186 | Q16: 4.4858
B17: 左折 | K17: 左折 | L17: 2.1033 | M17: 0.875 | N17: 1.1551 | O17: 1.9062 | P17: 3.0526 | Q17: 3.6901
B18: 直進 | K18: 直進 | L18: 7.8432 | M18: 13.1915 | N18: 12.9318 | O18: 12.642 | P18: 9.1125 | Q18: 11.1998
B19: 合計 | K19: 合計 | L19: 8.0381 | M19: 6.8586 | N19: 7.737 | O19: 9.3777 | P19: 9.2628 | Q19: 10.5296
K20: 右左折_通過 | L20: 28 | M20: 19 | N20: 27 | O20: 30 | P20: 36 | Q20: 39
K21: 直進_通過 | L21: 206 | M21: 209 | N21: 209 | O21: 209 | P21: 206 | Q21: 208
B24: 600/600/600 | K24: 600/300/600
C25: 1 | D25: 2 | E25: 3 | F25: 4 | G25: 5 | H25: 6 | L25: 1 | M25: 2 | N25: 3 | O25: 4 | P25: 5 | Q25: 6
C26: 全て受け入れ | D26: 道交法 | E26: 0.2 | F26: 0.4 | G26: 既存 | H26: 提案 | L26: 全て受け入れ | M26: 道交法 | N26: 0.2 | O26: 0.4 | P26: 既存 | Q26: 提案
B27: 右折 | K27: 右折 | L27: 3.7682 | M27: 0.9432 | N27: 1.1648 | O27: 2.106 | P27: 3.05 | Q27: 4.8791
B28: 左折 | K28: 左折 | L28: 3.679 | M28: 0.9423 | N28: 1.224 | O28: 2.5024 | P28: 2.8706 | Q28: 3.8792
B29: 直進 | K29: 直進 | L29: 7.448 | M29: 13.2291 | N29: 13.0584 | O29: 12.1444 | P29: 8.2385 | Q29: 10.8952
B30: 合計 | K30: 合計 | L30: 8.1943 | M30: 7.0302 | N30: 7.3592 | O30: 8.8916 | P30: 8.0674 | Q30: 10.1851
K31: 右左折_通過 | L31: 45 | M31: 24 | N31: 30 | O31: 40 | P31: 45 | Q31: 48
K32: 直進_通過 | L32: 192 | M32: 197 | N32: 197 | O32: 197 | P32: 195 | Q32: 195
K35: 570/360/570
L36: 1 | M36: 2 | N36: 3 | O36: 4 | P36: 5 | Q36: 6
L37: 全て受け入れ | M37: 道交法 | N37: 0.2 | O37: 0.4 | P37: 既存 | Q37: 提案
K38: 右折 | L38: 4.4712 | M38: 0.8773 | N38: 1.2953 | O38: 1.8045 | P38: 3.7508 | Q38: 2.9614
K39: 左折 | L39: 3.4599 | M39: 0.792 | N39: 1.11 | O39: 1.7544 | P39: 3.1561 | Q39: 2.8846
K40: 直進 | L40: 6.672 | M40: 13.2053 | N40: 12.8422 | O40: 12.4939 | P40: 7.4717 | Q40: 9.9788
K41: 合計 | L41: 7.6901 | M41: 6.2209 | N41: 6.8497 | O41: 7.5742 | P41: 7.876 | Q41: 8.4781
K42: 右左折_通過 | L42: 58 | M42: 26 | N42: 35 | O42: 47 | P42: 55 | Q42: 49
K43: 直進_通過 | L43: 181 | M43: 186 | N43: 186 | O43: 185 | P43: 183 | Q43: 184
K46: 540/420/540
L47: 1 | M47: 2 | N47: 3 | O47: 4 | P47: 5 | Q47: 6
L48: 全て受け入れ | M48: 道交法 | N48: 0.2 | O48: 0.4 | P48: 既存 | Q48: 提案
K49: 右折 | L49: 2.4049 | M49: 1.1405 | N49: 1.3715 | O49: 1.6524 | P49: 3.4342 | Q49: 3.8408
...

Sheet 平均
B2: 400/400/400 | K2: 660/180/660
C3: 1 | D3: 2 | E3: 3 | F3: 4 | G3: 5 | H3: 6 | L3: 1 | M3: 2 | N3: 3 | O3: 4 | P3: 5 | Q3: 6
C4: 全て受け入れ | D4: 道交法 | E4: 0.2 | F4: 0.4 | G4: 既存 | H4: 提案 | L4: 全て受け入れ | M4: 道交法 | N4: 0.2 | O4: 0.4 | P4: 既存 | Q4: 提案 | X4: 180 | Y4: 300 | Z4: 360 | AA4: 420
B5: 右折 | C5: =ROUND(AVERAGE(seed1!C5,seed2!C5,seed3!C5,seed4!C5,seed5!C5),4) -> 5.0141 | D5: =ROUND(AVERAGE(seed1!D5,seed2!D5,seed3!D5,seed4!D5,seed5!D5),4) -> 5.1676 | E5: =ROUND(AVERAGE(seed1!E5,seed2!E5,seed3!E5,seed4!E5,seed5!E5),4) -> 5.587 | F5: =ROUND(AVERAGE(seed1!F5,seed2!F5,seed3!F5,seed4!F5,seed5!F5),4) -> 4.5356 | G5: =ROUND(AVERAGE(seed1!G5,seed2!G5,seed3!G5,seed4!G5,seed5!G5),4) -> 5.6414 | H5: =ROUND(AVERAGE(seed1!H5,seed2!H5,seed3!H5,seed4!H5,seed5!H5),4) -> 5.7118 | K5: 右折 | L5: =ROUND(AVERAGE(seed1!L5,seed2!L5,seed3!L5,seed4!L5,seed5!L5),4) -> 6.3352 | M5: =ROUND(AVERAGE(seed1!M5,seed2!M5,seed3!M5,seed4!M5,seed5!M5),4) -> 1.2466 | N5: =ROUND(AVERAGE(seed1!N5,seed2!N5,seed3!N5,seed4!N5,seed5!N5),4) -> 2.1851 | O5: =ROUND(AVERAGE(seed1!O5,seed2!O5,seed3!O5,seed4!O5,seed5!O5),4) -> 4.1663 | P5: =ROUND(AVERAGE(seed1!P5,seed2!P5,seed3!P5,seed4!P5,seed5!P5),4) -> 5.5818 | Q5: =ROUND(AVERAGE(seed1!Q5,seed2!Q5,seed3!Q5,seed4!Q5,seed5!Q5),4) -> 5.4079 | W5: 100%受け入れ | X5: 11.3074 | Y5: 9.2329 | Z5: 6.9719 | AA5: 6.8955
B6: 左折 | C6: =ROUND(AVERAGE(seed1!C6,seed2!C6,seed3!C6,seed4!C6,seed5!C6),4) -> 5.5177 | D6: =ROUND(AVERAGE(seed1!D6,seed2!D6,seed3!D6,seed4!D6,seed5!D6),4) -> 4.0211 | E6: =ROUND(AVERAGE(seed1!E6,seed2!E6,seed3!E6,seed4!E6,seed5!E6),4) -> 4.9473 | F6: =ROUND(AVERAGE(seed1!F6,seed2!F6,seed3!F6,seed4!F6,seed5!F6),4) -> 3.6069 | G6: =ROUND(AVERAGE(seed1!G6,seed2!G6,seed3!G6,seed4!G6,seed5!G6),4) -> 5.0275 | H6: =ROUND(AVERAGE(seed1!H6,seed2!H6,seed3!H6,seed4!H6,seed5!H6),4) -> 5.3461 | K6: 左折 | L6: =ROUND(AVERAGE(seed1!L6,seed2!L6,seed3!L6,seed4!L6,seed5!L6),4) -> 5.3634 | M6: =ROUND(AVERAGE(seed1!M6,seed2!M6,seed3!M6,seed4!M6,seed5!M6),4) -> 1.2218 | N6: =ROUND(AVERAGE(seed1!N6,seed2!N6,seed3!N6,seed4!N6,seed5!N6),4) -> 1.9349 | O6: =ROUND(AVERAGE(seed1!O6,seed2!O6,seed3!O6,seed4!O6,seed5!O6),4) -> 3.1565 | P6: =ROUND(AVERAGE(seed1!P6,seed2!P6,seed3!P6,seed4!P6,seed5!P6),4) -> 4.6466 | Q6: =ROUND(AVERAGE(seed1!Q6,seed2!Q6,seed3!Q6,seed4!Q6,seed5!Q6),4) -> 4.3086 | W6: 道交法ベース | X6: 8.5501 | Y6: 7.3219 | Z6: 6.2888 | AA6: 5.3544
B7: 直進 | C7: =ROUND(AVERAGE(seed1!C7,seed2!C7,seed3!C7,seed4!C7,seed5!C7),4) -> 5.3369 | D7: =ROUND(AVERAGE(seed1!D7,seed2!D7,seed3!D7,seed4!D7,seed5!D7),4) -> 7.871 | E7: =ROUND(AVERAGE(seed1!E7,seed2!E7,seed3!E7,seed4!E7,seed5!E7),4) -> 8.3345 | F7: =ROUND(AVERAGE(seed1!F7,seed2!F7,seed3!F7,seed4!F7,seed5!F7),4) -> 6.1604 | G7: =ROUND(AVERAGE(seed1!G7,seed2!G7,seed3!G7,seed4!G7,seed5!G7),4) -> 6.509 | H7: =ROUND(AVERAGE(seed1!H7,seed2!H7,seed3!H7,seed4!H7,seed5!H7),4) -> 7.1756 | K7: 直進 | L7: =ROUND(AVERAGE(seed1!L7,seed2!L7,seed3!L7,seed4!L7,seed5!L7),4) -> 10.6152 | M7: =ROUND(AVERAGE(seed1!M7,seed2!M7,seed3!M7,seed4!M7,seed5!M7),4) -> 13.1634 | N7: =ROUND(AVERAGE(seed1!N7,seed2!N7,seed3!N7,seed4!N7,seed5!N7),4) -> 12.9713 | O7: =ROUND(AVERAGE(seed1!O7,seed2!O7,seed3!O7,seed4!O7,seed5!O7),4) -> 12.6276 | P7: =ROUND(AVERAGE(seed1!P7,seed2!P7,seed3!P7,seed4!P7,seed5!P7),4) -> 11.0643 | Q7: =ROUND(AVERAGE(seed1!Q7,seed2!Q7,seed3!Q7,seed4!Q7,seed5!Q7),4) -> 12.3351 | W7: 速度変化率 | X7: 10.1057 | Y7: 7.7754 | Z7: 6.9744 | AA7: 6.2559
B8: 合計 | C8: =ROUND(AVERAGE(seed1!C8,seed2!C8,seed3!C8,seed4!C8,seed5!C8),4) -> 7.1926 | D8: =ROUND(AVERAGE(seed1!D8,seed2!D8,seed3!D8,seed4!D8,seed5!D8),4) -> 7.2162 | E8: =ROUND(AVERAGE(seed1!E8,seed2!E8,seed3!E8,seed4!E8,seed5!E8),4) -> 7.8629 | F8: =ROUND(AVERAGE(seed1!F8,seed2!F8,seed3!F8,seed4!F8,seed5!F8),4) -> 6.1673 | G8: =ROUND(AVERAGE(seed1!G8,seed2!G8,seed3!G8,seed4!G8,seed5!G8),4) -> 7.5538 | H8: =ROUND(AVERAGE(seed1!H8,seed2!H8,seed3!H8,seed4!H8,seed5!H8),4) -> 7.8222 | K8: 合計 | L8: =ROUND(AVERAGE(seed1!L8,seed2!L8,seed3!L8,seed4!L8,seed5!L8),4) -> 11.1658 | M8: =ROUND(AVERAGE(seed1!M8,seed2!M8,seed3!M8,seed4!M8,seed5!M8),4) -> 8.6829 | N8: =ROUND(AVERAGE(seed1!N8,seed2!N8,seed3!N8,seed4!N8,seed5!N8),4) -> 9.925 | O8: =ROUND(AVERAGE(seed1!O8,seed2!O8,seed3!O8,seed4!O8,seed5!O8),4) -> 11.2717 | P8: =ROUND(AVERAGE(seed1!P8,seed2!P8,seed3!P8,seed4!P8,seed5!P8),4) -> 11.1541 | Q8: =ROUND(AVERAGE(seed1!Q8,seed2!Q8,seed3!Q8,seed4!Q8,seed5!Q8),4) -> 11.7161 | W8: 周辺考慮 | X8: 11.0958 | Y8: 8.7158 | Z8: 8.067 | AA8: 7.6181
K9: 右左折_通過 | L9: =ROUND(AVERAGE(seed1!L9,seed2!L9,seed3!L9,seed4!L9,seed5!L9),1) -> 28 | M9: =ROUND(AVERAGE(seed1!M9,seed2!M9,seed3!M9,seed4!M9,seed5!M9),1) -> 19.2 | N9: =ROUND(AVERAGE(seed1!N9,seed2!N9,seed3!N9,seed4!N9,seed5!N9),1) -> 24.6 | O9: =ROUND(AVERAGE(seed1!O9,seed2!O9,seed3!O9,seed4!O9,seed5!O9),1) -> 27.8 | P9: =ROUND(AVERAGE(seed1!P9,seed2!P9,seed3!P9,seed4!P9,seed5!P9),1) -> 28.2 | Q9: =ROUND(AVERAGE(seed1!Q9,seed2!Q9,seed3!Q9,seed4!Q9,seed5!Q9),1) -> 27.8 | S9: 30 | W9: 提案手法 | X9: 11.6391 | Y9: 9.9255 | Z9: 9.5125 | AA9: 8.8747
B10: 交差点前_平均 | C10: =ROUND(AVERAGE(C5:C7),4) -> 5.2896 | D10: =ROUND(AVERAGE(D5:D7),4) -> 5.6866 | E10: =ROUND(AVERAGE(E5:E7),4) -> 6.2896 | F10: =ROUND(AVERAGE(F5:F7),4) -> 4.7676 | G10: =ROUND(AVERAGE(G5:G7),4) -> 5.726 | H10: =ROUND(AVERAGE(H5:H7),4) -> 6.0778 | K10: 直進_通過 | L10: =ROUND(AVERAGE(seed1!L10,seed2!L10,seed3!L10,seed4!L10,seed5!L10),1) -> 214 | M10: =ROUND(AVERAGE(seed1!M10,seed2!M10,seed3!M10,seed4!M10,seed5!M10),1) -> 214.8 | N10: =ROUND(AVERAGE(seed1!N10,seed2!N10,seed3!N10,seed4!N10,seed5!N10),1) -> 214.6 | O10: =ROUND(AVERAGE(seed1!O10,seed2!O10,seed3!O10,seed4!O10,seed5!O10),1) -> 214.4 | P10: =ROUND(AVERAGE(seed1!P10,seed2!P10,seed3!P10,seed4!P10,seed5!P10),1) -> 214 | Q10: =ROUND(AVERAGE(seed1!Q10,seed2!Q10,seed3!Q10,seed4!Q10,seed5!Q10),1) -> 214.4 | S10: 220 | W10: 100%受け入れ | X10: 27.7 | Y10: 46.3 | Z10: 49.3 | AA10: 65.7
K11: 交差点前_平均 | L11: =ROUND(AVERAGE(L5:L7),4) -> 7.4379 | M11: =ROUND(AVERAGE(M5:M7),4) -> 5.2106 | N11: =ROUND(AVERAGE(N5:N7),4) -> 5.6971 | O11: =ROUND(AVERAGE(O5:O7),4) -> 6.6501 | P11: =ROUND(AVERAGE(P5:P7),4) -> 7.0976 | Q11: =ROUND(AVERAGE(Q5:Q7),4) -> 7.3505 | W11: 道交法ベース | X11: 20 | Y11: 28.7 | Z11: 27 | AA11: 23.7
W12: 速度変化率 | X12: 24.3 | Y12: 33.7 | Z12: 38.7 | AA12: 39.7
B13: 500/500/500 | K13: 630/240/630 | W13: 周辺考慮 | X13: 28 | Y13: 45.7 | Z13: 54.3 | AA13: 62
C14: 1 | D14: 2 | E14: 3 | F14: 4 | G14: 5 | H14: 6 | L14: 1 | M14: 2 | N14: 3 | O14: 4 | P14: 5 | Q14: 6 | W14: 提案手法 | X14: 27.7 | Y14: 46.3 | Z14: 56 | AA14: 64.3
C15: 全て受け入れ | D15: 道交法 | E15: 0.2 | F15: 0.4 | G15: 既存 | H15: 提案 | L15: 全て受け入れ | M15: 道交法 | N15: 0.2 | O15: 0.4 | P15: 既存 | Q15: 提案
B16: 右折 | C16: =ROUND(AVERAGE(seed1!C16,seed2!C16,seed3!C16,seed4!C16,seed5!C16),4) -> 2.3552 | D16: =ROUND(AVERAGE(seed1!D16,seed2!D16,seed3!D16,seed4!D16,seed5!D16),4) -> 3.6726 | E16: =ROUND(AVERAGE(seed1!E16,seed2!E16,seed3!E16,seed4!E16,seed5!E16),4) -> 4.5023 | F16: =ROUND(AVERAGE(seed1!F16,seed2!F16,seed3!F16,seed4!F16,seed5!F16),4) -> 4.4153 | G16: =ROUND(AVERAGE(seed1!G16,seed2!G16,seed3!G16,seed4!G16,seed5!G16),4) -> 3.6725 | H16: =ROUND(AVERAGE(seed1!H16,seed2!H16,seed3!H16,seed4!H16,seed5!H16),4) -> 4.1683 | K16: 右折 | L16: =ROUND(AVERAGE(seed1!L16,seed2!L16,seed3!L16,seed4!L16,seed5!L16),4) -> 4.6297 | M16: =ROUND(AVERAGE(seed1!M16,seed2!M16,seed3!M16,seed4!M16,seed5!M16),4) -> 1.1748 | N16: =ROUND(AVERAGE(seed1!N16,seed2!N16,seed3!N16,seed4!N16,seed5!N16),4) -> 1.9327 | O16: =ROUND(AVERAGE(seed1!O16,seed2!O16,seed3!O16,seed4!O16,seed5!O16),4) -> 2.9881 | P16: =ROUND(AVERAGE(seed1!P16,seed2!P16,seed3!P16,seed4!P16,seed5!P16),4) -> 4.6924 | Q16: =ROUND(AVERAGE(seed1!Q16,seed2!Q16,seed3!Q16,seed4!Q16,seed5!Q16),4) -> 5.0788
B17: 左折 | C17: =ROUND(AVERAGE(seed1!C17,seed2!C17,seed3!C17,seed4!C17,seed5!C17),4) -> 3.517 | D17: =ROUND(AVERAGE(seed1!D17,seed2!D17,seed3!D17,seed4!D17,seed5!D17),4) -> 2.7263 | E17: =ROUND(AVERAGE(seed1!E17,seed2!E17,seed3!E17,seed4!E17,seed5!E17),4) -> 3.4627 | F17: =ROUND(AVERAGE(seed1!F17,seed2!F17,seed3!F17,seed4!F17,seed5!F17),4) -> 3.8485 | G17: =ROUND(AVERAGE(seed1!G17,seed2!G17,seed3!G17,seed4!G17,seed5!G17),4) -> 3.4044 | H17: =ROUND(AVERAGE(seed1!H17,seed2!H17,seed3!H17,seed4!H17,seed5!H17),4) -> 4.2433 | K17: 左折 | L17: =ROUND(AVERAGE(seed1!L17,seed2!L17,seed3!L17,seed4!L17,seed5!L17),4) -> 3.8698 | M17: =ROUND(AVERAGE(seed1!M17,seed2!M17,seed3!M17,seed4!M17,seed5!M17),4) -> 1.2632 | N17: =ROUND(AVERAGE(seed1!N17,seed2!N17,seed3!N17,seed4!N17,seed5!N17),4) -> 1.8718 | O17: =ROUND(AVERAGE(seed1!O17,seed2!O17,seed3!O17,seed4!O17,seed5!O17),4) -> 2.8164 | P17: =ROUND(AVERAGE(seed1!P17,seed2!P17,seed3!P17,seed4!P17,seed5!P17),4) -> 4.4436 | Q17: =ROUND(AVERAGE(seed1!Q17,seed2!Q17,seed3!Q17,seed4!Q17,seed5!Q17),4) -> 4.5117
B18: 直進 | C18: =ROUND(AVERAGE(seed1!C18,seed2!C18,seed3!C18,seed4!C18,seed5!C18),4) -> 2.1511 | D18: =ROUND(AVERAGE(seed1!D18,seed2!D18,seed3!D18,seed4!D18,seed5!D18),4) -> 4.8586 | E18: =ROUND(AVERAGE(seed1!E18,seed2!E18,seed3!E18,seed4!E18,seed5!E18),4) -> 5.7112 | F18: =ROUND(AVERAGE(seed1!F18,seed2!F18,seed3!F18,seed4!F18,seed5!F18),4) -> 5.4159 | G18: =ROUND(AVERAGE(seed1!G18,seed2!G18,seed3!G18,seed4!G18,seed5!G18),4) -> 4.3412 | H18: =ROUND(AVERAGE(seed1!H18,seed2!H18,seed3!H18,seed4!H18,seed5!H18),4) -> 4.8142 | K18: 直進 | L18: =ROUND(AVERAGE(seed1!L18,seed2!L18,seed3!L18,seed4!L18,seed5!L18),4) -> 9.1079 | M18: =ROUND(AVERAGE(seed1!M18,seed2!M18,seed3!M18,seed4!M18,seed5!M18),4) -> 13.1877 | N18: =ROUND(AVERAGE(seed1!N18,seed2!N18,seed3!N18,seed4!N18,seed5!N18),4) -> 12.9164 | O18: =ROUND(AVERAGE(seed1!O18,seed2!O18,seed3!O18,seed4!O18,seed5!O18),4) -> 12.4976 | P18: =ROUND(AVERAGE(seed1!P18,seed2!P18,seed3!P18,seed4!P18,seed5!P18),4) -> 10.1406 | Q18: =ROUND(AVERAGE(seed1!Q18,seed2!Q18,seed3!Q18,seed4!Q18,seed5!Q18),4) -> 11.7357 | Y18: =(Y9-Y8)/((Y9+Y8)/2) -> 0.12978709 | Z18: =(Z9-Z8)/((Z9+Z8)/2) -> 0.16445291 | AA18: =(AA9-AA8)/((AA9+AA8)/2) -> 0.15238165
B19: 合計 | C19: =ROUND(AVERAGE(seed1!C19,seed2!C19,seed3!C19,seed4!C19,seed5!C19),4) -> 4.051 | D19: =ROUND(AVERAGE(seed1!D19,seed2!D19,seed3!D19,seed4!D19,seed5!D19),4) -> 5.6945 | E19: =ROUND(AVERAGE(seed1!E19,seed2!E19,seed3!E19,seed4!E19,seed5!E19),4) -> 6.5408 | F19: =ROUND(AVERAGE(seed1!F19,seed2!F19,seed3!F19,seed4!F19,seed5!F19),4) -> 6.4124 | G19: =ROUND(AVERAGE(seed1!G19,seed2!G19,seed3!G19,seed4!G19,seed5!G19),4) -> 5.6555 | H19: =ROUND(AVERAGE(seed1!H19,seed2!H19,seed3!H19,seed4!H19,seed5!H19),4) -> 7.2766 | I19: seed2 | K19: 合計 | L19: =ROUND(AVERAGE(seed1!L19,seed2!L19,seed3!L19,seed4!L19,seed5!L19),4) -> 9.5198 | M19: =ROUND(AVERAGE(seed1!M19,seed2!M19,seed3!M19,seed4!M19,seed5!M19),4) -> 7.7905 | N19: =ROUND(AVERAGE(seed1!N19,seed2!N19,seed3!N19,seed4!N19,seed5!N19),4) -> 8.915 | O19: =ROUND(AVERAGE(seed1!O19,seed2!O19,seed3!O19,seed4!O19,seed5!O19),4) -> 10.2397 | P19: =ROUND(AVERAGE(seed1!P19,seed2!P19,seed3!P19,seed4!P19,seed5!P19),4) -> 10.1473 | Q19: =ROUND(AVERAGE(seed1!Q19,seed2!Q19,seed3!Q19,seed4!Q19,seed5!Q19),4) -> 11.0795
K20: 右左折_通過 | L20: =ROUND(AVERAGE(seed1!L20,seed2!L20,seed3!L20,seed4!L20,seed5!L20),1) -> 34.6 | M20: =ROUND(AVERAGE(seed1!M20,seed2!M20,seed3!M20,seed4!M20,seed5!M20),1) -> 24.8 | N20: =ROUND(AVERAGE(seed1!N20,seed2!N20,seed3!N20,seed4!N20,seed5!N20),1) -> 31.8 | O20: =ROUND(AVERAGE(seed1!O20,seed2!O20,seed3!O20,seed4!O20,seed5!O20),1) -> 33.2 | P20: =ROUND(AVERAGE(seed1!P20,seed2!P20,seed3!P20,seed4!P20,seed5!P20),1) -> 36.2 | Q20: =ROUND(AVERAGE(seed1!Q20,seed2!Q20,seed3!Q20,seed4!Q20,seed5!Q20),1) -> 37 | S20: 40
B21: 交差点前_平均 | C21: =ROUND(AVERAGE(C16:C18),4) -> 2.6744 | D21: =ROUND(AVERAGE(D16:D18),4) -> 3.7525 | E21: =ROUND(AVERAGE(E16:E18),4) -> 4.5587 | F21: =ROUND(AVERAGE(F16:F18),4) -> 4.5599 | G21: =ROUND(AVERAGE(G16:G18),4) -> 3.806 | H21: =ROUND(AVERAGE(H16:H18),4) -> 4.4086 | K21: 直進_通過 | L21: =ROUND(AVERAGE(seed1!L21,seed2!L21,seed3!L21,seed4!L21,seed5!L21),1) -> 183.8 | M21: =ROUND(AVERAGE(seed1!M21,seed2!M21,seed3!M21,seed4!M21,seed5!M21),1) -> 205.8 | N21: =ROUND(AVERAGE(seed1!N21,seed2!N21,seed3!N21,seed4!N21,seed5!N21),1) -> 205.8 | O21: =ROUND(AVERAGE(seed1!O21,seed2!O21,seed3!O21,seed4!O21,seed5!O21),1) -> 205.8 | P21: =ROUND(AVERAGE(seed1!P21,seed2!P21,seed3!P21,seed4!P21,seed5!P21),1) -> 203 | Q21: =ROUND(AVERAGE(seed1!Q21,seed2!Q21,seed3!Q21,seed4!Q21,seed5!Q21),1) -> 205.6 | S21: 210
K22: 交差点前_平均 | L22: =ROUND(AVERAGE(L16:L18),4) -> 5.8691 | M22: =ROUND(AVERAGE(M16:M18),4) -> 5.2086 | N22: =ROUND(AVERAGE(N16:N18),4) -> 5.5736 | O22: =ROUND(AVERAGE(O16:O18),4) -> 6.1007 | P22: =ROUND(AVERAGE(P16:P18),4) -> 6.4255 | Q22: =ROUND(AVERAGE(Q16:Q18),4) -> 7.1087 | X22: 400 | Y22: 500 | Z22: 600
W23: 100%受け入れ | X23: 7.1926 | Y23: 4.051 | Z23: 2.6919
B24: 600/600/600 | K24: 600/300/600 | W24: 道交法ベース | X24: 7.2162 | Y24: 5.6945 | Z24: 3.4965
C25: 1 | D25: 2 | E25: 3 | F25: 4 | G25: 5 | H25: 6 | L25: 1 | M25: 2 | N25: 3 | O25: 4 | P25: 5 | Q25: 6 | W25: 速度変化率 | X25: 7.8629 | Y25: 6.5408 | Z25: 3.7923
C26: 全て受け入れ | D26: 道交法 | E26: 0.2 | F26: 0.4 | G26: 既存 | H26: 提案 | L26: 全て受け入れ | M26: 道交法 | N26: 0.2 | O26: 0.4 | P26: 既存 | Q26: 提案 | W26: 周辺考慮 | X26: 7.5538 | Y26: 5.6555 | Z26: 3.353
B27: 右折 | C27: =ROUND(AVERAGE(seed1!C27,seed2!C27,seed3!C27,seed4!C27,seed5!C27),4) -> 1.1962 | D27: =ROUND(AVERAGE(seed1!D27,seed2!D27,seed3!D27,seed4!D27,seed5!D27),4) -> 2.3067 | E27: =ROUND(AVERAGE(seed1!E27,seed2!E27,seed3!E27,seed4!E27,seed5!E27),4) -> 2.4276 | F27: =ROUND(AVERAGE(seed1!F27,seed2!F27,seed3!F27,seed4!F27,seed5!F27),4) -> 2.3688 | G27: =ROUND(AVERAGE(seed1!G27,seed2!G27,seed3!G27,seed4!G27,seed5!G27),4) -> 2.0056 | H27: =ROUND(AVERAGE(seed1!H27,seed2!H27,seed3!H27,seed4!H27,seed5!H27),4) -> 2.0859 | K27: 右折 | L27: =ROUND(AVERAGE(seed1!L27,seed2!L27,seed3!L27,seed4!L27,seed5!L27),4) -> 5.3018 | M27: =ROUND(AVERAGE(seed1!M27,seed2!M27,seed3!M27,seed4!M27,seed5!M27),4) -> 1.2564 | N27: =ROUND(AVERAGE(seed1!N27,seed2!N27,seed3!N27,seed4!N27,seed5!N27),4) -> 1.8027 | O27: =ROUND(AVERAGE(seed1!O27,seed2!O27,seed3!O27,seed4!O27,seed5!O27),4) -> 2.903 | P27: =ROUND(AVERAGE(seed1!P27,seed2!P27,seed3!P27,seed4!P27,seed5!P27),4) -> 4.0705 | Q27: =ROUND(AVERAGE(seed1!Q27,seed2!Q27,seed3!Q27,seed4!Q27,seed5!Q27),4) -> 4.8528 | W27: 提案手法 | X27: 7.8222 | Y27: 7.2766 | Z27: 3.7233
B28: 左折 | C28: =ROUND(AVERAGE(seed1!C28,seed2!C28,seed3!C28,seed4!C28,seed5!C28),4) -> 1.9327 | D28: =ROUND(AVERAGE(seed1!D28,seed2!D28,seed3!D28,seed4!D28,seed5!D28),4) -> 1.4152 | E28: =ROUND(AVERAGE(seed1!E28,seed2!E28,seed3!E28,seed4!E28,seed5!E28),4) -> 1.8567 | F28: =ROUND(AVERAGE(seed1!F28,seed2!F28,seed3!F28,seed4!F28,seed5!F28),4) -> 2.0288 | G28: =ROUND(AVERAGE(seed1!G28,seed2!G28,seed3!G28,seed4!G28,seed5!G28),4) -> 1.9131 | H28: =ROUND(AVERAGE(seed1!H28,seed2!H28,seed3!H28,seed4!H28,seed5!H28),4) -> 2.335 | K28: 左折 | L28: =ROUND(AVERAGE(seed1!L28,seed2!L28,seed3!L28,seed4!L28,seed5!L28),4) -> 4.4503 | M28: =ROUND(AVERAGE(seed1!M28,seed2!M28,seed3!M28,seed4!M28,seed5!M28),4) -> 1.0161 | N28: =ROUND(AVERAGE(seed1!N28,seed2!N28,seed3!N28,seed4!N28,seed5!N28),4) -> 1.4421 | O28: =ROUND(AVERAGE(seed1!O28,seed2!O28,seed3!O28,seed4!O28,seed5!O28),4) -> 2.6664 | P28: =ROUND(AVERAGE(seed1!P28,seed2!P28,seed3!P28,seed4!P28,seed5!P28),4) -> 3.3115 | Q28: =ROUND(AVERAGE(seed1!Q28,seed2!Q28,seed3!Q28,seed4!Q28,seed5!Q28),4) -> 4.1773
B29: 直進 | C29: =ROUND(AVERAGE(seed1!C29,seed2!C29,seed3!C29,seed4!C29,seed5!C29),4) -> 1.8983 | D29: =ROUND(AVERAGE(seed1!D29,seed2!D29,seed3!D29,seed4!D29,seed5!D29),4) -> 2.9228 | E29: =ROUND(AVERAGE(seed1!E29,seed2!E29,seed3!E29,seed4!E29,seed5!E29),4) -> 2.7614 | F29: =ROUND(AVERAGE(seed1!F29,seed2!F29,seed3!F29,seed4!F29,seed5!F29),4) -> 3.0223 | G29: =ROUND(AVERAGE(seed1!G29,seed2!G29,seed3!G29,seed4!G29,seed5!G29),4) -> 2.1222 | H29: =ROUND(AVERAGE(seed1!H29,seed2!H29,seed3!H29,seed4!H29,seed5!H29),4) -> 2.4382 | K29: 直進 | L29: =ROUND(AVERAGE(seed1!L29,seed2!L29,seed3!L29,seed4!L29,seed5!L29),4) -> 8.2313 | M29: =ROUND(AVERAGE(seed1!M29,seed2!M29,seed3!M29,seed4!M29,seed5!M29),4) -> 13.2147 | N29: =ROUND(AVERAGE(seed1!N29,seed2!N29,seed3!N29,seed4!N29,seed5!N29),4) -> 12.9572 | O29: =ROUND(AVERAGE(seed1!O29,seed2!O29,seed3!O29,seed4!O29,seed5!O29),4) -> 12.3209 | P29: =ROUND(AVERAGE(seed1!P29,seed2!P29,seed3!P29,seed4!P29,seed5!P29),4) -> 9.0097 | Q29: =ROUND(AVERAGE(seed1!Q29,seed2!Q29,seed3!Q29,seed4!Q29,seed5!Q29),4) -> 10.846 | Y29: =(7.2766-6.5408)/((7.2766+6.5408)/2) -> 0.10650339
B30: 合計 | C30: =ROUND(AVERAGE(seed1!C30,seed2!C30,seed3!C30,seed4!C30,seed5!C30),4) -> 2.6919 | D30: =ROUND(AVERAGE(seed1!D30,seed2!D30,seed3!D30,seed4!D30,seed5!D30),4) -> 3.4965 | E30: =ROUND(AVERAGE(seed1!E30,seed2!E30,seed3!E30,seed4!E30,seed5!E30),4) -> 3.7923 | F30: =ROUND(AVERAGE(seed1!F30,seed2!F30,seed3!F30,seed4!F30,seed5!F30),4) -> 3.9699 | G30: =ROUND(AVERAGE(seed1!G30,seed2!G30,seed3!G30,seed4!G30,seed5!G30),4) -> 3.353 | H30: =ROUND(AVERAGE(seed1!H30,seed2!H30,seed3!H30,seed4!H30,seed5!H30),4) -> 3.7233 | K30: 合計 | L30: =ROUND(AVERAGE(seed1!L30,seed2!L30,seed3!L30,seed4!L30,seed5!L30),4) -> 9.0798 | M30: =ROUND(AVERAGE(seed1!M30,seed2!M30,seed3!M30,seed4!M30,seed5!M30),4) -> 7.2777 | N30: =ROUND(AVERAGE(seed1!N30,seed2!N30,seed3!N30,seed4!N30,seed5!N30),4) -> 7.984 | O30: =ROUND(AVERAGE(seed1!O30,seed2!O30,seed3!O30,seed4!O30,seed5!O30),4) -> 9.3689 | P30: =ROUND(AVERAGE(seed1!P30,seed2!P30,seed3!P30,seed4!P30,seed5!P30),4) -> 8.7589 | Q30: =ROUND(AVERAGE(seed1!Q30,seed2!Q30,seed3!Q30,seed4!Q30,seed5!Q30),4) -> 10.1818
K31: 右左折_通過 | L31: =ROUND(AVERAGE(seed1!L31,seed2!L31,seed3!L31,seed4!L31,seed5!L31),1) -> 45.8 | M31: =ROUND(AVERAGE(seed1!M31,seed2!M31,seed3!M31,seed4!M31,seed5!M31),1) -> 28.6 | N31: =ROUND(AVERAGE(seed1!N31,seed2!N31,seed3!N31,seed4!N31,seed5!N31),1) -> 34.4 | O31: =ROUND(AVERAGE(seed1!O31,seed2!O31,seed3!O31,seed4!O31,seed5!O31),1) -> 42.6 | P31: =ROUND(AVERAGE(seed1!P31,seed2!P31,seed3!P31,seed4!P31,seed5!P31),1) -> 45.4 | Q31: =ROUND(AVERAGE(seed1!Q31,seed2!Q31,seed3!Q31,seed4!Q31,seed5!Q31),1) -> 46.6 | S31: 50
B32: 交差点前_平均 | C32: =ROUND(AVERAGE(C27:C29),4) -> 1.6757 | D32: =ROUND(AVERAGE(D27:D29),4) -> 2.2149 | E32: =ROUND(AVERAGE(E27:E29),4) -> 2.3486 | F32: =ROUND(AVERAGE(F27:F29),4) -> 2.4733 | G32: =ROUND(AVERAGE(G27:G29),4) -> 2.0136 | H32: =ROUND(AVERAGE(H27:H29),4) -> 2.2864 | K32: 直進_通過 | L32: =ROUND(AVERAGE(seed1!L32,seed2!L32,seed3!L32,seed4!L32,seed5!L32),1) -> 193.2 | M32: =ROUND(AVERAGE(seed1!M32,seed2!M32,seed3!M32,seed4!M32,seed5!M32),1) -> 195.8 | N32: =ROUND(AVERAGE(seed1!N32,seed2!N32,seed3!N32,seed4!N32,seed5!N32),1) -> 195.8 | O32: =ROUND(AVERAGE(seed1!O32,seed2!O32,seed3!O32,seed4!O32,seed5!O32),1) -> 195.6 | P32: =ROUND(AVERAGE(seed1!P32,seed2!P32,seed3!P32,seed4!P32,seed5!P32),1) -> 193.2 | Q32: =ROUND(AVERAGE(seed1!Q32,seed2!Q32,seed3!Q32,seed4!Q32,seed5!Q32),1) -> 194.2 | S32: 200 | X32: 180 | Y32: 300 | Z32: 360 | AA32: 420
K33: 交差点前_平均 | L33: =ROUND(AVERAGE(L27:L29),4) -> 5.9945 | M33: =ROUND(AVERAGE(M27:M29),4) -> 5.1624 | N33: =ROUND(AVERAGE(N27:N29),4) -> 5.4007 | O33: =ROUND(AVERAGE(O27:O29),4) -> 5.9634 | P33: =ROUND(AVERAGE(P27:P29),4) -> 5.4639 | Q33: =ROUND(AVERAGE(Q27:Q29),4) -> 6.6254 | W33: 100%受け入れ | X33: 11.3074 | Y33: 9.2329 | Z33: 6.9719 | AA33: 6.8955
W34: 道交法ベース | X34: 8.5501 | Y34: 7.3219 | Z34: 6.2888 | AA34: 5.3544
K35: 570/360/570 | W35: 速度変化率 | X35: 10.1057 | Y35: 7.7754 | Z35: 6.9744 | AA35: 6.2559
L36: 1 | M36: 2 | N36: 3 | O36: 4 | P36: 5 | Q36: 6 | W36: 周辺考慮 | X36: 11.0958 | Y36: 8.7158 | Z36: 8.067 | AA36: 7.6181
L37: 全て受け入れ | M37: 道交法 | N37: 0.2 | O37: 0.4 | P37: 既存 | Q37: 提案 | W37: 提案手法 | X37: 11.6391 | Y37: 9.9255 | Z37: 9.5125 | AA37: 8.8747
K38: 右折 | L38: =ROUND(AVERAGE(seed1!L38,seed2!L38,seed3!L38,seed4!L38,seed5!L38),4) -> 4.0349 | M38: =ROUND(AVERAGE(seed1!M38,seed2!M38,seed3!M38,seed4!M38,seed5!M38),4) -> 0.9623 | N38: =ROUND(AVERAGE(seed1!N38,seed2!N38,seed3!N38,seed4!N38,seed5!N38),4) -> 1.3067 | O38: =ROUND(AVERAGE(seed1!O38,seed2!O38,seed3!O38,seed4!O38,seed5!O38),4) -> 2.3347 | P38: =ROUND(AVERAGE(seed1!P38,seed2!P38,seed3!P38,seed4!P38,seed5!P38),4) -> 3.6872 | Q38: =ROUND(AVERAGE(seed1!Q38,seed2!Q38,seed3!Q38,seed4!Q38,seed5!Q38),4) -> 4.2384
K39: 左折 | L39: =ROUND(AVERAGE(seed1!L39,seed2!L39,seed3!L39,seed4!L39,seed5!L39),4) -> 3.6003 | M39: =ROUND(AVERAGE(seed1!M39,seed2!M39,seed3!M39,seed4!M39,seed5!M39),4) -> 0.803 | N39: =ROUND(AVERAGE(seed1!N39,seed2!N39,seed3!N39,seed4!N39,seed5!N39),4) -> 1.2702 | O39: =ROUND(AVERAGE(seed1!O39,seed2!O39,seed3!O39,seed4!O39,seed5!O39),4) -> 2.0056 | P39: =ROUND(AVERAGE(seed1!P39,seed2!P39,seed3!P39,seed4!P39,seed5!P39),4) -> 3.2919 | Q39: =ROUND(AVERAGE(seed1!Q39,seed2!Q39,seed3!Q39,seed4!Q39,seed5!Q39),4) -> 3.8635
K40: 直進 | L40: =ROUND(AVERAGE(seed1!L40,seed2!L40,seed3!L40,seed4!L40,seed5!L40),4) -> 6.6415 | M40: =ROUND(AVERAGE(seed1!M40,seed2!M40,seed3!M40,seed4!M40,seed5!M40),4) -> 13.224 | N40: =ROUND(AVERAGE(seed1!N40,seed2!N40,seed3!N40,seed4!N40,seed5!N40),4) -> 12.8223 | O40: =ROUND(AVERAGE(seed1!O40,seed2!O40,seed3!O40,seed4!O40,seed5!O40),4) -> 12.2915 | P40: =ROUND(AVERAGE(seed1!P40,seed2!P40,seed3!P40,seed4!P40,seed5!P40),4) -> 8.1725 | Q40: =ROUND(AVERAGE(seed1!Q40,seed2!Q40,seed3!Q40,seed4!Q40,seed5!Q40),4) -> 9.9962
K41: 合計 | L41: =ROUND(AVERAGE(seed1!L41,seed2!L41,seed3!L41,seed4!L41,seed5!L41),4) -> 7.4911 | M41: =ROUND(AVERAGE(seed1!M41,seed2!M41,seed3!M41,seed4!M41,seed5!M41),4) -> 6.2621 | N41: =ROUND(AVERAGE(seed1!N41,seed2!N41,seed3!N41,seed4!N41,seed5!N41),4) -> 6.8497 | O41: =ROUND(AVERAGE(seed1!O41,seed2!O41,seed3!O41,seed4!O41,seed5!O41),4) -> 8.0755 | P41: =ROUND(AVERAGE(seed1!P41,seed2!P41,seed3!P41,seed4!P41,seed5!P41),4) -> 8.1436 | Q41: =ROUND(AVERAGE(seed1!Q41,seed2!Q41,seed3!Q41,seed4!Q41,seed5!Q41),4) -> 9.2596
...
