Workbook

Sheet Sheet1
A2: 加藤さん | D2: 0 | E2: 0.1 | F2: 0.2 | G2: 0.3 | H2: 0.4 | I2: 0.5 | J2: 0.6 | K2: 0.7 | L2: 0.8 | M2: 0.9 | N2: 1 | O2: 1.1 | P2: 1.2 | Q2: 1.3 | R2: 1.4 | S2: 1.5 | T2: 1.6 | U2: 1.7 | V2: 1.8 | W2: 1.9 | X2: 2 | Y2: 2.1 | Z2: 2.2 | AA2: 2.3 | AB2: 2.4 | AC2: 2.5 | AD2: 2.6 | AE2: 2.7 | AF2: 2.8 | AG2: 2.9 | AH2: 3 | AI2: 3.1 | AJ2: 3.2 | AK2: 3.3 | AL2: 3.4 | AM2: 3.5 | AN2: 3.6 | AO2: 3.7 | AP2: 3.8 | AQ2: 3.9 | AR2: 4 | AS2: 4.1 | AT2: 4.2 | AU2: 4.3 | AV2: 4.4 | AW2: 4.5 | AX2: 4.6 | AY2: 4.7 | AZ2: 4.8 | BA2: 4.9 | BB2: 5 | BC2: 5.1 | BD2: 5.2 | BE2: 5.3 | BF2: 5.4 | BG2: 5.5 | BH2: 5.6 | BI2: 5.7 | BJ2: 5.8 | BK2: 5.9 | BL2: 6 | BM2: 6.1 | BN2: 6.2 | BO2: 6.3 | BP2: 6.4 | BQ2: 6.5 | BR2: 6.6 | BS2: 6.7 | BT2: 6.8 | BU2: 6.9 | BV2: 7 | BW2: 7.1 | BX2: 7.2 | BY2: 7.3 | BZ2: 7.4 | CA2: 7.5 | CB2: 7.6 | CC2: 7.7 | CD2: 7.8 | CE2: 7.9 | CF2: 8 | CG2: 8.1 | CH2: 8.2 | CI2: 8.3 | CJ2: 8.4 | CK2: 8.5 | CL2: 8.6 | CM2: 8.7 | CN2: 8.8 | CO2: 8.9 | CP2: 9 | CQ2: 9.1 | CR2: 9.2 | CS2: 9.3 | CT2: 9.4 | CU2: 9.5 | CV2: 9.6 | CW2: 9.7 | CX2: 9.8 | CY2: 9.9 | CZ2: 10 | DA2: 10.1 | DB2: 10.2 | DC2: 10.3 | DD2: 10.4 | DE2: 10.5 | DF2: 10.6 | DG2: 10.7 | DH2: 10.8 | DI2: 10.9 | DJ2: 11 | DK2: 11.1 | DL2: 11.2 | DM2: 11.3 | DN2: 11.4 | DO2: 11.5 | DP2: 11.6 | DQ2: 11.7 | DR2: 11.8 | DS2: 11.9 | DT2: 12 | DU2: 12.1 | DV2: 12.2 | DW2: 12.3 | DX2: 12.4 | DY2: 12.5 | DZ2: 12.6 | EA2: 12.7 | EB2: 12.8 | EC2: 12.9 | ED2: 13 | EE2: 13.1 | EF2: 13.2 | EG2: 13.3 | EH2: 13.4 | EI2: 13.5 | EJ2: 13.6 | EK2: 13.7 | EL2: 13.8 | EM2: 13.9 | EN2: 14 | EO2: 14.1 | EP2: 14.2 | EQ2: 14.3 | ER2: 14.4 | ES2: 14.5 | ET2: 14.6 | EU2: 14.7 | EV2: 14.8 | EW2: 14.9 | EX2: 15 | EY2: 15.1 | EZ2: 15.2 | FA2: 15.3 | FB2: 15.4 | FC2: 15.5 | FD2: 15.6 | FE2: 15.7 | FF2: 15.8 | FG2: 15.9 | FH2: 16 | FI2: 16.1 | FJ2: 16.2 | FK2: 16.3 | FL2: 16.4 | FM2: 16.5 | FN2: 16.6 | FO2: 16.7
A4: cav0 | B4: 1 | D4: 531 | E4: 10 | F4: 6 | G4: 6 | H4: 4 | I4: 4 | J4: 6 | K4: 4 | L4: 3 | M4: 3 | N4: 3 | O4: 4 | P4: 3 | Q4: 3 | R4: 3 | S4: 3 | T4: 3 | U4: 3 | V4: 3 | W4: 2 | X4: 3 | Y4: 3 | Z4: 2 | AA4: 3 | AB4: 1 | AC4: 4 | AD4: 2 | AE4: 2 | AF4: 2 | AG4: 2 | AH4: 3 | AI4: 2 | AJ4: 3 | AK4: 1 | AL4: 3 | AM4: 2 | AN4: 2 | AO4: 3 | AP4: 2 | AQ4: 1 | AR4: 4 | AS4: 0 | AT4: 4 | AU4: 2 | AV4: 2 | AW4: 2 | AX4: 1 | AY4: 4 | AZ4: 1 | BA4: 2 | BB4: 3 | BC4: 2 | BD4: 2 | BE4: 2 | BF4: 3 | BG4: 1 | BH4: 2 | BI4: 2 | BJ4: 3 | BK4: 3 | BL4: 3 | BM4: 1 | BN4: 3 | BO4: 1 | BP4: 2 | BQ4: 3 | BR4: 3 | BS4: 1 | BT4: 3 | BU4: 1 | BV4: 4 | BW4: 1 | BX4: 3 | BY4: 2 | BZ4: 3 | CA4: 1 | CB4: 4 | CC4: 2 | CD4: 3 | CE4: 4 | CF4: 2 | CG4: 1 | CH4: 4 | CI4: 1 | CJ4: 4 | CK4: 2 | CL4: 2 | CM4: 4 | CN4: 1 | CO4: 5 | CP4: 2 | CQ4: 3 | CR4: 2 | CS4: 3 | CT4: 3 | CU4: 3 | CV4: 4 | CW4: 3 | CX4: 4 | CY4: 3 | CZ4: 4 | DA4: 4 | DB4: 5 | DC4: 9 | DD4: 6 | DE4: 7 | DF4: 7 | DG4: 7 | DH4: 6 | DI4: 6 | DJ4: 12 | DK4: 6 | DL4: 7 | DM4: 8 | DN4: 13 | DO4: 22 | DP4: 36 | DQ4: 35 | DR4: 35 | DS4: 34 | DT4: 30 | DU4: 32 | DV4: 49 | DW4: 29 | DX4: 14 | DY4: 18 | DZ4: 19 | EA4: 10 | EB4: 9 | EC4: 16 | ED4: 12 | EE4: 20 | EF4: 22 | EG4: 34 | EH4: 27 | EI4: 26 | EJ4: 20 | EK4: 15 | EL4: 13 | EM4: 15 | EN4: 14 | EO4: 15 | EP4: 15 | EQ4: 11 | ER4: 17 | ES4: 22 | ET4: 14 | EU4: 16 | EV4: 15 | EW4: 9 | EX4: 16 | EY4: 13 | EZ4: 18 | FA4: 15 | FB4: 15 | FC4: 15 | FD4: 8 | FE4: 18 | FF4: 16 | FG4: 28 | FH4: 24 | FI4: 22 | FJ4: 34 | FK4: 24 | FL4: 41 | FM4: 33 | FN4: 87 | FO4: 1653
B5: 2 | D5: 334 | E5: 6 | F5: 4 | G5: 4 | H5: 3 | I5: 3 | J5: 3 | K5: 2 | L5: 3 | M5: 2 | N5: 1 | O5: 3 | P5: 2 | Q5: 1 | R5: 2 | S5: 2 | T5: 1 | U5: 2 | V5: 2 | W5: 2 | X5: 1 | Y5: 2 | Z5: 1 | AA5: 2 | AB5: 1 | AC5: 2 | AD5: 1 | AE5: 2 | AF5: 1 | AG5: 1 | AH5: 2 | AI5: 1 | AJ5: 2 | AK5: 2 | AL5: 0 | AM5: 2 | AN5: 1 | AO5: 2 | AP5: 3 | AQ5: 2 | AR5: 2 | AS5: 1 | AT5: 2 | AU5: 1 | AV5: 2 | AW5: 2 | AX5: 2 | AY5: 2 | AZ5: 2 | BA5: 2 | BB5: 1 | BC5: 2 | BD5: 1 | BE5: 2 | BF5: 2 | BG5: 2 | BH5: 2 | BI5: 2 | BJ5: 2 | BK5: 1 | BL5: 2 | BM5: 3 | BN5: 1 | BO5: 3 | BP5: 0 | BQ5: 4 | BR5: 0 | BS5: 2 | BT5: 2 | BU5: 2 | BV5: 3 | BW5: 1 | BX5: 3 | BY5: 2 | BZ5: 2 | CA5: 2 | CB5: 1 | CC5: 3 | CD5: 1 | CE5: 4 | CF5: 1 | CG5: 2 | CH5: 3 | CI5: 2 | CJ5: 2 | CK5: 2 | CL5: 2 | CM5: 2 | CN5: 2 | CO5: 3 | CP5: 3 | CQ5: 2 | CR5: 2 | CS5: 4 | CT5: 1 | CU5: 3 | CV5: 9 | CW5: 8 | CX5: 4 | CY5: 5 | CZ5: 5 | DA5: 4 | DB5: 12 | DC5: 7 | DD5: 13 | DE5: 11 | DF5: 15 | DG5: 17 | DH5: 16 | DI5: 17 | DJ5: 14 | DK5: 13 | DL5: 12 | DM5: 13 | DN5: 15 | DO5: 25 | DP5: 32 | DQ5: 23 | DR5: 14 | DS5: 18 | DT5: 22 | DU5: 24 | DV5: 25 | DW5: 12 | DX5: 20 | DY5: 22 | DZ5: 10 | EA5: 9 | EB5: 16 | EC5: 16 | ED5: 24 | EE5: 36 | EF5: 23 | EG5: 22 | EH5: 21 | EI5: 27 | EJ5: 15 | EK5: 12 | EL5: 10 | EM5: 15 | EN5: 11 | EO5: 12 | EP5: 13 | EQ5: 10 | ER5: 14 | ES5: 16 | ET5: 10 | EU5: 12 | EV5: 14 | EW5: 12 | EX5: 13 | EY5: 14 | EZ5: 12 | FA5: 13 | FB5: 13 | FC5: 14 | FD5: 8 | FE5: 12 | FF5: 16 | FG5: 17 | FH5: 14 | FI5: 16 | FJ5: 23 | FK5: 18 | FL5: 49 | FM5: 77 | FN5: 126 | FO5: 1704
B6: 3 | D6: 0 | E6: 0 | F6: 0 | G6: 0 | H6: 0 | I6: 0 | J6: 0 | K6: 0 | L6: 0 | M6: 0 | N6: 0 | O6: 0 | P6: 0 | Q6: 0 | R6: 0 | S6: 0 | T6: 0 | U6: 0 | V6: 0 | W6: 0 | X6: 0 | Y6: 0 | Z6: 0 | AA6: 0 | AB6: 0 | AC6: 0 | AD6: 0 | AE6: 0 | AF6: 0 | AG6: 0 | AH6: 0 | AI6: 0 | AJ6: 0 | AK6: 0 | AL6: 0 | AM6: 0 | AN6: 0 | AO6: 0 | AP6: 0 | AQ6: 0 | AR6: 0 | AS6: 0 | AT6: 0 | AU6: 0 | AV6: 0 | AW6: 0 | AX6: 0 | AY6: 0 | AZ6: 0 | BA6: 0 | BB6: 0 | BC6: 0 | BD6: 0 | BE6: 0 | BF6: 0 | BG6: 0 | BH6: 0 | BI6: 0 | BJ6: 0 | BK6: 0 | BL6: 0 | BM6: 0 | BN6: 0 | BO6: 0 | BP6: 0 | BQ6: 0 | BR6: 0 | BS6: 0 | BT6: 0 | BU6: 0 | BV6: 0 | BW6: 0 | BX6: 0 | BY6: 0 | BZ6: 0 | CA6: 0 | CB6: 0 | CC6: 0 | CD6: 0 | CE6: 0 | CF6: 0 | CG6: 0 | CH6: 0 | CI6: 0 | CJ6: 0 | CK6: 0 | CL6: 0 | CM6: 0 | CN6: 0 | CO6: 0 | CP6: 0 | CQ6: 0 | CR6: 0 | CS6: 0 | CT6: 0 | CU6: 0 | CV6: 0 | CW6: 0 | CX6: 0 | CY6: 0 | CZ6: 0 | DA6: 0 | DB6: 0 | DC6: 0 | DD6: 0 | DE6: 0 | DF6: 0 | DG6: 0 | DH6: 0 | DI6: 0 | DJ6: 0 | DK6: 0 | DL6: 0 | DM6: 0 | DN6: 0 | DO6: 0 | DP6: 0 | DQ6: 0 | DR6: 0 | DS6: 3 | DT6: 4 | DU6: 2 | DV6: 2 | DW6: 2 | DX6: 1 | DY6: 1 | DZ6: 2 | EA6: 4 | EB6: 15 | EC6: 14 | ED6: 28 | EE6: 33 | EF6: 22 | EG6: 31 | EH6: 22 | EI6: 31 | EJ6: 20 | EK6: 13 | EL6: 6 | EM6: 9 | EN6: 7 | EO6: 7 | EP6: 10 | EQ6: 7 | ER6: 7 | ES6: 9 | ET6: 6 | EU6: 8 | EV6: 7 | EW6: 7 | EX6: 9 | EY6: 8 | EZ6: 10 | FA6: 10 | FB6: 16 | FC6: 15 | FD6: 12 | FE6: 12 | FF6: 11 | FG6: 33 | FH6: 34 | FI6: 49 | FJ6: 44 | FK6: 41 | FL6: 79 | FM6: 94 | FN6: 155 | FO6: 1847
B7: 4 | D7: 300 | E7: 4 | F7: 3 | G7: 2 | H7: 3 | I7: 1 | J7: 3 | K7: 0 | L7: 2 | M7: 1 | N7: 2 | O7: 1 | P7: 1 | Q7: 2 | R7: 0 | S7: 3 | T7: 0 | U7: 2 | V7: 0 | W7: 1 | X7: 2 | Y7: 0 | Z7: 2 | AA7: 0 | AB7: 1 | AC7: 2 | AD7: 1 | AE7: 1 | AF7: 0 | AG7: 2 | AH7: 0 | AI7: 2 | AJ7: 1 | AK7: 2 | AL7: 0 | AM7: 1 | AN7: 1 | AO7: 1 | AP7: 0 | AQ7: 2 | AR7: 0 | AS7: 1 | AT7: 1 | AU7: 1 | AV7: 1 | AW7: 1 | AX7: 0 | AY7: 2 | AZ7: 0 | BA7: 1 | BB7: 2 | BC7: 1 | BD7: 1 | BE7: 0 | BF7: 2 | BG7: 0 | BH7: 1 | BI7: 1 | BJ7: 1 | BK7: 1 | BL7: 1 | BM7: 0 | BN7: 2 | BO7: 0 | BP7: 1 | BQ7: 1 | BR7: 1 | BS7: 0 | BT7: 2 | BU7: 1 | BV7: 1 | BW7: 1 | BX7: 0 | BY7: 2 | BZ7: 1 | CA7: 0 | CB7: 2 | CC7: 1 | CD7: 1 | CE7: 1 | CF7: 1 | CG7: 1 | CH7: 1 | CI7: 1 | CJ7: 1 | CK7: 1 | CL7: 1 | CM7: 1 | CN7: 1 | CO7: 2 | CP7: 0 | CQ7: 2 | CR7: 1 | CS7: 2 | CT7: 0 | CU7: 1 | CV7: 2 | CW7: 1 | CX7: 1 | CY7: 6 | CZ7: 9 | DA7: 7 | DB7: 3 | DC7: 9 | DD7: 4 | DE7: 5 | DF7: 5 | DG7: 2 | DH7: 6 | DI7: 3 | DJ7: 8 | DK7: 6 | DL7: 5 | DM7: 7 | DN7: 18 | DO7: 17 | DP7: 8 | DQ7: 6 | DR7: 12 | DS7: 10 | DT7: 11 | DU7: 8 | DV7: 9 | DW7: 4 | DX7: 7 | DY7: 9 | DZ7: 4 | EA7: 8 | EB7: 10 | EC7: 10 | ED7: 12 | EE7: 15 | EF7: 14 | EG7: 28 | EH7: 18 | EI7: 23 | EJ7: 9 | EK7: 11 | EL7: 6 | EM7: 8 | EN7: 10 | EO7: 18 | EP7: 13 | EQ7: 11 | ER7: 11 | ES7: 10 | ET7: 11 | EU7: 11 | EV7: 10 | EW7: 8 | EX7: 11 | EY7: 9 | EZ7: 10 | FA7: 12 | FB7: 12 | FC7: 12 | FD7: 20 | FE7: 28 | FF7: 32 | FG7: 34 | FH7: 38 | FI7: 60 | FJ7: 53 | FK7: 44 | FL7: 51 | FM7: 88 | FN7: 138 | FO7: 2081
B8: 5 | D8: 140 | E8: 15 | F8: 3 | G8: 3 | H8: 1 | I8: 3 | J8: 1 | K8: 2 | L8: 1 | M8: 1 | N8: 2 | O8: 0 | P8: 2 | Q8: 1 | R8: 1 | S8: 1 | T8: 2 | U8: 0 | V8: 2 | W8: 0 | X8: 2 | Y8: 2 | Z8: 1 | AA8: 2 | AB8: 2 | AC8: 1 | AD8: 1 | AE8: 2 | AF8: 1 | AG8: 1 | AH8: 1 | AI8: 2 | AJ8: 1 | AK8: 2 | AL8: 0 | AM8: 2 | AN8: 2 | AO8: 1 | AP8: 1 | AQ8: 2 | AR8: 0 | AS8: 3 | AT8: 0 | AU8: 2 | AV8: 1 | AW8: 1 | AX8: 2 | AY8: 1 | AZ8: 0 | BA8: 3 | BB8: 1 | BC8: 7 | BD8: 5 | BE8: 5 | BF8: 3 | BG8: 3 | BH8: 3 | BI8: 3 | BJ8: 3 | BK8: 1 | BL8: 4 | BM8: 3 | BN8: 3 | BO8: 1 | BP8: 3 | BQ8: 2 | BR8: 3 | BS8: 1 | BT8: 3 | BU8: 2 | BV8: 2 | BW8: 4 | BX8: 0 | BY8: 3 | BZ8: 3 | CA8: 1 | CB8: 3 | CC8: 3 | CD8: 1 | CE8: 4 | CF8: 2 | CG8: 2 | CH8: 2 | CI8: 2 | CJ8: 2 | CK8: 5 | CL8: 1 | CM8: 1 | CN8: 4 | CO8: 2 | CP8: 2 | CQ8: 2 | CR8: 2 | CS8: 4 | CT8: 2 | CU8: 3 | CV8: 2 | CW8: 3 | CX8: 3 | CY8: 2 | CZ8: 5 | DA8: 13 | DB8: 11 | DC8: 18 | DD8: 13 | DE8: 13 | DF8: 15 | DG8: 18 | DH8: 26 | DI8: 36 | DJ8: 8 | DK8: 15 | DL8: 10 | DM8: 15 | DN8: 9 | DO8: 13 | DP8: 11 | DQ8: 14 | DR8: 19 | DS8: 14 | DT8: 18 | DU8: 11 | DV8: 13 | DW8: 12 | DX8: 13 | DY8: 11 | DZ8: 13 | EA8: 12 | EB8: 14 | EC8: 23 | ED8: 23 | EE8: 27 | EF8: 14 | EG8: 28 | EH8: 22 | EI8: 18 | EJ8: 17 | EK8: 20 | EL8: 33 | EM8: 14 | EN8: 21 | EO8: 25 | EP8: 20 | EQ8: 11 | ER8: 36 | ES8: 42 | ET8: 25 | EU8: 23 | EV8: 29 | EW8: 18 | EX8: 20 | EY8: 25 | EZ8: 24 | FA8: 30 | FB8: 23 | FC8: 23 | FD8: 19 | FE8: 21 | FF8: 23 | FG8: 26 | FH8: 33 | FI8: 32 | FJ8: 41 | FK8: 37 | FL8: 51 | FM8: 82 | FN8: 136 | FO8: 1764
B9: 計 | D9: =SUM(D4:D8) -> 1305 | E9: =SUM(E4:E8) -> 35 | F9: =SUM(F4:F8) -> 16 | G9: =SUM(G4:G8) -> 15 | H9: =SUM(H4:H8) -> 11 | I9: =SUM(I4:I8) -> 11 | J9: =SUM(J4:J8) -> 13 | K9: =SUM(K4:K8) -> 8 | ... FO9: =SUM(FO4:FO8) -> 9049
B10: 累計 | D10: =C10+D9 -> 1305 | E10: =D10+E9 -> 1340 | F10: =E10+F9 -> 1356 | G10: =F10+G9 -> 1371 | H10: =G10+H9 -> 1382 | I10: =H10+I9 -> 1393 | J10: =I10+J9 -> 1406 | K10: =J10+K9 -> 1414 | ... FO10: =FN10+FO9 -> 17361
D16: =SUM(D9:M9) -> 1430 | E16: =SUM(O9:W9) -> 63 | F16: =SUM(X9:AG9) -> 64 | G16: =SUM(AH9:AQ9) -> 63 | H16: =SUM(AR9:BA9) -> 61 | I16: =SUM(BB9:BK9) -> 84 | J16: =SUM(BL9:BU9) -> 74 | K16: =SUM(BV9:CE9) -> 83 | L16: =SUM(CF9:CO9) -> 81 | M16: =SUM(CP9:CY9) -> 112 | N16: =SUM(CZ9:DI9) -> 399 | O16: =SUM(DJ9:DS9) -> 615 | P16: =SUM(DT9:EC9) -> 669 | Q16: =SUM(ED9:EM9) -> 984 | R16: =SUM(EN9:EW9) -> 710 | S16: =SUM(EX9:FG9) -> 844 | T16: =SUM(FH9:FL9) -> 952 | U16: =FM9 -> 374 | V16: =FN9 -> 642 | W16: =FO9 -> 9049
A22: cav1 | B22: 1 | D22: 0 | E22: 0 | F22: 0 | G22: 0 | H22: 0 | I22: 0 | J22: 0 | K22: 0 | L22: 0 | M22: 0 | N22: 0 | O22: 0 | P22: 0 | Q22: 0 | R22: 0 | S22: 0 | T22: 0 | U22: 0 | V22: 0 | W22: 0 | X22: 0 | Y22: 0 | Z22: 0 | AA22: 0 | AB22: 0 | AC22: 0 | AD22: 0 | AE22: 0 | AF22: 0 | AG22: 0 | AH22: 0 | AI22: 0 | AJ22: 0 | AK22: 0 | AL22: 0 | AM22: 0 | AN22: 0 | AO22: 0 | AP22: 0 | AQ22: 0 | AR22: 0 | AS22: 0 | AT22: 0 | AU22: 0 | AV22: 0 | AW22: 0 | AX22: 0 | AY22: 0 | AZ22: 0 | BA22: 0 | BB22: 0 | BC22: 0 | BD22: 0 | BE22: 0 | BF22: 0 | BG22: 0 | BH22: 0 | BI22: 0 | BJ22: 0 | BK22: 0 | BL22: 0 | BM22: 0 | BN22: 0 | BO22: 0 | BP22: 0 | BQ22: 0 | BR22: 0 | BS22: 0 | BT22: 0 | BU22: 0 | BV22: 0 | BW22: 0 | BX22: 0 | BY22: 0 | BZ22: 0 | CA22: 0 | CB22: 0 | CC22: 0 | CD22: 0 | CE22: 0 | CF22: 0 | CG22: 0 | CH22: 0 | CI22: 0 | CJ22: 0 | CK22: 0 | CL22: 0 | CM22: 0 | CN22: 0 | CO22: 0 | CP22: 0 | CQ22: 0 | CR22: 0 | CS22: 0 | CT22: 0 | CU22: 0 | CV22: 0 | CW22: 0 | CX22: 0 | CY22: 0 | CZ22: 0 | DA22: 0 | DB22: 0 | DC22: 0 | DD22: 0 | DE22: 0 | DF22: 2 | DG22: 3 | DH22: 2 | DI22: 1 | DJ22: 2 | DK22: 1 | DL22: 1 | DM22: 1 | DN22: 2 | DO22: 2 | DP22: 1 | DQ22: 7 | DR22: 6 | DS22: 3 | DT22: 6 | DU22: 0 | DV22: 3 | DW22: 4 | DX22: 1 | DY22: 3 | DZ22: 3 | EA22: 2 | EB22: 4 | EC22: 0 | ED22: 4 | EE22: 1 | EF22: 2 | EG22: 2 | EH22: 2 | EI22: 2 | EJ22: 2 | EK22: 1 | EL22: 2 | EM22: 2 | EN22: 4 | EO22: 20 | EP22: 8 | EQ22: 6 | ER22: 6 | ES22: 4 | ET22: 5 | EU22: 6 | EV22: 4 | EW22: 4 | EX22: 5 | EY22: 5 | EZ22: 4 | FA22: 6 | FB22: 5 | FC22: 4 | FD22: 6 | FE22: 5 | FF22: 5 | FG22: 7 | FH22: 4 | FI22: 6 | FJ22: 8 | FK22: 6 | FL22: 12 | FM22: 14 | FN22: 34 | FO22: 2775
B23: 2 | D23: 0 | E23: 0 | F23: 0 | G23: 0 | H23: 0 | I23: 0 | J23: 0 | K23: 0 | L23: 0 | M23: 0 | N23: 0 | O23: 0 | P23: 0 | Q23: 0 | R23: 0 | S23: 0 | T23: 0 | U23: 0 | V23: 0 | W23: 0 | X23: 0 | Y23: 0 | Z23: 0 | AA23: 0 | AB23: 0 | AC23: 0 | AD23: 0 | AE23: 0 | AF23: 0 | AG23: 0 | AH23: 0 | AI23: 0 | AJ23: 0 | AK23: 0 | AL23: 0 | AM23: 0 | AN23: 0 | AO23: 0 | AP23: 0 | AQ23: 0 | AR23: 0 | AS23: 0 | AT23: 0 | AU23: 0 | AV23: 0 | AW23: 0 | AX23: 0 | AY23: 0 | AZ23: 0 | BA23: 0 | BB23: 0 | BC23: 0 | BD23: 0 | BE23: 0 | BF23: 0 | BG23: 0 | BH23: 0 | BI23: 0 | BJ23: 0 | BK23: 0 | BL23: 0 | BM23: 0 | BN23: 0 | BO23: 0 | BP23: 0 | BQ23: 0 | BR23: 0 | BS23: 0 | BT23: 0 | BU23: 0 | BV23: 0 | BW23: 0 | BX23: 0 | BY23: 0 | BZ23: 0 | CA23: 0 | CB23: 0 | CC23: 0 | CD23: 0 | CE23: 0 | CF23: 0 | CG23: 0 | CH23: 0 | CI23: 0 | CJ23: 0 | CK23: 0 | CL23: 0 | CM23: 0 | CN23: 0 | CO23: 0 | CP23: 0 | CQ23: 0 | CR23: 0 | CS23: 0 | CT23: 10 | CU23: 3 | CV23: 3 | CW23: 2 | CX23: 1 | CY23: 2 | CZ23: 2 | DA23: 2 | DB23: 1 | DC23: 2 | DD23: 0 | DE23: 2 | DF23: 1 | DG23: 1 | DH23: 1 | DI23: 1 | DJ23: 1 | DK23: 1 | DL23: 2 | DM23: 0 | DN23: 2 | DO23: 0 | DP23: 1 | DQ23: 1 | DR23: 1 | DS23: 1 | DT23: 0 | DU23: 5 | DV23: 15 | DW23: 7 | DX23: 5 | DY23: 7 | DZ23: 5 | EA23: 1 | EB23: 5 | EC23: 2 | ED23: 2 | EE23: 3 | EF23: 3 | EG23: 3 | EH23: 2 | EI23: 3 | EJ23: 2 | EK23: 3 | EL23: 3 | EM23: 2 | EN23: 3 | EO23: 2 | EP23: 3 | EQ23: 1 | ER23: 4 | ES23: 3 | ET23: 2 | EU23: 3 | EV23: 2 | EW23: 3 | EX23: 1 | EY23: 4 | EZ23: 3 | FA23: 1 | FB23: 4 | FC23: 2 | FD23: 3 | FE23: 3 | FF23: 4 | FG23: 4 | FH23: 6 | FI23: 2 | FJ23: 6 | FK23: 6 | FL23: 6 | FM23: 9 | FN23: 14 | FO23: 3032
B24: 3 | D24: 0 | E24: 0 | F24: 0 | G24: 0 | H24: 0 | I24: 0 | J24: 0 | K24: 0 | L24: 0 | M24: 0 | N24: 0 | O24: 0 | P24: 0 | Q24: 0 | R24: 0 | S24: 0 | T24: 0 | U24: 0 | V24: 0 | W24: 0 | X24: 0 | Y24: 0 | Z24: 0 | AA24: 0 | AB24: 0 | AC24: 0 | AD24: 0 | AE24: 0 | AF24: 0 | AG24: 0 | AH24: 0 | AI24: 0 | AJ24: 0 | AK24: 0 | AL24: 0 | AM24: 0 | AN24: 0 | AO24: 0 | AP24: 0 | AQ24: 0 | AR24: 0 | AS24: 0 | AT24: 0 | AU24: 0 | AV24: 0 | AW24: 0 | AX24: 0 | AY24: 0 | AZ24: 0 | BA24: 0 | BB24: 0 | BC24: 0 | BD24: 0 | BE24: 0 | BF24: 0 | BG24: 0 | BH24: 0 | BI24: 0 | BJ24: 0 | BK24: 0 | BL24: 0 | BM24: 0 | BN24: 0 | BO24: 0 | BP24: 0 | BQ24: 0 | BR24: 0 | BS24: 0 | BT24: 0 | BU24: 0 | BV24: 0 | BW24: 0 | BX24: 0 | BY24: 0 | BZ24: 0 | CA24: 0 | CB24: 0 | CC24: 0 | CD24: 0 | CE24: 0 | CF24: 0 | CG24: 0 | CH24: 0 | CI24: 0 | CJ24: 0 | CK24: 0 | CL24: 0 | CM24: 2 | CN24: 4 | CO24: 2 | CP24: 1 | CQ24: 2 | CR24: 1 | CS24: 1 | CT24: 2 | CU24: 1 | CV24: 0 | CW24: 3 | CX24: 2 | CY24: 2 | CZ24: 1 | DA24: 1 | DB24: 1 | DC24: 1 | DD24: 1 | DE24: 1 | DF24: 5 | DG24: 4 | DH24: 2 | DI24: 3 | DJ24: 1 | DK24: 11 | DL24: 12 | DM24: 11 | DN24: 9 | DO24: 6 | DP24: 5 | DQ24: 7 | DR24: 5 | DS24: 5 | DT24: 5 | DU24: 4 | DV24: 9 | DW24: 8 | DX24: 9 | DY24: 5 | DZ24: 6 | EA24: 6 | EB24: 5 | EC24: 4 | ED24: 5 | EE24: 6 | EF24: 4 | EG24: 7 | EH24: 5 | EI24: 7 | EJ24: 2 | EK24: 6 | EL24: 7 | EM24: 4 | EN24: 4 | EO24: 4 | EP24: 7 | EQ24: 3 | ER24: 6 | ES24: 8 | ET24: 3 | EU24: 4 | EV24: 5 | EW24: 5 | EX24: 4 | EY24: 6 | EZ24: 6 | FA24: 5 | FB24: 6 | FC24: 3 | FD24: 8 | FE24: 8 | FF24: 4 | FG24: 8 | FH24: 16 | FI24: 32 | FJ24: 31 | FK24: 23 | FL24: 34 | FM24: 35 | FN24: 277 | FO24: 2274
B25: 4 | D25: 0 | E25: 0 | F25: 0 | G25: 0 | H25: 0 | I25: 0 | J25: 0 | K25: 0 | L25: 0 | M25: 0 | N25: 0 | O25: 0 | P25: 0 | Q25: 0 | R25: 0 | S25: 0 | T25: 0 | U25: 0 | V25: 0 | W25: 0 | X25: 0 | Y25: 0 | Z25: 0 | AA25: 0 | AB25: 0 | AC25: 0 | AD25: 0 | AE25: 0 | AF25: 0 | AG25: 0 | AH25: 0 | AI25: 0 | AJ25: 0 | AK25: 0 | AL25: 0 | AM25: 0 | AN25: 0 | AO25: 0 | AP25: 0 | AQ25: 0 | AR25: 0 | AS25: 0 | AT25: 0 | AU25: 0 | AV25: 0 | AW25: 0 | AX25: 0 | AY25: 0 | AZ25: 0 | BA25: 0 | BB25: 0 | BC25: 0 | BD25: 0 | BE25: 0 | BF25: 0 | BG25: 0 | BH25: 0 | BI25: 0 | BJ25: 0 | BK25: 0 | BL25: 0 | BM25: 0 | BN25: 0 | BO25: 0 | BP25: 0 | BQ25: 0 | BR25: 0 | BS25: 0 | BT25: 0 | BU25: 0 | BV25: 0 | BW25: 0 | BX25: 0 | BY25: 0 | BZ25: 0 | CA25: 0 | CB25: 0 | CC25: 0 | CD25: 0 | CE25: 0 | CF25: 0 | CG25: 0 | CH25: 0 | CI25: 0 | CJ25: 0 | CK25: 0 | CL25: 0 | CM25: 0 | CN25: 0 | CO25: 0 | CP25: 0 | CQ25: 0 | CR25: 0 | CS25: 0 | CT25: 0 | CU25: 0 | CV25: 0 | CW25: 0 | CX25: 0 | CY25: 0 | CZ25: 0 | DA25: 0 | DB25: 0 | DC25: 0 | DD25: 1 | DE25: 3 | DF25: 2 | DG25: 2 | DH25: 2 | DI25: 3 | DJ25: 4 | DK25: 2 | DL25: 3 | DM25: 5 | DN25: 1 | DO25: 4 | DP25: 4 | DQ25: 1 | DR25: 4 | DS25: 3 | DT25: 2 | DU25: 1 | DV25: 3 | DW25: 2 | DX25: 2 | DY25: 2 | DZ25: 4 | EA25: 0 | EB25: 2 | EC25: 3 | ED25: 1 | EE25: 1 | EF25: 1 | EG25: 3 | EH25: 0 | EI25: 1 | EJ25: 1 | EK25: 2 | EL25: 0 | EM25: 1 | EN25: 10 | EO25: 30 | EP25: 16 | EQ25: 10 | ER25: 9 | ES25: 8 | ET25: 7 | EU25: 9 | EV25: 5 | EW25: 6 | EX25: 6 | EY25: 6 | EZ25: 9 | FA25: 7 | FB25: 7 | FC25: 5 | FD25: 6 | FE25: 9 | FF25: 7 | FG25: 17 | FH25: 24 | FI25: 19 | FJ25: 25 | FK25: 20 | FL25: 27 | FM25: 27 | FN25: 185 | FO25: 2494
B26: 5 | D26: 0 | E26: 0 | F26: 0 | G26: 0 | H26: 0 | I26: 0 | J26: 0 | K26: 0 | L26: 0 | M26: 0 | N26: 0 | O26: 0 | P26: 0 | Q26: 0 | R26: 0 | S26: 0 | T26: 0 | U26: 0 | V26: 0 | W26: 0 | X26: 0 | Y26: 0 | Z26: 0 | AA26: 0 | AB26: 0 | AC26: 0 | AD26: 0 | AE26: 0 | AF26: 0 | AG26: 0 | AH26: 0 | AI26: 0 | AJ26: 0 | AK26: 0 | AL26: 0 | AM26: 0 | AN26: 0 | AO26: 0 | AP26: 0 | AQ26: 0 | AR26: 0 | AS26: 0 | AT26: 0 | AU26: 0 | AV26: 0 | AW26: 0 | AX26: 0 | AY26: 0 | AZ26: 0 | BA26: 0 | BB26: 0 | BC26: 0 | BD26: 0 | BE26: 0 | BF26: 0 | BG26: 0 | BH26: 0 | BI26: 0 | BJ26: 0 | BK26: 0 | BL26: 0 | BM26: 0 | BN26: 0 | BO26: 0 | BP26: 0 | BQ26: 0 | BR26: 0 | BS26: 0 | BT26: 0 | BU26: 0 | BV26: 0 | BW26: 0 | BX26: 0 | BY26: 0 | BZ26: 0 | CA26: 0 | CB26: 0 | CC26: 0 | CD26: 0 | CE26: 0 | CF26: 0 | CG26: 0 | CH26: 0 | CI26: 0 | CJ26: 0 | CK26: 0 | CL26: 0 | CM26: 0 | CN26: 0 | CO26: 0 | CP26: 0 | CQ26: 0 | CR26: 0 | CS26: 0 | CT26: 0 | CU26: 0 | CV26: 0 | CW26: 0 | CX26: 0 | CY26: 0 | CZ26: 0 | DA26: 0 | DB26: 0 | DC26: 0 | DD26: 0 | DE26: 0 | DF26: 2 | DG26: 3 | DH26: 7 | DI26: 3 | DJ26: 3 | DK26: 2 | DL26: 3 | DM26: 1 | DN26: 4 | DO26: 7 | DP26: 8 | DQ26: 15 | DR26: 12 | DS26: 10 | DT26: 9 | DU26: 13 | DV26: 5 | DW26: 6 | DX26: 4 | DY26: 4 | DZ26: 2 | EA26: 3 | EB26: 4 | EC26: 2 | ED26: 11 | EE26: 8 | EF26: 5 | EG26: 4 | EH26: 9 | EI26: 11 | EJ26: 7 | EK26: 5 | EL26: 7 | EM26: 7 | EN26: 4 | EO26: 6 | EP26: 10 | EQ26: 6 | ER26: 6 | ES26: 4 | ET26: 15 | EU26: 9 | EV26: 7 | EW26: 10 | EX26: 10 | EY26: 5 | EZ26: 8 | FA26: 14 | FB26: 11 | FC26: 6 | FD26: 11 | FE26: 9 | FF26: 8 | FG26: 31 | FH26: 37 | FI26: 27 | FJ26: 32 | FK26: 19 | FL26: 44 | FM26: 29 | FN26: 55 | FO26: 2406
B27: 計 | D27: =SUM(D22:D26) -> 0 | E27: =SUM(E22:E26) -> 0 | F27: =SUM(F22:F26) -> 0 | G27: =SUM(G22:G26) -> 0 | H27: =SUM(H22:H26) -> 0 | I27: =SUM(I22:I26) -> 0 | J27: =SUM(J22:J26) -> 0 | K27: =SUM(K22:K26) -> 0 | ... FO27: =SUM(FO22:FO26) -> 12981
B28: 累計 | D28: =C28+D27 -> 0 | E28: =D28+E27 -> 0 | F28: =E28+F27 -> 0 | G28: =F28+G27 -> 0 | H28: =G28+H27 -> 0 | I28: =H28+I27 -> 0 | J28: =I28+J27 -> 0 | K28: =J28+K27 -> 0 | ... FO28: =FN28+FO27 -> 15505
B30: 全合計 | D30: =D9+D27 -> 1305 | E30: =E9+E27 -> 35 | F30: =F9+F27 -> 16 | G30: =G9+G27 -> 15 | H30: =H9+H27 -> 11 | I30: =I9+I27 -> 11 | J30: =J9+J27 -> 13 | K30: =K9+K27 -> 8 | ... FO30: =FO9+FO27 -> 22030
B31: 累計 | D31: =C31+D30 -> 1305 | E31: =D31+E30 -> 1340 | F31: =E31+F30 -> 1356 | G31: =F31+G30 -> 1371 | H31: =G31+H30 -> 1382 | I31: =H31+I30 -> 1393 | J31: =I31+J30 -> 1406 | K31: =J31+K30 -> 1414 | ... FO31: =FN31+FO30 -> 32866
D34: =SUM(D27:M27) -> 0 | E34: =SUM(O27:W27) -> 0 | F34: =SUM(X27:AG27) -> 0 | G34: =SUM(AH27:AQ27) -> 0 | H34: =SUM(AR27:BA27) -> 0 | I34: =SUM(BB27:BK27) -> 0 | J34: =SUM(BL27:BU27) -> 0 | K34: =SUM(BV27:CE27) -> 0 | L34: =SUM(CF27:CO27) -> 8 | M34: =SUM(CP27:CY27) -> 36 | N34: =SUM(CZ27:DI27) -> 69 | O34: =SUM(DJ27:DS27) -> 204 | P34: =SUM(DT27:EC27) -> 212 | Q34: =SUM(ED27:EM27) -> 184 | R34: =SUM(EN27:EW27) -> 329 | S34: =SUM(EX27:FG27) -> 331 | T34: =SUM(FH27:FL27) -> 472 | U34: =FM27 -> 114 | V34: =FN27 -> 565 | W34: =FO27 -> 12981
A36: 全て | D36: 0 | E36: 0.1 | F36: 0.2 | G36: 0.3 | H36: 0.4 | I36: 0.5 | J36: 0.6 | K36: 0.7 | L36: 0.8 | M36: 0.9 | N36: 1 | O36: 1.1 | P36: 1.2 | Q36: 1.3 | R36: 1.4 | S36: 1.5 | T36: 1.6 | U36: 1.7 | V36: 1.8 | W36: 1.9 | X36: 2 | Y36: 2.1 | Z36: 2.2 | AA36: 2.3 | AB36: 2.4 | AC36: 2.5 | AD36: 2.6 | AE36: 2.7 | AF36: 2.8 | AG36: 2.9 | AH36: 3 | AI36: 3.1 | AJ36: 3.2 | AK36: 3.3 | AL36: 3.4 | AM36: 3.5 | AN36: 3.6 | AO36: 3.7 | AP36: 3.8 | AQ36: 3.9 | AR36: 4 | AS36: 4.1 | AT36: 4.2 | AU36: 4.3 | AV36: 4.4 | AW36: 4.5 | AX36: 4.6 | AY36: 4.7 | AZ36: 4.8 | BA36: 4.9 | BB36: 5 | BC36: 5.1 | BD36: 5.2 | BE36: 5.3 | BF36: 5.4 | BG36: 5.5 | BH36: 5.6 | BI36: 5.7 | BJ36: 5.8 | BK36: 5.9 | BL36: 6 | BM36: 6.1 | BN36: 6.2 | BO36: 6.3 | BP36: 6.4 | BQ36: 6.5 | BR36: 6.6 | BS36: 6.7 | BT36: 6.8 | BU36: 6.9 | BV36: 7 | BW36: 7.1 | BX36: 7.2 | BY36: 7.3 | BZ36: 7.4 | CA36: 7.5 | CB36: 7.6 | CC36: 7.7 | CD36: 7.8 | CE36: 7.9 | CF36: 8 | CG36: 8.1 | CH36: 8.2 | CI36: 8.3 | CJ36: 8.4 | CK36: 8.5 | CL36: 8.6 | CM36: 8.7 | CN36: 8.8 | CO36: 8.9 | CP36: 9 | CQ36: 9.1 | CR36: 9.2 | CS36: 9.3 | CT36: 9.4 | CU36: 9.5 | CV36: 9.6 | CW36: 9.7 | CX36: 9.8 | CY36: 9.9 | CZ36: 10 | DA36: 10.1 | DB36: 10.2 | DC36: 10.3 | DD36: 10.4 | DE36: 10.5 | DF36: 10.6 | DG36: 10.7 | DH36: 10.8 | DI36: 10.9 | DJ36: 11 | DK36: 11.1 | DL36: 11.2 | DM36: 11.3 | DN36: 11.4 | DO36: 11.5 | DP36: 11.6 | DQ36: 11.7 | DR36: 11.8 | DS36: 11.9 | DT36: 12 | DU36: 12.1 | DV36: 12.2 | DW36: 12.3 | DX36: 12.4 | DY36: 12.5 | DZ36: 12.6 | EA36: 12.7 | EB36: 12.8 | EC36: 12.9 | ED36: 13 | EE36: 13.1 | EF36: 13.2 | EG36: 13.3 | EH36: 13.4 | EI36: 13.5 | EJ36: 13.6 | EK36: 13.7 | EL36: 13.8 | EM36: 13.9 | EN36: 14 | EO36: 14.1 | EP36: 14.2 | EQ36: 14.3 | ER36: 14.4 | ES36: 14.5 | ET36: 14.6 | EU36: 14.7 | EV36: 14.8 | EW36: 14.9 | EX36: 15 | EY36: 15.1 | EZ36: 15.2 | FA36: 15.3 | FB36: 15.4 | FC36: 15.5 | FD36: 15.6 | FE36: 15.7 | FF36: 15.8 | FG36: 15.9 | FH36: 16 | FI36: 16.1 | FJ36: 16.2 | FK36: 16.3 | FL36: 16.4 | FM36: 16.5 | FN36: 16.6 | FO36: 16.7
A38: cav0 | B38: 1 | D38: 0 | E38: 0 | F38: 0 | G38: 0 | H38: 0 | I38: 0 | J38: 0 | K38: 0 | L38: 0 | M38: 0 | N38: 0 | O38: 0 | P38: 0 | Q38: 0 | R38: 0 | S38: 0 | T38: 0 | U38: 0 | V38: 0 | W38: 0 | X38: 0 | Y38: 0 | Z38: 0 | AA38: 0 | AB38: 0 | AC38: 2 | AD38: 1 | AE38: 1 | AF38: 1 | AG38: 0 | AH38: 2 | AI38: 1 | AJ38: 0 | AK38: 1 | AL38: 0 | AM38: 1 | AN38: 0 | AO38: 1 | AP38: 0 | AQ38: 1 | AR38: 0 | AS38: 1 | AT38: 0 | AU38: 1 | AV38: 0 | AW38: 1 | AX38: 0 | AY38: 1 | AZ38: 0 | BA38: 1 | BB38: 1 | BC38: 0 | BD38: 1 | BE38: 0 | BF38: 0 | BG38: 1 | BH38: 1 | BI38: 2 | BJ38: 0 | BK38: 2 | BL38: 0 | BM38: 2 | BN38: 1 | BO38: 1 | BP38: 1 | BQ38: 2 | BR38: 0 | BS38: 2 | BT38: 0 | BU38: 2 | BV38: 1 | BW38: 1 | BX38: 1 | BY38: 1 | BZ38: 1 | CA38: 1 | CB38: 2 | CC38: 0 | CD38: 2 | CE38: 1 | CF38: 1 | CG38: 1 | CH38: 2 | CI38: 1 | CJ38: 1 | CK38: 2 | CL38: 1 | CM38: 2 | CN38: 1 | CO38: 1 | CP38: 2 | CQ38: 1 | CR38: 2 | CS38: 2 | CT38: 2 | CU38: 5 | CV38: 7 | CW38: 5 | CX38: 5 | CY38: 13 | CZ38: 43 | DA38: 13 | DB38: 32 | DC38: 22 | DD38: 28 | DE38: 34 | DF38: 12 | DG38: 14 | DH38: 12 | DI38: 13 | DJ38: 19 | DK38: 38 | DL38: 34 | DM38: 27 | DN38: 30 | DO38: 36 | DP38: 48 | DQ38: 17 | DR38: 26 | DS38: 24 | DT38: 34 | DU38: 34 | DV38: 16 | DW38: 28 | DX38: 33 | DY38: 22 | DZ38: 27 | EA38: 13 | EB38: 17 | EC38: 29 | ED38: 30 | EE38: 37 | EF38: 34 | EG38: 57 | EH38: 27 | EI38: 40 | EJ38: 30 | EK38: 16 | EL38: 17 | EM38: 17 | EN38: 17 | EO38: 17 | EP38: 14 | EQ38: 13 | ER38: 15 | ES38: 18 | ET38: 10 | EU38: 18 | EV38: 16 | EW38: 17 | EX38: 24 | EY38: 20 | EZ38: 19 | FA38: 16 | FB38: 15 | FC38: 19 | FD38: 13 | FE38: 18 | FF38: 19 | FG38: 18 | FH38: 24 | FI38: 22 | FJ38: 31 | FK38: 26 | FL38: 43 | FM38: 59 | FN38: 101 | FO38: 1589
B39: 2 | D39: 0 | E39: 0 | F39: 0 | G39: 0 | H39: 0 | I39: 0 | J39: 0 | K39: 0 | L39: 0 | M39: 0 | N39: 0 | O39: 0 | P39: 0 | Q39: 0 | R39: 0 | S39: 0 | T39: 0 | U39: 0 | V39: 0 | W39: 0 | X39: 0 | Y39: 0 | Z39: 0 | AA39: 0 | AB39: 0 | AC39: 0 | AD39: 0 | AE39: 0 | AF39: 0 | AG39: 0 | AH39: 0 | AI39: 0 | AJ39: 0 | AK39: 0 | AL39: 0 | AM39: 0 | AN39: 0 | AO39: 0 | AP39: 0 | AQ39: 0 | AR39: 0 | AS39: 0 | AT39: 0 | AU39: 0 | AV39: 0 | AW39: 0 | AX39: 0 | AY39: 0 | AZ39: 1 | BA39: 0 | BB39: 0 | BC39: 1 | BD39: 0 | BE39: 0 | BF39: 0 | BG39: 1 | BH39: 0 | BI39: 2 | BJ39: 8 | BK39: 4 | BL39: 2 | BM39: 2 | BN39: 4 | BO39: 2 | BP39: 1 | BQ39: 4 | BR39: 0 | BS39: 3 | BT39: 2 | BU39: 1 | BV39: 2 | BW39: 1 | BX39: 2 | BY39: 1 | BZ39: 2 | CA39: 0 | CB39: 2 | CC39: 1 | CD39: 2 | CE39: 0 | CF39: 2 | CG39: 2 | CH39: 1 | CI39: 2 | CJ39: 0 | CK39: 2 | CL39: 1 | CM39: 1 | CN39: 0 | CO39: 3 | CP39: 0 | CQ39: 1 | CR39: 2 | CS39: 0 | CT39: 1 | CU39: 2 | CV39: 1 | CW39: 1 | CX39: 1 | CY39: 1 | CZ39: 3 | DA39: 1 | DB39: 5 | DC39: 10 | DD39: 5 | DE39: 6 | DF39: 6 | DG39: 11 | DH39: 10 | DI39: 25 | DJ39: 8 | DK39: 8 | DL39: 13 | DM39: 6 | DN39: 18 | DO39: 15 | DP39: 39 | DQ39: 12 | DR39: 9 | DS39: 13 | DT39: 16 | DU39: 13 | DV39: 13 | DW39: 15 | DX39: 23 | DY39: 9 | DZ39: 18 | EA39: 16 | EB39: 18 | EC39: 28 | ED39: 19 | EE39: 38 | EF39: 37 | EG39: 27 | EH39: 17 | EI39: 26 | EJ39: 15 | EK39: 8 | EL39: 13 | EM39: 13 | EN39: 9 | EO39: 10 | EP39: 9 | EQ39: 8 | ER39: 13 | ES39: 8 | ET39: 16 | EU39: 19 | EV39: 14 | EW39: 19 | EX39: 20 | EY39: 19 | EZ39: 20 | FA39: 16 | FB39: 19 | FC39: 18 | FD39: 14 | FE39: 17 | FF39: 17 | FG39: 21 | FH39: 18 | FI39: 21 | FJ39: 30 | FK39: 20 | FL39: 34 | FM39: 63 | FN39: 122 | FO39: 1967
B40: 3 | D40: 0 | E40: 0 | F40: 0 | G40: 0 | H40: 0 | I40: 0 | J40: 0 | K40: 0 | L40: 0 | M40: 0 | N40: 0 | O40: 0 | P40: 0 | Q40: 0 | R40: 0 | S40: 0 | T40: 0 | U40: 0 | V40: 0 | W40: 0 | X40: 0 | Y40: 0 | Z40: 0 | AA40: 0 | AB40: 0 | AC40: 0 | AD40: 0 | AE40: 0 | AF40: 0 | AG40: 0 | AH40: 0 | AI40: 0 | AJ40: 0 | AK40: 0 | AL40: 0 | AM40: 0 | AN40: 0 | AO40: 0 | AP40: 0 | AQ40: 0 | AR40: 0 | AS40: 0 | AT40: 0 | AU40: 0 | AV40: 0 | AW40: 0 | AX40: 0 | AY40: 0 | AZ40: 0 | BA40: 0 | BB40: 0 | BC40: 0 | BD40: 0 | BE40: 0 | BF40: 0 | BG40: 0 | BH40: 0 | BI40: 0 | BJ40: 0 | BK40: 0 | BL40: 0 | BM40: 0 | BN40: 0 | BO40: 0 | BP40: 0 | BQ40: 0 | BR40: 0 | BS40: 0 | BT40: 0 | BU40: 0 | BV40: 0 | BW40: 0 | BX40: 0 | BY40: 0 | BZ40: 0 | CA40: 0 | CB40: 0 | CC40: 0 | CD40: 0 | CE40: 0 | CF40: 0 | CG40: 0 | CH40: 0 | CI40: 0 | CJ40: 0 | CK40: 0 | CL40: 0 | CM40: 0 | CN40: 0 | CO40: 0 | CP40: 0 | CQ40: 0 | CR40: 0 | CS40: 0 | CT40: 0 | CU40: 0 | CV40: 0 | CW40: 0 | CX40: 0 | CY40: 0 | CZ40: 0 | DA40: 0 | DB40: 0 | DC40: 0 | DD40: 0 | DE40: 0 | DF40: 0 | DG40: 0 | DH40: 0 | DI40: 0 | DJ40: 0 | DK40: 0 | DL40: 0 | DM40: 0 | DN40: 0 | DO40: 0 | DP40: 0 | DQ40: 0 | DR40: 0 | DS40: 0 | DT40: 0 | DU40: 0 | DV40: 0 | DW40: 0 | DX40: 0 | DY40: 0 | DZ40: 0 | EA40: 3 | EB40: 12 | EC40: 12 | ED40: 22 | EE40: 28 | EF40: 20 | EG40: 28 | EH40: 20 | EI40: 27 | EJ40: 20 | EK40: 16 | EL40: 9 | EM40: 9 | EN40: 9 | EO40: 7 | EP40: 11 | EQ40: 8 | ER40: 8 | ES40: 9 | ET40: 7 | EU40: 8 | EV40: 8 | EW40: 7 | EX40: 11 | EY40: 8 | EZ40: 11 | FA40: 10 | FB40: 11 | FC40: 14 | FD40: 25 | FE40: 19 | FF40: 18 | FG40: 42 | FH40: 59 | FI40: 50 | FJ40: 54 | FK40: 47 | FL40: 54 | FM40: 86 | FN40: 152 | FO40: 1835
B41: 4 | D41: 0 | E41: 0 | F41: 0 | G41: 0 | H41: 0 | I41: 0 | J41: 0 | K41: 0 | L41: 0 | M41: 0 | N41: 0 | O41: 0 | P41: 0 | Q41: 0 | R41: 0 | S41: 0 | T41: 0 | U41: 0 | V41: 0 | W41: 0 | X41: 0 | Y41: 0 | Z41: 0 | AA41: 0 | AB41: 0 | AC41: 0 | AD41: 0 | AE41: 0 | AF41: 0 | AG41: 0 | AH41: 0 | AI41: 0 | AJ41: 0 | AK41: 0 | AL41: 0 | AM41: 0 | AN41: 0 | AO41: 0 | AP41: 0 | AQ41: 0 | AR41: 0 | AS41: 0 | AT41: 0 | AU41: 0 | AV41: 0 | AW41: 0 | AX41: 0 | AY41: 0 | AZ41: 0 | BA41: 0 | BB41: 0 | BC41: 0 | BD41: 3 | BE41: 3 | BF41: 2 | BG41: 2 | BH41: 0 | BI41: 3 | BJ41: 1 | BK41: 1 | BL41: 1 | BM41: 2 | BN41: 0 | BO41: 2 | BP41: 0 | BQ41: 2 | BR41: 0 | BS41: 2 | BT41: 0 | BU41: 2 | BV41: 0 | BW41: 2 | BX41: 0 | BY41: 2 | BZ41: 1 | CA41: 1 | CB41: 1 | CC41: 1 | CD41: 1 | CE41: 1 | CF41: 1 | CG41: 1 | CH41: 1 | CI41: 1 | CJ41: 1 | CK41: 1 | CL41: 1 | CM41: 2 | CN41: 0 | CO41: 2 | CP41: 0 | CQ41: 2 | CR41: 2 | CS41: 1 | CT41: 1 | CU41: 2 | CV41: 1 | CW41: 1 | CX41: 2 | CY41: 7 | CZ41: 22 | DA41: 10 | DB41: 9 | DC41: 6 | DD41: 4 | DE41: 5 | DF41: 6 | DG41: 6 | DH41: 4 | DI41: 8 | DJ41: 6 | DK41: 23 | DL41: 25 | DM41: 14 | DN41: 18 | DO41: 19 | DP41: 16 | DQ41: 20 | DR41: 21 | DS41: 17 | DT41: 15 | DU41: 16 | DV41: 20 | DW41: 23 | DX41: 17 | DY41: 19 | DZ41: 22 | EA41: 19 | EB41: 24 | EC41: 20 | ED41: 23 | EE41: 25 | EF41: 33 | EG41: 40 | EH41: 36 | EI41: 36 | EJ41: 31 | EK41: 18 | EL41: 15 | EM41: 17 | EN41: 19 | EO41: 30 | EP41: 23 | EQ41: 23 | ER41: 18 | ES41: 20 | ET41: 26 | EU41: 21 | EV41: 17 | EW41: 16 | EX41: 20 | EY41: 21 | EZ41: 19 | FA41: 20 | FB41: 21 | FC41: 22 | FD41: 30 | FE41: 37 | FF41: 49 | FG41: 46 | FH41: 52 | FI41: 76 | FJ41: 68 | FK41: 58 | FL41: 74 | FM41: 113 | FN41: 180 | FO41: 1578
B42: 5 | D42: 0 | E42: 0 | F42: 0 | G42: 0 | H42: 0 | I42: 0 | J42: 0 | K42: 0 | L42: 0 | M42: 0 | N42: 0 | O42: 0 | P42: 0 | Q42: 0 | R42: 0 | S42: 0 | T42: 0 | U42: 0 | V42: 0 | W42: 0 | X42: 0 | Y42: 0 | Z42: 0 | AA42: 0 | AB42: 0 | AC42: 0 | AD42: 0 | AE42: 0 | AF42: 0 | AG42: 0 | AH42: 0 | AI42: 0 | AJ42: 0 | AK42: 0 | AL42: 0 | AM42: 0 | AN42: 0 | AO42: 0 | AP42: 0 | AQ42: 0 | AR42: 0 | AS42: 0 | AT42: 0 | AU42: 0 | AV42: 7 | AW42: 3 | AX42: 4 | AY42: 2 | AZ42: 2 | BA42: 1 | BB42: 2 | BC42: 1 | BD42: 1 | BE42: 2 | BF42: 2 | BG42: 0 | BH42: 2 | BI42: 1 | BJ42: 1 | BK42: 1 | BL42: 0 | BM42: 2 | BN42: 1 | BO42: 1 | BP42: 1 | BQ42: 0 | BR42: 2 | BS42: 0 | BT42: 1 | BU42: 1 | BV42: 1 | BW42: 1 | BX42: 1 | BY42: 0 | BZ42: 1 | CA42: 1 | CB42: 1 | CC42: 0 | CD42: 1 | CE42: 1 | CF42: 0 | CG42: 1 | CH42: 1 | CI42: 1 | CJ42: 0 | CK42: 4 | CL42: 3 | CM42: 4 | CN42: 0 | CO42: 2 | CP42: 2 | CQ42: 2 | CR42: 1 | CS42: 2 | CT42: 0 | CU42: 4 | CV42: 0 | CW42: 2 | CX42: 2 | CY42: 1 | CZ42: 2 | DA42: 1 | DB42: 2 | DC42: 1 | DD42: 2 | DE42: 0 | DF42: 3 | DG42: 16 | DH42: 1 | DI42: 5 | DJ42: 2 | DK42: 2 | DL42: 3 | DM42: 3 | DN42: 2 | DO42: 2 | DP42: 4 | DQ42: 0 | DR42: 7 | DS42: 9 | DT42: 4 | DU42: 5 | DV42: 3 | DW42: 6 | DX42: 5 | DY42: 2 | DZ42: 6 | EA42: 2 | EB42: 9 | EC42: 7 | ED42: 9 | EE42: 13 | EF42: 15 | EG42: 25 | EH42: 12 | EI42: 9 | EJ42: 11 | EK42: 11 | EL42: 13 | EM42: 9 | EN42: 22 | EO42: 23 | EP42: 15 | EQ42: 14 | ER42: 30 | ES42: 29 | ET42: 25 | EU42: 25 | EV42: 24 | EW42: 32 | EX42: 24 | EY42: 27 | EZ42: 31 | FA42: 32 | FB42: 47 | FC42: 39 | FD42: 49 | FE42: 32 | FF42: 48 | FG42: 42 | FH42: 43 | FI42: 50 | FJ42: 53 | FK42: 53 | FL42: 63 | FM42: 53 | FN42: 246 | FO42: 2047
B43: 計 | D43: =SUM(D38:D42) -> 0 | E43: =SUM(E38:E42) -> 0 | F43: =SUM(F38:F42) -> 0 | G43: =SUM(G38:G42) -> 0 | H43: =SUM(H38:H42) -> 0 | I43: =SUM(I38:I42) -> 0 | J43: =SUM(J38:J42) -> 0 | K43: =SUM(K38:K42) -> 0 | ... FO43: =SUM(FO38:FO42) -> 9016
B44: 累計 | D44: =C44+D43 -> 0 | E44: =D44+E43 -> 0 | F44: =E44+F43 -> 0 | G44: =F44+G43 -> 0 | H44: =G44+H43 -> 0 | I44: =H44+I43 -> 0 | J44: =I44+J43 -> 0 | K44: =J44+K43 -> 0 | ... FO44: =FN44+FO43 -> 16523
D50: =SUM(D43:M43) -> 0 | E50: =SUM(O43:W43) -> 0 | F50: =SUM(X43:AG43) -> 5 | G50: =SUM(AH43:AQ43) -> 7 | H50: =SUM(AR43:BA43) -> 25 | I50: =SUM(BB43:BK43) -> 52 | J50: =SUM(BL43:BU43) -> 52 | K50: =SUM(BV43:CE43) -> 42 | L50: =SUM(CF43:CO43) -> 54 | M50: =SUM(CP43:CY43) -> 89 | N50: =SUM(CZ43:DI43) -> 418 | O50: =SUM(DJ43:DS43) -> 653 | P50: =SUM(DT43:EC43) -> 693 | Q50: =SUM(ED43:EM43) -> 1118 | R50: =SUM(EN43:EW43) -> 814 | S50: =SUM(EX43:FG43) -> 1187 | T50: =SUM(FH43:FL43) -> 1123 | U50: =FM43 -> 374 | V50: =FN43 -> 801 | W50: =FO43 -> 9016
A52: cav1 | B52: 1 | D52: 15 | E52: 4 | F52: 6 | G52: 3 | H52: 2 | I52: 4 | J52: 2 | K52: 3 | L52: 3 | M52: 6 | N52: 7 | O52: 11 | P52: 6 | Q52: 8 | R52: 9 | S52: 10 | T52: 10 | U52: 14 | V52: 10 | W52: 11 | X52: 9 | Y52: 7 | Z52: 10 | AA52: 7 | AB52: 5 | AC52: 7 | AD52: 3 | AE52: 5 | AF52: 5 | AG52: 7 | AH52: 15 | AI52: 9 | AJ52: 11 | AK52: 9 | AL52: 7 | AM52: 15 | AN52: 6 | AO52: 8 | AP52: 5 | AQ52: 9 | AR52: 8 | AS52: 8 | AT52: 9 | AU52: 7 | AV52: 8 | AW52: 9 | AX52: 6 | AY52: 9 | AZ52: 4 | BA52: 11 | BB52: 6 | BC52: 14 | BD52: 15 | BE52: 14 | BF52: 12 | BG52: 9 | BH52: 10 | BI52: 7 | BJ52: 7 | BK52: 5 | BL52: 3 | BM52: 7 | BN52: 5 | BO52: 4 | BP52: 14 | BQ52: 36 | BR52: 31 | BS52: 12 | BT52: 5 | BU52: 5 | BV52: 7 | BW52: 5 | BX52: 7 | BY52: 4 | BZ52: 9 | CA52: 9 | CB52: 11 | CC52: 10 | CD52: 10 | CE52: 12 | CF52: 7 | CG52: 8 | CH52: 7 | CI52: 8 | CJ52: 8 | CK52: 6 | CL52: 3 | CM52: 2 | CN52: 4 | CO52: 7 | CP52: 1 | CQ52: 5 | CR52: 3 | CS52: 11 | CT52: 11 | CU52: 5 | CV52: 4 | CW52: 3 | CX52: 4 | CY52: 3 | CZ52: 11 | DA52: 7 | DB52: 3 | DC52: 9 | DD52: 4 | DE52: 4 | DF52: 8 | DG52: 8 | DH52: 20 | DI52: 13 | DJ52: 8 | DK52: 8 | DL52: 11 | DM52: 13 | DN52: 14 | DO52: 13 | DP52: 5 | DQ52: 9 | DR52: 5 | DS52: 6 | DT52: 6 | DU52: 7 | DV52: 6 | DW52: 7 | DX52: 4 | DY52: 8 | DZ52: 3 | EA52: 6 | EB52: 6 | EC52: 3 | ED52: 5 | EE52: 4 | EF52: 10 | EG52: 15 | EH52: 17 | EI52: 6 | EJ52: 4 | EK52: 3 | EL52: 6 | EM52: 8 | EN52: 9 | EO52: 40 | EP52: 28 | EQ52: 10 | ER52: 12 | ES52: 11 | ET52: 9 | EU52: 11 | EV52: 8 | EW52: 8 | EX52: 11 | EY52: 10 | EZ52: 9 | FA52: 13 | FB52: 14 | FC52: 26 | FD52: 23 | FE52: 21 | FF52: 19 | FG52: 24 | FH52: 13 | FI52: 61 | FJ52: 34 | FK52: 24 | FL52: 30 | FM52: 24 | FN52: 55 | FO52: 1668
B53: 2 | D53: 0 | E53: 0 | F53: 0 | G53: 0 | H53: 0 | I53: 0 | J53: 0 | K53: 0 | L53: 0 | M53: 0 | N53: 0 | O53: 0 | P53: 0 | Q53: 0 | R53: 0 | S53: 0 | T53: 0 | U53: 0 | V53: 0 | W53: 0 | X53: 0 | Y53: 0 | Z53: 0 | AA53: 0 | AB53: 0 | AC53: 0 | AD53: 0 | AE53: 0 | AF53: 0 | AG53: 0 | AH53: 0 | AI53: 0 | AJ53: 0 | AK53: 0 | AL53: 0 | AM53: 0 | AN53: 0 | AO53: 0 | AP53: 0 | AQ53: 0 | AR53: 0 | AS53: 0 | AT53: 0 | AU53: 2 | AV53: 3 | AW53: 2 | AX53: 1 | AY53: 2 | AZ53: 1 | BA53: 5 | BB53: 2 | BC53: 2 | BD53: 1 | BE53: 1 | BF53: 2 | BG53: 2 | BH53: 7 | BI53: 4 | BJ53: 2 | BK53: 2 | BL53: 1 | BM53: 3 | BN53: 1 | BO53: 1 | BP53: 2 | BQ53: 2 | BR53: 12 | BS53: 6 | BT53: 5 | BU53: 4 | BV53: 3 | BW53: 4 | BX53: 5 | BY53: 6 | BZ53: 3 | CA53: 5 | CB53: 3 | CC53: 14 | CD53: 12 | CE53: 6 | CF53: 5 | CG53: 5 | CH53: 5 | CI53: 5 | CJ53: 5 | CK53: 5 | CL53: 5 | CM53: 3 | CN53: 10 | CO53: 16 | CP53: 10 | CQ53: 7 | CR53: 12 | CS53: 6 | CT53: 9 | CU53: 5 | CV53: 5 | CW53: 6 | CX53: 7 | CY53: 4 | CZ53: 16 | DA53: 7 | DB53: 8 | DC53: 3 | DD53: 7 | DE53: 5 | DF53: 6 | DG53: 5 | DH53: 3 | DI53: 8 | DJ53: 5 | DK53: 4 | DL53: 4 | DM53: 6 | DN53: 3 | DO53: 4 | DP53: 9 | DQ53: 47 | DR53: 22 | DS53: 18 | DT53: 22 | DU53: 22 | DV53: 18 | DW53: 23 | DX53: 35 | DY53: 38 | DZ53: 31 | EA53: 37 | EB53: 37 | EC53: 31 | ED53: 17 | EE53: 15 | EF53: 24 | EG53: 26 | EH53: 17 | EI53: 13 | EJ53: 15 | EK53: 15 | EL53: 14 | EM53: 17 | EN53: 15 | EO53: 64 | EP53: 43 | EQ53: 17 | ER53: 15 | ES53: 15 | ET53: 13 | EU53: 13 | EV53: 11 | EW53: 11 | EX53: 23 | EY53: 31 | EZ53: 28 | FA53: 59 | FB53: 33 | FC53: 33 | FD53: 21 | FE53: 18 | FF53: 27 | FG53: 24 | FH53: 40 | FI53: 60 | FJ53: 53 | FK53: 54 | FL53: 61 | FM53: 51 | FN53: 92 | FO53: 1557
B54: 3 | D54: 0 | E54: 0 | F54: 0 | G54: 0 | H54: 0 | I54: 0 | J54: 0 | K54: 0 | L54: 0 | M54: 0 | N54: 0 | O54: 0 | P54: 0 | Q54: 0 | R54: 0 | S54: 0 | T54: 0 | U54: 0 | V54: 0 | W54: 0 | X54: 0 | Y54: 0 | Z54: 0 | AA54: 0 | AB54: 0 | AC54: 0 | AD54: 0 | AE54: 0 | AF54: 0 | AG54: 0 | AH54: 0 | AI54: 0 | AJ54: 0 | AK54: 0 | AL54: 0 | AM54: 0 | AN54: 0 | AO54: 0 | AP54: 0 | AQ54: 0 | AR54: 0 | AS54: 0 | AT54: 0 | AU54: 0 | AV54: 0 | AW54: 0 | AX54: 0 | AY54: 0 | AZ54: 0 | BA54: 0 | BB54: 0 | BC54: 0 | BD54: 0 | BE54: 0 | BF54: 0 | BG54: 0 | BH54: 0 | BI54: 0 | BJ54: 0 | BK54: 0 | BL54: 0 | BM54: 0 | BN54: 0 | BO54: 0 | BP54: 0 | BQ54: 0 | BR54: 0 | BS54: 0 | BT54: 0 | BU54: 0 | BV54: 0 | BW54: 0 | BX54: 0 | BY54: 0 | BZ54: 5 | CA54: 5 | CB54: 4 | CC54: 1 | CD54: 2 | CE54: 1 | CF54: 1 | CG54: 2 | CH54: 1 | CI54: 0 | CJ54: 2 | CK54: 1 | CL54: 1 | CM54: 2 | CN54: 0 | CO54: 1 | CP54: 1 | CQ54: 1 | CR54: 10 | CS54: 3 | CT54: 4 | CU54: 3 | CV54: 2 | CW54: 5 | CX54: 1 | CY54: 4 | CZ54: 2 | DA54: 2 | DB54: 2 | DC54: 2 | DD54: 3 | DE54: 1 | DF54: 5 | DG54: 5 | DH54: 3 | DI54: 12 | DJ54: 8 | DK54: 7 | DL54: 4 | DM54: 6 | DN54: 6 | DO54: 6 | DP54: 6 | DQ54: 5 | DR54: 3 | DS54: 3 | DT54: 7 | DU54: 4 | DV54: 5 | DW54: 4 | DX54: 3 | DY54: 9 | DZ54: 4 | EA54: 5 | EB54: 3 | EC54: 4 | ED54: 5 | EE54: 3 | EF54: 3 | EG54: 4 | EH54: 5 | EI54: 3 | EJ54: 5 | EK54: 5 | EL54: 4 | EM54: 4 | EN54: 3 | EO54: 4 | EP54: 4 | EQ54: 5 | ER54: 3 | ES54: 5 | ET54: 5 | EU54: 3 | EV54: 6 | EW54: 3 | EX54: 4 | EY54: 6 | EZ54: 3 | FA54: 6 | FB54: 7 | FC54: 4 | FD54: 6 | FE54: 8 | FF54: 5 | FG54: 17 | FH54: 15 | FI54: 37 | FJ54: 39 | FK54: 30 | FL54: 44 | FM54: 41 | FN54: 258 | FO54: 2259
B55: 4 | D55: 0 | E55: 0 | F55: 0 | G55: 0 | H55: 0 | I55: 0 | J55: 0 | K55: 0 | L55: 0 | M55: 0 | N55: 0 | O55: 0 | P55: 0 | Q55: 0 | R55: 0 | S55: 0 | T55: 0 | U55: 0 | V55: 0 | W55: 0 | X55: 0 | Y55: 0 | Z55: 0 | AA55: 0 | AB55: 0 | AC55: 0 | AD55: 0 | AE55: 0 | AF55: 0 | AG55: 0 | AH55: 0 | AI55: 0 | AJ55: 0 | AK55: 0 | AL55: 0 | AM55: 0 | AN55: 0 | AO55: 0 | AP55: 0 | AQ55: 0 | AR55: 0 | AS55: 0 | AT55: 0 | AU55: 0 | AV55: 0 | AW55: 0 | AX55: 0 | AY55: 0 | AZ55: 0 | BA55: 0 | BB55: 0 | BC55: 0 | BD55: 0 | BE55: 0 | BF55: 0 | BG55: 0 | BH55: 0 | BI55: 0 | BJ55: 0 | BK55: 0 | BL55: 0 | BM55: 0 | BN55: 0 | BO55: 0 | BP55: 0 | BQ55: 0 | BR55: 0 | BS55: 0 | BT55: 0 | BU55: 0 | BV55: 0 | BW55: 0 | BX55: 0 | BY55: 0 | BZ55: 0 | CA55: 0 | CB55: 0 | CC55: 0 | CD55: 0 | CE55: 0 | CF55: 0 | CG55: 0 | CH55: 0 | CI55: 0 | CJ55: 0 | CK55: 0 | CL55: 0 | CM55: 0 | CN55: 1 | CO55: 5 | CP55: 2 | CQ55: 3 | CR55: 1 | CS55: 2 | CT55: 3 | CU55: 3 | CV55: 2 | CW55: 6 | CX55: 5 | CY55: 1 | CZ55: 4 | DA55: 2 | DB55: 4 | DC55: 6 | DD55: 10 | DE55: 16 | DF55: 15 | DG55: 12 | DH55: 9 | DI55: 8 | DJ55: 9 | DK55: 7 | DL55: 7 | DM55: 9 | DN55: 12 | DO55: 15 | DP55: 13 | DQ55: 7 | DR55: 10 | DS55: 10 | DT55: 10 | DU55: 8 | DV55: 8 | DW55: 6 | DX55: 4 | DY55: 17 | DZ55: 7 | EA55: 7 | EB55: 5 | EC55: 5 | ED55: 7 | EE55: 7 | EF55: 5 | EG55: 69 | EH55: 29 | EI55: 27 | EJ55: 26 | EK55: 19 | EL55: 23 | EM55: 21 | EN55: 17 | EO55: 27 | EP55: 26 | EQ55: 24 | ER55: 32 | ES55: 17 | ET55: 20 | EU55: 14 | EV55: 29 | EW55: 25 | EX55: 21 | EY55: 16 | EZ55: 13 | FA55: 15 | FB55: 14 | FC55: 15 | FD55: 18 | FE55: 15 | FF55: 15 | FG55: 35 | FH55: 39 | FI55: 38 | FJ55: 48 | FK55: 32 | FL55: 40 | FM55: 37 | FN55: 205 | FO55: 1809
B56: 5 | D56: 42 | E56: 14 | F56: 6 | G56: 4 | H56: 7 | I56: 5 | J56: 5 | K56: 4 | L56: 3 | M56: 4 | N56: 2 | O56: 12 | P56: 7 | Q56: 7 | R56: 8 | S56: 6 | T56: 6 | U56: 7 | V56: 7 | W56: 5 | X56: 6 | Y56: 11 | Z56: 22 | AA56: 12 | AB56: 19 | AC56: 11 | AD56: 21 | AE56: 16 | AF56: 26 | AG56: 28 | AH56: 15 | AI56: 21 | AJ56: 28 | AK56: 34 | AL56: 38 | AM56: 35 | AN56: 40 | AO56: 28 | AP56: 27 | AQ56: 18 | AR56: 21 | AS56: 32 | AT56: 24 | AU56: 25 | AV56: 24 | AW56: 31 | AX56: 26 | AY56: 26 | AZ56: 13 | BA56: 13 | BB56: 18 | BC56: 25 | BD56: 9 | BE56: 10 | BF56: 9 | BG56: 17 | BH56: 26 | BI56: 26 | BJ56: 21 | BK56: 37 | BL56: 20 | BM56: 12 | BN56: 15 | BO56: 15 | BP56: 17 | BQ56: 15 | BR56: 37 | BS56: 35 | BT56: 15 | BU56: 20 | BV56: 18 | BW56: 21 | BX56: 14 | BY56: 11 | BZ56: 9 | CA56: 16 | CB56: 13 | CC56: 10 | CD56: 20 | CE56: 16 | CF56: 12 | CG56: 12 | CH56: 9 | CI56: 13 | CJ56: 10 | CK56: 5 | CL56: 6 | CM56: 8 | CN56: 9 | CO56: 16 | CP56: 7 | CQ56: 13 | CR56: 11 | CS56: 9 | CT56: 18 | CU56: 4 | CV56: 6 | CW56: 7 | CX56: 5 | CY56: 9 | CZ56: 7 | DA56: 5 | DB56: 10 | DC56: 12 | DD56: 9 | DE56: 8 | DF56: 10 | DG56: 9 | DH56: 11 | DI56: 13 | DJ56: 12 | DK56: 14 | DL56: 15 | DM56: 10 | DN56: 10 | DO56: 10 | DP56: 10 | DQ56: 9 | DR56: 12 | DS56: 9 | DT56: 10 | DU56: 9 | DV56: 12 | DW56: 13 | DX56: 9 | DY56: 9 | DZ56: 8 | EA56: 15 | EB56: 13 | EC56: 10 | ED56: 14 | EE56: 17 | EF56: 11 | EG56: 9 | EH56: 10 | EI56: 11 | EJ56: 7 | EK56: 10 | EL56: 8 | EM56: 9 | EN56: 8 | EO56: 13 | EP56: 13 | EQ56: 9 | ER56: 11 | ES56: 12 | ET56: 14 | EU56: 16 | EV56: 11 | EW56: 17 | EX56: 7 | EY56: 15 | EZ56: 14 | FA56: 17 | FB56: 17 | FC56: 10 | FD56: 16 | FE56: 15 | FF56: 10 | FG56: 17 | FH56: 18 | FI56: 22 | FJ56: 22 | FK56: 22 | FL56: 34 | FM56: 29 | FN56: 60 | FO56: 883
B57: 計 | D57: =SUM(D52:D56) -> 57 | E57: =SUM(E52:E56) -> 18 | F57: =SUM(F52:F56) -> 12 | G57: =SUM(G52:G56) -> 7 | H57: =SUM(H52:H56) -> 9 | I57: =SUM(I52:I56) -> 9 | J57: =SUM(J52:J56) -> 7 | K57: =SUM(K52:K56) -> 7 | ... FO57: =SUM(FO52:FO56) -> 8176
B58: 累計 | D58: =C58+D57 -> 57 | E58: =D58+E57 -> 75 | F58: =E58+F57 -> 87 | G58: =F58+G57 -> 94 | H58: =G58+H57 -> 103 | I58: =H58+I57 -> 112 | J58: =I58+J57 -> 119 | K58: =J58+K57 -> 126 | ... FO58: =FN58+FO57 -> 16365
B60: 全合計 | D60: =D43+D57 -> 57 | E60: =E43+E57 -> 18 | F60: =F43+F57 -> 12 | G60: =G43+G57 -> 7 | H60: =H43+H57 -> 9 | I60: =I43+I57 -> 9 | J60: =J43+J57 -> 7 | K60: =K43+K57 -> 7 | ... FO60: =FO43+FO57 -> 17192
B61: 累計 | D61: =C61+D60 -> 57 | E61: =D61+E60 -> 75 | F61: =E61+F60 -> 87 | G61: =F61+G60 -> 94 | H61: =G61+H60 -> 103 | I61: =H61+I60 -> 112 | J61: =I61+J60 -> 119 | K61: =J61+K60 -> 126 | ... FO61: =FN61+FO60 -> 32888
D64: =SUM(D57:M57) -> 142 | E64: =SUM(O57:W57) -> 154 | F64: =SUM(X57:AG57) -> 237 | G64: =SUM(AH57:AQ57) -> 378 | H64: =SUM(AR57:BA57) -> 330 | I64: =SUM(BB57:BK57) -> 322 | J64: =SUM(BL57:BU57) -> 360 | K64: =SUM(BV57:CE57) -> 311 | L64: =SUM(CF57:CO57) -> 241 | M64: =SUM(CP57:CY57) -> 272 | N64: =SUM(CZ57:DI57) -> 372 | O64: =SUM(DJ57:DS57) -> 478 | P64: =SUM(DT57:EC57) -> 583 | Q64: =SUM(ED57:EM57) -> 631 | R64: =SUM(EN57:EW57) -> 759 | S64: =SUM(EX57:FG57) -> 848 | T64: =SUM(FH57:FL57) -> 910 | U64: =FM57 -> 182 | V64: =FN57 -> 670 | W64: =FO57 -> 8176

Sheet Sheet2
A2: α=0.5 | B2: 100001 | D2: 0 | E2: 0.1 | F2: 0.2 | G2: 0.3 | H2: 0.4 | I2: 0.5 | J2: 0.6 | K2: 0.7 | L2: 0.8 | M2: 0.9 | N2: 1 | O2: 1.1 | P2: 1.2 | Q2: 1.3 | R2: 1.4 | S2: 1.5 | T2: 1.6 | U2: 1.7 | V2: 1.8 | W2: 1.9 | X2: 2 | Y2: 2.1 | Z2: 2.2 | AA2: 2.3 | AB2: 2.4 | AC2: 2.5 | AD2: 2.6 | AE2: 2.7 | AF2: 2.8 | AG2: 2.9 | AH2: 3 | AI2: 3.1 | AJ2: 3.2 | AK2: 3.3 | AL2: 3.4 | AM2: 3.5 | AN2: 3.6 | AO2: 3.7 | AP2: 3.8 | AQ2: 3.9 | AR2: 4 | AS2: 4.1 | AT2: 4.2 | AU2: 4.3 | AV2: 4.4 | AW2: 4.5 | AX2: 4.6 | AY2: 4.7 | AZ2: 4.8 | BA2: 4.9 | BB2: 5 | BC2: 5.1 | BD2: 5.2 | BE2: 5.3 | BF2: 5.4 | BG2: 5.5 | BH2: 5.6 | BI2: 5.7 | BJ2: 5.8 | BK2: 5.9 | BL2: 6 | BM2: 6.1 | BN2: 6.2 | BO2: 6.3 | BP2: 6.4 | BQ2: 6.5 | BR2: 6.6 | BS2: 6.7 | BT2: 6.8 | BU2: 6.9 | BV2: 7 | BW2: 7.1 | BX2: 7.2 | BY2: 7.3 | BZ2: 7.4 | CA2: 7.5 | CB2: 7.6 | CC2: 7.7 | CD2: 7.8 | CE2: 7.9 | CF2: 8 | CG2: 8.1 | CH2: 8.2 | CI2: 8.3 | CJ2: 8.4 | CK2: 8.5 | CL2: 8.6 | CM2: 8.7 | CN2: 8.8 | CO2: 8.9 | CP2: 9 | CQ2: 9.1 | CR2: 9.2 | CS2: 9.3 | CT2: 9.4 | CU2: 9.5 | CV2: 9.6 | CW2: 9.7 | CX2: 9.8 | CY2: 9.9 | CZ2: 10 | DA2: 10.1 | DB2: 10.2 | DC2: 10.3 | DD2: 10.4 | DE2: 10.5 | DF2: 10.6 | DG2: 10.7 | DH2: 10.8 | DI2: 10.9 | DJ2: 11 | DK2: 11.1 | DL2: 11.2 | DM2: 11.3 | DN2: 11.4 | DO2: 11.5 | DP2: 11.6 | DQ2: 11.7 | DR2: 11.8 | DS2: 11.9 | DT2: 12 | DU2: 12.1 | DV2: 12.2 | DW2: 12.3 | DX2: 12.4 | DY2: 12.5 | DZ2: 12.6 | EA2: 12.7 | EB2: 12.8 | EC2: 12.9 | ED2: 13 | EE2: 13.1 | EF2: 13.2 | EG2: 13.3 | EH2: 13.4 | EI2: 13.5 | EJ2: 13.6 | EK2: 13.7 | EL2: 13.8 | EM2: 13.9 | EN2: 14 | EO2: 14.1 | EP2: 14.2 | EQ2: 14.3 | ER2: 14.4 | ES2: 14.5 | ET2: 14.6 | EU2: 14.7 | EV2: 14.8 | EW2: 14.9 | EX2: 15 | EY2: 15.1 | EZ2: 15.2 | FA2: 15.3 | FB2: 15.4 | FC2: 15.5 | FD2: 15.6 | FE2: 15.7 | FF2: 15.8 | FG2: 15.9 | FH2: 16 | FI2: 16.1 | FJ2: 16.2 | FK2: 16.3 | FL2: 16.4 | FM2: 16.5 | FN2: 16.6 | FO2: 16.7
A4: cav0 | B4: 1 | D4: 0 | E4: 0 | F4: 0 | G4: 0 | H4: 3 | I4: 1 | J4: 2 | K4: 2 | L4: 1 | M4: 0 | N4: 2 | O4: 2 | P4: 0 | Q4: 1 | R4: 1 | S4: 1 | T4: 0 | U4: 2 | V4: 0 | W4: 1 | X4: 0 | Y4: 2 | Z4: 0 | AA4: 1 | AB4: 0 | AC4: 8 | AD4: 4 | AE4: 2 | AF4: 3 | AG4: 3 | AH4: 3 | AI4: 2 | AJ4: 3 | AK4: 2 | AL4: 1 | AM4: 3 | AN4: 2 | AO4: 3 | AP4: 2 | AQ4: 2 | AR4: 3 | AS4: 2 | AT4: 10 | AU4: 3 | AV4: 4 | AW4: 4 | AX4: 3 | AY4: 4 | AZ4: 4 | BA4: 3 | BB4: 12 | BC4: 7 | BD4: 9 | BE4: 3 | BF4: 8 | BG4: 8 | BH4: 2 | BI4: 2 | BJ4: 2 | BK4: 0 | BL4: 4 | BM4: 0 | BN4: 2 | BO4: 2 | BP4: 3 | BQ4: 1 | BR4: 3 | BS4: 8 | BT4: 3 | BU4: 3 | BV4: 3 | BW4: 2 | BX4: 5 | BY4: 3 | BZ4: 4 | CA4: 2 | CB4: 5 | CC4: 1 | CD4: 2 | CE4: 3 | CF4: 3 | CG4: 4 | CH4: 2 | CI4: 4 | CJ4: 2 | CK4: 3 | CL4: 4 | CM4: 2 | CN4: 3 | CO4: 3 | CP4: 3 | CQ4: 3 | CR4: 3 | CS4: 5 | CT4: 2 | CU4: 4 | CV4: 2 | CW4: 4 | CX4: 4 | CY4: 9 | CZ4: 19 | DA4: 19 | DB4: 29 | DC4: 38 | DD4: 21 | DE4: 15 | DF4: 15 | DG4: 18 | DH4: 18 | DI4: 27 | DJ4: 21 | DK4: 19 | DL4: 29 | DM4: 28 | DN4: 14 | DO4: 18 | DP4: 20 | DQ4: 26 | DR4: 13 | DS4: 28 | DT4: 16 | DU4: 13 | DV4: 13 | DW4: 13 | DX4: 13 | DY4: 15 | DZ4: 31 | EA4: 32 | EB4: 40 | EC4: 29 | ED4: 28 | EE4: 49 | EF4: 35 | EG4: 53 | EH4: 36 | EI4: 45 | EJ4: 24 | EK4: 22 | EL4: 23 | EM4: 18 | EN4: 18 | EO4: 22 | EP4: 18 | EQ4: 17 | ER4: 19 | ES4: 21 | ET4: 21 | EU4: 24 | EV4: 23 | EW4: 16 | EX4: 36 | EY4: 18 | EZ4: 17 | FA4: 15 | FB4: 14 | FC4: 21 | FD4: 14 | FE4: 17 | FF4: 19 | FG4: 17 | FH4: 21 | FI4: 20 | FJ4: 29 | FK4: 22 | FL4: 40 | FM4: 51 | FN4: 96 | FO4: 1500
B5: 2 | D5: 40 | E5: 7 | F5: 13 | G5: 10 | H5: 9 | I5: 7 | J5: 5 | K5: 5 | L5: 8 | M5: 6 | N5: 6 | O5: 8 | P5: 7 | Q5: 8 | R5: 4 | S5: 7 | T5: 6 | U5: 19 | V5: 5 | W5: 5 | X5: 3 | Y5: 3 | Z5: 4 | AA5: 2 | AB5: 4 | AC5: 3 | AD5: 2 | AE5: 3 | AF5: 4 | AG5: 2 | AH5: 3 | AI5: 5 | AJ5: 1 | AK5: 3 | AL5: 0 | AM5: 5 | AN5: 1 | AO5: 1 | AP5: 3 | AQ5: 2 | AR5: 1 | AS5: 4 | AT5: 2 | AU5: 4 | AV5: 4 | AW5: 2 | AX5: 1 | AY5: 5 | AZ5: 2 | BA5: 2 | BB5: 1 | BC5: 3 | BD5: 2 | BE5: 2 | BF5: 3 | BG5: 2 | BH5: 1 | BI5: 4 | BJ5: 2 | BK5: 1 | BL5: 4 | BM5: 2 | BN5: 4 | BO5: 1 | BP5: 2 | BQ5: 5 | BR5: 2 | BS5: 11 | BT5: 4 | BU5: 3 | BV5: 2 | BW5: 4 | BX5: 2 | BY5: 2 | BZ5: 3 | CA5: 3 | CB5: 0 | CC5: 4 | CD5: 2 | CE5: 3 | CF5: 2 | CG5: 1 | CH5: 3 | CI5: 2 | CJ5: 3 | CK5: 3 | CL5: 3 | CM5: 2 | CN5: 5 | CO5: 1 | CP5: 5 | CQ5: 2 | CR5: 6 | CS5: 4 | CT5: 2 | CU5: 4 | CV5: 11 | CW5: 23 | CX5: 15 | CY5: 11 | CZ5: 4 | DA5: 2 | DB5: 6 | DC5: 1 | DD5: 6 | DE5: 1 | DF5: 4 | DG5: 3 | DH5: 10 | DI5: 20 | DJ5: 6 | DK5: 6 | DL5: 6 | DM5: 4 | DN5: 5 | DO5: 16 | DP5: 25 | DQ5: 23 | DR5: 16 | DS5: 22 | DT5: 27 | DU5: 25 | DV5: 19 | DW5: 8 | DX5: 17 | DY5: 24 | DZ5: 15 | EA5: 23 | EB5: 12 | EC5: 18 | ED5: 22 | EE5: 22 | EF5: 29 | EG5: 13 | EH5: 18 | EI5: 25 | EJ5: 16 | EK5: 15 | EL5: 8 | EM5: 16 | EN5: 13 | EO5: 9 | EP5: 17 | EQ5: 25 | ER5: 28 | ES5: 10 | ET5: 7 | EU5: 13 | EV5: 10 | EW5: 8 | EX5: 12 | EY5: 11 | EZ5: 12 | FA5: 12 | FB5: 13 | FC5: 17 | FD5: 21 | FE5: 19 | FF5: 19 | FG5: 21 | FH5: 21 | FI5: 23 | FJ5: 26 | FK5: 25 | FL5: 27 | FM5: 87 | FN5: 128 | FO5: 1757
B6: 3 | D6: 0 | E6: 0 | F6: 0 | G6: 0 | H6: 0 | I6: 0 | J6: 0 | K6: 0 | L6: 0 | M6: 0 | N6: 0 | O6: 0 | P6: 0 | Q6: 0 | R6: 0 | S6: 0 | T6: 0 | U6: 0 | V6: 0 | W6: 0 | X6: 0 | Y6: 0 | Z6: 0 | AA6: 0 | AB6: 0 | AC6: 0 | AD6: 0 | AE6: 0 | AF6: 0 | AG6: 0 | AH6: 0 | AI6: 0 | AJ6: 0 | AK6: 0 | AL6: 0 | AM6: 0 | AN6: 0 | AO6: 0 | AP6: 0 | AQ6: 0 | AR6: 0 | AS6: 0 | AT6: 0 | AU6: 0 | AV6: 0 | AW6: 0 | AX6: 0 | AY6: 0 | AZ6: 0 | BA6: 0 | BB6: 0 | BC6: 0 | BD6: 0 | BE6: 0 | BF6: 0 | BG6: 0 | BH6: 0 | BI6: 0 | BJ6: 0 | BK6: 0 | BL6: 0 | BM6: 0 | BN6: 0 | BO6: 0 | BP6: 0 | BQ6: 0 | BR6: 0 | BS6: 0 | BT6: 0 | BU6: 0 | BV6: 0 | BW6: 0 | BX6: 0 | BY6: 0 | BZ6: 0 | CA6: 0 | CB6: 0 | CC6: 0 | CD6: 0 | CE6: 0 | CF6: 0 | CG6: 0 | CH6: 0 | CI6: 0 | CJ6: 0 | CK6: 0 | CL6: 0 | CM6: 0 | CN6: 0 | CO6: 4 | CP6: 3 | CQ6: 1 | CR6: 2 | CS6: 3 | CT6: 1 | CU6: 1 | CV6: 1 | CW6: 2 | CX6: 0 | CY6: 2 | CZ6: 0 | DA6: 2 | DB6: 1 | DC6: 1 | DD6: 1 | DE6: 1 | DF6: 1 | DG6: 1 | DH6: 2 | DI6: 0 | DJ6: 2 | DK6: 1 | DL6: 2 | DM6: 0 | DN6: 2 | DO6: 1 | DP6: 1 | DQ6: 1 | DR6: 2 | DS6: 1 | DT6: 1 | DU6: 2 | DV6: 1 | DW6: 2 | DX6: 1 | DY6: 2 | DZ6: 2 | EA6: 4 | EB6: 15 | EC6: 17 | ED6: 21 | EE6: 31 | EF6: 20 | EG6: 31 | EH6: 28 | EI6: 36 | EJ6: 23 | EK6: 15 | EL6: 8 | EM6: 12 | EN6: 9 | EO6: 10 | EP6: 20 | EQ6: 10 | ER6: 17 | ES6: 17 | ET6: 10 | EU6: 13 | EV6: 14 | EW6: 10 | EX6: 15 | EY6: 16 | EZ6: 18 | FA6: 16 | FB6: 15 | FC6: 13 | FD6: 12 | FE6: 14 | FF6: 13 | FG6: 35 | FH6: 38 | FI6: 55 | FJ6: 62 | FK6: 82 | FL6: 80 | FM6: 76 | FN6: 173 | FO6: 1673
B7: 4 | D7: 101 | E7: 2 | F7: 1 | G7: 2 | H7: 1 | I7: 1 | J7: 1 | K7: 1 | L7: 1 | M7: 1 | N7: 0 | O7: 1 | P7: 0 | Q7: 1 | R7: 1 | S7: 1 | T7: 0 | U7: 1 | V7: 0 | W7: 1 | X7: 0 | Y7: 1 | Z7: 0 | AA7: 1 | AB7: 0 | AC7: 1 | AD7: 0 | AE7: 1 | AF7: 0 | AG7: 1 | AH7: 0 | AI7: 1 | AJ7: 0 | AK7: 1 | AL7: 1 | AM7: 0 | AN7: 1 | AO7: 0 | AP7: 1 | AQ7: 0 | AR7: 0 | AS7: 1 | AT7: 0 | AU7: 1 | AV7: 0 | AW7: 1 | AX7: 0 | AY7: 1 | AZ7: 0 | BA7: 1 | BB7: 0 | BC7: 0 | BD7: 1 | BE7: 0 | BF7: 1 | BG7: 1 | BH7: 0 | BI7: 1 | BJ7: 0 | BK7: 1 | BL7: 0 | BM7: 1 | BN7: 0 | BO7: 1 | BP7: 0 | BQ7: 1 | BR7: 0 | BS7: 1 | BT7: 0 | BU7: 1 | BV7: 0 | BW7: 1 | BX7: 0 | BY7: 1 | BZ7: 1 | CA7: 0 | CB7: 1 | CC7: 0 | CD7: 1 | CE7: 0 | CF7: 1 | CG7: 0 | CH7: 1 | CI7: 0 | CJ7: 1 | CK7: 0 | CL7: 1 | CM7: 1 | CN7: 0 | CO7: 1 | CP7: 0 | CQ7: 1 | CR7: 1 | CS7: 1 | CT7: 0 | CU7: 1 | CV7: 1 | CW7: 0 | CX7: 1 | CY7: 5 | CZ7: 11 | DA7: 9 | DB7: 7 | DC7: 5 | DD7: 3 | DE7: 4 | DF7: 5 | DG7: 5 | DH7: 3 | DI7: 7 | DJ7: 6 | DK7: 5 | DL7: 5 | DM7: 5 | DN7: 8 | DO7: 12 | DP7: 12 | DQ7: 20 | DR7: 18 | DS7: 12 | DT7: 13 | DU7: 11 | DV7: 17 | DW7: 9 | DX7: 10 | DY7: 13 | DZ7: 14 | EA7: 14 | EB7: 19 | EC7: 14 | ED7: 18 | EE7: 19 | EF7: 17 | EG7: 29 | EH7: 20 | EI7: 26 | EJ7: 11 | EK7: 12 | EL7: 9 | EM7: 9 | EN7: 12 | EO7: 20 | EP7: 15 | EQ7: 13 | ER7: 12 | ES7: 13 | ET7: 12 | EU7: 14 | EV7: 11 | EW7: 9 | EX7: 12 | EY7: 13 | EZ7: 13 | FA7: 13 | FB7: 14 | FC7: 15 | FD7: 21 | FE7: 29 | FF7: 36 | FG7: 36 | FH7: 40 | FI7: 64 | FJ7: 55 | FK7: 46 | FL7: 56 | FM7: 93 | FN7: 148 | FO7: 2034
B8: 5 | D8: 0 | E8: 4 | F8: 6 | G8: 3 | H8: 2 | I8: 3 | J8: 1 | K8: 1 | L8: 0 | M8: 1 | N8: 1 | O8: 0 | P8: 1 | Q8: 0 | R8: 1 | S8: 1 | T8: 0 | U8: 1 | V8: 1 | W8: 0 | X8: 1 | Y8: 0 | Z8: 1 | AA8: 0 | AB8: 1 | AC8: 0 | AD8: 2 | AE8: 2 | AF8: 3 | AG8: 2 | AH8: 1 | AI8: 3 | AJ8: 1 | AK8: 1 | AL8: 1 | AM8: 2 | AN8: 0 | AO8: 2 | AP8: 1 | AQ8: 1 | AR8: 0 | AS8: 2 | AT8: 1 | AU8: 1 | AV8: 1 | AW8: 1 | AX8: 0 | AY8: 1 | AZ8: 1 | BA8: 1 | BB8: 1 | BC8: 7 | BD8: 5 | BE8: 3 | BF8: 3 | BG8: 3 | BH8: 2 | BI8: 3 | BJ8: 3 | BK8: 1 | BL8: 3 | BM8: 3 | BN8: 2 | BO8: 2 | BP8: 2 | BQ8: 2 | BR8: 2 | BS8: 2 | BT8: 2 | BU8: 1 | BV8: 3 | BW8: 1 | BX8: 2 | BY8: 2 | BZ8: 1 | CA8: 2 | CB8: 2 | CC8: 2 | CD8: 2 | CE8: 2 | CF8: 1 | CG8: 3 | CH8: 2 | CI8: 2 | CJ8: 1 | CK8: 3 | CL8: 1 | CM8: 2 | CN8: 1 | CO8: 3 | CP8: 2 | CQ8: 1 | CR8: 2 | CS8: 2 | CT8: 2 | CU8: 2 | CV8: 2 | CW8: 3 | CX8: 1 | CY8: 3 | CZ8: 2 | DA8: 10 | DB8: 11 | DC8: 13 | DD8: 12 | DE8: 9 | DF8: 12 | DG8: 19 | DH8: 13 | DI8: 15 | DJ8: 15 | DK8: 12 | DL8: 12 | DM8: 14 | DN8: 13 | DO8: 20 | DP8: 22 | DQ8: 30 | DR8: 23 | DS8: 18 | DT8: 39 | DU8: 23 | DV8: 18 | DW8: 20 | DX8: 30 | DY8: 17 | DZ8: 9 | EA8: 15 | EB8: 12 | EC8: 28 | ED8: 21 | EE8: 29 | EF8: 13 | EG8: 29 | EH8: 23 | EI8: 17 | EJ8: 21 | EK8: 22 | EL8: 38 | EM8: 21 | EN8: 20 | EO8: 29 | EP8: 21 | EQ8: 18 | ER8: 34 | ES8: 26 | ET8: 24 | EU8: 28 | EV8: 21 | EW8: 20 | EX8: 22 | EY8: 28 | EZ8: 24 | FA8: 31 | FB8: 22 | FC8: 33 | FD8: 29 | FE8: 26 | FF8: 25 | FG8: 31 | FH8: 44 | FI8: 43 | FJ8: 55 | FK8: 80 | FL8: 59 | FM8: 94 | FN8: 149 | FO8: 1632
B9: 計 | D9: =SUM(D4:D8) -> 141 | E9: =SUM(E4:E8) -> 13 | F9: =SUM(F4:F8) -> 20 | G9: =SUM(G4:G8) -> 15 | H9: =SUM(H4:H8) -> 15 | I9: =SUM(I4:I8) -> 12 | J9: =SUM(J4:J8) -> 9 | K9: =SUM(K4:K8) -> 9 | ... FO9: =SUM(FO4:FO8) -> 8596
B10: 累計 | D10: =C10+D9 -> 141 | E10: =D10+E9 -> 154 | F10: =E10+F9 -> 174 | G10: =F10+G9 -> 189 | H10: =G10+H9 -> 204 | I10: =H10+I9 -> 216 | J10: =I10+J9 -> 225 | K10: =J10+K9 -> 234 | ... FO10: =FN10+FO9 -> 16772
D16: =SUM(D9:M9) -> 252 | E16: =SUM(O9:W9) -> 88 | F16: =SUM(X9:AG9) -> 70 | G16: =SUM(AH9:AQ9) -> 65 | H16: =SUM(AR9:BA9) -> 81 | I16: =SUM(BB9:BK9) -> 110 | J16: =SUM(BL9:BU9) -> 93 | K16: =SUM(BV9:CE9) -> 79 | L16: =SUM(CF9:CO9) -> 84 | M16: =SUM(CP9:CY9) -> 169 | N16: =SUM(CZ9:DI9) -> 461 | O16: =SUM(DJ9:DS9) -> 640 | P16: =SUM(DT9:EC9) -> 795 | Q16: =SUM(ED9:EM9) -> 1146 | R16: =SUM(EN9:EW9) -> 841 | S16: =SUM(EX9:FG9) -> 985 | T16: =SUM(FH9:FL9) -> 1113 | U16: =FM9+FN9 -> 1095 | V16: =FO9 -> 8596
A20: cav1 | B20: 1 | D20: 0 | E20: 0 | F20: 0 | G20: 0 | H20: 0 | I20: 0 | J20: 0 | K20: 0 | L20: 0 | M20: 0 | N20: 0 | O20: 0 | P20: 0 | Q20: 0 | R20: 0 | S20: 0 | T20: 0 | U20: 0 | V20: 0 | W20: 0 | X20: 0 | Y20: 0 | Z20: 0 | AA20: 0 | AB20: 0 | AC20: 0 | AD20: 0 | AE20: 4 | AF20: 2 | AG20: 2 | AH20: 0 | AI20: 2 | AJ20: 2 | AK20: 0 | AL20: 2 | AM20: 0 | AN20: 1 | AO20: 1 | AP20: 0 | AQ20: 2 | AR20: 0 | AS20: 1 | AT20: 4 | AU20: 3 | AV20: 4 | AW20: 4 | AX20: 8 | AY20: 7 | AZ20: 3 | BA20: 8 | BB20: 10 | BC20: 8 | BD20: 6 | BE20: 6 | BF20: 6 | BG20: 3 | BH20: 7 | BI20: 3 | BJ20: 8 | BK20: 2 | BL20: 3 | BM20: 6 | BN20: 5 | BO20: 4 | BP20: 5 | BQ20: 4 | BR20: 10 | BS20: 13 | BT20: 9 | BU20: 9 | BV20: 7 | BW20: 4 | BX20: 7 | BY20: 13 | BZ20: 15 | CA20: 15 | CB20: 11 | CC20: 11 | CD20: 16 | CE20: 12 | CF20: 10 | CG20: 10 | CH20: 13 | CI20: 8 | CJ20: 10 | CK20: 6 | CL20: 13 | CM20: 6 | CN20: 11 | CO20: 5 | CP20: 9 | CQ20: 7 | CR20: 7 | CS20: 5 | CT20: 9 | CU20: 6 | CV20: 9 | CW20: 14 | CX20: 32 | CY20: 10 | CZ20: 11 | DA20: 8 | DB20: 6 | DC20: 18 | DD20: 7 | DE20: 12 | DF20: 13 | DG20: 12 | DH20: 14 | DI20: 7 | DJ20: 13 | DK20: 10 | DL20: 17 | DM20: 10 | DN20: 22 | DO20: 14 | DP20: 19 | DQ20: 19 | DR20: 10 | DS20: 14 | DT20: 13 | DU20: 14 | DV20: 14 | DW20: 12 | DX20: 12 | DY20: 12 | DZ20: 7 | EA20: 6 | EB20: 7 | EC20: 6 | ED20: 9 | EE20: 8 | EF20: 7 | EG20: 4 | EH20: 9 | EI20: 7 | EJ20: 6 | EK20: 8 | EL20: 6 | EM20: 8 | EN20: 8 | EO20: 25 | EP20: 14 | EQ20: 11 | ER20: 11 | ES20: 9 | ET20: 14 | EU20: 12 | EV20: 15 | EW20: 11 | EX20: 14 | EY20: 12 | EZ20: 15 | FA20: 17 | FB20: 11 | FC20: 13 | FD20: 14 | FE20: 18 | FF20: 20 | FG20: 26 | FH20: 27 | FI20: 64 | FJ20: 77 | FK20: 56 | FL20: 46 | FM20: 46 | FN20: 72 | FO20: 1670
B21: 2 | D21: 0 | E21: 0 | F21: 0 | G21: 0 | H21: 0 | I21: 0 | J21: 0 | K21: 0 | L21: 0 | M21: 0 | N21: 0 | O21: 0 | P21: 0 | Q21: 0 | R21: 0 | S21: 0 | T21: 0 | U21: 0 | V21: 0 | W21: 0 | X21: 0 | Y21: 0 | Z21: 0 | AA21: 0 | AB21: 0 | AC21: 0 | AD21: 0 | AE21: 0 | AF21: 0 | AG21: 0 | AH21: 0 | AI21: 0 | AJ21: 0 | AK21: 0 | AL21: 0 | AM21: 0 | AN21: 1 | AO21: 0 | AP21: 1 | AQ21: 0 | AR21: 1 | AS21: 0 | AT21: 0 | AU21: 1 | AV21: 0 | AW21: 1 | AX21: 0 | AY21: 1 | AZ21: 0 | BA21: 0 | BB21: 1 | BC21: 0 | BD21: 1 | BE21: 0 | BF21: 0 | BG21: 1 | BH21: 0 | BI21: 1 | BJ21: 0 | BK21: 1 | BL21: 0 | BM21: 1 | BN21: 0 | BO21: 1 | BP21: 0 | BQ21: 1 | BR21: 1 | BS21: 0 | BT21: 2 | BU21: 2 | BV21: 1 | BW21: 1 | BX21: 1 | BY21: 0 | BZ21: 1 | CA21: 1 | CB21: 1 | CC21: 0 | CD21: 1 | CE21: 1 | CF21: 0 | CG21: 1 | CH21: 1 | CI21: 1 | CJ21: 0 | CK21: 1 | CL21: 0 | CM21: 1 | CN21: 1 | CO21: 0 | CP21: 1 | CQ21: 0 | CR21: 0 | CS21: 1 | CT21: 0 | CU21: 1 | CV21: 0 | CW21: 1 | CX21: 0 | CY21: 1 | CZ21: 1 | DA21: 0 | DB21: 0 | DC21: 1 | DD21: 0 | DE21: 2 | DF21: 1 | DG21: 2 | DH21: 0 | DI21: 1 | DJ21: 2 | DK21: 1 | DL21: 2 | DM21: 1 | DN21: 3 | DO21: 3 | DP21: 10 | DQ21: 4 | DR21: 5 | DS21: 4 | DT21: 6 | DU21: 4 | DV21: 4 | DW21: 3 | DX21: 4 | DY21: 2 | DZ21: 4 | EA21: 3 | EB21: 2 | EC21: 5 | ED21: 2 | EE21: 3 | EF21: 3 | EG21: 1 | EH21: 3 | EI21: 4 | EJ21: 1 | EK21: 3 | EL21: 2 | EM21: 3 | EN21: 2 | EO21: 48 | EP21: 22 | EQ21: 24 | ER21: 23 | ES21: 22 | ET21: 21 | EU21: 20 | EV21: 18 | EW21: 17 | EX21: 19 | EY21: 18 | EZ21: 24 | FA21: 32 | FB21: 33 | FC21: 33 | FD21: 26 | FE21: 26 | FF21: 32 | FG21: 36 | FH21: 36 | FI21: 35 | FJ21: 49 | FK21: 46 | FL21: 85 | FM21: 99 | FN21: 266 | FO21: 2010
B22: 3 | D22: 0 | E22: 0 | F22: 0 | G22: 0 | H22: 0 | I22: 0 | J22: 0 | K22: 0 | L22: 0 | M22: 0 | N22: 0 | O22: 0 | P22: 0 | Q22: 0 | R22: 0 | S22: 0 | T22: 0 | U22: 0 | V22: 0 | W22: 0 | X22: 0 | Y22: 0 | Z22: 0 | AA22: 0 | AB22: 0 | AC22: 0 | AD22: 0 | AE22: 0 | AF22: 0 | AG22: 0 | AH22: 0 | AI22: 0 | AJ22: 0 | AK22: 0 | AL22: 0 | AM22: 0 | AN22: 0 | AO22: 0 | AP22: 0 | AQ22: 0 | AR22: 0 | AS22: 0 | AT22: 0 | AU22: 0 | AV22: 0 | AW22: 0 | AX22: 0 | AY22: 0 | AZ22: 0 | BA22: 0 | BB22: 0 | BC22: 0 | BD22: 0 | BE22: 0 | BF22: 0 | BG22: 0 | BH22: 0 | BI22: 0 | BJ22: 0 | BK22: 0 | BL22: 0 | BM22: 0 | BN22: 0 | BO22: 0 | BP22: 0 | BQ22: 0 | BR22: 0 | BS22: 0 | BT22: 0 | BU22: 0 | BV22: 0 | BW22: 0 | BX22: 0 | BY22: 0 | BZ22: 0 | CA22: 0 | CB22: 0 | CC22: 0 | CD22: 0 | CE22: 0 | CF22: 0 | CG22: 0 | CH22: 0 | CI22: 0 | CJ22: 0 | CK22: 7 | CL22: 6 | CM22: 5 | CN22: 9 | CO22: 6 | CP22: 4 | CQ22: 4 | CR22: 3 | CS22: 4 | CT22: 3 | CU22: 2 | CV22: 3 | CW22: 1 | CX22: 3 | CY22: 2 | CZ22: 2 | DA22: 2 | DB22: 3 | DC22: 2 | DD22: 2 | DE22: 1 | DF22: 7 | DG22: 3 | DH22: 5 | DI22: 3 | DJ22: 3 | DK22: 2 | DL22: 3 | DM22: 4 | DN22: 4 | DO22: 3 | DP22: 3 | DQ22: 4 | DR22: 3 | DS22: 2 | DT22: 3 | DU22: 4 | DV22: 2 | DW22: 4 | DX22: 2 | DY22: 4 | DZ22: 5 | EA22: 1 | EB22: 3 | EC22: 4 | ED22: 2 | EE22: 4 | EF22: 3 | EG22: 2 | EH22: 3 | EI22: 3 | EJ22: 4 | EK22: 3 | EL22: 4 | EM22: 3 | EN22: 3 | EO22: 4 | EP22: 5 | EQ22: 2 | ER22: 3 | ES22: 4 | ET22: 4 | EU22: 1 | EV22: 5 | EW22: 2 | EX22: 4 | EY22: 5 | EZ22: 2 | FA22: 9 | FB22: 6 | FC22: 5 | FD22: 6 | FE22: 6 | FF22: 6 | FG22: 28 | FH22: 32 | FI22: 33 | FJ22: 36 | FK22: 24 | FL22: 36 | FM22: 37 | FN22: 266 | FO22: 2294
B23: 4 | D23: 0 | E23: 0 | F23: 0 | G23: 0 | H23: 0 | I23: 0 | J23: 0 | K23: 0 | L23: 0 | M23: 0 | N23: 0 | O23: 0 | P23: 0 | Q23: 0 | R23: 0 | S23: 0 | T23: 0 | U23: 0 | V23: 0 | W23: 0 | X23: 0 | Y23: 0 | Z23: 0 | AA23: 0 | AB23: 0 | AC23: 0 | AD23: 0 | AE23: 0 | AF23: 0 | AG23: 0 | AH23: 0 | AI23: 0 | AJ23: 0 | AK23: 0 | AL23: 0 | AM23: 0 | AN23: 0 | AO23: 0 | AP23: 0 | AQ23: 0 | AR23: 0 | AS23: 0 | AT23: 0 | AU23: 0 | AV23: 0 | AW23: 0 | AX23: 0 | AY23: 0 | AZ23: 0 | BA23: 0 | BB23: 0 | BC23: 0 | BD23: 0 | BE23: 0 | BF23: 0 | BG23: 0 | BH23: 0 | BI23: 0 | BJ23: 0 | BK23: 0 | BL23: 0 | BM23: 0 | BN23: 0 | BO23: 0 | BP23: 0 | BQ23: 0 | BR23: 0 | BS23: 0 | BT23: 0 | BU23: 0 | BV23: 0 | BW23: 0 | BX23: 0 | BY23: 0 | BZ23: 0 | CA23: 0 | CB23: 0 | CC23: 0 | CD23: 0 | CE23: 0 | CF23: 0 | CG23: 0 | CH23: 0 | CI23: 0 | CJ23: 0 | CK23: 0 | CL23: 5 | CM23: 5 | CN23: 4 | CO23: 8 | CP23: 4 | CQ23: 5 | CR23: 3 | CS23: 3 | CT23: 4 | CU23: 6 | CV23: 2 | CW23: 3 | CX23: 3 | CY23: 3 | CZ23: 2 | DA23: 1 | DB23: 4 | DC23: 2 | DD23: 4 | DE23: 6 | DF23: 9 | DG23: 6 | DH23: 5 | DI23: 4 | DJ23: 6 | DK23: 3 | DL23: 4 | DM23: 4 | DN23: 9 | DO23: 8 | DP23: 5 | DQ23: 4 | DR23: 10 | DS23: 7 | DT23: 6 | DU23: 6 | DV23: 5 | DW23: 5 | DX23: 3 | DY23: 14 | DZ23: 8 | EA23: 6 | EB23: 8 | EC23: 6 | ED23: 4 | EE23: 7 | EF23: 5 | EG23: 6 | EH23: 3 | EI23: 6 | EJ23: 4 | EK23: 5 | EL23: 3 | EM23: 7 | EN23: 4 | EO23: 22 | EP23: 15 | EQ23: 12 | ER23: 9 | ES23: 10 | ET23: 7 | EU23: 7 | EV23: 8 | EW23: 5 | EX23: 6 | EY23: 8 | EZ23: 9 | FA23: 9 | FB23: 6 | FC23: 8 | FD23: 8 | FE23: 9 | FF23: 8 | FG23: 19 | FH23: 25 | FI23: 21 | FJ23: 27 | FK23: 23 | FL23: 30 | FM23: 32 | FN23: 189 | FO23: 2339
