Workbook

Sheet seed1
B2: 合流車線 | C2: 本線 | E2: 提案手法 | F2: 線形, v_max | I2: 提案手法 | J2: 2次, v_max | M2: 加藤さん | Q2: 全て受け入れ | U2: PriMa20% | Y2: PriMa40%
B3: [台/h] | C3: [台/h] | E3: all_speed | F3: cav0_speed | G3: cav1_speed | I3: all_speed | J3: cav0_speed | K3: cav1_speed | M3: all_speed | N3: cav0_speed | O3: cav1_speed | Q3: all_speed | R3: cav0_speed | S3: cav1_speed | U3: all_speed | V3: cav0_speed | W3: cav1_speed | Y3: all_speed | Z3: cav0_speed | AA3: cav1_speed
A5: 合流開始 | B5: 500 | C5: 1500
A6: 100m | B6: 600 | C6: 1400 | E6: 13.9807 | F6: 10.4802 | G6: 15.9305 | I6: 13.953 | J6: 10.7099 | K6: 15.6944 | M6: 13.316 | N6: 8.4585 | O6: 16.5916 | Q6: 15.0126 | R6: 15.1362 | S6: 14.9592 | U6: 13.3409 | V6: 8.4041 | W6: 16.67 | Y6: 14.4613 | Z6: 10.963 | AA6: 16.4341
A7: シミュ時間 | B7: 700 | C7: 1300 | E7: 14.3396 | F7: 11.5207 | G7: 16.2998 | I7: 14.4049 | J7: 11.7791 | K7: 16.1656 | M7: 13.4833 | N7: 9.5427 | O7: 16.6316 | U7: 13.4347 | V7: 9.3851 | W7: 16.67 | Y7: 14.4596 | Z7: 11.5775 | AA7: 16.4585
A8: 90s | B8: 800 | C8: 1200 | E8: 14.8798 | F8: 13.9894 | G8: 15.4995 | I8: 14.8798 | J8: 13.9894 | K8: 15.4995 | M8: 14.6327 | N8: 12.2469 | O8: 16.4714 | Q8: 13.9253 | R8: 13.9872 | S8: 13.8836 | U8: 13.2803 | V8: 9.5541 | W8: 16.67 | Y8: 14.859 | Z8: 14.4838 | AA8: 15.1201
B9: 900 | C9: 1100 | E9: 14.353 | F9: 13.8627 | G9: 14.7638 | I9: 14.186 | J9: 13.3457 | K9: 14.918 | M9: 13.5723 | N9: 10.8293 | O9: 16.4697 | U9: 13.9186 | V9: 11.1933 | W9: 16.6526 | Y9: 13.7034 | Z9: 12.0751 | AA9: 15.22
B10: 1000 | C10: 1000 | E10: 13.1447 | F10: 11.4646 | G10: 15.2908 | I10: 13.1476 | J10: 11.4664 | K10: 15.2952 | M10: 13.3282 | N10: 11.1765 | O10: 16.1254 | Q10: 12.3548 | R10: 13.1778 | S10: 11.5046 | U10: 12.9891 | V10: 10.3566 | W10: 16.6539 | Y10: 13.6985 | Z10: 11.757 | AA10: 16.2263
B11: 1100 | C11: 900 | E11: 13.1326 | F11: 11.9699 | G11: 14.7824 | I11: 13.2665 | J11: 11.9245 | K11: 15.2493 | M11: 11.8986 | N11: 9.688 | O11: 15.9007 | U11: 11.1115 | V11: 8.2609 | W11: 16.67 | Y11: 13.8425 | Z11: 12.5112 | AA11: 15.8756
B12: 1200 | C12: 800 | E12: 13.5338 | F12: 12.4747 | G12: 15.7075 | I12: 13.2615 | J12: 12.0978 | K12: 15.697 | M12: 13.7065 | N12: 12.4393 | O12: 16.4057 | Q12: 11.6302 | R12: 11.0565 | S12: 12.6423 | U12: 12.9314 | V12: 11.2909 | W12: 16.67 | Y12: 13.7787 | Z12: 12.5721 | AA12: 16.3491
B13: 1300 | C13: 700 | E13: 12.5734 | F13: 11.8931 | G13: 14.1813 | I13: 12.494 | J13: 11.8091 | K13: 14.1148 | M13: 12.9901 | N13: 11.6655 | O13: 16.4344 | U13: 12.3301 | V13: 10.7182 | W13: 16.67 | Y13: 13.2334 | Z13: 12.0013 | AA13: 16.3906
B14: 1400 | C14: 600 | E14: 14.6437 | F14: 14.7782 | G14: 14.2905 | I14: 14.6437 | J14: 14.7782 | K14: 14.2905 | M14: 14.8161 | N14: 14.2444 | O14: 16.4853 | Q14: 14.5272 | R14: 14.3391 | S14: 15.0166 | U14: 13.8314 | V14: 12.9341 | W14: 16.67 | Y14: 14.3841 | Z14: 13.7125 | AA14: 16.3921
B15: 1500 | C15: 500
B17: 1000 | C17: 1400 | E17: 11.6044 | F17: 8.8373 | G17: 14.3065 | I17: 13.0043 | J17: 10.9689 | K17: 14.9076 | M17: 12.271 | N17: 8.6384 | O17: 16.3195 | Q17: 9.5235 | R17: 11.288 | S17: 8.3542 | U17: 10.6457 | V17: 6.0438 | W17: 16.67 | Y17: 12.5416 | Z17: 9.5652 | AA17: 15.429
B18: 1200 | C18: 1200 | E18: 11.2031 | F18: 9.2244 | G18: 14.1014 | I18: 10.7808 | J18: 8.5475 | K18: 14.0295 | M18: 10.7243 | N18: 7.5946 | O18: 16.1672 | Q18: 9.8401 | R18: 9.1093 | S18: 10.646 | U18: 9.1935 | V18: 5.3888 | W18: 16.67 | Y18: 12.3975 | Z18: 10.8865 | AA18: 14.4532
B19: 1400 | C19: 1000 | E19: 9.7118 | F19: 8.3575 | G19: 12.1452 | I19: 10.1048 | J19: 8.716 | K19: 12.5553 | M19: 9.8103 | N19: 7.0644 | O19: 16.0017 | Q19: 9.0388 | R19: 9.9766 | S19: 8.0455 | U19: 8.9702 | V19: 5.9741 | W19: 16.573 | Y19: 8.9133 | Z19: 6.9764 | AA19: 12.2169
B20: 800 | C20: 800 | E20: 15.4299 | F20: 14.8014 | G20: 16.0919 | I20: 15.4316 | J20: 14.8037 | K20: 16.093 | M20: 15.3182 | N20: 14.2231 | O20: 16.5309 | Q20: 15.2888 | R20: 14.8104 | S20: 15.7919 | U20: 13.8413 | V20: 11.6925 | W20: 16.67 | Y20: 15.4814 | Z20: 14.4705 | AA20: 16.6005
B22: 500 | C22: 1500
A23: (30s~) | B23: 600 | C23: 1400 | E23: 13.4799 | F23: 9.7997 | G23: 15.7887 | I23: 13.5129 | J23: 9.747 | K23: 15.7683 | M23: 12.7934 | N23: 7.9516 | O23: 16.5633 | Q23: 14.8851 | R23: 15.0801 | S23: 14.796 | U23: 12.8253 | V23: 7.8876 | W23: 16.67 | Y23: 14.0992 | Z23: 10.3804 | AA23: 16.4718
B24: 700 | C24: 1300 | E24: 13.9321 | F24: 11.1097 | G24: 16.2874 | I24: 14.0882 | J24: 11.133 | K24: 16.4417 | M24: 12.9946 | N24: 9.2562 | O24: 16.6159 | U24: 12.9319 | V24: 9.0729 | W24: 16.67 | Y24: 14.0883 | Z24: 11.1754 | AA24: 16.5117
B25: 800 | C25: 1200 | E25: 14.5335 | F25: 13.5471 | G25: 15.2316 | I25: 14.5335 | J25: 13.5471 | K25: 15.2316 | M25: 14.2334 | N25: 11.4625 | O25: 16.4581 | Q25: 13.3603 | R25: 13.551 | S25: 13.231 | U25: 12.6439 | V25: 8.5342 | W25: 16.67 | Y25: 14.5074 | Z25: 14.1609 | AA25: 14.7527
B26: 900 | C26: 1100 | E26: 13.9481 | F26: 13.4636 | G26: 14.3531 | I26: 13.7353 | J26: 12.8187 | K26: 14.5405 | M26: 12.9489 | N26: 9.8557 | O26: 16.4108 | U26: 13.3607 | V26: 10.2317 | W26: 16.6475 | Y26: 13.1204 | Z26: 11.3337 | AA26: 14.8263
B27: 1000 | C27: 1000 | E27: 12.5798 | F27: 10.5575 | G27: 15.1586 | I27: 12.5835 | J27: 10.5597 | K27: 15.1641 | M27: 12.8102 | N27: 10.2006 | O27: 16.2124 | Q27: 11.5907 | R27: 12.6657 | S27: 10.5411 | U27: 12.2892 | V27: 9.2216 | W27: 16.6495 | Y27: 13.1699 | Z27: 10.9211 | AA27: 16.1074
B28: 1100 | C28: 900 | E28: 12.6734 | F28: 11.3073 | G28: 14.8286 | I28: 12.832 | J28: 11.23 | K28: 15.5001 | M28: 10.9854 | N28: 8.7728 | O28: 15.749 | U28: 9.9848 | V28: 7.1547 | W28: 16.67 | Y28: 13.3378 | Z28: 11.9704 | AA28: 15.7322
B29: 1200 | C29: 800 | E29: 12.8681 | F29: 11.7501 | G29: 15.5629 | I29: 12.5153 | J29: 11.2908 | K29: 15.5447 | M29: 13.0367 | N29: 11.7624 | O29: 16.2846 | Q29: 10.529 | R29: 10.0437 | S29: 11.4727 | U29: 12.0768 | V29: 10.4189 | W29: 16.67 | Y29: 13.1305 | Z29: 11.9257 | AA29: 16.2012
B30: 1300 | C30: 700 | E30: 11.6532 | F30: 11.0716 | G30: 13.3123 | I30: 11.5522 | J30: 10.9704 | K30: 13.2144 | M30: 12.1496 | N30: 10.8755 | O30: 16.3131 | U30: 11.3127 | V30: 9.7486 | W30: 16.67 | Y30: 12.4546 | Z30: 11.2724 | AA30: 16.2469
B31: 1400 | C31: 600 | E31: 14.1785 | F31: 14.3819 | G31: 13.6529 | I31: 14.1785 | J31: 14.3819 | K31: 13.6529 | M31: 14.3988 | N31: 13.7089 | O31: 16.4418 | Q31: 14.0354 | R31: 13.8194 | S31: 14.5869 | U31: 13.2776 | V31: 12.2423 | W31: 16.67 | Y31: 13.9648 | Z31: 13.1959 | AA31: 16.3089
B32: 1500 | C32: 500
B34: 1000 | C34: 1400 | E34: 10.9029 | F34: 7.5483 | G34: 14.2289 | I34: 12.5645 | J34: 9.9993 | K34: 14.9777 | M34: 11.4996 | N34: 7.4422 | O34: 16.2434 | Q34: 8.4796 | R34: 10.3254 | S34: 7.3392 | U34: 9.5818 | V34: 4.5835 | W34: 16.67 | Y34: 11.8265 | Z34: 8.3611 | AA34: 15.2376
B35: 1200 | C35: 1200 | E35: 10.1421 | F35: 8.2727 | G35: 13.382 | I35: 9.626 | J35: 7.482 | K35: 13.2985 | M35: 9.6691 | N35: 6.7236 | O35: 15.9844 | Q35: 8.6653 | R35: 8.0365 | S35: 9.4148 | U35: 7.8256 | V35: 4.2726 | W35: 16.67 | Y35: 11.6183 | Z35: 10.0613 | AA35: 14.1004
B36: 1400 | C36: 1000 | E36: 8.8406 | F36: 7.3027 | G36: 11.7863 | I36: 9.3031 | J36: 7.677 | K36: 12.3532 | M36: 8.657 | N36: 5.8149 | O36: 15.9512 | Q36: 8.1417 | R36: 8.8209 | S36: 7.4579 | U36: 7.7657 | V36: 4.7905 | W36: 16.5378 | Y36: 7.9035 | Z36: 5.7039 | AA36: 11.8408
B37: 800 | C37: 800 | E37: 15.1945 | F37: 14.4872 | G37: 15.9849 | I37: 15.1967 | J37: 14.4901 | K37: 15.9865 | M37: 15.0509 | N37: 13.782 | O37: 16.5634 | Q37: 15.016 | R37: 14.4995 | S37: 15.5918 | U37: 13.2834 | V37: 10.9796 | W37: 16.67 | Y37: 15.2591 | Z37: 14.087 | AA37: 16.6558
A39: 合流開始 | B39: 500 | C39: 1500
A40: 200m | B40: 600 | C40: 1400 | E40: 13.4701 | F40: 9.1384 | G40: 16.1362 | I40: 12.4244 | J40: 9.3875 | K40: 14.0683 | M40: 13.5769 | N40: 8.7189 | O40: 16.6026 | Q40: 11.9949 | R40: 13.7747 | S40: 11.3482 | U40: 12.7728 | V40: 7.2879 | W40: 16.67 | Y40: 13.617 | Z40: 8.809 | AA40: 16.5757 | AC40: 13.4697 | AD40: 9.1215 | AE40: 16.1454
A41: シミュ時間 | B41: 700 | C41: 1300
A42: 90s | B42: 800 | C42: 1200 | E42: 14.1485 | F42: 12.0514 | G42: 15.6809 | I42: 14.126 | J42: 12.9897 | K42: 15.5409 | M42: 12.957 | N42: 8.9645 | O42: 16.6033 | Q42: 12.6724 | R42: 13.6592 | S42: 12.0415 | U42: 11.2956 | V42: 6.4324 | W42: 16.67 | Y42: 13.3998 | Z42: 9.7714 | AA42: 16.5778 | AC42: 14.2365 | AD42: 12.4999 | AE42: 15.4896
B43: 900 | C43: 1100
B44: 1000 | C44: 1000 | E44: 11.1839 | F44: 9.0303 | G44: 14.2303 | I44: 10.9635 | J44: 9.34 | K44: 13.0487 | M44: 10.7782 | N44: 7.4445 | O44: 16.0638 | Q44: 9.6902 | R44: 9.5586 | S44: 9.8304 | U44: 8.7503 | V44: 4.8916 | W44: 16.626 | Y44: 10.4372 | Z44: 6.9253 | AA44: 16.3472 | AC44: 10.9737 | AD44: 8.8496 | AE44: 13.9642
B45: 1100 | C45: 900
B46: 1200 | C46: 800 | E46: 8.9654 | F46: 7.434 | G46: 12.1897 | I46: 8.9654 | J46: 7.434 | K46: 12.1897 | M46: 9.643 | N46: 7.1443 | O46: 16.2739 | Q46: 9.1818 | R46: 8.0817 | S46: 11.1893 | U46: 6.926 | V46: 4.0377 | W46: 16.6459 | Y46: 8.9463 | Z46: 6.3368 | AA46: 16.2153 | AC46: 10.4113 | AD46: 9.0644 | AE46: 13.1077
...

Sheet seed2
B2: 合流車線 | C2: 本線 | E2: 提案手法 | F2: 線形, v_max | I2: 提案手法 | J2: 2次, v_max | M2: 加藤さん | Q2: 全て受け入れ | U2: PriMa20% | Y2: PriMa40%
B3: [台/h] | C3: [台/h] | E3: all_speed | F3: cav0_speed | G3: cav1_speed | I3: all_speed | J3: cav0_speed | K3: cav1_speed | M3: all_speed | N3: cav0_speed | O3: cav1_speed | Q3: all_speed | R3: cav0_speed | S3: cav1_speed | U3: all_speed | V3: cav0_speed | W3: cav1_speed | Y3: all_speed | Z3: cav0_speed | AA3: cav1_speed
A5: 合流開始 | B5: 500 | C5: 1500
A6: 100m | B6: 600 | C6: 1400 | E6: 14.1666 | F6: 10.4359 | G6: 16.2895 | I6: 14.3205 | J6: 10.9704 | K6: 16.139 | M6: 14.0191 | N6: 9.8531 | O6: 16.5126 | Q6: 13.3129 | R6: 15.3915 | S6: 12.5396 | U6: 13.1505 | V6: 7.9884 | W6: 16.67 | Y6: 13.7254 | Z6: 14.7701 | AA6: 13.3162
A7: シミュ時間 | B7: 700 | C7: 1300
A8: 90s | B8: 800 | C8: 1200 | E8: 14.9901 | F8: 13.468 | G8: 16.211 | I8: 14.3914 | J8: 13.5174 | K8: 15.0455 | M8: 14.8239 | N8: 12.7501 | O8: 16.5539 | Q8: 13.2801 | R8: 14.4199 | S8: 12.4885 | U8: 13.0453 | V8: 9.47 | W8: 16.67 | Y8: 15.5214 | Z8: 14.8563 | AA8: 16.0027
B9: 900 | C9: 1100
B10: 1000 | C10: 1000 | E10: 13.1419 | F10: 12.09 | G10: 14.3004 | I10: 12.873 | J10: 11.7184 | K10: 14.1444 | M10: 13.1357 | N10: 11.4564 | O10: 15.02 | Q10: 12.597 | R10: 12.8719 | S10: 12.3272 | U10: 11.3217 | V10: 7.9661 | W10: 16.67 | Y10: 13.4411 | Z10: 11.9498 | AA10: 15.1425
B11: 1100 | C11: 900
B12: 1200 | C12: 800 | E12: 11.3883 | F12: 10.1153 | G12: 13.8715 | I12: 11.4443 | J12: 10.2772 | K12: 13.7352 | M12: 11.7288 | N12: 9.9787 | O12: 15.3841 | Q12: 10.7125 | R12: 10.478 | S12: 11.1204 | U12: 10.6849 | V12: 8.2118 | W12: 16.67 | Y12: 13.9818 | Z12: 12.6904 | AA12: 16.4349
B13: 1300 | C13: 700
B14: 1400 | C14: 600 | E14: 14.0421 | F14: 13.655 | G14: 15.1709 | I14: 14.0537 | J14: 13.6165 | K14: 15.3302 | M14: 13.7534 | N14: 12.9107 | O14: 16.2441 | Q14: 12.3773 | R14: 13.014 | S14: 10.8702 | U14: 13.3812 | V14: 12.3373 | W14: 16.67 | Y14: 13.6152 | Z14: 12.7003 | AA14: 16.4582
B15: 1500 | C15: 500
B17: 1000 | C17: 1400 | E17: 12.7493 | F17: 10.423 | G17: 14.9324 | I17: 12.7279 | J17: 11.3878 | K17: 13.812 | M17: 12.1192 | N17: 8.6336 | O17: 15.9701 | Q17: 11.4801 | R17: 12.5657 | S17: 10.7271 | U17: 11.4336 | V17: 7.0507 | W17: 16.67 | Y17: 13.6069 | Z17: 11.0456 | AA17: 15.9431
B18: 1200 | C18: 1200 | E18: 11.3454 | F18: 10.8792 | G18: 11.8212 | I18: 11.3454 | J18: 10.8792 | K18: 11.8212 | M18: 12.8676 | N18: 10.363 | O18: 16.1692 | Q18: 10.9604 | R18: 13.0512 | S18: 9.2395 | U18: 9.6326 | V18: 5.7077 | W18: 16.67 | Y18: 13.5437 | Z18: 11.4689 | AA18: 16.1164
B19: 1400 | C19: 1000 | E19: 10.4691 | F19: 9.1065 | G19: 12.918 | I19: 9.4792 | J19: 8.9498 | K19: 10.2938 | M19: 11.7318 | N19: 9.9062 | O19: 15.3864 | Q19: 8.7582 | R19: 8.7844 | S19: 8.7207 | U19: 10.0066 | V19: 7.2686 | W19: 16.67 | Y19: 11.779 | Z19: 9.9028 | AA19: 15.6425
B20: 800 | C20: 800 | E20: 14.7547 | F20: 14.6452 | G20: 14.8641 | I20: 14.7429 | J20: 14.6336 | K20: 14.8522 | M20: 15.2068 | N20: 13.9285 | O20: 16.67 | Q20: 14.3626 | R20: 14.8675 | S20: 13.8633 | U20: 14.4558 | V20: 12.6581 | W20: 16.67 | Y20: 15.5282 | Z20: 14.6992 | AA20: 16.4325
B22: 500 | C22: 1500
A23: (30s~) | B23: 600 | C23: 1400 | E23: 13.5777 | F23: 8.8672 | G23: 16.1988 | I23: 13.7696 | J23: 9.4893 | K23: 16.0114 | M23: 13.3972 | N23: 8.2046 | O23: 16.4791 | Q23: 12.5241 | R23: 15.1825 | S23: 11.6746 | U23: 12.3375 | V23: 6.1373 | W23: 16.67 | Y23: 13.0259 | Z23: 14.3148 | AA23: 12.586
B24: 700 | C24: 1300
B25: 800 | C25: 1200 | E25: 14.6661 | F25: 12.4554 | G25: 16.1637 | I25: 13.9323 | J25: 12.4963 | K25: 14.8264 | M25: 14.4631 | N25: 11.5226 | O25: 16.5612 | Q25: 12.5859 | R25: 13.7352 | S25: 11.9302 | U25: 11.1726 | V25: 7.8995 | W25: 16.67 | Y25: 15.3228 | Z25: 14.3036 | AA25: 15.9248
B26: 900 | C26: 1100
B27: 1000 | C27: 1000 | E27: 12.4185 | F27: 10.9995 | G27: 13.8869 | I27: 12.0906 | J27: 10.5329 | K27: 13.7027 | M27: 12.409 | N27: 10.2084 | O27: 14.7389 | Q27: 11.783 | R27: 11.963 | S27: 11.6207 | U27: 10.4366 | V27: 6.5745 | W27: 16.67 | Y27: 12.7849 | Z27: 10.8474 | AA27: 14.8934
B28: 1100 | C28: 900
B29: 1200 | C29: 800 | E29: 10.3256 | F29: 8.8141 | G29: 13.3177 | I29: 10.3916 | J29: 9.0116 | K29: 13.1444 | M29: 10.742 | N29: 8.6821 | O29: 15.1791 | Q29: 9.4907 | R29: 9.1883 | S29: 10.0109 | U29: 9.7021 | V29: 6.9928 | W29: 16.67 | Y29: 13.42 | Z29: 11.8773 | AA29: 16.3796
B30: 1300 | C30: 700
B31: 1400 | C31: 600 | E31: 13.5566 | F31: 13.1112 | G31: 14.8582 | I31: 13.5722 | J31: 13.0627 | K31: 15.0637 | M31: 13.1862 | N31: 12.1585 | O31: 16.2421 | Q31: 11.4923 | R31: 12.2958 | S31: 9.6836 | U31: 12.9369 | V31: 11.7746 | W31: 16.67 | Y31: 13.048 | Z31: 11.988 | AA31: 16.4081
B32: 1500 | C32: 500
B34: 1000 | C34: 1400 | E34: 11.9818 | F34: 9.1966 | G34: 14.6514 | I34: 11.9557 | J34: 10.2801 | K34: 13.291 | M34: 11.3515 | N34: 7.5435 | O34: 15.7826 | Q34: 10.4576 | R34: 11.7076 | S34: 9.6335 | U34: 10.535 | V34: 5.7395 | W34: 16.67 | Y34: 13.0231 | Z34: 9.8934 | AA34: 15.9205
B35: 1200 | C35: 1200 | E35: 10.3303 | F35: 9.6177 | G35: 11.0202 | I35: 10.3303 | J35: 9.6177 | K35: 11.0202 | M35: 12.1179 | N35: 9.0581 | O35: 16.1578 | Q35: 9.88 | R35: 12.2275 | S35: 8.1295 | U35: 8.5671 | V35: 4.2993 | W35: 16.67 | Y35: 12.9332 | Z35: 10.3519 | AA35: 16.093
B36: 1400 | C36: 1000 | E36: 9.3849 | F36: 7.8298 | G36: 12.2544 | I36: 8.2387 | J36: 7.6144 | K36: 9.1912 | M36: 10.8459 | N36: 8.7768 | O36: 15.2331 | Q36: 7.396 | R36: 7.3637 | S36: 7.4413 | U36: 8.8543 | V36: 5.9464 | W36: 16.67 | Y36: 10.9063 | Z36: 8.7873 | AA36: 15.5632
B37: 800 | C37: 800 | E37: 14.2671 | F37: 13.8665 | G37: 14.5956 | I37: 14.2522 | J37: 13.8502 | K37: 14.5819 | M37: 14.8256 | N37: 12.9235 | O37: 16.67 | Q37: 13.7753 | R37: 14.1763 | S37: 13.4502 | U37: 13.9008 | V37: 11.3156 | W37: 16.67 | Y37: 15.2296 | Z37: 13.9506 | AA37: 16.3938
A39: 合流開始 | B39: 500 | C39: 1500
A40: 200m | B40: 600 | C40: 1400 | E40: 14.3984 | F40: 11.2399 | G40: 16.0378 | I40: 14.3984 | J40: 11.2399 | K40: 16.0378 | M40: 11.8661 | N40: 5.9129 | O40: 16.67 | Q40: 12.7173 | R40: 14.2921 | S40: 12.1089 | U40: 11.8661 | V40: 5.9129 | W40: 16.67 | Y40: 13.0215 | Z40: 7.7986 | AA40: 16.55662 | AC40: 14.0814 | AD40: 10.1882 | AE40: 16.2505
A41: シミュ時間 | B41: 700 | C41: 1300
A42: 90s | B42: 800 | C42: 1200 | E42: 12.27 | F42: 9.8374 | G42: 14.4492 | I42: 12.1301 | J42: 9.9362 | K42: 14.0449 | M42: 13.6382 | N42: 10.552 | O42: 16.4756 | Q42: 10.5161 | R42: 12.7879 | S42: 9.0541 | U42: 10.8321 | V42: 6.2907 | W42: 16.6514 | Y42: 11.8565 | Z42: 7.83 | AA42: 16.3038 | AC42: 12.27 | AD42: 9.8374 | AE42: 14.4492
B43: 900 | C43: 1100
B44: 1000 | C44: 1000 | E44: 12.6874 | F44: 10.7624 | G44: 15.1321 | I44: 12.2368 | J44: 10.3615 | K44: 14.5662 | M44: 11.6234 | N44: 8.3357 | O44: 16.6052 | Q44: 12.2579 | R44: 12.156 | S44: 12.3606 | U44: 11.0438 | V44: 7.5644 | W44: 16.6266 | Y44: 11.6234 | Z44: 8.3357 | AA44: 16.6052 | AC44: 12.6874 | AD44: 10.7624 | AE44: 15.1321
B45: 1100 | C45: 900
B46: 1200 | C46: 800 | E46: 9.9168 | F46: 8.3143 | G46: 13.3499 | I46: 10.1717 | J46: 8.8187 | K46: 13.0986 | M46: 9.1454 | N46: 6.4094 | O46: 16.1907 | Q46: 10.1115 | R46: 8.6725 | S46: 13.109 | U46: 9.3262 | V46: 6.5604 | W46: 16.5506 | Y46: 9.3262 | Z46: 6.5604 | AA46: 16.5506 | AC46: 9.9168 | AD46: 8.3143 | AE46: 13.3499
...

Sheet seed3
B2: 合流車線 | C2: 本線 | E2: 提案手法 | F2: 線形, v_max | I2: 提案手法 | J2: 2次, v_max | M2: 加藤さん | Q2: 全て受け入れ | U2: PriMa20% | Y2: PriMa40%
B3: [台/h] | C3: [台/h] | E3: all_speed | F3: cav0_speed | G3: cav1_speed | I3: all_speed | J3: cav0_speed | K3: cav1_speed | M3: all_speed | N3: cav0_speed | O3: cav1_speed | Q3: all_speed | R3: cav0_speed | S3: cav1_speed | U3: all_speed | V3: cav0_speed | W3: cav1_speed | Y3: all_speed | Z3: cav0_speed | AA3: cav1_speed
A5: 合流開始 | B5: 500 | C5: 1500
A6: 100m | B6: 600 | C6: 1400 | E6: 15.3352 | F6: 13.5838 | G6: 16.1625 | I6: 15.3683 | J6: 14.7685 | K6: 15.6262 | M6: 13.8286 | N6: 9.5068 | O6: 16.5214 | Q6: 14.8653 | R6: 14.1352 | S6: 15.1821 | U6: 13.344 | V6: 8.423 | W6: 16.67 | Y6: 15.8716 | Z6: 15.4505 | AA6: 16.0513
A7: シミュ時間 | B7: 700 | C7: 1300
A8: 90s | B8: 800 | C8: 1200 | E8: 13.376 | F8: 10.6125 | G8: 15.8998 | I8: 13.3063 | J8: 10.7196 | K8: 15.6091 | M8: 13.9313 | N8: 11.0265 | O8: 16.5149 | Q8: 12.0966 | R8: 11.9932 | S8: 12.1636 | U8: 12.1511 | V8: 8.097 | W8: 16.67 | Y8: 14.0219 | Z8: 11.3342 | AA8: 16.3744
B9: 900 | C9: 1100
B10: 1000 | C10: 1000 | E10: 12.4887 | F10: 10.6394 | G10: 15 | I10: 11.9106 | J10: 10.7758 | K10: 13.344 | M10: 11.2105 | N10: 8.4549 | O10: 15.7707 | Q10: 9.1415 | R10: 8.017 | S10: 10.4485 | U10: 11.1048 | V10: 7.8833 | W10: 16.6516 | Y10: 12.8364 | Z10: 10.4451 | AA10: 16.3435
B11: 1100 | C11: 900
B12: 1200 | C12: 800 | E12: 11.6059 | F12: 10.2135 | G12: 14.0622 | I12: 10.8532 | J12: 9.7043 | K12: 12.8649 | M12: 11.6554 | N12: 9.7465 | O12: 15.7791 | Q12: 10.0698 | R12: 10.516 | S12: 9.5223 | U12: 9.7576 | V12: 6.984 | W12: 16.67 | Y12: 11.8662 | Z12: 10.1141 | AA12: 15.3712
B13: 1300 | C13: 700
B14: 1400 | C14: 600 | E14: 8.799 | F14: 7.9519 | G14: 10.6633 | I14: 8.799 | J14: 7.9519 | K14: 10.6633 | M14: 11.3412 | N14: 9.9348 | O14: 15.715 | Q14: 10.2224 | R14: 10.9431 | S14: 9.0669 | U14: 10.6022 | V14: 8.7757 | W14: 16.6595 | Y14: 11.243 | Z14: 9.6632 | AA14: 16.0559
B15: 1500 | C15: 500
B17: 1000 | C17: 1400 | E17: 10.5282 | F17: 8.2002 | G17: 12.805 | I17: 10.0927 | J17: 7.8959 | K17: 12.1731 | M17: 11.2507 | N17: 7.2483 | O17: 16.3592 | Q17: 9.8756 | R17: 10.6196 | S17: 9.4017 | U17: 9.4506 | V17: 4.5779 | W17: 16.67 | Y17: 12.0285 | Z17: 8.4746 | AA17: 15.9757
B18: 1200 | C18: 1200 | E18: 10.7438 | F18: 8.4663 | G18: 13.7968 | I18: 10.4953 | J18: 8.2935 | K18: 13.3721 | M18: 10.4474 | N18: 7.2177 | O18: 15.8514 | Q18: 8.7872 | R18: 9.8149 | S18: 7.9123 | U18: 9.1498 | V18: 5.0734 | W18: 16.6548 | Y18: 10.7168 | Z18: 7.4898 | AA18: 15.9824
B19: 1400 | C19: 1000 | E19: 10.1567 | F19: 8.8713 | G19: 12.3128 | I19: 8.5595 | J19: 7.3309 | K19: 10.5585 | M19: 9.8217 | N19: 7.0742 | O19: 15.9647 | Q19: 9.3647 | R19: 11.0009 | S19: 7.7335 | U19: 8.5607 | V19: 5.3628 | W19: 16.6527 | Y19: 9.6365 | Z19: 6.7257 | AA19: 16.3789
B20: 800 | C20: 800 | E20: 15.3164 | F20: 14.4108 | G20: 16.3948 | I20: 15.3164 | J20: 14.4108 | K20: 16.3948 | M20: 15.317 | N20: 14.3017 | O20: 16.5455 | Q20: 16.0057 | R20: 15.7959 | S20: 16.2312 | U20: 13.1964 | V20: 10.8642 | W20: 16.67 | Y20: 13.9837 | Z20: 12.1849 | AA20: 16.4342
B22: 500 | C22: 1500
A23: (30s~) | B23: 600 | C23: 1400 | E23: 15.038 | F23: 13.1314 | G23: 16.049 | I23: 15.0752 | J23: 14.5355 | K23: 15.3301 | M23: 13.2328 | N23: 8.8258 | O23: 16.4689 | Q23: 14.4383 | R23: 13.7786 | S23: 14.752 | U23: 12.6391 | V23: 7.6473 | W23: 16.67 | Y23: 15.7316 | Z23: 15.3694 | AA23: 15.901
B24: 700 | C24: 1300
B25: 800 | C25: 1200 | E25: 13.0399 | F25: 9.7618 | G25: 16.2994 | I25: 12.9454 | J25: 9.8832 | K25: 15.8887 | M25: 13.5961 | N25: 10.1798 | O25: 16.5577 | Q25: 11.4163 | R25: 11.4576 | S25: 11.3903 | U25: 11.3211 | V25: 7.0778 | W25: 16.67 | Y25: 13.6569 | Z25: 10.6475 | AA25: 16.4791
B26: 900 | C26: 1100
B27: 1000 | C27: 1000 | E27: 11.9948 | F27: 10.0173 | G27: 15.1486 | I27: 11.2355 | J27: 10.1749 | K27: 12.7637 | M27: 10.173 | N27: 7.61 | O27: 15.436 | Q27: 8.1744 | R27: 6.9759 | S27: 9.6812 | U27: 10.0611 | V27: 6.9871 | W27: 16.6422 | Y27: 12.1656 | Z27: 9.7413 | AA27: 16.4664
B28: 1100 | C28: 900
B29: 1200 | C29: 800 | E29: 10.9101 | F29: 9.256 | G29: 14.1355 | I29: 9.9624 | J29: 8.6424 | K29: 12.5057 | M29: 10.7605 | N29: 8.8984 | O29: 15.4934 | Q29: 9.2661 | R29: 9.4662 | S29: 9.0223 | U29: 8.3998 | V29: 5.6819 | W29: 16.67 | Y29: 11.0092 | Z29: 9.2792 | AA29: 14.9904
B30: 1300 | C30: 700
B31: 1400 | C31: 600 | E31: 7.5644 | F31: 6.6683 | G31: 9.7011 | I31: 7.5644 | J31: 6.6683 | K31: 9.7011 | M31: 10.4522 | N31: 9.1561 | O31: 15.4358 | Q31: 9.4129 | R31: 10.026 | S31: 8.4303 | U31: 9.475 | V31: 7.7615 | W31: 16.6539 | Y31: 10.3143 | Z31: 8.8098 | AA31: 15.9489
B32: 1500 | C32: 500
B34: 1000 | C34: 1400 | E34: 9.9596 | F34: 7.1945 | G34: 12.9992 | I34: 9.4259 | J34: 6.8419 | K34: 12.14 | M34: 10.3281 | N34: 6.5332 | O34: 16.2173 | Q34: 9.1681 | R34: 9.9921 | S34: 8.6448 | U34: 8.1272 | V34: 3.5239 | W34: 16.67 | Y34: 11.2654 | Z34: 7.5813 | AA34: 16.0953
B35: 1200 | C35: 1200 | E35: 9.9609 | F35: 7.242 | G35: 13.8342 | I35: 9.6783 | J35: 7.0548 | K35: 13.291 | M35: 9.3675 | N35: 6.0457 | O35: 15.5814 | Q35: 7.9192 | R35: 8.6034 | S35: 7.3676 | U35: 7.7955 | V35: 3.5951 | W35: 16.6495 | Y35: 9.7214 | Z35: 6.3086 | AA35: 15.9195
B36: 1400 | C36: 1000 | E36: 9.2945 | F36: 7.8061 | G36: 11.9371 | I36: 7.4262 | J36: 6.0391 | K36: 9.7874 | M36: 8.6521 | N36: 5.816 | O36: 15.9074 | Q36: 8.5744 | R36: 10.0934 | S36: 7.1497 | U36: 7.1301 | V36: 3.9443 | W36: 16.646 | Y36: 8.4262 | Z36: 5.4254 | AA36: 16.471
B37: 800 | C37: 800 | E37: 15.2822 | F37: 14.2566 | G37: 16.5369 | I37: 15.2822 | J37: 14.2566 | K37: 16.5369 | M37: 15.2691 | N37: 14.2367 | O37: 16.5435 | Q37: 16.2576 | R37: 16.1057 | S37: 16.4186 | U37: 12.5324 | V37: 9.9921 | W37: 16.67 | Y37: 13.5583 | Z37: 11.6393 | AA37: 16.3383
A39: 合流開始 | B39: 500 | C39: 1500
A40: 200m | B40: 600 | C40: 1400 | E40: 14.3272 | F40: 11.122 | G40: 15.9968 | I40: 14.2397 | J40: 11.1572 | K40: 15.8835 | M40: 12.1989 | N40: 6.1974 | O40: 16.67 | Q40: 14.6109 | R40: 13.3536 | S40: 15.1697 | U40: 12.1989 | V40: 6.1974 | W40: 16.67 | Y40: 14.8462 | Z40: 12.7329 | AA40: 15.8551 | AC40: 13.5402 | AD40: 9.3872 | AE40: 16.0007
A41: シミュ時間 | B41: 700 | C41: 1300
A42: 90s | B42: 800 | C42: 1200 | E42: 11.8627 | F42: 9.0711 | G42: 14.5149 | I42: 11.2844 | J42: 8.3232 | K42: 13.9836 | M42: 9.3588 | N42: 4.3408 | O42: 16.67 | Q42: 12.982 | R42: 12.8924 | S42: 13.0385 | U42: 9.3588 | V42: 4.3408 | W42: 16.67 | Y42: 9.9633 | Z42: 5.0171 | AA42: 16.6077 | AC42: 11.7086 | AD42: 8.5679 | AE42: 14.7988
B43: 900 | C43: 1100
B44: 1000 | C44: 1000 | E44: 11.348 | F44: 9.9275 | G44: 13.181 | I44: 11.1033 | J44: 9.1505 | K44: 13.792 | M44: 8.4448 | N44: 4.5946 | O44: 16.6293 | Q44: 10.974 | R44: 10.2669 | S44: 11.7546 | U44: 8.4448 | V44: 4.5946 | W44: 16.6293 | Y44: 9.0119 | Z44: 5.2158 | AA44: 16.5551 | AC44: 11.348 | AD44: 9.9275 | AE44: 13.181
B45: 1100 | C45: 900
B46: 1200 | C46: 800 | E46: 10.6366 | F46: 9.5573 | G46: 12.3747 | I46: 10.9795 | J46: 9.7772 | K46: 12.9786 | M46: 8.2006 | N46: 5.0914 | O46: 16.5595 | Q46: 10.1768 | R46: 10.984 | S46: 9.253 | U46: 6.8341 | V46: 3.5991 | W46: 16.6544 | Y46: 8.6824 | Z46: 5.6732 | AA46: 16.3736 | AC46: 10.7931 | AD46: 9.6851 | AE46: 12.6036
...

Sheet seed4
B2: 合流車線 | C2: 本線 | E2: 提案手法 | F2: 線形, v_max | I2: 提案手法 | J2: 2次, v_max | M2: 加藤さん | Q2: 全て受け入れ | U2: PriMa20% | Y2: PriMa40%
B3: [台/h] | C3: [台/h] | E3: all_speed | F3: cav0_speed | G3: cav1_speed | I3: all_speed | J3: cav0_speed | K3: cav1_speed | M3: all_speed | N3: cav0_speed | O3: cav1_speed | Q3: all_speed | R3: cav0_speed | S3: cav1_speed | U3: all_speed | V3: cav0_speed | W3: cav1_speed | Y3: all_speed | Z3: cav0_speed | AA3: cav1_speed
A5: 合流開始 | B5: 500 | C5: 1500
A6: 100m | B6: 600 | C6: 1400 | E6: 14.3689 | F6: 11.3293 | G6: 16.0394 | I6: 14.3689 | J6: 11.3293 | K6: 16.0394 | M6: 13.8008 | N6: 9.5499 | O6: 16.5097 | Q6: 12.7177 | R6: 8.7112 | S6: 15.4293 | U6: 12.4547 | V6: 7.0527 | W6: 16.67 | Y6: 14.171 | Z6: 10.4405 | AA6: 16.4057
A7: シミュ時間 | B7: 700 | C7: 1300
A8: 90s | B8: 800 | C8: 1200 | E8: 11.9817 | F8: 10.473 | G8: 13.2769 | I8: 12.8447 | J8: 10.7745 | K8: 14.7788 | M8: 13.3421 | N8: 10.4294 | O8: 16.2901 | Q8: 11.374 | R8: 11.1386 | S8: 11.5504 | U8: 12.7957 | V8: 9.1915 | W8: 16.67 | Y8: 13.2778 | Z8: 10.1236 | AA8: 16.4795
B9: 900 | C9: 1100
B10: 1000 | C10: 1000 | E10: 14.5477 | F10: 14.3202 | G10: 14.7909 | I10: 14.5477 | J10: 14.3202 | K10: 14.7909 | M10: 14.6877 | N10: 13.237 | O10: 16.483 | Q10: 11.938 | R10: 13.1557 | S10: 10.7488 | U10: 13.0054 | V10: 10.4245 | W10: 16.67 | Y10: 14.0685 | Z10: 12.2149 | AA10: 16.5147
B11: 1100 | C11: 900
B12: 1200 | C12: 800 | E12: 10.4724 | F12: 9.3445 | G12: 12.5721 | I12: 10.4664 | J12: 9.0256 | K12: 13.2423 | M12: 12.0706 | N12: 10.2636 | O12: 15.991 | Q12: 10.1405 | R12: 10.1702 | S12: 10.1001 | U12: 11.0532 | V12: 8.7219 | W12: 16.67 | Y12: 12.0238 | Z12: 10.0593 | AA12: 16.2784
B13: 1300 | C13: 700
B14: 1400 | C14: 600 | E14: 12.0103 | F14: 11.3837 | G14: 13.6479 | I14: 13.11 | J14: 12.2615 | K14: 15.3837 | M14: 12.4258 | N14: 11.1872 | O14: 16.0346 | Q14: 10.2754 | R14: 11.8053 | S14: 7.2 | U14: 11.7998 | V14: 10.2532 | W14: 16.67 | Y14: 13.1457 | Z14: 12.0872 | AA14: 16.0884
B15: 1500 | C15: 500
B17: 1000 | C17: 1400 | E17: 12.3617 | F17: 10.2505 | G17: 14.2692 | I17: 12.2022 | J17: 11.0522 | K17: 13.1062 | M17: 12.1303 | N17: 8.4354 | O17: 16.3654 | Q17: 11.221 | R17: 11.8672 | S17: 10.7622 | U17: 11.2742 | V17: 6.9418 | W17: 16.67 | Y17: 13.4305 | Z17: 10.6565 | AA17: 16.1394
B18: 1200 | C18: 1200 | E18: 9.469 | F18: 7.8353 | G18: 11.5527 | I18: 9.7612 | J18: 7.4484 | K18: 13.0474 | M18: 10.6733 | N18: 7.7449 | O18: 15.5377 | Q18: 9.5332 | R18: 10.2028 | S18: 8.9047 | U18: 9.713 | V18: 5.95 | W18: 16.6643 | Y18: 11.4473 | Z18: 8.46 | AA18: 16.2387
B19: 1400 | C19: 1000 | E19: 9.9188 | F19: 8.8148 | G19: 11.8038 | I19: 10.0931 | J19: 9.1852 | K19: 11.6338 | M19: 11.8159 | N19: 9.7331 | O19: 15.803 | Q19: 10.117 | R19: 9.3229 | S19: 11.2961 | U19: 11.2571 | V19: 8.7111 | W19: 16.67 | Y19: 12.622 | Z19: 10.6758 | AA19: 16.1721
B20: 800 | C20: 800 | E20: 15.8382 | F20: 15.3444 | G20: 16.4256 | I20: 15.3773 | J20: 15.3698 | K20: 15.3857 | M20: 15.1975 | N20: 14.1915 | O20: 16.4583 | Q20: 15.109 | R20: 14.4079 | S20: 15.9605 | U20: 14.8666 | V20: 13.4778 | W20: 16.67 | Y20: 15.8987 | Z20: 15.3406 | AA20: 16.5625
B22: 500 | C22: 1500
A23: (30s~) | B23: 600 | C23: 1400 | E23: 13.9846 | F23: 10.4887 | G23: 15.954 | I23: 13.9846 | J23: 10.4887 | K23: 15.954 | M23: 13.2867 | N23: 8.456 | O23: 16.5523 | Q23: 11.9642 | R23: 7.539 | S23: 15.1754 | U23: 11.7543 | V23: 6.0351 | W23: 16.67 | Y23: 13.7401 | Z23: 9.4666 | AA23: 16.4191
B24: 700 | C24: 1300
B25: 800 | C25: 1200 | E25: 10.8879 | F25: 9.0618 | G25: 12.449 | I25: 11.9212 | J25: 9.45 | K25: 14.2703 | M25: 12.5366 | N25: 9.0735 | O25: 16.1803 | Q25: 10.2069 | R25: 9.8556 | S25: 10.461 | U25: 11.8647 | V25: 7.6284 | W25: 16.67 | Y25: 12.448 | Z25: 8.6836 | AA25: 16.4242
B26: 900 | C26: 1100
B27: 1000 | C27: 1000 | E27: 14.0046 | F27: 13.7522 | G27: 14.2731 | I27: 14.0046 | J27: 13.7522 | K27: 14.2731 | M27: 14.1952 | N27: 12.4521 | O27: 16.4305 | Q27: 10.8428 | R27: 12.3405 | S27: 9.4173 | U27: 12.1369 | V27: 9.1573 | W27: 16.67 | Y27: 13.4345 | Z27: 11.2495 | AA27: 16.4714
B28: 1100 | C28: 900
B29: 1200 | C29: 800 | E29: 9.3389 | F29: 8.2158 | G29: 11.6959 | I29: 9.318 | J29: 7.8325 | K29: 12.585 | M29: 11.1402 | N29: 9.349 | O29: 15.8548 | Q29: 9.0788 | R29: 9.0806 | S29: 9.0763 | U29: 9.9936 | V29: 7.7531 | W29: 16.67 | Y29: 11.0754 | Z29: 9.0875 | AA29: 16.2868
B30: 1300 | C30: 700
B31: 1400 | C31: 600 | E31: 10.9806 | F31: 10.4103 | G31: 12.6289 | I31: 12.3051 | J31: 11.437 | K31: 14.914 | M31: 11.4978 | N31: 10.3201 | O31: 15.7946 | Q31: 9.0086 | R31: 10.9526 | S31: 5.0033 | U31: 10.7652 | V31: 9.1619 | W31: 16.67 | Y31: 12.3623 | Z31: 11.2488 | AA31: 15.8709
B32: 1500 | C32: 500
B34: 1000 | C34: 1400 | E34: 11.5177 | F34: 8.9937 | G34: 13.8077 | I34: 11.3429 | J34: 9.897 | K34: 12.4495 | M34: 11.3472 | N34: 7.2367 | O34: 16.2954 | Q34: 10.1945 | R34: 10.8826 | S34: 9.7286 | U34: 10.3601 | V34: 5.6108 | W34: 16.67 | Y34: 12.7782 | Z34: 9.4926 | AA34: 16.0603
B35: 1200 | C35: 1200 | E35: 8.3586 | F35: 6.4484 | G35: 10.8187 | I35: 8.6831 | J35: 6.0235 | K35: 12.5915 | M35: 9.6254 | N35: 6.4407 | O35: 15.3243 | Q35: 8.5544 | R35: 9.1217 | S35: 8.0493 | U35: 8.5911 | V35: 4.5984 | W35: 16.6626 | Y35: 10.5554 | Z35: 7.2443 | AA35: 16.2323
B36: 1400 | C36: 1000 | E36: 8.7491 | F36: 7.5911 | G36: 10.7898 | I36: 8.9314 | J36: 7.9999 | K36: 10.5623 | M36: 10.9142 | N36: 8.5984 | O36: 15.6373 | Q36: 8.9894 | R36: 8.1207 | S36: 10.2835 | U36: 10.3593 | V36: 7.6282 | W36: 16.67 | Y36: 11.8739 | Z36: 9.6706 | AA36: 16.1143
B37: 800 | C37: 800 | E37: 15.6066 | F37: 14.8705 | G37: 16.3778 | I37: 15.0301 | J37: 14.9041 | K37: 15.1523 | M37: 14.803 | N37: 13.3674 | O37: 16.417 | Q37: 14.6898 | R37: 13.6397 | S37: 15.8245 | U37: 14.3904 | V37: 12.4538 | W37: 16.67 | Y37: 15.6839 | Z37: 14.8654 | AA37: 16.5415
A39: 合流開始 | B39: 500 | C39: 1500
A40: 200m | B40: 600 | C40: 1400 | E40: 14.2766 | F40: 11.1999 | G40: 15.9264 | I40: 14.2856 | J40: 12.1666 | K40: 15.3174 | M40: 12.3856 | N40: 6.8156 | O40: 16.5853 | Q40: 13.6767 | R40: 14.33 | S40: 13.4028 | U40: 11.1652 | V40: 5.0679 | W40: 16.67 | Y40: 14.4085 | Z40: 11.1159 | AA40: 16.1863 | AC40: 14.2991 | AD40: 11.141 | AE40: 15.9926
A41: シミュ時間 | B41: 700 | C41: 1300
A42: 90s | B42: 800 | C42: 1200 | E42: 11.2461 | F42: 8.6519 | G42: 13.7941 | I42: 11.3306 | J42: 8.9629 | K42: 13.6036 | M42: 11.0203 | N42: 6.662 | O42: 16.478 | Q42: 11.5825 | R42: 11.2767 | S42: 11.8063 | U42: 8.9064 | V42: 4.1001 | W42: 16.67 | Y42: 11.3473 | Z42: 7.4978 | AA42: 15.5839 | AC42: 11.4271 | AD42: 8.6513 | AE42: 14.2077
B43: 900 | C43: 1100
B44: 1000 | C44: 1000 | E44: 11.8547 | F44: 9.7996 | G44: 14.6424 | I44: 11.876 | J44: 9.9495 | K44: 14.4603 | M44: 11.4369 | N44: 8.1915 | O44: 16.3799 | Q44: 11.7162 | R44: 10.92 | S44: 12.6382 | U44: 7.6892 | V44: 3.7186 | W44: 16.6326 | Y44: 11.4369 | Z44: 8.1915 | AA44: 16.3799 | AC44: 11.8547 | AD44: 9.7996 | AE44: 14.6424
B45: 1100 | C45: 900
B46: 1200 | C46: 800 | E46: 9.0776 | F46: 6.9924 | G46: 13.5534 | I46: 9.0776 | J46: 6.9924 | K46: 13.5534 | M46: 7.8301 | N46: 4.7938 | O46: 16.4334 | Q46: 9.5226 | R46: 8.4402 | S46: 11.447 | U46: 7.3979 | V46: 4.3085 | W46: 16.6646 | Y46: 8.2033 | Z46: 5.3006 | AA46: 15.8028 | AC46: 9.8102 | AD46: 7.9321 | AE46: 13.8614
...

Sheet seed5
B2: 合流車線 | C2: 本線 | E2: 提案手法 | F2: 線形, v_max | I2: 提案手法 | J2: 2次, v_max | M2: 加藤さん | Q2: 全て受け入れ | U2: PriMa20% | Y2: PriMa40%
B3: [台/h] | C3: [台/h] | E3: all_speed | F3: cav0_speed | G3: cav1_speed | I3: all_speed | J3: cav0_speed | K3: cav1_speed | M3: all_speed | N3: cav0_speed | O3: cav1_speed | Q3: all_speed | R3: cav0_speed | S3: cav1_speed | U3: all_speed | V3: cav0_speed | W3: cav1_speed | Y3: all_speed | Z3: cav0_speed | AA3: cav1_speed
A5: 合流開始 | B5: 500 | C5: 1500
A6: 100m | B6: 600 | C6: 1400 | E6: 12.2298 | F6: 8.2746 | G6: 14.7645 | I6: 12.2297 | J6: 8.4412 | K6: 14.6523 | M6: 12.1528 | N6: 7.034 | O6: 16.3523 | Q6: 10.7473 | R6: 12.8081 | S6: 9.9479 | U6: 10.9851 | V6: 5.0583 | W6: 16.67 | Y6: 13.5072 | Z6: 9.4378 | AA6: 16.2016
A7: シミュ時間 | B7: 700 | C7: 1300
A8: 90s | B8: 800 | C8: 1200 | E8: 11.2441 | F8: 10.07 | G8: 12.207 | I8: 11.2287 | J8: 10.0524 | K8: 12.193 | M8: 11.4893 | N8: 7.5013 | O8: 16.4496 | Q8: 10.9131 | R8: 14.3608 | S8: 9.0648 | U8: 11.0078 | V8: 6.5945 | W8: 16.67 | Y8: 13.5653 | Z8: 10.8642 | AA8: 16.1618
B9: 900 | C9: 1100
B10: 1000 | C10: 1000 | E10: 12.7586 | F10: 10.9416 | G10: 14.8934 | I10: 10.9404 | J10: 9.4868 | K10: 12.6538 | M10: 13.4937 | N10: 11.4493 | O10: 16.0453 | Q10: 10.0874 | R10: 9.56 | S10: 10.6169 | U10: 11.3013 | V10: 7.9161 | W10: 16.67 | Y10: 13.3252 | Z10: 11.0661 | AA10: 16.1908
B11: 1100 | C11: 900
B12: 1200 | C12: 800 | E12: 12.3987 | F12: 10.6351 | G12: 15.5971 | I12: 12.0496 | J12: 10.6766 | K12: 14.4424 | M12: 11.1486 | N12: 8.803 | O12: 16.0655 | Q12: 9.5597 | R12: 8.8422 | S12: 10.594 | U12: 10.5957 | V12: 7.8988 | W12: 16.67 | Y12: 11.1272 | Z12: 9.149 | AA12: 14.8141
B13: 1300 | C13: 700
B14: 1400 | C14: 600 | E14: 12.0521 | F14: 11.2614 | G14: 14.4654 | I14: 12.8471 | J14: 12.1039 | K14: 15.1037 | M14: 11.796 | N14: 10.559 | O14: 16.2041 | Q14: 9.6116 | R14: 9.3776 | S14: 10.1903 | U14: 11.4488 | V14: 10.0761 | W14: 16.6638 | Y14: 11.8891 | Z14: 10.8329 | AA14: 15.3561
B15: 1500 | C15: 500
B17: 1000 | C17: 1400 | E17: 11.0268 | F17: 8.7107 | G17: 13.1524 | I17: 9.7607 | J17: 7.3486 | K17: 11.8105 | M17: 10.7803 | N17: 6.4531 | O17: 16.0992 | Q17: 9.6034 | R17: 10.5017 | S17: 9.0384 | U17: 9.8726 | V17: 4.9002 | W17: 16.67 | Y17: 11.7982 | Z17: 7.9615 | AA17: 15.9164
B18: 1200 | C18: 1200 | E18: 11.4731 | F18: 9.442 | G18: 13.991 | I18: 9.6639 | J18: 8.3902 | K18: 11.0887 | M18: 9.9703 | N18: 6.1519 | O18: 16.3736 | Q18: 9.2609 | R18: 9.6005 | S18: 8.9574 | U18: 9.8064 | V18: 5.9316 | W18: 16.67 | Y18: 10.9495 | Z18: 7.5102 | AA18: 16.2682
B19: 1400 | C19: 1000 | E19: 9.2366 | F19: 7.5893 | G19: 12.499 | I19: 9.0341 | J19: 7.4102 | K19: 12.0747 | M19: 10.9195 | N19: 8.6316 | O19: 16.1425 | Q19: 8.1934 | R19: 8.2233 | S19: 8.1439 | U19: 10.7741 | V19: 8.2854 | W19: 16.67 | Y19: 11.083 | Z19: 9.0697 | AA19: 15.4281
B20: 800 | C20: 800 | E20: 12.1775 | F20: 10.9554 | G20: 13.6293 | I20: 11.9894 | J20: 11.1074 | K20: 13.0032 | M20: 13.1805 | N20: 10.9449 | O20: 16.2376 | Q20: 11.4092 | R20: 10.8248 | S20: 12.0931 | U20: 12.8004 | V20: 10.119 | W20: 16.67 | Y20: 13.8867 | Z20: 11.9414 | AA20: 16.4094
B22: 500 | C22: 1500
A23: (30s~) | B23: 600 | C23: 1400 | E23: 11.5118 | F23: 6.9882 | G23: 14.7019 | I23: 11.5127 | J23: 7.1858 | K23: 14.5557 | M23: 11.3379 | N23: 6.1666 | O23: 16.2487 | Q23: 9.6998 | R23: 12.2453 | S23: 8.7374 | U23: 9.9494 | V23: 4.0519 | W23: 16.67 | Y23: 12.925 | Z23: 8.4456 | AA23: 16.2478
B24: 700 | C24: 1300
B25: 800 | C25: 1200 | E25: 10.3069 | F25: 9.2648 | G25: 11.2541 | I25: 10.2883 | J25: 9.2444 | K25: 11.2366 | M25: 10.6504 | N25: 6.848 | O25: 16.3699 | Q25: 9.9018 | R25: 14.2806 | S25: 7.5242 | U25: 10.0749 | V25: 5.8475 | W25: 16.67 | Y25: 13.0374 | Z25: 10.2922 | AA25: 16.1205
B26: 900 | C26: 1100
B27: 1000 | C27: 1000 | E27: 12.1101 | F27: 10.1947 | G27: 14.6696 | I27: 9.953 | J27: 8.5786 | K27: 11.773 | M27: 12.9149 | N27: 10.8731 | O27: 15.8851 | Q27: 9.0128 | R27: 8.6593 | S27: 9.3948 | U27: 10.3244 | V27: 7.0427 | W27: 16.67 | Y27: 12.6867 | Z27: 10.3748 | AA27: 16.1198
B28: 1100 | C28: 900
B29: 1200 | C29: 800 | E29: 11.6286 | F29: 9.9642 | G29: 15.4124 | I29: 11.2746 | J29: 9.9564 | K29: 14.1077 | M29: 10.1332 | N29: 8.052 | O29: 15.7746 | Q29: 8.4439 | R29: 7.9036 | S29: 9.3259 | U29: 9.471 | V29: 7.0534 | W29: 16.67 | Y29: 10.1233 | Z29: 8.3027 | AA29: 14.3277
B30: 1300 | C30: 700
B31: 1400 | C31: 600 | E31: 11.3239 | F31: 10.4693 | G31: 14.1752 | I31: 12.2806 | J31: 11.458 | K31: 15.025 | M31: 10.9344 | N31: 9.6671 | O31: 16.1337 | Q31: 8.513 | R31: 8.2147 | S31: 9.2692 | U31: 10.5462 | V31: 9.1732 | W31: 16.6612 | Y31: 11.038 | Z31: 9.9618 | AA31: 14.9952
B32: 1500 | C32: 500
B34: 1000 | C34: 1400 | E34: 10.0998 | F34: 7.8828 | G34: 12.4517 | I34: 8.7604 | J34: 6.368 | K34: 11.0438 | M34: 9.7638 | N34: 5.7239 | O34: 15.8782 | Q34: 8.5997 | R34: 9.857 | S34: 7.7643 | U34: 8.6897 | V34: 4.0493 | W34: 16.67 | Y34: 11.018 | Z34: 7.0654 | AA34: 16.1584
B35: 1200 | C35: 1200 | E35: 10.5409 | F35: 8.6058 | G35: 13.2941 | I35: 8.4637 | J35: 7.4282 | K35: 9.7437 | M35: 8.7722 | N35: 5.14 | O35: 16.2585 | Q35: 8.1185 | R35: 8.72 | S35: 7.5529 | U35: 8.5972 | V35: 4.9328 | W35: 16.67 | Y35: 9.9193 | Z35: 6.4955 | AA35: 16.3449
B36: 1400 | C36: 1000 | E36: 8.2588 | F36: 6.635 | G36: 11.8849 | I36: 7.9707 | J36: 6.3633 | K36: 11.3262 | M36: 9.9315 | N36: 7.7234 | O36: 15.9992 | Q36: 7.0882 | R36: 7.3968 | S36: 6.5439 | U36: 9.7614 | V36: 7.3692 | W36: 16.67 | Y36: 10.0996 | Z36: 8.1615 | AA36: 15.0439
B37: 800 | C37: 800 | E37: 11.4498 | F37: 10.0869 | G37: 13.0881 | I37: 11.2477 | J37: 10.269 | K37: 12.3793 | M37: 12.596 | N37: 10.095 | O37: 16.1488 | Q37: 10.5832 | R37: 9.9618 | S37: 11.3171 | U37: 12.1537 | V37: 9.1702 | W37: 16.67 | Y37: 13.4059 | Z37: 11.1982 | AA37: 16.3552
A39: 合流開始 | B39: 500 | C39: 1500
A40: 200m | B40: 600 | C40: 1400 | E40: 11.6382 | F40: 8.0888 | G40: 13.8035 | I40: 11.6523 | J40: 8.2485 | K40: 13.6954 | M40: 10.7681 | N40: 4.6291 | O40: 16.6572 | Q40: 9.9976 | R40: 12.6397 | S40: 9.0893 | U40: 10.7681 | V40: 4.6291 | W40: 16.6572 | Y40: 11.3614 | Z40: 5.4186 | AA40: 16.5334 | AC40: 11.7288 | AD40: 7.7721 | AE40: 14.2443
A41: シミュ時間 | B41: 700 | C41: 1300
A42: 90s | B42: 800 | C42: 1200 | E42: 11.2163 | F42: 7.5669 | G42: 14.8424 | I42: 11.2163 | J42: 7.5669 | K42: 14.8424 | M42: 10.1647 | N42: 5.3114 | O42: 16.5923 | Q42: 10.5584 | R42: 10.9341 | S42: 10.3102 | U42: 9.602 | V42: 4.6402 | W42: 16.67 | Y42: 10.1845 | Z42: 5.3374 | AA42: 16.5614 | AC42: 10.4628 | AD42: 7.6158 | AE42: 13.1429
B43: 900 | C43: 1100
B44: 1000 | C44: 1000 | E44: 10.1008 | F44: 8.0677 | G44: 12.7892 | I44: 11.4044 | J44: 8.5052 | K44: 15.1861 | M44: 9.1848 | N44: 5.1189 | O44: 16.5637 | Q44: 10.8214 | R44: 10.2514 | S44: 11.3748 | U44: 8.6918 | V44: 4.5482 | W44: 16.6464 | Y44: 9.5114 | Z44: 5.5072 | AA44: 16.4503 | AC44: 10.495 | AD44: 8.307 | AE44: 13.4079
B45: 1100 | C45: 900
B46: 1200 | C46: 800 | E46: 8.4133 | F46: 6.2428 | G46: 12.6901 | I46: 8.4133 | J46: 6.2428 | K46: 12.6901 | M46: 7.194 | N46: 3.812 | O46: 16.6466 | Q46: 9.3899 | R46: 7.8154 | S46: 12.0867 | U46: 7.194 | V46: 3.812 | W46: 16.6466 | Y46: 7.9729 | Z46: 4.7062 | AA46: 16.4665 | AC46: 9.7166 | AD46: 8.35 | AE46: 11.9885
...

Sheet seed6
B2: 合流車線 | C2: 本線 | E2: 提案手法 | F2: 線形, v_max | I2: 提案手法 | J2: 2次, v_max | M2: 加藤さん | Q2: 全て受け入れ | U2: PriMa20% | Y2: PriMa40%
B3: [台/h] | C3: [台/h] | E3: all_speed | F3: cav0_speed | G3: cav1_speed | I3: all_speed | J3: cav0_speed | K3: cav1_speed | M3: all_speed | N3: cav0_speed | O3: cav1_speed | Q3: all_speed | R3: cav0_speed | S3: cav1_speed | U3: all_speed | V3: cav0_speed | W3: cav1_speed | Y3: all_speed | Z3: cav0_speed | AA3: cav1_speed
A5: 合流開始 | B5: 500 | C5: 1500
A6: 100m | B6: 600 | C6: 1400 | E6: 13.1398 | F6: 9.6903 | G6: 15.1641 | I6: 13.2353 | J6: 10.5273 | K6: 14.7109 | M6: 13.443 | N6: 8.9372 | O6: 16.533 | Q6: 10.2293 | R6: 9.8195 | S6: 10.4339 | U6: 13.2461 | V6: 8.3739 | W6: 16.67 | Y6: 14.074 | Z6: 10.8119 | AA6: 16.0479
A7: シミュ時間 | B7: 700 | C7: 1300
A8: 90s | B8: 800 | C8: 1200 | E8: 11.88 | F8: 8.7267 | G8: 14.9369 | I8: 14.0745 | J8: 11.4972 | K8: 16.2265 | M8: 13.2297 | N8: 9.8943 | O8: 16.3771 | Q8: 11.042 | R8: 11.4462 | S8: 10.7623 | U8: 12.8647 | V8: 8.9291 | W8: 16.67 | Y8: 13.8221 | Z8: 11.2573 | AA8: 16.0701
B9: 900 | C9: 1100
B10: 1000 | C10: 1000 | E10: 10.5988 | F10: 8.7533 | G10: 13.0647 | I10: 10.6892 | J10: 8.9241 | K10: 13.09 | M10: 12.3403 | N10: 10.0613 | O10: 15.5279 | Q10: 9.9537 | R10: 8.5633 | S10: 11.6026 | U10: 11.1063 | V10: 7.874 | W10: 16.67 | Y10: 12.669 | Z10: 10.373 | AA10: 15.8777
B11: 1100 | C11: 900
B12: 1200 | C12: 800 | E12: 12.6151 | F12: 11.6391 | G12: 14.3577 | I12: 13.166 | J12: 12.2358 | K12: 14.837 | M12: 11.8113 | N12: 9.9 | O12: 15.9639 | Q12: 11.3047 | R12: 10.1265 | S12: 13.3793 | U12: 12.0431 | V12: 9.9841 | W12: 16.67 | Y12: 11.1827 | Z12: 8.8833 | AA12: 16.3547
B13: 1300 | C13: 700
B14: 1400 | C14: 600 | E14: 13.1611 | F14: 13.0293 | G14: 13.4649 | I14: 13.1597 | J14: 13.0095 | K14: 13.5065 | M14: 13.3446 | N14: 12.3987 | O14: 16.0452 | Q14: 12.9015 | R14: 13.3942 | S14: 11.8142 | U14: 12.1216 | V14: 10.6889 | W14: 16.67 | Y14: 11.3462 | Z14: 10.9084 | AA14: 12.4713
B15: 1500 | C15: 500
B17: 1000 | C17: 1400 | E17: 10.4837 | F17: 7.6821 | G17: 13.2277 | I17: 10.1757 | J17: 7.7087 | K17: 12.581 | M17: 11.0718 | N17: 6.7313 | O17: 16.3846 | Q17: 9.3017 | R17: 8.6837 | S17: 9.8023 | U17: 10.2887 | V17: 5.456 | W17: 16.67 | Y17: 11.7589 | Z17: 7.7169 | AA17: 16.2755
B18: 1200 | C18: 1200 | E18: 10.7934 | F18: 8.7367 | G18: 13.3156 | I18: 10.7934 | J18: 8.7367 | K18: 13.3156 | M18: 10.393 | N18: 6.9545 | O18: 16.0426 | Q18: 8.8159 | R18: 12.3006 | S18: 6.3398 | U18: 9.6905 | V18: 5.7808 | W18: 16.67 | Y18: 10.2987 | Z18: 7.8308 | AA18: 13.9248
B19: 1400 | C19: 1000 | E19: 9.8755 | F19: 8.1858 | G19: 12.7198 | I19: 9.1666 | J19: 8.1444 | K19: 10.8332 | M19: 9.5646 | N19: 6.8298 | O19: 15.6118 | Q19: 8.3291 | R19: 6.783 | S19: 11.1777 | U19: 9.7789 | V19: 6.7519 | W19: 16.6677 | Y19: 10.6058 | Z19: 8.7057 | AA19: 14.2526
B20: 800 | C20: 800 | E20: 13.9816 | F20: 12.0976 | G20: 16.3381 | I20: 13.8766 | J20: 12.0583 | K20: 16.1515 | M20: 14.0041 | N20: 12.0549 | O20: 16.4426 | Q20: 13.8906 | R20: 13.617 | S20: 14.1834 | U20: 13.0808 | V20: 10.3969 | W20: 16.67 | Y20: 14.0299 | Z20: 12.0512 | AA20: 16.5086
B22: 500 | C22: 1500
A23: (30s~) | B23: 600 | C23: 1400 | E23: 12.5791 | F23: 8.8966 | G23: 14.9245 | I23: 12.701 | J23: 9.8449 | K23: 14.3633 | M23: 12.8386 | N23: 8.0958 | O23: 16.4921 | Q23: 9.1956 | R23: 9.0855 | S23: 9.2527 | U23: 12.16 | V23: 7.466 | W23: 16.67 | Y23: 13.6179 | Z23: 10.1239 | AA23: 15.9403
B24: 700 | C24: 1300
B25: 800 | C25: 1200 | E25: 11.2317 | F25: 7.9186 | G25: 14.6216 | I25: 13.72 | J25: 10.9179 | K25: 16.1442 | M25: 12.7623 | N25: 9.1841 | O25: 16.3216 | Q25: 10.3089 | R25: 10.8833 | S25: 9.9099 | U25: 12.3428 | V25: 8.1119 | W25: 16.67 | Y25: 13.44 | Z25: 10.6787 | AA25: 15.9654
B26: 900 | C26: 1100
B27: 1000 | C27: 1000 | E27: 9.814 | F27: 8.1601 | G27: 12.3498 | I27: 9.9095 | J27: 8.3478 | K27: 12.3614 | M27: 11.8294 | N27: 9.6185 | O27: 15.4697 | Q27: 9.0898 | R27: 7.9367 | S27: 10.6139 | U27: 10.3138 | V27: 7.2862 | W27: 16.67 | Y27: 12.1791 | Z27: 9.9406 | AA27: 15.8743
B28: 1100 | C28: 900
B29: 1200 | C29: 800 | E29: 11.8606 | F29: 10.7853 | G29: 13.8518 | I29: 12.5276 | J29: 11.5001 | K29: 14.4459 | M29: 10.9276 | N29: 8.8575 | O29: 15.7957 | Q29: 10.3528 | R29: 9.0575 | S29: 12.7038 | U29: 11.2024 | V29: 8.9734 | W29: 16.67 | Y29: 10.1867 | Z29: 7.6963 | AA29: 16.2935
B30: 1300 | C30: 700
B31: 1400 | C31: 600 | E31: 12.5247 | F31: 12.2675 | G31: 13.0559 | I31: 12.5225 | J31: 12.2422 | K31: 13.1026 | M31: 12.7486 | N31: 11.5234 | O31: 16.0131 | Q31: 12.2073 | R31: 12.7278 | S31: 11.1857 | U31: 11.3335 | V31: 9.5773 | W31: 16.67 | Y31: 10.4569 | Z31: 9.8593 | AA31: 11.8785
B32: 1500 | C32: 500
B34: 1000 | C34: 1400 | E34: 9.8241 | F34: 6.985 | G34: 12.7859 | I34: 9.4825 | J34: 7.0245 | K34: 12.0306 | M34: 10.4064 | N34: 6.0363 | O34: 16.3217 | Q34: 8.5247 | R34: 8.0756 | S34: 8.9007 | U34: 9.5274 | V34: 4.6822 | W34: 16.67 | Y34: 11.2294 | Z34: 7.0323 | AA34: 16.3601
B35: 1200 | C35: 1200 | E35: 9.9721 | F35: 7.7576 | G35: 12.8618 | I35: 9.9721 | J35: 7.7576 | K35: 12.8618 | M35: 9.371 | N35: 5.9129 | O35: 15.8467 | Q35: 7.8119 | R35: 11.766 | S35: 5.1282 | U35: 8.5637 | V35: 4.6428 | W35: 16.67 | Y35: 9.2569 | Z35: 6.8137 | AA35: 13.2339
B36: 1400 | C36: 1000 | E36: 9.0588 | F36: 7.2322 | G36: 12.2607 | I36: 8.2164 | J36: 7.1913 | K36: 9.9423 | M36: 8.4916 | N36: 5.6767 | O36: 15.4449 | Q36: 7.2743 | R36: 5.6965 | S36: 10.3501 | U36: 8.7362 | V36: 5.6326 | W36: 16.6669 | Y36: 9.7407 | Z36: 7.7686 | AA36: 13.829
B37: 800 | C37: 800 | E37: 13.6016 | F37: 11.5995 | G37: 16.265 | I37: 13.4779 | J37: 11.5544 | K37: 16.0371 | M37: 13.6282 | N37: 11.5506 | O37: 16.3926 | Q37: 13.4801 | R37: 13.3094 | S37: 13.669 | U37: 12.5631 | V37: 9.7037 | W37: 16.67 | Y37: 13.662 | Z37: 11.5524 | AA37: 16.4729
A39: 合流開始 | B39: 500 | C39: 1500
A40: 200m | B40: 600 | C40: 1400 | E40: 12.8649 | F40: 9.1435 | G40: 15.2144 | I40: 12.8444 | J40: 9.2924 | K40: 15.0612 | M40: 11.5888 | N40: 5.581 | O40: 16.67 | Q40: 12.1807 | R40: 12.255 | S40: 12.1474 | U40: 11.5888 | V40: 5.581 | W40: 16.67 | Y40: 13.3386 | Z40: 8.4544 | AA40: 16.56 | AC40: 12.9758 | AD40: 8.7582 | AE40: 15.6967
A41: シミュ時間 | B41: 700 | C41: 1300
A42: 90s | B42: 800 | C42: 1200 | E42: 11.6882 | F42: 9.09 | G42: 13.9953 | I42: 11.6884 | J42: 9.1356 | K42: 13.8824 | M42: 12.1974 | N42: 7.8229 | O42: 16.5655 | Q42: 12.1679 | R42: 14.0144 | S42: 11.1763 | U42: 10.0829 | V42: 4.8901 | W42: 16.67 | Y42: 12.1975 | Z42: 7.8229 | AA42: 16.5655 | AC42: 11.9982 | AD42: 8.7793 | AE42: 14.8908
B43: 900 | C43: 1100
B44: 1000 | C44: 1000 | E44: 10.8846 | F44: 9.0088 | G44: 13.3702 | I44: 10.8627 | J44: 8.8807 | K44: 13.4947 | M44: 8.6085 | N44: 4.5136 | O44: 16.67 | Q44: 10.2314 | R44: 10.3957 | S44: 10.08 | U44: 8.6085 | V44: 4.5136 | W44: 16.67 | Y44: 10.699 | Z44: 7.5123 | AA44: 15.3621 | AC44: 10.248 | AD44: 8.0218 | AE44: 13.3589
B45: 1100 | C45: 900
B46: 1200 | C46: 800 | E46: 8.5419 | F46: 7.3664 | G46: 10.5748 | I46: 8.5512 | J46: 7.293 | K46: 10.7259 | M46: 9.8019 | N46: 7.0642 | O46: 16.3866 | Q46: 8.5958 | R46: 7.3998 | S46: 10.6705 | U46: 8.3937 | V46: 5.375 | W46: 16.6569 | Y46: 9.8019 | Z46: 7.0642 | AA46: 16.3866 | AC46: 8.5419 | AD46: 7.3664 | AE46: 10.5748
...

Sheet average1-6
B2: 合流車線 | C2: 本線 | E2: 提案手法 | F2: 線形, v_max | I2: 提案手法 | J2: 2次, v_max | M2: 加藤さん | Q2: 全て受け入れ | U2: PriMa20% | Y2: PriMa40%
B3: [台/h] | C3: [台/h] | E3: all_speed | F3: cav0_speed | G3: cav1_speed | I3: all_speed | J3: cav0_speed | K3: cav1_speed | M3: all_speed | N3: cav0_speed | O3: cav1_speed | Q3: all_speed | R3: cav0_speed | S3: cav1_speed | U3: all_speed | V3: cav0_speed | W3: cav1_speed | Y3: all_speed | Z3: cav0_speed | AA3: cav1_speed | AG3: 提案１ | AH3: 提案２ | AI3: 提案３ | AJ3: Kato | AK3: always | AL3: PriMa0.2 | AM3: PriMa0.4
A5: 合流開始 | B5: 500 | C5: 1500
A6: 100m | B6: 600 | C6: 1400 | E6: =ROUND(AVERAGE(seed1!E6,seed2!E6,seed3!E6,seed4!E6,seed5!E6,seed6!E6),4) -> 13.8702 | F6: =ROUND(AVERAGE(seed1!F6,seed2!F6,seed3!F6,seed4!F6,seed5!F6,seed6!F6),4) -> 10.6324 | G6: =ROUND(AVERAGE(seed1!G6,seed2!G6,seed3!G6,seed4!G6,seed5!G6,seed6!G6),4) -> 15.7251 | I6: =ROUND(AVERAGE(seed1!I6,seed2!I6,seed3!I6,seed4!I6,seed5!I6,seed6!I6),4) -> 13.9126 | J6: =ROUND(AVERAGE(seed1!J6,seed2!J6,seed3!J6,seed4!J6,seed5!J6,seed6!J6),4) -> 11.1244 | K6: =ROUND(AVERAGE(seed1!K6,seed2!K6,seed3!K6,seed4!K6,seed5!K6,seed6!K6),4) -> 15.477 | M6: =ROUND(AVERAGE(seed1!M6,seed2!M6,seed3!M6,seed4!M6,seed5!M6,seed6!M6),4) -> 13.4267 | N6: =ROUND(AVERAGE(seed1!N6,seed2!N6,seed3!N6,seed4!N6,seed5!N6,seed6!N6),4) -> 8.8899 | O6: =ROUND(AVERAGE(seed1!O6,seed2!O6,seed3!O6,seed4!O6,seed5!O6,seed6!O6),4) -> 16.5034 | Q6: =ROUND(AVERAGE(seed1!Q6,seed2!Q6,seed3!Q6,seed4!Q6,seed5!Q6,seed6!Q6),4) -> 12.8142 | R6: =ROUND(AVERAGE(seed1!R6,seed2!R6,seed3!R6,seed4!R6,seed5!R6,seed6!R6),4) -> 12.667 | S6: =ROUND(AVERAGE(seed1!S6,seed2!S6,seed3!S6,seed4!S6,seed5!S6,seed6!S6),4) -> 13.082 | U6: =ROUND(AVERAGE(seed1!U6,seed2!U6,seed3!U6,seed4!U6,seed5!U6,seed6!U6),4) -> 12.7536 | V6: =ROUND(AVERAGE(seed1!V6,seed2!V6,seed3!V6,seed4!V6,seed5!V6,seed6!V6),4) -> 7.5501 | W6: =ROUND(AVERAGE(seed1!W6,seed2!W6,seed3!W6,seed4!W6,seed5!W6,seed6!W6),4) -> 16.67 | Y6: =ROUND(AVERAGE(seed1!Y6,seed2!Y6,seed3!Y6,seed4!Y6,seed5!Y6,seed6!Y6),4) -> 14.3018 | Z6: =ROUND(AVERAGE(seed1!Z6,seed2!Z6,seed3!Z6,seed4!Z6,seed5!Z6,seed6!Z6),4) -> 11.979 | AA6: =ROUND(AVERAGE(seed1!AA6,seed2!AA6,seed3!AA6,seed4!AA6,seed5!AA6,seed6!AA6),4) -> 15.7428 | AG6: =E6 -> 13.8702 | AH6: =I6 -> 13.9126 | AI6: =AC6 -> 0 | AJ6: =M6 -> 13.4267 | AK6: =Q6 -> 12.8142 | AL6: =U6 -> 12.7536 | AM6: =Y6 -> 14.3018
A7: シミュ時間 | B7: 700 | C7: 1300 | AG7: =E7 -> 0 | AH7: =I7 -> 0 | AI7: =AC7 -> 0 | AJ7: =M7 -> 0 | AK7: =Q7 -> 0 | AL7: =U7 -> 0 | AM7: =Y7 -> 0
A8: 90s | B8: 800 | C8: 1200 | E8: =ROUND(AVERAGE(seed1!E8,seed2!E8,seed3!E8,seed4!E8,seed5!E8,seed6!E8),4) -> 13.0586 | F8: =ROUND(AVERAGE(seed1!F8,seed2!F8,seed3!F8,seed4!F8,seed5!F8,seed6!F8),4) -> 11.2233 | G8: =ROUND(AVERAGE(seed1!G8,seed2!G8,seed3!G8,seed4!G8,seed5!G8,seed6!G8),4) -> 14.6719 | I8: =ROUND(AVERAGE(seed1!I8,seed2!I8,seed3!I8,seed4!I8,seed5!I8,seed6!I8),4) -> 13.4542 | J8: =ROUND(AVERAGE(seed1!J8,seed2!J8,seed3!J8,seed4!J8,seed5!J8,seed6!J8),4) -> 11.7584 | K8: =ROUND(AVERAGE(seed1!K8,seed2!K8,seed3!K8,seed4!K8,seed5!K8,seed6!K8),4) -> 14.8921 | M8: =ROUND(AVERAGE(seed1!M8,seed2!M8,seed3!M8,seed4!M8,seed5!M8,seed6!M8),4) -> 13.5748 | N8: =ROUND(AVERAGE(seed1!N8,seed2!N8,seed3!N8,seed4!N8,seed5!N8,seed6!N8),4) -> 10.6414 | O8: =ROUND(AVERAGE(seed1!O8,seed2!O8,seed3!O8,seed4!O8,seed5!O8,seed6!O8),4) -> 16.4428 | Q8: =ROUND(AVERAGE(seed1!Q8,seed2!Q8,seed3!Q8,seed4!Q8,seed5!Q8,seed6!Q8),4) -> 12.1052 | R8: =ROUND(AVERAGE(seed1!R8,seed2!R8,seed3!R8,seed4!R8,seed5!R8,seed6!R8),4) -> 12.891 | S8: =ROUND(AVERAGE(seed1!S8,seed2!S8,seed3!S8,seed4!S8,seed5!S8,seed6!S8),4) -> 11.6522 | U8: =ROUND(AVERAGE(seed1!U8,seed2!U8,seed3!U8,seed4!U8,seed5!U8,seed6!U8),4) -> 12.5242 | V8: =ROUND(AVERAGE(seed1!V8,seed2!V8,seed3!V8,seed4!V8,seed5!V8,seed6!V8),4) -> 8.6394 | W8: =ROUND(AVERAGE(seed1!W8,seed2!W8,seed3!W8,seed4!W8,seed5!W8,seed6!W8),4) -> 16.67 | Y8: =ROUND(AVERAGE(seed1!Y8,seed2!Y8,seed3!Y8,seed4!Y8,seed5!Y8,seed6!Y8),4) -> 14.1779 | Z8: =ROUND(AVERAGE(seed1!Z8,seed2!Z8,seed3!Z8,seed4!Z8,seed5!Z8,seed6!Z8),4) -> 12.1532 | AA8: =ROUND(AVERAGE(seed1!AA8,seed2!AA8,seed3!AA8,seed4!AA8,seed5!AA8,seed6!AA8),4) -> 16.0348 | AG8: =E8 -> 13.0586 | AH8: =I8 -> 13.4542 | AI8: =AC8 -> 0 | AJ8: =M8 -> 13.5748 | AK8: =Q8 -> 12.1052 | AL8: =U8 -> 12.5242 | AM8: =Y8 -> 14.1779
B9: 900 | C9: 1100 | AG9: =E9 -> 0 | AH9: =I9 -> 0 | AI9: =AC9 -> 0 | AJ9: =M9 -> 0 | AK9: =Q9 -> 0 | AL9: =U9 -> 0 | AM9: =Y9 -> 0
B10: 1000 | C10: 1000 | E10: =ROUND(AVERAGE(seed1!E10,seed2!E10,seed3!E10,seed4!E10,seed5!E10,seed6!E10),4) -> 12.7801 | F10: =ROUND(AVERAGE(seed1!F10,seed2!F10,seed3!F10,seed4!F10,seed5!F10,seed6!F10),4) -> 11.3682 | G10: =ROUND(AVERAGE(seed1!G10,seed2!G10,seed3!G10,seed4!G10,seed5!G10,seed6!G10),4) -> 14.5567 | I10: =ROUND(AVERAGE(seed1!I10,seed2!I10,seed3!I10,seed4!I10,seed5!I10,seed6!I10),4) -> 12.3514 | J10: =ROUND(AVERAGE(seed1!J10,seed2!J10,seed3!J10,seed4!J10,seed5!J10,seed6!J10),4) -> 11.1153 | K10: =ROUND(AVERAGE(seed1!K10,seed2!K10,seed3!K10,seed4!K10,seed5!K10,seed6!K10),4) -> 13.8864 | M10: =ROUND(AVERAGE(seed1!M10,seed2!M10,seed3!M10,seed4!M10,seed5!M10,seed6!M10),4) -> 13.0327 | N10: =ROUND(AVERAGE(seed1!N10,seed2!N10,seed3!N10,seed4!N10,seed5!N10,seed6!N10),4) -> 10.9726 | O10: =ROUND(AVERAGE(seed1!O10,seed2!O10,seed3!O10,seed4!O10,seed5!O10,seed6!O10),4) -> 15.8287 | Q10: =ROUND(AVERAGE(seed1!Q10,seed2!Q10,seed3!Q10,seed4!Q10,seed5!Q10,seed6!Q10),4) -> 11.0121 | R10: =ROUND(AVERAGE(seed1!R10,seed2!R10,seed3!R10,seed4!R10,seed5!R10,seed6!R10),4) -> 10.891 | S10: =ROUND(AVERAGE(seed1!S10,seed2!S10,seed3!S10,seed4!S10,seed5!S10,seed6!S10),4) -> 11.2081 | U10: =ROUND(AVERAGE(seed1!U10,seed2!U10,seed3!U10,seed4!U10,seed5!U10,seed6!U10),4) -> 11.8048 | V10: =ROUND(AVERAGE(seed1!V10,seed2!V10,seed3!V10,seed4!V10,seed5!V10,seed6!V10),4) -> 8.7368 | W10: =ROUND(AVERAGE(seed1!W10,seed2!W10,seed3!W10,seed4!W10,seed5!W10,seed6!W10),4) -> 16.6643 | Y10: =ROUND(AVERAGE(seed1!Y10,seed2!Y10,seed3!Y10,seed4!Y10,seed5!Y10,seed6!Y10),4) -> 13.3398 | Z10: =ROUND(AVERAGE(seed1!Z10,seed2!Z10,seed3!Z10,seed4!Z10,seed5!Z10,seed6!Z10),4) -> 11.301 | AA10: =ROUND(AVERAGE(seed1!AA10,seed2!AA10,seed3!AA10,seed4!AA10,seed5!AA10,seed6!AA10),4) -> 16.0493 | AG10: =E10 -> 12.7801 | AH10: =I10 -> 12.3514 | AI10: =AC10 -> 0 | AJ10: =M10 -> 13.0327 | AK10: =Q10 -> 11.0121 | AL10: =U10 -> 11.8048 | AM10: =Y10 -> 13.3398
B11: 1100 | C11: 900 | AG11: =E11 -> 0 | AH11: =I11 -> 0 | AI11: =AC11 -> 0 | AJ11: =M11 -> 0 | AK11: =Q11 -> 0 | AL11: =U11 -> 0 | AM11: =Y11 -> 0
B12: 1200 | C12: 800 | E12: =ROUND(AVERAGE(seed1!E12,seed2!E12,seed3!E12,seed4!E12,seed5!E12,seed6!E12),4) -> 12.0024 | F12: =ROUND(AVERAGE(seed1!F12,seed2!F12,seed3!F12,seed4!F12,seed5!F12,seed6!F12),4) -> 10.737 | G12: =ROUND(AVERAGE(seed1!G12,seed2!G12,seed3!G12,seed4!G12,seed5!G12,seed6!G12),4) -> 14.3614 | I12: =ROUND(AVERAGE(seed1!I12,seed2!I12,seed3!I12,seed4!I12,seed5!I12,seed6!I12),4) -> 11.8735 | J12: =ROUND(AVERAGE(seed1!J12,seed2!J12,seed3!J12,seed4!J12,seed5!J12,seed6!J12),4) -> 10.6696 | K12: =ROUND(AVERAGE(seed1!K12,seed2!K12,seed3!K12,seed4!K12,seed5!K12,seed6!K12),4) -> 14.1365 | M12: =ROUND(AVERAGE(seed1!M12,seed2!M12,seed3!M12,seed4!M12,seed5!M12,seed6!M12),4) -> 12.0202 | N12: =ROUND(AVERAGE(seed1!N12,seed2!N12,seed3!N12,seed4!N12,seed5!N12,seed6!N12),4) -> 10.1885 | O12: =ROUND(AVERAGE(seed1!O12,seed2!O12,seed3!O12,seed4!O12,seed5!O12,seed6!O12),4) -> 15.9316 | Q12: =ROUND(AVERAGE(seed1!Q12,seed2!Q12,seed3!Q12,seed4!Q12,seed5!Q12,seed6!Q12),4) -> 10.5696 | R12: =ROUND(AVERAGE(seed1!R12,seed2!R12,seed3!R12,seed4!R12,seed5!R12,seed6!R12),4) -> 10.1982 | S12: =ROUND(AVERAGE(seed1!S12,seed2!S12,seed3!S12,seed4!S12,seed5!S12,seed6!S12),4) -> 11.2264 | U12: =ROUND(AVERAGE(seed1!U12,seed2!U12,seed3!U12,seed4!U12,seed5!U12,seed6!U12),4) -> 11.1777 | V12: =ROUND(AVERAGE(seed1!V12,seed2!V12,seed3!V12,seed4!V12,seed5!V12,seed6!V12),4) -> 8.8486 | W12: =ROUND(AVERAGE(seed1!W12,seed2!W12,seed3!W12,seed4!W12,seed5!W12,seed6!W12),4) -> 16.67 | Y12: =ROUND(AVERAGE(seed1!Y12,seed2!Y12,seed3!Y12,seed4!Y12,seed5!Y12,seed6!Y12),4) -> 12.3267 | Z12: =ROUND(AVERAGE(seed1!Z12,seed2!Z12,seed3!Z12,seed4!Z12,seed5!Z12,seed6!Z12),4) -> 10.578 | AA12: =ROUND(AVERAGE(seed1!AA12,seed2!AA12,seed3!AA12,seed4!AA12,seed5!AA12,seed6!AA12),4) -> 15.9337 | AG12: =E12 -> 12.0024 | AH12: =I12 -> 11.8735 | AI12: =AC12 -> 0 | AJ12: =M12 -> 12.0202 | AK12: =Q12 -> 10.5696 | AL12: =U12 -> 11.1777 | AM12: =Y12 -> 12.3267
B13: 1300 | C13: 700 | AG13: =E13 -> 0 | AH13: =I13 -> 0 | AI13: =AC13 -> 0 | AJ13: =M13 -> 0 | AK13: =Q13 -> 0 | AL13: =U13 -> 0 | AM13: =Y13 -> 0
B14: 1400 | C14: 600 | E14: =ROUND(AVERAGE(seed1!E14,seed2!E14,seed3!E14,seed4!E14,seed5!E14,seed6!E14),4) -> 12.4514 | F14: =ROUND(AVERAGE(seed1!F14,seed2!F14,seed3!F14,seed4!F14,seed5!F14,seed6!F14),4) -> 12.0099 | G14: =ROUND(AVERAGE(seed1!G14,seed2!G14,seed3!G14,seed4!G14,seed5!G14,seed6!G14),4) -> 13.6172 | I14: =ROUND(AVERAGE(seed1!I14,seed2!I14,seed3!I14,seed4!I14,seed5!I14,seed6!I14),4) -> 12.7689 | J14: =ROUND(AVERAGE(seed1!J14,seed2!J14,seed3!J14,seed4!J14,seed5!J14,seed6!J14),4) -> 12.2869 | K14: =ROUND(AVERAGE(seed1!K14,seed2!K14,seed3!K14,seed4!K14,seed5!K14,seed6!K14),4) -> 14.0463 | M14: =ROUND(AVERAGE(seed1!M14,seed2!M14,seed3!M14,seed4!M14,seed5!M14,seed6!M14),4) -> 12.9129 | N14: =ROUND(AVERAGE(seed1!N14,seed2!N14,seed3!N14,seed4!N14,seed5!N14,seed6!N14),4) -> 11.8725 | O14: =ROUND(AVERAGE(seed1!O14,seed2!O14,seed3!O14,seed4!O14,seed5!O14,seed6!O14),4) -> 16.1214 | Q14: =ROUND(AVERAGE(seed1!Q14,seed2!Q14,seed3!Q14,seed4!Q14,seed5!Q14,seed6!Q14),4) -> 11.6526 | R14: =ROUND(AVERAGE(seed1!R14,seed2!R14,seed3!R14,seed4!R14,seed5!R14,seed6!R14),4) -> 12.1456 | S14: =ROUND(AVERAGE(seed1!S14,seed2!S14,seed3!S14,seed4!S14,seed5!S14,seed6!S14),4) -> 10.693 | U14: =ROUND(AVERAGE(seed1!U14,seed2!U14,seed3!U14,seed4!U14,seed5!U14,seed6!U14),4) -> 12.1975 | V14: =ROUND(AVERAGE(seed1!V14,seed2!V14,seed3!V14,seed4!V14,seed5!V14,seed6!V14),4) -> 10.8442 | W14: =ROUND(AVERAGE(seed1!W14,seed2!W14,seed3!W14,seed4!W14,seed5!W14,seed6!W14),4) -> 16.6672 | Y14: =ROUND(AVERAGE(seed1!Y14,seed2!Y14,seed3!Y14,seed4!Y14,seed5!Y14,seed6!Y14),4) -> 12.6039 | Z14: =ROUND(AVERAGE(seed1!Z14,seed2!Z14,seed3!Z14,seed4!Z14,seed5!Z14,seed6!Z14),4) -> 11.6508 | AA14: =ROUND(AVERAGE(seed1!AA14,seed2!AA14,seed3!AA14,seed4!AA14,seed5!AA14,seed6!AA14),4) -> 15.4703 | AG14: =E14 -> 12.4514 | AH14: =I14 -> 12.7689 | AI14: =AC14 -> 0 | AJ14: =M14 -> 12.9129 | AK14: =Q14 -> 11.6526 | AL14: =U14 -> 12.1975 | AM14: =Y14 -> 12.6039
B15: 1500 | C15: 500 | AG15: =E15 -> 0 | AH15: =I15 -> 0 | AI15: =AC15 -> 0 | AJ15: =M15 -> 0 | AK15: =Q15 -> 0 | AL15: =U15 -> 0 | AM15: =Y15 -> 0
AG16: =E16 -> 0 | AH16: =I16 -> 0 | AI16: =AC16 -> 0 | AJ16: =M16 -> 0 | AK16: =Q16 -> 0 | AL16: =U16 -> 0 | AM16: =Y16 -> 0
B17: 1000 | C17: 1400 | E17: =ROUND(AVERAGE(seed1!E17,seed2!E17,seed3!E17,seed4!E17,seed5!E17,seed6!E17),4) -> 11.459 | F17: =ROUND(AVERAGE(seed1!F17,seed2!F17,seed3!F17,seed4!F17,seed5!F17,seed6!F17),4) -> 9.0173 | G17: =ROUND(AVERAGE(seed1!G17,seed2!G17,seed3!G17,seed4!G17,seed5!G17,seed6!G17),4) -> 13.7822 | I17: =ROUND(AVERAGE(seed1!I17,seed2!I17,seed3!I17,seed4!I17,seed5!I17,seed6!I17),4) -> 11.3273 | J17: =ROUND(AVERAGE(seed1!J17,seed2!J17,seed3!J17,seed4!J17,seed5!J17,seed6!J17),4) -> 9.3937 | K17: =ROUND(AVERAGE(seed1!K17,seed2!K17,seed3!K17,seed4!K17,seed5!K17,seed6!K17),4) -> 13.0651 | M17: =ROUND(AVERAGE(seed1!M17,seed2!M17,seed3!M17,seed4!M17,seed5!M17,seed6!M17),4) -> 11.6039 | N17: =ROUND(AVERAGE(seed1!N17,seed2!N17,seed3!N17,seed4!N17,seed5!N17,seed6!N17),4) -> 7.69 | O17: =ROUND(AVERAGE(seed1!O17,seed2!O17,seed3!O17,seed4!O17,seed5!O17,seed6!O17),4) -> 16.2497 | Q17: =ROUND(AVERAGE(seed1!Q17,seed2!Q17,seed3!Q17,seed4!Q17,seed5!Q17,seed6!Q17),4) -> 10.1676 | R17: =ROUND(AVERAGE(seed1!R17,seed2!R17,seed3!R17,seed4!R17,seed5!R17,seed6!R17),4) -> 10.921 | S17: =ROUND(AVERAGE(seed1!S17,seed2!S17,seed3!S17,seed4!S17,seed5!S17,seed6!S17),4) -> 9.681 | U17: =ROUND(AVERAGE(seed1!U17,seed2!U17,seed3!U17,seed4!U17,seed5!U17,seed6!U17),4) -> 10.4942 | V17: =ROUND(AVERAGE(seed1!V17,seed2!V17,seed3!V17,seed4!V17,seed5!V17,seed6!V17),4) -> 5.8284 | W17: =ROUND(AVERAGE(seed1!W17,seed2!W17,seed3!W17,seed4!W17,seed5!W17,seed6!W17),4) -> 16.67 | Y17: =ROUND(AVERAGE(seed1!Y17,seed2!Y17,seed3!Y17,seed4!Y17,seed5!Y17,seed6!Y17),4) -> 12.5274 | Z17: =ROUND(AVERAGE(seed1!Z17,seed2!Z17,seed3!Z17,seed4!Z17,seed5!Z17,seed6!Z17),4) -> 9.2367 | AA17: =ROUND(AVERAGE(seed1!AA17,seed2!AA17,seed3!AA17,seed4!AA17,seed5!AA17,seed6!AA17),4) -> 15.9465 | AG17: =E17 -> 11.459 | AH17: =I17 -> 11.3273 | AI17: =AC17 -> 0 | AJ17: =M17 -> 11.6039 | AK17: =Q17 -> 10.1676 | AL17: =U17 -> 10.4942 | AM17: =Y17 -> 12.5274
